File: DSC/Olivia/2025_08_05_TS_Al2O3_n60C_250C_10Cmin_x3.csv
Filename,2025_08_05_TS_Al2O3_n60C_250C_10Cmin_x3
Instrument name,DSC2A-00468 (192.168.1.100)
Operator,Yarger
rundate,8/5/2025
Sample name,2025_08_05_TS_Al2O3_n60C_250C_10Cmin_x3
proceduresegments,Data Off ; Equilibrate -60.00 °C; Data On ; Ramp 10.00 °C/min to 250.00 °C; Data Off ; Isothermal 2.0 min; Data On ; Ramp 10.00 °C/min to -60.00 °C; Data Off ; Isothermal 2.0 min; Data On ; Ramp 10.00 °C/min to 250.00 °C; Data Off ; Isothermal 2.0 min; Data On ; Ramp 10.00 °C/min to -60.00 °C; Data Off ; Isothermal 2.0 min; Data On ; Ramp 10.00 °C/min to 250.00 °C
[File Parameters]
Run date,8/5/2025 9:48:17 PM
Trios version,5.1.1.46572
Original File Name,
Current File Name,D:\DSC2500\JYarger\2025_08_05_TS_Al2O3_n60C_250C_10Cmin_x3.tri
[Procedure]
Procedure Name,Al2O3_TS_Pans_n60C_250C_10Cmin_x3
Sample Name,2025_08_05_TS_Al2O3_n60C_250C_10Cmin_x3
Sample Mass,4.15 mg
Reference Sample Mass,0 mg
Pan Mass,32.82 mg
Pan Number,7
Reference Pan Mass,32.52 mg
Reference Pan Number,37
Pan Type,Aluminum
Comments,Thermal support Al pans/lids. DSC_Samples_A2_Tray_July2025 google sheet.
Project Name,Calibration
Operator,Yarger
Test,Custom
Unload Max Temperature,30
Unload Min Temperature,30
Load Max Temperature,30
Load Min Temperature,30
Stop on Gas Flow Error,Yes
[Signal List]
Signal #1,Time (min)
Signal #2,Temperature (°C)
Signal #3,Heat Flow (mW)
Signal #4,Delta T (µV)
Signal #5,Delta Tzero (µV)
Signal #6,Tzero Temperature (°C)
Signal #7,Cell Purge (mL/min)
Signal #8,Heater Temp (°C)
Signal #9,Power Delivered (W)
Signal #10,Reference Junction Temperature (°C)
Signal #11,Flange Temperature (°C)
Signal #12,Heat Flow Phase (rad)
Signal #13,Total Heat Capacity (J/°C)
Signal #14,Heat Capacity (J/°C)
[Configuration]
Company Name,ASU
Instrument Name,DSC2A-00468
Instrument Type,DSC2500
Serial Number,DSC2A-00468
IP,192.168.1.100
Location of Instrument,MRRC
DisplayType,Unknown
Sample Interval ,0.1 s/pt
Selected Heat Flow,T4P
Exotherm Direction,Down
Cell Serial,DRC2-00792
Lid Type,Standard
Cooler,RCS 90
Leave Cooler on at End of Sequence,On
Gas 2,Nitrogen
Gas Selected,Channel 1
Flow Rate,50 mL/min
Secondary Purge,On
Licensed Heat Flow,Heat Flow T4P
Modulation Licensed,Yes
[Versions]
Common IDD Version,1
Cortex Version,VER 2.10.2.31
Driver,5.0.0.6
GDM Version,1.0.3.3
TouchscreenVersion,1.0.0.16145
FEP Version,1.2.1.21
FEP Bootloader,2.0.0.5
AutoSampler Version,2.1.1.26
Auto Sampler Bootloader,2.0.0.5
FCM Version,1.1.0.3
FCM Bootloader,2.0.0.5
[Experiment Logs]
Experiment Log Entry # 1,Air Cool is off.
Experiment Log Entry # 3,Data On set to 0
Experiment Log Entry # 5,Equilibrate Segment -60 (C) Started
Experiment Log Entry # 7,Data On set to 1
Experiment Log Entry # 9,Ramp Segment 10 C/min to 250 Started
Experiment Log Entry # 11,Data On set to 0
Experiment Log Entry # 13,Isothermal Segment 2 min started
Experiment Log Entry # 15,Data On set to 1
Experiment Log Entry # 17,Ramp Segment 10 C/min to -60 Started
Experiment Log Entry # 19,Data On set to 0
Experiment Log Entry # 21,Isothermal Segment 2 min started
Experiment Log Entry # 23,Data On set to 1
Experiment Log Entry # 25,Ramp Segment 10 C/min to 250 Started
Experiment Log Entry # 27,Data On set to 0
Experiment Log Entry # 29,Isothermal Segment 2 min started
Experiment Log Entry # 31,Data On set to 1
Experiment Log Entry # 33,Ramp Segment 10 C/min to -60 Started
Experiment Log Entry # 35,Data On set to 0
Experiment Log Entry # 37,Isothermal Segment 2 min started
Experiment Log Entry # 39,Data On set to 1
Experiment Log Entry # 41,Ramp Segment 10 C/min to 250 Started
[Method Log]
Method Log Entry # 1,Data Off
Method Log Entry # 2,Equilibrate -60 °C
Method Log Entry # 3,Data On
Method Log Entry # 4,(Ramp 284783) Ramp 10 °C/minute to 250 °C
Method Log Entry # 5,Data Off
Method Log Entry # 6,Isothermal 2 minutes
Method Log Entry # 7,Data On
Method Log Entry # 8,(Ramp 284787) Ramp 10 °C/minute to -60 °C
Method Log Entry # 9,Data Off
Method Log Entry # 10,Isothermal 2 minutes
Method Log Entry # 11,Data On
Method Log Entry # 12,(Ramp 284791) Ramp 10 °C/minute to 250 °C
Method Log Entry # 13,Data Off
Method Log Entry # 14,Isothermal 2 minutes
Method Log Entry # 15,Data On
Method Log Entry # 16,(Ramp 284795) Ramp 10 °C/minute to -60 °C
Method Log Entry # 17,Data Off
Method Log Entry # 18,Isothermal 2 minutes
Method Log Entry # 19,Data On
Method Log Entry # 20,(Ramp 284799) Ramp 10 °C/minute to 250 °C
Cell Serial,DRC2-00792
[T1 Calibration]
Slope,-0.008529666
Offset,9.636258
Initial Temperature,98.23
GUID,f8bfdadc-4977-4fdf-ba6d-0ba9134940c3
[TZero Calibration]
Date Applied,11/29/2022 4:06:13 PM
Description,From -89.059 °C to 396.009 °C at 20.000°C/min
Gas Type,Nitrogen
Pan Type,None
Source Files 1,C:\Users\yargerlab\Desktop\DSC Data\General\TZero_calibration_11_29_22_2nd(2).tri
Source Files 2,C:\Users\yargerlab\Desktop\DSC Data\General\TZero_calibration_11_29_22_2nd(3).tri
Delta T Offset,13.05235
Delta T Slope,-0.007271007
Delta T0 Offset,-13.69128
Delta T0 Slope,0.06063341
[Temperature Calibration]
Date Applied,11/29/2022 7:12:28 PM
Description,From 106.590 °C to 186.590 °C at 10.000°C/min
Gas Type,Nitrogen
Pan Type,Tzero Aluminum Hermetic
Source Files 1,C:\Users\yargerlab\Desktop\DSC Data\General\Indium(6).tri
Measured 1,157.391
Known 1,156.598
[Cell Constant Calibration]
Date Applied,11/29/2022 7:12:29 PM
Description,From 106.590 °C to 186.590 °C at 10.000°C/min
Gas Type,Nitrogen
Pan Type,Tzero Aluminum Hermetic
Source Files 1,C:\Users\yargerlab\Desktop\DSC Data\General\Indium(6).tri
T4P KCell,1.006051
Onset Slope,63.26126 mW/°C
[Direct Cp Calibration]
Date Applied,11/30/2022 11:04:51 AM
Description,From -79.983 °C to 298.409 °C at 10.000°C/min
Gas Type,Nitrogen
Pan Type,Tzero Aluminum Hermetic
Source Files 1,C:\Users\yargerlab\Desktop\DSC Data\General\Sapphire_Heat_Capacity_11_30_22.tri
[Rev Cp Calibration]
Date Applied,11/30/2022 1:58:51 PM
Description,From -79.996 °C to 292.812 °C at 3.000°C/min
Gas Type,Nitrogen
Pan Type,Tzero Aluminum Hermetic
Source Files 1,C:\Users\yargerlab\Desktop\DSC Data\General\Sapphire_MDSC_Calibration_11_30_22.tri
[step]
Ramp 10.00 °C/min to 250.00 °C
Time,Temperature,Heat Flow (Normalized)
min,°C,W/g
0.00,-59.81,-0.048
0.02,-59.81,-0.045
0.04,-59.81,-0.041
0.07,-59.79,-0.042
0.09,-59.74,-0.045
0.11,-59.65,-0.045
0.13,-59.53,-0.032
0.15,-59.39,-0.003
0.17,-59.22,0.022
0.19,-59.04,0.051
0.22,-58.85,0.075
0.24,-58.65,0.094
0.26,-58.44,0.109
0.28,-58.24,0.119
0.30,-58.03,0.129
0.33,-57.82,0.134
0.35,-57.61,0.137
0.37,-57.40,0.140
0.39,-57.19,0.143
0.41,-56.98,0.143
0.43,-56.77,0.145
0.45,-56.55,0.146
0.48,-56.34,0.146
0.50,-56.13,0.147
0.52,-55.92,0.148
0.54,-55.70,0.149
0.56,-55.49,0.149
0.58,-55.28,0.150
0.61,-55.06,0.150
0.63,-54.85,0.150
0.65,-54.64,0.151
0.67,-54.42,0.151
0.69,-54.21,0.152
0.72,-53.99,0.152
0.74,-53.78,0.153
0.76,-53.56,0.153
0.78,-53.35,0.153
0.80,-53.14,0.154
0.82,-52.92,0.154
0.85,-52.70,0.154
0.87,-52.49,0.155
0.89,-52.28,0.155
0.91,-52.06,0.155
0.93,-51.84,0.156
0.95,-51.63,0.156
0.98,-51.41,0.156
1.00,-51.20,0.157
1.02,-50.98,0.157
1.04,-50.77,0.157
1.06,-50.55,0.157
1.08,-50.34,0.158
1.11,-50.12,0.158
1.13,-49.90,0.158
1.15,-49.69,0.158
1.17,-49.47,0.158
1.19,-49.26,0.159
1.21,-49.04,0.159
1.23,-48.82,0.159
1.26,-48.61,0.159
1.28,-48.39,0.159
1.30,-48.18,0.159
1.32,-47.96,0.159
1.34,-47.74,0.160
1.37,-47.53,0.160
1.39,-47.31,0.160
1.41,-47.09,0.160
1.43,-46.88,0.160
1.45,-46.66,0.160
1.47,-46.44,0.160
1.49,-46.23,0.160
1.52,-46.01,0.160
1.54,-45.79,0.160
1.56,-45.58,0.161
1.58,-45.36,0.161
1.60,-45.14,0.161
1.63,-44.93,0.161
1.65,-44.71,0.161
1.67,-44.49,0.161
1.69,-44.28,0.161
1.71,-44.06,0.161
1.73,-43.84,0.161
1.76,-43.63,0.161
1.78,-43.41,0.161
1.80,-43.19,0.161
1.82,-42.98,0.161
1.84,-42.76,0.161
1.86,-42.54,0.161
1.88,-42.32,0.161
1.91,-42.11,0.161
1.93,-41.89,0.162
1.95,-41.67,0.162
1.97,-41.46,0.162
1.99,-41.24,0.162
2.02,-41.02,0.162
2.04,-40.81,0.162
2.06,-40.59,0.162
2.08,-40.37,0.162
2.10,-40.16,0.162
2.12,-39.94,0.162
2.14,-39.72,0.162
2.17,-39.51,0.162
2.19,-39.29,0.162
2.21,-39.07,0.162
2.23,-38.85,0.162
2.25,-38.64,0.162
2.28,-38.42,0.162
2.30,-38.20,0.162
2.32,-37.99,0.162
2.34,-37.77,0.162
2.36,-37.55,0.162
2.38,-37.34,0.162
2.41,-37.12,0.162
2.43,-36.90,0.162
2.45,-36.68,0.162
2.47,-36.47,0.162
2.49,-36.25,0.162
2.51,-36.03,0.162
2.54,-35.82,0.162
2.56,-35.60,0.162
2.58,-35.38,0.162
2.60,-35.17,0.162
2.62,-34.95,0.162
2.64,-34.73,0.162
2.66,-34.52,0.162
2.69,-34.30,0.162
2.71,-34.08,0.162
2.73,-33.86,0.162
2.75,-33.65,0.162
2.77,-33.43,0.162
2.79,-33.21,0.162
2.82,-33.00,0.162
2.84,-32.78,0.162
2.86,-32.56,0.162
2.88,-32.35,0.162
2.90,-32.13,0.162
2.93,-31.91,0.162
2.95,-31.70,0.162
2.97,-31.48,0.162
2.99,-31.26,0.162
3.01,-31.04,0.162
3.03,-30.83,0.162
3.06,-30.61,0.162
3.08,-30.39,0.162
3.10,-30.18,0.162
3.12,-29.96,0.162
3.14,-29.74,0.162
3.16,-29.53,0.162
3.19,-29.31,0.162
3.21,-29.09,0.162
3.23,-28.87,0.162
3.25,-28.66,0.162
3.27,-28.44,0.162
3.29,-28.22,0.162
3.31,-28.01,0.162
3.34,-27.79,0.162
3.36,-27.57,0.162
3.38,-27.36,0.162
3.40,-27.14,0.162
3.42,-26.92,0.162
3.44,-26.70,0.162
3.47,-26.49,0.162
3.49,-26.27,0.162
3.51,-26.05,0.162
3.53,-25.84,0.162
3.55,-25.62,0.162
3.58,-25.40,0.162
3.60,-25.19,0.162
3.62,-24.97,0.162
3.64,-24.75,0.162
3.66,-24.54,0.162
3.68,-24.32,0.162
3.71,-24.10,0.162
3.73,-23.88,0.162
3.75,-23.67,0.162
3.77,-23.45,0.162
3.79,-23.23,0.162
3.81,-23.02,0.162
3.84,-22.80,0.162
3.86,-22.58,0.162
3.88,-22.37,0.162
3.90,-22.15,0.162
3.92,-21.93,0.162
3.94,-21.72,0.162
3.96,-21.50,0.163
3.99,-21.28,0.163
4.01,-21.06,0.163
4.03,-20.85,0.163
4.05,-20.63,0.163
4.07,-20.41,0.163
4.09,-20.20,0.163
4.12,-19.98,0.163
4.14,-19.76,0.163
4.16,-19.55,0.163
4.18,-19.33,0.163
4.20,-19.11,0.163
4.23,-18.90,0.163
4.25,-18.68,0.163
4.27,-18.46,0.163
4.29,-18.24,0.163
4.31,-18.03,0.163
4.33,-17.81,0.163
4.35,-17.59,0.163
4.38,-17.38,0.163
4.40,-17.16,0.163
4.42,-16.94,0.163
4.44,-16.73,0.163
4.46,-16.51,0.163
4.49,-16.29,0.163
4.51,-16.08,0.163
4.53,-15.86,0.163
4.55,-15.64,0.163
4.57,-15.42,0.163
4.59,-15.21,0.163
4.61,-14.99,0.163
4.64,-14.77,0.163
4.66,-14.56,0.163
4.68,-14.34,0.163
4.70,-14.12,0.163
4.72,-13.91,0.164
4.75,-13.69,0.164
4.77,-13.47,0.164
4.79,-13.26,0.164
4.81,-13.04,0.164
4.83,-12.82,0.164
4.85,-12.60,0.164
4.88,-12.39,0.164
4.90,-12.17,0.164
4.92,-11.95,0.164
4.94,-11.74,0.164
4.96,-11.52,0.164
4.98,-11.30,0.164
5.00,-11.09,0.164
5.03,-10.87,0.164
5.05,-10.65,0.164
5.07,-10.44,0.164
5.09,-10.22,0.164
5.11,-10.00,0.164
5.14,-9.79,0.164
5.16,-9.57,0.164
5.18,-9.35,0.164
5.20,-9.14,0.164
5.22,-8.92,0.164
5.24,-8.70,0.165
5.26,-8.48,0.165
5.29,-8.27,0.165
5.31,-8.05,0.165
5.33,-7.83,0.165
5.35,-7.62,0.165
5.37,-7.40,0.165
5.40,-7.18,0.165
5.42,-6.96,0.165
5.44,-6.75,0.165
5.46,-6.53,0.165
5.48,-6.31,0.165
5.50,-6.10,0.165
5.53,-5.88,0.165
5.55,-5.66,0.165
5.57,-5.45,0.165
5.59,-5.23,0.166
5.61,-5.01,0.166
5.63,-4.80,0.166
5.65,-4.58,0.166
5.68,-4.36,0.166
5.70,-4.15,0.166
5.72,-3.93,0.166
5.74,-3.71,0.166
5.76,-3.49,0.166
5.79,-3.28,0.166
5.81,-3.06,0.166
5.83,-2.84,0.166
5.85,-2.63,0.166
5.87,-2.41,0.166
5.89,-2.19,0.166
5.91,-1.98,0.166
5.94,-1.76,0.166
5.96,-1.54,0.167
5.98,-1.32,0.167
6.00,-1.11,0.167
6.02,-0.89,0.167
6.05,-0.68,0.167
6.07,-0.46,0.167
6.09,-0.24,0.167
6.11,-0.02,0.167
6.13,0.19,0.167
6.15,0.41,0.167
6.18,0.63,0.167
6.20,0.84,0.167
6.22,1.06,0.167
6.24,1.28,0.167
6.26,1.50,0.167
6.28,1.71,0.168
6.30,1.93,0.168
6.33,2.15,0.168
6.35,2.36,0.168
6.37,2.58,0.168
6.39,2.80,0.168
6.41,3.01,0.168
6.44,3.23,0.168
6.46,3.45,0.168
6.48,3.66,0.168
6.50,3.88,0.168
6.52,4.10,0.168
6.54,4.31,0.168
6.56,4.53,0.169
6.59,4.75,0.169
6.61,4.97,0.169
6.63,5.18,0.169
6.65,5.40,0.169
6.67,5.62,0.169
6.70,5.83,0.169
6.72,6.05,0.169
6.74,6.27,0.169
6.76,6.48,0.169
6.78,6.70,0.169
6.80,6.92,0.170
6.83,7.13,0.170
6.85,7.35,0.170
6.87,7.57,0.170
6.89,7.79,0.170
6.91,8.00,0.170
6.93,8.22,0.170
6.95,8.44,0.170
6.98,8.65,0.170
7.00,8.87,0.170
7.02,9.09,0.170
7.04,9.30,0.171
7.06,9.52,0.171
7.09,9.74,0.171
7.11,9.95,0.171
7.13,10.17,0.171
7.15,10.39,0.171
7.17,10.60,0.171
7.19,10.82,0.171
7.21,11.04,0.171
7.24,11.25,0.171
7.26,11.47,0.171
7.28,11.69,0.172
7.30,11.90,0.172
7.32,12.12,0.172
7.35,12.34,0.172
7.37,12.56,0.172
7.39,12.77,0.172
7.41,12.99,0.172
7.43,13.21,0.172
7.45,13.42,0.173
7.48,13.64,0.173
7.50,13.86,0.173
7.52,14.07,0.173
7.54,14.29,0.173
7.56,14.51,0.173
7.58,14.72,0.173
7.60,14.94,0.173
7.63,15.16,0.174
7.65,15.38,0.174
7.67,15.59,0.174
7.69,15.81,0.174
7.71,16.03,0.174
7.74,16.24,0.174
7.76,16.46,0.174
7.78,16.68,0.175
7.80,16.89,0.175
7.82,17.11,0.175
7.84,17.33,0.175
7.86,17.55,0.175
7.89,17.76,0.175
7.91,17.98,0.176
7.93,18.20,0.176
7.95,18.41,0.176
7.97,18.63,0.176
8.00,18.85,0.176
8.02,19.06,0.176
8.04,19.28,0.176
8.06,19.50,0.177
8.08,19.71,0.177
8.10,19.93,0.177
8.13,20.15,0.177
8.15,20.36,0.177
8.17,20.58,0.177
8.19,20.80,0.178
8.21,21.01,0.178
8.23,21.23,0.178
8.25,21.45,0.178
8.28,21.66,0.178
8.30,21.88,0.178
8.32,22.10,0.178
8.34,22.31,0.179
8.36,22.53,0.179
8.39,22.75,0.179
8.41,22.97,0.179
8.43,23.18,0.179
8.45,23.40,0.180
8.47,23.62,0.180
8.49,23.83,0.180
8.51,24.05,0.180
8.54,24.26,0.180
8.56,24.48,0.181
8.58,24.70,0.181
8.60,24.92,0.181
8.62,25.13,0.181
8.65,25.35,0.181
8.67,25.57,0.181
8.69,25.78,0.182
8.71,26.00,0.182
8.73,26.22,0.182
8.75,26.43,0.182
8.78,26.65,0.182
8.80,26.87,0.183
8.82,27.08,0.183
8.84,27.30,0.183
8.86,27.52,0.183
8.88,27.73,0.184
8.90,27.95,0.184
8.93,28.17,0.184
8.95,28.38,0.184
8.97,28.60,0.184
8.99,28.82,0.185
9.01,29.04,0.185
9.03,29.25,0.185
9.06,29.47,0.185
9.08,29.69,0.185
9.10,29.90,0.186
9.12,30.12,0.186
9.14,30.34,0.186
9.17,30.55,0.186
9.19,30.77,0.187
9.21,30.99,0.187
9.23,31.20,0.187
9.25,31.42,0.187
9.27,31.64,0.188
9.30,31.86,0.188
9.32,32.07,0.188
9.34,32.29,0.188
9.36,32.51,0.189
9.38,32.72,0.189
9.40,32.94,0.189
9.43,33.16,0.189
9.45,33.37,0.190
9.47,33.59,0.190
9.49,33.81,0.190
9.51,34.02,0.190
9.53,34.24,0.191
9.55,34.46,0.191
9.58,34.67,0.191
9.60,34.89,0.191
9.62,35.11,0.192
9.64,35.32,0.192
9.66,35.54,0.192
9.68,35.76,0.193
9.71,35.97,0.193
9.73,36.19,0.193
9.75,36.41,0.193
9.77,36.63,0.194
9.79,36.84,0.194
9.82,37.06,0.194
9.84,37.28,0.194
9.86,37.49,0.195
9.88,37.71,0.195
9.90,37.93,0.195
9.92,38.14,0.196
9.95,38.36,0.196
9.97,38.58,0.196
9.99,38.79,0.197
10.01,39.01,0.197
10.03,39.23,0.197
10.05,39.44,0.197
10.08,39.66,0.198
10.10,39.88,0.198
10.12,40.10,0.198
10.14,40.31,0.199
10.16,40.53,0.199
10.18,40.75,0.199
10.20,40.96,0.200
10.23,41.18,0.200
10.25,41.40,0.200
10.27,41.61,0.200
10.29,41.83,0.201
10.31,42.05,0.201
10.33,42.26,0.201
10.36,42.48,0.202
10.38,42.70,0.202
10.40,42.91,0.203
10.42,43.13,0.203
10.44,43.35,0.203
10.47,43.56,0.204
10.49,43.78,0.204
10.51,44.00,0.204
10.53,44.21,0.205
10.55,44.43,0.205
10.57,44.65,0.205
10.60,44.86,0.206
10.62,45.08,0.206
10.64,45.30,0.206
10.66,45.52,0.207
10.68,45.73,0.207
10.70,45.95,0.207
10.73,46.17,0.208
10.75,46.38,0.208
10.77,46.60,0.209
10.79,46.82,0.209
10.81,47.03,0.209
10.83,47.25,0.210
10.85,47.47,0.210
10.88,47.68,0.210
10.90,47.90,0.211
10.92,48.12,0.211
10.94,48.34,0.212
10.96,48.55,0.212
10.98,48.77,0.212
11.01,48.99,0.213
11.03,49.20,0.213
11.05,49.42,0.213
11.07,49.63,0.214
11.09,49.85,0.214
11.12,50.07,0.214
11.14,50.29,0.215
11.16,50.50,0.215
11.18,50.72,0.216
11.20,50.94,0.216
11.22,51.15,0.216
11.25,51.37,0.217
11.27,51.59,0.217
11.29,51.80,0.217
11.31,52.02,0.218
11.33,52.24,0.218
11.35,52.45,0.219
11.38,52.67,0.219
11.40,52.89,0.219
11.42,53.10,0.220
11.44,53.32,0.220
11.46,53.54,0.221
11.48,53.75,0.221
11.50,53.97,0.221
11.53,54.19,0.222
11.55,54.41,0.222
11.57,54.62,0.223
11.59,54.84,0.223
11.61,55.05,0.223
11.63,55.27,0.224
11.66,55.49,0.224
11.68,55.71,0.225
11.70,55.92,0.225
11.72,56.14,0.225
11.74,56.36,0.226
11.77,56.57,0.226
11.79,56.79,0.227
11.81,57.01,0.227
11.83,57.22,0.227
11.85,57.44,0.228
11.87,57.66,0.228
11.90,57.87,0.229
11.92,58.09,0.229
11.94,58.31,0.229
11.96,58.52,0.230
11.98,58.74,0.230
12.00,58.96,0.230
12.03,59.17,0.231
12.05,59.39,0.231
12.07,59.61,0.232
12.09,59.82,0.232
12.11,60.04,0.232
12.13,60.26,0.233
12.15,60.48,0.233
12.18,60.69,0.234
12.20,60.91,0.234
12.22,61.13,0.234
12.24,61.34,0.235
12.26,61.56,0.235
12.28,61.78,0.235
12.31,61.99,0.236
12.33,62.21,0.236
12.35,62.43,0.237
12.37,62.64,0.237
12.39,62.86,0.237
12.42,63.08,0.238
12.44,63.29,0.238
12.46,63.51,0.239
12.48,63.73,0.239
12.50,63.94,0.239
12.52,64.16,0.240
12.55,64.38,0.240
12.57,64.59,0.241
12.59,64.81,0.241
12.61,65.03,0.241
12.63,65.25,0.242
12.65,65.46,0.242
12.68,65.68,0.243
12.70,65.90,0.243
12.72,66.11,0.243
12.74,66.33,0.244
12.76,66.55,0.244
12.78,66.76,0.244
12.80,66.98,0.245
12.83,67.20,0.245
12.85,67.41,0.245
12.87,67.63,0.246
12.89,67.85,0.246
12.91,68.06,0.246
12.93,68.28,0.247
12.96,68.50,0.247
12.98,68.71,0.248
13.00,68.93,0.248
13.02,69.15,0.248
13.04,69.36,0.249
13.07,69.58,0.249
13.09,69.80,0.249
13.11,70.01,0.250
13.13,70.23,0.250
13.15,70.45,0.250
13.17,70.67,0.250
13.20,70.88,0.251
13.22,71.10,0.251
13.24,71.32,0.251
13.26,71.53,0.252
13.28,71.75,0.252
13.30,71.97,0.252
13.33,72.18,0.253
13.35,72.40,0.253
13.37,72.62,0.253
13.39,72.84,0.254
13.41,73.05,0.254
13.43,73.27,0.254
13.45,73.49,0.254
13.48,73.70,0.255
13.50,73.92,0.255
13.52,74.14,0.255
13.54,74.35,0.255
13.56,74.57,0.256
13.58,74.79,0.256
13.61,75.00,0.256
13.63,75.22,0.257
13.65,75.44,0.257
13.67,75.65,0.257
13.69,75.87,0.257
13.72,76.09,0.258
13.74,76.30,0.258
13.76,76.52,0.258
13.78,76.74,0.258
13.80,76.95,0.259
13.82,77.17,0.259
13.85,77.39,0.259
13.87,77.61,0.259
13.89,77.82,0.259
13.91,78.04,0.260
13.93,78.25,0.260
13.95,78.47,0.260
13.98,78.69,0.260
14.00,78.90,0.260
14.02,79.12,0.261
14.04,79.34,0.261
14.06,79.55,0.261
14.08,79.77,0.261
14.10,79.99,0.261
14.13,80.20,0.261
14.15,80.42,0.262
14.17,80.64,0.262
14.19,80.85,0.262
14.21,81.07,0.262
14.23,81.29,0.262
14.26,81.51,0.262
14.28,81.72,0.263
14.30,81.94,0.263
14.32,82.16,0.263
14.34,82.37,0.263
14.37,82.59,0.263
14.39,82.81,0.263
14.41,83.03,0.263
14.43,83.24,0.263
14.45,83.46,0.263
14.47,83.67,0.264
14.50,83.89,0.264
14.52,84.11,0.264
14.54,84.33,0.264
14.56,84.54,0.264
14.58,84.76,0.264
14.60,84.98,0.264
14.63,85.19,0.264
14.65,85.41,0.264
14.67,85.63,0.264
14.69,85.84,0.264
14.71,86.06,0.264
14.73,86.28,0.264
14.75,86.49,0.264
14.78,86.71,0.264
14.80,86.93,0.264
14.82,87.15,0.264
14.84,87.36,0.264
14.86,87.58,0.264
14.88,87.80,0.264
14.91,88.01,0.264
14.93,88.23,0.264
14.95,88.45,0.264
14.97,88.66,0.264
14.99,88.88,0.264
15.02,89.10,0.264
15.04,89.31,0.264
15.06,89.53,0.264
15.08,89.75,0.264
15.10,89.97,0.264
15.12,90.18,0.264
15.15,90.40,0.264
15.17,90.61,0.264
15.19,90.83,0.264
15.21,91.05,0.264
15.23,91.27,0.264
15.25,91.48,0.264
15.28,91.70,0.264
15.30,91.92,0.264
15.32,92.13,0.264
15.34,92.35,0.264
15.36,92.57,0.264
15.38,92.78,0.264
15.40,93.00,0.264
15.43,93.22,0.264
15.45,93.44,0.264
15.47,93.65,0.263
15.49,93.87,0.263
15.51,94.08,0.263
15.53,94.30,0.263
15.56,94.52,0.263
15.58,94.73,0.263
15.60,94.95,0.263
15.62,95.17,0.263
15.64,95.39,0.263
15.67,95.60,0.263
15.69,95.82,0.263
15.71,96.04,0.262
15.73,96.25,0.262
15.75,96.47,0.262
15.77,96.69,0.262
15.80,96.91,0.262
15.82,97.12,0.262
15.84,97.34,0.262
15.86,97.56,0.262
15.88,97.77,0.261
15.90,97.99,0.261
15.93,98.21,0.261
15.95,98.42,0.261
15.97,98.64,0.261
15.99,98.86,0.261
16.01,99.07,0.261
16.03,99.29,0.260
16.05,99.51,0.260
16.08,99.73,0.260
16.10,99.94,0.260
16.12,100.16,0.260
16.14,100.38,0.260
16.16,100.59,0.260
16.18,100.81,0.259
16.21,101.03,0.259
16.23,101.24,0.259
16.25,101.46,0.259
16.27,101.68,0.259
16.29,101.90,0.258
16.32,102.11,0.258
16.34,102.33,0.258
16.36,102.55,0.258
16.38,102.76,0.258
16.40,102.98,0.257
16.42,103.20,0.257
16.45,103.41,0.257
16.47,103.63,0.257
16.49,103.85,0.257
16.51,104.06,0.256
16.53,104.28,0.256
16.55,104.50,0.256
16.58,104.71,0.256
16.60,104.93,0.256
16.62,105.15,0.255
16.64,105.36,0.255
16.66,105.58,0.255
16.68,105.80,0.255
16.70,106.02,0.255
16.73,106.23,0.254
16.75,106.45,0.254
16.77,106.67,0.254
16.79,106.88,0.254
16.81,107.10,0.254
16.83,107.32,0.253
16.86,107.53,0.253
16.88,107.75,0.253
16.90,107.97,0.253
16.92,108.19,0.252
16.94,108.40,0.252
16.97,108.62,0.252
16.99,108.84,0.252
17.01,109.05,0.252
17.03,109.27,0.251
17.05,109.49,0.251
17.07,109.70,0.251
17.09,109.92,0.251
17.12,110.14,0.251
17.14,110.35,0.250
17.16,110.57,0.250
17.18,110.79,0.250
17.20,111.01,0.250
17.23,111.22,0.249
17.25,111.44,0.249
17.27,111.66,0.249
17.29,111.87,0.249
17.31,112.09,0.248
17.33,112.31,0.248
17.36,112.52,0.248
17.38,112.74,0.248
17.40,112.96,0.248
17.42,113.17,0.247
17.44,113.39,0.247
17.46,113.61,0.247
17.48,113.83,0.247
17.51,114.04,0.246
17.53,114.26,0.246
17.55,114.48,0.246
17.57,114.69,0.246
17.59,114.91,0.245
17.62,115.13,0.245
17.64,115.34,0.245
17.66,115.56,0.245
17.68,115.78,0.245
17.70,115.99,0.244
17.72,116.21,0.244
17.74,116.43,0.244
17.77,116.65,0.244
17.79,116.86,0.244
17.81,117.08,0.244
17.83,117.30,0.243
17.85,117.51,0.243
17.88,117.73,0.243
17.90,117.95,0.243
17.92,118.16,0.242
17.94,118.38,0.242
17.96,118.60,0.242
17.98,118.81,0.242
18.01,119.03,0.241
18.03,119.25,0.241
18.05,119.46,0.241
18.07,119.68,0.241
18.09,119.90,0.241
18.11,120.12,0.240
18.13,120.33,0.240
18.16,120.55,0.240
18.18,120.77,0.240
18.20,120.98,0.240
18.22,121.20,0.239
18.24,121.42,0.239
18.27,121.63,0.239
18.29,121.85,0.239
18.31,122.07,0.239
18.33,122.28,0.239
18.35,122.50,0.238
18.37,122.72,0.238
18.39,122.94,0.238
18.42,123.15,0.238
18.44,123.37,0.238
18.46,123.58,0.237
18.48,123.80,0.237
18.50,124.02,0.237
18.53,124.24,0.237
18.55,124.45,0.236
18.57,124.67,0.236
18.59,124.89,0.236
18.61,125.11,0.236
18.63,125.32,0.236
18.66,125.54,0.236
18.68,125.76,0.236
18.70,125.97,0.235
18.72,126.19,0.235
18.74,126.41,0.235
18.76,126.62,0.235
18.78,126.84,0.235
18.81,127.06,0.234
18.83,127.27,0.234
18.85,127.49,0.234
18.87,127.71,0.234
18.89,127.92,0.234
18.92,128.14,0.234
18.94,128.36,0.233
18.96,128.57,0.233
18.98,128.79,0.233
19.00,129.01,0.233
19.02,129.22,0.233
19.04,129.44,0.233
19.07,129.66,0.233
19.09,129.87,0.232
19.11,130.09,0.232
19.13,130.31,0.232
19.15,130.52,0.232
19.18,130.74,0.232
19.20,130.96,0.232
19.22,131.18,0.232
19.24,131.39,0.231
19.26,131.61,0.231
19.28,131.83,0.231
19.31,132.04,0.231
19.33,132.26,0.231
19.35,132.48,0.231
19.37,132.69,0.231
19.39,132.91,0.231
19.41,133.13,0.230
19.43,133.34,0.230
19.46,133.56,0.230
19.48,133.78,0.230
19.50,133.99,0.230
19.52,134.21,0.230
19.54,134.43,0.230
19.57,134.65,0.230
19.59,134.86,0.230
19.61,135.08,0.230
19.63,135.30,0.230
19.65,135.51,0.229
19.67,135.73,0.229
19.69,135.95,0.229
19.72,136.16,0.229
19.74,136.38,0.229
19.76,136.60,0.229
19.78,136.81,0.229
19.80,137.03,0.229
19.83,137.25,0.228
19.85,137.47,0.228
19.87,137.68,0.228
19.89,137.90,0.228
19.91,138.12,0.228
19.93,138.34,0.228
19.96,138.55,0.228
19.98,138.77,0.228
20.00,138.99,0.228
20.02,139.20,0.228
20.04,139.42,0.228
20.06,139.64,0.228
20.08,139.85,0.227
20.11,140.07,0.227
20.13,140.29,0.227
20.15,140.50,0.227
20.17,140.72,0.227
20.19,140.94,0.227
20.22,141.15,0.227
20.24,141.37,0.227
20.26,141.59,0.227
20.28,141.80,0.226
20.30,142.02,0.226
20.32,142.24,0.226
20.34,142.45,0.226
20.37,142.67,0.226
20.39,142.89,0.226
20.41,143.11,0.226
20.43,143.32,0.226
20.45,143.54,0.226
20.48,143.76,0.226
20.50,143.97,0.226
20.52,144.19,0.226
20.54,144.41,0.225
20.56,144.62,0.225
20.58,144.84,0.225
20.61,145.06,0.225
20.63,145.28,0.225
20.65,145.49,0.225
20.67,145.71,0.225
20.69,145.93,0.225
20.71,146.14,0.225
20.73,146.36,0.225
20.76,146.58,0.225
20.78,146.79,0.224
20.80,147.01,0.224
20.82,147.23,0.224
20.84,147.44,0.224
20.87,147.66,0.224
20.89,147.88,0.224
20.91,148.09,0.224
20.93,148.31,0.224
20.95,148.53,0.224
20.97,148.74,0.224
20.99,148.96,0.224
21.02,149.18,0.224
21.04,149.39,0.224
21.06,149.61,0.224
21.08,149.83,0.224
21.10,150.05,0.224
21.13,150.26,0.223
21.15,150.48,0.223
21.17,150.69,0.223
21.19,150.91,0.223
21.21,151.13,0.223
21.23,151.35,0.223
21.26,151.56,0.223
21.28,151.78,0.223
21.30,152.00,0.223
21.32,152.21,0.223
21.34,152.43,0.223
21.36,152.65,0.223
21.38,152.86,0.223
21.41,153.08,0.223
21.43,153.30,0.223
21.45,153.51,0.223
21.47,153.73,0.223
21.49,153.95,0.223
21.52,154.16,0.223
21.54,154.38,0.223
21.56,154.60,0.223
21.58,154.81,0.223
21.60,155.03,0.222
21.62,155.25,0.222
21.64,155.47,0.223
21.67,155.68,0.223
21.69,155.90,0.223
21.71,156.12,0.223
21.73,156.33,0.223
21.75,156.55,0.222
21.78,156.77,0.222
21.80,156.98,0.222
21.82,157.20,0.222
21.84,157.42,0.222
21.86,157.63,0.222
21.88,157.85,0.222
21.91,158.07,0.222
21.93,158.28,0.222
21.95,158.50,0.222
21.97,158.72,0.222
21.99,158.94,0.222
22.01,159.15,0.222
22.03,159.37,0.222
22.06,159.59,0.222
22.08,159.80,0.222
22.10,160.02,0.222
22.12,160.24,0.222
22.14,160.45,0.222
22.17,160.67,0.222
22.19,160.89,0.221
22.21,161.10,0.221
22.23,161.32,0.221
22.25,161.54,0.221
22.27,161.75,0.221
22.29,161.97,0.221
22.32,162.19,0.221
22.34,162.41,0.221
22.36,162.62,0.221
22.38,162.84,0.221
22.40,163.06,0.221
22.43,163.27,0.221
22.45,163.49,0.221
22.47,163.71,0.221
22.49,163.92,0.221
22.51,164.14,0.221
22.53,164.36,0.221
22.56,164.57,0.221
22.58,164.79,0.221
22.60,165.01,0.221
22.62,165.22,0.221
22.64,165.44,0.221
22.66,165.66,0.221
22.68,165.87,0.221
22.71,166.09,0.221
22.73,166.31,0.221
22.75,166.52,0.221
22.77,166.74,0.221
22.79,166.96,0.221
22.82,167.17,0.221
22.84,167.39,0.221
22.86,167.61,0.221
22.88,167.82,0.221
22.90,168.04,0.221
22.92,168.26,0.221
22.94,168.48,0.221
22.97,168.69,0.221
22.99,168.91,0.221
23.01,169.13,0.221
23.03,169.34,0.221
23.05,169.56,0.221
23.08,169.78,0.220
23.10,170.00,0.220
23.12,170.21,0.220
23.14,170.43,0.220
23.16,170.65,0.220
23.18,170.86,0.220
23.21,171.08,0.220
23.23,171.30,0.220
23.25,171.51,0.220
23.27,171.73,0.220
23.29,171.95,0.220
23.31,172.16,0.220
23.33,172.38,0.220
23.36,172.60,0.220
23.38,172.81,0.220
23.40,173.03,0.220
23.42,173.25,0.220
23.44,173.46,0.220
23.47,173.68,0.220
23.49,173.90,0.220
23.51,174.12,0.220
23.53,174.33,0.220
23.55,174.55,0.220
23.57,174.77,0.220
23.59,174.98,0.220
23.62,175.20,0.220
23.64,175.42,0.220
23.66,175.63,0.220
23.68,175.85,0.220
23.70,176.07,0.220
23.73,176.28,0.220
23.75,176.50,0.220
23.77,176.72,0.220
23.79,176.93,0.220
23.81,177.15,0.220
23.83,177.37,0.220
23.86,177.58,0.220
23.88,177.80,0.220
23.90,178.02,0.220
23.92,178.23,0.220
23.94,178.45,0.220
23.96,178.67,0.220
23.98,178.88,0.219
24.01,179.10,0.219
24.03,179.32,0.219
24.05,179.53,0.219
24.07,179.75,0.219
24.09,179.97,0.219
24.12,180.19,0.219
24.14,180.40,0.219
24.16,180.62,0.219
24.18,180.84,0.219
24.20,181.05,0.219
24.22,181.27,0.219
24.24,181.49,0.219
24.27,181.70,0.219
24.29,181.92,0.219
24.31,182.14,0.219
24.33,182.36,0.219
24.35,182.57,0.219
24.38,182.79,0.219
24.40,183.01,0.219
24.42,183.22,0.219
24.44,183.44,0.219
24.46,183.65,0.219
24.48,183.87,0.219
24.51,184.09,0.219
24.53,184.30,0.219
24.55,184.52,0.219
24.57,184.74,0.219
24.59,184.95,0.219
24.61,185.17,0.219
24.63,185.39,0.219
24.66,185.61,0.219
24.68,185.82,0.219
24.70,186.04,0.219
24.72,186.26,0.219
24.74,186.47,0.219
24.77,186.69,0.219
24.79,186.91,0.219
24.81,187.12,0.219
24.83,187.34,0.219
24.85,187.56,0.219
24.87,187.77,0.219
24.89,187.99,0.219
24.92,188.21,0.219
24.94,188.42,0.219
24.96,188.64,0.219
24.98,188.86,0.219
25.00,189.07,0.219
25.03,189.29,0.219
25.05,189.51,0.219
25.07,189.72,0.219
25.09,189.94,0.219
25.11,190.16,0.219
25.13,190.38,0.219
25.16,190.59,0.219
25.18,190.81,0.219
25.20,191.03,0.219
25.22,191.24,0.219
25.24,191.46,0.219
25.26,191.68,0.219
25.28,191.89,0.219
25.31,192.11,0.219
25.33,192.33,0.219
25.35,192.54,0.219
25.37,192.76,0.219
25.39,192.98,0.219
25.42,193.19,0.219
25.44,193.41,0.219
25.46,193.63,0.219
25.48,193.84,0.219
25.50,194.06,0.219
25.52,194.28,0.218
25.54,194.49,0.218
25.57,194.71,0.218
25.59,194.93,0.218
25.61,195.15,0.218
25.63,195.36,0.218
25.65,195.58,0.218
25.68,195.80,0.218
25.70,196.01,0.218
25.72,196.23,0.218
25.74,196.45,0.218
25.76,196.66,0.218
25.78,196.88,0.218
25.81,197.10,0.218
25.83,197.31,0.218
25.85,197.53,0.218
25.87,197.75,0.218
25.89,197.97,0.218
25.91,198.18,0.218
25.93,198.40,0.218
25.96,198.61,0.218
25.98,198.83,0.218
26.00,199.05,0.218
26.02,199.26,0.218
26.04,199.48,0.218
26.07,199.70,0.218
26.09,199.92,0.218
26.11,200.13,0.218
26.13,200.35,0.218
26.15,200.57,0.218
26.17,200.78,0.218
26.19,201.00,0.218
26.22,201.22,0.218
26.24,201.44,0.218
26.26,201.65,0.218
26.28,201.87,0.218
26.30,202.08,0.218
26.33,202.30,0.218
26.35,202.52,0.218
26.37,202.73,0.218
26.39,202.95,0.218
26.41,203.17,0.218
26.43,203.38,0.218
26.46,203.60,0.218
26.48,203.82,0.218
26.50,204.04,0.218
26.52,204.25,0.218
26.54,204.47,0.218
26.56,204.69,0.218
26.58,204.90,0.218
26.61,205.12,0.218
26.63,205.34,0.218
26.65,205.55,0.218
26.67,205.77,0.218
26.69,205.99,0.218
26.72,206.20,0.218
26.74,206.42,0.218
26.76,206.64,0.218
26.78,206.85,0.218
26.80,207.07,0.218
26.82,207.29,0.218
26.84,207.50,0.218
26.87,207.72,0.218
26.89,207.94,0.218
26.91,208.15,0.218
26.93,208.37,0.218
26.95,208.59,0.218
26.98,208.80,0.218
27.00,209.02,0.218
27.02,209.24,0.218
27.04,209.45,0.218
27.06,209.67,0.218
27.08,209.89,0.218
27.11,210.10,0.218
27.13,210.32,0.218
27.15,210.54,0.218
27.17,210.76,0.218
27.19,210.97,0.218
27.21,211.19,0.218
27.23,211.41,0.218
27.26,211.62,0.218
27.28,211.84,0.218
27.30,212.06,0.218
27.32,212.27,0.218
27.34,212.49,0.218
27.37,212.71,0.218
27.39,212.93,0.218
27.41,213.14,0.218
27.43,213.36,0.218
27.45,213.57,0.218
27.47,213.79,0.218
27.49,214.01,0.217
27.52,214.23,0.217
27.54,214.44,0.217
27.56,214.66,0.217
27.58,214.88,0.217
27.60,215.09,0.217
27.63,215.31,0.217
27.65,215.53,0.217
27.67,215.74,0.217
27.69,215.96,0.218
27.71,216.18,0.218
27.73,216.39,0.217
27.76,216.61,0.217
27.78,216.83,0.217
27.80,217.05,0.218
27.82,217.26,0.218
27.84,217.48,0.217
27.86,217.70,0.217
27.88,217.91,0.217
27.91,218.13,0.217
27.93,218.34,0.217
27.95,218.56,0.217
27.97,218.78,0.217
27.99,219.00,0.218
28.02,219.21,0.218
28.04,219.43,0.218
28.06,219.65,0.218
28.08,219.86,0.218
28.10,220.08,0.218
28.12,220.30,0.218
28.14,220.51,0.218
28.17,220.73,0.218
28.19,220.95,0.218
28.21,221.16,0.218
28.23,221.38,0.218
28.25,221.60,0.217
28.28,221.81,0.217
28.30,222.03,0.217
28.32,222.25,0.217
28.34,222.46,0.218
28.36,222.68,0.218
28.38,222.90,0.218
28.41,223.11,0.218
28.43,223.33,0.218
28.45,223.55,0.218
28.47,223.77,0.218
28.49,223.98,0.218
28.51,224.20,0.218
28.53,224.42,0.218
28.56,224.63,0.218
28.58,224.85,0.218
28.60,225.07,0.218
28.62,225.28,0.218
28.64,225.50,0.218
28.67,225.72,0.218
28.69,225.93,0.218
28.71,226.15,0.218
28.73,226.37,0.218
28.75,226.58,0.218
28.77,226.80,0.218
28.79,227.02,0.218
28.82,227.23,0.218
28.84,227.45,0.218
28.86,227.67,0.218
28.88,227.88,0.218
28.90,228.10,0.218
28.93,228.32,0.218
28.95,228.53,0.218
28.97,228.75,0.218
28.99,228.97,0.218
29.01,229.19,0.218
29.03,229.40,0.218
29.06,229.62,0.218
29.08,229.84,0.218
29.10,230.05,0.218
29.12,230.27,0.218
29.14,230.49,0.218
29.16,230.70,0.218
29.18,230.92,0.218
29.21,231.14,0.218
29.23,231.35,0.218
29.25,231.57,0.218
29.27,231.79,0.218
29.29,232.00,0.218
29.32,232.22,0.218
29.34,232.44,0.218
29.36,232.65,0.219
29.38,232.87,0.220
29.40,233.09,0.221
29.42,233.30,0.221
29.44,233.52,0.221
29.47,233.74,0.221
29.49,233.95,0.221
29.51,234.17,0.221
29.53,234.39,0.221
29.55,234.61,0.221
29.58,234.82,0.221
29.60,235.04,0.221
29.62,235.26,0.221
29.64,235.47,0.221
29.66,235.69,0.221
29.68,235.91,0.221
29.71,236.12,0.221
29.73,236.34,0.221
29.75,236.55,0.221
29.77,236.77,0.220
29.79,236.99,0.220
29.81,237.21,0.220
29.83,237.42,0.220
29.86,237.64,0.220
29.88,237.86,0.221
29.90,238.07,0.221
29.92,238.29,0.221
29.94,238.51,0.221
29.97,238.72,0.221
29.99,238.94,0.221
30.01,239.16,0.223
30.03,239.37,0.223
30.05,239.59,0.223
30.07,239.81,0.223
30.09,240.02,0.223
30.12,240.24,0.223
30.14,240.46,0.223
30.16,240.68,0.223
30.18,240.89,0.222
30.20,241.11,0.222
30.23,241.33,0.222
30.25,241.54,0.222
30.27,241.76,0.222
30.29,241.98,0.222
30.31,242.19,0.222
30.33,242.41,0.222
30.36,242.63,0.222
30.38,242.84,0.222
30.40,243.06,0.222
30.42,243.28,0.222
30.44,243.49,0.222
30.46,243.71,0.222
30.48,243.93,0.222
30.51,244.15,0.222
30.53,244.36,0.222
30.55,244.58,0.222
30.57,244.80,0.222
30.59,245.01,0.222
30.62,245.23,0.222
30.64,245.45,0.222
30.66,245.66,0.222
30.68,245.88,0.222
30.70,246.10,0.222
30.72,246.31,0.222
30.74,246.53,0.222
30.77,246.75,0.222
30.79,246.96,0.222
30.81,247.18,0.222
30.83,247.39,0.222
30.85,247.61,0.222
30.88,247.83,0.222
30.90,248.05,0.222
30.92,248.26,0.222
30.94,248.48,
30.96,248.70,
30.98,248.91,
30.99,,

[step]
Ramp 10.00 °C/min to -60.00 °C
Time,Temperature,Heat Flow (Normalized)
min,°C,W/g
32.99,250.16,-0.025
33.02,250.16,-0.025
33.04,250.16,-0.025
33.06,250.14,-0.020
33.08,250.09,-0.016
33.10,250.00,-0.027
33.12,249.88,-0.068
33.14,249.73,-0.113
33.17,249.55,-0.158
33.19,249.36,-0.194
33.21,249.16,-0.220
33.23,248.95,-0.235
33.25,248.75,-0.246
33.28,248.53,-0.253
33.30,248.32,-0.255
33.32,248.11,-0.259
33.34,247.89,-0.259
33.36,247.68,-0.260
33.38,247.47,-0.261
33.41,247.25,-0.261
33.43,247.04,-0.261
33.45,246.82,-0.262
33.47,246.61,-0.262
33.49,246.39,-0.262
33.51,246.17,-0.263
33.53,245.96,-0.263
33.56,245.75,-0.263
33.58,245.53,-0.264
33.60,245.32,-0.264
33.62,245.10,-0.264
33.64,244.88,-0.264
33.67,244.67,-0.265
33.69,244.46,-0.265
33.71,244.24,-0.265
33.73,244.02,-0.265
33.75,243.81,-0.265
33.77,243.59,-0.266
33.79,243.38,-0.266
33.82,243.16,-0.266
33.84,242.94,-0.266
33.86,242.73,-0.266
33.88,242.51,-0.266
33.90,242.30,-0.266
33.93,242.08,-0.267
33.95,241.87,-0.267
33.97,241.65,-0.267
33.99,241.43,-0.267
34.01,241.22,-0.267
34.03,241.00,-0.267
34.06,240.79,-0.267
34.08,240.57,-0.267
34.10,240.36,-0.267
34.12,240.14,-0.267
34.14,239.92,-0.267
34.16,239.71,-0.267
34.19,239.49,-0.267
34.21,239.28,-0.267
34.23,239.06,-0.267
34.25,238.84,-0.267
34.27,238.63,-0.267
34.29,238.41,-0.267
34.31,238.20,-0.267
34.34,237.98,-0.267
34.36,237.76,-0.267
34.38,237.55,-0.267
34.40,237.33,-0.267
34.42,237.11,-0.267
34.44,236.90,-0.267
34.47,236.68,-0.267
34.49,236.47,-0.267
34.51,236.25,-0.267
34.53,236.03,-0.267
34.55,235.82,-0.267
34.58,235.60,-0.267
34.60,235.38,-0.267
34.62,235.17,-0.267
34.64,234.95,-0.267
34.66,234.73,-0.267
34.68,234.52,-0.267
34.71,234.30,-0.267
34.73,234.09,-0.267
34.75,233.87,-0.267
34.77,233.65,-0.267
34.79,233.44,-0.267
34.81,233.22,-0.267
34.84,233.01,-0.267
34.86,232.79,-0.267
34.88,232.57,-0.267
34.90,232.36,-0.267
34.92,232.14,-0.267
34.94,231.92,-0.267
34.96,231.71,-0.267
34.99,231.49,-0.267
35.01,231.27,-0.267
35.03,231.06,-0.267
35.05,230.84,-0.267
35.07,230.63,-0.267
35.09,230.41,-0.267
35.12,230.19,-0.267
35.14,229.98,-0.267
35.16,229.76,-0.267
35.18,229.54,-0.267
35.20,229.33,-0.267
35.23,229.11,-0.267
35.25,228.89,-0.267
35.27,228.68,-0.267
35.29,228.46,-0.267
35.31,228.24,-0.267
35.33,228.02,-0.267
35.36,227.81,-0.267
35.38,227.59,-0.267
35.40,227.37,-0.267
35.42,227.16,-0.267
35.44,226.94,-0.267
35.46,226.73,-0.267
35.49,226.51,-0.267
35.51,226.29,-0.267
35.53,226.08,-0.267
35.55,225.86,-0.267
35.57,225.64,-0.267
35.59,225.43,-0.266
35.61,225.21,-0.266
35.64,224.99,-0.266
35.66,224.78,-0.266
35.68,224.56,-0.266
35.70,224.34,-0.266
35.72,224.13,-0.266
35.74,223.91,-0.266
35.77,223.70,-0.266
35.79,223.48,-0.266
35.81,223.26,-0.266
35.83,223.05,-0.266
35.85,222.83,-0.266
35.88,222.61,-0.266
35.90,222.39,-0.266
35.92,222.18,-0.266
35.94,221.96,-0.266
35.96,221.75,-0.266
35.98,221.53,-0.266
36.01,221.31,-0.266
36.03,221.10,-0.266
36.05,220.88,-0.266
36.07,220.66,-0.266
36.09,220.45,-0.266
36.11,220.23,-0.266
36.14,220.01,-0.266
36.16,219.80,-0.266
36.18,219.58,-0.266
36.20,219.37,-0.266
36.22,219.15,-0.266
36.24,218.93,-0.266
36.26,218.72,-0.266
36.29,218.50,-0.266
36.31,218.28,-0.266
36.33,218.07,-0.266
36.35,217.85,-0.266
36.37,217.63,-0.266
36.39,217.42,-0.266
36.42,217.20,-0.266
36.44,216.98,-0.266
36.46,216.77,-0.266
36.48,216.55,-0.266
36.50,216.33,-0.266
36.53,216.12,-0.266
36.55,215.90,-0.266
36.57,215.68,-0.266
36.59,215.47,-0.266
36.61,215.25,-0.266
36.63,215.03,-0.266
36.66,214.81,-0.266
36.68,214.60,-0.266
36.70,214.38,-0.266
36.72,214.17,-0.266
36.74,213.95,-0.266
36.76,213.73,-0.265
36.79,213.52,-0.265
36.81,213.30,-0.265
36.83,213.09,-0.265
36.85,212.87,-0.265
36.87,212.65,-0.265
36.89,212.43,-0.265
36.91,212.22,-0.265
36.94,212.00,-0.265
36.96,211.78,-0.265
36.98,211.57,-0.265
37.00,211.35,-0.265
37.02,211.13,-0.265
37.04,210.92,-0.265
37.07,210.70,-0.265
37.09,210.48,-0.265
37.11,210.27,-0.265
37.13,210.05,-0.265
37.15,209.83,-0.265
37.18,209.62,-0.265
37.20,209.40,-0.265
37.22,209.18,-0.265
37.24,208.97,-0.265
37.26,208.75,-0.265
37.28,208.53,-0.265
37.31,208.32,-0.265
37.33,208.10,-0.265
37.35,207.88,-0.265
37.37,207.67,-0.265
37.39,207.45,-0.265
37.41,207.23,-0.265
37.44,207.02,-0.265
37.46,206.80,-0.265
37.48,206.58,-0.265
37.50,206.37,-0.265
37.52,206.15,-0.265
37.54,205.94,-0.265
37.56,205.72,-0.265
37.59,205.50,-0.265
37.61,205.29,-0.265
37.63,205.07,-0.265
37.65,204.85,-0.265
37.67,204.64,-0.265
37.69,204.42,-0.265
37.72,204.20,-0.265
37.74,203.99,-0.265
37.76,203.77,-0.265
37.78,203.55,-0.265
37.80,203.34,-0.265
37.83,203.12,-0.265
37.85,202.90,-0.265
37.87,202.69,-0.265
37.89,202.47,-0.265
37.91,202.25,-0.265
37.93,202.04,-0.265
37.96,201.82,-0.265
37.98,201.60,-0.265
38.00,201.39,-0.265
38.02,201.17,-0.265
38.04,200.95,-0.265
38.06,200.74,-0.265
38.09,200.52,-0.265
38.11,200.31,-0.265
38.13,200.09,-0.265
38.15,199.87,-0.265
38.17,199.66,-0.265
38.19,199.44,-0.264
38.21,199.22,-0.265
38.24,199.01,-0.265
38.26,198.79,-0.264
38.28,198.57,-0.264
38.30,198.36,-0.264
38.32,198.14,-0.264
38.34,197.92,-0.265
38.37,197.71,-0.265
38.39,197.49,-0.265
38.41,197.27,-0.265
38.43,197.06,-0.264
38.45,196.84,-0.264
38.48,196.62,-0.264
38.50,196.41,-0.264
38.52,196.19,-0.265
38.54,195.98,-0.264
38.56,195.76,-0.264
38.58,195.54,-0.265
38.61,195.33,-0.265
38.63,195.11,-0.265
38.65,194.89,-0.265
38.67,194.67,-0.265
38.69,194.46,-0.265
38.71,194.24,-0.265
38.74,194.02,-0.265
38.76,193.81,-0.265
38.78,193.59,-0.264
38.80,193.37,-0.264
38.82,193.16,-0.264
38.84,192.94,-0.264
38.86,192.72,-0.264
38.89,192.51,-0.264
38.91,192.29,-0.264
38.93,192.07,-0.264
38.95,191.86,-0.264
38.97,191.64,-0.264
38.99,191.42,-0.264
39.02,191.21,-0.264
39.04,190.99,-0.264
39.06,190.77,-0.264
39.08,190.56,-0.264
39.10,190.34,-0.264
39.13,190.13,-0.264
39.15,189.91,-0.264
39.17,189.69,-0.264
39.19,189.48,-0.264
39.21,189.26,-0.263
39.23,189.04,-0.263
39.26,188.83,-0.263
39.28,188.61,-0.263
39.30,188.39,-0.263
39.32,188.18,-0.263
39.34,187.96,-0.263
39.36,187.74,-0.263
39.39,187.53,-0.263
39.41,187.31,-0.263
39.43,187.09,-0.263
39.45,186.88,-0.263
39.47,186.66,-0.263
39.49,186.44,-0.263
39.51,186.22,-0.263
39.54,186.01,-0.263
39.56,185.79,-0.263
39.58,185.58,-0.263
39.60,185.36,-0.263
39.62,185.14,-0.263
39.64,184.93,-0.263
39.67,184.71,-0.263
39.69,184.49,-0.263
39.71,184.28,-0.263
39.73,184.06,-0.263
39.75,183.84,-0.263
39.78,183.63,-0.263
39.80,183.41,-0.263
39.82,183.19,-0.263
39.84,182.98,-0.263
39.86,182.76,-0.263
39.88,182.54,-0.263
39.91,182.33,-0.263
39.93,182.11,-0.263
39.95,181.89,-0.263
39.97,181.68,-0.263
39.99,181.46,-0.263
40.01,181.24,-0.263
40.04,181.03,-0.263
40.06,180.81,-0.263
40.08,180.60,-0.263
40.10,180.38,-0.263
40.12,180.16,-0.263
40.14,179.94,-0.263
40.16,179.73,-0.263
40.19,179.51,-0.263
40.21,179.29,-0.263
40.23,179.08,-0.263
40.25,178.86,-0.263
40.27,178.65,-0.263
40.29,178.43,-0.263
40.32,178.21,-0.262
40.34,178.00,-0.262
40.36,177.78,-0.262
40.38,177.56,-0.263
40.40,177.35,-0.262
40.43,177.13,-0.263
40.45,176.91,-0.263
40.47,176.70,-0.263
40.49,176.48,-0.262
40.51,176.26,-0.262
40.53,176.04,-0.262
40.56,175.83,-0.263
40.58,175.61,-0.262
40.60,175.40,-0.262
40.62,175.18,-0.262
40.64,174.96,-0.262
40.66,174.75,-0.262
40.69,174.53,-0.262
40.71,174.31,-0.262
40.73,174.10,-0.262
40.75,173.88,-0.262
40.77,173.66,-0.262
40.79,173.45,-0.262
40.81,173.23,-0.262
40.84,173.01,-0.262
40.86,172.80,-0.262
40.88,172.58,-0.262
40.90,172.36,-0.262
40.92,172.15,-0.262
40.94,171.93,-0.262
40.97,171.71,-0.262
40.99,171.50,-0.262
41.01,171.28,-0.262
41.03,171.07,-0.262
41.05,170.85,-0.262
41.08,170.63,-0.262
41.10,170.42,-0.262
41.12,170.20,-0.262
41.14,169.98,-0.262
41.16,169.77,-0.262
[...]
140.99,28.68,0.165
141.01,28.90,0.165
141.03,29.12,0.165
141.05,29.33,0.165
141.08,29.55,0.165
141.10,29.77,0.165
141.12,29.98,0.165
141.14,30.20,0.165
141.16,30.42,0.165
141.18,30.63,0.165
141.20,30.85,0.165
141.23,31.07,0.165
141.25,31.29,0.165
141.27,31.50,0.165
141.29,31.72,0.165
141.31,31.94,0.166
141.33,32.15,0.166
141.36,32.37,0.166
141.38,32.59,0.166
141.40,32.80,0.166
141.42,33.02,0.166
141.44,33.24,0.166
141.47,33.45,0.166
141.49,33.67,0.166
141.51,33.89,0.166
141.53,34.10,0.166
141.55,34.32,0.166
141.57,34.54,0.166
141.60,34.75,0.166
141.62,34.97,0.166
141.64,35.19,0.166
141.66,35.41,0.166
141.68,35.62,0.166
141.70,35.84,0.166
141.73,36.06,0.166
141.75,36.27,0.166
141.77,36.49,0.166
141.79,36.71,0.166
141.81,36.92,0.167
141.83,37.14,0.167
141.85,37.36,0.167
141.88,37.57,0.167
141.90,37.79,0.167
141.92,38.01,0.167
141.94,38.22,0.167
141.96,38.44,0.167
141.98,38.66,0.167
142.01,38.88,0.167
142.03,39.09,0.167
142.05,39.31,0.167
142.07,39.53,0.167
142.09,39.74,0.167
142.12,39.96,0.167
142.14,40.18,0.167
142.16,40.39,0.167
142.18,40.61,0.167
142.20,40.83,0.168
142.22,41.05,0.168
142.25,41.26,0.168
142.27,41.48,0.168
142.29,41.70,0.168
142.31,41.91,0.168
142.33,42.13,0.168
142.35,42.35,0.168
142.38,42.56,0.168
142.40,42.78,0.168
142.42,43.00,0.168
142.44,43.21,0.168
142.46,43.43,0.168
142.48,43.65,0.168
142.50,43.86,0.168
142.53,44.08,0.168
142.55,44.30,0.168
142.57,44.51,0.168
142.59,44.73,0.168
142.61,44.95,0.168
142.63,45.17,0.168
142.66,45.38,0.168
142.68,45.60,0.169
142.70,45.82,0.169
142.72,46.03,0.169
142.74,46.25,0.169
142.77,46.47,0.169
142.79,46.68,0.169
142.81,46.90,0.169
142.83,47.12,0.169
142.85,47.33,0.169
142.87,47.55,0.169
142.90,47.77,0.169
142.92,47.99,0.169
142.94,48.20,0.169
142.96,48.42,0.169
142.98,48.64,0.169
143.00,48.85,0.169
143.03,49.07,0.169
143.05,49.29,0.169
143.07,49.50,0.169
143.09,49.72,0.169
143.11,49.94,0.170
143.13,50.15,0.170
143.15,50.37,0.170
143.18,50.59,0.170
143.20,50.81,0.170
143.22,51.02,0.170
143.24,51.24,0.170
143.26,51.46,0.170
143.28,51.67,0.170
143.31,51.89,0.170
143.33,52.11,0.170
143.35,52.32,0.170
143.37,52.54,0.170
143.39,52.76,0.170
143.42,52.97,0.170
143.44,53.19,0.170
143.46,53.41,0.170
143.48,53.62,0.170
143.50,53.84,0.170
143.52,54.06,0.170
143.55,54.27,0.170
143.57,54.49,0.170
143.59,54.71,0.170
143.61,54.93,0.170
143.63,55.14,0.170
143.65,55.36,0.171
143.68,55.58,0.171
143.70,55.79,0.171
143.72,56.01,0.171
143.74,56.23,0.171
143.76,56.44,0.171
143.78,56.66,0.171
143.80,56.88,0.171
143.83,57.09,0.171
143.85,57.31,0.171
143.87,57.53,0.171
143.89,57.74,0.171
143.91,57.96,0.171
143.93,58.18,0.171
143.96,58.40,0.171
143.98,58.61,0.171
144.00,58.83,0.171
144.02,59.05,0.171
144.04,59.26,0.171
144.07,59.48,0.171
144.09,59.70,0.171
144.11,59.92,0.171
144.13,60.13,0.171
144.15,60.35,0.171
144.17,60.56,0.172
144.20,60.78,0.172
144.22,61.00,0.172
144.24,61.21,0.172
144.26,61.43,0.172
144.28,61.65,0.172
144.30,61.87,0.172
144.33,62.08,0.172
144.35,62.30,0.172
144.37,62.52,0.172
144.39,62.73,0.172
144.41,62.95,0.172
144.43,63.17,0.172
144.45,63.38,0.172
144.48,63.60,0.172
144.50,63.82,0.172
144.52,64.03,0.172
144.54,64.25,0.172
144.56,64.47,0.172
144.58,64.69,0.172
144.61,64.90,0.172
144.63,65.12,0.173
144.65,65.34,0.173
144.67,65.55,0.173
144.69,65.77,0.173
144.72,65.99,0.173
144.74,66.20,0.173
144.76,66.42,0.173
144.78,66.64,0.173
144.80,66.85,0.173
144.82,67.07,0.173
144.85,67.29,0.173
144.87,67.51,0.173
144.89,67.72,0.173
144.91,67.94,0.173
144.93,68.16,0.173
144.95,68.37,0.173
144.98,68.59,0.173
145.00,68.81,0.173
145.02,69.02,0.173
145.04,69.24,0.173
145.06,69.46,0.173
145.08,69.67,0.173
145.10,69.89,0.173
145.13,70.11,0.174
145.15,70.32,0.174
145.17,70.54,0.174
145.19,70.76,0.174
145.21,70.98,0.174
145.23,71.19,0.174
145.26,71.41,0.174
145.28,71.63,0.174
145.30,71.84,0.174
145.32,72.06,0.174
145.34,72.28,0.174
145.37,72.49,0.174
145.39,72.71,0.174
145.41,72.93,0.174
145.43,73.14,0.174
145.45,73.36,0.174
145.47,73.58,0.174
145.50,73.79,0.174
145.52,74.01,0.175
145.54,74.23,0.175
145.56,74.45,0.175
145.58,74.66,0.175
145.60,74.88,0.175
145.63,75.10,0.175
145.65,75.31,0.175
145.67,75.53,0.175
145.69,75.75,0.175
145.71,75.96,0.175
145.73,76.18,0.175
145.75,76.40,0.175
145.78,76.61,0.175
145.80,76.83,0.175
145.82,77.05,0.175
145.84,77.26,0.175
145.86,77.48,0.176
145.88,77.70,0.176
145.91,77.92,0.176
145.93,78.13,0.176
145.95,78.35,0.176
145.97,78.57,0.176
145.99,78.78,0.176
146.02,79.00,0.176
146.04,79.22,0.176
146.06,79.44,0.176
146.08,79.65,0.176
146.10,79.87,0.176
146.12,80.09,0.176
146.15,80.30,0.176
146.17,80.52,0.176
146.19,80.74,0.176
146.21,80.95,0.176
146.23,81.17,0.176
146.25,81.39,0.176
146.28,81.60,0.176
146.30,81.82,0.176
146.32,82.04,0.176
146.34,82.25,0.176
146.36,82.47,0.176
146.38,82.69,0.176
146.40,82.90,0.176
146.43,83.12,0.177
146.45,83.34,0.177
146.47,83.56,0.177
146.49,83.77,0.177
146.51,83.99,0.177
146.53,84.21,0.177
146.56,84.42,0.177
146.58,84.64,0.177
146.60,84.86,0.177
146.62,85.07,0.177
146.64,85.29,0.177
146.67,85.51,0.177
146.69,85.72,0.177
146.71,85.94,0.177
146.73,86.16,0.177
146.75,86.37,0.177
146.77,86.59,0.177
146.80,86.81,0.177
146.82,87.02,0.177
146.84,87.24,0.177
146.86,87.46,0.177
146.88,87.68,0.177
146.90,87.89,0.177
146.93,88.11,0.177
146.95,88.33,0.177
146.97,88.54,0.177
146.99,88.76,0.177
147.01,88.98,0.177
147.03,89.19,0.177
147.05,89.41,0.177
147.08,89.63,0.177
147.10,89.84,0.177
147.12,90.06,0.177
147.14,90.28,0.177
147.16,90.49,0.177
147.18,90.71,0.177
147.21,90.93,0.178
147.23,91.14,0.178
147.25,91.36,0.178
147.27,91.58,0.178
147.29,91.79,0.178
147.32,92.01,0.178
147.34,92.23,0.178
147.36,92.45,0.178
147.38,92.66,0.178
147.40,92.88,0.178
147.42,93.09,0.178
147.45,93.31,0.178
147.47,93.53,0.178
147.49,93.75,0.178
147.51,93.96,0.178
147.53,94.18,0.178
147.55,94.40,0.178
147.58,94.61,0.178
147.60,94.83,0.178
147.62,95.05,0.178
147.64,95.26,0.179
147.66,95.48,0.179
147.68,95.70,0.179
147.70,95.91,0.179
147.73,96.13,0.179
147.75,96.35,0.179
147.77,96.57,0.179
147.79,96.78,0.179
147.81,97.00,0.179
147.83,97.22,0.179
147.86,97.43,0.179
147.88,97.65,0.179
147.90,97.87,0.179
147.92,98.08,0.179
147.94,98.30,0.179
147.97,98.52,0.179
147.99,98.73,0.179
148.01,98.95,0.179
148.03,99.17,0.179
148.05,99.38,0.179
148.07,99.60,0.179
148.10,99.82,0.179
148.12,100.04,0.179
148.14,100.25,0.179
148.16,100.47,0.179
148.18,100.69,0.179
148.20,100.90,0.180
148.23,101.12,0.180
148.25,101.34,0.180
148.27,101.55,0.180
148.29,101.77,0.180
148.31,101.99,0.180
148.33,102.21,0.180
148.35,102.42,0.180
148.38,102.64,0.180
148.40,102.86,0.180
148.42,103.07,0.180
148.44,103.29,0.180
148.46,103.51,0.180
148.48,103.72,0.180
148.51,103.94,0.180
148.53,104.16,0.180
148.55,104.37,0.180
148.57,104.59,0.180
148.59,104.81,0.180
148.62,105.02,0.180
148.64,105.24,0.180
148.66,105.46,0.180
148.68,105.67,0.180
148.70,105.89,0.180
148.72,106.11,0.180
148.75,106.33,0.181
148.77,106.54,0.181
148.79,106.76,0.181
148.81,106.98,0.181
148.83,107.19,0.181
148.85,107.41,0.181
148.88,107.63,0.181
148.90,107.84,0.181
148.92,108.06,0.181
148.94,108.28,0.181
148.96,108.49,0.181
148.98,108.71,0.181
149.00,108.93,0.181
149.03,109.14,0.181
149.05,109.36,0.181
149.07,109.58,0.181
149.09,109.79,0.181
149.11,110.01,0.181
149.13,110.23,0.181
149.16,110.44,0.181
149.18,110.66,0.181
149.20,110.88,0.182
149.22,111.09,0.182
149.24,111.31,0.182
149.27,111.53,0.182
149.29,111.75,0.182
149.31,111.96,0.182
149.33,112.18,0.182
149.35,112.40,0.182
149.37,112.61,0.182
149.40,112.83,0.182
149.42,113.05,0.182
149.44,113.26,0.182
149.46,113.48,0.182
149.48,113.70,0.182
149.50,113.91,0.183
149.53,114.13,0.183
149.55,114.35,0.183
149.57,114.56,0.183
149.59,114.78,0.183
149.61,115.00,0.183
149.63,115.21,0.183
149.65,115.43,0.183
149.68,115.65,0.183
149.70,115.87,0.183
149.72,116.08,0.183
149.74,116.30,0.183
149.76,116.52,0.183
149.78,116.73,0.183
149.81,116.95,0.183
149.83,117.17,0.183
149.85,117.38,0.183
149.87,117.60,0.183
149.89,117.82,0.183
149.92,118.03,0.183
149.94,118.25,0.183
149.96,118.47,0.183
149.98,118.69,0.183
150.00,118.90,0.183
150.02,119.12,0.183
150.05,119.34,0.183
150.07,119.55,0.184
150.09,119.77,0.184
150.11,119.99,0.184
150.13,120.20,0.184
150.15,120.42,0.184
150.18,120.64,0.184
150.20,120.85,0.184
150.22,121.07,0.184
150.24,121.29,0.184
150.26,121.50,0.184
150.28,121.72,0.184
150.30,121.94,0.184
150.33,122.15,0.184
150.35,122.37,0.184
150.37,122.59,0.184
150.39,122.80,0.184
150.41,123.02,0.184
150.43,123.24,0.184
150.46,123.45,0.184
150.48,123.67,0.184
150.50,123.89,0.184
150.52,124.11,0.184
150.54,124.32,0.184
150.57,124.54,0.184
150.59,124.76,0.184
150.61,124.97,0.184
150.63,125.19,0.184
150.65,125.41,0.184
150.67,125.62,0.185
150.70,125.84,0.185
150.72,126.06,0.185
150.74,126.27,0.185
150.76,126.49,0.185
150.78,126.71,0.185
150.80,126.92,0.185
150.83,127.14,0.185
150.85,127.36,0.185
150.87,127.57,0.185
150.89,127.79,0.185
150.91,128.01,0.185
150.93,128.22,0.185
150.95,128.44,0.185
150.98,128.66,0.185
151.00,128.87,0.185
151.02,129.09,0.185
151.04,129.31,0.185
151.06,129.53,0.185
151.08,129.74,0.185
151.11,129.96,0.185
151.13,130.18,0.186
151.15,130.39,0.186
151.17,130.61,0.186
151.19,130.83,0.186
151.22,131.04,0.186
151.24,131.26,0.186
151.26,131.48,0.186
151.28,131.70,0.186
151.30,131.91,0.186
151.32,132.13,0.186
151.35,132.35,0.186
151.37,132.56,0.186
151.39,132.78,0.186
151.41,133.00,0.186
151.43,133.21,0.186
151.45,133.43,0.186
151.48,133.65,0.186
151.50,133.86,0.186
151.52,134.08,0.186
151.54,134.30,0.186
151.56,134.51,0.186
151.58,134.73,0.186
151.60,134.95,0.186
151.63,135.17,0.186
151.65,135.38,0.186
151.67,135.60,0.187
151.69,135.82,0.187
151.71,136.03,0.187
151.73,136.25,0.187
151.76,136.46,0.187
151.78,136.68,0.187
151.80,136.90,0.187
151.82,137.11,0.187
151.84,137.33,0.187
151.87,137.55,0.187
151.89,137.77,0.187
151.91,137.98,0.187
151.93,138.20,0.187
151.95,138.42,0.187
151.97,138.63,0.187
152.00,138.85,0.187
152.02,139.07,0.187
152.04,139.29,0.187
152.06,139.50,0.187
152.08,139.72,0.187
152.10,139.94,0.187
152.13,140.15,0.187
152.15,140.37,0.187
152.17,140.58,0.187
152.19,140.80,0.187
152.21,141.02,0.187
152.23,141.24,0.187
152.25,141.45,0.187
152.28,141.67,0.188
152.30,141.89,0.188
152.32,142.10,0.188
152.34,142.32,0.188
152.36,142.54,0.188
152.38,142.75,0.188
152.41,142.97,0.188
152.43,143.19,0.188
152.45,143.40,0.188
152.47,143.62,0.188
152.49,143.84,0.188
152.52,144.05,0.188
152.54,144.27,0.188
152.56,144.49,0.188
152.58,144.70,0.188
152.60,144.92,0.188
152.62,145.14,0.188
152.65,145.36,0.188
152.67,145.57,0.188
152.69,145.79,0.188
152.71,146.01,0.188
152.73,146.22,0.188
152.75,146.44,0.188
152.78,146.66,0.188
152.80,146.87,0.188
152.82,147.09,0.188
152.84,147.31,0.189
152.86,147.52,0.189
152.88,147.74,0.189
152.90,147.96,0.189
152.93,148.17,0.189
152.95,148.39,0.189
152.97,148.61,0.189
152.99,148.82,0.189
153.01,149.04,0.189
153.03,149.26,0.189
153.06,149.48,0.189
153.08,149.69,0.189
153.10,149.91,0.189
153.12,150.13,0.189
153.14,150.34,0.189
153.17,150.56,0.189
153.19,150.78,0.189
153.21,150.99,0.189
153.23,151.21,0.189
153.25,151.43,0.189
153.27,151.64,0.189
153.30,151.86,0.189
153.32,152.08,0.190
153.34,152.29,0.190
153.36,152.51,0.190
153.38,152.73,0.190
153.40,152.95,0.190
153.43,153.16,0.190
153.45,153.38,0.190
153.47,153.60,0.190
153.49,153.81,0.190
153.51,154.03,0.190
153.53,154.25,0.190
153.55,154.46,0.190
153.58,154.68,0.190
153.60,154.90,0.190
153.62,155.11,0.190
153.64,155.33,0.190
153.66,155.55,0.190
153.68,155.77,0.190
153.71,155.98,0.190
153.73,156.20,0.190
153.75,156.42,0.190
153.77,156.63,0.190
153.79,156.85,0.190
153.82,157.07,0.190
153.84,157.28,0.190
153.86,157.50,0.190
153.88,157.72,0.190
153.90,157.93,0.190
153.92,158.15,0.190
153.95,158.37,0.190
153.97,158.58,0.190
153.99,158.80,0.191
154.01,159.02,0.191
154.03,159.23,0.191
154.05,159.45,0.191
154.08,159.67,0.191
154.10,159.88,0.191
154.12,160.10,0.191
154.14,160.32,0.191
154.16,160.53,0.191
154.18,160.75,0.191
154.20,160.97,0.191
154.23,161.18,0.191
154.25,161.40,0.191
154.27,161.62,0.191
154.29,161.83,0.191
154.31,162.05,0.191
154.33,162.27,0.191
154.36,162.48,0.191
154.38,162.70,0.191
154.40,162.92,0.191
154.42,163.13,0.191
154.44,163.35,0.191
154.47,163.57,0.191
154.49,163.79,0.191
154.51,164.00,0.191
154.53,164.22,0.192
154.55,164.44,0.192
154.57,164.65,0.192
154.60,164.87,0.192
154.62,165.09,0.192
154.64,165.30,0.192
154.66,165.52,0.192
154.68,165.74,0.192
154.70,165.95,0.192
154.73,166.17,0.192
154.75,166.39,0.192
154.77,166.60,0.192
154.79,166.82,0.192
154.81,167.04,0.192
154.83,167.25,0.192
154.85,167.47,0.192
154.88,167.69,0.192
154.90,167.91,0.192
154.92,168.12,0.192
154.94,168.34,0.192
154.96,168.56,0.192
154.98,168.77,0.192
155.01,168.99,0.192
155.03,169.21,0.192
155.05,169.42,0.192
155.07,169.64,0.192
155.09,169.86,0.192
155.12,170.07,0.193
155.14,170.29,0.193
155.16,170.51,0.193
155.18,170.72,0.193
155.20,170.94,0.193
155.22,171.16,0.193
155.25,171.37,0.193
155.27,171.59,0.193
155.29,171.81,0.193
155.31,172.02,0.193
155.33,172.24,0.193
155.35,172.46,0.193
155.38,172.67,0.193
155.40,172.89,0.193
155.42,173.11,0.193
155.44,173.32,0.193
155.46,173.54,0.193
155.48,173.76,0.193
155.50,173.98,0.193
155.53,174.19,0.193
155.55,174.41,0.193
155.57,174.63,0.193
155.59,174.84,0.193
155.61,175.06,0.194
155.63,175.28,0.194
155.66,175.49,0.194
155.68,175.71,0.194
155.70,175.93,0.194
155.72,176.14,0.194
155.74,176.36,0.194
155.77,176.58,0.194
155.79,176.79,0.194
155.81,177.01,0.194
155.83,177.23,0.194
155.85,177.44,0.194
155.87,177.66,0.194
155.90,177.88,0.194
155.92,178.09,0.194
155.94,178.31,0.194
155.96,178.53,0.194
155.98,178.75,0.194
156.00,178.96,0.194
156.03,179.18,0.194
156.05,179.40,0.194
156.07,179.61,0.194
156.09,179.83,0.194
156.11,180.05,0.194
156.13,180.26,0.194
156.15,180.48,0.194
156.18,180.70,0.195
156.20,180.91,0.195
156.22,181.13,0.195
156.24,181.35,0.195
156.26,181.56,0.195
156.28,181.78,0.195
156.31,182.00,0.195
156.33,182.22,0.195
156.35,182.43,0.195
156.37,182.65,0.195
156.39,182.87,0.195
156.42,183.08,0.195
156.44,183.30,0.195
156.46,183.51,0.195
156.48,183.73,0.195
156.50,183.95,0.195
156.52,184.16,0.195
156.55,184.38,0.195
156.57,184.60,0.195
156.59,184.82,0.195
156.61,185.03,0.195
156.63,185.25,0.195
156.65,185.47,0.195
156.68,185.68,0.196
156.70,185.90,0.196
156.72,186.12,0.196
156.74,186.33,0.196
156.76,186.55,0.196
156.78,186.77,0.196
156.80,186.98,0.196
156.83,187.20,0.196
156.85,187.42,0.196
156.87,187.63,0.196
156.89,187.85,0.196
156.91,188.07,0.196
156.93,188.29,0.196
156.96,188.50,0.196
156.98,188.72,0.196
157.00,188.94,0.196
157.02,189.15,0.196
157.04,189.37,0.196
157.07,189.59,0.196
157.09,189.80,0.197
157.11,190.02,0.197
157.13,190.24,0.197
157.15,190.45,0.197
157.17,190.67,0.197
157.20,190.89,0.197
157.22,191.10,0.197
157.24,191.32,0.197
157.26,191.54,0.197
157.28,191.76,0.197
157.30,191.97,0.197
157.33,192.19,0.197
157.35,192.40,0.197
157.37,192.62,0.197
157.39,192.84,0.197
157.41,193.06,0.197
157.43,193.27,0.197
157.45,193.49,0.197
157.48,193.70,0.197
157.50,193.92,0.197
157.52,194.14,0.197
157.54,194.35,0.197
157.56,194.57,0.197
157.58,194.79,0.197
157.61,195.01,0.197
157.63,195.22,0.197
157.65,195.44,0.198
157.67,195.66,0.198
157.69,195.87,0.198
157.72,196.09,0.198
157.74,196.31,0.198
157.76,196.53,0.198
157.78,196.74,0.198
157.80,196.96,0.198
157.82,197.18,0.198
157.85,197.39,0.198
157.87,197.61,0.198
157.89,197.82,0.198
157.91,198.04,0.198
157.93,198.26,0.198
157.95,198.47,0.198
157.98,198.69,0.198
158.00,198.91,0.198
158.02,199.13,0.198
158.04,199.34,0.198
158.06,199.56,0.198
158.08,199.77,0.198
158.10,199.99,0.198
158.13,200.21,0.198
158.15,200.43,0.198
158.17,200.64,0.198
158.19,200.86,0.199
158.21,201.08,0.199
158.23,201.29,0.199
158.26,201.51,0.199
158.28,201.73,0.199
158.30,201.94,0.199
158.32,202.16,0.199
158.34,202.38,0.199
158.37,202.59,0.199
158.39,202.81,0.199
158.41,203.03,0.199
158.43,203.25,0.199
158.45,203.46,0.199
158.47,203.68,0.199
158.50,203.90,0.199
158.52,204.11,0.199
158.54,204.33,0.199
158.56,204.55,0.199
158.58,204.76,0.199
158.60,204.98,0.199
158.63,205.20,0.199
158.65,205.41,0.200
158.67,205.63,0.200
158.69,205.85,0.200
158.71,206.06,0.200
158.73,206.28,0.200
158.75,206.50,0.200
158.78,206.71,0.200
158.80,206.93,0.200
158.82,207.15,0.200
158.84,207.36,0.200
158.86,207.58,0.200
158.88,207.80,0.200
158.91,208.02,0.200
158.93,208.23,0.200
158.95,208.45,0.200
158.97,208.67,0.200
158.99,208.88,0.200
159.02,209.10,0.200
159.04,209.32,0.200
159.06,209.53,0.200
159.08,209.75,0.200
159.10,209.97,0.200
159.12,210.18,0.201
159.15,210.40,0.201
159.17,210.62,0.201
159.19,210.83,0.201
159.21,211.05,0.201
159.23,211.27,0.201
159.25,211.48,0.201
159.28,211.70,0.201
159.30,211.92,0.201
159.32,212.13,0.201
159.34,212.35,0.201
159.36,212.57,0.201
159.38,212.78,0.201
159.40,213.00,0.201
159.43,213.22,0.201
159.45,213.43,0.201
159.47,213.65,0.201
159.49,213.87,0.201
159.51,214.08,0.201
159.53,214.30,0.201
159.56,214.52,0.201
159.58,214.74,0.201
159.60,214.95,0.201
159.62,215.17,0.202
159.64,215.39,0.202
159.67,215.60,0.202
159.69,215.82,0.202
159.71,216.04,0.202
159.73,216.25,0.202
159.75,216.47,0.202
159.77,216.69,0.202
159.80,216.90,0.202
159.82,217.12,0.202
159.84,217.34,0.202
159.86,217.55,0.202
159.88,217.77,0.202
159.90,217.99,0.202
159.93,218.20,0.202
159.95,218.42,0.202
159.97,218.64,0.202
159.99,218.86,0.202
160.01,219.07,0.202
160.03,219.29,0.202
160.05,219.51,0.202
160.08,219.72,0.202
160.10,219.94,0.202
160.12,220.16,0.203
160.14,220.37,0.203
160.16,220.59,0.203
160.18,220.81,0.203
160.21,221.02,0.203
160.23,221.24,0.203
160.25,221.46,0.203
160.27,221.67,0.203
160.29,221.89,0.203
160.32,222.11,0.203
160.34,222.32,0.203
160.36,222.54,0.203
160.38,222.76,0.203
160.40,222.97,0.203
160.42,223.19,0.204
160.45,223.41,0.204
160.47,223.62,0.204
160.49,223.84,0.204
160.51,224.06,0.204
160.53,224.27,0.204
160.55,224.49,0.204
160.58,224.71,0.204
160.60,224.92,0.204
160.62,225.14,0.204
160.64,225.36,0.204
160.66,225.57,0.204
160.68,225.79,0.204
160.70,226.01,0.204
160.73,226.23,0.204
160.75,226.44,0.204
160.77,226.66,0.204
160.79,226.88,0.204
160.81,227.09,0.204
160.83,227.31,0.204
160.86,227.53,0.204
160.88,227.74,0.204
160.90,227.96,0.205
160.92,228.18,0.205
160.94,228.39,0.205
160.97,228.61,0.205
160.99,228.83,0.205
161.01,229.04,0.205
161.03,229.26,0.205
161.05,229.48,0.205
161.07,229.69,0.205
161.10,229.91,0.205
161.12,230.13,0.205
161.14,230.35,0.205
161.16,230.56,0.205
161.18,230.78,0.205
161.20,231.00,0.205
161.23,231.21,0.205
161.25,231.43,0.205
161.27,231.65,0.205
161.29,231.86,0.205
161.31,232.08,0.206
161.33,232.30,0.206
161.35,232.51,0.206
161.38,232.73,0.206
161.40,232.95,0.206
161.42,233.16,0.206
161.44,233.38,0.206
161.46,233.60,0.206
161.48,233.81,0.206
161.51,234.03,0.206
161.53,234.25,0.206
161.55,234.46,0.206
161.57,234.68,0.206
161.59,234.90,0.206
161.62,235.12,0.206
161.64,235.33,0.206
161.66,235.55,0.206
161.68,235.77,0.206
161.70,235.98,0.207
161.72,236.20,0.207
161.75,236.41,0.207
161.77,236.63,0.207
161.79,236.85,0.207
161.81,237.06,0.207
161.83,237.28,0.207
161.85,237.50,0.207
161.88,237.72,0.207
161.90,237.93,0.207
161.92,238.15,0.207
161.94,238.37,0.207
161.96,238.58,0.207
161.98,238.80,0.207
162.00,239.02,0.207
162.03,239.23,0.207
162.05,239.45,0.207
162.07,239.67,0.207
162.09,239.88,0.208
162.11,240.10,0.208
162.13,240.32,0.208
162.16,240.53,0.208
162.18,240.75,0.208
162.20,240.97,0.208
162.22,241.18,0.208
162.24,241.40,0.208
162.27,241.62,0.208
162.29,241.83,0.208
162.31,242.05,0.208
162.33,242.27,0.208
162.35,242.48,0.208
162.37,242.70,0.208
162.40,242.92,0.208
162.42,243.13,0.208
162.44,243.35,0.208
162.46,243.57,0.208
162.48,243.78,0.208
162.50,244.00,0.208
162.53,244.22,0.208
162.55,244.44,0.209
162.57,244.65,0.209
162.59,244.87,0.209
162.61,245.09,0.209
162.63,245.30,0.209
162.65,245.52,0.209
162.68,245.74,0.209
162.70,245.95,0.209
162.72,246.17,0.209
162.74,246.39,0.209
162.76,246.60,0.209
162.78,246.82,0.209
162.81,247.04,0.209
162.83,247.25,0.209
162.85,247.47,0.209
162.87,247.69,0.209
162.89,247.90,0.209
162.92,248.12,0.210
162.94,248.34,0.210
162.96,248.55,
162.98,248.77,
163.00,,