File: DSC/Olivia/2025_07_20_Indium_Std_TS_Al_PanLid_100C_200C_10Cmin_x3.csv
Filename,2025_07_20_Indium_Std_TS_Al_PanLid_100C_200C_10Cmin_x3
Instrument name,DSC2A-00468 (192.168.1.100)
Operator,Yarger
rundate,7/20/2025
Sample name,2025_07_20_Indium_Std_TS_Al_PanLid_100C_200C_10Cmin_x3
proceduresegments,Data Off ; Equilibrate 100.00 °C; Data On ; Ramp 10.00 °C/min to 200.00 °C; Data Off ; Isothermal 2.0 min; Data On ; Ramp 10.00 °C/min to 100.00 °C; Data Off ; Isothermal 2.0 min; Data On ; Ramp 10.00 °C/min to 200.00 °C; Data Off ; Isothermal 2.0 min; Data On ; Ramp 10.00 °C/min to 100.00 °C; Data Off ; Isothermal 2.0 min; Data On ; Ramp 10.00 °C/min to 200.00 °C
[File Parameters]
Run date,7/20/2025 9:40:30 PM
Trios version,5.1.1.46572
Original File Name,
Current File Name,D:\DSC2500\Gibbons\2025_07_20_Indium_Std_TS_Al_PanLid_100C_200C_10Cmin_x3.tri
[Procedure]
Procedure Name,Indium_100C_200C_10Cmin_x3
Sample Name,2025_07_20_Indium_Std_TS_Al_PanLid_100C_200C_10Cmin_x3
Sample Mass,5.37 mg
Reference Sample Mass,0 mg
Pan Mass,32.8 mg
Pan Number,39
Reference Pan Mass,32.52 mg
Reference Pan Number,37
Pan Type,Aluminum
Comments,Thermal support Al pans/lids. DSC_Samples_A2_Tray_July2025 google sheet.
Project Name,Pharma - Cocrystals
Operator,Yarger
Test,Custom
Unload Max Temperature,30
Unload Min Temperature,30
Load Max Temperature,30
Load Min Temperature,30
Stop on Gas Flow Error,Yes
[Signal List]
Signal #1,Time (min)
Signal #2,Temperature (°C)
Signal #3,Heat Flow (mW)
Signal #4,Delta T (µV)
Signal #5,Delta Tzero (µV)
Signal #6,Tzero Temperature (°C)
Signal #7,Cell Purge (mL/min)
Signal #8,Heater Temp (°C)
Signal #9,Power Delivered (W)
Signal #10,Reference Junction Temperature (°C)
Signal #11,Flange Temperature (°C)
Signal #12,Heat Flow Phase (rad)
Signal #13,Total Heat Capacity (J/°C)
Signal #14,Heat Capacity (J/°C)
[Configuration]
Company Name,ASU
Instrument Name,DSC2A-00468
Instrument Type,DSC2500
Serial Number,DSC2A-00468
IP,192.168.1.100
Location of Instrument,MRRC
DisplayType,Unknown
Sample Interval ,0.1 s/pt
Selected Heat Flow,T4P
Exotherm Direction,Down
Cell Serial,DRC2-00792
Lid Type,Standard
Cooler,RCS 90
Leave Cooler on at End of Sequence,On
Gas 2,Nitrogen
Gas Selected,Channel 1
Flow Rate,50 mL/min
Secondary Purge,On
Licensed Heat Flow,Heat Flow T4P
Modulation Licensed,Yes
[Versions]
Common IDD Version,1
Cortex Version,VER 2.10.2.31
Driver,5.0.0.6
GDM Version,1.0.3.3
TouchscreenVersion,1.0.0.16145
FEP Version,1.2.1.21
FEP Bootloader,2.0.0.5
AutoSampler Version,2.1.1.26
Auto Sampler Bootloader,2.0.0.5
FCM Version,1.1.0.3
FCM Bootloader,2.0.0.5
[Experiment Logs]
Experiment Log Entry # 1,Data On set to 0
Experiment Log Entry # 3,Equilibrate Segment 100 (C) Started
Experiment Log Entry # 5,Air Cool is off.
Experiment Log Entry # 7,Data On set to 1
Experiment Log Entry # 9,Ramp Segment 10 C/min to 200 Started
Experiment Log Entry # 11,Data On set to 0
Experiment Log Entry # 13,Isothermal Segment 2 min started
Experiment Log Entry # 15,Data On set to 1
Experiment Log Entry # 17,Ramp Segment 10 C/min to 100 Started
Experiment Log Entry # 19,Data On set to 0
Experiment Log Entry # 21,Isothermal Segment 2 min started
Experiment Log Entry # 23,Data On set to 1
Experiment Log Entry # 25,Ramp Segment 10 C/min to 200 Started
Experiment Log Entry # 27,Data On set to 0
Experiment Log Entry # 29,Isothermal Segment 2 min started
Experiment Log Entry # 31,Data On set to 1
Experiment Log Entry # 33,Ramp Segment 10 C/min to 100 Started
Experiment Log Entry # 35,Data On set to 0
Experiment Log Entry # 37,Isothermal Segment 2 min started
Experiment Log Entry # 39,Data On set to 1
Experiment Log Entry # 41,Ramp Segment 10 C/min to 200 Started
[Method Log]
Method Log Entry # 1,Data Off
Method Log Entry # 2,Equilibrate 100 °C
Method Log Entry # 3,Data On
Method Log Entry # 4,(Ramp 43966) Ramp 10 °C/minute to 200 °C
Method Log Entry # 5,Data Off
Method Log Entry # 6,Isothermal 2 minutes
Method Log Entry # 7,Data On
Method Log Entry # 8,(Ramp 43970) Ramp 10 °C/minute to 100 °C
Method Log Entry # 9,Data Off
Method Log Entry # 10,Isothermal 2 minutes
Method Log Entry # 11,Data On
Method Log Entry # 12,(Ramp 43974) Ramp 10 °C/minute to 200 °C
Method Log Entry # 13,Data Off
Method Log Entry # 14,Isothermal 2 minutes
Method Log Entry # 15,Data On
Method Log Entry # 16,(Ramp 43978) Ramp 10 °C/minute to 100 °C
Method Log Entry # 17,Data Off
Method Log Entry # 18,Isothermal 2 minutes
Method Log Entry # 19,Data On
Method Log Entry # 20,(Ramp 43982) Ramp 10 °C/minute to 200 °C
Cell Serial,DRC2-00792
[T1 Calibration]
Slope,-0.008529666
Offset,9.636258
Initial Temperature,98.23
GUID,f8bfdadc-4977-4fdf-ba6d-0ba9134940c3
[TZero Calibration]
Date Applied,11/29/2022 4:06:13 PM
Description,From -89.059 °C to 396.009 °C at 20.000°C/min
Gas Type,Nitrogen
Pan Type,None
Source Files 1,C:\Users\yargerlab\Desktop\DSC Data\General\TZero_calibration_11_29_22_2nd(2).tri
Source Files 2,C:\Users\yargerlab\Desktop\DSC Data\General\TZero_calibration_11_29_22_2nd(3).tri
Delta T Offset,13.05235
Delta T Slope,-0.007271007
Delta T0 Offset,-13.69128
Delta T0 Slope,0.06063341
[Temperature Calibration]
Date Applied,11/29/2022 7:12:28 PM
Description,From 106.590 °C to 186.590 °C at 10.000°C/min
Gas Type,Nitrogen
Pan Type,Tzero Aluminum Hermetic
Source Files 1,C:\Users\yargerlab\Desktop\DSC Data\General\Indium(6).tri
Measured 1,157.391
Known 1,156.598
[Cell Constant Calibration]
Date Applied,11/29/2022 7:12:29 PM
Description,From 106.590 °C to 186.590 °C at 10.000°C/min
Gas Type,Nitrogen
Pan Type,Tzero Aluminum Hermetic
Source Files 1,C:\Users\yargerlab\Desktop\DSC Data\General\Indium(6).tri
T4P KCell,1.006051
Onset Slope,63.26126 mW/°C
[Direct Cp Calibration]
Date Applied,11/30/2022 11:04:51 AM
Description,From -79.983 °C to 298.409 °C at 10.000°C/min
Gas Type,Nitrogen
Pan Type,Tzero Aluminum Hermetic
Source Files 1,C:\Users\yargerlab\Desktop\DSC Data\General\Sapphire_Heat_Capacity_11_30_22.tri
[Rev Cp Calibration]
Date Applied,11/30/2022 1:58:51 PM
Description,From -79.996 °C to 292.812 °C at 3.000°C/min
Gas Type,Nitrogen
Pan Type,Tzero Aluminum Hermetic
Source Files 1,C:\Users\yargerlab\Desktop\DSC Data\General\Sapphire_MDSC_Calibration_11_30_22.tri
[step]
Ramp 10.00 °C/min to 200.00 °C
Time,Temperature,Heat Flow (Normalized)
min,°C,W/g
0.00,100.16,-0.018
0.01,100.16,-0.018
0.01,100.16,-0.019
0.02,100.16,-0.020
0.03,100.16,-0.020
0.03,100.16,-0.021
0.04,100.17,-0.023
0.05,100.17,-0.027
0.05,100.18,-0.033
0.06,100.19,-0.042
0.07,100.20,-0.050
0.07,100.22,-0.059
0.08,100.24,-0.069
0.09,100.26,-0.078
0.09,100.29,-0.086
0.10,100.32,-0.094
0.11,100.35,-0.100
0.11,100.39,-0.104
0.12,100.43,-0.107
0.13,100.48,-0.108
0.13,100.52,-0.108
0.14,100.57,-0.106
0.15,100.62,-0.103
0.15,100.68,-0.099
0.16,100.73,-0.095
0.17,100.79,-0.088
0.17,100.85,-0.081
0.18,100.90,-0.073
0.19,100.96,-0.066
0.19,101.02,-0.060
0.20,101.08,-0.053
0.21,101.15,-0.047
0.21,101.21,-0.042
0.22,101.27,-0.036
0.23,101.33,-0.031
0.23,101.39,-0.027
0.24,101.46,-0.023
0.25,101.52,-0.020
0.25,101.58,-0.016
0.26,101.65,-0.014
0.27,101.71,-0.011
0.27,101.77,-0.008
0.28,101.84,-0.007
0.29,101.90,-0.005
0.29,101.97,-0.003
0.30,102.03,-0.001
0.31,102.10,0.000
0.31,102.16,0.001
0.32,102.23,0.002
0.33,102.29,0.003
0.33,102.36,0.004
0.34,102.42,0.005
0.35,102.49,0.006
0.35,102.55,0.006
0.36,102.62,0.007
0.37,102.68,0.008
0.37,102.75,0.008
0.38,102.81,0.009
0.39,102.88,0.010
0.39,102.94,0.010
0.40,103.01,0.011
0.41,103.08,0.011
0.41,103.14,0.011
0.42,103.21,0.012
0.43,103.28,0.012
0.43,103.34,0.013
0.44,103.41,0.013
0.45,103.47,0.013
0.45,103.54,0.013
0.46,103.61,0.014
0.47,103.67,0.014
0.47,103.74,0.014
0.48,103.80,0.014
0.49,103.87,0.014
0.49,103.94,0.014
0.50,104.00,0.015
0.51,104.07,0.015
0.51,104.13,0.015
0.52,104.20,0.015
0.53,104.27,0.015
0.53,104.33,0.015
0.54,104.40,0.016
0.55,104.46,0.016
0.55,104.53,0.016
0.56,104.60,0.016
0.57,104.66,0.016
0.57,104.73,0.016
0.58,104.80,0.016
0.59,104.86,0.016
0.59,104.93,0.017
0.60,105.00,0.017
0.61,105.06,0.017
0.61,105.13,0.017
0.62,105.19,0.017
0.63,105.26,0.017
0.63,105.33,0.017
0.64,105.39,0.017
0.65,105.46,0.017
0.65,105.53,0.018
0.66,105.59,0.018
0.67,105.66,0.018
0.67,105.72,0.018
0.68,105.79,0.018
0.69,105.86,0.018
0.69,105.92,0.018
0.70,105.99,0.018
0.71,106.06,0.018
0.71,106.12,0.018
0.72,106.19,0.019
0.73,106.26,0.019
0.73,106.32,0.019
0.74,106.39,0.019
0.75,106.45,0.019
0.75,106.52,0.019
0.76,106.59,0.019
0.77,106.65,0.019
0.77,106.72,0.019
0.78,106.79,0.019
0.79,106.85,0.019
0.79,106.92,0.020
0.80,106.98,0.020
0.81,107.05,0.020
0.81,107.12,0.020
0.82,107.18,0.020
0.83,107.25,0.020
0.83,107.32,0.020
0.84,107.38,0.020
0.85,107.45,0.020
0.85,107.52,0.020
0.86,107.58,0.020
0.87,107.65,0.020
0.87,107.72,0.020
0.88,107.78,0.020
0.89,107.85,0.020
0.89,107.91,0.021
0.90,107.98,0.021
0.91,108.05,0.021
0.91,108.11,0.021
0.92,108.18,0.021
0.93,108.25,0.021
0.93,108.31,0.021
0.94,108.38,0.021
0.95,108.45,0.021
0.95,108.51,0.021
0.96,108.58,0.021
0.97,108.65,0.021
0.97,108.71,0.021
0.98,108.78,0.021
0.99,108.85,0.021
0.99,108.91,0.021
1.00,108.98,0.022
1.01,109.05,0.022
1.01,109.11,0.022
1.02,109.18,0.022
1.03,109.25,0.022
1.03,109.31,0.022
1.04,109.38,0.022
1.05,109.45,0.022
1.05,109.51,0.022
1.06,109.58,0.022
1.07,109.65,0.022
1.07,109.71,0.022
1.08,109.78,0.022
1.09,109.85,0.022
1.09,109.91,0.022
1.10,109.98,0.022
1.11,110.05,0.022
1.11,110.11,0.022
1.12,110.18,0.022
1.13,110.25,0.022
1.13,110.31,0.022
1.14,110.38,0.023
1.15,110.44,0.023
1.15,110.51,0.023
1.16,110.58,0.023
1.17,110.64,0.023
1.17,110.71,0.023
1.18,110.78,0.023
1.19,110.84,0.023
1.19,110.91,0.023
1.20,110.98,0.023
1.21,111.04,0.023
1.21,111.11,0.023
1.22,111.18,0.023
1.23,111.24,0.023
1.23,111.31,0.023
1.24,111.38,0.023
1.25,111.44,0.023
1.25,111.51,0.023
1.26,111.58,0.023
1.27,111.64,0.023
1.27,111.71,0.023
1.28,111.78,0.023
1.29,111.84,0.023
1.29,111.91,0.023
1.30,111.98,0.023
1.31,112.04,0.023
1.31,112.11,0.023
1.32,112.18,0.023
1.33,112.24,0.023
1.33,112.31,0.023
1.34,112.38,0.024
1.35,112.44,0.024
1.35,112.51,0.024
1.36,112.58,0.024
1.37,112.64,0.024
1.37,112.71,0.024
1.38,112.78,0.024
1.39,112.84,0.024
1.39,112.91,0.024
1.40,112.98,0.024
1.41,113.04,0.024
1.41,113.11,0.024
1.42,113.18,0.024
1.43,113.24,0.024
1.43,113.31,0.024
1.44,113.38,0.024
1.45,113.44,0.024
1.45,113.51,0.024
1.46,113.58,0.024
1.47,113.64,0.024
1.47,113.71,0.024
1.48,113.78,0.024
1.49,113.84,0.024
1.49,113.91,0.024
1.50,113.98,0.024
1.51,114.04,0.024
1.51,114.11,0.024
1.52,114.18,0.024
1.53,114.24,0.024
1.53,114.31,0.024
1.54,114.38,0.024
1.55,114.44,0.024
1.55,114.51,0.024
1.56,114.58,0.024
1.57,114.64,0.024
1.57,114.71,0.024
1.58,114.78,0.024
1.59,114.84,0.024
1.59,114.91,0.024
1.60,114.98,0.024
1.61,115.04,0.024
1.61,115.11,0.024
1.62,115.18,0.024
1.63,115.24,0.024
1.63,115.31,0.024
1.64,115.38,0.024
1.65,115.44,0.024
1.65,115.51,0.024
1.66,115.58,0.024
1.67,115.64,0.024
1.67,115.71,0.024
1.68,115.78,0.024
1.69,115.85,0.024
1.69,115.91,0.024
1.70,115.98,0.024
1.71,116.04,0.024
1.71,116.11,0.024
1.72,116.18,0.024
1.73,116.24,0.024
1.73,116.31,0.024
1.74,116.38,0.024
1.75,116.44,0.024
1.75,116.51,0.024
1.76,116.58,0.024
1.77,116.65,0.024
1.77,116.71,0.024
1.78,116.78,0.025
1.79,116.84,0.025
1.79,116.91,0.024
1.80,116.98,0.025
1.81,117.04,0.025
1.81,117.11,0.025
1.82,117.18,0.025
1.83,117.24,0.025
1.83,117.31,0.025
1.84,117.38,0.025
1.85,117.44,0.025
1.85,117.51,0.025
1.86,117.58,0.025
1.87,117.65,0.025
1.87,117.71,0.025
1.88,117.78,0.025
1.89,117.84,0.025
1.89,117.91,0.025
1.90,117.98,0.025
1.91,118.05,0.025
1.91,118.11,0.025
1.92,118.18,0.025
1.93,118.25,0.025
1.93,118.31,0.025
1.94,118.38,0.025
1.95,118.45,0.025
1.95,118.51,0.025
1.96,118.58,0.025
1.97,118.65,0.025
1.97,118.71,0.025
1.98,118.78,0.025
1.99,118.84,0.025
1.99,118.91,0.025
2.00,118.98,0.025
2.01,119.05,0.025
2.01,119.11,0.025
2.02,119.18,0.025
2.03,119.25,0.025
2.03,119.31,0.025
2.04,119.38,0.025
2.05,119.45,0.025
2.05,119.51,0.025
2.06,119.58,0.025
2.07,119.65,0.025
2.07,119.71,0.025
2.08,119.78,0.025
2.09,119.85,0.025
2.09,119.91,0.025
2.10,119.98,0.025
2.11,120.05,0.025
2.11,120.11,0.025
2.12,120.18,0.025
2.13,120.25,0.025
2.13,120.31,0.025
2.14,120.38,0.025
2.15,120.45,0.025
2.15,120.51,0.025
2.16,120.58,0.025
2.17,120.65,0.025
2.17,120.71,0.025
2.18,120.78,0.025
2.19,120.85,0.025
2.19,120.91,0.025
2.20,120.98,0.025
2.21,121.05,0.025
2.21,121.11,0.025
2.22,121.18,0.025
2.23,121.25,0.025
2.23,121.31,0.025
2.24,121.38,0.025
2.25,121.45,0.025
2.25,121.51,0.025
2.26,121.58,0.025
2.27,121.65,0.025
2.27,121.71,0.025
2.28,121.78,0.025
2.29,121.85,0.025
2.29,121.91,0.025
2.30,121.98,0.025
2.31,122.05,0.025
2.31,122.11,0.025
2.32,122.18,0.025
2.33,122.25,0.025
2.33,122.31,0.025
2.34,122.38,0.025
2.35,122.45,0.025
2.35,122.51,0.025
2.36,122.58,0.025
2.37,122.65,0.025
2.37,122.71,0.025
2.38,122.78,0.025
2.39,122.85,0.025
2.39,122.91,0.025
2.40,122.98,0.025
2.41,123.05,0.025
2.41,123.11,0.025
2.42,123.18,0.025
2.43,123.25,0.025
2.43,123.31,0.025
2.44,123.38,0.025
2.45,123.45,0.025
2.45,123.51,0.025
2.46,123.58,0.025
2.47,123.65,0.025
2.47,123.72,0.025
2.48,123.78,0.025
2.49,123.85,0.025
2.49,123.91,0.025
2.50,123.98,0.025
2.51,124.05,0.025
2.51,124.12,0.025
2.52,124.18,0.025
2.53,124.25,0.025
2.53,124.32,0.025
2.54,124.38,0.025
2.55,124.45,0.025
2.55,124.52,0.025
2.56,124.58,0.025
2.57,124.65,0.025
2.57,124.72,0.025
2.58,124.78,0.025
2.59,124.85,0.025
2.59,124.92,0.025
2.60,124.98,0.025
2.61,125.05,0.025
2.61,125.12,0.025
2.62,125.18,0.025
2.63,125.25,0.025
2.63,125.32,0.025
2.64,125.38,0.025
2.65,125.45,0.025
2.65,125.52,0.025
2.66,125.58,0.025
2.67,125.65,0.025
2.67,125.72,0.025
2.68,125.78,0.025
2.69,125.85,0.025
2.69,125.92,0.025
2.70,125.98,0.025
2.71,126.05,0.025
2.71,126.12,0.025
2.72,126.18,0.025
2.73,126.25,0.026
2.73,126.32,0.025
2.74,126.38,0.025
2.75,126.45,0.025
2.75,126.52,0.025
2.76,126.58,0.025
2.77,126.65,0.025
2.77,126.72,0.025
2.78,126.78,0.025
2.79,126.85,0.025
2.79,126.92,0.025
2.80,126.98,0.025
2.81,127.05,0.025
2.81,127.12,0.025
2.82,127.18,0.025
2.83,127.25,0.025
2.83,127.32,0.025
2.84,127.38,0.025
2.85,127.45,0.025
2.85,127.52,0.025
2.86,127.59,0.025
2.87,127.65,0.025
2.87,127.72,0.025
2.88,127.78,0.025
2.89,127.85,0.025
2.89,127.92,0.025
2.90,127.98,0.025
2.91,128.05,0.026
2.91,128.12,0.026
2.92,128.18,0.026
2.93,128.25,0.026
2.93,128.32,0.026
2.94,128.38,0.026
2.95,128.45,0.026
2.95,128.52,0.026
2.96,128.58,0.026
2.97,128.65,0.026
2.97,128.72,0.026
2.98,128.78,0.026
2.99,128.85,0.026
2.99,128.92,0.026
3.00,128.99,0.026
3.01,129.05,0.026
3.01,129.12,0.026
3.02,129.18,0.026
3.03,129.25,0.026
3.03,129.32,0.026
3.04,129.39,0.026
3.05,129.45,0.025
3.05,129.52,0.025
3.06,129.59,0.025
3.07,129.65,0.025
3.07,129.72,0.025
3.08,129.79,0.025
3.09,129.85,0.025
3.09,129.92,0.025
3.10,129.99,0.025
3.11,130.05,0.025
3.11,130.12,0.025
3.12,130.19,0.025
3.13,130.25,0.025
3.13,130.32,0.026
3.14,130.39,0.026
3.15,130.45,0.026
3.15,130.52,0.026
3.16,130.59,0.026
3.17,130.65,0.026
3.17,130.72,0.026
3.18,130.79,0.026
3.19,130.85,0.026
3.19,130.92,0.026
3.20,130.99,0.026
3.21,131.05,0.026
3.21,131.12,0.026
3.22,131.19,0.026
3.23,131.25,0.026
3.23,131.32,0.026
3.24,131.39,0.026
3.25,131.45,0.025
3.25,131.52,0.025
3.26,131.59,0.025
3.27,131.65,0.025
3.27,131.72,0.025
3.28,131.79,0.025
3.29,131.85,0.025
3.29,131.92,0.025
3.30,131.99,0.025
3.31,132.05,0.025
3.31,132.12,0.025
3.32,132.19,0.026
3.33,132.25,0.026
3.33,132.32,0.026
3.34,132.39,0.026
3.35,132.46,0.026
3.35,132.52,0.026
3.36,132.59,0.026
3.37,132.65,0.026
3.37,132.72,0.026
3.38,132.79,0.026
3.39,132.85,0.026
3.39,132.92,0.026
3.40,132.99,0.026
3.41,133.05,0.026
3.41,133.12,0.026
3.42,133.19,0.026
3.43,133.25,0.026
3.43,133.32,0.026
3.44,133.39,0.026
3.45,133.45,0.026
3.45,133.52,0.026
3.46,133.59,0.026
3.47,133.66,0.026
3.47,133.72,0.026
3.48,133.79,0.026
3.49,133.86,0.026
3.49,133.92,0.026
3.50,133.99,0.026
3.51,134.05,0.026
3.51,134.12,0.026
3.52,134.19,0.026
3.53,134.26,0.026
3.53,134.32,0.026
3.54,134.39,0.026
3.55,134.46,0.026
3.55,134.52,0.026
3.56,134.59,0.026
3.57,134.66,0.026
3.57,134.72,0.026
3.58,134.79,0.026
3.59,134.86,0.026
3.59,134.92,0.026
3.60,134.99,0.026
3.61,135.06,0.026
3.61,135.12,0.026
3.62,135.19,0.026
3.63,135.26,0.026
3.63,135.32,0.026
3.64,135.39,0.026
3.65,135.46,0.026
3.65,135.52,0.026
3.66,135.59,0.026
3.67,135.66,0.026
3.67,135.72,0.026
3.68,135.79,0.026
3.69,135.86,0.026
3.69,135.92,0.026
3.70,135.99,0.026
3.71,136.06,0.026
3.71,136.12,0.026
3.72,136.19,0.026
3.73,136.26,0.026
3.73,136.32,0.026
3.74,136.39,0.026
3.75,136.46,0.026
3.75,136.52,0.026
3.76,136.59,0.026
3.77,136.66,0.026
3.77,136.72,0.026
3.78,136.79,0.026
3.79,136.86,0.026
3.79,136.92,0.026
3.80,136.99,0.026
3.81,137.06,0.026
3.81,137.12,0.026
3.82,137.19,0.026
3.83,137.26,0.026
3.83,137.32,0.026
3.84,137.39,0.026
3.85,137.46,0.026
3.85,137.53,0.026
3.86,137.59,0.026
3.87,137.66,0.026
3.87,137.72,0.026
3.88,137.79,0.026
3.89,137.86,0.026
3.89,137.93,0.026
3.90,137.99,0.026
3.91,138.06,0.026
3.91,138.13,0.026
3.92,138.19,0.026
3.93,138.26,0.026
3.93,138.33,0.026
3.94,138.39,0.026
3.95,138.46,0.026
3.95,138.53,0.026
3.96,138.59,0.026
3.97,138.66,0.026
3.97,138.73,0.026
3.98,138.79,0.026
3.99,138.86,0.026
3.99,138.93,0.026
4.00,138.99,0.026
4.01,139.06,0.026
4.01,139.13,0.026
4.02,139.19,0.026
4.03,139.26,0.026
4.03,139.33,0.026
4.04,139.39,0.026
4.05,139.46,0.026
4.05,139.53,0.026
4.06,139.59,0.026
4.07,139.66,0.026
4.07,139.73,0.026
4.08,139.79,0.026
4.09,139.86,0.026
4.09,139.93,0.026
4.10,139.99,0.026
4.11,140.06,0.026
4.11,140.13,0.026
4.12,140.19,0.026
4.13,140.26,0.026
4.13,140.33,0.026
4.14,140.39,0.026
4.15,140.46,0.026
4.15,140.53,0.026
4.16,140.59,0.026
4.17,140.66,0.026
4.17,140.73,0.026
4.18,140.79,0.026
4.19,140.86,0.026
4.19,140.93,0.026
4.20,140.99,0.026
4.21,141.06,0.026
4.21,141.13,0.026
4.22,141.19,0.026
4.23,141.26,0.026
4.23,141.33,0.026
4.24,141.39,0.026
4.25,141.46,0.026
4.25,141.53,0.026
4.26,141.59,0.026
4.27,141.66,0.026
4.27,141.73,0.026
4.28,141.79,0.026
4.29,141.86,0.026
4.29,141.93,0.026
4.30,141.99,0.026
4.31,142.06,0.026
4.31,142.13,0.026
4.32,142.19,0.026
4.33,142.26,0.026
4.33,142.33,0.026
4.34,142.39,0.026
4.35,142.46,0.026
4.35,142.53,0.026
4.36,142.59,0.026
4.37,142.66,0.026
4.37,142.73,0.026
4.38,142.79,0.026
4.39,142.86,0.026
4.39,142.93,0.026
4.40,142.99,0.026
4.41,143.06,0.026
4.41,143.13,0.026
4.42,143.19,0.026
4.43,143.26,0.026
4.43,143.33,0.026
4.44,143.40,0.026
4.45,143.46,0.026
4.45,143.53,0.026
4.46,143.59,0.025
4.47,143.66,0.025
4.47,143.73,0.025
4.48,143.80,0.025
4.49,143.86,0.025
4.49,143.93,0.025
4.50,144.00,0.025
4.51,144.06,0.025
4.51,144.13,0.025
4.52,144.20,0.026
4.53,144.26,0.026
4.53,144.33,0.025
4.54,144.40,0.025
4.55,144.46,0.026
4.55,144.53,0.026
4.56,144.60,0.026
4.57,144.66,0.026
4.57,144.73,0.026
4.58,144.80,0.026
4.59,144.86,0.026
4.59,144.93,0.026
4.60,145.00,0.026
4.61,145.06,0.026
4.61,145.13,0.026
4.62,145.20,0.026
4.63,145.26,0.026
4.63,145.33,0.026
4.64,145.40,0.026
4.65,145.46,0.026
4.65,145.53,0.026
4.66,145.60,0.026
4.67,145.66,0.026
4.67,145.73,0.026
4.68,145.80,0.026
4.69,145.87,0.026
4.69,145.93,0.026
4.70,146.00,0.026
4.71,146.07,0.026
4.71,146.13,0.026
4.72,146.20,0.026
4.73,146.27,0.026
4.73,146.33,0.026
4.74,146.40,0.026
4.75,146.47,0.026
4.75,146.53,0.026
4.76,146.60,0.026
4.77,146.66,0.026
4.77,146.73,0.026
4.78,146.80,0.026
4.79,146.86,0.026
4.79,146.93,0.026
4.80,147.00,0.026
4.81,147.07,0.026
4.81,147.13,0.026
4.82,147.20,0.026
4.83,147.26,0.026
4.83,147.33,0.026
4.84,147.40,0.026
4.85,147.46,0.026
4.85,147.53,0.026
4.86,147.60,0.026
4.87,147.66,0.026
4.87,147.73,0.026
4.88,147.80,0.026
4.89,147.87,0.026
4.89,147.93,0.026
4.90,148.00,0.026
4.91,148.07,0.026
4.91,148.13,0.026
4.92,148.20,0.026
4.93,148.27,0.026
4.93,148.33,0.026
4.94,148.40,0.026
4.95,148.47,0.026
4.95,148.53,0.026
4.96,148.60,0.026
4.97,148.67,0.026
4.97,148.73,0.026
4.98,148.80,0.026
4.99,148.87,0.026
4.99,148.93,0.026
5.00,149.00,0.026
5.01,149.07,0.026
5.01,149.13,0.026
5.02,149.20,0.026
5.03,149.27,0.026
5.03,149.33,0.026
5.04,149.40,0.026
5.05,149.47,0.026
5.05,149.53,0.026
5.06,149.60,0.026
5.07,149.67,0.026
5.07,149.73,0.026
5.08,149.80,0.026
5.09,149.87,0.026
5.09,149.93,0.026
5.10,150.00,0.026
5.11,150.07,0.026
5.11,150.13,0.026
5.12,150.20,0.026
5.13,150.27,0.026
5.13,150.33,0.026
5.14,150.40,0.026
5.15,150.47,0.026
5.15,150.53,0.026
5.16,150.60,0.026
5.17,150.67,0.026
5.17,150.73,0.026
5.18,150.80,0.026
5.19,150.87,0.026
5.19,150.93,0.026
5.20,151.00,0.026
5.21,151.07,0.026
5.21,151.13,0.026
5.22,151.20,0.026
5.23,151.27,0.026
5.23,151.33,0.026
5.24,151.40,0.026
5.25,151.47,0.026
5.25,151.54,0.026
5.26,151.60,0.026
5.27,151.67,0.026
5.27,151.73,0.026
5.28,151.80,0.026
5.29,151.87,0.026
5.29,151.93,0.026
5.30,152.00,0.026
5.31,152.07,0.026
5.31,152.13,0.026
5.32,152.20,0.026
5.33,152.27,0.026
5.33,152.33,0.026
5.34,152.40,0.026
5.35,152.47,0.026
5.35,152.53,0.026
5.36,152.60,0.026
5.37,152.67,0.026
5.37,152.74,0.026
5.38,152.80,0.026
5.39,152.87,0.026
5.39,152.94,0.026
5.40,153.00,0.026
5.41,153.07,0.026
5.41,153.14,0.026
5.42,153.20,0.026
5.43,153.27,0.026
5.43,153.34,0.026
5.44,153.40,0.026
5.45,153.47,0.026
5.45,153.54,0.026
5.46,153.60,0.026
5.47,153.67,0.026
5.47,153.74,0.026
5.48,153.81,0.026
5.49,153.87,0.026
5.49,153.94,0.026
5.50,154.01,0.026
5.51,154.07,0.026
5.51,154.14,0.026
5.52,154.21,0.026
5.53,154.27,0.026
5.53,154.34,0.026
5.54,154.41,0.026
5.55,154.47,0.026
5.55,154.54,0.026
5.56,154.61,0.026
5.57,154.67,0.026
5.57,154.74,0.026
5.58,154.81,0.026
5.59,154.87,0.026
5.59,154.94,0.026
5.60,155.01,0.026
5.61,155.07,0.026
5.61,155.14,0.026
5.62,155.21,0.026
5.63,155.27,0.026
5.63,155.34,0.026
5.64,155.41,0.026
5.65,155.47,0.026
5.65,155.54,0.026
5.66,155.61,0.026
5.67,155.67,0.026
5.67,155.74,0.026
5.68,155.81,0.026
5.69,155.87,0.026
5.69,155.94,0.026
5.70,156.01,0.026
5.71,156.07,0.026
5.71,156.14,0.026
5.72,156.21,0.026
5.73,156.27,0.026
5.73,156.34,0.026
5.74,156.41,0.026
5.75,156.47,0.026
5.75,156.54,0.027
5.76,156.61,0.027
5.77,156.67,0.029
5.77,156.74,0.045
5.78,156.80,0.106
5.79,156.86,0.278
5.79,156.90,0.517
5.80,156.94,0.729
5.81,156.97,0.910
5.81,157.00,1.072
5.82,157.02,1.219
5.83,157.05,1.351
5.83,157.08,1.475
5.84,157.11,1.599
5.85,157.13,1.724
5.85,157.16,1.848
5.86,157.19,1.973
5.87,157.21,2.097
5.87,157.24,2.221
5.88,157.27,2.345
5.89,157.30,2.469
5.89,157.33,2.593
5.90,157.35,2.717
5.91,157.38,2.839
5.91,157.41,2.959
5.92,157.44,3.077
5.93,157.47,3.188
5.93,157.50,3.284
5.94,157.53,3.333
5.95,157.57,3.296
5.95,157.62,3.102
5.96,157.70,2.584
5.97,157.83,1.939
5.97,157.96,1.532
5.98,158.10,1.280
5.99,158.23,1.102
5.99,158.36,0.967
6.00,158.48,0.859
6.01,158.60,0.767
6.01,158.71,0.691
6.02,158.82,0.626
6.03,158.92,0.565
6.03,159.03,0.512
6.04,159.12,0.467
6.05,159.22,0.421
6.05,159.31,0.384
6.06,159.40,0.350
6.07,159.49,0.319
6.07,159.57,0.290
6.08,159.66,0.265
6.09,159.74,0.242
6.09,159.82,0.222
6.10,159.90,0.203
6.11,159.97,0.186
6.11,160.05,0.171
6.12,160.13,0.156
6.13,160.20,0.144
6.13,160.28,0.133
6.14,160.35,0.123
6.15,160.42,0.115
6.15,160.49,0.106
6.16,160.56,0.098
6.17,160.63,0.092
6.17,160.71,0.086
6.18,160.78,0.079
6.19,160.84,0.075
6.19,160.91,0.071
6.20,160.98,0.067
6.21,161.05,0.063
6.21,161.12,0.060
6.22,161.19,0.057
6.23,161.26,0.054
6.23,161.33,0.052
6.24,161.39,0.049
6.25,161.46,0.048
6.25,161.53,0.046
6.26,161.60,0.044
6.27,161.67,0.043
6.27,161.73,0.042
6.28,161.80,0.042
6.29,161.87,0.041
6.29,161.93,0.039
6.30,162.00,0.039
6.31,162.07,0.038
6.31,162.14,0.038
6.32,162.20,0.037
6.33,162.27,0.036
6.33,162.34,0.036
6.34,162.41,0.036
6.35,162.47,0.035
6.35,162.54,0.035
6.36,162.61,0.035
6.37,162.67,0.034
6.37,162.74,0.034
6.38,162.81,0.034
6.39,162.87,0.034
6.39,162.94,0.034
6.40,163.01,0.034
6.41,163.07,0.034
6.41,163.14,0.034
6.42,163.21,0.033
6.43,163.28,0.033
6.43,163.34,0.033
6.44,163.41,0.033
6.45,163.48,0.033
6.45,163.54,0.033
6.46,163.61,0.033
6.47,163.68,0.032
6.47,163.74,0.032
6.48,163.81,0.032
6.49,163.88,0.032
6.49,163.94,0.032
6.50,164.01,0.032
6.51,164.08,0.032
6.51,164.14,0.032
6.52,164.21,0.032
6.53,164.28,0.032
6.53,164.34,0.032
6.54,164.41,0.032
6.55,164.48,0.032
6.55,164.54,0.032
6.56,164.61,0.032
6.57,164.68,0.032
6.57,164.74,0.032
6.58,164.81,0.032
6.59,164.88,0.032
6.59,164.94,0.032
6.60,165.01,0.032
6.61,165.08,0.032
6.61,165.14,0.032
6.62,165.21,0.032
6.63,165.28,0.032
6.63,165.34,0.032
6.64,165.41,0.032
6.65,165.48,0.032
6.65,165.54,0.031
6.66,165.61,0.031
6.67,165.68,0.031
6.67,165.74,0.031
6.68,165.81,0.031
6.69,165.88,0.031
6.69,165.94,0.031
6.70,166.01,0.031
6.71,166.08,0.031
6.71,166.14,0.031
6.72,166.21,0.031
6.73,166.28,0.031
6.73,166.34,0.031
6.74,166.41,0.031
6.75,166.48,0.031
6.75,166.54,0.031
6.76,166.61,0.031
6.77,166.68,0.031
6.77,166.74,0.031
6.78,166.81,0.031
6.79,166.88,0.031
6.79,166.95,0.031
6.80,167.01,0.031
6.81,167.08,0.031
6.81,167.15,0.031
6.82,167.21,0.031
6.83,167.28,0.031
6.83,167.35,0.031
6.84,167.41,0.031
6.85,167.48,0.031
6.85,167.55,0.031
6.86,167.61,0.031
6.87,167.68,0.031
6.87,167.74,0.031
6.88,167.81,0.031
6.89,167.88,0.031
6.89,167.94,0.031
6.90,168.01,0.031
6.91,168.08,0.031
6.91,168.15,0.031
6.92,168.21,0.031
6.93,168.28,0.031
6.93,168.35,0.031
6.94,168.41,0.031
6.95,168.48,0.031
6.95,168.55,0.031
6.96,168.61,0.031
6.97,168.68,0.031
6.97,168.75,0.031
6.98,168.81,0.031
6.99,168.88,0.031
6.99,168.95,0.031
7.00,169.01,0.031
7.01,169.08,0.031
7.01,169.15,0.031
7.02,169.21,0.031
7.03,169.28,0.031
7.03,169.35,0.031
7.04,169.41,0.031
7.05,169.48,0.031
7.05,169.55,0.031
7.06,169.61,0.031
7.07,169.68,0.031
7.07,169.75,0.031
7.08,169.81,0.031
7.09,169.88,0.031
7.09,169.95,0.031
7.10,170.01,0.031
7.11,170.08,0.031
7.11,170.15,0.031
7.12,170.21,0.031
7.13,170.28,0.031
7.13,170.35,0.031
7.14,170.41,0.031
7.15,170.48,0.031
7.15,170.55,0.031
7.16,170.61,0.031
7.17,170.68,0.031
7.17,170.75,0.031
7.18,170.81,0.031
7.19,170.88,0.031
7.19,170.95,0.031
7.20,171.01,0.031
7.21,171.08,0.031
7.21,171.15,0.031
7.22,171.21,0.031
7.23,171.28,0.031
7.23,171.35,0.031
7.24,171.41,0.031
7.25,171.48,0.031
7.25,171.55,0.031
7.26,171.61,0.031
7.27,171.68,0.031
7.27,171.75,0.031
7.28,171.81,0.031
7.29,171.88,0.031
7.29,171.95,0.031
7.30,172.01,0.031
7.31,172.08,0.031
7.31,172.15,0.031
7.32,172.21,0.031
7.33,172.28,0.031
7.33,172.35,0.031
7.34,172.41,0.031
7.35,172.48,0.031
7.35,172.55,0.031
7.36,172.61,0.031
7.37,172.68,0.031
7.37,172.75,0.031
7.38,172.81,0.031
7.39,172.88,0.031
7.39,172.95,0.031
7.40,173.01,0.031
7.41,173.08,0.031
7.41,173.15,0.031
7.42,173.21,0.031
7.43,173.28,0.031
7.43,173.35,0.031
7.44,173.41,0.031
7.45,173.48,0.031
7.45,173.55,0.031
7.46,173.61,0.031
7.47,173.68,0.031
7.47,173.75,0.031
7.48,173.81,0.031
7.49,173.88,0.031
7.49,173.95,0.031
7.50,174.01,0.031
7.51,174.08,0.031
7.51,174.15,0.031
7.52,174.21,0.031
7.53,174.28,0.031
7.53,174.35,0.031
7.54,174.41,0.031
7.55,174.48,0.031
7.55,174.55,0.031
7.56,174.61,0.031
7.57,174.68,0.031
7.57,174.75,0.031
7.58,174.81,0.031
7.59,174.88,0.031
7.59,174.95,0.031
7.60,175.01,0.031
7.61,175.08,0.031
7.61,175.15,0.031
7.62,175.22,0.031
7.63,175.28,0.031
7.63,175.35,0.031
7.64,175.42,0.031
7.65,175.48,0.031
7.65,175.55,0.031
7.66,175.62,0.031
7.67,175.68,0.031
7.67,175.75,0.031
7.68,175.82,0.031
7.69,175.88,0.031
7.69,175.95,0.031
7.70,176.02,0.031
7.71,176.08,0.031
7.71,176.15,0.031
7.72,176.22,0.031
7.73,176.28,0.031
7.73,176.35,0.031
7.74,176.42,0.031
7.75,176.48,0.031
7.75,176.55,0.031
7.76,176.62,0.031
7.77,176.68,0.031
7.77,176.75,0.031
7.78,176.82,0.031
7.79,176.88,0.031
7.79,176.95,0.031
7.80,177.02,0.031
7.81,177.08,0.031
7.81,177.15,0.031
7.82,177.22,0.031
7.83,177.28,0.031
7.83,177.35,0.031
7.84,177.42,0.031
7.85,177.48,0.031
7.85,177.55,0.031
7.86,177.62,0.031
7.87,177.68,0.031
7.87,177.75,0.031
7.88,177.82,0.031
7.89,177.89,0.031
7.89,177.95,0.031
7.90,178.02,0.031
7.91,178.09,0.031
7.91,178.15,0.031
7.92,178.22,0.031
7.93,178.29,0.031
7.93,178.35,0.031
7.94,178.42,0.031
7.95,178.49,0.031
7.95,178.55,0.031
7.96,178.62,0.031
7.97,178.69,0.031
7.97,178.75,0.031
7.98,178.82,0.031
7.99,178.89,0.031
7.99,178.95,0.031
8.00,179.02,0.031
8.01,179.09,0.031
8.01,179.15,0.031
8.02,179.22,0.031
8.03,179.29,0.031
8.03,179.35,0.031
8.04,179.42,0.031
8.05,179.49,0.031
8.05,179.55,0.031
8.06,179.62,0.031
8.07,179.69,0.031
8.07,179.75,0.031
8.08,179.82,0.031
8.09,179.89,0.031
8.09,179.95,0.031
8.10,180.02,0.031
8.11,180.09,0.031
8.11,180.15,0.031
8.12,180.22,0.031
8.13,180.29,0.031
8.13,180.35,0.031
8.14,180.42,0.031
8.15,180.49,0.031
8.15,180.55,0.031
8.16,180.62,0.031
8.17,180.68,0.031
8.17,180.75,0.031
8.18,180.82,0.031
8.19,180.88,0.031
8.19,180.95,0.031
8.20,181.02,0.031
8.21,181.08,0.031
8.21,181.15,0.031
8.22,181.22,0.031
8.23,181.29,0.031
8.23,181.35,0.031
8.24,181.42,0.031
8.25,181.49,0.031
8.25,181.55,0.031
8.26,181.62,0.031
8.27,181.69,0.031
8.27,181.75,0.031
8.28,181.82,0.031
8.29,181.89,0.031
8.29,181.95,0.031
8.30,182.02,0.031
8.31,182.09,0.031
8.31,182.15,0.031
8.32,182.22,0.031
8.33,182.29,0.031
8.33,182.35,0.031
8.34,182.42,0.031
8.35,182.49,0.031
8.35,182.55,0.031
8.36,182.62,0.031
8.37,182.69,0.031
8.37,182.75,0.031
8.38,182.82,0.031
8.39,182.89,0.031
8.39,182.95,0.031
8.40,183.02,0.031
8.41,183.09,0.031
8.41,183.16,0.031
8.42,183.22,0.031
8.43,183.29,0.031
8.43,183.35,0.031
8.44,183.42,0.031
8.45,183.49,0.031
8.45,183.56,0.031
8.46,183.62,0.031
8.47,183.69,0.031
8.47,183.76,0.031
8.48,183.82,0.031
8.49,183.89,0.031
8.49,183.96,0.031
8.50,184.02,0.031
8.51,184.09,0.031
8.51,184.16,0.031
8.52,184.22,0.031
8.53,184.29,0.031
8.53,184.36,0.031
8.54,184.42,0.031
8.55,184.49,0.031
8.55,184.56,0.031
8.56,184.62,0.031
8.57,184.69,0.031
8.57,184.76,0.031
8.58,184.82,0.031
8.59,184.89,0.031
8.59,184.96,0.031
8.60,185.02,0.031
8.61,185.09,0.031
8.61,185.16,0.031
8.62,185.22,0.031
8.63,185.29,0.031
8.63,185.36,0.031
8.64,185.42,0.031
8.65,185.49,0.031
8.65,185.56,0.031
8.66,185.62,0.031
8.67,185.69,0.031
8.67,185.76,0.031
8.68,185.82,0.031
8.69,185.89,0.031
8.69,185.96,0.031
8.70,186.02,0.031
8.71,186.09,0.031
8.71,186.16,0.031
8.72,186.22,0.031
8.73,186.29,0.031
8.73,186.36,0.031
8.74,186.42,0.031
8.75,186.49,0.031
8.75,186.56,0.031
8.76,186.62,0.031
8.77,186.69,0.031
8.77,186.76,0.031
8.78,186.83,0.031
8.79,186.89,0.031
8.79,186.96,0.031
8.80,187.03,0.031
8.81,187.09,0.031
8.81,187.16,0.031
8.82,187.23,0.031
8.83,187.29,0.031
8.83,187.36,0.031
8.84,187.43,0.031
8.85,187.49,0.032
8.85,187.56,0.031
8.86,187.63,0.032
8.87,187.69,0.032
8.87,187.76,0.032
8.88,187.82,0.032
8.89,187.89,0.032
8.89,187.96,0.032
8.90,188.03,0.032
8.91,188.09,0.032
8.91,188.16,0.032
8.92,188.22,0.032
8.93,188.29,0.032
8.93,188.36,0.031
8.94,188.43,0.031
8.95,188.49,0.031
8.95,188.56,0.031
8.96,188.63,0.031
8.97,188.69,0.031
8.97,188.76,0.031
8.98,188.83,0.031
8.99,188.89,0.031
8.99,188.96,0.031
9.00,189.03,0.031
9.01,189.09,0.031
9.01,189.16,0.031
9.02,189.23,0.031
9.03,189.29,0.031
9.03,189.36,0.031
9.04,189.43,0.031
9.05,189.49,0.031
9.05,189.56,0.031
9.06,189.63,0.031
9.07,189.69,0.031
9.07,189.76,0.031
9.08,189.83,0.031
9.09,189.89,0.031
9.09,189.96,0.031
9.10,190.03,0.031
9.11,190.09,0.031
9.11,190.16,0.031
9.12,190.23,0.031
9.13,190.29,0.032
9.13,190.36,0.032
9.14,190.43,0.032
9.15,190.49,0.032
9.15,190.56,0.032
9.16,190.63,0.032
9.17,190.69,0.032
9.17,190.76,0.032
9.18,190.83,0.032
9.19,190.89,0.032
9.19,190.96,0.032
9.20,191.03,0.032
9.21,191.09,0.032
9.21,191.16,0.032
9.22,191.23,0.032
9.23,191.29,0.032
9.23,191.36,0.032
9.24,191.43,0.032
9.25,191.49,0.032
9.25,191.56,0.032
9.26,191.63,0.032
9.27,191.69,0.032
9.27,191.76,0.032
9.28,191.83,0.032
9.29,191.89,0.032
9.29,191.96,0.032
9.30,192.03,0.032
9.31,192.09,0.032
9.31,192.16,0.032
9.32,192.23,0.032
9.33,192.29,0.032
9.33,192.36,0.032
9.34,192.43,0.032
9.35,192.49,0.032
9.35,192.56,0.032
9.36,192.63,0.032
9.37,192.69,0.032
9.37,192.76,0.032
9.38,192.83,0.032
9.39,192.89,0.032
9.39,192.96,0.032
9.40,193.03,0.032
9.41,193.09,0.032
9.41,193.16,0.032
9.42,193.23,0.032
9.43,193.29,0.032
9.43,193.36,0.032
9.44,193.43,0.032
9.45,193.49,0.032
9.45,193.56,0.032
9.46,193.63,0.032
9.47,193.69,0.032
9.47,193.76,0.032
9.48,193.83,0.032
9.49,193.89,0.032
9.49,193.96,0.032
9.50,194.03,0.032
9.51,194.09,0.032
9.51,194.16,0.032
9.52,194.23,0.032
9.53,194.29,0.032
9.53,194.36,0.032
9.54,194.43,0.032
9.55,194.49,0.032
9.55,194.56,0.032
9.56,194.63,0.032
9.57,194.69,0.032
9.57,194.76,0.032
9.58,194.83,0.032
9.59,194.89,0.032
9.59,194.96,0.032
9.60,195.03,0.032
9.61,195.10,0.032
9.61,195.16,0.032
9.62,195.23,0.032
9.63,195.29,0.032
9.63,195.36,0.032
9.64,195.43,0.032
9.65,195.50,0.032
9.65,195.56,0.032
9.66,195.63,0.032
9.67,195.70,0.032
9.67,195.76,0.032
9.68,195.83,0.032
9.69,195.90,0.032
9.69,195.96,0.032
9.70,196.03,0.032
9.71,196.10,0.032
9.71,196.16,0.032
9.72,196.23,0.032
9.73,196.30,0.032
9.73,196.36,0.032
9.74,196.43,0.032
9.75,196.50,0.032
9.75,196.56,0.032
9.76,196.63,0.032
9.77,196.70,0.032
9.77,196.76,0.032
9.78,196.83,0.032
9.79,196.90,0.032
9.79,196.96,0.032
9.80,197.03,0.032
9.81,197.10,0.032
9.81,197.17,0.032
9.82,197.23,0.032
9.83,197.30,0.032
9.83,197.36,0.032
9.84,197.43,0.032
9.85,197.50,0.032
9.85,197.57,0.032
9.86,197.63,0.032
9.87,197.70,0.032
9.87,197.77,0.032
9.88,197.83,0.032
9.89,197.90,0.032
9.89,197.97,0.032
9.90,198.03,0.032
9.91,198.10,0.032
9.91,198.17,0.032
9.92,198.23,0.032
9.93,198.30,0.032
9.93,198.37,0.032
9.94,198.43,
9.95,198.50,
9.95,198.57,
9.96,198.63,
9.97,198.70,
9.97,198.77,
9.98,198.83,
9.99,198.90,
9.99,,
10.00,,

[step]
Ramp 10.00 °C/min to 100.00 °C
Time,Temperature,Heat Flow (Normalized)
min,°C,W/g
12.00,200.16,-0.030
12.00,200.16,-0.030
12.01,200.16,-0.030
12.02,200.16,-0.030
12.02,200.16,-0.030
12.03,200.16,-0.030
12.04,200.15,-0.029
12.04,200.15,-0.028
12.05,200.15,-0.024
12.06,200.14,-0.014
12.06,200.13,-0.006
12.07,200.11,0.001
12.08,200.10,0.010
12.08,200.08,0.018
12.09,200.05,0.024
12.10,200.03,0.029
12.10,199.99,0.032
12.11,199.96,0.034
12.12,199.92,0.034
12.12,199.88,0.033
12.13,199.83,0.032
12.14,199.79,0.026
12.14,199.74,0.023
12.15,199.69,0.016
12.16,199.63,0.008
12.16,199.58,-0.002
12.17,199.52,-0.009
12.18,199.46,-0.016
12.18,199.40,-0.024
12.19,199.34,-0.031
12.20,199.28,-0.038
12.20,199.22,-0.043
12.21,199.16,-0.047
12.22,199.10,-0.053
12.22,199.03,-0.057
12.23,198.97,-0.060
12.24,198.91,-0.063
12.24,198.84,-0.067
12.25,198.78,-0.070
12.26,198.72,-0.071
12.26,198.65,-0.072
12.27,198.59,-0.074
12.28,198.52,-0.076
12.28,198.46,-0.077
12.29,198.39,-0.078
12.30,198.33,-0.079
12.30,198.26,-0.079
12.31,198.20,-0.080
12.32,198.13,-0.081
12.32,198.07,-0.081
12.33,198.00,-0.082
12.34,197.94,-0.082
12.34,197.87,-0.083
12.35,197.80,-0.083
12.36,197.74,-0.084
12.36,197.67,-0.084
12.37,197.61,-0.084
12.38,197.54,-0.084
12.38,197.48,-0.084
12.39,197.41,-0.084
12.40,197.34,-0.085
12.40,197.28,-0.085
12.41,197.21,-0.085
12.42,197.15,-0.085
12.42,197.08,-0.085
12.43,197.01,-0.085
12.44,196.95,-0.085
12.44,196.88,-0.086
12.45,196.82,-0.086
12.46,196.75,-0.086
12.46,196.68,-0.086
12.47,196.62,-0.086
12.48,196.55,-0.086
12.48,196.49,-0.086
12.49,196.42,-0.086
12.50,196.35,-0.087
12.50,196.29,-0.087
12.51,196.22,-0.087
12.52,196.15,-0.087
12.52,196.09,-0.087
12.53,196.02,-0.087
12.54,195.96,-0.087
12.54,195.89,-0.087
12.55,195.82,-0.087
12.56,195.76,-0.088
12.56,195.69,-0.088
12.57,195.63,-0.088
12.58,195.56,-0.088
12.58,195.49,-0.088
12.59,195.43,-0.088
12.60,195.36,-0.088
12.60,195.30,-0.088
12.61,195.23,-0.088
12.62,195.16,-0.088
12.62,195.10,-0.088
12.63,195.03,-0.088
12.64,194.96,-0.088
12.64,194.90,-0.088
12.65,194.83,-0.089
12.66,194.77,-0.089
12.66,194.70,-0.089
12.67,194.63,-0.089
12.68,194.57,-0.089
12.68,194.50,-0.089
12.69,194.43,-0.089
12.70,194.37,-0.089
12.70,194.30,-0.089
12.71,194.23,-0.089
12.72,194.17,-0.089
12.72,194.10,-0.089
12.73,194.04,-0.089
12.74,193.97,-0.089
12.74,193.90,-0.089
12.75,193.84,-0.089
12.76,193.77,-0.090
12.76,193.70,-0.090
12.77,193.64,-0.090
12.78,193.57,-0.090
12.78,193.51,-0.090
12.79,193.44,-0.090
12.80,193.37,-0.090
12.80,193.31,-0.090
12.81,193.24,-0.090
12.82,193.17,-0.090
12.82,193.11,-0.090
12.83,193.04,-0.090
12.84,192.98,-0.090
12.84,192.91,-0.090
12.85,192.84,-0.090
12.86,192.78,-0.090
12.86,192.71,-0.090
12.87,192.64,-0.090
12.88,192.58,-0.090
12.88,192.51,-0.090
12.89,192.44,-0.090
12.90,192.38,-0.090
12.90,192.31,-0.090
12.91,192.25,-0.090
12.92,192.18,-0.090
12.92,192.11,-0.090
12.93,192.04,-0.090
12.94,191.98,-0.090
12.94,191.91,-0.090
12.95,191.85,-0.090
12.96,191.78,-0.090
12.96,191.71,-0.090
12.97,191.65,-0.090
12.98,191.58,-0.090
12.98,191.51,-0.090
12.99,191.45,-0.090
13.00,191.38,-0.090
13.00,191.31,-0.090
13.01,191.25,-0.090
13.02,191.18,-0.090
13.02,191.11,-0.090
13.03,191.05,-0.090
13.04,190.98,-0.090
13.04,190.92,-0.090
13.05,190.85,-0.090
13.06,190.78,-0.090
13.06,190.72,-0.090
13.07,190.65,-0.090
13.08,190.59,-0.091
13.08,190.52,-0.091
13.09,190.45,-0.091
13.10,190.38,-0.091
13.10,190.32,-0.091
13.11,190.25,-0.091
13.12,190.19,-0.091
13.12,190.12,-0.091
13.13,190.05,-0.090
13.14,189.99,-0.090
13.14,189.92,-0.090
13.15,189.85,-0.090
13.16,189.79,-0.090
13.16,189.72,-0.090
13.17,189.65,-0.090
13.18,189.59,-0.090
13.18,189.52,-0.090
13.19,189.45,-0.090
13.20,189.39,-0.090
13.20,189.32,-0.090
13.21,189.25,-0.090
13.22,189.19,-0.090
13.22,189.12,-0.090
13.23,189.05,-0.090
13.24,188.99,-0.090
13.24,188.92,-0.090
13.25,188.85,-0.090
13.26,188.79,-0.090
13.26,188.72,-0.090
13.27,188.65,-0.090
13.28,188.59,-0.090
13.28,188.52,-0.090
13.29,188.46,-0.090
13.30,188.39,-0.090
13.30,188.32,-0.090
13.31,188.26,-0.090
13.32,188.19,-0.090
13.32,188.12,-0.090
13.33,188.06,-0.090
13.34,187.99,-0.090
13.34,187.92,-0.090
13.35,187.86,-0.090
13.36,187.79,-0.090
13.36,187.72,-0.090
13.37,187.66,-0.090
13.38,187.59,-0.090
13.38,187.52,-0.090
13.39,187.46,-0.090
13.40,187.39,-0.090
13.40,187.32,-0.090
13.41,187.26,-0.090
13.42,187.19,-0.090
13.42,187.12,-0.090
13.43,187.06,-0.090
13.44,186.99,-0.090
13.44,186.93,-0.090
13.45,186.86,-0.090
13.46,186.79,-0.090
13.46,186.72,-0.090
13.47,186.66,-0.090
13.48,186.59,-0.090
13.48,186.53,-0.090
13.49,186.46,-0.090
13.50,186.39,-0.090
13.50,186.33,-0.090
13.51,186.26,-0.090
13.52,186.19,-0.090
13.52,186.13,-0.090
13.53,186.06,-0.090
13.54,185.99,-0.090
13.54,185.93,-0.090
13.55,185.86,-0.090
13.56,185.79,-0.090
13.56,185.73,-0.090
13.57,185.66,-0.090
13.58,185.59,-0.090
13.58,185.53,-0.090
13.59,185.46,-0.090
13.60,185.39,-0.090
13.60,185.33,-0.090
13.61,185.26,-0.090
13.62,185.19,-0.090
13.62,185.13,-0.090
13.63,185.06,-0.090
13.64,184.99,-0.090
13.64,184.93,-0.090
13.65,184.86,-0.090
13.66,184.79,-0.090
13.66,184.73,-0.090
13.67,184.66,-0.090
13.68,184.59,-0.090
13.68,184.53,-0.090
13.69,184.46,-0.090
13.70,184.40,-0.090
13.70,184.33,-0.090
13.71,184.26,-0.090
13.72,184.20,-0.089
13.72,184.13,-0.089
13.73,184.06,-0.089
13.74,184.00,-0.089
13.74,183.93,-0.089
13.75,183.86,-0.089
13.76,183.80,-0.089
13.76,183.73,-0.089
13.77,183.66,-0.089
13.78,183.60,-0.089
13.78,183.53,-0.089
13.79,183.46,-0.089
13.80,183.40,-0.089
13.80,183.33,-0.089
13.81,183.26,-0.089
13.82,183.20,-0.089
13.82,183.13,-0.089
13.83,183.06,-0.089
13.84,183.00,-0.089
13.84,182.93,-0.089
13.85,182.86,-0.089
13.86,182.80,-0.089
13.86,182.73,-0.089
13.87,182.66,-0.089
13.88,182.60,-0.089
13.88,182.53,-0.089
13.89,182.46,-0.089
13.90,182.40,-0.089
13.90,182.33,-0.089
13.91,182.26,-0.089
13.92,182.20,-0.089
13.92,182.13,-0.089
13.93,182.06,-0.089
13.94,181.99,-0.089
13.94,181.93,-0.089
13.95,181.86,-0.089
13.96,181.80,-0.089
13.96,181.73,-0.089
13.97,181.66,-0.089
13.98,181.60,-0.089
13.98,181.53,-0.089
13.99,181.46,-0.089
14.00,181.40,-0.089
14.00,181.33,-0.089
14.01,181.26,-0.089
14.02,181.20,-0.089
14.02,181.13,-0.089
14.03,181.06,-0.089
14.04,181.00,-0.089
14.04,180.93,-0.089
14.05,180.86,-0.089
14.06,180.80,-0.089
14.06,180.73,-0.089
14.07,180.66,-0.089
14.08,180.60,-0.089
14.08,180.53,-0.089
14.09,180.46,-0.089
14.10,180.40,-0.089
14.10,180.33,-0.089
14.11,180.26,-0.089
14.12,180.20,-0.089
14.12,180.13,-0.089
14.13,180.06,-0.089
14.14,180.00,-0.089
14.14,179.93,-0.089
14.15,179.86,-0.089
14.16,179.80,-0.089
14.16,179.73,-0.089
14.17,179.66,-0.089
14.18,179.60,-0.089
14.18,179.53,-0.089
14.19,179.46,-0.089
14.20,179.40,-0.089
14.20,179.33,-0.088
14.21,179.26,-0.088
14.22,179.20,-0.088
14.22,179.13,-0.088
[...]
50.97,128.66,0.034
50.98,128.73,0.034
50.98,128.80,0.034
50.99,128.86,0.034
51.00,128.93,0.034
51.00,129.00,0.034
51.01,129.06,0.034
51.02,129.13,0.034
51.02,129.20,0.033
51.03,129.26,0.033
51.04,129.33,0.034
51.04,129.40,0.033
51.05,129.46,0.033
51.06,129.53,0.033
51.06,129.60,0.033
51.07,129.66,0.033
51.08,129.73,0.033
51.08,129.80,0.033
51.09,129.86,0.033
51.10,129.93,0.033
51.10,130.00,0.033
51.11,130.06,0.033
51.12,130.13,0.033
51.12,130.20,0.033
51.13,130.26,0.033
51.14,130.33,0.033
51.14,130.40,0.033
51.15,130.46,0.033
51.16,130.53,0.033
51.16,130.60,0.033
51.17,130.66,0.033
51.18,130.73,0.033
51.18,130.80,0.033
51.19,130.87,0.033
51.20,130.93,0.033
51.20,131.00,0.033
51.21,131.06,0.033
51.22,131.13,0.033
51.22,131.20,0.033
51.23,131.27,0.033
51.24,131.33,0.033
51.24,131.40,0.033
51.25,131.47,0.033
51.26,131.53,0.033
51.26,131.60,0.033
51.27,131.67,0.033
51.28,131.73,0.033
51.28,131.80,0.033
51.29,131.87,0.033
51.30,131.93,0.033
51.30,132.00,0.033
51.31,132.07,0.033
51.32,132.13,0.033
51.32,132.20,0.033
51.33,132.27,0.033
51.34,132.33,0.033
51.34,132.40,0.033
51.35,132.47,0.033
51.36,132.53,0.033
51.36,132.60,0.033
51.37,132.67,0.033
51.38,132.73,0.033
51.38,132.80,0.033
51.39,132.87,0.033
51.40,132.93,0.033
51.40,133.00,0.033
51.41,133.07,0.033
51.42,133.13,0.033
51.42,133.20,0.033
51.43,133.27,0.033
51.44,133.33,0.033
51.44,133.40,0.033
51.45,133.47,0.033
51.46,133.53,0.033
51.46,133.60,0.033
51.47,133.67,0.033
51.48,133.73,0.033
51.48,133.80,0.033
51.49,133.87,0.033
51.50,133.93,0.033
51.50,134.00,0.033
51.51,134.07,0.033
51.52,134.13,0.033
51.52,134.20,0.033
51.53,134.27,0.033
51.54,134.33,0.033
51.54,134.40,0.033
51.55,134.47,0.033
51.56,134.54,0.033
51.56,134.60,0.033
51.57,134.67,0.033
51.58,134.73,0.033
51.58,134.80,0.033
51.59,134.87,0.033
51.60,134.94,0.033
51.60,135.00,0.033
51.61,135.07,0.033
51.62,135.14,0.033
51.62,135.20,0.033
51.63,135.27,0.033
51.64,135.34,0.033
51.64,135.40,0.033
51.65,135.47,0.033
51.66,135.54,0.033
51.66,135.60,0.033
51.67,135.67,0.033
51.68,135.74,0.033
51.68,135.80,0.033
51.69,135.87,0.033
51.70,135.94,0.033
51.70,136.00,0.033
51.71,136.07,0.033
51.72,136.14,0.033
51.72,136.20,0.033
51.73,136.27,0.033
51.74,136.34,0.033
51.74,136.40,0.033
51.75,136.47,0.033
51.76,136.54,0.033
51.76,136.60,0.033
51.77,136.67,0.033
51.78,136.74,0.033
51.78,136.80,0.033
51.79,136.87,0.033
51.80,136.94,0.033
51.80,137.00,0.033
51.81,137.07,0.033
51.82,137.14,0.033
51.82,137.20,0.033
51.83,137.27,0.033
51.84,137.34,0.033
51.84,137.40,0.033
51.85,137.47,0.033
51.86,137.54,0.033
51.86,137.60,0.033
51.87,137.67,0.033
51.88,137.74,0.033
51.88,137.80,0.033
51.89,137.87,0.033
51.90,137.94,0.033
51.90,138.00,0.033
51.91,138.07,0.033
51.92,138.14,0.033
51.92,138.20,0.033
51.93,138.27,0.033
51.94,138.34,0.033
51.94,138.40,0.033
51.95,138.47,0.033
51.96,138.54,0.033
51.96,138.60,0.033
51.97,138.67,0.033
51.98,138.74,0.033
51.98,138.80,0.033
51.99,138.87,0.033
52.00,138.94,0.033
52.00,139.00,0.033
52.01,139.07,0.033
52.02,139.14,0.033
52.02,139.20,0.033
52.03,139.27,0.033
52.04,139.34,0.033
52.04,139.40,0.033
52.05,139.47,0.033
52.06,139.54,0.033
52.06,139.60,0.033
52.07,139.67,0.033
52.08,139.74,0.033
52.08,139.81,0.033
52.09,139.87,0.033
52.10,139.94,0.033
52.10,140.00,0.033
52.11,140.07,0.033
52.12,140.14,0.033
52.12,140.20,0.033
52.13,140.27,0.033
52.14,140.34,0.033
52.14,140.41,0.033
52.15,140.47,0.033
52.16,140.54,0.033
52.16,140.61,0.033
52.17,140.67,0.033
52.18,140.74,0.033
52.18,140.81,0.033
52.19,140.87,0.033
52.20,140.94,0.033
52.20,141.01,0.033
52.21,141.07,0.033
52.22,141.14,0.033
52.22,141.21,0.033
52.23,141.27,0.033
52.24,141.34,0.033
52.24,141.41,0.033
52.25,141.47,0.033
52.26,141.54,0.033
52.26,141.61,0.033
52.27,141.67,0.033
52.28,141.74,0.033
52.28,141.81,0.033
52.29,141.87,0.033
52.30,141.94,0.033
52.30,142.01,0.033
52.31,142.07,0.033
52.32,142.14,0.033
52.32,142.21,0.033
52.33,142.27,0.033
52.34,142.34,0.033
52.34,142.41,0.033
52.35,142.47,0.033
52.36,142.54,0.033
52.36,142.61,0.033
52.37,142.67,0.033
52.38,142.74,0.033
52.38,142.81,0.033
52.39,142.87,0.033
52.40,142.94,0.033
52.40,143.01,0.033
52.41,143.07,0.033
52.42,143.14,0.033
52.42,143.21,0.033
52.43,143.27,0.033
52.44,143.34,0.033
52.44,143.41,0.033
52.45,143.47,0.033
52.46,143.54,0.033
52.46,143.61,0.033
52.47,143.67,0.033
52.48,143.74,0.033
52.48,143.81,0.033
52.49,143.87,0.033
52.50,143.94,0.033
52.50,144.01,0.033
52.51,144.08,0.033
52.52,144.14,0.033
52.52,144.21,0.033
52.53,144.27,0.033
52.54,144.34,0.033
52.54,144.41,0.033
52.55,144.47,0.033
52.56,144.54,0.033
52.56,144.61,0.033
52.57,144.67,0.033
52.58,144.74,0.033
52.58,144.81,0.033
52.59,144.88,0.033
52.60,144.94,0.033
52.60,145.01,0.033
52.61,145.07,0.033
52.62,145.14,0.033
52.62,145.21,0.033
52.63,145.28,0.033
52.64,145.34,0.033
52.64,145.41,0.033
52.65,145.48,0.033
52.66,145.54,0.033
52.66,145.61,0.033
52.67,145.68,0.033
52.68,145.74,0.033
52.68,145.81,0.033
52.69,145.88,0.033
52.70,145.94,0.033
52.70,146.01,0.033
52.71,146.08,0.033
52.72,146.14,0.033
52.72,146.21,0.033
52.73,146.28,0.033
52.74,146.34,0.033
52.74,146.41,0.033
52.75,146.48,0.033
52.76,146.54,0.033
52.76,146.61,0.033
52.77,146.68,0.033
52.78,146.74,0.033
52.78,146.81,0.033
52.79,146.88,0.033
52.80,146.94,0.033
52.80,147.01,0.033
52.81,147.08,0.033
52.82,147.14,0.033
52.82,147.21,0.033
52.83,147.28,0.033
52.84,147.34,0.033
52.84,147.41,0.033
52.85,147.48,0.033
52.86,147.54,0.033
52.86,147.61,0.033
52.87,147.68,0.033
52.88,147.74,0.033
52.88,147.81,0.033
52.89,147.88,0.033
52.90,147.94,0.033
52.90,148.01,0.033
52.91,148.08,0.033
52.92,148.14,0.033
52.92,148.21,0.033
52.93,148.28,0.033
52.94,148.34,0.033
52.94,148.41,0.033
52.95,148.48,0.033
52.96,148.54,0.033
52.96,148.61,0.033
52.97,148.68,0.033
52.98,148.75,0.033
52.98,148.81,0.033
52.99,148.88,0.033
53.00,148.95,0.033
53.00,149.01,0.033
53.01,149.08,0.033
53.02,149.14,0.033
53.02,149.21,0.033
53.03,149.28,0.033
53.04,149.34,0.033
53.04,149.41,0.033
53.05,149.48,0.033
53.06,149.55,0.033
53.06,149.61,0.033
53.07,149.68,0.033
53.08,149.75,0.033
53.08,149.81,0.033
53.09,149.88,0.033
53.10,149.95,0.033
53.10,150.01,0.033
53.11,150.08,0.033
53.12,150.15,0.033
53.12,150.21,0.033
53.13,150.28,0.033
53.14,150.35,0.033
53.14,150.41,0.033
53.15,150.48,0.033
53.16,150.55,0.033
53.16,150.61,0.033
53.17,150.68,0.033
53.18,150.75,0.033
53.18,150.81,0.033
53.19,150.88,0.033
53.20,150.95,0.033
53.20,151.01,0.033
53.21,151.08,0.033
53.22,151.15,0.033
53.22,151.21,0.033
53.23,151.28,0.033
53.24,151.35,0.033
53.24,151.41,0.033
53.25,151.48,0.033
53.26,151.55,0.033
53.26,151.61,0.033
53.27,151.68,0.033
53.28,151.75,0.033
53.28,151.81,0.033
53.29,151.88,0.033
53.30,151.95,0.033
53.30,152.01,0.033
53.31,152.08,0.033
53.32,152.14,0.033
53.32,152.21,0.033
53.33,152.28,0.033
53.34,152.35,0.033
53.34,152.41,0.033
53.35,152.48,0.033
53.36,152.55,0.033
53.36,152.61,0.033
53.37,152.68,0.033
53.38,152.75,0.033
53.38,152.81,0.033
53.39,152.88,0.033
53.40,152.95,0.033
53.40,153.01,0.033
53.41,153.08,0.033
53.42,153.15,0.033
53.42,153.21,0.033
53.43,153.28,0.033
53.44,153.35,0.033
53.44,153.41,0.033
53.45,153.48,0.033
53.46,153.55,0.033
53.46,153.61,0.033
53.47,153.68,0.033
53.48,153.75,0.033
53.48,153.81,0.033
53.49,153.88,0.033
53.50,153.95,0.033
53.50,154.01,0.033
53.51,154.08,0.033
53.52,154.15,0.033
53.52,154.22,0.033
53.53,154.28,0.033
53.54,154.35,0.033
53.54,154.42,0.033
53.55,154.48,0.033
53.56,154.55,0.033
53.56,154.62,0.033
53.57,154.68,0.033
53.58,154.75,0.033
53.58,154.82,0.033
53.59,154.88,0.033
53.60,154.95,0.033
53.60,155.02,0.033
53.61,155.08,0.033
53.62,155.15,0.033
53.62,155.22,0.033
53.63,155.28,0.033
53.64,155.35,0.033
53.64,155.42,0.033
53.65,155.48,0.034
53.66,155.55,0.034
53.66,155.62,0.034
53.67,155.68,0.034
53.68,155.75,0.034
53.68,155.82,0.034
53.69,155.89,0.034
53.70,155.95,0.034
53.70,156.02,0.034
53.71,156.08,0.034
53.72,156.15,0.034
53.72,156.22,0.034
53.73,156.28,0.034
53.74,156.35,0.034
53.74,156.42,0.034
53.75,156.48,0.034
53.76,156.55,0.034
53.76,156.62,0.035
53.77,156.68,0.039
53.78,156.75,0.081
53.78,156.81,0.215
53.79,156.85,0.447
53.80,156.89,0.667
53.80,156.92,0.847
53.81,156.95,1.005
53.82,156.98,1.148
53.82,157.01,1.286
53.83,157.04,1.418
53.84,157.07,1.549
53.84,157.09,1.676
53.85,157.12,1.805
53.86,157.15,1.933
53.86,157.18,2.058
53.87,157.20,2.186
53.88,157.23,2.312
53.88,157.26,2.438
53.89,157.28,2.563
53.90,157.31,2.689
53.90,157.34,2.813
53.91,157.37,2.937
53.92,157.40,3.058
53.92,157.42,3.176
53.93,157.45,3.283
53.94,157.48,3.349
53.94,157.52,3.336
53.95,157.57,3.216
53.96,157.64,2.809
53.96,157.75,2.139
53.97,157.88,1.637
53.98,158.02,1.345
53.98,158.15,1.147
53.99,158.28,1.000
54.00,158.41,0.885
54.00,158.53,0.792
54.01,158.64,0.712
54.02,158.75,0.641
54.02,158.86,0.579
54.03,158.96,0.524
54.04,159.06,0.477
54.04,159.16,0.432
54.05,159.25,0.392
54.06,159.34,0.357
54.06,159.43,0.326
54.07,159.52,0.297
54.08,159.60,0.272
54.08,159.68,0.248
54.09,159.76,0.226
54.10,159.84,0.208
54.10,159.92,0.190
54.11,160.00,0.175
54.12,160.07,0.161
54.12,160.15,0.148
54.13,160.22,0.137
54.14,160.29,0.126
54.14,160.37,0.117
54.15,160.44,0.109
54.16,160.51,0.101
54.16,160.58,0.095
54.17,160.65,0.088
54.18,160.72,0.082
54.18,160.79,0.078
54.19,160.86,0.073
54.20,160.93,0.068
54.20,161.00,0.066
54.21,161.07,0.062
54.22,161.14,0.059
54.22,161.20,0.057
54.23,161.27,0.054
54.24,161.34,0.051
54.24,161.41,0.050
54.25,161.48,0.048
54.26,161.54,0.047
54.26,161.61,0.046
54.27,161.68,0.044
54.28,161.75,0.044
54.28,161.81,0.043
54.29,161.88,0.042
54.30,161.95,0.041
54.30,162.02,0.040
54.31,162.08,0.040
54.32,162.15,0.039
54.32,162.22,0.039
54.33,162.28,0.039
54.34,162.35,0.038
54.34,162.42,0.037
54.35,162.48,0.037
54.36,162.55,0.037
54.36,162.62,0.037
54.37,162.69,0.037
54.38,162.75,0.036
54.38,162.82,0.036
54.39,162.89,0.036
54.40,162.95,0.036
54.40,163.02,0.036
54.41,163.09,0.036
54.42,163.15,0.036
54.42,163.22,0.035
54.43,163.29,0.035
54.44,163.36,0.035
54.44,163.42,0.035
54.45,163.49,0.035
54.46,163.56,0.035
54.46,163.62,0.035
54.47,163.69,0.035
54.48,163.75,0.035
54.48,163.82,0.035
54.49,163.89,0.035
54.50,163.96,0.035
54.50,164.02,0.035
54.51,164.09,0.035
54.52,164.16,0.035
54.52,164.22,0.035
54.53,164.29,0.035
54.54,164.35,0.034
54.54,164.42,0.034
54.55,164.49,0.034
54.56,164.55,0.034
54.56,164.62,0.034
54.57,164.69,0.034
54.58,164.76,0.034
54.58,164.82,0.034
54.59,164.89,0.034
54.60,164.96,0.034
54.60,165.02,0.034
54.61,165.09,0.034
54.62,165.16,0.034
54.62,165.22,0.034
54.63,165.29,0.034
54.64,165.36,0.034
54.64,165.42,0.034
54.65,165.49,0.034
54.66,165.56,0.034
54.66,165.62,0.034
54.67,165.69,0.034
54.68,165.75,0.034
54.68,165.82,0.034
54.69,165.89,0.034
54.70,165.96,0.034
54.70,166.02,0.034
54.71,166.09,0.034
54.72,166.16,0.034
54.72,166.22,0.034
54.73,166.29,0.034
54.74,166.36,0.034
54.74,166.42,0.034
54.75,166.49,0.034
54.76,166.56,0.034
54.76,166.62,0.034
54.77,166.69,0.034
54.78,166.76,0.034
54.78,166.82,0.034
54.79,166.89,0.034
54.80,166.96,0.034
54.80,167.02,0.034
54.81,167.09,0.033
54.82,167.16,0.033
54.82,167.22,0.033
54.83,167.29,0.033
54.84,167.36,0.033
54.84,167.42,0.033
54.85,167.49,0.033
54.86,167.56,0.033
54.86,167.62,0.033
54.87,167.69,0.033
54.88,167.76,0.033
54.88,167.83,0.033
54.89,167.89,0.033
54.90,167.96,0.033
54.90,168.03,0.033
54.91,168.09,0.033
54.92,168.16,0.033
54.92,168.23,0.033
54.93,168.29,0.033
54.94,168.36,0.033
54.94,168.43,0.033
54.95,168.49,0.033
54.96,168.56,0.033
54.96,168.63,0.033
54.97,168.69,0.033
54.98,168.76,0.033
54.98,168.83,0.033
54.99,168.89,0.033
55.00,168.96,0.033
55.00,169.03,0.033
55.01,169.09,0.033
55.02,169.16,0.033
55.02,169.23,0.033
55.03,169.29,0.033
55.04,169.36,0.033
55.04,169.43,0.033
55.05,169.49,0.033
55.06,169.56,0.033
55.06,169.62,0.033
55.07,169.69,0.033
55.08,169.76,0.033
55.08,169.83,0.033
55.09,169.89,0.033
55.10,169.96,0.033
55.10,170.03,0.033
55.11,170.09,0.033
55.12,170.16,0.033
55.12,170.23,0.033
55.13,170.29,0.033
55.14,170.36,0.033
55.14,170.43,0.033
55.15,170.49,0.033
55.16,170.56,0.033
55.16,170.62,0.033
55.17,170.69,0.033
55.18,170.76,0.033
55.18,170.83,0.033
55.19,170.89,0.033
55.20,170.96,0.033
55.20,171.03,0.033
55.21,171.09,0.033
55.22,171.16,0.033
55.22,171.23,0.033
55.23,171.29,0.033
55.24,171.36,0.033
55.24,171.43,0.033
55.25,171.49,0.033
55.26,171.56,0.033
55.26,171.63,0.033
55.27,171.69,0.033
55.28,171.76,0.033
55.28,171.83,0.033
55.29,171.89,0.033
55.30,171.96,0.033
55.30,172.03,0.033
55.31,172.09,0.033
55.32,172.16,0.033
55.32,172.23,0.033
55.33,172.29,0.033
55.34,172.36,0.033
55.34,172.43,0.033
55.35,172.50,0.033
55.36,172.56,0.033
55.36,172.63,0.033
55.37,172.69,0.033
55.38,172.76,0.033
55.38,172.83,0.033
55.39,172.89,0.033
55.40,172.96,0.033
55.40,173.03,0.033
55.41,173.09,0.033
55.42,173.16,0.033
55.42,173.23,0.033
55.43,173.30,0.033
55.44,173.36,0.033
55.44,173.43,0.033
55.45,173.50,0.033
55.46,173.56,0.033
55.46,173.63,0.033
55.47,173.69,0.033
55.48,173.76,0.033
55.48,173.83,0.033
55.49,173.89,0.033
55.50,173.96,0.033
55.50,174.03,0.033
55.51,174.09,0.033
55.52,174.16,0.033
55.52,174.23,0.033
55.53,174.30,0.033
55.54,174.36,0.033
55.54,174.43,0.033
55.55,174.49,0.033
55.56,174.56,0.033
55.56,174.63,0.033
55.57,174.69,0.033
55.58,174.76,0.033
55.58,174.83,0.033
55.59,174.90,0.033
55.60,174.96,0.033
55.60,175.03,0.033
55.61,175.10,0.033
55.62,175.16,0.033
55.62,175.23,0.033
55.63,175.30,0.033
55.64,175.36,0.033
55.64,175.43,0.033
55.65,175.50,0.033
55.66,175.56,0.033
55.66,175.63,0.033
55.67,175.70,0.033
55.68,175.76,0.033
55.68,175.83,0.033
55.69,175.90,0.033
55.70,175.96,0.033
55.70,176.03,0.033
55.71,176.10,0.033
55.72,176.16,0.033
55.72,176.23,0.033
55.73,176.30,0.033
55.74,176.36,0.033
55.74,176.43,0.033
55.75,176.50,0.033
55.76,176.56,0.033
55.76,176.63,0.033
55.77,176.70,0.033
55.78,176.76,0.033
55.78,176.83,0.033
55.79,176.90,0.033
55.80,176.96,0.033
55.80,177.03,0.033
55.81,177.10,0.033
55.82,177.16,0.033
55.82,177.23,0.033
55.83,177.30,0.033
55.84,177.37,0.033
55.84,177.43,0.033
55.85,177.50,0.033
55.86,177.57,0.033
55.86,177.63,0.033
55.87,177.70,0.033
55.88,177.76,0.033
55.88,177.83,0.033
55.89,177.90,0.033
55.90,177.96,0.033
55.90,178.03,0.033
55.91,178.10,0.033
55.92,178.17,0.033
55.92,178.23,0.033
55.93,178.30,0.033
55.94,178.37,0.033
55.94,178.43,0.033
55.95,178.50,0.033
55.96,178.57,0.033
55.96,178.63,0.033
55.97,178.70,0.033
55.98,178.77,0.033
55.98,178.83,0.033
55.99,178.90,0.033
56.00,178.97,0.033
56.00,179.03,0.033
56.01,179.10,0.033
56.02,179.17,0.033
56.02,179.23,0.033
56.03,179.30,0.033
56.04,179.37,0.033
56.04,179.43,0.033
56.05,179.50,0.033
56.06,179.57,0.033
56.06,179.63,0.033
56.07,179.70,0.033
56.08,179.77,0.033
56.08,179.83,0.033
56.09,179.90,0.033
56.10,179.97,0.033
56.10,180.03,0.033
56.11,180.10,0.033
56.12,180.17,0.033
56.12,180.23,0.033
56.13,180.30,0.033
56.14,180.37,0.033
56.14,180.43,0.033
56.15,180.50,0.033
56.16,180.57,0.033
56.16,180.63,0.033
56.17,180.70,0.033
56.18,180.77,0.033
56.18,180.83,0.033
56.19,180.90,0.033
56.20,180.97,0.033
56.20,181.03,0.033
56.21,181.10,0.033
56.22,181.17,0.033
56.22,181.23,0.033
56.23,181.30,0.033
56.24,181.37,0.033
56.24,181.43,0.033
56.25,181.50,0.033
56.26,181.57,0.033
56.26,181.63,0.033
56.27,181.70,0.033
56.28,181.77,0.033
56.28,181.83,0.033
56.29,181.90,0.033
56.30,181.97,0.033
56.30,182.03,0.033
56.31,182.10,0.033
56.32,182.17,0.033
56.32,182.24,0.033
56.33,182.30,0.033
56.34,182.37,0.033
56.34,182.44,0.033
56.35,182.50,0.033
56.36,182.57,0.033
56.36,182.64,0.033
56.37,182.70,0.033
56.38,182.77,0.033
56.38,182.84,0.033
56.39,182.90,0.033
56.40,182.97,0.033
56.40,183.04,0.033
56.41,183.10,0.033
56.42,183.17,0.033
56.42,183.24,0.033
56.43,183.30,0.033
56.44,183.37,0.033
56.44,183.44,0.033
56.45,183.50,0.033
56.46,183.57,0.033
56.46,183.64,0.033
56.47,183.70,0.033
56.48,183.77,0.033
56.48,183.83,0.033
56.49,183.90,0.033
56.50,183.97,0.033
56.50,184.04,0.033
56.51,184.10,0.033
56.52,184.17,0.033
56.52,184.24,0.033
56.53,184.30,0.033
56.54,184.37,0.033
56.54,184.44,0.033
56.55,184.50,0.033
56.56,184.57,0.033
56.56,184.64,0.033
56.57,184.70,0.033
56.58,184.77,0.033
56.58,184.83,0.033
56.59,184.90,0.033
56.60,184.97,0.033
56.60,185.03,0.033
56.61,185.10,0.033
56.62,185.17,0.033
56.62,185.24,0.033
56.63,185.30,0.033
56.64,185.37,0.033
56.64,185.43,0.033
56.65,185.50,0.033
56.66,185.57,0.033
56.66,185.64,0.033
56.67,185.70,0.033
56.68,185.77,0.033
56.68,185.84,0.033
56.69,185.90,0.033
56.70,185.97,0.033
56.70,186.04,0.033
56.71,186.10,0.033
56.72,186.17,0.033
56.72,186.24,0.033
56.73,186.30,0.033
56.74,186.37,0.033
56.74,186.44,0.033
56.75,186.50,0.033
56.76,186.57,0.033
56.76,186.64,0.033
56.77,186.70,0.033
56.78,186.77,0.033
56.78,186.84,0.033
56.79,186.90,0.033
56.80,186.97,0.033
56.80,187.04,0.033
56.81,187.11,0.033
56.82,187.17,0.033
56.82,187.24,0.033
56.83,187.31,0.033
56.84,187.37,0.033
56.84,187.44,0.033
56.85,187.51,0.033
56.86,187.57,0.033
56.86,187.64,0.033
56.87,187.71,0.033
56.88,187.77,0.033
56.88,187.84,0.033
56.89,187.91,0.033
56.90,187.97,0.033
56.90,188.04,0.033
56.91,188.11,0.033
56.92,188.17,0.033
56.92,188.24,0.033
56.93,188.31,0.033
56.94,188.37,0.033
56.94,188.44,0.033
56.95,188.51,0.033
56.96,188.57,0.033
56.96,188.64,0.033
56.97,188.71,0.033
56.98,188.77,0.033
56.98,188.84,0.033
56.99,188.91,0.033
57.00,188.97,0.033
57.00,189.04,0.033
57.01,189.11,0.033
57.02,189.17,0.033
57.02,189.24,0.033
57.03,189.31,0.033
57.04,189.37,0.033
57.04,189.44,0.033
57.05,189.51,0.033
57.06,189.57,0.033
57.06,189.64,0.033
57.07,189.71,0.033
57.08,189.77,0.033
57.08,189.84,0.033
57.09,189.91,0.033
57.10,189.97,0.033
57.10,190.04,0.033
57.11,190.11,0.033
57.12,190.17,0.033
57.12,190.24,0.033
57.13,190.30,0.033
57.14,190.37,0.033
57.14,190.44,0.033
57.15,190.51,0.033
57.16,190.57,0.033
57.16,190.64,0.033
57.17,190.71,0.033
57.18,190.77,0.033
57.18,190.84,0.033
57.19,190.91,0.033
57.20,190.97,0.033
57.20,191.04,0.033
57.21,191.11,0.033
57.22,191.17,0.033
57.22,191.24,0.033
57.23,191.31,0.033
57.24,191.37,0.033
57.24,191.44,0.033
57.25,191.51,0.033
57.26,191.57,0.033
57.26,191.64,0.033
57.27,191.71,0.033
57.28,191.77,0.033
57.28,191.84,0.033
57.29,191.91,0.033
57.30,191.97,0.033
57.30,192.04,0.033
57.31,192.11,0.033
57.32,192.17,0.033
57.32,192.24,0.033
57.33,192.31,0.033
57.34,192.37,0.033
57.34,192.44,0.033
57.35,192.51,0.033
57.36,192.57,0.033
57.36,192.64,0.033
57.37,192.71,0.033
57.38,192.77,0.033
57.38,192.84,0.033
57.39,192.91,0.033
57.40,192.97,0.033
57.40,193.04,0.033
57.41,193.11,0.033
57.42,193.17,0.033
57.42,193.24,0.033
57.43,193.31,0.033
57.44,193.37,0.033
57.44,193.44,0.033
57.45,193.51,0.033
57.46,193.57,0.033
57.46,193.64,0.033
57.47,193.71,0.033
57.48,193.77,0.033
57.48,193.84,0.033
57.49,193.91,0.033
57.50,193.97,0.033
57.50,194.04,0.033
57.51,194.11,0.033
57.52,194.17,0.033
57.52,194.24,0.033
57.53,194.31,0.033
57.54,194.37,0.033
57.54,194.44,0.033
57.55,194.51,0.033
57.56,194.58,0.033
57.56,194.64,0.033
57.57,194.71,0.033
57.58,194.78,0.033
57.58,194.84,0.033
57.59,194.91,0.033
57.60,194.97,0.033
57.60,195.04,0.033
57.61,195.11,0.033
57.62,195.18,0.034
57.62,195.24,0.034
57.63,195.31,0.034
57.64,195.38,0.034
57.64,195.44,0.034
57.65,195.51,0.034
57.66,195.58,0.034
57.66,195.64,0.034
57.67,195.71,0.034
57.68,195.78,0.034
57.68,195.84,0.034
57.69,195.91,0.034
57.70,195.98,0.034
57.70,196.04,0.034
57.71,196.11,0.034
57.72,196.18,0.034
57.72,196.24,0.034
57.73,196.31,0.034
57.74,196.38,0.034
57.74,196.44,0.034
57.75,196.51,0.034
57.76,196.58,0.034
57.76,196.64,0.034
57.77,196.71,0.034
57.78,196.78,0.034
57.78,196.84,0.034
57.79,196.91,0.034
57.80,196.98,0.034
57.80,197.04,0.034
57.81,197.11,0.034
57.82,197.18,0.034
57.82,197.24,0.034
57.83,197.31,0.034
57.84,197.38,0.034
57.84,197.44,0.034
57.85,197.51,0.034
57.86,197.58,0.034
57.86,197.64,0.034
57.87,197.71,0.034
57.88,197.78,0.034
57.88,197.84,0.034
57.89,197.91,0.034
57.90,197.98,0.034
57.90,198.04,0.034
57.91,198.11,0.034
57.92,198.18,0.034
57.92,198.24,0.034
57.93,198.31,0.034
57.94,198.38,0.034
57.94,198.44,
57.95,198.51,
57.96,198.58,
57.96,198.64,
57.97,198.71,
57.98,198.78,
57.98,198.84,
57.99,,
57.99,,