File: DSC/Olivia/2025_08_01_PVP29_n60C_200C_10Cmin_x3.csv
Filename,2025_08_01_PVP29_n60C_200C_10Cmin_x3
Instrument name,DSC2A-00468 (192.168.1.100)
Operator,Yarger
rundate,8/1/2025
Sample name,2025_08_01_PVP29_n60C_200C_10Cmin_x3
proceduresegments,Data Off ; Equilibrate -60.00 °C; Data On ; Ramp 10.00 °C/min to 200.00 °C; Data Off ; Isothermal 2.0 min; Data On ; Ramp 10.00 °C/min to -60.00 °C; Data Off ; Isothermal 2.0 min; Data On ; Ramp 10.00 °C/min to 200.00 °C; Data Off ; Isothermal 2.0 min; Data On ; Ramp 10.00 °C/min to -60.00 °C; Data Off ; Isothermal 2.0 min; Data On ; Ramp 10.00 °C/min to 200.00 °C
[File Parameters]
Run date,8/1/2025 6:35:13 PM
Trios version,5.1.1.46572
Original File Name,
Current File Name,D:\DSC2500\Gibbons\2025_08_01_PVP29_n60C_200C_10Cmin_x3.tri
[Procedure]
Procedure Name,PVP29_n60C_200C_10Cmin_x3
Sample Name,2025_08_01_PVP29_n60C_200C_10Cmin_x3
Sample Mass,8.79 mg
Reference Sample Mass,0 mg
Pan Mass,32.33 mg
Pan Number,44
Reference Pan Mass,32.52 mg
Reference Pan Number,37
Pan Type,Aluminum
Comments,Thermal support Al pans/lids. DSC_Samples_A2_Tray_July2025 google sheet.
Project Name,Pharma - Cocrystals
Operator,Yarger
Test,Custom
Unload Max Temperature,30
Unload Min Temperature,30
Load Max Temperature,30
Load Min Temperature,30
Stop on Gas Flow Error,Yes
[Signal List]
Signal #1,Time (min)
Signal #2,Temperature (°C)
Signal #3,Heat Flow (mW)
Signal #4,Delta T (µV)
Signal #5,Delta Tzero (µV)
Signal #6,Tzero Temperature (°C)
Signal #7,Cell Purge (mL/min)
Signal #8,Heater Temp (°C)
Signal #9,Power Delivered (W)
Signal #10,Reference Junction Temperature (°C)
Signal #11,Flange Temperature (°C)
Signal #12,Heat Flow Phase (rad)
Signal #13,Total Heat Capacity (J/°C)
Signal #14,Heat Capacity (J/°C)
[Configuration]
Company Name,ASU
Instrument Name,DSC2A-00468
Instrument Type,DSC2500
Serial Number,DSC2A-00468
IP,192.168.1.100
Location of Instrument,MRRC
DisplayType,Unknown
Sample Interval ,0.1 s/pt
Selected Heat Flow,T4P
Exotherm Direction,Down
Cell Serial,DRC2-00792
Lid Type,Standard
Cooler,RCS 90
Leave Cooler on at End of Sequence,On
Gas 2,Nitrogen
Gas Selected,Channel 1
Flow Rate,50 mL/min
Secondary Purge,On
Licensed Heat Flow,Heat Flow T4P
Modulation Licensed,Yes
[Versions]
Common IDD Version,1
Cortex Version,VER 2.10.2.31
Driver,5.0.0.6
GDM Version,1.0.3.3
TouchscreenVersion,1.0.0.16145
FEP Version,1.2.1.21
FEP Bootloader,2.0.0.5
AutoSampler Version,2.1.1.26
Auto Sampler Bootloader,2.0.0.5
FCM Version,1.1.0.3
FCM Bootloader,2.0.0.5
[Experiment Logs]
Experiment Log Entry # 1,Data On set to 0
Experiment Log Entry # 3,Equilibrate Segment -60 (C) Started
Experiment Log Entry # 5,Air Cool is off.
Experiment Log Entry # 7,Data On set to 1
Experiment Log Entry # 9,Ramp Segment 10 C/min to 200 Started
Experiment Log Entry # 11,Data On set to 0
Experiment Log Entry # 13,Isothermal Segment 2 min started
Experiment Log Entry # 15,Data On set to 1
Experiment Log Entry # 17,Ramp Segment 10 C/min to -60 Started
Experiment Log Entry # 19,Auto sampler has detected that GDM has gone offline
Experiment Log Entry # 21,Data On set to 0
Experiment Log Entry # 23,Isothermal Segment 2 min started
Experiment Log Entry # 25,Data On set to 1
Experiment Log Entry # 27,Ramp Segment 10 C/min to 200 Started
Experiment Log Entry # 29,Data On set to 0
Experiment Log Entry # 31,Isothermal Segment 2 min started
Experiment Log Entry # 33,Data On set to 1
Experiment Log Entry # 35,Ramp Segment 10 C/min to -60 Started
Experiment Log Entry # 37,Data On set to 0
Experiment Log Entry # 39,Isothermal Segment 2 min started
Experiment Log Entry # 41,Data On set to 1
Experiment Log Entry # 43,Ramp Segment 10 C/min to 200 Started
[Method Log]
Method Log Entry # 1,Data Off
Method Log Entry # 2,Equilibrate -60 °C
Method Log Entry # 3,Data On
Method Log Entry # 4,(Ramp 21218) Ramp 10 °C/minute to 200 °C
Method Log Entry # 5,Data Off
Method Log Entry # 6,Isothermal 2 minutes
Method Log Entry # 7,Data On
Method Log Entry # 8,(Ramp 21222) Ramp 10 °C/minute to -60 °C
Method Log Entry # 9,Data Off
Method Log Entry # 10,Isothermal 2 minutes
Method Log Entry # 11,Data On
Method Log Entry # 12,(Ramp 21226) Ramp 10 °C/minute to 200 °C
Method Log Entry # 13,Data Off
Method Log Entry # 14,Isothermal 2 minutes
Method Log Entry # 15,Data On
Method Log Entry # 16,(Ramp 21230) Ramp 10 °C/minute to -60 °C
Method Log Entry # 17,Data Off
Method Log Entry # 18,Isothermal 2 minutes
Method Log Entry # 19,Data On
Method Log Entry # 20,(Ramp 21234) Ramp 10 °C/minute to 200 °C
Cell Serial,DRC2-00792
[T1 Calibration]
Slope,-0.008529666
Offset,9.636258
Initial Temperature,98.23
GUID,f8bfdadc-4977-4fdf-ba6d-0ba9134940c3
[TZero Calibration]
Date Applied,11/29/2022 4:06:13 PM
Description,From -89.059 °C to 396.009 °C at 20.000°C/min
Gas Type,Nitrogen
Pan Type,None
Source Files 1,C:\Users\yargerlab\Desktop\DSC Data\General\TZero_calibration_11_29_22_2nd(2).tri
Source Files 2,C:\Users\yargerlab\Desktop\DSC Data\General\TZero_calibration_11_29_22_2nd(3).tri
Delta T Offset,13.05235
Delta T Slope,-0.007271007
Delta T0 Offset,-13.69128
Delta T0 Slope,0.06063341
[Temperature Calibration]
Date Applied,11/29/2022 7:12:28 PM
Description,From 106.590 °C to 186.590 °C at 10.000°C/min
Gas Type,Nitrogen
Pan Type,Tzero Aluminum Hermetic
Source Files 1,C:\Users\yargerlab\Desktop\DSC Data\General\Indium(6).tri
Measured 1,157.391
Known 1,156.598
[Cell Constant Calibration]
Date Applied,11/29/2022 7:12:29 PM
Description,From 106.590 °C to 186.590 °C at 10.000°C/min
Gas Type,Nitrogen
Pan Type,Tzero Aluminum Hermetic
Source Files 1,C:\Users\yargerlab\Desktop\DSC Data\General\Indium(6).tri
T4P KCell,1.006051
Onset Slope,63.26126 mW/°C
[Direct Cp Calibration]
Date Applied,11/30/2022 11:04:51 AM
Description,From -79.983 °C to 298.409 °C at 10.000°C/min
Gas Type,Nitrogen
Pan Type,Tzero Aluminum Hermetic
Source Files 1,C:\Users\yargerlab\Desktop\DSC Data\General\Sapphire_Heat_Capacity_11_30_22.tri
[Rev Cp Calibration]
Date Applied,11/30/2022 1:58:51 PM
Description,From -79.996 °C to 292.812 °C at 3.000°C/min
Gas Type,Nitrogen
Pan Type,Tzero Aluminum Hermetic
Source Files 1,C:\Users\yargerlab\Desktop\DSC Data\General\Sapphire_MDSC_Calibration_11_30_22.tri
[step]
Ramp 10.00 °C/min to 200.00 °C
Time,Temperature,Heat Flow (Normalized)
min,°C,W/g
0.00,-59.80,-0.044
0.02,-59.81,-0.041
0.04,-59.81,-0.038
0.05,-59.80,-0.038
0.07,-59.77,-0.040
0.09,-59.72,-0.041
0.11,-59.64,-0.040
0.13,-59.54,-0.024
0.15,-59.43,-0.007
0.16,-59.30,0.015
0.18,-59.15,0.038
0.20,-59.00,0.060
0.22,-58.85,0.081
0.24,-58.69,0.099
0.26,-58.52,0.114
0.28,-58.35,0.126
0.29,-58.19,0.136
0.31,-58.01,0.144
0.33,-57.84,0.152
0.35,-57.67,0.157
0.37,-57.50,0.161
0.39,-57.32,0.166
0.40,-57.14,0.168
0.42,-56.97,0.171
0.44,-56.79,0.174
0.46,-56.61,0.176
0.48,-56.44,0.177
0.50,-56.26,0.178
0.51,-56.08,0.180
0.53,-55.90,0.181
0.55,-55.72,0.182
0.57,-55.54,0.183
0.59,-55.36,0.183
0.60,-55.18,0.184
0.62,-55.00,0.185
0.64,-54.82,0.186
0.66,-54.64,0.187
0.68,-54.46,0.187
0.70,-54.28,0.187
0.72,-54.10,0.187
0.73,-53.92,0.188
0.75,-53.73,0.188
0.77,-53.55,0.189
0.79,-53.37,0.189
0.81,-53.19,0.189
0.83,-53.01,0.190
0.84,-52.83,0.190
0.86,-52.64,0.190
0.88,-52.46,0.191
0.90,-52.28,0.191
0.92,-52.10,0.191
0.93,-51.92,0.192
0.95,-51.73,0.192
0.97,-51.55,0.192
0.99,-51.37,0.192
1.01,-51.19,0.193
1.03,-51.00,0.193
1.05,-50.82,0.193
1.06,-50.64,0.193
1.08,-50.46,0.194
1.10,-50.28,0.194
1.12,-50.09,0.194
1.14,-49.91,0.194
1.16,-49.73,0.195
1.17,-49.55,0.195
1.19,-49.36,0.195
1.21,-49.18,0.195
1.23,-49.00,0.196
1.25,-48.81,0.196
1.27,-48.63,0.196
1.28,-48.45,0.196
1.30,-48.26,0.197
1.32,-48.08,0.197
1.34,-47.90,0.197
1.36,-47.72,0.197
1.38,-47.53,0.197
1.39,-47.35,0.198
1.41,-47.17,0.198
1.43,-46.98,0.198
1.45,-46.80,0.198
1.47,-46.62,0.198
1.48,-46.43,0.199
1.50,-46.25,0.199
1.52,-46.07,0.199
1.54,-45.89,0.199
1.56,-45.70,0.199
1.58,-45.52,0.200
1.59,-45.34,0.200
1.61,-45.15,0.200
1.63,-44.97,0.200
1.65,-44.78,0.200
1.67,-44.60,0.201
1.69,-44.42,0.201
1.71,-44.24,0.201
1.72,-44.05,0.201
1.74,-43.87,0.201
1.76,-43.69,0.201
1.78,-43.50,0.202
1.80,-43.32,0.202
1.82,-43.13,0.202
1.83,-42.95,0.202
1.85,-42.77,0.202
1.87,-42.58,0.202
1.89,-42.40,0.203
1.91,-42.22,0.203
1.93,-42.03,0.203
1.94,-41.85,0.203
1.96,-41.67,0.203
1.98,-41.48,0.203
2.00,-41.30,0.204
2.02,-41.11,0.204
2.03,-40.93,0.204
2.05,-40.75,0.204
2.07,-40.56,0.204
2.09,-40.38,0.204
2.11,-40.20,0.205
2.13,-40.02,0.205
2.14,-39.83,0.205
2.16,-39.65,0.205
2.18,-39.46,0.205
2.20,-39.28,0.205
2.22,-39.10,0.205
2.24,-38.91,0.205
2.26,-38.73,0.206
2.27,-38.55,0.206
2.29,-38.37,0.206
2.31,-38.18,0.206
2.33,-38.00,0.206
2.35,-37.81,0.206
2.36,-37.63,0.206
2.38,-37.45,0.206
2.40,-37.26,0.207
2.42,-37.08,0.207
2.44,-36.90,0.207
2.46,-36.71,0.207
2.48,-36.53,0.207
2.49,-36.35,0.207
2.51,-36.16,0.207
2.53,-35.98,0.208
2.55,-35.79,0.208
2.57,-35.61,0.208
2.59,-35.43,0.208
2.60,-35.24,0.208
2.62,-35.06,0.208
2.64,-34.88,0.209
2.66,-34.69,0.209
2.68,-34.51,0.209
2.69,-34.33,0.209
2.71,-34.14,0.209
2.73,-33.96,0.209
2.75,-33.78,0.209
2.77,-33.59,0.209
2.79,-33.41,0.210
2.81,-33.23,0.210
2.82,-33.04,0.210
2.84,-32.86,0.210
2.86,-32.68,0.210
2.88,-32.49,0.210
2.90,-32.31,0.210
2.91,-32.12,0.211
2.93,-31.94,0.211
2.95,-31.76,0.211
2.97,-31.57,0.211
2.99,-31.39,0.211
3.01,-31.21,0.211
3.03,-31.02,0.212
3.04,-30.84,0.212
3.06,-30.66,0.212
3.08,-30.47,0.212
3.10,-30.29,0.212
3.12,-30.10,0.212
3.14,-29.92,0.212
3.15,-29.74,0.213
3.17,-29.55,0.213
3.19,-29.37,0.213
3.21,-29.19,0.213
3.23,-29.01,0.213
3.24,-28.82,0.213
3.26,-28.64,0.213
3.28,-28.45,0.214
3.30,-28.27,0.214
3.32,-28.09,0.214
3.34,-27.90,0.214
3.36,-27.72,0.214
3.37,-27.54,0.214
3.39,-27.35,0.214
3.41,-27.17,0.215
3.43,-26.99,0.215
3.45,-26.80,0.215
3.46,-26.62,0.215
3.48,-26.44,0.215
3.50,-26.25,0.215
3.52,-26.07,0.216
3.54,-25.88,0.216
3.56,-25.70,0.216
3.58,-25.52,0.216
3.59,-25.33,0.216
3.61,-25.15,0.216
3.63,-24.97,0.217
3.65,-24.78,0.217
3.67,-24.60,0.217
3.69,-24.42,0.217
3.70,-24.23,0.217
3.72,-24.05,0.217
3.74,-23.87,0.218
3.76,-23.68,0.218
3.78,-23.50,0.218
3.79,-23.32,0.218
3.81,-23.13,0.218
3.83,-22.95,0.218
3.85,-22.77,0.218
3.87,-22.58,0.219
3.89,-22.40,0.219
3.91,-22.22,0.219
3.92,-22.03,0.219
3.94,-21.85,0.219
3.96,-21.67,0.219
3.98,-21.48,0.220
4.00,-21.30,0.220
4.01,-21.11,0.220
4.03,-20.93,0.220
4.05,-20.75,0.220
4.07,-20.56,0.220
4.09,-20.38,0.221
4.11,-20.20,0.221
4.13,-20.01,0.221
4.14,-19.83,0.221
4.16,-19.65,0.221
4.18,-19.46,0.221
4.20,-19.28,0.222
4.22,-19.10,0.222
4.24,-18.91,0.222
4.25,-18.73,0.222
4.27,-18.55,0.222
4.29,-18.36,0.222
4.31,-18.18,0.223
4.33,-18.00,0.223
4.35,-17.81,0.223
4.36,-17.63,0.223
4.38,-17.44,0.223
4.40,-17.26,0.224
4.42,-17.08,0.224
4.44,-16.89,0.224
4.45,-16.71,0.224
4.47,-16.53,0.224
4.49,-16.34,0.224
4.51,-16.16,0.225
4.53,-15.98,0.225
4.55,-15.79,0.225
4.56,-15.61,0.225
4.58,-15.43,0.225
4.60,-15.24,0.226
4.62,-15.06,0.226
4.64,-14.88,0.226
4.66,-14.69,0.226
4.68,-14.51,0.226
4.69,-14.33,0.226
4.71,-14.14,0.227
4.73,-13.96,0.227
4.75,-13.78,0.227
4.77,-13.59,0.227
4.79,-13.41,0.227
4.80,-13.23,0.228
4.82,-13.04,0.228
4.84,-12.86,0.228
4.86,-12.68,0.228
4.88,-12.49,0.228
4.90,-12.31,0.229
4.91,-12.13,0.229
4.93,-11.94,0.229
4.95,-11.76,0.229
4.97,-11.57,0.229
4.99,-11.39,0.229
5.00,-11.21,0.230
5.02,-11.02,0.230
5.04,-10.84,0.230
5.06,-10.66,0.230
5.08,-10.47,0.230
5.10,-10.29,0.231
5.11,-10.11,0.231
5.13,-9.92,0.231
5.15,-9.74,0.231
5.17,-9.56,0.231
5.19,-9.37,0.232
5.21,-9.19,0.232
5.23,-9.01,0.232
5.24,-8.82,0.232
5.26,-8.64,0.233
5.28,-8.45,0.233
5.30,-8.27,0.233
5.32,-8.09,0.233
5.34,-7.91,0.233
5.35,-7.72,0.234
5.37,-7.54,0.234
5.39,-7.35,0.234
5.41,-7.17,0.234
5.43,-6.99,0.234
5.45,-6.81,0.235
5.46,-6.62,0.235
5.48,-6.44,0.235
5.50,-6.26,0.235
5.52,-6.07,0.235
5.54,-5.89,0.236
5.55,-5.70,0.236
5.57,-5.52,0.236
5.59,-5.34,0.236
5.61,-5.15,0.236
5.63,-4.97,0.237
5.65,-4.79,0.237
5.66,-4.60,0.237
5.68,-4.42,0.237
5.70,-4.24,0.238
5.72,-4.05,0.238
5.74,-3.87,0.238
5.76,-3.69,0.238
5.78,-3.50,0.238
5.79,-3.32,0.239
5.81,-3.14,0.239
5.83,-2.95,0.239
5.85,-2.77,0.239
5.87,-2.58,0.240
5.89,-2.40,0.240
5.90,-2.22,0.240
5.92,-2.03,0.241
5.94,-1.85,0.241
5.96,-1.67,0.241
5.98,-1.48,0.241
6.00,-1.30,0.241
6.01,-1.12,0.242
6.03,-0.93,0.242
6.05,-0.75,0.242
6.07,-0.57,0.242
6.09,-0.38,0.243
6.10,-0.20,0.243
6.12,-0.02,0.243
6.14,0.17,0.243
6.16,0.35,0.243
6.18,0.53,0.244
6.20,0.72,0.244
6.21,0.90,0.244
6.23,1.08,0.245
6.25,1.27,0.245
6.27,1.45,0.245
6.29,1.64,0.245
6.31,1.82,0.246
6.33,2.00,0.246
6.34,2.19,0.246
6.36,2.37,0.246
6.38,2.55,0.246
6.40,2.73,0.247
6.42,2.92,0.247
6.44,3.10,0.247
6.45,3.28,0.247
6.47,3.47,0.248
6.49,3.65,0.248
6.51,3.83,0.248
6.53,4.02,0.248
6.55,4.20,0.249
6.56,4.38,0.249
6.58,4.57,0.249
6.60,4.75,0.249
6.62,4.93,0.250
6.64,5.12,0.250
6.65,5.30,0.250
6.67,5.49,0.251
6.69,5.67,0.251
6.71,5.85,0.251
6.73,6.04,0.251
6.75,6.22,0.252
6.76,6.40,0.252
6.78,6.59,0.252
6.80,6.77,0.253
6.82,6.95,0.253
6.84,7.14,0.253
6.86,7.32,0.253
6.88,7.50,0.254
6.89,7.69,0.254
6.91,7.87,0.254
6.93,8.05,0.255
6.95,8.24,0.255
6.97,8.42,0.255
6.99,8.61,0.255
7.00,8.79,0.256
7.02,8.97,0.256
7.04,9.15,0.256
7.06,9.34,0.257
7.08,9.52,0.257
7.10,9.71,0.257
7.11,9.89,0.257
7.13,10.07,0.258
7.15,10.26,0.258
7.17,10.44,0.259
7.19,10.62,0.259
7.20,10.81,0.259
7.22,10.99,0.259
7.24,11.17,0.260
7.26,11.36,0.260
7.28,11.54,0.260
7.30,11.72,0.261
7.31,11.91,0.261
7.33,12.09,0.261
7.35,12.27,0.262
7.37,12.46,0.262
7.39,12.64,0.262
7.41,12.82,0.263
7.43,13.01,0.263
7.44,13.19,0.263
7.46,13.37,0.264
7.48,13.55,0.264
7.50,13.74,0.264
7.52,13.92,0.265
7.54,14.11,0.265
7.55,14.29,0.265
7.57,14.47,0.266
7.59,14.66,0.266
7.61,14.84,0.266
7.63,15.02,0.267
7.65,15.21,0.267
7.66,15.39,0.267
7.68,15.57,0.268
7.70,15.76,0.268
7.72,15.94,0.269
7.74,16.12,0.269
7.75,16.31,0.269
7.77,16.49,0.269
7.79,16.67,0.270
7.81,16.86,0.270
7.83,17.04,0.271
7.85,17.22,0.271
7.86,17.41,0.271
7.88,17.59,0.272
7.90,17.77,0.272
7.92,17.96,0.272
7.94,18.14,0.273
7.96,18.32,0.273
7.98,18.51,0.274
7.99,18.69,0.274
8.01,18.87,0.274
8.03,19.06,0.275
8.05,19.24,0.275
8.07,19.42,0.275
8.09,19.61,0.276
8.10,19.79,0.276
8.12,19.97,0.277
8.14,20.16,0.277
8.16,20.34,0.278
8.18,20.52,0.278
8.20,20.71,0.279
8.21,20.89,0.279
8.23,21.07,0.280
8.25,21.25,0.280
8.27,21.44,0.280
8.29,21.62,0.281
8.30,21.80,0.281
8.32,21.99,0.282
8.34,22.17,0.282
8.36,22.36,0.282
8.38,22.54,0.283
8.40,22.72,0.284
8.41,22.91,0.284
8.43,23.09,0.285
8.45,23.27,0.286
8.47,23.45,0.286
8.49,23.64,0.287
8.51,23.82,0.287
8.53,24.00,0.287
8.54,24.19,0.288
8.56,24.37,0.288
8.58,24.55,0.289
8.60,24.74,0.289
8.62,24.92,0.290
8.63,25.10,0.290
8.65,25.29,0.291
8.67,25.47,0.293
8.69,25.65,0.294
8.71,25.84,0.294
8.73,26.02,0.295
8.75,26.20,0.295
8.76,26.39,0.296
8.78,26.57,0.296
8.80,26.75,0.297
8.82,26.94,0.297
8.84,27.12,0.297
8.85,27.30,0.298
8.87,27.48,0.299
8.89,27.67,0.299
8.91,27.85,0.299
8.93,28.03,0.300
8.95,28.22,0.301
8.97,28.40,0.301
8.98,28.58,0.302
9.00,28.77,0.302
9.02,28.95,0.303
9.04,29.13,0.303
9.06,29.32,0.304
9.08,29.50,0.305
9.09,29.68,0.305
9.11,29.87,0.306
9.13,30.05,0.307
9.15,30.23,0.307
9.17,30.42,0.308
9.18,30.60,0.309
9.20,30.78,0.309
9.22,30.96,0.310
9.24,31.15,0.311
9.26,31.33,0.312
9.28,31.52,0.312
9.30,31.70,0.313
9.31,31.88,0.314
9.33,32.06,0.315
9.35,32.25,0.315
9.37,32.43,0.316
9.39,32.61,0.317
9.40,32.80,0.317
9.42,32.98,0.319
9.44,33.16,0.319
9.46,33.35,0.320
9.48,33.53,0.320
9.50,33.71,0.321
9.52,33.90,0.322
9.53,34.08,0.323
9.55,34.26,0.324
9.57,34.45,0.325
9.59,34.63,0.325
9.61,34.81,0.326
9.63,34.99,0.327
9.64,35.18,0.328
9.66,35.36,0.329
9.68,35.54,0.330
9.70,35.73,0.331
9.72,35.91,0.332
9.73,36.09,0.333
9.75,36.28,0.334
9.77,36.46,0.335
9.79,36.64,0.336
9.81,36.83,0.336
9.83,37.01,0.337
9.85,37.19,0.338
9.86,37.38,0.339
9.88,37.56,0.340
9.90,37.74,0.341
9.92,37.92,0.342
9.94,38.11,0.343
9.95,38.29,0.344
9.97,38.47,0.345
9.99,38.66,0.346
10.01,38.84,0.347
10.03,39.02,0.349
10.05,39.20,0.349
10.07,39.39,0.351
10.08,39.57,0.352
10.10,39.75,0.354
10.12,39.94,0.355
10.14,40.12,0.356
10.16,40.30,0.357
10.18,40.49,0.358
10.19,40.67,0.360
10.21,40.85,0.362
10.23,41.03,0.363
10.25,41.22,0.364
10.27,41.40,0.366
10.28,41.58,0.367
10.30,41.77,0.369
10.32,41.95,0.371
10.34,42.13,0.372
10.36,42.31,0.374
10.38,42.50,0.375
10.40,42.68,0.377
10.41,42.86,0.378
10.43,43.04,0.380
10.45,43.23,0.382
10.47,43.41,0.384
10.49,43.59,0.386
10.50,43.78,0.387
10.52,43.96,0.389
10.54,44.14,0.391
10.56,44.32,0.394
10.58,44.50,0.395
10.60,44.69,0.397
10.62,44.87,0.399
10.63,45.05,0.401
10.65,45.23,0.403
10.67,45.42,0.405
10.69,45.60,0.407
10.71,45.78,0.409
10.73,45.96,0.411
10.74,46.15,0.413
10.76,46.33,0.415
10.78,46.51,0.418
10.80,46.69,0.420
10.82,46.88,0.421
10.83,47.06,0.424
10.85,47.24,0.425
10.87,47.42,0.427
10.89,47.61,0.429
10.91,47.79,0.431
10.93,47.97,0.432
10.95,48.15,0.434
10.96,48.34,0.435
10.98,48.52,0.436
11.00,48.70,0.438
11.02,48.88,0.439
11.04,49.07,0.441
11.05,49.25,0.442
11.07,49.43,0.443
11.09,49.62,0.444
11.11,49.80,0.445
11.13,49.98,0.446
11.15,50.16,0.447
11.17,50.35,0.448
11.18,50.53,0.449
11.20,50.71,0.449
11.22,50.90,0.450
11.24,51.08,0.451
11.26,51.26,0.451
11.28,51.44,0.452
11.29,51.63,0.452
11.31,51.81,0.453
11.33,51.99,0.453
11.35,52.18,0.454
11.37,52.36,0.455
11.38,52.54,0.455
11.40,52.73,0.456
11.42,52.91,0.456
11.44,53.09,0.456
11.46,53.28,0.457
11.48,53.46,0.457
11.50,53.64,0.458
11.51,53.83,0.458
11.53,54.01,0.458
11.55,54.19,0.459
11.57,54.38,0.459
11.59,54.56,0.460
11.60,54.74,0.461
11.62,54.93,0.462
11.64,55.11,0.462
11.66,55.29,0.463
11.68,55.48,0.464
11.70,55.66,0.465
11.72,55.84,0.467
11.73,56.03,0.468
11.75,56.21,0.469
11.77,56.39,0.470
11.79,56.58,0.471
11.81,56.76,0.473
11.83,56.94,0.475
11.84,57.12,0.477
11.86,57.31,0.478
11.88,57.49,0.480
11.90,57.67,0.482
11.92,57.85,0.483
11.93,58.04,0.485
11.95,58.22,0.487
11.97,58.40,0.489
11.99,58.59,0.491
12.01,58.77,0.493
12.03,58.95,0.495
12.05,59.13,0.497
12.06,59.31,0.499
12.08,59.50,0.501
12.10,59.68,0.503
12.12,59.86,0.505
12.14,60.04,0.507
12.15,60.23,0.509
12.17,60.41,0.511
12.19,60.59,0.513
12.21,60.77,0.515
12.23,60.96,0.517
12.25,61.14,0.519
12.27,61.32,0.522
12.28,61.50,0.523
12.30,61.69,0.526
12.32,61.87,0.527
12.34,62.05,0.530
12.36,62.23,0.531
12.38,62.41,0.533
12.39,62.60,0.535
12.41,62.78,0.537
12.43,62.96,0.539
12.45,63.14,0.541
12.47,63.33,0.543
12.48,63.51,0.545
12.50,63.69,0.547
12.52,63.87,0.549
12.54,64.06,0.551
12.56,64.24,0.552
12.58,64.42,0.555
12.60,64.60,0.556
12.61,64.79,0.558
12.63,64.97,0.559
12.65,65.15,0.562
12.67,65.33,0.564
12.69,65.52,0.566
12.70,65.70,0.567
12.72,65.88,0.569
12.74,66.06,0.571
12.76,66.25,0.573
12.78,66.43,0.575
12.80,66.61,0.577
12.82,66.80,0.579
12.83,66.98,0.581
12.85,67.16,0.583
12.87,67.34,0.585
12.89,67.53,0.587
12.91,67.71,0.589
12.93,67.89,0.591
12.94,68.07,0.593
12.96,68.25,0.595
12.98,68.44,0.597
13.00,68.62,0.599
13.02,68.80,0.601
13.03,68.98,0.603
13.05,69.17,0.605
13.07,69.35,0.607
13.09,69.53,0.610
13.11,69.71,0.612
13.13,69.90,0.614
13.15,70.08,0.616
13.16,70.26,0.618
13.18,70.44,0.620
13.20,70.63,0.622
13.22,70.81,0.625
13.24,71.00,0.628
13.25,71.18,0.631
13.27,71.36,0.634
13.29,71.55,0.636
13.31,71.73,0.639
13.33,71.91,0.640
13.35,72.09,0.642
13.37,72.27,0.643
13.38,72.46,0.645
13.40,72.64,0.647
13.42,72.82,0.649
13.44,73.00,0.651
13.46,73.18,0.654
13.48,73.37,0.655
13.49,73.55,0.658
13.51,73.73,0.661
13.53,73.91,0.663
13.55,74.09,0.666
13.57,74.28,0.668
13.58,74.46,0.670
13.60,74.64,0.673
13.62,74.82,0.675
13.64,75.00,0.677
13.66,75.19,0.680
13.68,75.37,0.683
13.70,75.55,0.685
13.71,75.73,0.688
13.73,75.91,0.691
13.75,76.10,0.694
13.77,76.28,0.697
13.79,76.46,0.699
13.80,76.64,0.702
13.82,76.82,0.705
13.84,77.01,0.708
13.86,77.19,0.710
13.88,77.37,0.713
13.90,77.55,0.716
13.92,77.73,0.719
13.93,77.92,0.721
13.95,78.10,0.725
13.97,78.28,0.728
13.99,78.46,0.731
14.01,78.65,0.733
14.03,78.83,0.737
14.04,79.01,0.739
14.06,79.19,0.742
14.08,79.37,0.745
14.10,79.55,0.748
14.12,79.74,0.751
14.13,79.92,0.754
14.15,80.10,0.757
14.17,80.28,0.759
14.19,80.46,0.762
14.21,80.64,0.766
14.23,80.83,0.769
14.25,81.01,0.772
14.26,81.19,0.775
14.28,81.37,0.778
14.30,81.55,0.781
14.32,81.74,0.784
14.34,81.92,0.788
14.35,82.10,0.791
14.37,82.28,0.794
14.39,82.46,0.798
14.41,82.65,0.800
14.43,82.83,0.804
14.45,83.01,0.807
14.47,83.19,0.810
14.48,83.37,0.813
14.50,83.55,0.817
14.52,83.74,0.820
14.54,83.92,0.824
14.56,84.10,0.827
14.58,84.28,0.831
14.59,84.46,0.834
14.61,84.64,0.838
14.63,84.83,0.841
14.65,85.01,0.845
14.67,85.19,0.848
14.68,85.37,0.852
14.70,85.55,0.855
14.72,85.73,0.860
14.74,85.91,0.863
14.76,86.10,0.866
14.78,86.28,0.870
14.80,86.46,0.874
14.81,86.64,0.877
14.83,86.82,0.882
14.85,87.00,0.885
14.87,87.19,0.889
14.89,87.37,0.893
14.90,87.55,0.898
14.92,87.73,0.901
14.94,87.91,0.905
14.96,88.10,0.909
14.98,88.28,0.912
15.00,88.46,0.916
15.02,88.64,0.920
15.03,88.82,0.924
15.05,89.00,0.929
15.07,89.18,0.932
15.09,89.36,0.936
15.11,89.55,0.941
15.13,89.73,0.945
15.14,89.91,0.948
15.16,90.09,0.953
15.18,90.27,0.957
15.20,90.45,0.961
15.22,90.63,0.965
15.23,90.82,0.969
15.25,91.00,0.974
15.27,91.18,0.978
15.29,91.36,0.983
15.31,91.54,0.987
15.33,91.72,0.991
15.35,91.90,0.996
15.36,92.09,1.000
15.38,92.27,1.005
15.40,92.45,1.008
15.42,92.63,1.013
15.44,92.81,1.017
15.45,92.99,1.021
15.47,93.17,1.026
15.49,93.35,1.030
15.51,93.53,1.034
15.53,93.71,1.038
15.55,93.90,1.044
15.57,94.08,1.048
15.58,94.26,1.053
15.60,94.44,1.057
15.62,94.62,1.062
15.64,94.80,1.066
15.66,94.98,1.071
15.68,95.17,1.076
15.69,95.35,1.081
15.71,95.53,1.085
15.73,95.71,1.090
15.75,95.89,1.094
15.77,96.07,1.099
15.78,96.25,1.103
15.80,96.43,1.108
15.82,96.62,1.112
15.84,96.79,1.117
15.86,96.98,1.122
15.88,97.16,1.126
15.90,97.34,1.130
15.91,97.52,1.135
15.93,97.70,1.140
15.95,97.88,1.144
15.97,98.06,1.149
15.99,98.24,1.154
16.00,98.42,1.158
16.02,98.61,1.164
16.04,98.79,1.168
16.06,98.97,1.173
16.08,99.15,1.177
16.10,99.33,1.182
16.12,99.51,1.187
16.13,99.69,1.192
16.15,99.87,1.196
16.17,100.05,1.200
16.19,100.24,1.205
16.21,100.42,1.209
16.23,100.60,1.214
16.24,100.78,1.219
16.26,100.96,1.222
16.28,101.14,1.227
16.30,101.32,1.232
16.32,101.50,1.236
16.33,101.68,1.241
16.35,101.87,1.245
16.37,102.05,1.250
16.39,102.23,1.254
16.41,102.41,1.258
16.43,102.59,1.263
16.45,102.77,1.266
16.46,102.95,1.271
16.48,103.14,1.275
16.50,103.32,1.279
16.52,103.50,1.283
16.54,103.68,1.287
16.55,103.86,1.291
16.57,104.04,1.295
16.59,104.22,1.298
16.61,104.40,1.302
16.63,104.59,1.306
16.65,104.77,1.309
16.67,104.95,1.313
16.68,105.13,1.317
16.70,105.31,1.320
16.72,105.49,1.324
16.74,105.68,1.327
16.76,105.86,1.330
16.78,106.04,1.334
16.79,106.22,1.336
16.81,106.40,1.339
16.83,106.59,1.343
16.85,106.77,1.346
16.87,106.95,1.348
16.88,107.13,1.351
16.90,107.31,1.353
16.92,107.50,1.356
16.94,107.68,1.358
16.96,107.86,1.361
16.98,108.04,1.363
17.00,108.22,1.365
17.01,108.41,1.367
17.03,108.59,1.369
17.05,108.77,1.371
17.07,108.96,1.373
17.09,109.14,1.375
17.11,109.32,1.376
17.12,109.50,1.377
17.14,109.69,1.378
17.16,109.87,1.379
17.18,110.05,1.381
17.20,110.23,1.381
17.22,110.42,1.382
17.23,110.60,1.382
17.25,110.78,1.383
17.27,110.97,1.384
17.29,111.15,1.384
17.31,111.33,1.384
17.33,111.52,1.384
17.34,111.70,1.385
17.36,111.88,1.385
17.38,112.07,1.385
17.40,112.25,1.385
17.42,112.43,1.385
17.43,112.62,1.385
17.45,112.80,1.385
17.47,112.99,1.385
17.49,113.17,1.384
17.51,113.36,1.384
17.53,113.54,1.383
17.54,113.73,1.381
17.56,113.91,1.379
17.58,114.09,1.377
17.60,114.28,1.375
17.62,114.46,1.373
17.64,114.65,1.371
17.66,114.83,1.369
17.67,115.02,1.366
17.69,115.20,1.363
17.71,115.39,1.361
17.73,115.57,1.358
17.75,115.76,1.354
17.77,115.94,1.352
17.78,116.13,1.349
17.80,116.31,1.346
17.82,116.50,1.342
17.84,116.68,1.339
17.86,116.87,1.335
17.88,117.05,1.331
17.89,117.24,1.328
17.91,117.43,1.323
17.93,117.61,1.320
17.95,117.80,1.315
17.97,117.98,1.311
17.98,118.17,1.307
18.00,118.35,1.302
18.02,118.54,1.298
18.04,118.73,1.294
18.06,118.91,1.289
18.08,119.10,1.283
18.09,119.29,1.279
18.11,119.47,1.273
18.13,119.66,1.268
18.15,119.84,1.263
18.17,120.03,1.256
18.19,120.22,1.252
18.21,120.40,1.246
18.22,120.59,1.240
18.24,120.78,1.235
18.26,120.96,1.229
18.28,121.15,1.224
18.30,121.34,1.218
18.32,121.52,1.212
18.33,121.71,1.207
18.35,121.90,1.200
18.37,122.08,1.194
18.39,122.27,1.188
18.41,122.46,1.182
18.43,122.64,1.175
18.44,122.83,1.169
18.46,123.02,1.162
18.48,123.21,1.156
18.50,123.39,1.149
18.52,123.58,1.143
18.53,123.77,1.136
18.55,123.95,1.130
18.57,124.14,1.123
18.59,124.33,1.117
18.61,124.52,1.109
18.63,124.70,1.103
18.64,124.89,1.096
18.66,125.08,1.089
18.68,125.27,1.082
18.70,125.45,1.075
18.72,125.64,1.069
18.74,125.83,1.061
18.76,126.01,1.054
18.77,126.20,1.047
18.79,126.39,1.040
18.81,126.58,1.033
18.83,126.76,1.026
18.85,126.95,1.019
18.87,127.14,1.011
18.88,127.32,1.004
18.90,127.51,0.998
18.92,127.70,0.990
18.94,127.89,0.983
18.96,128.08,0.976
18.98,128.26,0.969
18.99,128.45,0.962
19.01,128.64,0.955
19.03,128.82,0.947
19.05,129.01,0.940
19.07,129.20,0.933
19.08,129.39,0.926
19.10,129.57,0.919
19.12,129.76,0.912
19.14,129.95,0.905
19.16,130.14,0.898
19.18,130.32,0.891
19.19,130.51,0.884
19.21,130.70,0.878
19.23,130.89,0.870
19.25,131.07,0.864
19.27,131.26,0.857
19.29,131.45,0.849
19.31,131.63,0.842
19.32,131.82,0.836
19.34,132.01,0.829
19.36,132.20,0.822
19.38,132.38,0.815
19.40,132.57,0.809
19.42,132.76,0.802
19.43,132.95,0.796
19.45,133.13,0.789
19.47,133.32,0.782
19.49,133.51,0.776
19.51,133.69,0.769
19.53,133.88,0.763
19.54,134.07,0.757
19.56,134.25,0.750
19.58,134.44,0.744
19.60,134.63,0.738
19.62,134.81,0.732
19.63,135.00,0.726
19.65,135.19,0.719
19.67,135.37,0.713
19.69,135.56,0.706
19.71,135.75,0.700
19.73,135.93,0.695
19.74,136.12,0.688
19.76,136.31,0.683
19.78,136.49,0.677
19.80,136.68,0.671
19.82,136.87,0.665
19.84,137.05,0.660
19.86,137.24,0.654
19.87,137.43,0.649
19.89,137.61,0.643
19.91,137.80,0.638
19.93,137.98,0.633
19.95,138.17,0.627
19.97,138.36,0.622
19.98,138.54,0.617
20.00,138.73,0.612
20.02,138.92,0.607
20.04,139.10,0.602
20.06,139.29,0.597
20.08,139.48,0.592
20.09,139.66,0.588
20.11,139.85,0.583
20.13,140.04,0.577
20.15,140.22,0.573
20.17,140.41,0.568
20.18,140.59,0.563
20.20,140.78,0.558
20.22,140.97,0.555
20.24,141.15,0.550
20.26,141.34,0.545
20.28,141.52,0.540
20.29,141.71,0.536
20.31,141.89,0.532
20.33,142.08,0.528
20.35,142.26,0.523
20.37,142.45,0.519
20.39,142.64,0.515
20.41,142.82,0.512
20.42,143.01,0.508
20.44,143.20,0.505
20.46,143.38,0.501
20.48,143.57,0.497
20.50,143.75,0.493
20.52,143.94,0.489
20.53,144.12,0.485
20.55,144.31,0.482
20.57,144.49,0.478
20.59,144.68,0.474
20.61,144.86,0.471
20.63,145.05,0.468
20.64,145.23,0.465
20.66,145.42,0.461
20.68,145.61,0.458
20.70,145.79,0.455
20.72,145.98,0.452
20.73,146.16,0.449
20.75,146.35,0.446
20.77,146.53,0.443
20.79,146.72,0.440
20.81,146.90,0.438
20.83,147.09,0.434
20.84,147.27,0.432
20.86,147.46,0.429
20.88,147.64,0.427
20.90,147.83,0.425
20.92,148.01,0.422
20.94,148.20,0.420
20.96,148.38,0.418
20.97,148.57,0.415
20.99,148.75,0.413
21.01,148.94,0.411
21.03,149.12,0.409
21.05,149.30,0.407
21.07,149.49,0.405
21.08,149.67,0.402
21.10,149.86,0.401
21.12,150.04,0.399
21.14,150.23,0.397
21.16,150.41,0.396
21.18,150.60,0.394
21.19,150.78,0.393
21.21,150.97,0.392
21.23,151.15,0.390
21.25,151.33,0.388
21.27,151.52,0.387
21.28,151.70,0.386
21.30,151.89,0.384
21.32,152.07,0.383
21.34,152.25,0.382
21.36,152.44,0.380
21.38,152.62,0.379
21.39,152.81,0.378
21.41,152.99,0.377
21.43,153.17,0.376
21.45,153.36,0.376
21.47,153.54,0.374
21.49,153.73,0.373
21.51,153.91,0.373
21.52,154.09,0.371
21.54,154.28,0.370
21.56,154.46,0.369
21.58,154.65,0.369
21.60,154.83,0.368
21.62,155.01,0.367
21.63,155.20,0.366
21.65,155.38,0.365
21.67,155.57,0.364
21.69,155.75,0.364
21.71,155.94,0.363
21.73,156.12,0.362
21.74,156.30,0.361
21.76,156.49,0.360
21.78,156.67,0.359
21.80,156.86,0.359
21.82,157.04,0.358
21.83,157.22,0.357
21.85,157.41,0.356
21.87,157.59,0.355
21.89,157.78,0.355
21.91,157.96,0.353
21.93,158.15,0.351
21.94,158.33,0.350
21.96,158.51,0.349
21.98,158.70,0.348
22.00,158.88,0.346
22.02,159.06,0.345
22.04,159.25,0.344
22.06,159.43,0.343
22.07,159.62,0.342
22.09,159.80,0.341
22.11,159.98,0.340
22.13,160.17,0.339
22.15,160.35,0.339
22.17,160.54,0.337
22.18,160.72,0.336
22.20,160.90,0.335
22.22,161.09,0.335
22.24,161.27,0.334
22.26,161.46,0.334
22.28,161.64,0.333
22.29,161.82,0.333
22.31,162.01,0.332
22.33,162.19,0.331
22.35,162.38,0.331
22.37,162.56,0.330
22.38,162.74,0.330
22.40,162.93,0.329
22.42,163.11,0.328
22.44,163.29,0.328
22.46,163.48,0.328
22.48,163.66,0.327
22.49,163.85,0.327
22.51,164.03,0.327
22.53,164.21,0.326
22.55,164.40,0.326
22.57,164.58,0.326
22.59,164.76,0.325
22.61,164.95,0.325
22.62,165.13,0.325
22.64,165.31,0.324
22.66,165.50,0.324
22.68,165.68,0.324
22.70,165.86,0.323
22.72,166.05,0.323
22.73,166.23,0.323
22.75,166.41,0.323
22.77,166.60,0.322
22.79,166.78,0.322
22.81,166.97,0.322
22.83,167.15,0.322
22.84,167.33,0.322
22.86,167.52,0.321
22.88,167.70,0.321
22.90,167.88,0.321
22.92,168.07,0.321
22.93,168.25,0.321
22.95,168.43,0.321
22.97,168.62,0.320
22.99,168.80,0.320
23.01,168.98,0.320
23.03,169.17,0.320
23.04,169.35,0.320
23.06,169.53,0.320
23.08,169.72,0.320
23.10,169.90,0.320
23.12,170.08,0.320
23.14,170.27,0.319
23.16,170.45,0.319
23.17,170.63,0.319
23.19,170.82,0.319
23.21,171.00,0.319
23.23,171.19,0.319
23.25,171.37,0.319
23.27,171.55,0.319
23.28,171.74,0.319
23.30,171.92,0.319
23.32,172.10,0.319
23.34,172.29,0.319
23.36,172.47,0.319
23.38,172.65,0.320
23.39,172.84,0.320
23.41,173.02,0.320
23.43,173.20,0.320
23.45,173.39,0.320
23.47,173.57,0.320
23.48,173.75,0.320
23.50,173.94,0.320
23.52,174.12,0.320
23.54,174.30,0.320
23.56,174.49,0.320
23.58,174.67,0.320
23.59,174.86,0.320
23.61,175.04,0.320
23.63,175.22,0.320
23.65,175.41,0.320
23.67,175.59,0.321
23.69,175.77,0.321
23.71,175.96,0.321
23.72,176.14,0.321
23.74,176.32,0.321
23.76,176.51,0.321
23.78,176.69,0.321
23.80,176.87,0.321
23.82,177.06,0.321
23.83,177.24,0.322
23.85,177.42,0.322
23.87,177.61,0.322
23.89,177.79,0.322
23.91,177.97,0.322
23.93,178.16,0.322
23.94,178.34,0.322
23.96,178.52,0.322
23.98,178.71,0.322
24.00,178.89,0.322
24.02,179.07,0.323
24.03,179.26,0.323
24.05,179.44,0.323
24.07,179.62,0.323
24.09,179.81,0.323
24.11,179.99,0.323
24.13,180.17,0.323
24.14,180.36,0.323
24.16,180.54,0.324
24.18,180.72,0.324
24.20,180.91,0.324
24.22,181.09,0.324
24.24,181.27,0.324
24.26,181.46,0.324
24.27,181.64,0.324
24.29,181.82,0.324
24.31,182.01,0.325
24.33,182.19,0.325
24.35,182.37,0.325
24.37,182.56,0.325
24.38,182.74,0.325
24.40,182.93,0.325
24.42,183.11,0.326
24.44,183.29,0.326
24.46,183.48,0.326
24.48,183.66,0.326
24.49,183.84,0.326
24.51,184.03,0.326
24.53,184.21,0.326
24.55,184.39,0.326
24.57,184.58,0.327
24.58,184.76,0.327
24.60,184.94,0.327
24.62,185.13,0.327
24.64,185.31,0.327
24.66,185.49,0.327
24.68,185.68,0.327
24.69,185.86,0.327
24.71,186.04,0.328
24.73,186.23,0.328
24.75,186.41,0.328
24.77,186.59,0.328
24.79,186.78,0.328
24.81,186.96,0.328
24.82,187.15,0.329
24.84,187.33,0.329
24.86,187.51,0.329
24.88,187.70,0.329
24.90,187.88,0.329
24.92,188.06,0.329
24.93,188.25,0.330
24.95,188.43,0.330
24.97,188.61,0.330
24.99,188.80,0.330
25.01,188.98,0.330
25.03,189.16,0.330
25.04,189.35,0.330
25.06,189.53,0.330
25.08,189.71,0.331
25.10,189.90,0.331
25.12,190.08,0.331
25.13,190.26,0.331
25.15,190.45,0.331
25.17,190.63,0.331
25.19,190.81,0.331
25.21,191.00,0.332
25.23,191.18,0.332
25.24,191.36,0.332
25.26,191.55,0.332
25.28,191.73,0.332
25.30,191.91,0.332
25.32,192.10,0.333
25.34,192.28,0.333
25.36,192.46,0.333
25.37,192.65,0.333
25.39,192.83,0.333
25.41,193.01,0.334
25.43,193.20,0.334
25.45,193.38,0.334
25.47,193.56,0.334
25.48,193.75,0.334
25.50,193.93,0.335
25.52,194.11,0.335
25.54,194.30,0.335
25.56,194.48,0.335
25.58,194.66,0.335
25.59,194.85,0.335
25.61,195.03,0.336
25.63,195.21,0.336
25.65,195.40,0.336
25.67,195.58,0.336
25.68,195.76,0.336
25.70,195.95,0.337
25.72,196.13,0.337
25.74,196.31,0.337
25.76,196.50,0.337
25.78,196.68,0.337
25.79,196.86,0.338
25.81,197.05,0.338
25.83,197.23,0.338
25.85,197.41,0.338
25.87,197.60,0.338
25.89,197.78,0.339
25.91,197.97,0.339
25.92,198.15,0.339
25.94,198.33,
25.96,198.51,
25.98,198.70,
25.99,,

[step]
Ramp 10.00 °C/min to -60.00 °C
Time,Temperature,Heat Flow (Normalized)
min,°C,W/g
27.99,200.15,0.001
28.01,200.15,0.001
28.03,200.14,0.001
28.05,200.13,0.001
28.07,200.10,0.003
28.08,200.05,0.000
28.10,199.98,-0.026
28.12,199.88,-0.061
28.14,199.76,-0.104
28.16,199.62,-0.147
28.18,199.47,-0.186
28.19,199.32,-0.218
28.21,199.16,-0.243
28.23,199.00,-0.263
28.25,198.83,-0.276
28.27,198.66,-0.288
28.29,198.49,-0.297
28.31,198.31,-0.303
28.32,198.14,-0.309
28.34,197.96,-0.313
28.36,197.78,-0.317
28.38,197.60,-0.321
28.40,197.42,-0.323
28.42,197.24,-0.325
28.43,197.06,-0.327
28.45,196.88,-0.329
28.47,196.70,-0.329
28.49,196.52,-0.330
28.51,196.34,-0.331
28.53,196.16,-0.331
28.54,195.97,-0.332
28.56,195.79,-0.332
28.58,195.61,-0.332
28.60,195.43,-0.332
28.62,195.25,-0.333
28.63,195.07,-0.333
28.65,194.89,-0.333
28.67,194.70,-0.333
28.69,194.52,-0.333
28.71,194.34,-0.334
28.73,194.16,-0.334
28.74,193.98,-0.334
28.76,193.79,-0.334
28.78,193.61,-0.334
28.80,193.43,-0.335
28.82,193.25,-0.335
28.84,193.07,-0.335
28.86,192.88,-0.335
28.87,192.70,-0.336
28.89,192.52,-0.336
28.91,192.34,-0.336
28.93,192.15,-0.336
28.95,191.97,-0.336
28.97,191.79,-0.337
28.98,191.60,-0.337
29.00,191.42,-0.337
29.02,191.24,-0.337
29.04,191.06,-0.337
29.06,190.87,-0.337
29.08,190.69,-0.338
29.09,190.51,-0.338
29.11,190.33,-0.338
29.13,190.14,-0.338
29.15,189.96,-0.338
29.17,189.78,-0.338
29.18,189.60,-0.338
29.20,189.41,-0.338
29.22,189.23,-0.338
29.24,189.05,-0.339
29.26,188.86,-0.339
29.28,188.68,-0.339
29.29,188.50,-0.339
29.31,188.32,-0.339
29.33,188.13,-0.339
29.35,187.95,-0.339
29.37,187.77,-0.339
29.39,187.58,-0.339
29.41,187.40,-0.339
29.42,187.22,-0.339
29.44,187.03,-0.340
29.46,186.85,-0.340
29.48,186.67,-0.340
29.50,186.49,-0.340
29.52,186.30,-0.340
29.53,186.12,-0.340
29.55,185.94,-0.340
29.57,185.75,-0.340
29.59,185.57,-0.340
29.61,185.39,-0.340
29.63,185.20,-0.340
29.64,185.02,-0.340
29.66,184.84,-0.340
29.68,184.66,-0.340
29.70,184.47,-0.340
29.72,184.29,-0.340
29.73,184.11,-0.340
29.75,183.92,-0.340
29.77,183.74,-0.340
29.79,183.56,-0.340
29.81,183.37,-0.340
29.83,183.19,-0.340
29.84,183.01,-0.340
29.86,182.82,-0.340
29.88,182.64,-0.340
29.90,182.46,-0.340
29.92,182.28,-0.340
29.94,182.09,-0.340
29.96,181.91,-0.340
29.97,181.73,-0.340
29.99,181.54,-0.340
30.01,181.36,-0.340
30.03,181.17,-0.340
30.05,180.99,-0.340
30.07,180.81,-0.340
30.08,180.63,-0.341
30.10,180.44,-0.340
30.12,180.26,-0.341
30.14,180.07,-0.340
30.16,179.89,-0.340
30.18,179.71,-0.340
30.19,179.53,-0.340
30.21,179.34,-0.340
30.23,179.16,-0.340
30.25,178.98,-0.340
30.27,178.79,-0.340
30.28,178.61,-0.340
30.30,178.43,-0.340
30.32,178.24,-0.340
30.34,178.06,-0.340
30.36,177.88,-0.340
30.38,177.69,-0.340
30.39,177.51,-0.340
30.41,177.33,-0.340
30.43,177.14,-0.340
30.45,176.96,-0.340
30.47,176.78,-0.340
30.49,176.59,-0.340
30.51,176.41,-0.340
30.52,176.23,-0.340
30.54,176.04,-0.340
30.56,175.86,-0.340
30.58,175.68,-0.340
30.60,175.49,-0.340
30.62,175.31,-0.340
30.63,175.13,-0.340
30.65,174.94,-0.340
30.67,174.76,-0.340
30.69,174.58,-0.340
30.71,174.39,-0.340
30.73,174.21,-0.340
30.74,174.03,-0.340
30.76,173.85,-0.339
30.78,173.66,-0.339
30.80,173.48,-0.339
30.82,173.30,-0.339
30.83,173.11,-0.339
30.85,172.93,-0.339
30.87,172.75,-0.339
30.89,172.56,-0.339
30.91,172.38,-0.339
30.93,172.20,-0.339
30.94,172.01,-0.339
30.96,171.83,-0.339
30.98,171.65,-0.339
31.00,171.46,-0.339
31.02,171.28,-0.339
31.04,171.10,-0.339
31.06,170.91,-0.339
31.07,170.73,-0.339
31.09,170.55,-0.339
31.11,170.36,-0.338
31.13,170.18,-0.338
31.15,170.00,-0.338
31.17,169.81,-0.338
31.18,169.63,-0.338
31.20,169.45,-0.338
31.22,169.26,-0.338
31.24,169.08,-0.338
31.26,168.90,-0.338
31.28,168.71,-0.338
31.29,168.53,-0.338
31.31,168.35,-0.338
31.33,168.16,-0.338
31.35,167.98,-0.337
31.37,167.80,-0.337
31.38,167.61,-0.337
31.40,167.43,-0.337
31.42,167.25,-0.337
31.44,167.06,-0.337
31.46,166.88,-0.337
31.48,166.70,-0.337
31.49,166.51,-0.337
31.51,166.33,-0.337
31.53,166.15,-0.337
31.55,165.96,-0.337
31.57,165.78,-0.336
31.59,165.60,-0.336
31.61,165.41,-0.336
31.62,165.23,-0.336
31.64,165.05,-0.336
31.66,164.86,-0.336
31.68,164.68,-0.336
31.70,164.50,-0.335
31.72,164.31,-0.335
31.73,164.13,-0.335
31.75,163.95,-0.335
31.77,163.77,-0.335
31.79,163.58,-0.334
31.81,163.40,-0.334
31.83,163.22,-0.334
31.84,163.03,-0.334
31.86,162.85,-0.334
31.88,162.67,-0.333
31.90,162.48,-0.333
31.92,162.30,-0.333
31.93,162.11,-0.333
31.95,161.93,-0.333
31.97,161.75,-0.333
31.99,161.56,-0.332
32.01,161.38,-0.332
32.03,161.20,-0.332
32.04,161.01,-0.332
32.06,160.83,-0.331
32.08,160.65,-0.331
32.10,160.46,-0.331
32.12,160.28,-0.331
32.14,160.10,-0.330
32.16,159.91,-0.330
32.17,159.73,-0.330
32.19,159.55,-0.329
32.21,159.36,-0.329
32.23,159.18,-0.328
32.25,159.00,-0.328
32.27,158.81,-0.327
32.28,158.63,-0.327
32.30,158.45,-0.327
32.32,158.26,-0.327
32.34,158.08,-0.326
32.36,157.90,-0.326
32.38,157.71,-0.326
32.39,157.53,-0.325
32.41,157.35,-0.325
32.43,157.16,-0.324
32.45,156.98,-0.324
32.47,156.79,-0.324
32.48,156.61,-0.323
32.50,156.43,-0.323
32.52,156.24,-0.323
32.54,156.06,-0.323
32.56,155.88,-0.322
32.58,155.69,-0.322
32.59,155.51,-0.321
32.61,155.33,-0.321
32.63,155.14,-0.320
32.65,154.96,-0.319
32.67,154.78,-0.319
32.69,154.59,-0.319
32.71,154.41,-0.318
32.72,154.23,-0.318
32.74,154.04,-0.318
32.76,153.86,-0.317
32.78,153.68,-0.317
32.80,153.49,-0.316
32.82,153.31,-0.316
32.83,153.13,-0.316
32.85,152.94,-0.315
32.87,152.76,-0.315
32.89,152.57,-0.315
32.91,152.39,-0.314
32.93,152.21,-0.314
32.94,152.03,-0.313
32.96,151.84,-0.313
32.98,151.66,-0.312
33.00,151.47,-0.312
33.02,151.29,-0.312
33.03,151.11,-0.311
33.05,150.93,-0.311
33.07,150.74,-0.310
33.09,150.56,-0.310
33.11,150.37,-0.309
33.13,150.19,-0.309
33.14,150.01,-0.309
33.16,149.82,-0.308
33.18,149.64,-0.308
33.20,149.46,-0.308
33.22,149.27,-0.307
33.24,149.09,-0.307
33.26,148.91,-0.306
33.27,148.72,-0.306
33.29,148.54,-0.305
33.31,148.36,-0.305
33.33,148.17,-0.305
33.35,147.99,-0.305
33.37,147.81,-0.304
33.38,147.62,-0.304
33.40,147.44,-0.304
33.42,147.26,-0.304
33.44,147.07,-0.303
33.46,146.89,-0.303
33.48,146.71,-0.302
33.49,146.52,-0.302
33.51,146.34,-0.302
33.53,146.15,-0.302
33.55,145.97,-0.301
33.57,145.79,-0.301
33.58,145.60,-0.301
33.60,145.42,-0.300
33.62,145.24,-0.300
33.64,145.05,-0.300
33.66,144.87,-0.300
33.68,144.69,-0.299
33.69,144.50,-0.299
33.71,144.32,-0.299
33.73,144.14,-0.298
33.75,143.95,-0.298
33.77,143.77,-0.298
33.79,143.59,-0.298
33.81,143.40,-0.297
33.82,143.22,-0.297
33.84,143.04,-0.297
33.86,142.85,-0.296
33.88,142.67,-0.296
33.90,142.49,-0.296
33.92,142.30,-0.295
33.93,142.12,-0.295
33.95,141.94,-0.295
33.97,141.75,-0.295
33.99,141.57,-0.294
34.01,141.39,-0.294
34.03,141.21,-0.294
34.04,141.02,-0.294
34.06,140.84,-0.293
34.08,140.65,-0.293
34.10,140.47,-0.293
34.12,140.29,-0.293
34.14,140.10,-0.293
34.15,139.92,-0.292
34.17,139.74,-0.292
34.19,139.55,-0.292
34.21,139.37,-0.292
34.23,139.19,-0.291
34.24,139.00,-0.291
34.26,138.82,-0.291
34.28,138.64,-0.291
34.30,138.46,-0.290
34.32,138.27,-0.290
34.34,138.09,-0.290
34.36,137.90,-0.290
34.37,137.72,-0.289
34.39,137.54,-0.289
34.41,137.35,-0.289
34.43,137.17,-0.289
34.45,136.98,-0.288
34.46,136.80,-0.288
34.48,136.62,-0.288
34.50,136.44,-0.288
34.52,136.25,-0.288
34.54,136.07,-0.287
34.56,135.89,-0.287
34.58,135.70,-0.287
34.59,135.52,-0.287
34.61,135.34,-0.287
34.63,135.15,-0.286
34.65,134.97,-0.286
34.67,134.79,-0.286
34.69,134.60,-0.286
34.70,134.42,-0.286
34.72,134.24,-0.286
34.74,134.05,-0.286
34.76,133.87,-0.285
34.78,133.69,-0.285
34.79,133.50,-0.285
34.81,133.32,-0.285
34.83,133.14,-0.285
34.85,132.95,-0.285
34.87,132.77,-0.284
34.89,132.59,-0.284
34.91,132.40,-0.284
34.92,132.22,-0.284
34.94,132.04,-0.284
34.96,131.85,-0.284
34.98,131.67,-0.283
35.00,131.49,-0.283
35.01,131.30,-0.283
35.03,131.12,-0.283
35.05,130.94,-0.283
35.07,130.75,-0.283
35.09,130.57,-0.283
35.11,130.39,-0.282
35.13,130.20,-0.282
35.14,130.02,-0.282
35.16,129.84,-0.282
35.18,129.65,-0.282
35.20,129.47,-0.282
35.22,129.29,-0.282
35.24,129.10,-0.282
35.25,128.92,-0.281
[...]
119.22,10.90,0.171
119.24,11.09,0.171
119.26,11.27,0.171
119.28,11.45,0.171
119.29,11.63,0.171
119.31,11.82,0.171
119.33,12.00,0.171
119.35,12.19,0.172
119.37,12.37,0.172
119.39,12.55,0.172
119.40,12.74,0.172
119.42,12.92,0.172
119.44,13.10,0.172
119.46,13.29,0.172
119.48,13.47,0.172
119.50,13.65,0.172
119.51,13.84,0.172
119.53,14.02,0.173
119.55,14.21,0.173
119.57,14.39,0.173
119.59,14.57,0.173
119.60,14.76,0.173
119.62,14.94,0.173
119.64,15.12,0.173
119.66,15.31,0.173
119.68,15.49,0.173
119.70,15.67,0.173
119.71,15.86,0.174
119.73,16.04,0.174
119.75,16.22,0.174
119.77,16.40,0.174
119.79,16.59,0.174
119.81,16.77,0.174
119.83,16.96,0.174
119.84,17.14,0.174
119.86,17.32,0.174
119.88,17.51,0.174
119.90,17.69,0.175
119.92,17.87,0.175
119.94,18.06,0.175
119.95,18.24,0.175
119.97,18.42,0.175
119.99,18.61,0.175
120.01,18.79,0.175
120.03,18.97,0.175
120.05,19.16,0.175
120.06,19.34,0.176
120.08,19.53,0.176
120.10,19.71,0.176
120.12,19.89,0.176
120.14,20.08,0.176
120.15,20.26,0.176
120.17,20.44,0.176
120.19,20.63,0.176
120.21,20.81,0.176
120.23,20.99,0.177
120.25,21.18,0.177
120.26,21.36,0.177
120.28,21.54,0.177
120.30,21.73,0.177
120.32,21.91,0.177
120.34,22.09,0.177
120.36,22.28,0.177
120.38,22.46,0.177
120.39,22.65,0.177
120.41,22.83,0.178
120.43,23.01,0.178
120.45,23.20,0.178
120.47,23.38,0.178
120.49,23.56,0.178
120.50,23.75,0.178
120.52,23.93,0.178
120.54,24.11,0.178
120.56,24.30,0.178
120.58,24.48,0.179
120.60,24.66,0.179
120.61,24.85,0.179
120.63,25.03,0.179
120.65,25.21,0.179
120.67,25.40,0.179
120.69,25.58,0.179
120.70,25.76,0.179
120.72,25.95,0.179
120.74,26.13,0.180
120.76,26.32,0.180
120.78,26.50,0.180
120.80,26.68,0.180
120.81,26.87,0.180
120.83,27.05,0.180
120.85,27.23,0.180
120.87,27.42,0.180
120.89,27.60,0.180
120.91,27.78,0.181
120.93,27.97,0.181
120.94,28.15,0.181
120.96,28.33,0.181
120.98,28.52,0.181
121.00,28.70,0.181
121.02,28.88,0.181
121.04,29.07,0.181
121.05,29.25,0.181
121.07,29.43,0.181
121.09,29.62,0.182
121.11,29.80,0.182
121.13,29.98,0.182
121.15,30.17,0.182
121.16,30.35,0.182
121.18,30.54,0.182
121.20,30.72,0.182
121.22,30.90,0.182
121.24,31.09,0.182
121.25,31.27,0.183
121.27,31.45,0.183
121.29,31.64,0.183
121.31,31.82,0.183
121.33,32.00,0.183
121.35,32.19,0.183
121.36,32.37,0.183
121.38,32.55,0.183
121.40,32.74,0.183
121.42,32.92,0.183
121.44,33.11,0.184
121.46,33.29,0.184
121.48,33.47,0.184
121.49,33.66,0.184
121.51,33.84,0.184
121.53,34.02,0.184
121.55,34.21,0.184
121.57,34.39,0.184
121.59,34.57,0.185
121.60,34.76,0.185
121.62,34.94,0.185
121.64,35.12,0.185
121.66,35.31,0.185
121.68,35.49,0.185
121.70,35.68,0.185
121.71,35.86,0.185
121.73,36.04,0.185
121.75,36.23,0.185
121.77,36.41,0.186
121.79,36.59,0.186
121.80,36.78,0.186
121.82,36.96,0.186
121.84,37.14,0.186
121.86,37.33,0.186
121.88,37.51,0.186
121.90,37.69,0.186
121.91,37.88,0.186
121.93,38.06,0.186
121.95,38.24,0.187
121.97,38.43,0.187
121.99,38.61,0.187
122.01,38.80,0.187
122.03,38.98,0.187
122.04,39.17,0.187
122.06,39.35,0.187
122.08,39.53,0.187
122.10,39.71,0.188
122.12,39.90,0.188
122.14,40.08,0.188
122.15,40.26,0.188
122.17,40.45,0.188
122.19,40.63,0.188
122.21,40.81,0.188
122.23,41.00,0.188
122.25,41.18,0.188
122.26,41.36,0.188
122.28,41.55,0.188
122.30,41.73,0.188
122.32,41.91,0.189
122.34,42.10,0.189
122.35,42.28,0.189
122.37,42.47,0.189
122.39,42.65,0.189
122.41,42.83,0.189
122.43,43.02,0.189
122.45,43.20,0.189
122.46,43.38,0.189
122.48,43.57,0.189
122.50,43.75,0.190
122.52,43.93,0.190
122.54,44.12,0.190
122.56,44.30,0.190
122.58,44.48,0.190
122.59,44.67,0.190
122.61,44.85,0.190
122.63,45.03,0.190
122.65,45.22,0.190
122.67,45.40,0.191
122.69,45.58,0.191
122.70,45.77,0.191
122.72,45.95,0.191
122.74,46.14,0.191
122.76,46.32,0.191
122.78,46.50,0.191
122.80,46.68,0.191
122.81,46.87,0.191
122.83,47.05,0.192
122.85,47.24,0.192
122.87,47.42,0.192
122.89,47.60,0.192
122.90,47.79,0.192
122.92,47.97,0.192
122.94,48.15,0.192
122.96,48.34,0.192
122.98,48.52,0.192
123.00,48.70,0.192
123.01,48.89,0.193
123.03,49.07,0.193
123.05,49.25,0.193
123.07,49.44,0.193
123.09,49.62,0.193
123.11,49.80,0.193
123.13,49.99,0.193
123.14,50.17,0.193
123.16,50.35,0.193
123.18,50.54,0.194
123.20,50.72,0.194
123.22,50.90,0.194
123.24,51.09,0.194
123.25,51.27,0.194
123.27,51.46,0.194
123.29,51.64,0.194
123.31,51.82,0.194
123.33,52.01,0.194
123.35,52.19,0.194
123.36,52.37,0.195
123.38,52.56,0.195
123.40,52.74,0.195
123.42,52.92,0.195
123.44,53.11,0.195
123.45,53.29,0.195
123.47,53.47,0.195
123.49,53.66,0.195
123.51,53.84,0.195
123.53,54.02,0.195
123.55,54.21,0.196
123.56,54.39,0.196
123.58,54.58,0.196
123.60,54.76,0.196
123.62,54.94,0.196
123.64,55.13,0.196
123.66,55.31,0.196
123.68,55.49,0.196
123.69,55.68,0.196
123.71,55.86,0.197
123.73,56.04,0.197
123.75,56.23,0.197
123.77,56.41,0.197
123.79,56.59,0.197
123.80,56.78,0.197
123.82,56.96,0.197
123.84,57.14,0.197
123.86,57.33,0.197
123.88,57.51,0.197
123.90,57.69,0.197
123.91,57.88,0.198
123.93,58.06,0.198
123.95,58.24,0.198
123.97,58.43,0.198
123.99,58.61,0.198
124.00,58.79,0.198
124.02,58.98,0.198
124.04,59.16,0.198
124.06,59.35,0.198
124.08,59.53,0.199
124.10,59.71,0.199
124.11,59.90,0.199
124.13,60.08,0.199
124.15,60.26,0.199
124.17,60.45,0.199
124.19,60.63,0.199
124.21,60.81,0.199
124.23,61.00,0.199
124.24,61.18,0.199
124.26,61.36,0.200
124.28,61.55,0.200
124.30,61.73,0.200
124.32,61.92,0.200
124.34,62.10,0.200
124.35,62.28,0.200
124.37,62.47,0.200
124.39,62.65,0.200
124.41,62.83,0.200
124.43,63.02,0.201
124.45,63.20,0.201
124.46,63.38,0.201
124.48,63.57,0.201
124.50,63.75,0.201
124.52,63.93,0.201
124.54,64.12,0.201
124.55,64.30,0.201
124.57,64.49,0.201
124.59,64.67,0.201
124.61,64.85,0.201
124.63,65.03,0.202
124.65,65.22,0.202
124.66,65.40,0.202
124.68,65.58,0.202
124.70,65.77,0.202
124.72,65.95,0.202
124.74,66.13,0.202
124.76,66.32,0.202
124.78,66.50,0.202
124.79,66.68,0.202
124.81,66.87,0.202
124.83,67.05,0.202
124.85,67.23,0.203
124.87,67.42,0.203
124.89,67.60,0.203
124.90,67.78,0.203
124.92,67.97,0.203
124.94,68.15,0.203
124.96,68.34,0.203
124.98,68.52,0.203
125.00,68.70,0.204
125.01,68.89,0.204
125.03,69.07,0.204
125.05,69.25,0.204
125.07,69.44,0.204
125.09,69.62,0.204
125.10,69.80,0.204
125.12,69.99,0.204
125.14,70.17,0.205
125.16,70.35,0.205
125.18,70.54,0.205
125.20,70.72,0.205
125.21,70.91,0.205
125.23,71.09,0.205
125.25,71.27,0.205
125.27,71.46,0.205
125.29,71.64,0.205
125.31,71.82,0.205
125.33,72.01,0.206
125.34,72.19,0.206
125.36,72.37,0.206
125.38,72.56,0.206
125.40,72.74,0.206
125.42,72.92,0.206
125.44,73.11,0.206
125.45,73.29,0.206
125.47,73.47,0.206
125.49,73.66,0.206
125.51,73.84,0.207
125.53,74.02,0.207
125.55,74.21,0.207
125.56,74.39,0.207
125.58,74.57,0.207
125.60,74.76,0.207
125.62,74.94,0.207
125.64,75.13,0.207
125.65,75.31,0.207
125.67,75.49,0.207
125.69,75.68,0.208
125.71,75.86,0.208
125.73,76.04,0.208
125.75,76.23,0.208
125.76,76.41,0.208
125.78,76.59,0.208
125.80,76.78,0.208
125.82,76.96,0.208
125.84,77.14,0.209
125.86,77.33,0.209
125.88,77.51,0.209
125.89,77.70,0.209
125.91,77.88,0.209
125.93,78.06,0.209
125.95,78.25,0.209
125.97,78.43,0.209
125.99,78.61,0.209
126.00,78.80,0.209
126.02,78.98,0.210
126.04,79.16,0.210
126.06,79.35,0.210
126.08,79.53,0.210
126.10,79.71,0.210
126.11,79.90,0.210
126.13,80.08,0.210
126.15,80.26,0.210
126.17,80.45,0.210
126.19,80.63,0.211
126.20,80.81,0.211
126.22,81.00,0.211
126.24,81.18,0.211
126.26,81.36,0.211
126.28,81.55,0.211
126.30,81.73,0.211
126.31,81.91,0.211
126.33,82.10,0.211
126.35,82.28,0.211
126.37,82.46,0.211
126.39,82.65,0.211
126.41,82.83,0.212
126.43,83.02,0.212
126.44,83.20,0.212
126.46,83.38,0.212
126.48,83.57,0.212
126.50,83.75,0.212
126.52,83.93,0.212
126.54,84.12,0.212
126.55,84.30,0.212
126.57,84.48,0.212
126.59,84.67,0.212
126.61,84.85,0.213
126.63,85.03,0.213
126.65,85.22,0.213
126.66,85.40,0.213
126.68,85.58,0.213
126.70,85.77,0.213
126.72,85.95,0.213
126.74,86.13,0.213
126.75,86.32,0.213
126.77,86.50,0.214
126.79,86.68,0.214
126.81,86.87,0.214
126.83,87.05,0.214
126.85,87.23,0.214
126.86,87.42,0.214
126.88,87.60,0.214
126.90,87.78,0.214
126.92,87.97,0.214
126.94,88.15,0.214
126.96,88.34,0.215
126.98,88.52,0.215
126.99,88.70,0.215
127.01,88.89,0.215
127.03,89.07,0.215
127.05,89.25,0.215
127.07,89.44,0.215
127.09,89.62,0.215
127.10,89.80,0.215
127.12,89.99,0.216
127.14,90.17,0.216
127.16,90.35,0.216
127.18,90.54,0.216
127.20,90.72,0.216
127.21,90.90,0.216
127.23,91.09,0.216
127.25,91.27,0.216
127.27,91.45,0.216
127.29,91.64,0.217
127.30,91.82,0.217
127.32,92.00,0.217
127.34,92.19,0.217
127.36,92.37,0.217
127.38,92.55,0.217
127.40,92.74,0.217
127.41,92.92,0.217
127.43,93.10,0.218
127.45,93.29,0.218
127.47,93.47,0.218
127.49,93.66,0.218
127.51,93.84,0.218
127.53,94.02,0.218
127.54,94.21,0.218
127.56,94.39,0.218
127.58,94.57,0.218
127.60,94.76,0.219
127.62,94.94,0.219
127.64,95.12,0.219
127.65,95.31,0.219
127.67,95.49,0.219
127.69,95.67,0.219
127.71,95.86,0.219
127.73,96.04,0.219
127.75,96.22,0.219
127.76,96.41,0.220
127.78,96.59,0.220
127.80,96.77,0.220
127.82,96.96,0.220
127.84,97.14,0.220
127.85,97.32,0.220
127.87,97.51,0.220
127.89,97.69,0.220
127.91,97.88,0.220
127.93,98.06,0.221
127.95,98.24,0.221
127.96,98.43,0.221
127.98,98.61,0.221
128.00,98.79,0.221
128.02,98.98,0.221
128.04,99.16,0.221
128.06,99.34,0.221
128.08,99.53,0.222
128.09,99.71,0.222
128.11,99.90,0.222
128.13,100.08,0.222
128.15,100.26,0.222
128.17,100.44,0.222
128.19,100.63,0.222
128.20,100.81,0.222
128.22,100.99,0.222
128.24,101.18,0.222
128.26,101.36,0.222
128.28,101.54,0.223
128.30,101.73,0.223
128.31,101.91,0.223
128.33,102.09,0.223
128.35,102.28,0.223
128.37,102.46,0.223
128.39,102.65,0.223
128.40,102.83,0.223
128.42,103.01,0.223
128.44,103.20,0.224
128.46,103.38,0.224
128.48,103.56,0.224
128.50,103.75,0.224
128.51,103.93,0.224
128.53,104.11,0.224
128.55,104.30,0.224
128.57,104.48,0.224
128.59,104.66,0.225
128.61,104.85,0.225
128.63,105.03,0.225
128.64,105.21,0.225
128.66,105.40,0.225
128.68,105.58,0.225
128.70,105.76,0.225
128.72,105.95,0.225
128.74,106.13,0.225
128.75,106.31,0.225
128.77,106.50,0.225
128.79,106.68,0.226
128.81,106.86,0.226
128.83,107.05,0.226
128.85,107.23,0.226
128.86,107.41,0.226
128.88,107.60,0.226
128.90,107.78,0.226
128.92,107.96,0.226
128.94,108.15,0.226
128.95,108.33,0.227
128.97,108.51,0.227
128.99,108.70,0.227
129.01,108.88,0.227
129.03,109.06,0.227
129.05,109.25,0.227
129.06,109.43,0.227
129.08,109.61,0.227
129.10,109.80,0.227
129.12,109.98,0.227
129.14,110.17,0.228
129.16,110.35,0.228
129.18,110.53,0.228
129.19,110.72,0.228
129.21,110.90,0.228
129.23,111.08,0.228
129.25,111.27,0.228
129.27,111.45,0.228
129.29,111.63,0.228
129.30,111.82,0.229
129.32,112.00,0.229
129.34,112.18,0.229
129.36,112.37,0.229
129.38,112.55,0.229
129.40,112.74,0.229
129.41,112.92,0.229
129.43,113.10,0.229
129.45,113.29,0.229
129.47,113.47,0.230
129.49,113.65,0.230
129.50,113.84,0.230
129.52,114.02,0.230
129.54,114.20,0.230
129.56,114.39,0.230
129.58,114.57,0.230
129.60,114.75,0.230
129.61,114.94,0.230
129.63,115.12,0.231
129.65,115.30,0.231
129.67,115.49,0.231
129.69,115.67,0.231
129.71,115.85,0.231
129.73,116.04,0.231
129.74,116.22,0.231
129.76,116.41,0.231
129.78,116.59,0.231
129.80,116.77,0.231
129.82,116.96,0.232
129.84,117.14,0.232
129.85,117.32,0.232
129.87,117.51,0.232
129.89,117.69,0.232
129.91,117.87,0.232
129.93,118.05,0.232
129.95,118.24,0.232
129.96,118.42,0.232
129.98,118.61,0.232
130.00,118.79,0.233
130.02,118.97,0.233
130.04,119.16,0.233
130.05,119.34,0.233
130.07,119.52,0.233
130.09,119.71,0.233
130.11,119.89,0.233
130.13,120.07,0.233
130.15,120.26,0.234
130.16,120.44,0.234
130.18,120.62,0.234
130.20,120.81,0.234
130.22,120.99,0.234
130.24,121.17,0.234
130.26,121.36,0.234
130.28,121.54,0.234
130.29,121.73,0.234
130.31,121.91,0.234
130.33,122.09,0.235
130.35,122.28,0.235
130.37,122.46,0.235
130.39,122.64,0.235
130.40,122.83,0.235
130.42,123.01,0.235
130.44,123.19,0.235
130.46,123.38,0.235
130.48,123.56,0.235
130.50,123.74,0.236
130.51,123.93,0.236
130.53,124.11,0.236
130.55,124.29,0.236
130.57,124.48,0.236
130.59,124.66,0.236
130.60,124.84,0.236
130.62,125.03,0.236
130.64,125.21,0.236
130.66,125.40,0.236
130.68,125.58,0.236
130.70,125.76,0.237
130.71,125.95,0.237
130.73,126.13,0.237
130.75,126.31,0.237
130.77,126.50,0.237
130.79,126.68,0.237
130.81,126.86,0.237
130.83,127.05,0.237
130.84,127.23,0.237
130.86,127.41,0.237
130.88,127.60,0.238
130.90,127.78,0.238
130.92,127.96,0.238
130.94,128.15,0.238
130.95,128.33,0.238
130.97,128.51,0.238
130.99,128.70,0.238
131.01,128.88,0.238
131.03,129.06,0.238
131.05,129.25,0.239
131.06,129.43,0.239
131.08,129.61,0.239
131.10,129.80,0.239
131.12,129.98,0.239
131.14,130.16,0.239
131.15,130.35,0.239
131.17,130.53,0.239
131.19,130.71,0.240
131.21,130.90,0.240
131.23,131.08,0.240
131.25,131.26,0.240
131.26,131.45,0.240
131.28,131.63,0.240
131.30,131.81,0.240
131.32,132.00,0.240
131.34,132.18,0.240
131.36,132.36,0.241
131.38,132.55,0.241
131.39,132.73,0.241
131.41,132.91,0.241
131.43,133.10,0.241
131.45,133.28,0.241
131.47,133.46,0.241
131.49,133.65,0.241
131.50,133.83,0.241
131.52,134.02,0.242
131.54,134.20,0.242
131.56,134.38,0.242
131.58,134.57,0.242
131.60,134.75,0.242
131.61,134.93,0.242
131.63,135.11,0.242
131.65,135.30,0.242
131.67,135.48,0.242
131.69,135.67,0.243
131.70,135.85,0.243
131.72,136.03,0.243
131.74,136.22,0.243
131.76,136.40,0.243
131.78,136.58,0.243
131.80,136.77,0.243
131.81,136.95,0.243
131.83,137.13,0.244
131.85,137.32,0.244
131.87,137.50,0.244
131.89,137.68,0.244
131.91,137.87,0.244
131.93,138.05,0.244
131.94,138.23,0.244
131.96,138.42,0.244
131.98,138.60,0.244
132.00,138.78,0.245
132.02,138.97,0.245
132.04,139.15,0.245
132.05,139.34,0.245
132.07,139.52,0.245
132.09,139.70,0.245
132.11,139.89,0.245
132.13,140.07,0.246
132.15,140.25,0.246
132.16,140.44,0.246
132.18,140.62,0.246
132.20,140.80,0.246
132.22,140.99,0.246
132.24,141.17,0.246
132.25,141.35,0.246
132.27,141.54,0.247
132.29,141.72,0.247
132.31,141.90,0.247
132.33,142.09,0.247
132.35,142.27,0.247
132.36,142.45,0.247
132.38,142.64,0.247
132.40,142.82,0.248
132.42,143.00,0.248
132.44,143.19,0.248
132.46,143.37,0.248
132.48,143.56,0.248
132.49,143.74,0.248
132.51,143.92,0.248
132.53,144.11,0.249
132.55,144.29,0.249
132.57,144.47,0.249
132.59,144.66,0.249
132.60,144.84,0.249
132.62,145.02,0.249
132.64,145.20,0.249
132.66,145.39,0.250
132.68,145.57,0.250
132.70,145.75,0.250
132.71,145.94,0.250
132.73,146.12,0.250
132.75,146.30,0.250
132.77,146.49,0.250
132.79,146.67,0.251
132.80,146.86,0.251
132.82,147.04,0.251
132.84,147.22,0.251
132.86,147.41,0.251
132.88,147.59,0.252
132.90,147.77,0.252
132.91,147.96,0.252
132.93,148.14,0.252
132.95,148.32,0.252
132.97,148.51,0.253
132.99,148.69,0.253
133.01,148.87,0.253
133.03,149.06,0.253
133.04,149.24,0.253
133.06,149.42,0.253
133.08,149.61,0.254
133.10,149.79,0.254
133.12,149.97,0.254
133.14,150.16,0.254
133.15,150.34,0.254
133.17,150.52,0.255
133.19,150.71,0.255
133.21,150.89,0.255
133.23,151.07,0.255
133.25,151.26,0.256
133.26,151.44,0.256
133.28,151.62,0.256
133.30,151.81,0.256
133.32,151.99,0.257
133.34,152.17,0.257
133.35,152.36,0.257
133.37,152.54,0.257
133.39,152.72,0.258
133.41,152.91,0.258
133.43,153.09,0.258
133.45,153.27,0.258
133.46,153.46,0.259
133.48,153.64,0.259
133.50,153.82,0.259
133.52,154.01,0.260
133.54,154.19,0.260
133.56,154.37,0.260
133.58,154.56,0.261
133.59,154.74,0.261
133.61,154.92,0.261
133.63,155.11,0.262
133.65,155.29,0.262
133.67,155.47,0.262
133.69,155.66,0.263
133.70,155.84,0.263
133.72,156.02,0.264
133.74,156.21,0.264
133.76,156.39,0.265
133.78,156.57,0.265
133.80,156.76,0.266
133.81,156.94,0.266
133.83,157.12,0.267
133.85,157.31,0.267
133.87,157.49,0.268
133.89,157.67,0.268
133.90,157.86,0.268
133.92,158.04,0.269
133.94,158.22,0.270
133.96,158.41,0.270
133.98,158.59,0.271
134.00,158.77,0.272
134.01,158.96,0.272
134.03,159.14,0.273
134.05,159.32,0.274
134.07,159.51,0.274
134.09,159.69,0.275
134.11,159.87,0.276
134.13,160.06,0.277
134.14,160.24,0.278
134.16,160.42,0.279
134.18,160.60,0.279
134.20,160.79,0.280
134.22,160.97,0.281
134.24,161.15,0.281
134.25,161.34,0.281
134.27,161.52,0.282
134.29,161.70,0.283
134.31,161.88,0.284
134.33,162.07,0.285
134.35,162.25,0.286
134.36,162.43,0.287
134.38,162.62,0.288
134.40,162.80,0.289
134.42,162.98,0.290
134.44,163.17,0.290
134.45,163.35,0.291
134.47,163.53,0.292
134.49,163.72,0.293
134.51,163.90,0.294
134.53,164.08,0.294
134.55,164.27,0.295
134.56,164.45,0.296
134.58,164.63,0.296
134.60,164.82,0.297
134.62,165.00,0.297
134.64,165.18,0.297
134.66,165.37,0.298
134.68,165.55,0.298
134.69,165.73,0.299
134.71,165.91,0.300
134.73,166.10,0.300
134.75,166.28,0.300
134.77,166.46,0.301
134.79,166.65,0.301
134.80,166.83,0.301
134.82,167.02,0.302
134.84,167.20,0.302
134.86,167.38,0.303
134.88,167.57,0.303
134.90,167.75,0.304
134.91,167.94,0.304
134.93,168.12,0.304
134.95,168.30,0.304
134.97,168.48,0.305
134.99,168.67,0.305
135.00,168.85,0.305
135.02,169.03,0.305
135.04,169.22,0.305
135.06,169.40,0.305
135.08,169.59,0.306
135.10,169.77,0.306
135.11,169.95,0.306
135.13,170.13,0.306
135.15,170.32,0.306
135.17,170.50,0.306
135.19,170.68,0.306
135.21,170.87,0.306
135.23,171.05,0.306
135.24,171.23,0.306
135.26,171.42,0.307
135.28,171.60,0.307
135.30,171.79,0.307
135.32,171.97,0.307
135.34,172.15,0.307
135.35,172.34,0.307
135.37,172.52,0.307
135.39,172.70,0.307
135.41,172.88,0.307
135.43,173.07,0.307
135.45,173.25,0.307
135.46,173.43,0.307
135.48,173.62,0.307
135.50,173.80,0.307
135.52,173.99,0.307
135.54,174.17,0.307
135.55,174.35,0.307
135.57,174.54,0.307
135.59,174.72,0.307
135.61,174.90,0.307
135.63,175.09,0.307
135.65,175.27,0.307
135.66,175.45,0.307
135.68,175.64,0.307
135.70,175.82,0.307
135.72,176.00,0.307
135.74,176.19,0.307
135.76,176.37,0.307
135.78,176.55,0.307
135.79,176.74,0.307
135.81,176.92,0.307
135.83,177.11,0.307
135.85,177.29,0.307
135.87,177.47,0.307
135.89,177.66,0.307
135.90,177.84,0.307
135.92,178.03,0.307
135.94,178.21,0.307
135.96,178.39,0.307
135.98,178.57,0.307
136.00,178.76,0.307
136.01,178.94,0.307
136.03,179.12,0.307
136.05,179.31,0.307
136.07,179.49,0.307
136.09,179.67,0.307
136.10,179.85,0.307
136.12,180.04,0.307
136.14,180.22,0.307
136.16,180.40,0.307
136.18,180.59,0.307
136.20,180.77,0.307
136.21,180.96,0.307
136.23,181.14,0.307
136.25,181.32,0.307
136.27,181.51,0.307
136.29,181.69,0.308
136.31,181.87,0.308
136.33,182.06,0.308
136.34,182.24,0.308
136.36,182.42,0.308
136.38,182.61,0.308
136.40,182.79,0.308
136.42,182.98,0.308
136.44,183.16,0.308
136.45,183.34,0.308
136.47,183.53,0.308
136.49,183.71,0.308
136.51,183.89,0.309
136.53,184.07,0.309
136.55,184.26,0.309
136.56,184.44,0.309
136.58,184.62,0.309
136.60,184.81,0.309
136.62,184.99,0.309
136.64,185.18,0.309
136.65,185.36,0.309
136.67,185.54,0.309
136.69,185.73,0.309
136.71,185.91,0.309
136.73,186.09,0.309
136.75,186.28,0.310
136.77,186.46,0.310
136.78,186.65,0.310
136.80,186.83,0.310
136.82,187.01,0.310
136.84,187.20,0.310
136.86,187.38,0.310
136.88,187.56,0.310
136.89,187.74,0.310
136.91,187.93,0.310
136.93,188.11,0.311
136.95,188.29,0.311
136.97,188.48,0.311
136.98,188.66,0.311
137.00,188.85,0.311
137.02,189.03,0.311
137.04,189.21,0.311
137.06,189.39,0.311
137.08,189.58,0.311
137.10,189.76,0.311
137.11,189.95,0.311
137.13,190.13,0.312
137.15,190.31,0.312
137.17,190.50,0.312
137.19,190.68,0.312
137.20,190.86,0.312
137.22,191.05,0.312
137.24,191.23,0.312
137.26,191.41,0.312
137.28,191.60,0.312
137.30,191.78,0.313
137.32,191.96,0.313
137.33,192.15,0.313
137.35,192.33,0.313
137.37,192.51,0.313
137.39,192.70,0.313
137.41,192.88,0.313
137.43,193.07,0.313
137.44,193.25,0.313
137.46,193.43,0.314
137.48,193.61,0.314
137.50,193.80,0.314
137.52,193.98,0.314
137.53,194.16,0.314
137.55,194.35,0.314
137.57,194.53,0.314
137.59,194.71,0.314
137.61,194.90,0.314
137.63,195.08,0.314
137.65,195.27,0.315
137.66,195.45,0.315
137.68,195.63,0.315
137.70,195.82,0.315
137.72,196.00,0.315
137.74,196.18,0.315
137.75,196.37,0.315
137.77,196.55,0.316
137.79,196.73,0.316
137.81,196.92,0.316
137.83,197.10,0.316
137.85,197.28,0.316
137.87,197.47,0.316
137.88,197.65,0.316
137.90,197.83,0.316
137.92,198.02,0.316
137.94,198.20,
137.96,198.38,
137.98,198.57,
137.99,,
138.00,,