File: DSC/Olivia/2025_08_10_1CBN_3PVP90_MP_n60C_250C_10Cmin_x3.csv
Filename,2025_08_10_1CBN_3PVP90_MP_n60C_250C_10Cmin_x3
Instrument name,DSC2A-00468 (192.168.1.100)
Operator,Yarger
rundate,8/10/2025
Sample name,2025_08_10_1CBN_3PVP90_MP_n60C_250C_10Cmin_x3
proceduresegments,Data Off ; Equilibrate -60.00 °C; Data On ; Ramp 10.00 °C/min to 250.00 °C; Data Off ; Isothermal 2.0 min; Data On ; Ramp 10.00 °C/min to -60.00 °C; Data Off ; Isothermal 2.0 min; Data On ; Ramp 10.00 °C/min to 250.00 °C; Data Off ; Isothermal 2.0 min; Data On ; Ramp 10.00 °C/min to -60.00 °C; Data Off ; Isothermal 2.0 min; Data On ; Ramp 10.00 °C/min to 250.00 °C
[File Parameters]
Run date,8/10/2025 10:11:49 PM
Trios version,5.1.1.46572
Original File Name,
Current File Name,D:\DSC2500\JYarger\2025_08_10_1CBN_3PVP90_MP_n60C_250C_10Cmin_x3.tri
[Procedure]
Procedure Name,TS_n60C_250C_10Cmin_x3
Sample Name,2025_08_10_1CBN_3PVP90_MP_n60C_250C_10Cmin_x3
Sample Mass,32.94 mg
Reference Sample Mass,0 mg
Pan Mass,12.39 mg
Pan Number,18
Reference Pan Mass,32.42 mg
Reference Pan Number,10
Pan Type,Aluminum
Comments,Thermal support Al pans/lids. DSC_Samples_A2_Tray_August2025 google sheet.
Project Name,Pharma
Operator,Yarger
Test,Custom
Unload Max Temperature,30
Unload Min Temperature,30
Load Max Temperature,30
Load Min Temperature,30
Stop on Gas Flow Error,Yes
[Signal List]
Signal #1,Time (min)
Signal #2,Temperature (°C)
Signal #3,Heat Flow (mW)
Signal #4,Delta T (µV)
Signal #5,Delta Tzero (µV)
Signal #6,Tzero Temperature (°C)
Signal #7,Cell Purge (mL/min)
Signal #8,Heater Temp (°C)
Signal #9,Power Delivered (W)
Signal #10,Reference Junction Temperature (°C)
Signal #11,Flange Temperature (°C)
Signal #12,Heat Flow Phase (rad)
Signal #13,Total Heat Capacity (J/°C)
Signal #14,Heat Capacity (J/°C)
[Configuration]
Company Name,ASU
Instrument Name,DSC2A-00468
Instrument Type,DSC2500
Serial Number,DSC2A-00468
IP,192.168.1.100
Location of Instrument,MRRC
DisplayType,Unknown
Sample Interval ,0.1 s/pt
Selected Heat Flow,T4P
Exotherm Direction,Down
Cell Serial,DRC2-00792
Lid Type,Standard
Cooler,RCS 90
Leave Cooler on at End of Sequence,On
Gas 2,Nitrogen
Gas Selected,Channel 1
Flow Rate,50 mL/min
Secondary Purge,On
Licensed Heat Flow,Heat Flow T4P
Modulation Licensed,Yes
[Versions]
Common IDD Version,1
Cortex Version,VER 2.10.2.31
Driver,5.0.0.6
GDM Version,1.0.3.3
TouchscreenVersion,1.0.0.16145
FEP Version,1.2.1.21
FEP Bootloader,2.0.0.5
AutoSampler Version,2.1.1.26
Auto Sampler Bootloader,2.0.0.5
FCM Version,1.1.0.3
FCM Bootloader,2.0.0.5
[Experiment Logs]
Experiment Log Entry # 1,Data On set to 0
Experiment Log Entry # 3,Equilibrate Segment -60 (C) Started
Experiment Log Entry # 5,Air Cool is off.
Experiment Log Entry # 7,Data On set to 1
Experiment Log Entry # 9,Ramp Segment 10 C/min to 250 Started
Experiment Log Entry # 11,Data On set to 0
Experiment Log Entry # 13,Isothermal Segment 2 min started
Experiment Log Entry # 15,Data On set to 1
Experiment Log Entry # 17,Ramp Segment 10 C/min to -60 Started
Experiment Log Entry # 19,Data On set to 0
Experiment Log Entry # 21,Isothermal Segment 2 min started
Experiment Log Entry # 23,Data On set to 1
Experiment Log Entry # 25,Ramp Segment 10 C/min to 250 Started
Experiment Log Entry # 27,Data On set to 0
Experiment Log Entry # 29,Isothermal Segment 2 min started
Experiment Log Entry # 31,Data On set to 1
Experiment Log Entry # 33,Ramp Segment 10 C/min to -60 Started
Experiment Log Entry # 35,Data On set to 0
Experiment Log Entry # 37,Isothermal Segment 2 min started
Experiment Log Entry # 39,Data On set to 1
Experiment Log Entry # 41,Ramp Segment 10 C/min to 250 Started
[Method Log]
Method Log Entry # 1,Data Off
Method Log Entry # 2,Equilibrate -60 °C
Method Log Entry # 3,Data On
Method Log Entry # 4,(Ramp 1077397) Ramp 10 °C/minute to 250 °C
Method Log Entry # 5,Data Off
Method Log Entry # 6,Isothermal 2 minutes
Method Log Entry # 7,Data On
Method Log Entry # 8,(Ramp 1077401) Ramp 10 °C/minute to -60 °C
Method Log Entry # 9,Data Off
Method Log Entry # 10,Isothermal 2 minutes
Method Log Entry # 11,Data On
Method Log Entry # 12,(Ramp 1077405) Ramp 10 °C/minute to 250 °C
Method Log Entry # 13,Data Off
Method Log Entry # 14,Isothermal 2 minutes
Method Log Entry # 15,Data On
Method Log Entry # 16,(Ramp 1077409) Ramp 10 °C/minute to -60 °C
Method Log Entry # 17,Data Off
Method Log Entry # 18,Isothermal 2 minutes
Method Log Entry # 19,Data On
Method Log Entry # 20,(Ramp 1077413) Ramp 10 °C/minute to 250 °C
Cell Serial,DRC2-00792
[T1 Calibration]
Slope,-0.008529666
Offset,9.636258
Initial Temperature,98.23
GUID,f8bfdadc-4977-4fdf-ba6d-0ba9134940c3
[TZero Calibration]
Date Applied,11/29/2022 4:06:13 PM
Description,From -89.059 °C to 396.009 °C at 20.000°C/min
Gas Type,Nitrogen
Pan Type,None
Source Files 1,C:\Users\yargerlab\Desktop\DSC Data\General\TZero_calibration_11_29_22_2nd(2).tri
Source Files 2,C:\Users\yargerlab\Desktop\DSC Data\General\TZero_calibration_11_29_22_2nd(3).tri
Delta T Offset,13.05235
Delta T Slope,-0.007271007
Delta T0 Offset,-13.69128
Delta T0 Slope,0.06063341
[Temperature Calibration]
Date Applied,11/29/2022 7:12:28 PM
Description,From 106.590 °C to 186.590 °C at 10.000°C/min
Gas Type,Nitrogen
Pan Type,Tzero Aluminum Hermetic
Source Files 1,C:\Users\yargerlab\Desktop\DSC Data\General\Indium(6).tri
Measured 1,157.391
Known 1,156.598
[Cell Constant Calibration]
Date Applied,11/29/2022 7:12:29 PM
Description,From 106.590 °C to 186.590 °C at 10.000°C/min
Gas Type,Nitrogen
Pan Type,Tzero Aluminum Hermetic
Source Files 1,C:\Users\yargerlab\Desktop\DSC Data\General\Indium(6).tri
T4P KCell,1.006051
Onset Slope,63.26126 mW/°C
[Direct Cp Calibration]
Date Applied,11/30/2022 11:04:51 AM
Description,From -79.983 °C to 298.409 °C at 10.000°C/min
Gas Type,Nitrogen
Pan Type,Tzero Aluminum Hermetic
Source Files 1,C:\Users\yargerlab\Desktop\DSC Data\General\Sapphire_Heat_Capacity_11_30_22.tri
[Rev Cp Calibration]
Date Applied,11/30/2022 1:58:51 PM
Description,From -79.996 °C to 292.812 °C at 3.000°C/min
Gas Type,Nitrogen
Pan Type,Tzero Aluminum Hermetic
Source Files 1,C:\Users\yargerlab\Desktop\DSC Data\General\Sapphire_MDSC_Calibration_11_30_22.tri
[step]
Ramp 10.00 °C/min to 250.00 °C
Time,Temperature,Heat Flow (Normalized)
min,°C,W/g
0.00,-59.78,-0.016
0.02,-59.79,-0.014
0.04,-59.79,-0.013
0.07,-59.77,-0.012
0.09,-59.72,-0.010
0.11,-59.64,-0.005
0.13,-59.53,0.002
0.15,-59.40,0.011
0.17,-59.25,0.021
0.19,-59.08,0.030
0.22,-58.90,0.039
0.24,-58.72,0.046
0.26,-58.52,0.052
0.28,-58.33,0.057
0.30,-58.13,0.061
0.33,-57.93,0.064
0.35,-57.73,0.067
0.37,-57.53,0.069
0.39,-57.32,0.070
0.41,-57.12,0.072
0.43,-56.91,0.073
0.45,-56.70,0.074
0.48,-56.49,0.075
0.50,-56.28,0.075
0.52,-56.07,0.076
0.54,-55.86,0.076
0.56,-55.64,0.077
0.58,-55.43,0.077
0.61,-55.22,0.078
0.63,-55.01,0.078
0.65,-54.79,0.078
0.67,-54.58,0.078
0.69,-54.37,0.079
0.72,-54.15,0.079
0.74,-53.94,0.079
0.76,-53.72,0.079
0.78,-53.51,0.079
0.80,-53.30,0.079
0.82,-53.08,0.080
0.85,-52.87,0.080
0.87,-52.65,0.080
0.89,-52.44,0.080
0.91,-52.22,0.080
0.93,-52.01,0.080
0.95,-51.79,0.080
0.98,-51.58,0.080
1.00,-51.36,0.081
1.02,-51.15,0.081
1.04,-50.93,0.081
1.06,-50.72,0.081
1.08,-50.50,0.081
1.11,-50.29,0.081
1.13,-50.07,0.081
1.15,-49.85,0.081
1.17,-49.64,0.081
1.19,-49.42,0.082
1.21,-49.21,0.082
1.23,-48.99,0.082
1.26,-48.77,0.082
1.28,-48.56,0.082
1.30,-48.34,0.082
1.32,-48.12,0.082
1.34,-47.91,0.082
1.37,-47.69,0.082
1.39,-47.48,0.082
1.41,-47.26,0.082
1.43,-47.05,0.083
1.45,-46.83,0.083
1.47,-46.61,0.083
1.49,-46.40,0.083
1.52,-46.18,0.083
1.54,-45.96,0.083
1.56,-45.75,0.083
1.58,-45.53,0.083
1.60,-45.31,0.083
1.63,-45.10,0.083
1.65,-44.88,0.083
1.67,-44.66,0.084
1.69,-44.45,0.084
1.71,-44.23,0.084
1.73,-44.01,0.084
1.76,-43.80,0.084
1.78,-43.58,0.084
1.80,-43.36,0.084
1.82,-43.15,0.084
1.84,-42.93,0.084
1.86,-42.71,0.084
1.88,-42.50,0.084
1.91,-42.28,0.084
1.93,-42.06,0.084
1.95,-41.85,0.085
1.97,-41.63,0.085
1.99,-41.41,0.085
2.02,-41.20,0.085
2.04,-40.98,0.085
2.06,-40.76,0.085
2.08,-40.55,0.085
2.10,-40.33,0.085
2.12,-40.11,0.085
2.14,-39.89,0.085
2.17,-39.68,0.085
2.19,-39.46,0.085
2.21,-39.24,0.085
2.23,-39.03,0.085
2.25,-38.81,0.086
2.28,-38.59,0.086
2.30,-38.38,0.086
2.32,-38.16,0.086
2.34,-37.94,0.086
2.36,-37.73,0.086
2.38,-37.51,0.086
2.41,-37.29,0.086
2.43,-37.08,0.086
2.45,-36.86,0.086
2.47,-36.64,0.086
2.49,-36.43,0.086
2.51,-36.21,0.086
2.54,-35.99,0.087
2.56,-35.77,0.087
2.58,-35.56,0.087
2.60,-35.34,0.087
2.62,-35.12,0.087
2.64,-34.91,0.087
2.66,-34.69,0.087
2.69,-34.47,0.087
2.71,-34.26,0.087
2.73,-34.04,0.087
2.75,-33.82,0.087
2.77,-33.61,0.087
2.79,-33.39,0.087
2.82,-33.17,0.087
2.84,-32.96,0.088
2.86,-32.74,0.088
2.88,-32.52,0.088
2.90,-32.30,0.088
2.93,-32.09,0.088
2.95,-31.87,0.088
2.97,-31.65,0.088
2.99,-31.44,0.088
3.01,-31.22,0.088
3.03,-31.00,0.088
3.06,-30.79,0.088
3.08,-30.57,0.088
3.10,-30.35,0.088
3.12,-30.14,0.088
3.14,-29.92,0.089
3.16,-29.70,0.089
3.19,-29.49,0.089
3.21,-29.27,0.089
3.23,-29.05,0.089
3.25,-28.84,0.089
3.27,-28.62,0.089
3.29,-28.40,0.089
3.31,-28.19,0.089
3.34,-27.97,0.089
3.36,-27.75,0.089
3.38,-27.53,0.089
3.40,-27.32,0.089
3.42,-27.10,0.090
3.44,-26.89,0.090
3.47,-26.67,0.090
3.49,-26.45,0.090
3.51,-26.23,0.090
3.53,-26.02,0.090
3.55,-25.80,0.090
3.58,-25.58,0.090
3.60,-25.37,0.090
3.62,-25.15,0.090
3.64,-24.93,0.090
3.66,-24.72,0.090
3.68,-24.50,0.091
3.71,-24.28,0.091
3.73,-24.07,0.091
3.75,-23.85,0.091
3.77,-23.63,0.091
3.79,-23.42,0.091
3.81,-23.20,0.091
3.84,-22.98,0.091
3.86,-22.77,0.091
3.88,-22.55,0.091
3.90,-22.33,0.091
3.92,-22.12,0.091
3.94,-21.90,0.092
3.96,-21.68,0.092
3.99,-21.46,0.092
4.01,-21.25,0.092
4.03,-21.03,0.092
4.05,-20.81,0.092
4.07,-20.60,0.092
4.09,-20.38,0.092
4.12,-20.16,0.092
4.14,-19.95,0.092
4.16,-19.73,0.092
4.18,-19.51,0.092
4.20,-19.30,0.093
4.23,-19.08,0.093
4.25,-18.86,0.093
4.27,-18.65,0.093
4.29,-18.43,0.093
4.31,-18.21,0.093
4.33,-18.00,0.093
4.35,-17.78,0.093
4.38,-17.56,0.093
4.40,-17.35,0.093
4.42,-17.13,0.093
4.44,-16.91,0.094
4.46,-16.70,0.094
4.49,-16.48,0.094
4.51,-16.26,0.094
4.53,-16.05,0.094
4.55,-15.83,0.094
4.57,-15.61,0.094
4.59,-15.40,0.094
4.61,-15.18,0.094
4.64,-14.96,0.094
4.66,-14.75,0.094
4.68,-14.53,0.094
4.70,-14.31,0.095
4.72,-14.10,0.095
4.75,-13.88,0.095
4.77,-13.66,0.095
4.79,-13.45,0.095
4.81,-13.23,0.095
4.83,-13.01,0.095
4.85,-12.79,0.095
4.88,-12.58,0.095
4.90,-12.36,0.095
4.92,-12.14,0.096
4.94,-11.93,0.096
4.96,-11.71,0.096
4.98,-11.49,0.096
5.00,-11.28,0.096
5.03,-11.06,0.096
5.05,-10.84,0.096
5.07,-10.62,0.096
5.09,-10.41,0.096
5.11,-10.19,0.096
5.14,-9.98,0.096
5.16,-9.76,0.097
5.18,-9.54,0.097
5.20,-9.33,0.097
5.22,-9.11,0.097
5.24,-8.89,0.097
5.26,-8.68,0.097
5.29,-8.46,0.097
5.31,-8.24,0.097
5.33,-8.03,0.097
5.35,-7.81,0.097
5.37,-7.59,0.098
5.40,-7.38,0.098
5.42,-7.16,0.098
5.44,-6.94,0.098
5.46,-6.73,0.098
5.48,-6.51,0.098
5.50,-6.29,0.098
5.53,-6.07,0.098
5.55,-5.86,0.098
5.57,-5.64,0.099
5.59,-5.42,0.099
5.61,-5.21,0.099
5.63,-4.99,0.099
5.65,-4.78,0.099
5.68,-4.56,0.099
5.70,-4.34,0.099
5.72,-4.12,0.099
5.74,-3.91,0.099
5.76,-3.69,0.099
5.79,-3.48,0.100
5.81,-3.26,0.100
5.83,-3.04,0.100
5.85,-2.83,0.100
5.87,-2.61,0.100
5.89,-2.39,0.100
5.91,-2.17,0.100
5.94,-1.96,0.100
5.96,-1.74,0.100
5.98,-1.52,0.101
6.00,-1.31,0.101
6.02,-1.09,0.101
6.05,-0.87,0.101
6.07,-0.66,0.101
6.09,-0.44,0.101
6.11,-0.22,0.101
6.13,-0.01,0.101
6.15,0.21,0.101
6.18,0.42,0.102
6.20,0.64,0.102
6.22,0.86,0.102
6.24,1.08,0.102
6.26,1.29,0.102
6.28,1.51,0.102
6.30,1.73,0.102
6.33,1.94,0.102
6.35,2.16,0.103
6.37,2.38,0.103
6.39,2.59,0.103
6.41,2.81,0.103
6.44,3.03,0.103
6.46,3.24,0.103
6.48,3.46,0.103
6.50,3.68,0.103
6.52,3.90,0.104
6.54,4.11,0.104
6.56,4.33,0.104
6.59,4.55,0.104
6.61,4.76,0.104
6.63,4.98,0.104
6.65,5.20,0.104
6.67,5.41,0.105
6.70,5.63,0.105
6.72,5.85,0.105
6.74,6.06,0.105
6.76,6.28,0.105
6.78,6.50,0.105
6.80,6.71,0.105
6.83,6.93,0.105
6.85,7.15,0.105
6.87,7.36,0.106
6.89,7.58,0.106
6.91,7.79,0.106
6.93,8.01,0.106
6.95,8.23,0.106
6.98,8.44,0.106
7.00,8.66,0.106
7.02,8.88,0.107
7.04,9.09,0.107
7.06,9.31,0.107
7.09,9.53,0.107
7.11,9.75,0.107
7.13,9.96,0.107
7.15,10.18,0.107
7.17,10.40,0.108
7.19,10.61,0.108
7.21,10.83,0.108
7.24,11.05,0.108
7.26,11.26,0.108
7.28,11.48,0.108
7.30,11.70,0.109
7.32,11.91,0.109
7.35,12.13,0.109
7.37,12.35,0.109
7.39,12.56,0.109
7.41,12.78,0.109
7.43,13.00,0.110
7.45,13.21,0.110
7.48,13.43,0.110
7.50,13.65,0.110
7.52,13.86,0.110
7.54,14.08,0.110
7.56,14.30,0.110
7.58,14.51,0.111
7.60,14.73,0.111
7.63,14.95,0.111
7.65,15.16,0.111
7.67,15.38,0.111
7.69,15.60,0.111
7.71,15.81,0.111
7.74,16.03,0.112
7.76,16.24,0.112
7.78,16.46,0.112
7.80,16.68,0.112
7.82,16.89,0.112
7.84,17.11,0.113
7.86,17.33,0.113
7.89,17.54,0.113
7.91,17.76,0.113
7.93,17.98,0.113
7.95,18.19,0.114
7.97,18.41,0.114
8.00,18.63,0.114
8.02,18.84,0.114
8.04,19.06,0.114
8.06,19.27,0.114
8.08,19.49,0.115
8.10,19.71,0.115
8.13,19.92,0.115
8.15,20.14,0.115
8.17,20.36,0.115
8.19,20.57,0.116
8.21,20.79,0.116
8.23,21.01,0.116
8.25,21.22,0.116
8.28,21.44,0.116
8.30,21.65,0.117
8.32,21.87,0.117
8.34,22.09,0.117
8.36,22.31,0.117
8.39,22.52,0.118
8.41,22.74,0.118
8.43,22.96,0.118
8.45,23.17,0.118
8.47,23.39,0.118
8.49,23.60,0.119
8.51,23.82,0.119
8.54,24.04,0.119
8.56,24.26,0.119
8.58,24.47,0.120
8.60,24.69,0.120
8.62,24.91,0.120
8.65,25.12,0.120
8.67,25.34,0.121
8.69,25.56,0.121
8.71,25.77,0.121
8.73,25.99,0.121
8.75,26.20,0.121
8.78,26.42,0.122
8.80,26.64,0.122
8.82,26.85,0.122
8.84,27.07,0.122
8.86,27.29,0.122
8.88,27.50,0.123
8.90,27.72,0.123
8.93,27.94,0.123
8.95,28.15,0.124
8.97,28.37,0.124
8.99,28.59,0.124
9.01,28.80,0.125
9.03,29.02,0.125
9.06,29.24,0.125
9.08,29.45,0.125
9.10,29.67,0.125
9.12,29.88,0.125
9.14,30.10,0.126
9.17,30.32,0.126
9.19,30.53,0.127
9.21,30.75,0.127
9.23,30.97,0.127
9.25,31.18,0.128
9.27,31.40,0.128
9.30,31.62,0.128
9.32,31.83,0.128
9.34,32.05,0.129
9.36,32.26,0.129
9.38,32.48,0.129
9.40,32.70,0.130
9.43,32.91,0.130
9.45,33.13,0.130
9.47,33.35,0.130
9.49,33.56,0.131
9.51,33.78,0.131
9.53,34.00,0.131
9.55,34.21,0.132
9.58,34.43,0.132
9.60,34.64,0.133
9.62,34.86,0.133
9.64,35.08,0.133
9.66,35.29,0.134
9.68,35.51,0.134
9.71,35.72,0.134
9.73,35.94,0.135
9.75,36.16,0.135
9.77,36.37,0.136
9.79,36.59,0.136
9.82,36.81,0.136
9.84,37.02,0.137
9.86,37.24,0.137
9.88,37.45,0.137
9.90,37.67,0.138
9.92,37.89,0.138
9.95,38.10,0.139
9.97,38.32,0.139
9.99,38.53,0.139
10.01,38.75,0.140
10.03,38.97,0.140
10.05,39.18,0.141
10.08,39.40,0.141
10.10,39.61,0.142
10.12,39.83,0.142
10.14,40.05,0.143
10.16,40.26,0.143
10.18,40.48,0.144
10.20,40.69,0.144
10.23,40.91,0.145
10.25,41.12,0.146
10.27,41.34,0.146
10.29,41.56,0.147
10.31,41.77,0.147
10.33,41.99,0.148
10.36,42.20,0.148
10.38,42.42,0.149
10.40,42.63,0.150
10.42,42.85,0.150
10.44,43.07,0.151
10.47,43.28,0.152
10.49,43.50,0.152
10.51,43.71,0.153
10.53,43.93,0.154
10.55,44.14,0.154
10.57,44.36,0.155
10.60,44.57,0.156
10.62,44.79,0.157
10.64,45.00,0.158
10.66,45.22,0.158
10.68,45.43,0.159
10.70,45.65,0.160
10.73,45.87,0.161
10.75,46.08,0.162
10.77,46.30,0.163
10.79,46.51,0.164
10.81,46.73,0.164
10.83,46.94,0.165
10.85,47.16,0.166
10.88,47.37,0.167
10.90,47.59,0.168
10.92,47.80,0.168
10.94,48.02,0.169
10.96,48.23,0.169
10.98,48.45,0.170
11.01,48.67,0.170
11.03,48.88,0.171
11.05,49.10,0.171
11.07,49.32,0.171
11.09,49.53,0.171
11.12,49.75,0.171
11.14,49.96,0.172
11.16,50.18,0.172
11.18,50.40,0.172
11.20,50.61,0.172
11.22,50.83,0.172
11.25,51.05,0.172
11.27,51.26,0.172
11.29,51.48,0.172
11.31,51.70,0.172
11.33,51.92,0.172
11.35,52.13,0.172
11.38,52.35,0.172
11.40,52.57,0.172
11.42,52.78,0.172
11.44,53.00,0.172
11.46,53.22,0.172
11.48,53.43,0.172
11.50,53.65,0.172
11.53,53.87,0.172
11.55,54.08,0.172
11.57,54.30,0.173
11.59,54.52,0.173
11.61,54.73,0.174
11.63,54.95,0.175
11.66,55.16,0.175
11.68,55.38,0.176
11.70,55.60,0.176
11.72,55.81,0.177
11.74,56.03,0.177
11.77,56.24,0.178
11.79,56.46,0.179
11.81,56.67,0.180
11.83,56.89,0.180
11.85,57.10,0.181
11.87,57.32,0.182
11.90,57.54,0.183
11.92,57.75,0.183
11.94,57.97,0.184
11.96,58.18,0.185
11.98,58.40,0.186
12.00,58.61,0.187
12.03,58.83,0.188
12.05,59.04,0.189
12.07,59.26,0.190
12.09,59.47,0.191
12.11,59.69,0.192
12.13,59.90,0.193
12.15,60.12,0.194
12.18,60.33,0.195
12.20,60.55,0.196
12.22,60.76,0.197
12.24,60.98,0.198
12.26,61.19,0.199
12.28,61.41,0.200
12.31,61.62,0.201
12.33,61.84,0.202
12.35,62.05,0.204
12.37,62.27,0.205
12.39,62.48,0.206
12.42,62.69,0.207
12.44,62.91,0.208
12.46,63.12,0.210
12.48,63.34,0.211
12.50,63.55,0.212
12.52,63.77,0.214
12.55,63.98,0.215
12.57,64.19,0.216
12.59,64.41,0.218
12.61,64.62,0.219
12.63,64.84,0.220
12.65,65.05,0.222
12.68,65.26,0.223
12.70,65.48,0.225
12.72,65.69,0.226
12.74,65.91,0.228
12.76,66.12,0.229
12.78,66.33,0.231
12.80,66.55,0.233
12.83,66.76,0.234
12.85,66.97,0.236
12.87,67.19,0.238
12.89,67.40,0.240
12.91,67.61,0.242
12.93,67.83,0.245
12.96,68.04,0.247
12.98,68.25,0.250
13.00,68.46,0.253
13.02,68.67,0.255
13.04,68.88,0.259
13.07,69.09,0.263
13.09,69.30,0.268
13.11,69.51,0.273
13.13,69.72,0.279
13.15,69.92,0.286
13.17,70.12,0.294
13.20,70.32,0.303
13.22,70.52,0.314
13.24,70.72,0.327
13.26,70.91,0.341
13.28,71.10,0.357
13.30,71.28,0.374
13.33,71.46,0.392
13.35,71.65,0.410
13.37,71.82,0.428
13.39,72.00,0.444
13.41,72.19,0.458
13.43,72.37,0.468
13.45,72.57,0.473
13.48,72.77,0.472
13.50,72.98,0.465
13.52,73.21,0.452
13.54,73.45,0.435
13.56,73.69,0.415
13.58,73.94,0.395
13.61,74.20,0.374
13.63,74.46,0.355
13.65,74.71,0.338
13.67,74.97,0.323
13.69,75.22,0.310
13.72,75.46,0.299
13.74,75.71,0.290
13.76,75.95,0.282
13.78,76.18,0.276
13.80,76.42,0.271
13.82,76.65,0.267
13.85,76.87,0.264
13.87,77.10,0.262
13.89,77.32,0.260
13.91,77.55,0.259
13.93,77.77,0.258
13.95,77.99,0.257
13.98,78.20,0.257
14.00,78.42,0.257
14.02,78.64,0.257
14.04,78.86,0.257
14.06,79.07,0.258
14.08,79.29,0.258
14.10,79.51,0.259
14.13,79.72,0.260
14.15,79.94,0.261
14.17,80.15,0.262
14.19,80.37,0.262
14.21,80.58,0.264
14.23,80.80,0.265
14.26,81.01,0.266
14.28,81.23,0.267
14.30,81.44,0.268
14.32,81.66,0.269
14.34,81.87,0.270
14.37,82.09,0.271
14.39,82.30,0.273
14.41,82.52,0.274
14.43,82.73,0.275
14.45,82.95,0.276
14.47,83.16,0.278
14.50,83.37,0.279
14.52,83.59,0.280
14.54,83.80,0.281
14.56,84.02,0.282
14.58,84.23,0.284
14.60,84.45,0.285
14.63,84.66,0.286
14.65,84.88,0.288
14.67,85.09,0.289
14.69,85.30,0.290
14.71,85.52,0.291
14.73,85.73,0.293
14.75,85.95,0.294
14.78,86.16,0.295
14.80,86.38,0.297
14.82,86.59,0.298
14.84,86.80,0.299
14.86,87.02,0.301
14.88,87.23,0.302
14.91,87.45,0.303
14.93,87.66,0.305
14.95,87.87,0.306
14.97,88.09,0.307
14.99,88.30,0.309
15.02,88.52,0.310
15.04,88.73,0.312
15.06,88.94,0.313
15.08,89.16,0.314
15.10,89.37,0.316
15.12,89.59,0.317
15.15,89.80,0.319
15.17,90.02,0.320
15.19,90.23,0.321
15.21,90.44,0.323
15.23,90.66,0.324
15.25,90.87,0.326
15.28,91.09,0.327
15.30,91.30,0.329
15.32,91.52,0.330
15.34,91.73,0.331
15.36,91.94,0.333
15.38,92.16,0.334
15.40,92.37,0.334
15.43,92.59,0.335
15.45,92.80,0.335
15.47,93.02,0.337
15.49,93.23,0.338
15.51,93.45,0.339
15.53,93.66,0.340
15.56,93.88,0.341
15.58,94.09,0.341
15.60,94.31,0.342
15.62,94.52,0.344
15.64,94.74,0.345
15.67,94.96,0.346
15.69,95.17,0.347
15.71,95.38,0.348
15.73,95.60,0.349
15.75,95.81,0.350
15.77,96.03,0.352
15.80,96.24,0.353
15.82,96.46,0.354
15.84,96.67,0.355
15.86,96.89,0.356
15.88,97.10,0.358
15.90,97.32,0.359
15.93,97.53,0.361
15.95,97.74,0.361
15.97,97.96,0.363
15.99,98.17,0.364
16.01,98.39,0.365
16.03,98.60,0.366
16.05,98.82,0.368
16.08,99.03,0.369
16.10,99.24,0.371
16.12,99.46,0.372
16.14,99.67,0.374
16.16,99.89,0.375
16.18,100.10,0.377
16.21,100.31,0.378
16.23,100.53,0.379
16.25,100.74,0.381
16.27,100.96,0.382
16.29,101.17,0.384
16.32,101.39,0.385
16.34,101.60,0.386
16.36,101.81,0.388
16.38,102.03,0.389
16.40,102.24,0.391
16.42,102.46,0.392
16.45,102.67,0.393
16.47,102.88,0.395
16.49,103.10,0.396
16.51,103.31,0.398
16.53,103.53,0.399
16.55,103.74,0.400
16.58,103.96,0.402
16.60,104.17,0.403
16.62,104.38,0.404
16.64,104.60,0.406
16.66,104.81,0.407
16.68,105.03,0.408
16.70,105.24,0.410
16.73,105.46,0.411
16.75,105.67,0.412
16.77,105.89,0.414
16.79,106.10,0.415
16.81,106.32,0.416
16.83,106.53,0.417
16.86,106.74,0.418
16.88,106.96,0.419
16.90,107.17,0.420
16.92,107.39,0.422
16.94,107.60,0.423
16.97,107.82,0.424
16.99,108.03,0.425
17.01,108.25,0.426
17.03,108.46,0.427
17.05,108.68,0.428
17.07,108.89,0.429
17.09,109.11,0.430
17.12,109.32,0.431
17.14,109.54,0.431
17.16,109.76,0.432
17.18,109.97,0.433
17.20,110.19,0.434
17.23,110.40,0.435
17.25,110.62,0.436
17.27,110.83,0.436
17.29,111.05,0.437
17.31,111.26,0.438
17.33,111.48,0.438
17.36,111.69,0.439
17.38,111.91,0.440
17.40,112.13,0.440
17.42,112.34,0.441
17.44,112.56,0.441
17.46,112.77,0.442
17.48,112.99,0.442
17.51,113.21,0.443
17.53,113.42,0.443
17.55,113.64,0.444
17.57,113.86,0.444
17.59,114.07,0.444
17.62,114.29,0.444
17.64,114.50,0.445
17.66,114.72,0.445
17.68,114.94,0.445
17.70,115.15,0.445
17.72,115.37,0.445
17.74,115.59,0.445
17.77,115.81,0.445
17.79,116.02,0.445
17.81,116.24,0.445
17.83,116.46,0.445
17.85,116.67,0.445
17.88,116.89,0.445
17.90,117.11,0.445
17.92,117.33,0.445
17.94,117.54,0.445
17.96,117.76,0.445
17.98,117.98,0.445
18.01,118.20,0.445
18.03,118.41,0.445
18.05,118.63,0.445
18.07,118.85,0.444
18.09,119.07,0.444
18.11,119.28,0.444
18.13,119.50,0.443
18.16,119.72,0.442
18.18,119.94,0.441
18.20,120.16,0.441
18.22,120.37,0.440
18.24,120.59,0.439
18.27,120.81,0.439
18.29,121.03,0.438
18.31,121.25,0.437
18.33,121.47,0.437
18.35,121.68,0.436
18.37,121.90,0.436
18.39,122.12,0.435
18.42,122.34,0.434
18.44,122.56,0.433
18.46,122.78,0.432
18.48,123.00,0.431
18.50,123.22,0.430
18.53,123.44,0.429
18.55,123.65,0.428
18.57,123.87,0.427
18.59,124.09,0.426
18.61,124.31,0.425
18.63,124.53,0.424
18.66,124.75,0.423
18.68,124.97,0.422
18.70,125.19,0.421
18.72,125.41,0.420
18.74,125.63,0.418
18.76,125.85,0.417
18.78,126.07,0.416
18.81,126.29,0.414
18.83,126.51,0.413
18.85,126.73,0.412
18.87,126.95,0.411
18.89,127.17,0.409
18.92,127.39,0.408
18.94,127.61,0.407
18.96,127.83,0.405
18.98,128.05,0.404
19.00,128.27,0.402
19.02,128.48,0.401
19.04,128.71,0.400
19.07,128.93,0.398
19.09,129.15,0.396
19.11,129.37,0.395
19.13,129.58,0.394
19.15,129.81,0.392
19.18,130.02,0.391
19.20,130.25,0.389
19.22,130.46,0.387
19.24,130.69,0.386
19.26,130.91,0.384
19.28,131.13,0.382
19.31,131.35,0.381
19.33,131.57,0.379
19.35,131.79,0.377
19.37,132.01,0.376
19.39,132.23,0.374
19.41,132.45,0.372
19.43,132.67,0.371
19.46,132.89,0.369
19.48,133.11,0.367
19.50,133.33,0.366
19.52,133.55,0.364
19.54,133.77,0.362
19.57,133.99,0.361
19.59,134.21,0.359
19.61,134.43,0.357
19.63,134.65,0.355
19.65,134.87,0.353
19.67,135.09,0.352
19.69,135.31,0.350
19.72,135.53,0.348
19.74,135.75,0.347
19.76,135.97,0.345
19.78,136.19,0.343
19.80,136.41,0.341
19.83,136.63,0.340
19.85,136.85,0.338
19.87,137.07,0.337
19.89,137.29,0.335
19.91,137.51,0.333
19.93,137.73,0.331
19.96,137.95,0.330
19.98,138.18,0.328
20.00,138.39,0.326
20.02,138.61,0.324
20.04,138.84,0.322
20.06,139.06,0.321
20.08,139.28,0.319
20.11,139.50,0.317
20.13,139.72,0.316
20.15,139.94,0.314
20.17,140.16,0.312
20.19,140.38,0.311
20.22,140.60,0.309
20.24,140.82,0.307
20.26,141.04,0.306
20.28,141.26,0.304
20.30,141.48,0.302
20.32,141.70,0.301
20.34,141.92,0.299
20.37,142.14,0.297
20.39,142.36,0.295
20.41,142.58,0.294
20.43,142.80,0.292
20.45,143.02,0.290
20.48,143.24,0.289
20.50,143.46,0.287
20.52,143.68,0.286
20.54,143.90,0.284
20.56,144.12,0.283
20.58,144.34,0.281
20.61,144.56,0.280
20.63,144.78,0.278
20.65,145.00,0.276
20.67,145.22,0.275
20.69,145.44,0.273
20.71,145.66,0.272
20.73,145.88,0.270
20.76,146.10,0.269
20.78,146.32,0.267
20.80,146.54,0.266
20.82,146.76,0.264
20.84,146.98,0.262
20.87,147.20,0.261
20.89,147.42,0.260
20.91,147.64,0.258
20.93,147.86,0.256
20.95,148.08,0.255
20.97,148.30,0.253
20.99,148.52,0.252
21.02,148.74,0.250
21.04,148.96,0.249
21.06,149.18,0.248
21.08,149.40,0.246
21.10,149.62,0.245
21.13,149.84,0.244
21.15,150.06,0.242
21.17,150.28,0.241
21.19,150.50,0.239
21.21,150.72,0.238
21.23,150.94,0.237
21.26,151.16,0.235
21.28,151.38,0.234
21.30,151.60,0.233
21.32,151.82,0.231
21.34,152.04,0.230
21.36,152.26,0.229
21.38,152.48,0.227
21.41,152.69,0.226
21.43,152.91,0.225
21.45,153.13,0.224
21.47,153.35,0.222
21.49,153.57,0.221
21.52,153.79,0.220
21.54,154.01,0.219
21.56,154.23,0.218
21.58,154.45,0.216
21.60,154.67,0.215
21.62,154.89,0.214
21.64,155.11,0.213
21.67,155.33,0.212
21.69,155.54,0.210
21.71,155.76,0.209
21.73,155.98,0.208
21.75,156.20,0.207
21.78,156.42,0.206
21.80,156.64,0.205
21.82,156.86,0.204
21.84,157.08,0.203
21.86,157.30,0.202
21.88,157.52,0.201
21.91,157.74,0.199
21.93,157.96,0.198
21.95,158.17,0.197
21.97,158.39,0.196
21.99,158.61,0.195
22.01,158.83,0.194
22.03,159.05,0.193
22.06,159.27,0.192
22.08,159.49,0.191
22.10,159.71,0.190
22.12,159.93,0.189
22.14,160.15,0.188
22.17,160.36,0.187
22.19,160.58,0.186
22.21,160.80,0.185
22.23,161.02,0.184
22.25,161.24,0.183
22.27,161.46,0.182
22.29,161.68,0.181
22.32,161.90,0.180
22.34,162.11,0.179
22.36,162.33,0.178
22.38,162.55,0.177
22.40,162.77,0.177
22.43,162.99,0.176
22.45,163.21,0.175
22.47,163.43,0.174
22.49,163.64,0.173
22.51,163.86,0.172
22.53,164.08,0.172
22.56,164.30,0.171
22.58,164.52,0.170
22.60,164.74,0.169
22.62,164.96,0.169
22.64,165.17,0.168
22.66,165.39,0.167
22.68,165.61,0.166
22.71,165.83,0.165
22.73,166.05,0.165
22.75,166.26,0.164
22.77,166.48,0.164
22.79,166.70,0.163
22.82,166.92,0.162
22.84,167.14,0.162
22.86,167.36,0.161
22.88,167.57,0.160
22.90,167.79,0.160
22.92,168.01,0.159
22.94,168.23,0.158
22.97,168.45,0.158
22.99,168.66,0.157
23.01,168.88,0.156
23.03,169.10,0.156
23.05,169.32,0.155
23.08,169.53,0.155
23.10,169.75,0.154
23.12,169.97,0.153
23.14,170.19,0.153
23.16,170.41,0.152
23.18,170.63,0.152
23.21,170.84,0.151
23.23,171.06,0.151
23.25,171.28,0.150
23.27,171.50,0.150
23.29,171.72,0.149
23.31,171.94,0.149
23.33,172.15,0.149
23.36,172.37,0.148
23.38,172.59,0.147
23.40,172.81,0.147
23.42,173.02,0.146
23.44,173.24,0.146
23.47,173.46,0.146
23.49,173.68,0.145
23.51,173.90,0.145
23.53,174.11,0.145
23.55,174.33,0.144
23.57,174.55,0.144
23.59,174.76,0.144
23.62,174.98,0.143
23.64,175.20,0.143
23.66,175.42,0.143
23.68,175.63,0.142
23.70,175.85,0.142
23.73,176.07,0.142
23.75,176.29,0.142
23.77,176.50,0.142
23.79,176.72,0.142
23.81,176.94,0.141
23.83,177.15,0.141
23.86,177.37,0.141
23.88,177.59,0.141
23.90,177.81,0.141
23.92,178.02,0.141
23.94,178.24,0.141
23.96,178.46,0.141
23.98,178.68,0.141
24.01,178.89,0.140
24.03,179.11,0.140
24.05,179.33,0.140
24.07,179.54,0.140
24.09,179.76,0.140
24.12,179.98,0.140
24.14,180.20,0.140
24.16,180.41,0.140
24.18,180.63,0.140
24.20,180.85,0.140
24.22,181.06,0.139
24.24,181.28,0.139
24.27,181.50,0.139
24.29,181.71,0.139
24.31,181.93,0.139
24.33,182.15,0.139
24.35,182.37,0.138
24.38,182.58,0.138
24.40,182.80,0.138
24.42,183.02,0.138
24.44,183.24,0.137
24.46,183.45,0.136
24.48,183.67,0.136
24.51,183.89,0.135
24.53,184.10,0.135
24.55,184.32,0.135
24.57,184.54,0.135
24.59,184.76,0.135
24.61,184.97,0.134
24.63,185.19,0.134
24.66,185.41,0.134
24.68,185.63,0.134
24.70,185.84,0.134
24.72,186.06,0.134
24.74,186.28,0.134
24.77,186.50,0.133
24.79,186.71,0.133
24.81,186.93,0.133
24.83,187.15,0.133
24.85,187.37,0.133
24.87,187.58,0.133
24.89,187.80,0.133
24.92,188.02,0.133
24.94,188.23,0.133
24.96,188.45,0.133
24.98,188.67,0.133
25.00,188.88,0.133
25.03,189.10,0.133
25.05,189.32,0.133
25.07,189.53,0.133
25.09,189.75,0.133
25.11,189.97,0.132
25.13,190.18,0.132
25.16,190.40,0.132
25.18,190.62,0.132
25.20,190.84,0.132
25.22,191.05,0.132
25.24,191.27,0.132
25.26,191.48,0.132
25.28,191.70,0.132
25.31,191.92,0.132
25.33,192.14,0.132
25.35,192.35,0.132
25.37,192.57,0.132
25.39,192.79,0.132
25.42,193.00,0.132
25.44,193.22,0.132
25.46,193.44,0.132
25.48,193.65,0.132
25.50,193.87,0.132
25.52,194.09,0.133
25.54,194.30,0.133
25.57,194.52,0.133
25.59,194.74,0.133
25.61,194.95,0.133
25.63,195.17,0.133
25.65,195.39,0.133
25.68,195.60,0.133
25.70,195.82,0.133
25.72,196.04,0.133
25.74,196.25,0.133
25.76,196.47,0.133
25.78,196.69,0.133
25.81,196.90,0.133
25.83,197.12,0.133
25.85,197.34,0.133
25.87,197.56,0.133
25.89,197.77,0.133
25.91,197.99,0.133
25.93,198.21,0.133
25.96,198.42,0.133
25.98,198.64,0.133
26.00,198.86,0.133
26.02,199.07,0.133
26.04,199.29,0.133
26.07,199.51,0.133
26.09,199.72,0.133
26.11,199.94,0.133
26.13,200.16,0.133
26.15,200.37,0.133
26.17,200.59,0.133
26.19,200.81,0.133
26.22,201.03,0.133
26.24,201.24,0.133
26.26,201.46,0.133
26.28,201.68,0.133
26.30,201.89,0.133
26.33,202.11,0.133
26.35,202.33,0.134
26.37,202.54,0.134
26.39,202.76,0.134
26.41,202.98,0.134
26.43,203.19,0.134
26.46,203.41,0.134
26.48,203.63,0.134
26.50,203.84,0.134
26.52,204.06,0.134
26.54,204.28,0.134
26.56,204.49,0.134
26.58,204.71,0.134
26.61,204.93,0.134
26.63,205.14,0.134
26.65,205.36,0.134
26.67,205.58,0.134
26.69,205.80,0.134
26.72,206.01,0.134
26.74,206.23,0.134
26.76,206.45,0.134
26.78,206.66,0.134
26.80,206.88,0.134
26.82,207.10,0.134
26.84,207.31,0.134
26.87,207.53,0.134
26.89,207.75,0.134
26.91,207.96,0.134
26.93,208.18,0.134
26.95,208.40,0.134
26.98,208.61,0.134
27.00,208.83,0.134
27.02,209.05,0.134
27.04,209.26,0.134
27.06,209.48,0.134
27.08,209.70,0.134
27.11,209.91,0.134
27.13,210.13,0.134
27.15,210.35,0.135
27.17,210.56,0.135
27.19,210.78,0.135
27.21,211.00,0.135
27.23,211.21,0.135
27.26,211.43,0.135
27.28,211.65,0.135
27.30,211.86,0.135
27.32,212.08,0.135
27.34,212.30,0.135
27.37,212.51,0.135
27.39,212.73,0.135
27.41,212.95,0.135
27.43,213.17,0.135
27.45,213.38,0.135
27.47,213.60,0.135
27.49,213.82,0.135
27.52,214.03,0.135
27.54,214.25,0.135
27.56,214.47,0.135
27.58,214.68,0.135
27.60,214.90,0.135
27.63,215.12,0.135
27.65,215.33,0.135
27.67,215.55,0.135
27.69,215.77,0.136
27.71,215.98,0.136
27.73,216.20,0.136
27.76,216.42,0.136
27.78,216.63,0.136
27.80,216.85,0.136
27.82,217.07,0.136
27.84,217.28,0.136
27.86,217.50,0.136
27.88,217.72,0.136
27.91,217.94,0.136
27.93,218.15,0.136
27.95,218.37,0.136
27.97,218.59,0.136
27.99,218.80,0.136
28.02,219.02,0.136
28.04,219.24,0.136
28.06,219.45,0.136
28.08,219.67,0.136
28.10,219.89,0.136
28.12,220.10,0.136
28.14,220.32,0.136
28.17,220.54,0.136
28.19,220.75,0.137
28.21,220.97,0.137
28.23,221.19,0.137
28.25,221.40,0.137
28.28,221.62,0.137
28.30,221.84,0.137
28.32,222.05,0.137
28.34,222.27,0.137
28.36,222.49,0.137
28.38,222.70,0.137
28.41,222.92,0.137
28.43,223.14,0.137
28.45,223.35,0.137
28.47,223.57,0.137
28.49,223.79,0.137
28.51,224.00,0.137
28.53,224.22,0.137
28.56,224.44,0.137
28.58,224.65,0.137
28.60,224.87,0.137
28.62,225.09,0.137
28.64,225.31,0.137
28.67,225.52,0.137
28.69,225.74,0.137
28.71,225.96,0.138
28.73,226.17,0.138
28.75,226.39,0.138
28.77,226.61,0.138
28.79,226.82,0.138
28.82,227.04,0.138
28.84,227.26,0.138
28.86,227.47,0.138
28.88,227.69,0.138
28.90,227.91,0.138
28.93,228.12,0.138
28.95,228.34,0.138
28.97,228.56,0.138
28.99,228.77,0.138
29.01,228.99,0.138
29.03,229.21,0.138
29.06,229.42,0.138
29.08,229.64,0.138
29.10,229.86,0.138
29.12,230.07,0.138
29.14,230.29,0.138
29.16,230.51,0.138
29.18,230.72,0.138
29.21,230.94,0.138
29.23,231.16,0.138
29.25,231.37,0.138
29.27,231.59,0.139
29.29,231.81,0.139
29.32,232.03,0.139
29.34,232.24,0.139
29.36,232.46,0.139
29.38,232.68,0.139
29.40,232.89,0.139
29.42,233.11,0.139
29.44,233.33,0.139
29.47,233.54,0.139
29.49,233.76,0.139
29.51,233.98,0.139
29.53,234.19,0.139
29.55,234.41,0.139
29.58,234.63,0.139
29.60,234.84,0.139
29.62,235.06,0.139
29.64,235.28,0.139
29.66,235.49,0.139
29.68,235.71,0.139
29.71,235.93,0.139
29.73,236.15,0.139
29.75,236.36,0.139
29.77,236.58,0.140
29.79,236.80,0.140
29.81,237.01,0.140
29.83,237.23,0.140
29.86,237.45,0.140
29.88,237.66,0.140
29.90,237.88,0.140
29.92,238.10,0.140
29.94,238.31,0.140
29.97,238.53,0.140
29.99,238.75,0.140
30.01,238.96,0.140
30.03,239.18,0.140
30.05,239.40,0.140
30.07,239.61,0.140
30.09,239.83,0.140
30.12,240.05,0.140
30.14,240.26,0.140
30.16,240.48,0.140
30.18,240.70,0.140
30.20,240.91,0.140
30.23,241.13,0.140
30.25,241.35,0.140
30.27,241.56,0.140
30.29,241.78,0.141
30.31,242.00,0.141
30.33,242.21,0.141
30.36,242.43,0.141
30.38,242.65,0.141
30.40,242.86,0.141
30.42,243.08,0.141
30.44,243.30,0.141
30.46,243.51,0.141
30.48,243.73,0.141
30.51,243.95,0.141
30.53,244.17,0.141
30.55,244.38,0.141
30.57,244.60,0.141
30.59,244.82,0.141
30.62,245.03,0.141
30.64,245.25,0.141
30.66,245.47,0.141
30.68,245.68,0.141
30.70,245.90,0.141
30.72,246.12,0.141
30.74,246.33,0.141
30.77,246.55,0.142
30.79,246.77,0.142
30.81,246.98,0.142
30.83,247.20,0.142
30.85,247.42,0.142
30.88,247.63,0.142
30.90,247.85,0.142
30.92,248.07,0.142
30.94,248.28,
30.96,248.50,
30.98,248.72,
30.99,,

[step]
Ramp 10.00 °C/min to -60.00 °C
Time,Temperature,Heat Flow (Normalized)
min,°C,W/g
32.99,250.16,-0.002
33.02,250.16,-0.002
33.04,250.15,-0.002
33.06,250.13,-0.002
33.08,250.08,-0.007
33.10,250.00,-0.018
33.12,249.90,-0.034
33.14,249.76,-0.054
33.17,249.60,-0.073
33.19,249.43,-0.090
33.21,249.25,-0.103
33.23,249.06,-0.113
33.25,248.87,-0.121
33.28,248.67,-0.126
33.30,248.46,-0.130
33.32,248.26,-0.133
33.34,248.05,-0.136
33.36,247.84,-0.138
33.38,247.63,-0.139
33.41,247.42,-0.140
33.43,247.21,-0.141
33.45,247.00,-0.142
33.47,246.79,-0.143
33.49,246.57,-0.143
33.51,246.36,-0.143
33.53,246.14,-0.144
33.56,245.93,-0.144
33.58,245.72,-0.144
33.60,245.50,-0.144
33.62,245.29,-0.144
33.64,245.07,-0.145
33.67,244.86,-0.145
33.69,244.64,-0.145
33.71,244.43,-0.145
33.73,244.21,-0.145
33.75,244.00,-0.145
33.77,243.78,-0.145
33.79,243.57,-0.145
33.82,243.35,-0.145
33.84,243.13,-0.145
33.86,242.92,-0.145
33.88,242.70,-0.145
33.90,242.49,-0.145
33.93,242.27,-0.145
33.95,242.06,-0.145
33.97,241.84,-0.145
33.99,241.63,-0.145
34.01,241.41,-0.145
34.03,241.19,-0.145
34.06,240.98,-0.145
34.08,240.76,-0.145
34.10,240.55,-0.145
34.12,240.33,-0.145
34.14,240.11,-0.145
34.16,239.90,-0.145
34.19,239.68,-0.145
34.21,239.47,-0.145
34.23,239.25,-0.145
34.25,239.03,-0.145
34.27,238.82,-0.145
34.29,238.60,-0.145
34.31,238.39,-0.145
34.34,238.17,-0.145
34.36,237.95,-0.145
34.38,237.74,-0.145
34.40,237.52,-0.145
34.42,237.31,-0.145
34.44,237.09,-0.145
34.47,236.87,-0.145
34.49,236.66,-0.145
34.51,236.44,-0.145
34.53,236.22,-0.145
34.55,236.01,-0.145
34.58,235.79,-0.145
34.60,235.58,-0.145
34.62,235.36,-0.145
34.64,235.14,-0.145
34.66,234.93,-0.145
34.68,234.71,-0.145
34.71,234.49,-0.145
34.73,234.27,-0.145
34.75,234.06,-0.145
34.77,233.84,-0.145
34.79,233.63,-0.145
34.81,233.41,-0.145
34.84,233.19,-0.145
34.86,232.98,-0.145
34.88,232.76,-0.145
34.90,232.54,-0.145
34.92,232.33,-0.145
34.94,232.11,-0.145
34.96,231.90,-0.145
34.99,231.68,-0.145
35.01,231.46,-0.145
35.03,231.25,-0.145
35.05,231.03,-0.145
35.07,230.81,-0.145
35.09,230.60,-0.145
35.12,230.38,-0.145
35.14,230.16,-0.145
35.16,229.95,-0.145
35.18,229.73,-0.145
35.20,229.52,-0.145
35.23,229.30,-0.145
35.25,229.08,-0.144
35.27,228.87,-0.144
35.29,228.65,-0.144
35.31,228.43,-0.144
35.33,228.22,-0.144
35.36,228.00,-0.144
35.38,227.78,-0.144
35.40,227.57,-0.144
35.42,227.35,-0.144
35.44,227.13,-0.144
35.46,226.92,-0.144
35.49,226.70,-0.144
35.51,226.48,-0.144
35.53,226.27,-0.144
35.55,226.05,-0.144
35.57,225.83,-0.144
35.59,225.62,-0.144
35.61,225.40,-0.144
35.64,225.18,-0.144
35.66,224.97,-0.144
35.68,224.75,-0.144
35.70,224.54,-0.144
35.72,224.32,-0.144
35.74,224.10,-0.144
35.77,223.89,-0.144
35.79,223.67,-0.144
35.81,223.45,-0.144
35.83,223.24,-0.144
35.85,223.02,-0.144
35.88,222.80,-0.144
35.90,222.59,-0.144
35.92,222.37,-0.144
35.94,222.15,-0.144
35.96,221.94,-0.144
35.98,221.72,-0.144
36.01,221.50,-0.144
36.03,221.29,-0.144
36.05,221.07,-0.144
36.07,220.85,-0.144
36.09,220.64,-0.144
36.11,220.42,-0.144
36.14,220.20,-0.144
36.16,219.99,-0.143
36.18,219.77,-0.143
36.20,219.55,-0.143
36.22,219.34,-0.143
36.24,219.12,-0.143
36.26,218.90,-0.143
36.29,218.69,-0.143
36.31,218.47,-0.143
36.33,218.26,-0.143
36.35,218.04,-0.143
36.37,217.82,-0.143
36.39,217.61,-0.143
36.42,217.39,-0.143
36.44,217.17,-0.143
36.46,216.96,-0.143
36.48,216.74,-0.143
36.50,216.52,-0.143
36.53,216.31,-0.143
36.55,216.09,-0.143
36.57,215.87,-0.143
36.59,215.66,-0.143
36.61,215.44,-0.143
36.63,215.22,-0.143
36.66,215.01,-0.143
36.68,214.79,-0.143
36.70,214.57,-0.143
36.72,214.36,-0.143
36.74,214.14,-0.143
36.76,213.92,-0.143
36.79,213.71,-0.143
36.81,213.49,-0.143
36.83,213.27,-0.143
36.85,213.06,-0.143
36.87,212.84,-0.143
36.89,212.62,-0.143
36.91,212.41,-0.142
36.94,212.19,-0.142
36.96,211.97,-0.142
36.98,211.76,-0.142
37.00,211.54,-0.142
37.02,211.33,-0.142
37.04,211.11,-0.142
37.07,210.89,-0.142
37.09,210.67,-0.142
37.11,210.46,-0.142
37.13,210.24,-0.142
37.15,210.03,-0.142
37.18,209.81,-0.142
37.20,209.59,-0.142
37.22,209.38,-0.142
37.24,209.16,-0.142
37.26,208.94,-0.142
37.28,208.73,-0.142
37.31,208.51,-0.142
37.33,208.29,-0.142
37.35,208.08,-0.142
37.37,207.86,-0.142
37.39,207.64,-0.142
37.41,207.43,-0.142
37.44,207.21,-0.142
37.46,206.99,-0.142
37.48,206.78,-0.142
37.50,206.56,-0.142
37.52,206.34,-0.142
37.54,206.13,-0.142
37.56,205.91,-0.142
37.59,205.69,-0.142
37.61,205.48,-0.142
37.63,205.26,-0.142
37.65,205.04,-0.141
37.67,204.83,-0.141
37.69,204.61,-0.141
37.72,204.39,-0.141
37.74,204.18,-0.141
37.76,203.96,-0.141
37.78,203.74,-0.141
37.80,203.53,-0.141
37.83,203.31,-0.141
37.85,203.10,-0.141
37.87,202.88,-0.141
37.89,202.66,-0.141
37.91,202.44,-0.141
37.93,202.23,-0.141
37.96,202.01,-0.141
37.98,201.79,-0.141
38.00,201.58,-0.141
38.02,201.36,-0.141
38.04,201.15,-0.141
38.06,200.93,-0.141
38.09,200.71,-0.141
38.11,200.50,-0.141
38.13,200.28,-0.141
38.15,200.06,-0.141
38.17,199.85,-0.141
38.19,199.63,-0.141
38.21,199.41,-0.141
38.24,199.20,-0.141
38.26,198.98,-0.141
38.28,198.76,-0.141
38.30,198.55,-0.141
38.32,198.33,-0.141
38.34,198.11,-0.141
38.37,197.90,-0.141
38.39,197.68,-0.141
38.41,197.46,-0.141
38.43,197.25,-0.141
38.45,197.03,-0.140
38.48,196.81,-0.140
38.50,196.60,-0.140
38.52,196.38,-0.140
38.54,196.16,-0.140
38.56,195.95,-0.140
38.58,195.73,-0.140
38.61,195.51,-0.140
38.63,195.30,-0.140
38.65,195.08,-0.140
38.67,194.86,-0.140
38.69,194.65,-0.140
38.71,194.43,-0.140
38.74,194.22,-0.140
38.76,194.00,-0.140
38.78,193.78,-0.140
38.80,193.57,-0.140
38.82,193.35,-0.140
38.84,193.13,-0.140
38.86,192.92,-0.140
38.89,192.70,-0.140
38.91,192.48,-0.140
38.93,192.27,-0.140
38.95,192.05,-0.140
38.97,191.83,-0.140
38.99,191.62,-0.140
39.02,191.40,-0.140
39.04,191.18,-0.140
39.06,190.97,-0.140
39.08,190.75,-0.140
39.10,190.54,-0.140
39.13,190.32,-0.139
39.15,190.10,-0.139
39.17,189.88,-0.139
39.19,189.67,-0.139
39.21,189.45,-0.139
39.23,189.23,-0.139
39.26,189.02,-0.139
39.28,188.80,-0.139
39.30,188.58,-0.139
39.32,188.37,-0.139
39.34,188.15,-0.139
39.36,187.94,-0.139
39.39,187.72,-0.139
39.41,187.50,-0.139
39.43,187.28,-0.139
39.45,187.07,-0.139
39.47,186.85,-0.139
39.49,186.63,-0.139
39.51,186.42,-0.139
39.54,186.20,-0.139
39.56,185.98,-0.139
39.58,185.77,-0.139
39.60,185.55,-0.139
39.62,185.34,-0.139
39.64,185.12,-0.139
39.67,184.90,-0.139
39.69,184.69,-0.139
39.71,184.47,-0.139
39.73,184.25,-0.139
39.75,184.03,-0.139
39.78,183.82,-0.139
39.80,183.60,-0.139
39.82,183.38,-0.139
39.84,183.17,-0.139
39.86,182.95,-0.138
39.88,182.74,-0.138
39.91,182.52,-0.138
39.93,182.30,-0.138
39.95,182.09,-0.138
39.97,181.87,-0.138
39.99,181.65,-0.138
40.01,181.44,-0.138
40.04,181.22,-0.138
40.06,181.00,-0.138
40.08,180.79,-0.138
40.10,180.57,-0.138
40.12,180.35,-0.138
40.14,180.14,-0.138
40.16,179.92,-0.138
40.19,179.70,-0.138
40.21,179.49,-0.138
40.23,179.27,-0.138
40.25,179.05,-0.138
40.27,178.84,-0.138
40.29,178.62,-0.138
40.32,178.40,-0.138
40.34,178.19,-0.137
40.36,177.97,-0.137
40.38,177.75,-0.137
40.40,177.54,-0.137
40.43,177.32,-0.137
40.45,177.10,-0.137
40.47,176.89,-0.137
40.49,176.67,-0.137
40.51,176.45,-0.137
40.53,176.24,-0.137
40.56,176.02,-0.137
40.58,175.80,-0.137
40.60,175.59,-0.137
40.62,175.37,-0.137
40.64,175.15,-0.137
40.66,174.94,-0.137
40.69,174.72,-0.137
40.71,174.50,-0.137
40.73,174.29,-0.136
40.75,174.07,-0.136
40.77,173.85,-0.136
40.79,173.64,-0.136
40.81,173.42,-0.136
40.84,173.21,-0.136
40.86,172.99,-0.136
40.88,172.77,-0.136
40.90,172.55,-0.136
40.92,172.34,-0.136
40.94,172.12,-0.136
40.97,171.90,-0.136
40.99,171.69,-0.136
41.01,171.47,-0.136
41.03,171.25,-0.136
41.05,171.04,-0.136
41.08,170.82,-0.136
41.10,170.60,-0.136
41.12,170.39,-0.136
41.14,170.17,-0.136
[...]
140.99,28.55,0.077
141.01,28.77,0.077
141.03,28.99,0.077
141.05,29.20,0.077
141.07,29.42,0.077
141.10,29.64,0.077
141.12,29.85,0.077
141.14,30.07,0.077
141.16,30.29,0.077
141.18,30.50,0.077
141.20,30.72,0.077
141.23,30.94,0.077
141.25,31.16,0.077
141.27,31.37,0.077
141.29,31.59,0.078
141.31,31.81,0.078
141.33,32.02,0.078
141.35,32.24,0.078
141.38,32.46,0.078
141.40,32.67,0.078
141.42,32.89,0.078
141.44,33.11,0.078
141.46,33.32,0.078
141.48,33.54,0.078
141.51,33.76,0.078
141.53,33.97,0.078
141.55,34.19,0.078
141.57,34.41,0.078
141.59,34.62,0.078
141.62,34.84,0.078
141.64,35.06,0.078
141.66,35.28,0.078
141.68,35.49,0.078
141.70,35.71,0.078
141.72,35.93,0.079
141.75,36.14,0.079
141.77,36.36,0.079
141.79,36.58,0.079
141.81,36.79,0.079
141.83,37.01,0.079
141.85,37.23,0.079
141.88,37.44,0.079
141.90,37.66,0.079
141.92,37.88,0.079
141.94,38.09,0.079
141.96,38.31,0.079
141.98,38.53,0.079
142.00,38.74,0.079
142.03,38.96,0.079
142.05,39.18,0.079
142.07,39.39,0.079
142.09,39.61,0.079
142.11,39.83,0.079
142.13,40.05,0.080
142.16,40.26,0.080
142.18,40.48,0.080
142.20,40.70,0.080
142.22,40.91,0.080
142.24,41.13,0.080
142.27,41.35,0.080
142.29,41.56,0.080
142.31,41.78,0.080
142.33,42.00,0.080
142.35,42.21,0.080
142.37,42.43,0.080
142.40,42.65,0.080
142.42,42.86,0.080
142.44,43.08,0.080
142.46,43.30,0.080
142.48,43.51,0.080
142.50,43.73,0.080
142.53,43.95,0.080
142.55,44.16,0.081
142.57,44.38,0.081
142.59,44.60,0.081
142.61,44.82,0.081
142.63,45.03,0.081
142.65,45.25,0.081
142.68,45.47,0.081
142.70,45.68,0.081
142.72,45.90,0.081
142.74,46.12,0.081
142.76,46.33,0.081
142.78,46.55,0.081
142.81,46.77,0.081
142.83,46.98,0.081
142.85,47.20,0.081
142.87,47.42,0.081
142.89,47.64,0.081
142.92,47.85,0.081
142.94,48.07,0.082
142.96,48.29,0.082
142.98,48.50,0.082
143.00,48.72,0.082
143.02,48.94,0.082
143.05,49.15,0.082
143.07,49.37,0.082
143.09,49.59,0.082
143.11,49.80,0.082
143.13,50.02,0.082
143.15,50.24,0.082
143.18,50.45,0.082
143.20,50.67,0.082
143.22,50.89,0.082
143.24,51.10,0.082
143.26,51.32,0.082
143.28,51.54,0.082
143.30,51.75,0.082
143.33,51.97,0.082
143.35,52.19,0.082
143.37,52.41,0.083
143.39,52.62,0.083
143.41,52.84,0.083
143.43,53.06,0.083
143.46,53.27,0.083
143.48,53.49,0.083
143.50,53.71,0.083
143.52,53.92,0.083
143.54,54.14,0.083
143.57,54.36,0.083
143.59,54.57,0.083
143.61,54.79,0.083
143.63,55.01,0.083
143.65,55.22,0.083
143.67,55.44,0.083
143.70,55.66,0.083
143.72,55.87,0.083
143.74,56.09,0.083
143.76,56.31,0.083
143.78,56.53,0.084
143.80,56.74,0.084
143.83,56.96,0.084
143.85,57.18,0.084
143.87,57.39,0.084
143.89,57.61,0.084
143.91,57.83,0.084
143.93,58.04,0.084
143.95,58.26,0.084
143.98,58.48,0.084
144.00,58.69,0.084
144.02,58.91,0.084
144.04,59.13,0.084
144.06,59.34,0.084
144.08,59.56,0.084
144.11,59.78,0.084
144.13,60.00,0.084
144.15,60.21,0.084
144.17,60.43,0.084
144.19,60.65,0.085
144.22,60.86,0.085
144.24,61.08,0.085
144.26,61.30,0.085
144.28,61.51,0.085
144.30,61.73,0.085
144.32,61.95,0.085
144.35,62.16,0.085
144.37,62.38,0.085
144.39,62.60,0.085
144.41,62.81,0.085
144.43,63.03,0.085
144.45,63.25,0.085
144.48,63.46,0.085
144.50,63.68,0.085
144.52,63.90,0.085
144.54,64.11,0.085
144.56,64.33,0.085
144.58,64.55,0.086
144.60,64.77,0.086
144.63,64.98,0.086
144.65,65.20,0.086
144.67,65.42,0.086
144.69,65.63,0.086
144.71,65.85,0.086
144.73,66.07,0.086
144.76,66.28,0.086
144.78,66.50,0.086
144.80,66.72,0.086
144.82,66.93,0.086
144.84,67.15,0.086
144.87,67.37,0.086
144.89,67.58,0.086
144.91,67.80,0.086
144.93,68.02,0.086
144.95,68.23,0.086
144.97,68.45,0.086
145.00,68.67,0.086
145.02,68.88,0.087
145.04,69.10,0.087
145.06,69.32,0.087
145.08,69.53,0.087
145.10,69.75,0.087
145.13,69.97,0.087
145.15,70.18,0.087
145.17,70.40,0.087
145.19,70.62,0.087
145.21,70.84,0.087
145.23,71.05,0.087
145.25,71.27,0.087
145.28,71.49,0.087
145.30,71.70,0.087
145.32,71.92,0.087
145.34,72.14,0.087
145.36,72.35,0.087
145.38,72.57,0.087
145.41,72.79,0.088
145.43,73.00,0.088
145.45,73.22,0.088
145.47,73.44,0.088
145.49,73.65,0.088
145.52,73.87,0.088
145.54,74.09,0.088
145.56,74.30,0.088
145.58,74.52,0.088
145.60,74.74,0.088
145.62,74.95,0.088
145.65,75.17,0.088
145.67,75.39,0.088
145.69,75.60,0.088
145.71,75.82,0.088
145.73,76.04,0.088
145.75,76.25,0.088
145.78,76.47,0.088
145.80,76.69,0.089
145.82,76.91,0.089
145.84,77.12,0.089
145.86,77.34,0.089
145.88,77.56,0.089
145.90,77.77,0.089
145.93,77.99,0.089
145.95,78.21,0.089
145.97,78.42,0.089
145.99,78.64,0.089
146.01,78.86,0.089
146.03,79.07,0.089
146.06,79.29,0.089
146.08,79.51,0.089
146.10,79.72,0.089
146.12,79.94,0.089
146.14,80.16,0.089
146.17,80.37,0.089
146.19,80.59,0.089
146.21,80.81,0.090
146.23,81.03,0.090
146.25,81.24,0.090
146.27,81.46,0.090
146.30,81.68,0.090
146.32,81.89,0.090
146.34,82.11,0.090
146.36,82.33,0.090
146.38,82.54,0.090
146.40,82.76,0.090
146.43,82.98,0.090
146.45,83.19,0.090
146.47,83.41,0.090
146.49,83.63,0.090
146.51,83.84,0.090
146.53,84.06,0.090
146.55,84.28,0.090
146.58,84.49,0.090
146.60,84.71,0.090
146.62,84.93,0.090
146.64,85.14,0.091
146.66,85.36,0.091
146.68,85.58,0.091
146.71,85.79,0.091
146.73,86.01,0.091
146.75,86.23,0.091
146.77,86.44,0.091
146.79,86.66,0.091
146.82,86.88,0.091
146.84,87.10,0.091
146.86,87.31,0.091
146.88,87.53,0.091
146.90,87.75,0.091
146.92,87.96,0.091
146.95,88.18,0.091
146.97,88.40,0.091
146.99,88.61,0.091
147.01,88.83,0.091
147.03,89.05,0.092
147.05,89.26,0.092
147.08,89.48,0.092
147.10,89.70,0.092
147.12,89.91,0.092
147.14,90.13,0.092
147.16,90.35,0.092
147.18,90.56,0.092
147.20,90.78,0.092
147.23,91.00,0.092
147.25,91.21,0.092
147.27,91.43,0.092
147.29,91.65,0.092
147.31,91.86,0.092
147.33,92.08,0.092
147.36,92.30,0.092
147.38,92.52,0.092
147.40,92.73,0.092
147.42,92.95,0.093
147.44,93.17,0.093
147.47,93.38,0.093
147.49,93.60,0.093
147.51,93.82,0.093
147.53,94.03,0.093
147.55,94.25,0.093
147.57,94.47,0.093
147.60,94.68,0.093
147.62,94.90,0.093
147.64,95.12,0.093
147.66,95.33,0.093
147.68,95.55,0.093
147.70,95.77,0.093
147.73,95.98,0.093
147.75,96.20,0.093
147.77,96.42,0.093
147.79,96.63,0.094
147.81,96.85,0.094
147.83,97.07,0.094
147.85,97.28,0.094
147.88,97.50,0.094
147.90,97.72,0.094
147.92,97.93,0.094
147.94,98.15,0.094
147.96,98.37,0.094
147.98,98.59,0.094
148.01,98.80,0.094
148.03,99.02,0.094
148.05,99.23,0.094
148.07,99.45,0.094
148.09,99.67,0.094
148.12,99.89,0.094
148.14,100.10,0.094
148.16,100.32,0.095
148.18,100.54,0.095
148.20,100.75,0.095
148.22,100.97,0.095
148.25,101.19,0.095
148.27,101.40,0.095
148.29,101.62,0.095
148.31,101.84,0.095
148.33,102.05,0.095
148.35,102.27,0.095
148.38,102.49,0.095
148.40,102.70,0.095
148.42,102.92,0.095
148.44,103.14,0.095
148.46,103.35,0.095
148.48,103.57,0.096
148.50,103.79,0.096
148.53,104.01,0.096
148.55,104.22,0.096
148.57,104.44,0.096
148.59,104.65,0.096
148.61,104.87,0.096
148.63,105.09,0.096
148.66,105.31,0.096
148.68,105.52,0.096
148.70,105.74,0.096
148.72,105.96,0.096
148.74,106.17,0.096
148.77,106.39,0.096
148.79,106.61,0.096
148.81,106.82,0.097
148.83,107.04,0.097
148.85,107.26,0.097
148.87,107.47,0.097
148.90,107.69,0.097
148.92,107.91,0.097
148.94,108.12,0.097
148.96,108.34,0.097
148.98,108.56,0.097
149.00,108.77,0.097
149.03,108.99,0.097
149.05,109.21,0.097
149.07,109.43,0.097
149.09,109.64,0.097
149.11,109.86,0.098
149.13,110.08,0.098
149.15,110.29,0.098
149.18,110.51,0.098
149.20,110.73,0.098
149.22,110.94,0.098
149.24,111.16,0.098
149.26,111.38,0.098
149.28,111.59,0.098
149.31,111.81,0.098
149.33,112.02,0.098
149.35,112.24,0.098
149.37,112.46,0.098
149.39,112.68,0.098
149.42,112.89,0.099
149.44,113.11,0.099
149.46,113.33,0.099
149.48,113.54,0.099
149.50,113.76,0.099
149.52,113.98,0.099
149.55,114.19,0.099
149.57,114.41,0.099
149.59,114.63,0.099
149.61,114.84,0.099
149.63,115.06,0.099
149.65,115.28,0.100
149.68,115.49,0.100
149.70,115.71,0.100
149.72,115.93,0.100
149.74,116.14,0.100
149.76,116.36,0.100
149.78,116.58,0.100
149.80,116.79,0.100
149.83,117.01,0.100
149.85,117.23,0.100
149.87,117.44,0.101
149.89,117.66,0.101
149.91,117.88,0.101
149.93,118.10,0.101
149.96,118.31,0.101
149.98,118.53,0.101
150.00,118.74,0.101
150.02,118.96,0.101
150.04,119.18,0.102
150.07,119.39,0.102
150.09,119.61,0.102
150.11,119.83,0.102
150.13,120.04,0.102
150.15,120.26,0.102
150.17,120.48,0.102
150.20,120.69,0.102
150.22,120.91,0.103
150.24,121.13,0.103
150.26,121.34,0.103
150.28,121.56,0.103
150.30,121.78,0.103
150.33,121.99,0.103
150.35,122.21,0.104
150.37,122.43,0.104
150.39,122.64,0.104
150.41,122.86,0.104
150.43,123.08,0.104
150.45,123.29,0.105
150.48,123.51,0.105
150.50,123.73,0.105
150.52,123.94,0.105
150.54,124.16,0.105
150.56,124.37,0.106
150.58,124.59,0.106
150.61,124.81,0.106
150.63,125.02,0.106
150.65,125.24,0.107
150.67,125.46,0.107
150.69,125.67,0.107
150.72,125.89,0.107
150.74,126.11,0.108
150.76,126.32,0.108
150.78,126.54,0.108
150.80,126.76,0.109
150.82,126.97,0.109
150.85,127.19,0.109
150.87,127.41,0.110
150.89,127.62,0.110
150.91,127.84,0.110
150.93,128.06,0.110
150.95,128.27,0.111
150.98,128.49,0.111
151.00,128.71,0.111
151.02,128.92,0.111
151.04,129.14,0.111
151.06,129.35,0.112
151.08,129.57,0.112
151.10,129.79,0.112
151.13,130.00,0.113
151.15,130.22,0.113
151.17,130.44,0.113
151.19,130.65,0.114
151.21,130.87,0.114
151.23,131.09,0.114
151.26,131.30,0.114
151.28,131.52,0.114
151.30,131.73,0.115
151.32,131.95,0.115
151.34,132.17,0.115
151.37,132.38,0.116
151.39,132.60,0.116
151.41,132.82,0.116
151.43,133.03,0.116
151.45,133.25,0.116
151.47,133.47,0.117
151.50,133.68,0.117
151.52,133.90,0.117
151.54,134.11,0.117
151.56,134.33,0.117
151.58,134.55,0.118
151.60,134.76,0.118
151.63,134.98,0.118
151.65,135.20,0.118
151.67,135.41,0.118
151.69,135.63,0.118
151.71,135.84,0.118
151.73,136.06,0.118
151.75,136.28,0.119
151.78,136.49,0.119
151.80,136.71,0.119
151.82,136.93,0.119
151.84,137.14,0.119
151.86,137.36,0.119
151.88,137.58,0.119
151.91,137.79,0.119
151.93,138.01,0.120
151.95,138.23,0.120
151.97,138.44,0.120
151.99,138.66,0.120
152.02,138.88,0.120
152.04,139.10,0.120
152.06,139.31,0.120
152.08,139.53,0.120
152.10,139.75,0.120
152.12,139.96,0.120
152.15,140.18,0.120
152.17,140.40,0.120
152.19,140.61,0.121
152.21,140.83,0.121
152.23,141.04,0.121
152.25,141.26,0.121
152.28,141.48,0.121
152.30,141.70,0.121
152.32,141.91,0.121
152.34,142.13,0.121
152.36,142.35,0.121
152.38,142.56,0.121
152.40,142.78,0.121
152.43,143.00,0.121
152.45,143.21,0.121
152.47,143.43,0.121
152.49,143.65,0.121
152.51,143.86,0.121
152.53,144.08,0.121
152.56,144.30,0.121
152.58,144.51,0.121
152.60,144.73,0.121
152.62,144.95,0.122
152.64,145.17,0.122
152.67,145.38,0.122
152.69,145.60,0.122
152.71,145.82,0.122
152.73,146.03,0.122
152.75,146.25,0.122
152.77,146.47,0.122
152.80,146.68,0.122
152.82,146.90,0.122
152.84,147.12,0.122
152.86,147.33,0.122
152.88,147.55,0.122
152.90,147.77,0.122
152.93,147.98,0.122
152.95,148.20,0.122
152.97,148.42,0.122
152.99,148.63,0.122
153.01,148.85,0.122
153.03,149.07,0.122
153.05,149.28,0.122
153.08,149.50,0.122
153.10,149.72,0.122
153.12,149.94,0.122
153.14,150.15,0.122
153.16,150.37,0.122
153.18,150.59,0.123
153.21,150.80,0.123
153.23,151.02,0.123
153.25,151.24,0.123
153.27,151.45,0.123
153.29,151.67,0.123
153.32,151.89,0.123
153.34,152.11,0.123
153.36,152.32,0.123
153.38,152.54,0.123
153.40,152.76,0.123
153.42,152.97,0.123
153.45,153.19,0.123
153.47,153.40,0.123
153.49,153.62,0.123
153.51,153.84,0.123
153.53,154.05,0.123
153.55,154.27,0.123
153.58,154.49,0.123
153.60,154.70,0.123
153.62,154.92,0.123
153.64,155.14,0.123
153.66,155.35,0.123
153.68,155.57,0.123
153.70,155.79,0.124
153.73,156.01,0.124
153.75,156.22,0.124
153.77,156.44,0.124
153.79,156.66,0.124
153.81,156.87,0.124
153.83,157.09,0.124
153.86,157.31,0.124
153.88,157.53,0.124
153.90,157.74,0.124
153.92,157.96,0.124
153.94,158.18,0.124
153.97,158.39,0.124
153.99,158.61,0.124
154.01,158.82,0.124
154.03,159.04,0.124
154.05,159.26,0.124
154.07,159.48,0.124
154.10,159.69,0.124
154.12,159.91,0.124
154.14,160.13,0.125
154.16,160.34,0.125
154.18,160.56,0.125
154.20,160.77,0.125
154.23,160.99,0.125
154.25,161.21,0.125
154.27,161.42,0.125
154.29,161.64,0.125
154.31,161.86,0.125
154.33,162.08,0.125
154.35,162.29,0.125
154.38,162.51,0.125
154.40,162.73,0.125
154.42,162.94,0.125
154.44,163.16,0.125
154.46,163.38,0.125
154.48,163.59,0.125
154.51,163.81,0.125
154.53,164.03,0.125
154.55,164.24,0.125
154.57,164.46,0.125
154.59,164.68,0.125
154.62,164.90,0.126
154.64,165.11,0.126
154.66,165.33,0.126
154.68,165.55,0.126
154.70,165.76,0.126
154.72,165.98,0.126
154.75,166.20,0.126
154.77,166.41,0.126
154.79,166.63,0.126
154.81,166.85,0.126
154.83,167.06,0.126
154.85,167.28,0.126
154.88,167.50,0.126
154.90,167.71,0.126
154.92,167.93,0.126
154.94,168.15,0.126
154.96,168.36,0.126
154.98,168.58,0.126
155.00,168.80,0.126
155.03,169.01,0.126
155.05,169.23,0.126
155.07,169.45,0.126
155.09,169.66,0.126
155.11,169.88,0.127
155.13,170.10,0.127
155.16,170.31,0.127
155.18,170.53,0.127
155.20,170.75,0.127
155.22,170.97,0.127
155.24,171.18,0.127
155.27,171.40,0.127
155.29,171.62,0.127
155.31,171.83,0.127
155.33,172.05,0.127
155.35,172.27,0.127
155.37,172.48,0.127
155.40,172.70,0.127
155.42,172.92,0.127
155.44,173.13,0.127
155.46,173.35,0.127
155.48,173.57,0.127
155.50,173.78,0.127
155.53,174.00,0.127
155.55,174.22,0.127
155.57,174.43,0.128
155.59,174.65,0.128
155.61,174.87,0.128
155.63,175.08,0.128
155.65,175.30,0.128
155.68,175.52,0.128
155.70,175.73,0.128
155.72,175.95,0.128
155.74,176.17,0.128
155.76,176.38,0.128
155.78,176.60,0.128
155.81,176.82,0.128
155.83,177.04,0.128
155.85,177.25,0.128
155.87,177.47,0.128
155.89,177.69,0.128
155.92,177.90,0.128
155.94,178.12,0.128
155.96,178.34,0.129
155.98,178.55,0.129
156.00,178.77,0.129
156.02,178.99,0.129
156.05,179.20,0.129
156.07,179.42,0.129
156.09,179.64,0.129
156.11,179.85,0.129
156.13,180.07,0.129
156.15,180.29,0.129
156.18,180.50,0.129
156.20,180.72,0.129
156.22,180.94,0.129
156.24,181.15,0.129
156.26,181.37,0.129
156.28,181.59,0.129
156.30,181.80,0.130
156.33,182.02,0.130
156.35,182.24,0.130
156.37,182.45,0.130
156.39,182.67,0.130
156.41,182.89,0.130
156.43,183.11,0.130
156.46,183.32,0.130
156.48,183.54,0.130
156.50,183.76,0.130
156.52,183.97,0.130
156.54,184.19,0.130
156.57,184.41,0.130
156.59,184.62,0.130
156.61,184.84,0.130
156.63,185.06,0.131
156.65,185.27,0.131
156.67,185.49,0.131
156.70,185.71,0.131
156.72,185.92,0.131
156.74,186.14,0.131
156.76,186.36,0.131
156.78,186.57,0.131
156.80,186.79,0.131
156.83,187.01,0.131
156.85,187.23,0.131
156.87,187.44,0.131
156.89,187.66,0.131
156.91,187.87,0.131
156.93,188.09,0.131
156.95,188.31,0.131
156.98,188.52,0.131
157.00,188.74,0.131
157.02,188.96,0.131
157.04,189.17,0.131
157.06,189.39,0.131
157.08,189.61,0.131
157.11,189.82,0.131
157.13,190.04,0.131
157.15,190.26,0.131
157.17,190.47,0.131
157.19,190.69,0.131
157.22,190.91,0.131
157.24,191.13,0.131
157.26,191.34,0.131
157.28,191.56,0.131
157.30,191.78,0.131
157.32,191.99,0.131
157.35,192.21,0.132
157.37,192.43,0.132
157.39,192.64,0.132
157.41,192.86,0.132
157.43,193.08,0.132
157.45,193.29,0.132
157.48,193.51,0.132
157.50,193.73,0.132
157.52,193.95,0.132
157.54,194.16,0.132
157.56,194.38,0.132
157.58,194.60,0.132
157.60,194.81,0.132
157.63,195.03,0.132
157.65,195.25,0.132
157.67,195.46,0.132
157.69,195.68,0.132
157.71,195.90,0.132
157.73,196.11,0.132
157.76,196.33,0.132
157.78,196.55,0.132
157.80,196.76,0.132
157.82,196.98,0.132
157.84,197.20,0.132
157.87,197.41,0.132
157.89,197.63,0.132
157.91,197.85,0.132
157.93,198.07,0.133
157.95,198.28,0.133
157.97,198.50,0.133
158.00,198.72,0.133
158.02,198.93,0.133
158.04,199.15,0.133
158.06,199.37,0.133
158.08,199.58,0.133
158.10,199.80,0.133
158.13,200.02,0.133
158.15,200.23,0.133
158.17,200.45,0.133
158.19,200.67,0.133
158.21,200.88,0.133
158.23,201.10,0.133
158.25,201.32,0.133
158.28,201.53,0.133
158.30,201.75,0.133
158.32,201.97,0.133
158.34,202.19,0.133
158.36,202.40,0.133
158.38,202.62,0.133
158.41,202.84,0.133
158.43,203.05,0.133
158.45,203.27,0.133
158.47,203.49,0.133
158.49,203.70,0.133
158.52,203.92,0.133
158.54,204.14,0.134
158.56,204.35,0.134
158.58,204.57,0.134
158.60,204.79,0.134
158.62,205.00,0.134
158.65,205.22,0.134
158.67,205.44,0.134
158.69,205.65,0.134
158.71,205.87,0.134
158.73,206.09,0.134
158.75,206.30,0.134
158.78,206.52,0.134
158.80,206.74,0.134
158.82,206.95,0.134
158.84,207.17,0.134
158.86,207.39,0.134
158.88,207.60,0.134
158.90,207.82,0.134
158.93,208.04,0.134
158.95,208.25,0.134
158.97,208.47,0.134
158.99,208.69,0.134
159.01,208.91,0.134
159.03,209.12,0.134
159.06,209.34,0.134
159.08,209.56,0.134
159.10,209.77,0.134
159.12,209.99,0.135
159.14,210.21,0.135
159.17,210.42,0.135
159.19,210.64,0.135
159.21,210.86,0.135
159.23,211.07,0.135
159.25,211.29,0.135
159.27,211.51,0.135
159.30,211.72,0.135
159.32,211.94,0.135
159.34,212.16,0.135
159.36,212.37,0.135
159.38,212.59,0.135
159.40,212.81,0.135
159.43,213.02,0.135
159.45,213.24,0.135
159.47,213.46,0.135
159.49,213.67,0.135
159.51,213.89,0.135
159.53,214.11,0.135
159.55,214.32,0.135
159.58,214.54,0.135
159.60,214.76,0.135
159.62,214.97,0.135
159.64,215.19,0.135
159.66,215.41,0.135
159.68,215.62,0.135
159.71,215.84,0.135
159.73,216.06,0.135
159.75,216.28,0.136
159.77,216.49,0.136
159.79,216.71,0.136
159.82,216.93,0.136
159.84,217.14,0.136
159.86,217.36,0.136
159.88,217.58,0.136
159.90,217.79,0.136
159.92,218.01,0.136
159.95,218.23,0.136
159.97,218.44,0.136
159.99,218.66,0.136
160.01,218.88,0.136
160.03,219.09,0.136
160.05,219.31,0.136
160.08,219.53,0.136
160.10,219.74,0.136
160.12,219.96,0.136
160.14,220.18,0.136
160.16,220.39,0.136
160.18,220.61,0.136
160.20,220.83,0.136
160.23,221.04,0.136
160.25,221.26,0.136
160.27,221.48,0.136
160.29,221.69,0.137
160.31,221.91,0.137
160.33,222.13,0.137
160.36,222.34,0.137
160.38,222.56,0.137
160.40,222.78,0.137
160.42,223.00,0.137
160.44,223.21,0.137
160.47,223.43,0.137
160.49,223.65,0.137
160.51,223.86,0.137
160.53,224.08,0.137
160.55,224.30,0.137
160.57,224.52,0.137
160.60,224.73,0.137
160.62,224.95,0.137
160.64,225.16,0.137
160.66,225.38,0.137
160.68,225.60,0.137
160.70,225.81,0.137
160.73,226.03,0.137
160.75,226.25,0.137
160.77,226.46,0.137
160.79,226.68,0.137
160.81,226.90,0.137
160.83,227.11,0.137
160.85,227.33,0.137
160.88,227.55,0.137
160.90,227.77,0.138
160.92,227.98,0.138
160.94,228.20,0.138
160.96,228.42,0.138
160.98,228.63,0.138
161.01,228.85,0.138
161.03,229.07,0.138
161.05,229.28,0.138
161.07,229.50,0.138
161.09,229.72,0.138
161.12,229.93,0.138
161.14,230.15,0.138
161.16,230.37,0.138
161.18,230.59,0.138
161.20,230.80,0.138
161.22,231.02,0.138
161.25,231.23,0.138
161.27,231.45,0.138
161.29,231.67,0.138
161.31,231.88,0.138
161.33,232.10,0.138
161.35,232.32,0.138
161.38,232.54,0.138
161.40,232.75,0.138
161.42,232.97,0.138
161.44,233.19,0.138
161.46,233.40,0.138
161.48,233.62,0.138
161.50,233.83,0.139
161.53,234.05,0.139
161.55,234.27,0.139
161.57,234.49,0.139
161.59,234.70,0.139
161.61,234.92,0.139
161.63,235.14,0.139
161.66,235.35,0.139
161.68,235.57,0.139
161.70,235.79,0.139
161.72,236.00,0.139
161.74,236.22,0.139
161.77,236.44,0.139
161.79,236.65,0.139
161.81,236.87,0.139
161.83,237.09,0.139
161.85,237.30,0.139
161.87,237.52,0.139
161.90,237.74,0.139
161.92,237.95,0.139
161.94,238.17,0.139
161.96,238.39,0.139
161.98,238.60,0.139
162.00,238.82,0.139
162.03,239.04,0.139
162.05,239.26,0.139
162.07,239.47,0.139
162.09,239.69,0.140
162.11,239.90,0.140
162.13,240.12,0.140
162.15,240.34,0.140
162.18,240.55,0.140
162.20,240.77,0.140
162.22,240.99,0.140
162.24,241.21,0.140
162.26,241.42,0.140
162.28,241.64,0.140
162.31,241.86,0.140
162.33,242.07,0.140
162.35,242.29,0.140
162.37,242.51,0.140
162.39,242.72,0.140
162.42,242.94,0.140
162.44,243.16,0.140
162.46,243.37,0.140
162.48,243.59,0.140
162.50,243.81,0.140
162.52,244.02,0.140
162.55,244.24,0.140
162.57,244.46,0.140
162.59,244.68,0.140
162.61,244.89,0.140
162.63,245.11,0.141
162.65,245.32,0.141
162.68,245.54,0.141
162.70,245.76,0.141
162.72,245.98,0.141
162.74,246.19,0.141
162.76,246.41,0.141
162.78,246.63,0.141
162.80,246.84,0.141
162.83,247.06,0.141
162.85,247.28,0.141
162.87,247.49,0.141
162.89,247.71,0.141
162.91,247.93,0.141
162.93,248.14,0.141
162.96,248.36,
162.98,248.58,
162.99,,