File: DSC/Olivia/2025_07_16_3CBD_1PVP40kD_MeOH_n60_140C_5Cmin_x4.csv
Filename,2025_07_16_3CBD_1PVP40kD_MeOH_n60_140C_5Cmin_x4
Instrument name,DSC2A-00468 (192.168.1.100)
Operator,Gibbons
rundate,7/16/2025
Sample name,2025_07_16_3CBD_1PVP40kD_MeOH_n60_140C_5Cmin_x4
proceduresegments,Data Off ; Equilibrate -60.00 °C; Data On ; Ramp 5.00 °C/min to 140.00 °C; Data Off ; Isothermal 2.0 min; Data On ; Ramp 5.00 °C/min to -60.00 °C; Data Off ; Isothermal 2.0 min; Data On ; Ramp 5.00 °C/min to 140.00 °C; Data Off ; Isothermal 2.0 min; Data On ; Ramp 5.00 °C/min to -60.00 °C; Data Off ; Isothermal 2.0 min; Data On ; Ramp 5.00 °C/min to 140.00 °C; Data Off ; Isothermal 2.0 min; Data On ; Ramp 5.00 °C/min to -60.00 °C; Data Off ; Isothermal 2.0 min; Data On ; Ramp 5.00 °C/min to 30.00 °C
[File Parameters]
Run date,7/16/2025 10:06:48 PM
Trios version,5.1.1.46572
Original File Name,
Current File Name,D:\DSC2500\Gibbons\2025_07_16_3CBD_1PVP40kD_MeOH_n60_140C_5Cmin_x4.tri
[Procedure]
Procedure Name,CBD_PVP_ASD_Vac_MeOH_n60_140C_5Cmin_x4
Sample Name,2025_07_16_3CBD_1PVP40kD_MeOH_n60_140C_5Cmin_x4
Sample Mass,4.09 mg
Reference Sample Mass,0 mg
Pan Mass,56.27 mg
Pan Number,15
Reference Pan Mass,56.6 mg
Reference Pan Number,1
Pan Type,Tzero Aluminum Hermetic
Comments,DSC Consumables Al Hermetically Sealed Pan. Y1 Tray (Google Sheet: DSC_Samples_Y1_Tray_June2025).
Project Name,Pharmaceuticals - Cannabinoids
Operator,Gibbons
Test,Custom
Unload Max Temperature,30
Unload Min Temperature,30
Load Max Temperature,30
Load Min Temperature,30
Stop on Gas Flow Error,Yes
[Signal List]
Signal #1,Time (min)
Signal #2,Temperature (°C)
Signal #3,Heat Flow (mW)
Signal #4,Delta T (µV)
Signal #5,Delta Tzero (µV)
Signal #6,Tzero Temperature (°C)
Signal #7,Cell Purge (mL/min)
Signal #8,Heater Temp (°C)
Signal #9,Power Delivered (W)
Signal #10,Reference Junction Temperature (°C)
Signal #11,Flange Temperature (°C)
Signal #12,Heat Flow Phase (rad)
Signal #13,Total Heat Capacity (J/°C)
Signal #14,Heat Capacity (J/°C)
[Configuration]
Company Name,ASU
Instrument Name,DSC2A-00468
Instrument Type,DSC2500
Serial Number,DSC2A-00468
IP,192.168.1.100
Location of Instrument,MRRC
DisplayType,Unknown
Sample Interval ,0.1 s/pt
Selected Heat Flow,T4P
Exotherm Direction,Down
Cell Serial,DRC2-00792
Lid Type,Standard
Cooler,RCS 90
Leave Cooler on at End of Sequence,On
Gas 2,Nitrogen
Gas Selected,Channel 1
Flow Rate,50 mL/min
Secondary Purge,On
Licensed Heat Flow,Heat Flow T4P
Modulation Licensed,Yes
[Versions]
Common IDD Version,1
Cortex Version,VER 2.10.2.31
Driver,5.0.0.6
GDM Version,1.0.3.3
TouchscreenVersion,1.0.0.16145
FEP Version,1.2.1.21
FEP Bootloader,2.0.0.5
AutoSampler Version,2.1.1.26
Auto Sampler Bootloader,2.0.0.5
FCM Version,1.1.0.3
FCM Bootloader,2.0.0.5
[Experiment Logs]
Experiment Log Entry # 1,Air Cool is off.
Experiment Log Entry # 3,Data On set to 0
Experiment Log Entry # 5,Equilibrate Segment -60 (C) Started
Experiment Log Entry # 7,Data On set to 1
Experiment Log Entry # 9,Ramp Segment 5 C/min to 140 Started
Experiment Log Entry # 11,Data On set to 0
Experiment Log Entry # 13,Isothermal Segment 2 min started
Experiment Log Entry # 15,Data On set to 1
Experiment Log Entry # 17,Ramp Segment 5 C/min to -60 Started
Experiment Log Entry # 19,Data On set to 0
Experiment Log Entry # 21,Isothermal Segment 2 min started
Experiment Log Entry # 23,Data On set to 1
Experiment Log Entry # 25,Ramp Segment 5 C/min to 140 Started
Experiment Log Entry # 27,Data On set to 0
Experiment Log Entry # 29,Isothermal Segment 2 min started
Experiment Log Entry # 31,Data On set to 1
Experiment Log Entry # 33,Ramp Segment 5 C/min to -60 Started
Experiment Log Entry # 35,Data On set to 0
Experiment Log Entry # 37,Isothermal Segment 2 min started
Experiment Log Entry # 39,Data On set to 1
Experiment Log Entry # 41,Ramp Segment 5 C/min to 140 Started
Experiment Log Entry # 43,Data On set to 0
Experiment Log Entry # 45,Isothermal Segment 2 min started
Experiment Log Entry # 47,Data On set to 1
Experiment Log Entry # 49,Ramp Segment 5 C/min to -60 Started
Experiment Log Entry # 51,Data On set to 0
Experiment Log Entry # 53,Isothermal Segment 2 min started
Experiment Log Entry # 55,Data On set to 1
Experiment Log Entry # 57,Ramp Segment 5 C/min to 30 Started
[Method Log]
Method Log Entry # 1,Data Off
Method Log Entry # 2,Equilibrate -60 °C
Method Log Entry # 3,Data On
Method Log Entry # 4,(Ramp 148396) Ramp 5 °C/minute to 140 °C
Method Log Entry # 5,Data Off
Method Log Entry # 6,Isothermal 2 minutes
Method Log Entry # 7,Data On
Method Log Entry # 8,(Ramp 148400) Ramp 5 °C/minute to -60 °C
Method Log Entry # 9,Data Off
Method Log Entry # 10,Isothermal 2 minutes
Method Log Entry # 11,Data On
Method Log Entry # 12,(Ramp 148404) Ramp 5 °C/minute to 140 °C
Method Log Entry # 13,Data Off
Method Log Entry # 14,Isothermal 2 minutes
Method Log Entry # 15,Data On
Method Log Entry # 16,(Ramp 148408) Ramp 5 °C/minute to -60 °C
Method Log Entry # 17,Data Off
Method Log Entry # 18,Isothermal 2 minutes
Method Log Entry # 19,Data On
Method Log Entry # 20,(Ramp 148412) Ramp 5 °C/minute to 140 °C
Method Log Entry # 21,Data Off
Method Log Entry # 22,Isothermal 2 minutes
Method Log Entry # 23,Data On
Method Log Entry # 24,(Ramp 148416) Ramp 5 °C/minute to -60 °C
Method Log Entry # 25,Data Off
Method Log Entry # 26,Isothermal 2 minutes
Method Log Entry # 27,Data On
Method Log Entry # 28,(Ramp 148420) Ramp 5 °C/minute to 30 °C
Cell Serial,DRC2-00792
[T1 Calibration]
Slope,-0.008529666
Offset,9.636258
Initial Temperature,98.23
GUID,f8bfdadc-4977-4fdf-ba6d-0ba9134940c3
[TZero Calibration]
Date Applied,11/29/2022 4:06:13 PM
Description,From -89.059 °C to 396.009 °C at 20.000°C/min
Gas Type,Nitrogen
Pan Type,None
Source Files 1,C:\Users\yargerlab\Desktop\DSC Data\General\TZero_calibration_11_29_22_2nd(2).tri
Source Files 2,C:\Users\yargerlab\Desktop\DSC Data\General\TZero_calibration_11_29_22_2nd(3).tri
Delta T Offset,13.05235
Delta T Slope,-0.007271007
Delta T0 Offset,-13.69128
Delta T0 Slope,0.06063341
[Temperature Calibration]
Date Applied,11/29/2022 7:12:28 PM
Description,From 106.590 °C to 186.590 °C at 10.000°C/min
Gas Type,Nitrogen
Pan Type,Tzero Aluminum Hermetic
Source Files 1,C:\Users\yargerlab\Desktop\DSC Data\General\Indium(6).tri
Measured 1,157.391
Known 1,156.598
[Cell Constant Calibration]
Date Applied,11/29/2022 7:12:29 PM
Description,From 106.590 °C to 186.590 °C at 10.000°C/min
Gas Type,Nitrogen
Pan Type,Tzero Aluminum Hermetic
Source Files 1,C:\Users\yargerlab\Desktop\DSC Data\General\Indium(6).tri
T4P KCell,1.006051
Onset Slope,63.26126 mW/°C
[Direct Cp Calibration]
Date Applied,11/30/2022 11:04:51 AM
Description,From -79.983 °C to 298.409 °C at 10.000°C/min
Gas Type,Nitrogen
Pan Type,Tzero Aluminum Hermetic
Source Files 1,C:\Users\yargerlab\Desktop\DSC Data\General\Sapphire_Heat_Capacity_11_30_22.tri
[Rev Cp Calibration]
Date Applied,11/30/2022 1:58:51 PM
Description,From -79.996 °C to 292.812 °C at 3.000°C/min
Gas Type,Nitrogen
Pan Type,Tzero Aluminum Hermetic
Source Files 1,C:\Users\yargerlab\Desktop\DSC Data\General\Sapphire_MDSC_Calibration_11_30_22.tri
[step]
Ramp 5.00 °C/min to 140.00 °C
Time,Temperature,Heat Flow (Normalized)
min,°C,W/g
0.00,-59.74,-0.033
0.03,-59.75,-0.032
0.05,-59.76,-0.024
0.08,-59.74,-0.005
0.11,-59.71,0.014
0.13,-59.65,0.033
0.16,-59.57,0.048
0.19,-59.48,0.060
0.21,-59.37,0.072
0.24,-59.26,0.078
0.27,-59.15,0.083
0.29,-59.04,0.088
0.32,-58.92,0.092
0.35,-58.80,0.093
0.37,-58.67,0.095
0.40,-58.55,0.096
0.43,-58.42,0.098
0.45,-58.29,0.099
0.48,-58.17,0.100
0.51,-58.04,0.100
0.53,-57.91,0.101
0.56,-57.78,0.101
0.59,-57.65,0.102
0.61,-57.52,0.102
0.64,-57.39,0.102
0.67,-57.26,0.103
0.69,-57.13,0.103
0.72,-57.00,0.103
0.75,-56.87,0.103
0.77,-56.74,0.103
0.80,-56.60,0.104
0.83,-56.47,0.104
0.85,-56.34,0.104
0.88,-56.21,0.104
0.91,-56.08,0.104
0.93,-55.95,0.104
0.96,-55.81,0.104
0.99,-55.68,0.104
1.01,-55.55,0.104
1.04,-55.42,0.104
1.07,-55.28,0.104
1.09,-55.15,0.104
1.12,-55.02,0.104
1.15,-54.89,0.104
1.17,-54.75,0.104
1.20,-54.62,0.104
1.23,-54.49,0.104
1.25,-54.36,0.104
1.28,-54.22,0.104
1.31,-54.09,0.104
1.33,-53.96,0.104
1.36,-53.83,0.104
1.39,-53.69,0.104
1.41,-53.56,0.104
1.44,-53.43,0.104
1.47,-53.29,0.104
1.49,-53.16,0.104
1.52,-53.03,0.104
1.55,-52.89,0.104
1.57,-52.76,0.104
1.60,-52.63,0.103
1.63,-52.50,0.103
1.65,-52.36,0.103
1.68,-52.23,0.103
1.71,-52.10,0.103
1.73,-51.96,0.103
1.76,-51.83,0.103
1.79,-51.70,0.103
1.81,-51.56,0.103
1.84,-51.43,0.103
1.87,-51.30,0.103
1.89,-51.16,0.103
1.92,-51.03,0.103
1.95,-50.90,0.103
1.97,-50.76,0.103
2.00,-50.63,0.103
2.03,-50.50,0.103
2.05,-50.36,0.103
2.08,-50.23,0.103
2.11,-50.10,0.102
2.13,-49.96,0.103
2.16,-49.83,0.102
2.19,-49.70,0.102
2.21,-49.57,0.102
2.24,-49.43,0.102
2.27,-49.30,0.102
2.29,-49.17,0.102
2.32,-49.03,0.102
2.35,-48.90,0.102
2.37,-48.77,0.102
2.40,-48.63,0.102
2.43,-48.50,0.102
2.45,-48.37,0.102
2.48,-48.23,0.102
2.51,-48.10,0.102
2.53,-47.97,0.102
2.56,-47.84,0.102
2.59,-47.70,0.102
2.61,-47.57,0.102
2.64,-47.44,0.102
2.67,-47.30,0.101
2.69,-47.17,0.102
2.72,-47.04,0.102
2.75,-46.90,0.102
2.77,-46.77,0.102
2.80,-46.64,0.102
2.83,-46.51,0.102
2.85,-46.37,0.102
2.88,-46.24,0.102
2.91,-46.10,0.102
2.93,-45.97,0.102
2.96,-45.84,0.102
2.99,-45.70,0.102
3.01,-45.57,0.102
3.04,-45.44,0.102
3.07,-45.30,0.102
3.09,-45.17,0.102
3.12,-45.04,0.102
3.15,-44.90,0.102
3.17,-44.77,0.102
3.20,-44.64,0.102
3.23,-44.50,0.102
3.25,-44.37,0.102
3.28,-44.24,0.102
3.31,-44.10,0.102
3.33,-43.97,0.102
3.36,-43.84,0.101
3.39,-43.70,0.102
3.41,-43.57,0.102
3.44,-43.44,0.102
3.47,-43.30,0.102
3.49,-43.17,0.102
3.52,-43.03,0.101
3.55,-42.90,0.101
3.57,-42.77,0.101
3.60,-42.63,0.101
3.63,-42.50,0.101
3.65,-42.37,0.101
3.68,-42.23,0.101
3.71,-42.10,0.101
3.73,-41.97,0.102
3.76,-41.83,0.101
3.79,-41.70,0.101
3.81,-41.57,0.101
3.84,-41.43,0.101
3.87,-41.30,0.101
3.89,-41.17,0.101
3.92,-41.03,0.101
3.95,-40.90,0.101
3.97,-40.77,0.101
4.00,-40.63,0.101
4.03,-40.50,0.101
4.05,-40.37,0.101
4.08,-40.23,0.101
4.11,-40.10,0.101
4.13,-39.96,0.101
4.16,-39.83,0.101
4.19,-39.70,0.102
4.21,-39.56,0.102
4.24,-39.43,0.102
4.27,-39.30,0.101
4.29,-39.16,0.101
4.32,-39.03,0.102
4.35,-38.90,0.101
4.37,-38.76,0.101
4.40,-38.63,0.101
4.43,-38.50,0.101
4.45,-38.36,0.101
4.48,-38.23,0.102
4.51,-38.09,0.101
4.53,-37.96,0.101
4.56,-37.83,0.101
4.59,-37.70,0.101
4.61,-37.56,0.101
4.64,-37.43,0.101
4.67,-37.29,0.101
4.69,-37.16,0.101
4.72,-37.03,0.102
4.75,-36.89,0.101
4.77,-36.76,0.102
4.80,-36.63,0.101
4.83,-36.49,0.101
4.85,-36.36,0.102
4.88,-36.23,0.102
4.91,-36.09,0.101
4.93,-35.96,0.101
4.96,-35.82,0.101
4.99,-35.69,0.102
5.01,-35.56,0.101
5.04,-35.42,0.102
5.07,-35.29,0.102
5.09,-35.16,0.101
5.12,-35.02,0.101
5.15,-34.89,0.101
5.17,-34.76,0.101
5.20,-34.62,0.102
5.23,-34.49,0.101
5.25,-34.36,0.102
5.28,-34.22,0.102
5.31,-34.09,0.102
5.33,-33.96,0.102
5.36,-33.82,0.102
5.39,-33.69,0.102
5.41,-33.56,0.102
5.44,-33.42,0.102
5.47,-33.29,0.102
5.49,-33.15,0.102
5.52,-33.02,0.102
5.55,-32.89,0.102
5.57,-32.75,0.102
5.60,-32.62,0.102
5.63,-32.49,0.102
5.65,-32.35,0.102
5.68,-32.22,0.102
5.71,-32.09,0.102
5.73,-31.95,0.102
5.76,-31.82,0.102
5.79,-31.69,0.102
5.81,-31.55,0.102
5.84,-31.42,0.102
5.87,-31.29,0.102
5.89,-31.15,0.102
5.92,-31.02,0.102
5.95,-30.88,0.102
5.97,-30.75,0.102
6.00,-30.62,0.102
6.03,-30.48,0.102
6.05,-30.35,0.102
6.08,-30.22,0.102
6.11,-30.08,0.102
6.13,-29.95,0.102
6.16,-29.82,0.102
6.19,-29.68,0.102
6.21,-29.55,0.102
6.24,-29.42,0.102
6.27,-29.28,0.102
6.29,-29.15,0.102
6.32,-29.02,0.102
6.35,-28.88,0.102
6.37,-28.75,0.102
6.40,-28.62,0.102
6.43,-28.48,0.102
6.45,-28.35,0.102
6.48,-28.21,0.102
6.51,-28.08,0.102
6.53,-27.95,0.102
6.56,-27.81,0.102
6.59,-27.68,0.102
6.61,-27.55,0.102
6.64,-27.42,0.102
6.67,-27.28,0.102
6.69,-27.15,0.102
6.72,-27.02,0.102
6.75,-26.88,0.102
6.77,-26.75,0.102
6.80,-26.61,0.102
6.83,-26.48,0.102
6.85,-26.35,0.102
6.88,-26.21,0.102
6.91,-26.08,0.102
6.93,-25.95,0.102
6.96,-25.81,0.102
6.99,-25.68,0.102
7.01,-25.55,0.102
7.04,-25.41,0.102
7.07,-25.28,0.102
7.09,-25.15,0.102
7.12,-25.01,0.102
7.15,-24.88,0.102
7.17,-24.75,0.102
7.20,-24.61,0.102
7.23,-24.48,0.102
7.25,-24.35,0.102
7.28,-24.21,0.102
7.31,-24.08,0.102
7.33,-23.94,0.102
7.36,-23.81,0.102
7.39,-23.68,0.102
7.41,-23.54,0.102
7.44,-23.41,0.102
7.47,-23.28,0.102
7.49,-23.14,0.102
7.52,-23.01,0.102
7.55,-22.88,0.102
7.57,-22.74,0.102
7.60,-22.61,0.103
7.63,-22.48,0.102
7.65,-22.34,0.103
7.68,-22.21,0.103
7.71,-22.08,0.103
7.73,-21.94,0.103
7.76,-21.81,0.103
7.79,-21.68,0.103
7.81,-21.54,0.103
7.84,-21.41,0.103
7.87,-21.27,0.103
7.89,-21.14,0.103
7.92,-21.01,0.103
7.95,-20.88,0.103
7.97,-20.74,0.103
8.00,-20.61,0.103
8.03,-20.47,0.103
8.05,-20.34,0.103
8.08,-20.21,0.103
8.11,-20.07,0.103
8.13,-19.94,0.103
8.16,-19.81,0.103
8.19,-19.67,0.103
8.21,-19.54,0.103
8.24,-19.41,0.103
8.27,-19.27,0.103
8.29,-19.14,0.103
8.32,-19.01,0.103
8.35,-18.87,0.103
8.37,-18.74,0.103
8.40,-18.60,0.103
8.43,-18.47,0.103
8.45,-18.34,0.103
8.48,-18.20,0.103
8.51,-18.07,0.103
8.53,-17.94,0.103
8.56,-17.80,0.103
8.59,-17.67,0.103
8.61,-17.54,0.103
8.64,-17.40,0.104
8.67,-17.27,0.104
8.69,-17.14,0.104
8.72,-17.00,0.104
8.75,-16.87,0.104
8.77,-16.74,0.104
8.80,-16.60,0.104
8.83,-16.47,0.104
8.85,-16.34,0.104
8.88,-16.21,0.104
8.91,-16.07,0.104
8.93,-15.94,0.104
8.96,-15.80,0.104
8.99,-15.67,0.104
9.01,-15.54,0.104
9.04,-15.40,0.104
9.07,-15.27,0.104
9.09,-15.14,0.104
9.12,-15.00,0.104
9.15,-14.87,0.104
9.17,-14.73,0.104
9.20,-14.60,0.104
9.23,-14.47,0.104
9.25,-14.34,0.104
9.28,-14.20,0.104
9.31,-14.07,0.104
9.33,-13.93,0.104
9.36,-13.80,0.104
9.39,-13.67,0.104
9.41,-13.53,0.104
9.44,-13.40,0.104
9.47,-13.27,0.104
9.49,-13.13,0.104
9.52,-13.00,0.104
9.55,-12.87,0.104
9.57,-12.73,0.104
9.60,-12.60,0.105
9.63,-12.47,0.105
9.65,-12.33,0.105
9.68,-12.20,0.105
9.71,-12.07,0.105
9.73,-11.93,0.105
9.76,-11.80,0.105
9.79,-11.67,0.105
9.81,-11.53,0.105
9.84,-11.40,0.105
9.87,-11.27,0.105
9.89,-11.13,0.105
9.92,-11.00,0.105
9.95,-10.87,0.105
9.97,-10.73,0.105
10.00,-10.60,0.105
10.03,-10.47,0.105
10.05,-10.33,0.105
10.08,-10.20,0.105
10.11,-10.06,0.105
10.13,-9.93,0.105
10.16,-9.80,0.105
10.19,-9.66,0.105
10.21,-9.53,0.105
10.24,-9.40,0.105
10.27,-9.26,0.105
10.29,-9.13,0.105
10.32,-9.00,0.105
10.35,-8.86,0.106
10.37,-8.73,0.105
10.40,-8.60,0.106
10.43,-8.46,0.106
10.45,-8.33,0.106
10.48,-8.20,0.106
10.51,-8.06,0.106
10.53,-7.93,0.106
10.56,-7.79,0.106
10.59,-7.66,0.106
10.61,-7.53,0.106
10.64,-7.39,0.106
10.67,-7.26,0.106
10.69,-7.13,0.106
10.72,-6.99,0.106
10.75,-6.86,0.106
10.77,-6.73,0.106
10.80,-6.59,0.106
10.83,-6.46,0.106
10.85,-6.33,0.106
10.88,-6.19,0.106
10.91,-6.06,0.106
10.93,-5.93,0.106
10.96,-5.79,0.107
10.99,-5.66,0.107
11.01,-5.53,0.107
11.04,-5.39,0.107
11.07,-5.26,0.107
11.09,-5.13,0.107
11.12,-4.99,0.107
11.15,-4.86,0.107
11.17,-4.73,0.107
11.20,-4.59,0.107
11.23,-4.46,0.107
11.25,-4.33,0.107
11.28,-4.19,0.107
11.31,-4.06,0.107
11.33,-3.93,0.107
11.36,-3.79,0.107
11.39,-3.66,0.107
11.41,-3.52,0.107
11.44,-3.39,0.107
11.47,-3.26,0.107
11.49,-3.13,0.107
11.52,-2.99,0.107
11.55,-2.86,0.108
11.57,-2.72,0.108
11.60,-2.59,0.108
11.63,-2.46,0.108
11.65,-2.32,0.108
11.68,-2.19,0.108
11.71,-2.06,0.108
11.73,-1.92,0.108
11.76,-1.79,0.108
11.79,-1.66,0.108
11.81,-1.52,0.108
11.84,-1.39,0.108
11.87,-1.26,0.108
11.89,-1.12,0.108
11.92,-0.99,0.108
11.95,-0.86,0.108
11.97,-0.72,0.109
12.00,-0.59,0.109
12.03,-0.46,0.109
12.05,-0.32,0.109
12.08,-0.19,0.109
12.11,-0.05,0.109
12.13,0.08,0.109
12.16,0.21,0.109
12.19,0.34,0.109
12.21,0.48,0.109
12.24,0.61,0.109
12.27,0.75,0.109
12.29,0.88,0.110
12.32,1.01,0.110
12.35,1.15,0.110
12.37,1.28,0.110
12.40,1.41,0.110
12.43,1.55,0.110
12.45,1.68,0.110
12.48,1.81,0.110
12.51,1.95,0.110
12.53,2.08,0.110
12.56,2.21,0.110
12.59,2.35,0.111
12.61,2.48,0.111
12.64,2.61,0.111
12.67,2.75,0.111
12.69,2.88,0.111
12.72,3.01,0.111
12.75,3.15,0.111
12.77,3.28,0.111
12.80,3.42,0.111
12.83,3.55,0.111
12.85,3.68,0.111
12.88,3.82,0.111
12.91,3.95,0.112
12.93,4.08,0.112
12.96,4.21,0.112
12.99,4.35,0.112
13.01,4.48,0.112
13.04,4.61,0.112
13.07,4.75,0.112
13.09,4.88,0.112
13.12,5.01,0.112
13.15,5.15,0.113
13.17,5.28,0.113
13.20,5.42,0.113
13.23,5.55,0.113
13.25,5.68,0.113
13.28,5.82,0.113
13.31,5.95,0.113
13.33,6.08,0.114
13.36,6.22,0.114
13.39,6.35,0.114
13.41,6.48,0.114
13.44,6.62,0.114
13.47,6.75,0.114
13.49,6.88,0.114
13.52,7.02,0.114
13.55,7.15,0.114
13.57,7.28,0.115
13.60,7.41,0.115
13.63,7.55,0.115
13.65,7.68,0.115
13.68,7.82,0.115
13.71,7.95,0.115
13.73,8.08,0.115
13.76,8.21,0.116
13.79,8.35,0.116
13.81,8.48,0.116
13.84,8.62,0.116
13.87,8.75,0.116
13.89,8.88,0.116
13.92,9.02,0.117
13.95,9.15,0.117
13.97,9.28,0.117
14.00,9.41,0.117
14.03,9.55,0.117
14.05,9.68,0.117
14.08,9.82,0.118
14.11,9.95,0.118
14.13,10.08,0.118
14.16,10.22,0.118
14.19,10.35,0.118
14.21,10.48,0.119
14.24,10.62,0.119
14.27,10.75,0.119
14.29,10.88,0.119
14.32,11.02,0.119
14.35,11.15,0.119
14.37,11.28,0.120
14.40,11.42,0.120
14.43,11.55,0.120
14.45,11.68,0.120
14.48,11.82,0.120
14.51,11.95,0.121
14.53,12.08,0.121
14.56,12.22,0.121
14.59,12.35,0.121
14.61,12.48,0.121
14.64,12.62,0.122
14.67,12.75,0.122
14.69,12.89,0.122
14.72,13.02,0.122
14.75,13.15,0.122
14.77,13.29,0.123
14.80,13.42,0.123
14.83,13.55,0.123
14.85,13.69,0.123
14.88,13.82,0.123
14.91,13.95,0.124
14.93,14.09,0.124
14.96,14.22,0.124
14.99,14.35,0.124
15.01,14.48,0.125
15.04,14.62,0.125
15.07,14.75,0.125
15.09,14.89,0.125
15.12,15.02,0.125
15.15,15.15,0.126
15.17,15.29,0.126
15.20,15.42,0.126
15.23,15.55,0.126
15.25,15.69,0.126
15.28,15.82,0.126
15.31,15.95,0.127
15.33,16.09,0.127
15.36,16.22,0.127
15.39,16.35,0.127
15.41,16.49,0.128
15.44,16.62,0.128
15.47,16.75,0.128
15.49,16.89,0.128
15.52,17.02,0.128
15.55,17.15,0.129
15.57,17.29,0.129
15.60,17.43,0.129
15.63,17.56,0.130
15.65,17.70,0.130
15.68,17.83,0.130
15.71,17.96,0.131
15.73,18.10,0.131
15.76,18.23,0.131
15.79,18.36,0.131
15.81,18.50,0.131
15.84,18.63,0.131
15.87,18.76,0.131
15.89,18.90,0.131
15.92,19.03,0.132
15.95,19.16,0.132
15.97,19.29,0.132
16.00,19.43,0.132
16.03,19.56,0.132
16.05,19.69,0.132
16.08,19.83,0.132
16.11,19.96,0.133
16.13,20.09,0.133
16.16,20.23,0.133
16.19,20.36,0.133
16.21,20.49,0.133
16.24,20.63,0.133
16.27,20.76,0.134
16.29,20.89,0.134
16.32,21.02,0.134
16.35,21.16,0.134
16.37,21.29,0.134
16.40,21.42,0.134
16.43,21.56,0.135
16.45,21.69,0.135
16.48,21.82,0.135
16.51,21.96,0.135
16.53,22.09,0.135
16.56,22.22,0.136
16.59,22.36,0.136
16.61,22.49,0.136
16.64,22.62,0.136
16.67,22.76,0.136
16.69,22.89,0.137
16.72,23.02,0.137
16.75,23.16,0.137
16.77,23.29,0.137
16.80,23.42,0.137
16.83,23.56,0.138
16.85,23.69,0.138
16.88,23.82,0.138
16.91,23.96,0.138
16.93,24.09,0.138
16.96,24.22,0.138
16.99,24.36,0.139
17.01,24.49,0.139
17.04,24.62,0.139
17.07,24.76,0.139
17.09,24.89,0.139
17.12,25.02,0.140
17.15,25.16,0.140
17.17,25.29,0.140
17.20,25.43,0.140
17.23,25.56,0.140
17.25,25.69,0.141
17.28,25.83,0.141
17.31,25.96,0.141
17.33,26.09,0.141
17.36,26.23,0.141
17.39,26.36,0.141
17.41,26.49,0.142
17.44,26.63,0.142
17.47,26.76,0.142
17.49,26.89,0.142
17.52,27.03,0.142
17.55,27.16,0.142
17.57,27.29,0.143
17.60,27.43,0.143
17.63,27.56,0.143
17.65,27.69,0.143
17.68,27.83,0.143
17.71,27.96,0.143
17.73,28.09,0.144
17.76,28.23,0.144
17.79,28.36,0.144
17.81,28.49,0.144
17.84,28.63,0.144
17.87,28.76,0.144
17.89,28.89,0.145
17.92,29.03,0.145
17.95,29.16,0.145
17.97,29.29,0.145
18.00,29.43,0.145
18.03,29.56,0.146
18.05,29.69,0.146
18.08,29.83,0.146
18.11,29.96,0.146
18.13,30.09,0.146
18.16,30.23,0.146
18.19,30.36,0.147
18.21,30.50,0.147
18.24,30.63,0.147
18.27,30.76,0.147
18.29,30.89,0.147
18.32,31.03,0.147
18.35,31.16,0.147
18.37,31.30,0.148
18.40,31.43,0.148
18.43,31.56,0.148
18.45,31.70,0.148
18.48,31.83,0.148
18.51,31.96,0.148
18.53,32.10,0.148
18.56,32.23,0.148
18.59,32.36,0.148
18.61,32.50,0.149
18.64,32.63,0.149
18.67,32.76,0.149
18.69,32.90,0.149
18.72,33.03,0.149
18.75,33.16,0.149
18.77,33.30,0.149
18.80,33.43,0.149
18.83,33.56,0.149
18.85,33.70,0.149
18.88,33.83,0.150
18.91,33.96,0.150
18.93,34.10,0.150
18.96,34.23,0.150
18.99,34.36,0.150
19.01,34.50,0.150
19.04,34.63,0.150
19.07,34.76,0.150
19.09,34.90,0.150
19.12,35.03,0.150
19.15,35.16,0.150
19.17,35.30,0.150
19.20,35.43,0.150
19.23,35.57,0.150
19.25,35.70,0.150
19.28,35.83,0.151
19.31,35.97,0.151
19.33,36.10,0.151
19.36,36.23,0.151
19.39,36.37,0.151
19.41,36.50,0.151
19.44,36.63,0.151
19.47,36.77,0.151
19.49,36.90,0.151
19.52,37.03,0.151
19.55,37.17,0.151
19.57,37.30,0.151
19.60,37.43,0.151
19.63,37.56,0.151
19.65,37.70,0.151
19.68,37.83,0.151
19.71,37.97,0.151
19.73,38.10,0.151
19.76,38.23,0.151
19.79,38.37,0.151
19.81,38.50,0.151
19.84,38.63,0.151
19.87,38.77,0.151
19.89,38.90,0.151
19.92,39.04,0.151
19.95,39.17,0.151
19.97,39.30,0.151
20.00,39.43,0.151
20.03,39.57,0.151
20.05,39.70,0.151
20.08,39.83,0.151
20.11,39.97,0.151
20.13,40.10,0.151
20.16,40.24,0.151
20.19,40.37,0.151
20.21,40.50,0.151
20.24,40.64,0.151
20.27,40.77,0.151
20.29,40.90,0.151
20.32,41.04,0.151
20.35,41.17,0.151
20.37,41.30,0.151
20.40,41.44,0.151
20.43,41.57,0.151
20.45,41.70,0.151
20.48,41.84,0.151
20.51,41.97,0.151
20.53,42.10,0.151
20.56,42.24,0.151
20.59,42.37,0.151
20.61,42.50,0.151
20.64,42.64,0.151
20.67,42.77,0.151
20.69,42.90,0.151
20.72,43.04,0.151
20.75,43.17,0.151
20.77,43.30,0.151
20.80,43.44,0.152
20.83,43.57,0.152
20.85,43.70,0.152
20.88,43.84,0.152
20.91,43.97,0.152
20.93,44.10,0.152
20.96,44.24,0.152
20.99,44.37,0.152
21.01,44.51,0.152
21.04,44.64,0.152
21.07,44.77,0.152
21.09,44.91,0.152
21.12,45.04,0.152
21.15,45.17,0.152
21.17,45.31,0.152
21.20,45.44,0.152
21.23,45.57,0.152
21.25,45.71,0.152
21.28,45.84,0.152
21.31,45.97,0.152
21.33,46.11,0.152
21.36,46.24,0.152
21.39,46.37,0.152
21.41,46.51,0.152
21.44,46.64,0.152
21.47,46.77,0.152
21.49,46.91,0.152
21.52,47.04,0.152
21.55,47.17,0.152
21.57,47.31,0.152
21.60,47.44,0.152
21.63,47.57,0.152
21.65,47.71,0.152
21.68,47.84,0.152
21.71,47.98,0.152
21.73,48.11,0.152
21.76,48.24,0.152
21.79,48.38,0.152
21.81,48.51,0.153
21.84,48.64,0.153
21.87,48.77,0.153
21.89,48.91,0.153
21.92,49.04,0.153
21.95,49.18,0.153
21.97,49.31,0.153
22.00,49.44,0.153
22.03,49.58,0.153
22.05,49.71,0.153
22.08,49.84,0.153
22.11,49.98,0.153
22.13,50.11,0.153
22.16,50.24,0.153
22.19,50.38,0.153
22.21,50.51,0.153
22.24,50.64,0.153
22.27,50.78,0.153
22.29,50.91,0.153
22.32,51.05,0.153
22.35,51.18,0.153
22.37,51.31,0.153
22.40,51.44,0.153
22.43,51.58,0.153
22.45,51.71,0.153
22.48,51.85,0.153
22.51,51.98,0.154
22.53,52.11,0.154
22.56,52.25,0.154
22.59,52.38,0.154
22.61,52.51,0.154
22.64,52.64,0.154
22.67,52.78,0.154
22.69,52.91,0.154
22.72,53.04,0.154
22.75,53.18,0.154
22.77,53.31,0.154
22.80,53.44,0.154
22.83,53.58,0.154
22.85,53.71,0.154
22.88,53.85,0.154
22.91,53.98,0.154
22.93,54.11,0.154
22.96,54.25,0.154
22.99,54.38,0.154
23.01,54.51,0.154
23.04,54.65,0.154
23.07,54.78,0.154
23.09,54.91,0.154
23.12,55.05,0.154
23.15,55.18,0.154
23.17,55.31,0.154
23.20,55.45,0.154
23.23,55.58,0.155
23.25,55.71,0.155
23.28,55.85,0.155
23.31,55.98,0.155
23.33,56.11,0.155
23.36,56.25,0.155
23.39,56.38,0.155
23.41,56.51,0.155
23.44,56.65,0.155
23.47,56.78,0.155
23.49,56.91,0.155
23.52,57.05,0.155
23.55,57.18,0.155
23.57,57.31,0.155
23.60,57.45,0.155
23.63,57.58,0.155
23.65,57.72,0.155
23.68,57.85,0.155
23.71,57.98,0.155
23.73,58.12,0.155
23.76,58.25,0.155
23.79,58.38,0.155
23.81,58.52,0.155
23.84,58.65,0.155
23.87,58.78,0.155
23.89,58.92,0.155
23.92,59.05,0.155
23.95,59.18,0.155
23.97,59.32,0.155
24.00,59.45,0.155
24.03,59.58,0.155
24.05,59.72,0.155
24.08,59.85,0.156
24.11,59.98,0.155
24.13,60.12,0.156
24.16,60.25,0.156
24.19,60.38,0.156
24.21,60.52,0.156
24.24,60.65,0.156
24.27,60.78,0.156
24.29,60.92,0.156
24.32,61.05,0.156
24.35,61.18,0.156
24.37,61.32,0.156
24.40,61.45,0.156
24.43,61.58,0.156
24.45,61.72,0.156
24.48,61.85,0.156
24.51,61.98,0.156
24.53,62.12,0.156
24.56,62.25,0.156
24.59,62.38,0.156
24.61,62.52,0.156
24.64,62.65,0.156
24.67,62.79,0.156
24.69,62.92,0.157
24.72,63.05,0.157
24.75,63.19,0.157
24.77,63.32,0.157
24.80,63.45,0.157
24.83,63.59,0.157
24.85,63.72,0.157
24.88,63.85,0.157
24.91,63.99,0.157
24.93,64.12,0.157
24.96,64.25,0.157
24.99,64.39,0.157
25.01,64.52,0.157
25.04,64.65,0.157
25.07,64.79,0.157
25.09,64.92,0.157
25.12,65.05,0.157
25.15,65.19,0.157
25.17,65.32,0.157
25.20,65.45,0.157
25.23,65.59,0.157
25.25,65.72,0.157
25.28,65.85,0.157
25.31,65.99,0.157
25.33,66.12,0.157
25.36,66.26,0.157
25.39,66.39,0.157
25.41,66.52,0.158
25.44,66.65,0.158
25.47,66.79,0.158
25.49,66.92,0.158
25.52,67.05,0.158
25.55,67.19,0.158
25.57,67.32,0.158
25.60,67.46,0.158
25.63,67.59,0.158
25.65,67.72,0.158
25.68,67.86,0.158
25.71,67.99,0.158
25.73,68.12,0.158
25.76,68.26,0.158
25.79,68.39,0.158
25.81,68.52,0.158
25.84,68.66,0.158
25.87,68.79,0.158
25.89,68.92,0.158
25.92,69.06,0.158
25.95,69.19,0.158
25.97,69.32,0.158
26.00,69.46,0.158
26.03,69.59,0.158
26.05,69.72,0.158
26.08,69.86,0.158
26.11,69.99,0.158
26.13,70.12,0.159
26.16,70.26,0.159
26.19,70.39,0.159
26.21,70.52,0.159
26.24,70.66,0.159
26.27,70.79,0.159
26.29,70.92,0.159
26.32,71.06,0.159
26.35,71.19,0.159
26.37,71.32,0.159
26.40,71.46,0.159
26.43,71.59,0.159
26.45,71.72,0.159
26.48,71.86,0.159
26.51,71.99,0.159
26.53,72.13,0.159
26.56,72.26,0.159
26.59,72.39,0.159
26.61,72.53,0.159
26.64,72.66,0.159
26.67,72.79,0.159
26.69,72.93,0.159
26.72,73.06,0.159
26.75,73.19,0.159
26.77,73.33,0.159
26.80,73.46,0.159
26.83,73.59,0.159
26.85,73.73,0.159
26.88,73.86,0.159
26.91,73.99,0.159
26.93,74.13,0.159
26.96,74.26,0.159
26.99,74.39,0.159
27.01,74.53,0.159
27.04,74.66,0.159
27.07,74.79,0.159
27.09,74.93,0.159
27.12,75.06,0.159
27.15,75.19,0.159
27.17,75.33,0.159
27.20,75.46,0.159
27.23,75.59,0.159
27.25,75.73,0.159
27.28,75.86,0.159
27.31,75.99,0.159
27.33,76.13,0.159
27.36,76.26,0.159
27.39,76.39,0.159
27.41,76.53,0.159
27.44,76.66,0.159
27.47,76.79,0.159
27.49,76.93,0.159
27.52,77.06,0.159
27.55,77.19,0.159
27.57,77.33,0.159
27.60,77.46,0.159
27.63,77.59,0.159
27.65,77.73,0.159
27.68,77.86,0.159
27.71,78.00,0.159
27.73,78.13,0.159
27.76,78.26,0.159
27.79,78.40,0.159
27.81,78.53,0.159
27.84,78.66,0.159
27.87,78.80,0.159
27.89,78.93,0.159
27.92,79.06,0.159
27.95,79.19,0.159
27.97,79.33,0.160
28.00,79.46,0.160
28.03,79.60,0.160
28.05,79.73,0.160
28.08,79.86,0.160
28.11,80.00,0.160
28.13,80.13,0.160
28.16,80.26,0.160
28.19,80.40,0.160
28.21,80.53,0.160
28.24,80.66,0.160
28.27,80.80,0.160
28.29,80.93,0.160
28.32,81.06,0.160
28.35,81.20,0.160
28.37,81.33,0.160
28.40,81.46,0.160
28.43,81.60,0.160
28.45,81.73,0.160
28.48,81.86,0.160
28.51,82.00,0.159
28.53,82.13,0.159
28.56,82.26,0.159
28.59,82.40,0.159
28.61,82.53,0.159
28.64,82.66,0.159
28.67,82.80,0.159
28.69,82.93,0.160
28.72,83.07,0.160
28.75,83.20,0.159
28.77,83.33,0.160
28.80,83.47,0.159
28.83,83.60,0.159
28.85,83.73,0.159
28.88,83.87,0.159
28.91,84.00,0.159
28.93,84.13,0.159
28.96,84.27,0.159
28.99,84.40,0.159
29.01,84.53,0.159
29.04,84.67,0.159
29.07,84.80,0.159
29.09,84.93,0.159
29.12,85.07,0.159
29.15,85.20,0.159
29.17,85.33,0.159
29.20,85.47,0.159
29.23,85.60,0.159
29.25,85.73,0.159
29.28,85.87,0.159
29.31,86.00,0.160
29.33,86.14,0.159
29.36,86.27,0.160
29.39,86.40,0.160
29.41,86.53,0.160
29.44,86.67,0.160
29.47,86.80,0.160
29.49,86.93,0.160
29.52,87.07,0.159
29.55,87.20,0.160
29.57,87.33,0.160
29.60,87.47,0.160
29.63,87.60,0.160
29.65,87.73,0.160
29.68,87.87,0.160
29.71,88.00,0.160
29.73,88.14,0.160
29.76,88.27,0.160
29.79,88.40,0.160
29.81,88.54,0.160
29.84,88.67,0.160
29.87,88.80,0.160
29.89,88.94,0.160
29.92,89.07,0.160
29.95,89.20,0.160
29.97,89.34,0.160
30.00,89.47,0.160
30.03,89.60,0.160
30.05,89.74,0.160
30.08,89.87,0.160
30.11,90.00,0.160
30.13,90.14,0.160
30.16,90.27,0.160
30.19,90.40,0.160
30.21,90.54,0.160
30.24,90.67,0.160
30.27,90.80,0.160
30.29,90.94,0.160
30.32,91.07,0.160
30.35,91.20,0.160
30.37,91.34,0.160
30.40,91.47,0.160
30.43,91.60,0.160
30.45,91.74,0.160
30.48,91.87,0.160
30.51,92.00,0.160
30.53,92.14,0.160
30.56,92.27,0.160
30.59,92.40,0.160
30.61,92.54,0.160
30.64,92.67,0.160
30.67,92.80,0.160
30.69,92.94,0.161
30.72,93.07,0.161
30.75,93.20,0.161
30.77,93.34,0.161
30.80,93.47,0.161
30.83,93.61,0.161
30.85,93.74,0.161
30.88,93.87,0.161
30.91,94.01,0.161
30.93,94.14,0.161
30.96,94.27,0.161
30.99,94.41,0.161
31.01,94.54,0.161
31.04,94.67,0.161
31.07,94.81,0.161
31.09,94.94,0.161
31.12,95.07,0.161
31.15,95.21,0.161
31.17,95.34,0.161
31.20,95.47,0.161
31.23,95.61,0.161
31.25,95.74,0.161
31.28,95.87,0.161
31.31,96.01,0.161
31.33,96.14,0.161
31.36,96.27,0.161
31.39,96.41,0.161
31.41,96.54,0.161
31.44,96.67,0.161
31.47,96.81,0.161
31.49,96.94,0.161
31.52,97.07,0.161
31.55,97.21,0.161
31.57,97.34,0.161
31.60,97.47,0.161
31.63,97.61,0.161
31.65,97.74,0.161
31.68,97.88,0.161
31.71,98.01,0.161
31.73,98.14,0.161
31.76,98.27,0.161
31.79,98.41,0.161
31.81,98.54,0.161
31.84,98.68,0.161
31.87,98.81,0.161
31.89,98.94,0.161
31.92,99.08,0.161
31.95,99.21,0.161
31.97,99.34,0.161
32.00,99.48,0.161
32.03,99.61,0.161
32.05,99.74,0.161
32.08,99.88,0.161
32.11,100.01,0.161
32.13,100.14,0.161
32.16,100.28,0.161
32.19,100.41,0.161
32.21,100.54,0.162
32.24,100.68,0.161
32.27,100.81,0.162
32.29,100.94,0.162
32.32,101.08,0.162
32.35,101.21,0.162
32.37,101.35,0.162
32.40,101.48,0.162
32.43,101.61,0.162
32.45,101.74,0.162
32.48,101.88,0.162
32.51,102.01,0.162
32.53,102.14,0.162
32.56,102.28,0.162
32.59,102.41,0.162
32.61,102.55,0.162
32.64,102.68,0.162
32.67,102.81,0.162
32.69,102.95,0.162
32.72,103.08,0.162
32.75,103.21,0.162
32.77,103.35,0.162
32.80,103.48,0.162
32.83,103.61,0.162
32.85,103.75,0.162
32.88,103.88,0.162
32.91,104.01,0.162
32.93,104.15,0.162
32.96,104.28,0.162
32.99,104.41,0.162
33.01,104.55,0.162
33.04,104.68,0.162
33.07,104.81,0.162
33.09,104.95,0.162
33.12,105.08,0.162
33.15,105.21,0.162
33.17,105.35,0.162
33.20,105.48,0.162
33.23,105.61,0.162
33.25,105.75,0.162
33.28,105.88,0.162
33.31,106.01,0.162
33.33,106.15,0.162
33.36,106.28,0.162
33.39,106.41,0.162
33.41,106.55,0.162
33.44,106.68,0.162
33.47,106.82,0.162
33.49,106.95,0.162
33.52,107.08,0.162
33.55,107.21,0.162
33.57,107.35,0.162
33.60,107.48,0.162
33.63,107.61,0.162
33.65,107.75,0.162
33.68,107.88,0.162
33.71,108.01,0.162
33.73,108.15,0.162
33.76,108.28,0.162
33.79,108.42,0.162
33.81,108.55,0.162
33.84,108.68,0.162
33.87,108.82,0.162
33.89,108.95,0.162
33.92,109.08,0.162
33.95,109.22,0.162
33.97,109.35,0.162
34.00,109.48,0.162
34.03,109.62,0.162
34.05,109.75,0.162
34.08,109.88,0.162
34.11,110.02,0.162
34.13,110.15,0.162
34.16,110.28,0.162
34.19,110.42,0.162
34.21,110.55,0.162
34.24,110.68,0.162
34.27,110.82,0.162
34.29,110.95,0.162
34.32,111.08,0.162
34.35,111.22,0.162
34.37,111.35,0.162
34.40,111.48,0.162
34.43,111.62,0.162
34.45,111.75,0.162
34.48,111.88,0.162
34.51,112.02,0.162
34.53,112.15,0.162
34.56,112.28,0.162
34.59,112.42,0.162
34.61,112.55,0.162
34.64,112.68,0.162
34.67,112.82,0.162
34.69,112.95,0.162
34.72,113.08,0.162
34.75,113.22,0.162
34.77,113.35,0.162
34.80,113.48,0.162
34.83,113.62,0.162
34.85,113.75,0.162
34.88,113.88,0.162
34.91,114.02,0.162
34.93,114.15,0.162
34.96,114.29,0.162
34.99,114.42,0.162
35.01,114.55,0.162
35.04,114.69,0.162
35.07,114.82,0.162
35.09,114.95,0.162
35.12,115.09,0.162
35.15,115.22,0.162
35.17,115.35,0.162
35.20,115.49,0.162
35.23,115.62,0.162
35.25,115.75,0.162
35.28,115.89,0.162
35.31,116.02,0.162
35.33,116.15,0.162
35.36,116.29,0.162
35.39,116.42,0.162
35.41,116.55,0.162
35.44,116.69,0.162
35.47,116.82,0.162
35.49,116.95,0.162
35.52,117.09,0.162
35.55,117.22,0.162
35.57,117.35,0.162
35.60,117.49,0.162
35.63,117.62,0.162
35.65,117.75,0.162
35.68,117.89,0.162
35.71,118.02,0.162
35.73,118.16,0.162
35.76,118.29,0.162
35.79,118.42,0.162
35.81,118.55,0.162
35.84,118.69,0.162
35.87,118.82,0.162
35.89,118.95,0.162
35.92,119.09,0.162
35.95,119.22,0.162
35.97,119.36,0.162
36.00,119.49,0.162
36.03,119.62,0.162
36.05,119.75,0.162
36.08,119.89,0.162
36.11,120.02,0.162
36.13,120.16,0.162
36.16,120.29,0.162
36.19,120.42,0.161
36.21,120.56,0.161
36.24,120.69,0.161
36.27,120.82,0.161
36.29,120.96,0.161
36.32,121.09,0.161
36.35,121.22,0.161
36.37,121.35,0.161
36.40,121.49,0.161
36.43,121.62,0.161
36.45,121.76,0.161
36.48,121.89,0.161
36.51,122.02,0.161
36.53,122.16,0.161
36.56,122.29,0.161
36.59,122.42,0.161
36.61,122.56,0.161
36.64,122.69,0.161
36.67,122.82,0.161
36.69,122.96,0.161
36.72,123.09,0.161
36.75,123.22,0.161
36.77,123.36,0.161
36.80,123.49,0.161
36.83,123.62,0.161
36.85,123.76,0.161
36.88,123.89,0.161
36.91,124.02,0.161
36.93,124.16,0.161
36.96,124.29,0.161
36.99,124.43,0.161
37.01,124.56,0.161
37.04,124.69,0.161
37.07,124.82,0.161
37.09,124.96,0.161
37.12,125.09,0.161
37.15,125.22,0.161
37.17,125.36,0.161
37.20,125.49,0.161
37.23,125.63,0.161
37.25,125.76,0.161
37.28,125.89,0.161
37.31,126.02,0.161
37.33,126.16,0.161
37.36,126.29,0.161
37.39,126.42,0.161
37.41,126.56,0.161
37.44,126.69,0.161
37.47,126.83,0.161
37.49,126.96,0.161
37.52,127.09,0.161
37.55,127.23,0.161
37.57,127.36,0.161
37.60,127.49,0.161
37.63,127.63,0.161
37.65,127.76,0.161
37.68,127.89,0.161
37.71,128.03,0.161
37.73,128.16,0.161
37.76,128.30,0.161
37.79,128.43,0.161
37.81,128.56,0.161
37.84,128.70,0.161
37.87,128.83,0.161
37.89,128.96,0.161
37.92,129.10,0.161
37.95,129.23,0.161
37.97,129.36,0.161
38.00,129.50,0.161
38.03,129.63,0.160
38.05,129.76,0.160
38.08,129.90,0.160
38.11,130.03,0.160
38.13,130.16,0.160
38.16,130.30,0.160
38.19,130.43,0.160
38.21,130.56,0.160
38.24,130.70,0.160
38.27,130.83,0.160
38.29,130.96,0.160
38.32,131.09,0.160
38.35,131.23,0.160
38.37,131.36,0.160
38.40,131.49,0.160
38.43,131.63,0.160
38.45,131.76,0.160
38.48,131.89,0.160
38.51,132.03,0.160
38.53,132.16,0.160
38.56,132.30,0.160
38.59,132.43,0.160
38.61,132.56,0.160
38.64,132.70,0.160
38.67,132.83,0.160
38.69,132.96,0.160
38.72,133.09,0.160
38.75,133.23,0.160
38.77,133.36,0.160
38.80,133.50,0.160
38.83,133.63,0.160
38.85,133.76,0.160
38.88,133.89,0.160
38.91,134.03,0.159
38.93,134.16,0.159
38.96,134.29,0.159
38.99,134.43,0.159
39.01,134.56,0.159
39.04,134.70,0.159
39.07,134.83,0.159
39.09,134.96,0.159
39.12,135.10,0.159
39.15,135.23,0.159
39.17,135.36,0.159
39.20,135.50,0.159
39.23,135.63,0.159
39.25,135.76,0.159
39.28,135.90,0.159
39.31,136.03,0.159
39.33,136.16,0.159
39.36,136.30,0.159
39.39,136.43,0.159
39.41,136.56,0.159
39.44,136.70,0.159
39.47,136.83,0.159
39.49,136.96,0.159
39.52,137.10,0.159
39.55,137.23,0.159
39.57,137.37,0.159
39.60,137.50,0.159
39.63,137.63,0.159
39.65,137.76,0.159
39.68,137.90,0.158
39.71,138.03,0.158
39.73,138.16,0.158
39.76,138.30,0.158
39.79,138.43,0.158
39.81,138.57,0.158
39.84,138.70,0.158
39.87,138.83,0.158
39.89,138.97,0.158
39.92,139.10,0.158
39.95,139.24,
39.97,139.38,
39.98,,

[step]
Ramp 5.00 °C/min to -60.00 °C
Time,Temperature,Heat Flow (Normalized)
min,°C,W/g
41.99,140.12,-0.068
42.01,140.12,-0.068
42.04,140.12,-0.069
42.07,140.09,-0.096
42.10,140.05,-0.132
42.13,139.98,-0.170
42.16,139.89,-0.204
42.18,139.78,-0.227
42.21,139.67,-0.245
42.24,139.55,-0.256
42.27,139.42,-0.266
42.30,139.29,-0.273
42.33,139.16,-0.278
42.35,139.03,-0.279
42.38,138.89,-0.281
42.41,138.75,-0.283
42.44,138.61,-0.284
42.47,138.48,-0.284
42.49,138.34,-0.285
42.52,138.20,-0.285
42.55,138.06,-0.286
42.58,137.92,-0.287
42.61,137.78,-0.287
42.64,137.64,-0.287
42.66,137.50,-0.288
42.69,137.36,-0.288
42.72,137.22,-0.288
42.75,137.08,-0.288
42.78,136.94,-0.289
42.81,136.79,-0.289
42.84,136.66,-0.289
42.86,136.51,-0.289
42.89,136.37,-0.289
42.92,136.23,-0.289
42.95,136.09,-0.289
42.98,135.95,-0.289
43.01,135.81,-0.289
43.03,135.67,-0.288
43.06,135.52,-0.288
43.09,135.38,-0.288
43.12,135.24,-0.288
43.15,135.10,-0.288
43.18,134.96,-0.288
43.20,134.82,-0.288
43.23,134.68,-0.288
43.26,134.53,-0.287
43.29,134.40,-0.287
43.32,134.25,-0.287
43.34,134.11,-0.287
43.37,133.97,-0.287
43.40,133.83,-0.287
43.43,133.69,-0.287
43.46,133.55,-0.287
43.49,133.40,-0.286
43.51,133.26,-0.286
43.54,133.12,-0.286
43.57,132.98,-0.286
43.60,132.84,-0.286
43.63,132.70,-0.286
43.66,132.55,-0.285
43.69,132.41,-0.285
43.71,132.27,-0.285
43.74,132.13,-0.285
43.77,131.99,-0.285
43.80,131.85,-0.284
43.83,131.71,-0.284
43.86,131.56,-0.284
43.88,131.42,-0.284
43.91,131.28,-0.284
43.94,131.14,-0.283
43.97,131.00,-0.283
44.00,130.86,-0.283
44.03,130.71,-0.283
44.05,130.57,-0.283
44.08,130.43,-0.282
44.11,130.29,-0.282
44.14,130.15,-0.282
44.17,130.01,-0.282
44.19,129.87,-0.282
44.22,129.72,-0.282
44.25,129.58,-0.281
44.28,129.44,-0.281
44.31,129.30,-0.281
44.34,129.16,-0.281
44.36,129.02,-0.280
44.39,128.87,-0.280
44.42,128.73,-0.280
44.45,128.59,-0.280
44.48,128.45,-0.280
44.51,128.31,-0.280
44.54,128.17,-0.280
44.56,128.02,-0.279
44.59,127.88,-0.279
44.62,127.74,-0.279
44.65,127.60,-0.279
44.68,127.46,-0.279
44.71,127.32,-0.279
44.73,127.17,-0.278
44.76,127.03,-0.278
44.79,126.89,-0.278
44.82,126.75,-0.278
44.85,126.61,-0.278
44.88,126.47,-0.278
44.90,126.33,-0.278
44.93,126.18,-0.277
44.96,126.04,-0.277
44.99,125.90,-0.277
45.02,125.76,-0.277
45.04,125.62,-0.277
45.07,125.48,-0.277
45.10,125.33,-0.277
45.13,125.19,-0.277
45.16,125.05,-0.277
45.19,124.91,-0.276
45.21,124.77,-0.276
45.24,124.63,-0.276
45.27,124.49,-0.276
45.30,124.34,-0.276
45.33,124.20,-0.276
45.36,124.06,-0.276
45.39,123.92,-0.275
45.41,123.78,-0.275
45.44,123.63,-0.275
45.47,123.49,-0.275
45.50,123.35,-0.275
45.53,123.21,-0.275
45.56,123.07,-0.275
45.58,122.93,-0.275
45.61,122.79,-0.275
45.64,122.64,-0.274
45.67,122.50,-0.274
45.70,122.36,-0.274
45.73,122.22,-0.274
45.75,122.08,-0.273
45.78,121.94,-0.273
45.81,121.80,-0.273
45.84,121.65,-0.273
45.87,121.51,-0.273
45.89,121.37,-0.273
45.92,121.23,-0.273
45.95,121.09,-0.273
45.98,120.94,-0.273
46.01,120.80,-0.273
46.04,120.66,-0.272
46.06,120.52,-0.272
46.09,120.38,-0.272
46.12,120.24,-0.272
46.15,120.09,-0.272
46.18,119.95,-0.272
46.21,119.81,-0.272
46.24,119.67,-0.272
46.26,119.53,-0.272
46.29,119.39,-0.272
46.32,119.24,-0.272
46.35,119.10,-0.271
46.38,118.96,-0.271
46.41,118.82,-0.271
46.43,118.68,-0.271
46.46,118.54,-0.271
46.49,118.40,-0.271
46.52,118.25,-0.271
46.55,118.11,-0.271
46.58,117.97,-0.271
46.60,117.83,-0.270
46.63,117.69,-0.270
46.66,117.55,-0.270
46.69,117.40,-0.270
46.72,117.26,-0.270
46.74,117.12,-0.270
46.77,116.98,-0.270
46.80,116.84,-0.269
46.83,116.70,-0.269
46.86,116.55,-0.269
46.89,116.41,-0.269
46.91,116.27,-0.269
46.94,116.13,-0.269
46.97,115.99,-0.269
47.00,115.85,-0.269
47.03,115.70,-0.268
47.06,115.56,-0.268
47.09,115.42,-0.268
47.11,115.28,-0.268
47.14,115.14,-0.268
47.17,115.00,-0.268
47.20,114.86,-0.268
47.23,114.71,-0.268
47.26,114.57,-0.268
47.28,114.43,-0.268
47.31,114.29,-0.268
47.34,114.15,-0.268
47.37,114.00,-0.268
47.40,113.86,-0.268
47.43,113.72,-0.268
47.45,113.58,-0.268
47.48,113.44,-0.268
47.51,113.30,-0.268
47.54,113.15,-0.267
47.57,113.01,-0.267
47.59,112.87,-0.267
47.62,112.73,-0.267
47.65,112.59,-0.267
47.68,112.45,-0.267
47.71,112.31,-0.267
47.74,112.16,-0.267
47.76,112.02,-0.267
47.79,111.88,-0.267
47.82,111.74,-0.266
47.85,111.60,-0.266
47.88,111.46,-0.266
47.91,111.31,-0.266
47.94,111.17,-0.266
47.96,111.03,-0.266
47.99,110.89,-0.266
48.02,110.75,-0.266
48.05,110.61,-0.266
48.08,110.47,-0.265
48.11,110.32,-0.265
48.13,110.18,-0.265
48.16,110.04,-0.265
48.19,109.90,-0.265
48.22,109.76,-0.265
48.25,109.61,-0.265
48.28,109.47,-0.265
48.30,109.33,-0.265
48.33,109.19,-0.265
48.36,109.05,-0.265
48.39,108.91,-0.265
48.42,108.76,-0.265
48.44,108.62,-0.265
48.47,108.48,-0.264
48.50,108.34,-0.264
48.53,108.20,-0.264
48.56,108.06,-0.264
48.59,107.92,-0.264
48.61,107.77,-0.264
48.64,107.63,-0.264
48.67,107.49,-0.263
48.70,107.35,-0.263
48.73,107.21,-0.263
48.76,107.07,-0.263
48.79,106.92,-0.263
48.81,106.78,-0.263
48.84,106.64,-0.263
48.87,106.50,-0.263
48.90,106.36,-0.263
48.93,106.22,-0.263
48.96,106.08,-0.263
48.98,105.93,-0.263
49.01,105.79,-0.263
49.04,105.65,-0.263
49.07,105.51,-0.263
49.10,105.37,-0.263
49.13,105.23,-0.262
49.15,105.08,-0.262
49.18,104.94,-0.262
49.21,104.80,-0.262
49.24,104.66,-0.262
49.27,104.52,-0.262
49.29,104.38,-0.262
49.32,104.23,-0.262
49.35,104.09,-0.262
49.38,103.95,-0.262
49.41,103.81,-0.262
49.44,103.67,-0.262
49.46,103.53,-0.261
49.49,103.39,-0.261
49.52,103.24,-0.261
49.55,103.10,-0.261
49.58,102.96,-0.261
49.61,102.82,-0.261
49.64,102.68,-0.261
49.66,102.54,-0.261
49.69,102.39,-0.261
49.72,102.25,-0.261
49.75,102.11,-0.260
49.78,101.97,-0.260
49.81,101.83,-0.260
[...]
256.17,-39.90,0.093
256.18,-39.84,0.093
256.19,-39.77,0.094
256.20,-39.70,0.093
256.22,-39.64,0.093
256.23,-39.57,0.094
256.25,-39.51,0.094
256.26,-39.44,0.093
256.27,-39.37,0.093
256.28,-39.30,0.093
256.30,-39.24,0.094
256.31,-39.17,0.094
256.33,-39.11,0.094
256.34,-39.04,0.094
256.35,-38.97,0.094
256.37,-38.90,0.094
256.38,-38.84,0.093
256.39,-38.77,0.093
256.40,-38.70,0.093
256.42,-38.64,0.094
256.43,-38.57,0.093
256.45,-38.50,0.094
256.46,-38.44,0.094
256.47,-38.37,0.093
256.48,-38.30,0.094
256.50,-38.24,0.093
256.51,-38.17,0.094
256.53,-38.10,0.094
256.54,-38.04,0.094
256.55,-37.97,0.094
256.57,-37.90,0.094
256.58,-37.84,0.094
256.59,-37.77,0.094
256.60,-37.70,0.094
256.62,-37.64,0.094
256.63,-37.57,0.094
256.65,-37.50,0.094
256.66,-37.44,0.094
256.67,-37.37,0.094
256.68,-37.30,0.094
256.70,-37.24,0.094
256.71,-37.17,0.094
256.73,-37.10,0.094
256.74,-37.04,0.094
256.75,-36.97,0.094
256.77,-36.90,0.094
256.78,-36.84,0.094
256.79,-36.77,0.094
256.80,-36.70,0.094
256.82,-36.64,0.094
256.83,-36.57,0.094
256.85,-36.50,0.094
256.86,-36.44,0.094
256.87,-36.37,0.094
256.88,-36.30,0.094
256.90,-36.23,0.094
256.91,-36.17,0.094
256.93,-36.10,0.094
256.94,-36.03,0.094
256.95,-35.97,0.094
256.97,-35.90,0.094
256.98,-35.83,0.094
256.99,-35.77,0.094
257.00,-35.70,0.094
257.02,-35.63,0.094
257.03,-35.57,0.094
257.05,-35.50,0.094
257.06,-35.43,0.094
257.07,-35.37,0.094
257.08,-35.30,0.094
257.10,-35.23,0.094
257.11,-35.17,0.094
257.13,-35.10,0.094
257.14,-35.03,0.094
257.15,-34.96,0.094
257.17,-34.90,0.094
257.18,-34.83,0.094
257.19,-34.77,0.094
257.20,-34.70,0.094
257.22,-34.63,0.094
257.23,-34.57,0.094
257.25,-34.50,0.094
257.26,-34.43,0.094
257.27,-34.36,0.094
257.28,-34.30,0.094
257.30,-34.23,0.094
257.31,-34.16,0.094
257.33,-34.10,0.094
257.34,-34.03,0.094
257.35,-33.96,0.094
257.37,-33.90,0.094
257.38,-33.83,0.094
257.39,-33.76,0.094
257.40,-33.70,0.094
257.42,-33.63,0.094
257.43,-33.56,0.094
257.45,-33.50,0.094
257.46,-33.43,0.094
257.47,-33.36,0.094
257.48,-33.30,0.094
257.50,-33.23,0.094
257.51,-33.16,0.094
257.53,-33.10,0.094
257.54,-33.03,0.094
257.55,-32.96,0.094
257.57,-32.90,0.094
257.58,-32.83,0.094
257.59,-32.76,0.094
257.60,-32.70,0.094
257.62,-32.63,0.094
257.63,-32.56,0.094
257.65,-32.50,0.094
257.66,-32.43,0.094
257.67,-32.36,0.094
257.68,-32.30,0.094
257.70,-32.23,0.094
257.71,-32.16,0.094
257.73,-32.10,0.094
257.74,-32.03,0.094
257.75,-31.96,0.094
257.77,-31.90,0.094
257.78,-31.83,0.094
257.79,-31.76,0.094
257.80,-31.70,0.094
257.82,-31.63,0.094
257.83,-31.56,0.094
257.85,-31.49,0.094
257.86,-31.43,0.094
257.87,-31.36,0.094
257.88,-31.29,0.094
257.90,-31.23,0.094
257.91,-31.16,0.094
257.93,-31.09,0.094
257.94,-31.03,0.094
257.95,-30.96,0.094
257.97,-30.89,0.094
257.98,-30.83,0.094
257.99,-30.76,0.094
258.00,-30.69,0.094
258.02,-30.63,0.094
258.03,-30.56,0.094
258.05,-30.49,0.094
258.06,-30.43,0.094
258.07,-30.36,0.094
258.08,-30.29,0.094
258.10,-30.23,0.094
258.11,-30.16,0.094
258.13,-30.09,0.094
258.14,-30.03,0.094
258.15,-29.96,0.094
258.17,-29.89,0.094
258.18,-29.83,0.094
258.19,-29.76,0.094
258.20,-29.69,0.094
258.22,-29.63,0.094
258.23,-29.56,0.095
258.25,-29.49,0.094
258.26,-29.43,0.094
258.27,-29.36,0.095
258.28,-29.29,0.094
258.30,-29.23,0.094
258.31,-29.16,0.094
258.33,-29.09,0.094
258.34,-29.03,0.094
258.35,-28.96,0.095
258.37,-28.89,0.095
258.38,-28.82,0.095
258.39,-28.76,0.095
258.40,-28.69,0.095
258.42,-28.62,0.095
258.43,-28.56,0.095
258.45,-28.49,0.095
258.46,-28.42,0.095
258.47,-28.36,0.095
258.48,-28.29,0.095
258.50,-28.22,0.095
258.51,-28.16,0.095
258.53,-28.09,0.095
258.54,-28.02,0.095
258.55,-27.96,0.095
258.57,-27.89,0.095
258.58,-27.82,0.095
258.59,-27.76,0.095
258.60,-27.69,0.095
258.62,-27.62,0.095
258.63,-27.56,0.095
258.65,-27.49,0.095
258.66,-27.42,0.095
258.67,-27.36,0.095
258.68,-27.29,0.095
258.70,-27.22,0.095
258.71,-27.16,0.095
258.73,-27.09,0.095
258.74,-27.02,0.095
258.75,-26.96,0.095
258.77,-26.89,0.095
258.78,-26.82,0.095
258.79,-26.76,0.095
258.80,-26.69,0.095
258.82,-26.62,0.095
258.83,-26.56,0.095
258.85,-26.49,0.095
258.86,-26.42,0.095
258.87,-26.36,0.095
258.88,-26.29,0.095
258.90,-26.22,0.095
258.91,-26.16,0.095
258.93,-26.09,0.095
258.94,-26.02,0.095
258.95,-25.96,0.095
258.97,-25.89,0.095
258.98,-25.82,0.095
258.99,-25.75,0.095
259.00,-25.69,0.095
259.02,-25.62,0.095
259.03,-25.56,0.095
259.05,-25.49,0.095
259.06,-25.42,0.095
259.07,-25.36,0.095
259.08,-25.29,0.095
259.10,-25.22,0.095
259.11,-25.15,0.095
259.13,-25.09,0.095
259.14,-25.02,0.095
259.15,-24.95,0.095
259.17,-24.89,0.095
259.18,-24.82,0.095
259.19,-24.75,0.095
259.20,-24.69,0.095
259.22,-24.62,0.095
259.23,-24.55,0.095
259.25,-24.49,0.095
259.26,-24.42,0.095
259.27,-24.36,0.095
259.28,-24.29,0.095
259.30,-24.22,0.095
259.31,-24.15,0.095
259.33,-24.09,0.095
259.34,-24.02,0.095
259.35,-23.95,0.095
259.37,-23.89,0.095
259.38,-23.82,0.095
259.39,-23.75,0.095
259.40,-23.69,0.095
259.42,-23.62,0.095
259.43,-23.55,0.095
259.45,-23.49,0.095
259.46,-23.42,0.095
259.47,-23.35,0.095
259.48,-23.29,0.095
259.50,-23.22,0.095
259.51,-23.15,0.095
259.53,-23.09,0.095
259.54,-23.02,0.095
259.55,-22.95,0.095
259.57,-22.89,0.095
259.58,-22.82,0.095
259.59,-22.75,0.095
259.60,-22.69,0.095
259.62,-22.62,0.095
259.63,-22.55,0.095
259.65,-22.49,0.095
259.66,-22.42,0.095
259.67,-22.35,0.095
259.68,-22.29,0.095
259.70,-22.22,0.095
259.71,-22.15,0.095
259.73,-22.08,0.095
259.74,-22.02,0.095
259.75,-21.95,0.095
259.77,-21.88,0.095
259.78,-21.82,0.095
259.79,-21.75,0.095
259.80,-21.68,0.095
259.82,-21.62,0.095
259.83,-21.55,0.095
259.85,-21.48,0.096
259.86,-21.42,0.095
259.87,-21.35,0.095
259.88,-21.29,0.096
259.90,-21.22,0.095
259.91,-21.15,0.096
259.93,-21.08,0.096
259.94,-21.02,0.096
259.95,-20.95,0.096
259.97,-20.88,0.096
259.98,-20.82,0.096
259.99,-20.75,0.096
260.00,-20.68,0.096
260.02,-20.62,0.096
260.03,-20.55,0.096
260.05,-20.48,0.096
260.06,-20.42,0.096
260.07,-20.35,0.096
260.08,-20.28,0.096
260.10,-20.22,0.096
260.11,-20.15,0.096
260.13,-20.08,0.096
260.14,-20.02,0.096
260.15,-19.95,0.096
260.17,-19.88,0.096
260.18,-19.82,0.096
260.19,-19.75,0.096
260.20,-19.68,0.096
260.22,-19.62,0.096
260.23,-19.55,0.096
260.25,-19.48,0.096
260.26,-19.42,0.096
260.27,-19.35,0.096
260.28,-19.28,0.096
260.30,-19.22,0.096
260.31,-19.15,0.096
260.33,-19.08,0.096
260.34,-19.02,0.096
260.35,-18.95,0.096
260.37,-18.88,0.096
260.38,-18.82,0.096
260.39,-18.75,0.096
260.40,-18.68,0.096
260.42,-18.61,0.096
260.43,-18.55,0.096
260.45,-18.48,0.096
260.46,-18.41,0.096
260.47,-18.35,0.096
260.48,-18.28,0.096
260.50,-18.22,0.096
260.51,-18.15,0.096
260.53,-18.08,0.096
260.54,-18.01,0.096
260.55,-17.95,0.096
260.57,-17.88,0.096
260.58,-17.81,0.096
260.59,-17.75,0.096
260.60,-17.68,0.096
260.62,-17.61,0.096
260.63,-17.55,0.096
260.65,-17.48,0.096
260.66,-17.41,0.096
260.67,-17.35,0.096
260.68,-17.28,0.096
260.70,-17.21,0.096
260.71,-17.15,0.096
260.73,-17.08,0.096
260.74,-17.02,0.096
260.75,-16.95,0.096
260.77,-16.88,0.096
260.78,-16.81,0.096
260.79,-16.75,0.096
260.80,-16.68,0.096
260.82,-16.61,0.096
260.83,-16.55,0.096
260.85,-16.48,0.097
260.86,-16.41,0.097
260.87,-16.35,0.097
260.88,-16.28,0.097
260.90,-16.22,0.097
260.91,-16.15,0.097
260.93,-16.08,0.097
260.94,-16.01,0.097
260.95,-15.95,0.097
260.97,-15.88,0.097
260.98,-15.81,0.097
260.99,-15.75,0.097
261.00,-15.68,0.097
261.02,-15.61,0.097
261.03,-15.55,0.097
261.05,-15.48,0.097
261.06,-15.41,0.097
261.07,-15.35,0.097
261.08,-15.28,0.097
261.10,-15.21,0.097
261.11,-15.15,0.097
261.13,-15.08,0.097
261.14,-15.01,0.097
261.15,-14.95,0.097
261.17,-14.88,0.097
261.18,-14.81,0.097
261.19,-14.75,0.097
261.20,-14.68,0.097
261.22,-14.61,0.097
261.23,-14.54,0.097
261.25,-14.48,0.097
261.26,-14.41,0.097
261.27,-14.35,0.097
261.28,-14.28,0.097
261.30,-14.21,0.097
261.31,-14.15,0.097
261.33,-14.08,0.097
261.34,-14.01,0.097
261.35,-13.94,0.097
261.37,-13.88,0.097
261.38,-13.81,0.097
261.39,-13.74,0.097
261.40,-13.68,0.097
261.42,-13.61,0.097
261.43,-13.54,0.097
261.45,-13.48,0.097
261.46,-13.41,0.097
261.47,-13.34,0.097
261.48,-13.28,0.097
261.50,-13.21,0.097
261.51,-13.14,0.097
261.53,-13.08,0.097
261.54,-13.01,0.097
261.55,-12.94,0.097
261.57,-12.88,0.097
261.58,-12.81,0.097
261.59,-12.74,0.097
261.60,-12.68,0.097
261.62,-12.61,0.097
261.63,-12.54,0.098
261.65,-12.48,0.097
261.66,-12.41,0.098
261.67,-12.34,0.098
261.68,-12.28,0.098
261.70,-12.21,0.098
261.71,-12.14,0.098
261.73,-12.08,0.098
261.74,-12.01,0.098
261.75,-11.94,0.098
261.77,-11.88,0.098
261.78,-11.81,0.098
261.79,-11.74,0.098
261.80,-11.68,0.098
261.82,-11.61,0.098
261.83,-11.54,0.098
261.85,-11.47,0.098
261.86,-11.41,0.098
261.87,-11.34,0.098
261.88,-11.28,0.098
261.90,-11.21,0.098
261.91,-11.14,0.098
261.93,-11.07,0.098
261.94,-11.01,0.098
261.95,-10.94,0.098
261.97,-10.87,0.098
261.98,-10.81,0.098
261.99,-10.74,0.098
262.00,-10.67,0.098
262.02,-10.61,0.098
262.03,-10.54,0.098
262.05,-10.47,0.098
262.06,-10.41,0.098
262.07,-10.34,0.098
262.08,-10.27,0.098
262.10,-10.20,0.098
262.11,-10.14,0.098
262.13,-10.07,0.098
262.14,-10.01,0.098
262.15,-9.94,0.098
262.17,-9.87,0.098
262.18,-9.81,0.098
262.19,-9.74,0.098
262.20,-9.67,0.098
262.22,-9.61,0.098
262.23,-9.54,0.098
262.25,-9.47,0.098
262.26,-9.40,0.098
262.27,-9.34,0.098
262.28,-9.27,0.098
262.30,-9.21,0.098
262.31,-9.14,0.098
262.33,-9.07,0.098
262.34,-9.01,0.098
262.35,-8.94,0.098
262.37,-8.87,0.098
262.38,-8.81,0.098
262.39,-8.74,0.098
262.40,-8.67,0.099
262.42,-8.61,0.099
262.43,-8.54,0.099
262.45,-8.47,0.099
262.46,-8.41,0.099
262.47,-8.34,0.099
262.48,-8.27,0.099
262.50,-8.21,0.099
262.51,-8.14,0.099
262.53,-8.07,0.099
262.54,-8.01,0.099
262.55,-7.94,0.099
262.57,-7.87,0.099
262.58,-7.81,0.099
262.59,-7.74,0.099
262.60,-7.67,0.099
262.62,-7.60,0.099
262.63,-7.54,0.099
262.65,-7.47,0.099
262.66,-7.40,0.099
262.67,-7.34,0.099
262.68,-7.27,0.099
262.70,-7.20,0.099
262.71,-7.14,0.099
262.73,-7.07,0.099
262.74,-7.00,0.099
262.75,-6.94,0.099
262.77,-6.87,0.099
262.78,-6.80,0.099
262.79,-6.74,0.099
262.80,-6.67,0.099
262.82,-6.60,0.099
262.83,-6.54,0.099
262.85,-6.47,0.099
262.86,-6.40,0.100
262.87,-6.34,0.100
262.88,-6.27,0.100
262.90,-6.20,0.100
262.91,-6.13,0.100
262.93,-6.07,0.100
262.94,-6.00,0.100
262.95,-5.93,0.100
262.97,-5.87,0.100
262.98,-5.80,0.100
262.99,-5.73,0.100
263.00,-5.67,0.100
263.02,-5.60,0.100
263.03,-5.53,0.100
263.05,-5.47,0.100
263.06,-5.40,0.100
263.07,-5.33,0.100
263.08,-5.27,0.100
263.10,-5.20,0.100
263.11,-5.13,0.100
263.13,-5.07,0.100
263.14,-5.00,0.100
263.15,-4.93,0.100
263.17,-4.87,0.100
263.18,-4.80,0.100
263.19,-4.73,0.100
263.20,-4.67,0.100
263.22,-4.60,0.100
263.23,-4.53,0.100
263.25,-4.47,0.100
263.26,-4.40,0.100
263.27,-4.33,0.100
263.28,-4.27,0.100
263.30,-4.20,0.100
263.31,-4.13,0.100
263.33,-4.07,0.100
263.34,-4.00,0.100
263.35,-3.93,0.100
263.37,-3.87,0.100
263.38,-3.80,0.100
263.39,-3.73,0.101
263.40,-3.67,0.100
263.42,-3.60,0.101
263.43,-3.53,0.101
263.45,-3.47,0.101
263.46,-3.40,0.101
263.47,-3.34,0.101
263.48,-3.27,0.101
263.50,-3.20,0.101
263.51,-3.14,0.101
263.53,-3.07,0.101
263.54,-3.00,0.101
263.55,-2.93,0.101
263.57,-2.87,0.101
263.58,-2.80,0.101
263.59,-2.73,0.101
263.60,-2.67,0.101
263.62,-2.60,0.101
263.63,-2.53,0.101
263.65,-2.47,0.101
263.66,-2.40,0.101
263.67,-2.33,0.101
263.68,-2.26,0.101
263.70,-2.20,0.102
263.71,-2.13,0.102
263.73,-2.06,0.102
263.74,-2.00,0.102
263.75,-1.93,0.102
263.77,-1.86,0.102
263.78,-1.80,0.102
263.79,-1.73,0.102
263.80,-1.66,0.102
263.82,-1.60,0.102
263.83,-1.53,0.102
263.85,-1.46,0.102
263.86,-1.40,0.102
263.87,-1.33,0.102
263.88,-1.26,0.102
263.90,-1.20,0.102
263.91,-1.13,0.102
263.93,-1.06,0.102
263.94,-1.00,0.102
263.95,-0.93,0.102
263.97,-0.86,0.102
263.98,-0.80,0.102
263.99,-0.73,0.102
264.00,-0.66,0.102
264.02,-0.60,0.102
264.03,-0.53,0.102
264.05,-0.46,0.102
264.06,-0.40,0.102
264.07,-0.33,0.102
264.08,-0.26,0.102
264.10,-0.20,0.102
264.11,-0.13,0.103
264.13,-0.06,0.103
264.14,0.00,0.103
264.15,0.07,0.103
264.17,0.14,0.103
264.18,0.20,0.103
264.19,0.27,0.103
264.20,0.34,0.103
264.22,0.40,0.103
264.23,0.47,0.103
264.25,0.54,0.103
264.26,0.60,0.103
264.27,0.67,0.103
264.28,0.74,0.103
264.30,0.80,0.103
264.31,0.87,0.103
264.33,0.94,0.103
264.34,1.00,0.103
264.35,1.07,0.103
264.37,1.14,0.103
264.38,1.21,0.103
264.39,1.27,0.103
264.40,1.34,0.103
264.42,1.40,0.103
264.43,1.47,0.104
264.45,1.54,0.104
264.46,1.60,0.104
264.47,1.67,0.104
264.48,1.74,0.104
264.50,1.80,0.104
264.51,1.87,0.104
264.53,1.94,0.104
264.54,2.01,0.104
264.55,2.07,0.104
264.57,2.14,0.104
264.58,2.21,0.104
264.59,2.27,0.104
264.60,2.34,0.104
264.62,2.40,0.104
264.63,2.47,0.104
264.65,2.54,0.104
264.66,2.60,0.104
264.67,2.67,0.104
264.68,2.74,0.104
264.70,2.81,0.104
264.71,2.87,0.105
264.73,2.94,0.105
264.74,3.01,0.105
264.75,3.07,0.105
264.77,3.14,0.105
264.78,3.21,0.105
264.79,3.27,0.105
264.80,3.34,0.105
264.82,3.41,0.105
264.83,3.47,0.105
264.85,3.54,0.105
264.86,3.61,0.105
264.87,3.67,0.105
264.88,3.74,0.105
264.90,3.81,0.105
264.91,3.87,0.106
264.93,3.94,0.106
264.94,4.01,0.106
264.95,4.07,0.106
264.97,4.14,0.106
264.98,4.21,0.106
264.99,4.27,0.106
265.00,4.34,0.106
265.02,4.41,0.106
265.03,4.47,0.106
265.05,4.54,0.106
265.06,4.61,0.106
265.07,4.67,0.106
265.08,4.74,0.106
265.10,4.81,0.106
265.11,4.87,0.106
265.13,4.94,0.107
265.14,5.01,0.107
265.15,5.07,0.107
265.17,5.14,0.107
265.18,5.21,0.107
265.19,5.27,0.107
265.20,5.34,0.107
265.22,5.41,0.107
265.23,5.47,0.107
265.25,5.54,0.107
265.26,5.61,0.107
265.27,5.67,0.107
265.28,5.74,0.107
265.30,5.81,0.108
265.31,5.87,0.108
265.33,5.94,0.108
265.34,6.01,0.108
265.35,6.07,0.108
265.37,6.14,0.108
265.38,6.21,0.108
265.39,6.27,0.108
265.40,6.34,0.108
265.42,6.41,0.108
265.43,6.47,0.108
265.45,6.54,0.109
265.46,6.61,0.109
265.47,6.67,0.109
265.48,6.74,0.109
265.50,6.81,0.109
265.51,6.87,0.109
265.53,6.94,0.109
265.54,7.01,0.109
265.55,7.07,0.109
265.57,7.14,0.109
265.58,7.21,0.109
265.59,7.28,0.110
265.60,7.34,0.110
265.62,7.41,0.110
265.63,7.47,0.110
265.65,7.54,0.110
265.66,7.61,0.110
265.67,7.67,0.110
265.68,7.74,0.110
265.70,7.81,0.110
265.71,7.87,0.110
265.73,7.94,0.110
265.74,8.01,0.111
265.75,8.07,0.111
265.77,8.14,0.111
265.78,8.21,0.111
265.79,8.28,0.111
265.80,8.34,0.111
265.82,8.41,0.111
265.83,8.47,0.111
265.85,8.54,0.111
265.86,8.61,0.111
265.87,8.67,0.112
265.88,8.74,0.112
265.90,8.81,0.112
265.91,8.87,0.112
265.93,8.94,0.112
265.94,9.01,0.112
265.95,9.07,0.112
265.97,9.14,0.112
265.98,9.21,0.112
265.99,9.27,0.112
266.00,9.34,0.112
266.02,9.41,0.113
266.03,9.48,0.113
266.05,9.54,0.113
266.06,9.61,0.113
266.07,9.67,0.113
266.08,9.74,0.113
266.10,9.81,0.113
266.11,9.88,0.113
266.13,9.94,0.113
266.14,10.01,0.113
266.15,10.08,0.114
266.17,10.14,0.114
266.18,10.21,0.114
266.19,10.28,0.114
266.20,10.34,0.114
266.22,10.41,0.114
266.23,10.47,0.114
266.25,10.54,0.114
266.26,10.61,0.114
266.27,10.68,0.114
266.28,10.74,0.115
266.30,10.81,0.115
266.31,10.88,0.115
266.33,10.94,0.115
266.34,11.01,0.115
266.35,11.08,0.115
266.37,11.14,0.115
266.38,11.21,0.115
266.39,11.28,0.115
266.40,11.34,0.116
266.42,11.41,0.116
266.43,11.48,0.116
266.45,11.54,0.116
266.46,11.61,0.116
266.47,11.68,0.116
266.48,11.74,0.116
266.50,11.81,0.116
266.51,11.88,0.116
266.53,11.94,0.116
266.54,12.01,0.117
266.55,12.08,0.117
266.57,12.14,0.117
266.58,12.21,0.117
266.59,12.28,0.117
266.60,12.34,0.117
266.62,12.41,0.117
266.63,12.48,0.118
266.65,12.54,0.118
266.66,12.61,0.118
266.67,12.68,0.118
266.68,12.74,0.118
266.70,12.81,0.118
266.71,12.88,0.118
266.73,12.94,0.118
266.74,13.01,0.119
266.75,13.08,0.119
266.77,13.14,0.119
266.78,13.21,0.119
266.79,13.28,0.119
266.80,13.34,0.119
266.82,13.41,0.119
266.83,13.48,0.119
266.85,13.54,0.119
266.86,13.61,0.120
266.87,13.68,0.120
266.88,13.74,0.120
266.90,13.81,0.120
266.91,13.88,0.120
266.93,13.95,0.120
266.94,14.01,0.120
266.95,14.08,0.120
266.97,14.14,0.120
266.98,14.21,0.121
266.99,14.28,0.121
267.00,14.34,0.121
267.02,14.41,0.121
267.03,14.48,0.121
267.05,14.54,0.121
267.06,14.61,0.121
267.07,14.68,0.121
267.08,14.74,0.122
267.10,14.81,0.122
267.11,14.88,0.122
267.13,14.94,0.122
267.14,15.01,0.122
267.15,15.08,0.122
267.17,15.14,0.122
267.18,15.21,0.122
267.19,15.28,0.123
267.20,15.34,0.123
267.22,15.41,0.123
267.23,15.48,0.123
267.25,15.54,0.123
267.26,15.61,0.123
267.27,15.68,0.123
267.28,15.74,0.123
267.30,15.81,0.124
267.31,15.88,0.124
267.33,15.95,0.124
267.34,16.01,0.124
267.35,16.08,0.124
267.37,16.15,0.124
267.38,16.21,0.124
267.39,16.28,0.124
267.40,16.34,0.125
267.42,16.41,0.125
267.43,16.48,0.125
267.45,16.54,0.125
267.46,16.61,0.125
267.47,16.68,0.125
267.48,16.74,0.125
267.50,16.81,0.125
267.51,16.88,0.126
267.53,16.94,0.126
267.54,17.01,0.126
267.55,17.08,0.126
267.57,17.15,0.126
267.58,17.21,0.126
267.59,17.28,0.126
267.60,17.34,0.126
267.62,17.41,0.126
267.63,17.48,0.127
267.65,17.54,0.127
267.66,17.61,0.127
267.67,17.68,0.127
267.68,17.74,0.127
267.70,17.81,0.127
267.71,17.88,0.127
267.73,17.94,0.127
267.74,18.01,0.127
267.75,18.08,0.128
267.77,18.14,0.128
267.78,18.21,0.128
267.79,18.28,0.128
267.80,18.34,0.128
267.82,18.41,0.128
267.83,18.48,0.128
267.85,18.55,0.128
267.86,18.61,0.128
267.87,18.68,0.129
267.88,18.75,0.129
267.90,18.81,0.129
267.91,18.88,0.129
267.93,18.95,0.129
267.94,19.01,0.129
267.95,19.08,0.129
267.97,19.14,0.129
267.98,19.21,0.129
267.99,19.28,0.129
268.00,19.35,0.130
268.02,19.41,0.130
268.03,19.48,0.130
268.05,19.55,0.130
268.06,19.61,0.130
268.07,19.68,0.130
268.08,19.75,0.130
268.10,19.81,0.130
268.11,19.88,0.130
268.13,19.95,0.131
268.14,20.01,0.131
268.15,20.08,0.131
268.17,20.15,0.131
268.18,20.21,0.131
268.19,20.28,0.131
268.20,20.35,0.131
268.22,20.41,0.131
268.23,20.48,0.131
268.25,20.55,0.131
268.26,20.61,0.131
268.27,20.68,0.131
268.28,20.75,0.132
268.30,20.81,0.132
268.31,20.88,0.132
268.33,20.95,0.132
268.34,21.01,0.132
268.35,21.08,0.132
268.37,21.15,0.132
268.38,21.21,0.132
268.39,21.28,0.132
268.40,21.35,0.132
268.42,21.41,0.132
268.43,21.48,0.132
268.45,21.55,0.132
268.46,21.61,0.133
268.47,21.68,0.133
268.48,21.75,0.133
268.50,21.81,0.133
268.51,21.88,0.133
268.53,21.95,0.133
268.54,22.01,0.133
268.55,22.08,0.133
268.57,22.15,0.133
268.58,22.21,0.133
268.59,22.28,0.133
268.60,22.35,0.133
268.62,22.41,0.133
268.63,22.48,0.133
268.65,22.55,0.133
268.66,22.61,0.133
268.67,22.68,0.133
268.68,22.75,0.134
268.70,22.81,0.134
268.71,22.88,0.134
268.73,22.95,0.134
268.74,23.01,0.134
268.75,23.08,0.134
268.77,23.15,0.134
268.78,23.21,0.134
268.79,23.28,0.134
268.80,23.35,0.134
268.82,23.41,0.134
268.83,23.48,0.134
268.85,23.55,0.134
268.86,23.61,0.134
268.87,23.68,0.134
268.88,23.75,0.134
268.90,23.81,0.134
268.91,23.88,0.135
268.93,23.95,0.135
268.94,24.01,0.135
268.95,24.08,0.135
268.97,24.15,0.135
268.98,24.21,0.135
268.99,24.28,0.135
269.00,24.35,0.135
269.02,24.41,0.135
269.03,24.48,0.135
269.05,24.55,0.135
269.06,24.62,0.135
269.07,24.68,0.135
269.08,24.75,0.135
269.10,24.81,0.135
269.11,24.88,0.135
269.13,24.95,0.136
269.14,25.01,0.136
269.15,25.08,0.136
269.17,25.15,0.136
269.18,25.21,0.136
269.19,25.28,0.136
269.20,25.35,0.136
269.22,25.42,0.136
269.23,25.48,0.136
269.25,25.55,0.136
269.26,25.61,0.136
269.27,25.68,0.136
269.28,25.75,0.136
269.30,25.81,0.136
269.31,25.88,0.136
269.33,25.95,0.136
269.34,26.02,0.137
269.35,26.08,0.137
269.37,26.15,0.137
269.38,26.21,0.137
269.39,26.28,0.137
269.40,26.35,0.137
269.42,26.42,0.137
269.43,26.48,0.137
269.45,26.55,0.137
269.46,26.62,0.137
269.47,26.68,0.137
269.48,26.75,0.137
269.50,26.82,0.137
269.51,26.88,0.137
269.53,26.95,0.137
269.54,27.02,0.137
269.55,27.08,0.137
269.57,27.15,0.137
269.58,27.22,0.137
269.59,27.28,0.137
269.60,27.35,0.138
269.62,27.42,0.137
269.63,27.48,0.137
269.65,27.55,0.138
269.66,27.62,0.138
269.67,27.68,0.138
269.68,27.75,0.138
269.70,27.82,0.138
269.71,27.88,0.138
269.73,27.95,0.138
269.74,28.02,0.138
269.75,28.08,0.138
269.77,28.15,0.138
269.78,28.22,0.138
269.79,28.29,0.138
269.80,28.35,0.138
269.82,28.42,0.138
269.83,28.48,0.138
269.85,28.55,0.138
269.86,28.62,0.138
269.87,28.69,0.138
269.88,28.75,0.139
269.90,28.82,0.139
269.91,28.88,0.139
269.93,28.95,0.139
269.94,29.02,
269.95,29.08,
269.97,29.15,
269.98,29.22,
269.99,,