File: DSC/Olivia/2025_08_01_1CBN_3PVP_MeOH_ASD_n60C_130C_10Cmin_x3.csv
Filename,2025_08_01_1CBN_3PVP_MeOH_ASD_n60C_130C_10Cmin_x3
Instrument name,DSC2A-00468 (192.168.1.100)
Operator,Yarger
rundate,8/1/2025
Sample name,2025_08_01_1CBN_3PVP_MeOH_ASD_n60C_130C_10Cmin_x3
proceduresegments,Data Off ; Equilibrate -60.00 °C; Data On ; Ramp 10.00 °C/min to 130.00 °C; Data Off ; Isothermal 2.0 min; Data On ; Ramp 10.00 °C/min to -60.00 °C; Data Off ; Isothermal 2.0 min; Data On ; Ramp 10.00 °C/min to 130.00 °C; Data Off ; Isothermal 2.0 min; Data On ; Ramp 10.00 °C/min to -60.00 °C; Data Off ; Isothermal 2.0 min; Data On ; Ramp 10.00 °C/min to 130.00 °C
[File Parameters]
Run date,8/1/2025 11:31:38 PM
Trios version,5.1.1.46572
Original File Name,
Current File Name,D:\DSC2500\Gibbons\2025_08_01_1CBN_3PVP_MeOH_ASD_n60C_130C_10Cmin_x3.tri
[Procedure]
Procedure Name,CBNPVP_n60C_130C_10Cmin_x3
Sample Name,2025_08_01_1CBN_3PVP_MeOH_ASD_n60C_130C_10Cmin_x3
Sample Mass,4.54 mg
Reference Sample Mass,0 mg
Pan Mass,32.72 mg
Pan Number,47
Reference Pan Mass,32.73 mg
Reference Pan Number,46
Pan Type,Aluminum
Comments,Thermal support Al pans/lids. DSC_Samples_A2_Tray_July2025 google sheet.
Project Name,Pharma - Cocrystals
Operator,Yarger
Test,Custom
Unload Max Temperature,30
Unload Min Temperature,30
Load Max Temperature,30
Load Min Temperature,30
Stop on Gas Flow Error,Yes
[Signal List]
Signal #1,Time (min)
Signal #2,Temperature (°C)
Signal #3,Heat Flow (mW)
Signal #4,Delta T (µV)
Signal #5,Delta Tzero (µV)
Signal #6,Tzero Temperature (°C)
Signal #7,Cell Purge (mL/min)
Signal #8,Heater Temp (°C)
Signal #9,Power Delivered (W)
Signal #10,Reference Junction Temperature (°C)
Signal #11,Flange Temperature (°C)
Signal #12,Heat Flow Phase (rad)
Signal #13,Total Heat Capacity (J/°C)
Signal #14,Heat Capacity (J/°C)
[Configuration]
Company Name,ASU
Instrument Name,DSC2A-00468
Instrument Type,DSC2500
Serial Number,DSC2A-00468
IP,192.168.1.100
Location of Instrument,MRRC
DisplayType,Unknown
Sample Interval ,0.1 s/pt
Selected Heat Flow,T4P
Exotherm Direction,Down
Cell Serial,DRC2-00792
Lid Type,Standard
Cooler,RCS 90
Leave Cooler on at End of Sequence,On
Gas 2,Nitrogen
Gas Selected,Channel 1
Flow Rate,50 mL/min
Secondary Purge,On
Licensed Heat Flow,Heat Flow T4P
Modulation Licensed,Yes
[Versions]
Common IDD Version,1
Cortex Version,VER 2.10.2.31
Driver,5.0.0.6
GDM Version,1.0.3.3
TouchscreenVersion,1.0.0.16145
FEP Version,1.2.1.21
FEP Bootloader,2.0.0.5
AutoSampler Version,2.1.1.26
Auto Sampler Bootloader,2.0.0.5
FCM Version,1.1.0.3
FCM Bootloader,2.0.0.5
[Experiment Logs]
Experiment Log Entry # 1,Data On set to 0
Experiment Log Entry # 3,Equilibrate Segment -60 (C) Started
Experiment Log Entry # 5,Data On set to 1
Experiment Log Entry # 7,Ramp Segment 10 C/min to 130 Started
Experiment Log Entry # 9,Data On set to 0
Experiment Log Entry # 11,Isothermal Segment 2 min started
Experiment Log Entry # 13,Data On set to 1
Experiment Log Entry # 15,Ramp Segment 10 C/min to -60 Started
Experiment Log Entry # 17,Data On set to 0
Experiment Log Entry # 19,Isothermal Segment 2 min started
Experiment Log Entry # 21,Data On set to 1
Experiment Log Entry # 23,Ramp Segment 10 C/min to 130 Started
Experiment Log Entry # 25,Data On set to 0
Experiment Log Entry # 27,Isothermal Segment 2 min started
Experiment Log Entry # 29,Data On set to 1
Experiment Log Entry # 31,Ramp Segment 10 C/min to -60 Started
Experiment Log Entry # 33,Data On set to 0
Experiment Log Entry # 35,Isothermal Segment 2 min started
Experiment Log Entry # 37,Data On set to 1
Experiment Log Entry # 39,Ramp Segment 10 C/min to 130 Started
[Method Log]
Method Log Entry # 1,Data Off
Method Log Entry # 2,Equilibrate -60 °C
Method Log Entry # 3,Data On
Method Log Entry # 4,(Ramp 85896) Ramp 10 °C/minute to 130 °C
Method Log Entry # 5,Data Off
Method Log Entry # 6,Isothermal 2 minutes
Method Log Entry # 7,Data On
Method Log Entry # 8,(Ramp 85900) Ramp 10 °C/minute to -60 °C
Method Log Entry # 9,Data Off
Method Log Entry # 10,Isothermal 2 minutes
Method Log Entry # 11,Data On
Method Log Entry # 12,(Ramp 85904) Ramp 10 °C/minute to 130 °C
Method Log Entry # 13,Data Off
Method Log Entry # 14,Isothermal 2 minutes
Method Log Entry # 15,Data On
Method Log Entry # 16,(Ramp 85908) Ramp 10 °C/minute to -60 °C
Method Log Entry # 17,Data Off
Method Log Entry # 18,Isothermal 2 minutes
Method Log Entry # 19,Data On
Method Log Entry # 20,(Ramp 85912) Ramp 10 °C/minute to 130 °C
Cell Serial,DRC2-00792
[T1 Calibration]
Slope,-0.008529666
Offset,9.636258
Initial Temperature,98.23
GUID,f8bfdadc-4977-4fdf-ba6d-0ba9134940c3
[TZero Calibration]
Date Applied,11/29/2022 4:06:13 PM
Description,From -89.059 °C to 396.009 °C at 20.000°C/min
Gas Type,Nitrogen
Pan Type,None
Source Files 1,C:\Users\yargerlab\Desktop\DSC Data\General\TZero_calibration_11_29_22_2nd(2).tri
Source Files 2,C:\Users\yargerlab\Desktop\DSC Data\General\TZero_calibration_11_29_22_2nd(3).tri
Delta T Offset,13.05235
Delta T Slope,-0.007271007
Delta T0 Offset,-13.69128
Delta T0 Slope,0.06063341
[Temperature Calibration]
Date Applied,11/29/2022 7:12:28 PM
Description,From 106.590 °C to 186.590 °C at 10.000°C/min
Gas Type,Nitrogen
Pan Type,Tzero Aluminum Hermetic
Source Files 1,C:\Users\yargerlab\Desktop\DSC Data\General\Indium(6).tri
Measured 1,157.391
Known 1,156.598
[Cell Constant Calibration]
Date Applied,11/29/2022 7:12:29 PM
Description,From 106.590 °C to 186.590 °C at 10.000°C/min
Gas Type,Nitrogen
Pan Type,Tzero Aluminum Hermetic
Source Files 1,C:\Users\yargerlab\Desktop\DSC Data\General\Indium(6).tri
T4P KCell,1.006051
Onset Slope,63.26126 mW/°C
[Direct Cp Calibration]
Date Applied,11/30/2022 11:04:51 AM
Description,From -79.983 °C to 298.409 °C at 10.000°C/min
Gas Type,Nitrogen
Pan Type,Tzero Aluminum Hermetic
Source Files 1,C:\Users\yargerlab\Desktop\DSC Data\General\Sapphire_Heat_Capacity_11_30_22.tri
[Rev Cp Calibration]
Date Applied,11/30/2022 1:58:51 PM
Description,From -79.996 °C to 292.812 °C at 3.000°C/min
Gas Type,Nitrogen
Pan Type,Tzero Aluminum Hermetic
Source Files 1,C:\Users\yargerlab\Desktop\DSC Data\General\Sapphire_MDSC_Calibration_11_30_22.tri
[step]
Ramp 10.00 °C/min to 130.00 °C
Time,Temperature,Heat Flow (Normalized)
min,°C,W/g
0.00,-59.81,-0.052
0.01,-59.81,-0.051
0.03,-59.81,-0.048
0.04,-59.81,-0.045
0.05,-59.80,-0.044
0.07,-59.79,-0.045
0.08,-59.76,-0.046
0.09,-59.71,-0.047
0.11,-59.66,-0.048
0.12,-59.59,-0.047
0.13,-59.51,-0.039
0.15,-59.41,-0.024
0.16,-59.32,-0.007
0.17,-59.21,0.009
0.19,-59.10,0.026
0.20,-58.99,0.043
0.21,-58.87,0.059
0.23,-58.75,0.073
0.24,-58.63,0.087
0.25,-58.51,0.099
0.27,-58.38,0.108
0.28,-58.26,0.118
0.29,-58.13,0.125
0.31,-58.00,0.131
0.32,-57.88,0.138
0.33,-57.75,0.141
0.35,-57.62,0.146
0.36,-57.49,0.148
0.37,-57.36,0.152
0.39,-57.24,0.154
0.40,-57.11,0.156
0.41,-56.98,0.158
0.43,-56.85,0.159
0.44,-56.72,0.161
0.45,-56.59,0.162
0.47,-56.46,0.163
0.48,-56.33,0.163
0.49,-56.20,0.165
0.51,-56.07,0.165
0.52,-55.94,0.166
0.53,-55.81,0.166
0.55,-55.68,0.167
0.56,-55.54,0.168
0.57,-55.41,0.168
0.59,-55.28,0.169
0.60,-55.15,0.169
0.61,-55.02,0.170
0.63,-54.89,0.170
0.64,-54.76,0.170
0.65,-54.62,0.170
0.67,-54.49,0.171
0.68,-54.36,0.171
0.69,-54.23,0.171
0.71,-54.10,0.172
0.72,-53.97,0.172
0.73,-53.83,0.172
0.75,-53.70,0.172
0.76,-53.57,0.173
0.77,-53.44,0.173
0.79,-53.31,0.173
0.80,-53.18,0.174
0.81,-53.04,0.174
0.83,-52.91,0.174
0.84,-52.78,0.175
0.85,-52.65,0.175
0.87,-52.51,0.175
0.88,-52.38,0.175
0.89,-52.25,0.176
0.91,-52.12,0.176
0.92,-51.99,0.176
0.93,-51.85,0.177
0.95,-51.72,0.177
0.96,-51.59,0.177
0.97,-51.45,0.177
0.99,-51.32,0.178
1.00,-51.19,0.178
1.01,-51.06,0.178
1.03,-50.92,0.178
1.04,-50.79,0.179
1.05,-50.66,0.179
1.07,-50.53,0.179
1.08,-50.39,0.179
1.09,-50.26,0.179
1.11,-50.13,0.180
1.12,-50.00,0.180
1.13,-49.86,0.180
1.15,-49.73,0.180
1.16,-49.60,0.180
1.17,-49.46,0.181
1.19,-49.33,0.181
1.20,-49.20,0.181
1.21,-49.07,0.181
1.23,-48.93,0.181
1.24,-48.80,0.181
1.25,-48.67,0.182
1.27,-48.53,0.182
1.28,-48.40,0.182
1.29,-48.27,0.182
1.31,-48.14,0.182
1.32,-48.00,0.182
1.33,-47.87,0.183
1.35,-47.74,0.183
1.36,-47.60,0.183
1.37,-47.47,0.183
1.39,-47.34,0.183
1.40,-47.21,0.183
1.41,-47.07,0.183
1.43,-46.94,0.183
1.44,-46.80,0.183
1.45,-46.67,0.184
1.47,-46.54,0.184
1.48,-46.41,0.184
1.49,-46.27,0.184
1.51,-46.14,0.184
1.52,-46.00,0.184
1.53,-45.87,0.184
1.55,-45.74,0.184
1.56,-45.60,0.184
1.57,-45.47,0.185
1.59,-45.34,0.185
1.60,-45.20,0.185
1.61,-45.07,0.185
1.63,-44.94,0.185
1.64,-44.80,0.185
1.65,-44.67,0.185
1.67,-44.54,0.185
1.68,-44.41,0.185
1.69,-44.27,0.185
1.71,-44.14,0.185
1.72,-44.00,0.186
1.73,-43.87,0.186
1.75,-43.74,0.186
1.76,-43.60,0.186
1.77,-43.47,0.186
1.79,-43.34,0.186
1.80,-43.20,0.186
1.81,-43.07,0.186
1.83,-42.93,0.186
1.84,-42.80,0.186
1.85,-42.67,0.186
1.87,-42.53,0.187
1.88,-42.40,0.187
1.89,-42.27,0.187
1.91,-42.13,0.187
1.92,-42.00,0.187
1.93,-41.87,0.187
1.95,-41.73,0.187
1.96,-41.60,0.187
1.97,-41.46,0.187
1.99,-41.33,0.187
2.00,-41.20,0.187
2.01,-41.07,0.187
2.03,-40.93,0.187
2.04,-40.80,0.188
2.05,-40.66,0.188
2.07,-40.53,0.188
2.08,-40.40,0.188
2.09,-40.26,0.188
2.11,-40.13,0.188
2.12,-40.00,0.188
2.13,-39.86,0.188
2.15,-39.73,0.188
2.16,-39.60,0.188
2.17,-39.46,0.188
2.19,-39.33,0.188
2.20,-39.20,0.188
2.21,-39.06,0.188
2.23,-38.93,0.188
2.24,-38.80,0.188
2.25,-38.66,0.188
2.27,-38.53,0.188
2.28,-38.40,0.188
2.29,-38.26,0.188
2.31,-38.13,0.188
2.32,-38.00,0.189
2.33,-37.86,0.189
2.35,-37.73,0.189
2.36,-37.59,0.189
2.37,-37.46,0.189
2.39,-37.33,0.189
2.40,-37.19,0.189
2.41,-37.06,0.189
2.43,-36.93,0.189
2.44,-36.79,0.189
2.45,-36.66,0.189
2.47,-36.53,0.189
2.48,-36.39,0.189
2.49,-36.26,0.189
2.51,-36.13,0.189
2.52,-35.99,0.189
2.53,-35.86,0.189
2.55,-35.73,0.189
2.56,-35.59,0.189
2.57,-35.46,0.189
2.59,-35.33,0.189
2.60,-35.19,0.189
2.61,-35.06,0.189
2.63,-34.92,0.189
2.64,-34.79,0.189
2.65,-34.66,0.190
2.67,-34.53,0.190
2.68,-34.39,0.190
2.69,-34.26,0.190
2.71,-34.13,0.190
2.72,-33.99,0.190
2.73,-33.86,0.190
2.75,-33.73,0.190
2.76,-33.59,0.190
2.77,-33.46,0.190
2.79,-33.33,0.190
2.80,-33.19,0.190
2.81,-33.06,0.190
2.83,-32.93,0.190
2.84,-32.79,0.190
2.85,-32.66,0.190
2.87,-32.52,0.190
2.88,-32.39,0.190
2.89,-32.26,0.190
2.91,-32.12,0.190
2.92,-31.99,0.190
2.93,-31.86,0.191
2.95,-31.72,0.191
2.96,-31.59,0.191
2.97,-31.45,0.191
2.99,-31.32,0.191
3.00,-31.19,0.191
3.01,-31.05,0.191
3.03,-30.92,0.191
3.04,-30.79,0.191
3.05,-30.65,0.191
3.07,-30.52,0.191
3.08,-30.39,0.191
3.09,-30.25,0.191
3.11,-30.12,0.191
3.12,-29.99,0.192
3.13,-29.85,0.192
3.15,-29.72,0.192
3.16,-29.59,0.192
3.17,-29.45,0.192
3.19,-29.32,0.192
3.20,-29.18,0.192
3.21,-29.05,0.192
3.23,-28.92,0.192
3.24,-28.78,0.192
3.25,-28.65,0.192
3.27,-28.52,0.192
3.28,-28.38,0.192
3.29,-28.25,0.192
3.31,-28.12,0.192
3.32,-27.98,0.193
3.33,-27.85,0.193
3.35,-27.72,0.193
3.36,-27.58,0.193
3.37,-27.45,0.193
3.39,-27.32,0.193
3.40,-27.18,0.193
3.41,-27.05,0.193
3.43,-26.91,0.193
3.44,-26.78,0.193
3.45,-26.65,0.193
3.47,-26.51,0.193
3.48,-26.38,0.193
3.49,-26.25,0.193
3.51,-26.11,0.193
3.52,-25.98,0.193
3.53,-25.85,0.194
3.55,-25.71,0.194
3.56,-25.58,0.194
3.57,-25.45,0.194
3.59,-25.31,0.194
3.60,-25.18,0.194
3.61,-25.05,0.194
3.63,-24.91,0.194
3.64,-24.78,0.194
3.65,-24.65,0.194
3.67,-24.51,0.194
3.68,-24.38,0.194
3.69,-24.24,0.194
3.71,-24.11,0.194
3.72,-23.98,0.194
3.73,-23.84,0.195
3.75,-23.71,0.195
3.76,-23.58,0.195
3.77,-23.44,0.195
3.79,-23.31,0.195
3.80,-23.18,0.195
3.81,-23.04,0.195
3.83,-22.91,0.195
3.84,-22.78,0.195
3.85,-22.64,0.195
3.87,-22.51,0.195
3.88,-22.38,0.195
3.89,-22.24,0.195
3.91,-22.11,0.195
3.92,-21.98,0.195
3.93,-21.84,0.195
3.95,-21.71,0.196
3.96,-21.57,0.196
3.97,-21.44,0.196
3.99,-21.31,0.196
4.00,-21.18,0.196
4.01,-21.04,0.196
4.03,-20.91,0.196
4.04,-20.77,0.196
4.05,-20.64,0.196
4.07,-20.51,0.196
4.08,-20.37,0.196
4.09,-20.24,0.196
4.11,-20.11,0.196
4.12,-19.97,0.196
4.13,-19.84,0.197
4.15,-19.71,0.197
4.16,-19.57,0.197
4.17,-19.44,0.197
4.19,-19.31,0.197
4.20,-19.17,0.197
4.21,-19.04,0.197
4.23,-18.91,0.197
4.24,-18.77,0.197
4.25,-18.64,0.197
4.27,-18.51,0.197
4.28,-18.37,0.197
4.29,-18.24,0.197
4.31,-18.10,0.197
4.32,-17.97,0.198
4.33,-17.84,0.198
4.35,-17.70,0.198
4.36,-17.57,0.198
4.37,-17.44,0.198
4.39,-17.30,0.198
4.40,-17.17,0.198
4.41,-17.04,0.198
4.43,-16.90,0.198
4.44,-16.77,0.198
4.45,-16.64,0.198
4.47,-16.50,0.198
4.48,-16.37,0.198
4.49,-16.24,0.199
4.51,-16.10,0.199
4.52,-15.97,0.199
4.53,-15.84,0.199
4.55,-15.70,0.199
4.56,-15.57,0.199
4.57,-15.44,0.199
4.59,-15.30,0.199
4.60,-15.17,0.199
4.61,-15.04,0.199
4.63,-14.90,0.199
4.64,-14.77,0.199
4.65,-14.63,0.199
4.67,-14.50,0.199
4.68,-14.37,0.200
4.69,-14.23,0.200
4.71,-14.10,0.200
4.72,-13.97,0.200
4.73,-13.83,0.200
4.75,-13.70,0.200
4.76,-13.57,0.200
4.77,-13.43,0.200
4.79,-13.30,0.200
4.80,-13.17,0.200
4.81,-13.03,0.200
4.83,-12.90,0.200
4.84,-12.77,0.201
4.85,-12.63,0.201
4.87,-12.50,0.201
4.88,-12.37,0.201
4.89,-12.23,0.201
4.91,-12.10,0.201
4.92,-11.97,0.201
4.93,-11.83,0.201
4.95,-11.70,0.201
4.96,-11.56,0.201
4.97,-11.43,0.201
4.99,-11.30,0.201
5.00,-11.16,0.202
5.01,-11.03,0.202
5.03,-10.90,0.202
5.04,-10.76,0.202
5.05,-10.63,0.202
5.07,-10.50,0.202
5.08,-10.36,0.202
5.09,-10.23,0.202
5.11,-10.10,0.202
5.12,-9.96,0.202
5.13,-9.83,0.202
5.15,-9.70,0.203
5.16,-9.56,0.203
5.17,-9.43,0.203
5.19,-9.30,0.203
5.20,-9.16,0.203
5.21,-9.03,0.203
5.23,-8.90,0.203
5.24,-8.76,0.203
5.25,-8.63,0.203
5.27,-8.50,0.203
5.28,-8.36,0.203
5.29,-8.23,0.204
5.31,-8.10,0.204
5.32,-7.96,0.204
5.33,-7.83,0.204
5.35,-7.69,0.204
5.36,-7.56,0.204
5.37,-7.43,0.204
5.39,-7.29,0.204
5.40,-7.16,0.204
5.41,-7.03,0.204
5.43,-6.89,0.205
5.44,-6.76,0.205
5.45,-6.63,0.205
5.47,-6.49,0.205
5.48,-6.36,0.205
5.49,-6.23,0.205
5.51,-6.09,0.205
5.52,-5.96,0.205
5.53,-5.83,0.205
5.55,-5.69,0.206
5.56,-5.56,0.206
5.57,-5.42,0.206
5.59,-5.29,0.206
5.60,-5.16,0.206
5.61,-5.03,0.206
5.63,-4.89,0.206
5.64,-4.76,0.206
5.65,-4.63,0.206
5.67,-4.49,0.206
5.68,-4.36,0.207
5.69,-4.23,0.207
5.71,-4.09,0.207
5.72,-3.96,0.207
5.73,-3.83,0.207
5.75,-3.69,0.207
5.76,-3.56,0.207
5.77,-3.42,0.207
5.79,-3.29,0.207
5.80,-3.16,0.208
5.81,-3.02,0.208
5.83,-2.89,0.208
5.84,-2.76,0.208
5.85,-2.62,0.208
5.87,-2.49,0.208
5.88,-2.36,0.208
5.89,-2.22,0.208
5.91,-2.09,0.208
5.92,-1.96,0.209
5.93,-1.82,0.209
5.95,-1.69,0.209
5.96,-1.55,0.209
5.97,-1.42,0.209
5.99,-1.29,0.209
6.00,-1.15,0.209
6.01,-1.02,0.209
6.03,-0.89,0.209
6.04,-0.75,0.210
6.05,-0.62,0.210
6.07,-0.49,0.210
6.08,-0.35,0.210
6.09,-0.22,0.210
6.11,-0.09,0.210
6.12,0.05,0.210
6.13,0.18,0.210
6.15,0.31,0.210
6.16,0.45,0.211
6.17,0.58,0.211
6.19,0.72,0.211
6.20,0.85,0.211
6.21,0.98,0.211
6.23,1.12,0.211
6.24,1.25,0.211
6.25,1.38,0.211
6.27,1.52,0.212
6.28,1.65,0.212
6.29,1.78,0.212
6.31,1.92,0.212
6.32,2.05,0.212
6.33,2.18,0.212
6.35,2.32,0.212
6.36,2.45,0.212
6.37,2.58,0.213
6.39,2.72,0.213
6.40,2.85,0.213
6.41,2.98,0.213
6.43,3.12,0.213
6.44,3.25,0.213
6.45,3.38,0.213
6.47,3.52,0.213
6.48,3.65,0.214
6.49,3.78,0.214
6.51,3.92,0.214
6.52,4.05,0.214
6.53,4.18,0.214
6.55,4.32,0.214
6.56,4.45,0.214
6.57,4.59,0.215
6.59,4.72,0.215
6.60,4.85,0.215
6.61,4.99,0.215
6.63,5.12,0.215
6.64,5.25,0.215
6.65,5.39,0.215
6.67,5.52,0.216
6.68,5.65,0.216
6.69,5.79,0.216
6.71,5.92,0.216
6.72,6.05,0.216
6.73,6.19,0.216
6.75,6.32,0.216
6.76,6.45,0.217
6.77,6.59,0.217
6.79,6.72,0.217
6.80,6.85,0.217
6.81,6.99,0.217
6.83,7.12,0.217
6.84,7.25,0.217
6.85,7.39,0.218
6.87,7.52,0.218
6.88,7.66,0.218
6.89,7.79,0.218
6.91,7.92,0.218
6.92,8.06,0.218
6.93,8.19,0.219
6.95,8.32,0.219
6.96,8.46,0.219
6.97,8.59,0.219
6.99,8.72,0.219
7.00,8.86,0.219
7.01,8.99,0.219
7.03,9.12,0.220
7.04,9.26,0.220
7.05,9.39,0.220
7.07,9.52,0.220
7.08,9.66,0.220
7.09,9.79,0.220
7.11,9.92,0.220
7.12,10.06,0.221
7.13,10.19,0.221
7.15,10.32,0.221
7.16,10.46,0.221
7.17,10.59,0.221
7.19,10.72,0.221
7.20,10.86,0.222
7.21,10.99,0.222
7.23,11.12,0.222
7.24,11.26,0.222
7.25,11.39,0.222
7.27,11.52,0.223
7.28,11.66,0.223
7.29,11.79,0.223
7.31,11.92,0.223
7.32,12.06,0.223
7.33,12.19,0.223
7.35,12.33,0.224
7.36,12.46,0.224
7.37,12.59,0.224
7.39,12.73,0.224
7.40,12.86,0.224
7.41,12.99,0.225
7.43,13.13,0.225
7.44,13.26,0.225
7.45,13.39,0.225
7.47,13.53,0.225
7.48,13.66,0.226
7.49,13.79,0.226
7.51,13.93,0.226
7.52,14.06,0.226
7.53,14.19,0.226
7.55,14.33,0.226
7.56,14.46,0.227
7.57,14.59,0.227
7.59,14.73,0.227
7.60,14.86,0.227
7.61,14.99,0.227
7.63,15.13,0.228
7.64,15.26,0.228
7.65,15.39,0.228
7.67,15.53,0.228
7.68,15.66,0.228
7.69,15.79,0.229
7.71,15.93,0.229
7.72,16.06,0.229
7.73,16.19,0.229
7.75,16.33,0.229
7.76,16.46,0.230
7.77,16.59,0.230
7.79,16.73,0.230
7.80,16.86,0.230
7.81,16.99,0.231
7.83,17.13,0.231
7.84,17.26,0.231
7.85,17.39,0.231
7.87,17.53,0.231
7.88,17.66,0.232
7.89,17.79,0.232
7.91,17.93,0.232
7.92,18.06,0.232
7.93,18.19,0.233
7.95,18.33,0.233
7.96,18.46,0.233
7.97,18.59,0.233
7.99,18.72,0.233
8.00,18.86,0.234
8.01,18.99,0.234
8.03,19.12,0.234
8.04,19.26,0.234
8.05,19.39,0.235
8.07,19.52,0.235
8.08,19.66,0.235
8.09,19.79,0.235
8.11,19.92,0.235
8.12,20.06,0.236
8.13,20.19,0.236
8.15,20.32,0.236
8.16,20.46,0.237
8.17,20.59,0.237
8.19,20.72,0.237
8.20,20.86,0.237
8.21,20.99,0.238
8.23,21.12,0.238
8.24,21.26,0.238
8.25,21.39,0.239
8.27,21.53,0.239
8.28,21.66,0.239
8.29,21.79,0.239
8.31,21.93,0.240
8.32,22.06,0.240
8.33,22.19,0.240
8.35,22.33,0.241
8.36,22.46,0.241
8.37,22.59,0.241
8.39,22.73,0.241
8.40,22.86,0.242
8.41,22.99,0.242
8.43,23.13,0.242
8.44,23.26,0.243
8.45,23.40,0.243
8.47,23.53,0.243
8.48,23.66,0.244
8.49,23.80,0.244
8.51,23.93,0.244
8.52,24.06,0.245
8.53,24.20,0.245
8.55,24.33,0.245
8.56,24.46,0.245
8.57,24.59,0.246
8.59,24.73,0.246
8.60,24.86,0.246
8.61,25.00,0.247
8.63,25.13,0.247
8.64,25.26,0.247
8.65,25.40,0.248
8.67,25.53,0.248
8.68,25.66,0.248
8.69,25.80,0.249
8.71,25.93,0.249
8.72,26.06,0.249
8.73,26.20,0.250
8.75,26.33,0.250
8.76,26.46,0.250
8.77,26.60,0.251
8.79,26.73,0.251
8.80,26.86,0.251
8.81,27.00,0.252
8.83,27.13,0.252
8.84,27.27,0.252
8.85,27.40,0.253
8.87,27.53,0.253
8.88,27.67,0.253
8.89,27.80,0.254
8.91,27.93,0.254
8.92,28.06,0.254
8.93,28.20,0.255
8.95,28.33,0.255
8.96,28.46,0.255
8.97,28.60,0.256
8.99,28.73,0.256
9.00,28.87,0.256
9.01,29.00,0.257
9.03,29.13,0.257
9.04,29.26,0.258
9.05,29.40,0.258
9.07,29.53,0.258
9.08,29.67,0.259
9.09,29.80,0.259
9.11,29.93,0.260
9.12,30.07,0.260
9.13,30.20,0.260
9.15,30.33,0.261
9.16,30.47,0.261
9.17,30.60,0.262
9.19,30.73,0.262
9.20,30.87,0.262
9.21,31.00,0.263
9.23,31.13,0.263
9.24,31.26,0.264
9.25,31.40,0.264
9.27,31.53,0.264
9.28,31.67,0.265
9.29,31.80,0.265
9.31,31.93,0.266
9.32,32.07,0.266
9.33,32.20,0.267
9.35,32.33,0.267
9.36,32.47,0.268
9.37,32.60,0.268
9.39,32.73,0.269
9.40,32.87,0.269
9.41,33.00,0.270
9.43,33.13,0.270
9.44,33.27,0.271
9.45,33.40,0.271
9.47,33.53,0.271
9.48,33.67,0.272
9.49,33.80,0.272
9.51,33.93,0.273
9.52,34.07,0.274
9.53,34.20,0.274
9.55,34.33,0.275
9.56,34.47,0.276
9.57,34.60,0.276
9.59,34.73,0.277
9.60,34.86,0.277
9.61,35.00,0.277
9.63,35.13,0.278
9.64,35.27,0.278
9.65,35.40,0.279
9.67,35.53,0.280
9.68,35.67,0.280
9.69,35.80,0.281
9.71,35.93,0.282
9.72,36.06,0.283
9.73,36.20,0.283
9.75,36.33,0.284
9.76,36.46,0.285
9.77,36.60,0.286
9.79,36.73,0.286
9.80,36.86,0.287
9.81,37.00,0.288
9.83,37.13,0.288
9.84,37.26,0.289
9.85,37.40,0.290
9.87,37.53,0.291
9.88,37.67,0.291
9.89,37.80,0.292
9.91,37.93,0.293
9.92,38.06,0.294
9.93,38.20,0.295
9.95,38.33,0.296
9.96,38.46,0.297
9.97,38.60,0.298
9.99,38.73,0.299
10.00,38.86,0.299
10.01,39.00,0.300
10.03,39.13,0.301
10.04,39.26,0.302
10.05,39.39,0.304
10.07,39.53,0.304
10.08,39.66,0.306
10.09,39.80,0.307
10.11,39.93,0.308
10.12,40.06,0.309
10.13,40.20,0.310
10.15,40.33,0.312
10.16,40.46,0.313
10.17,40.60,0.314
10.19,40.73,0.315
10.20,40.86,0.317
10.21,40.99,0.318
10.23,41.13,0.319
10.24,41.26,0.320
10.25,41.39,0.322
10.27,41.53,0.323
10.28,41.66,0.324
10.29,41.79,0.325
10.31,41.93,0.327
10.32,42.06,0.328
10.33,42.19,0.329
10.35,42.33,0.330
10.36,42.46,0.332
10.37,42.59,0.333
10.39,42.72,0.334
10.40,42.86,0.335
10.41,42.99,0.337
10.43,43.13,0.338
10.44,43.26,0.340
10.45,43.39,0.341
10.47,43.52,0.343
10.48,43.66,0.344
10.49,43.79,0.345
10.51,43.92,0.347
10.52,44.06,0.348
10.53,44.19,0.349
10.55,44.32,0.351
10.56,44.46,0.353
10.57,44.59,0.354
10.59,44.72,0.355
10.60,44.85,0.356
10.61,44.99,0.358
10.63,45.12,0.359
10.64,45.25,0.360
10.65,45.39,0.362
10.67,45.52,0.364
10.68,45.65,0.366
10.69,45.79,0.367
10.71,45.92,0.368
10.72,46.05,0.369
10.73,46.19,0.370
10.75,46.32,0.372
10.76,46.45,0.373
10.77,46.59,0.375
10.79,46.72,0.377
10.80,46.85,0.377
10.81,46.98,0.379
10.83,47.12,0.380
10.84,47.25,0.381
10.85,47.38,0.382
10.87,47.52,0.384
10.88,47.65,0.385
10.89,47.78,0.386
10.91,47.92,0.388
10.92,48.05,0.389
10.93,48.18,0.390
10.95,48.31,0.392
10.96,48.45,0.393
10.97,48.58,0.394
10.99,48.71,0.395
11.00,48.85,0.396
11.01,48.98,0.397
11.03,49.11,0.399
11.04,49.25,0.399
11.05,49.38,0.401
11.07,49.51,0.403
11.08,49.65,0.404
11.09,49.78,0.405
11.11,49.91,0.406
11.12,50.05,0.407
11.13,50.18,0.408
11.15,50.31,0.409
11.16,50.45,0.410
11.17,50.58,0.411
11.19,50.71,0.412
11.20,50.85,0.413
11.21,50.98,0.414
11.23,51.11,0.416
11.24,51.24,0.417
11.25,51.38,0.418
11.27,51.51,0.419
11.28,51.64,0.421
11.29,51.78,0.422
11.31,51.91,0.423
11.32,52.04,0.423
11.33,52.18,0.424
11.35,52.31,0.425
11.36,52.44,0.426
11.37,52.58,0.427
11.39,52.71,0.429
11.40,52.84,0.429
11.41,52.98,0.430
11.43,53.11,0.431
11.44,53.24,0.432
11.45,53.37,0.433
11.47,53.51,0.434
11.48,53.64,0.435
11.49,53.77,0.437
11.51,53.91,0.438
11.52,54.04,0.438
11.53,54.17,0.440
11.55,54.31,0.440
11.56,54.44,0.441
11.57,54.57,0.442
11.59,54.71,0.443
11.60,54.84,0.443
11.61,54.97,0.444
11.63,55.10,0.445
11.64,55.24,0.446
11.65,55.37,0.447
11.67,55.50,0.447
11.68,55.64,0.448
11.69,55.77,0.449
11.71,55.90,0.449
11.72,56.04,0.450
11.73,56.17,0.451
11.75,56.30,0.452
11.76,56.44,0.452
11.77,56.57,0.453
11.79,56.70,0.453
11.80,56.84,0.454
11.81,56.97,0.456
11.83,57.10,0.456
11.84,57.24,0.457
11.85,57.37,0.458
11.87,57.50,0.459
11.88,57.64,0.459
11.89,57.77,0.460
11.91,57.90,0.461
11.92,58.04,0.461
11.93,58.17,0.462
11.95,58.30,0.463
11.96,58.44,0.463
11.97,58.57,0.464
11.99,58.70,0.465
12.00,58.84,0.466
12.01,58.97,0.466
12.03,59.10,0.467
12.04,59.24,0.468
12.05,59.37,0.469
12.07,59.50,0.469
12.08,59.64,0.470
12.09,59.77,0.470
12.11,59.90,0.472
12.12,60.04,0.473
12.13,60.17,0.473
12.15,60.30,0.474
12.16,60.44,0.475
12.17,60.57,0.476
12.19,60.70,0.477
12.20,60.84,0.478
12.21,60.97,0.478
12.23,61.10,0.479
12.24,61.24,0.480
12.25,61.37,0.481
12.27,61.50,0.481
12.28,61.64,0.483
12.29,61.77,0.483
12.31,61.91,0.484
12.32,62.04,0.485
12.33,62.17,0.486
12.35,62.30,0.486
12.36,62.44,0.488
12.37,62.57,0.488
12.39,62.70,0.490
12.40,62.84,0.490
12.41,62.97,0.491
12.43,63.10,0.492
12.44,63.24,0.493
12.45,63.37,0.494
12.47,63.50,0.495
12.48,63.64,0.496
12.49,63.77,0.497
12.51,63.90,0.498
12.52,64.04,0.498
12.53,64.17,0.500
12.55,64.30,0.501
12.56,64.44,0.502
12.57,64.57,0.502
12.59,64.70,0.503
12.60,64.83,0.504
12.61,64.97,0.505
12.63,65.10,0.506
12.64,65.24,0.507
12.65,65.37,0.508
12.67,65.50,0.509
12.68,65.64,0.510
12.69,65.77,0.511
12.71,65.90,0.512
12.72,66.03,0.513
12.73,66.17,0.514
12.75,66.30,0.515
12.76,66.43,0.516
12.77,66.57,0.516
12.79,66.70,0.517
12.80,66.83,0.518
12.81,66.97,0.519
12.83,67.10,0.520
12.84,67.23,0.521
12.85,67.37,0.521
12.87,67.50,0.522
12.88,67.63,0.523
12.89,67.77,0.524
12.91,67.90,0.525
12.92,68.03,0.525
12.93,68.17,0.526
12.95,68.30,0.527
12.96,68.43,0.528
12.97,68.56,0.529
12.99,68.70,0.529
13.00,68.83,0.530
13.01,68.96,0.531
13.03,69.10,0.532
13.04,69.23,0.533
13.05,69.36,0.534
13.07,69.50,0.535
13.08,69.63,0.537
13.09,69.76,0.537
13.11,69.90,0.538
13.12,70.03,0.539
13.13,70.16,0.539
13.15,70.30,0.540
13.16,70.43,0.540
13.17,70.56,0.541
13.19,70.70,0.542
13.20,70.83,0.543
13.21,70.96,0.544
13.23,71.09,0.545
13.24,71.23,0.546
13.25,71.36,0.547
13.27,71.50,0.548
13.28,71.63,0.549
13.29,71.76,0.549
13.31,71.89,0.551
13.32,72.03,0.552
13.33,72.16,0.553
13.35,72.29,0.554
13.36,72.43,0.555
13.37,72.56,0.555
13.39,72.69,0.557
13.40,72.83,0.558
13.41,72.96,0.559
13.43,73.09,0.560
13.44,73.23,0.561
13.45,73.36,0.561
13.47,73.49,0.563
13.48,73.63,0.564
13.49,73.76,0.565
13.51,73.89,0.566
13.52,74.02,0.568
13.53,74.16,0.569
13.55,74.29,0.570
13.56,74.43,0.571
13.57,74.56,0.573
13.59,74.69,0.573
13.60,74.82,0.574
13.61,74.96,0.576
13.63,75.09,0.577
13.64,75.22,0.578
13.65,75.36,0.579
13.67,75.49,0.580
13.68,75.62,0.581
13.69,75.76,0.583
13.71,75.89,0.583
13.72,76.02,0.585
13.73,76.16,0.586
13.75,76.29,0.586
13.76,76.42,0.587
13.77,76.56,0.589
13.79,76.69,0.591
13.80,76.82,0.592
13.81,76.96,0.592
13.83,77.09,0.594
13.84,77.22,0.594
13.85,77.36,0.596
13.87,77.50,0.598
13.88,77.63,0.601
13.89,77.76,0.603
13.91,77.90,0.606
13.92,78.03,0.607
13.93,78.16,0.609
13.95,78.30,0.609
13.96,78.43,0.610
13.97,78.56,0.611
13.99,78.69,0.611
14.00,78.83,0.611
14.01,78.96,0.611
14.03,79.09,0.612
14.04,79.23,0.613
14.05,79.36,0.614
14.07,79.49,0.615
14.08,79.63,0.615
14.09,79.76,0.617
14.11,79.89,0.617
14.12,80.02,0.619
14.13,80.16,0.620
14.15,80.29,0.620
14.16,80.42,0.621
14.17,80.56,0.622
14.19,80.69,0.624
14.20,80.82,0.625
14.21,80.95,0.626
14.23,81.09,0.627
14.24,81.22,0.628
14.25,81.35,0.629
14.27,81.49,0.630
14.28,81.62,0.632
14.29,81.75,0.633
14.31,81.89,0.634
14.32,82.02,0.636
14.33,82.15,0.637
14.35,82.28,0.638
14.36,82.42,0.639
14.37,82.55,0.640
14.39,82.68,0.641
14.40,82.82,0.641
14.41,82.95,0.642
14.43,83.08,0.643
14.44,83.21,0.643
14.45,83.35,0.645
14.47,83.48,0.646
14.48,83.61,0.647
14.49,83.75,0.648
14.51,83.88,0.649
14.52,84.01,0.651
14.53,84.15,0.651
14.55,84.28,0.653
14.56,84.41,0.654
14.57,84.55,0.655
14.59,84.68,0.656
14.60,84.81,0.657
14.61,84.95,0.657
14.63,85.08,0.659
14.64,85.21,0.660
14.65,85.35,0.660
14.67,85.48,0.661
14.68,85.61,0.662
14.69,85.75,0.662
14.71,85.88,0.663
14.72,86.01,0.663
14.73,86.14,0.665
14.75,86.28,0.665
14.76,86.41,0.666
14.77,86.55,0.667
14.79,86.68,0.668
14.80,86.81,0.669
14.81,86.94,0.670
14.83,87.08,0.670
14.84,87.21,0.671
14.85,87.34,0.672
14.87,87.48,0.673
14.88,87.61,0.674
14.89,87.74,0.675
14.91,87.88,0.675
14.92,88.01,0.676
14.93,88.14,0.677
14.95,88.28,0.677
14.96,88.41,0.678
14.97,88.54,0.678
14.99,88.68,0.679
15.00,88.81,0.680
15.01,88.94,0.681
15.03,89.08,0.681
15.04,89.21,0.682
15.05,89.34,0.683
15.07,89.48,0.684
15.08,89.61,0.684
15.09,89.74,0.685
15.11,89.88,0.685
15.12,90.01,0.686
15.13,90.14,0.687
15.15,90.28,0.687
15.16,90.41,0.688
15.17,90.54,0.688
15.19,90.68,0.689
15.20,90.81,0.690
15.21,90.94,0.690
15.23,91.08,0.691
15.24,91.21,0.691
15.25,91.34,0.692
15.27,91.48,0.692
15.28,91.61,0.693
15.29,91.74,0.693
15.31,91.88,0.694
15.32,92.01,0.694
15.33,92.14,0.695
15.35,92.28,0.695
15.36,92.41,0.696
15.37,92.54,0.697
15.39,92.68,0.697
15.40,92.81,0.698
15.41,92.94,0.698
15.43,93.07,0.698
15.44,93.21,0.699
15.45,93.34,0.699
15.47,93.47,0.700
15.48,93.61,0.700
15.49,93.74,0.700
15.51,93.87,0.701
15.52,94.01,0.701
15.53,94.14,0.702
15.55,94.28,0.702
15.56,94.41,0.702
15.57,94.54,0.703
15.59,94.68,0.703
15.60,94.81,0.703
15.61,94.94,0.704
15.63,95.08,0.704
15.64,95.21,0.704
15.65,95.34,0.705
15.67,95.48,0.705
15.68,95.61,0.705
15.69,95.74,0.706
15.71,95.88,0.706
15.72,96.01,0.706
15.73,96.14,0.707
15.75,96.28,0.707
15.76,96.41,0.707
15.77,96.55,0.707
15.79,96.68,0.707
15.80,96.81,0.707
15.81,96.95,0.708
15.83,97.08,0.708
15.84,97.21,0.708
15.85,97.35,0.708
15.87,97.48,0.708
15.88,97.61,0.708
15.89,97.75,0.708
15.91,97.88,0.708
15.92,98.01,0.708
15.93,98.15,0.708
15.95,98.28,0.708
15.96,98.42,0.708
15.97,98.55,0.708
15.99,98.68,0.708
16.00,98.81,0.708
16.01,98.95,0.708
16.03,99.08,0.708
16.04,99.22,0.708
16.05,99.35,0.708
16.07,99.48,0.708
16.08,99.62,0.708
16.09,99.75,0.708
16.11,99.88,0.707
16.12,100.02,0.707
16.13,100.15,0.707
16.15,100.28,0.707
16.16,100.42,0.707
16.17,100.55,0.707
16.19,100.68,0.706
16.20,100.82,0.706
16.21,100.95,0.706
16.23,101.08,0.706
16.24,101.22,0.705
16.25,101.35,0.705
16.27,101.49,0.705
16.28,101.62,0.705
16.29,101.75,0.704
16.31,101.89,0.704
16.32,102.02,0.703
16.33,102.15,0.703
16.35,102.29,0.703
16.36,102.42,0.702
16.37,102.55,0.702
16.39,102.69,0.702
16.40,102.82,0.701
16.41,102.96,0.701
16.43,103.09,0.700
16.44,103.22,0.700
16.45,103.36,0.699
16.47,103.49,0.698
16.48,103.63,0.698
16.49,103.76,0.698
16.51,103.89,0.697
16.52,104.03,0.696
16.53,104.16,0.695
16.55,104.29,0.695
16.56,104.43,0.694
16.57,104.56,0.693
16.59,104.69,0.692
16.60,104.83,0.692
16.61,104.96,0.691
16.63,105.10,0.690
16.64,105.23,0.689
16.65,105.36,0.688
16.67,105.50,0.687
16.68,105.63,0.686
16.69,105.76,0.685
16.71,105.90,0.684
16.72,106.03,0.683
16.73,106.16,0.682
16.75,106.30,0.681
16.76,106.43,0.680
16.77,106.57,0.679
16.79,106.70,0.678
16.80,106.83,0.677
16.81,106.97,0.677
16.83,107.10,0.676
16.84,107.23,0.675
16.85,107.37,0.674
16.87,107.50,0.673
16.88,107.63,0.672
16.89,107.77,0.671
16.91,107.90,0.669
16.92,108.04,0.668
16.93,108.17,0.667
16.95,108.30,0.666
16.96,108.44,0.664
16.97,108.57,0.664
16.99,108.71,0.663
17.00,108.84,0.662
17.01,108.98,0.661
17.03,109.11,0.660
17.04,109.24,0.659
17.05,109.38,0.658
17.07,109.51,0.656
17.08,109.64,0.655
17.09,109.78,0.653
17.11,109.91,0.652
17.12,110.04,0.651
17.13,110.18,0.649
17.15,110.31,0.648
17.16,110.45,0.646
17.17,110.58,0.645
17.19,110.71,0.644
17.20,110.85,0.643
17.21,110.98,0.642
17.23,111.12,0.641
17.24,111.25,0.640
17.25,111.38,0.639
17.27,111.52,0.638
17.28,111.65,0.636
17.29,111.78,0.635
17.31,111.92,0.634
17.32,112.05,0.633
17.33,112.19,0.631
17.35,112.32,0.630
17.36,112.45,0.628
17.37,112.59,0.627
17.39,112.72,0.626
17.40,112.86,0.625
17.41,112.99,0.624
17.43,113.12,0.623
17.44,113.26,0.622
17.45,113.39,0.620
17.47,113.53,0.619
17.48,113.66,0.618
17.49,113.79,0.617
17.51,113.93,0.614
17.52,114.06,0.613
17.53,114.19,0.612
17.55,114.33,0.611
17.56,114.46,0.610
17.57,114.59,0.608
17.59,114.73,0.607
17.60,114.86,0.606
17.61,115.00,0.603
17.63,115.13,0.602
17.64,115.26,0.601
17.65,115.40,0.599
17.67,115.53,0.598
17.68,115.66,0.597
17.69,115.80,0.596
17.71,115.93,0.595
17.72,116.07,0.593
17.73,116.20,0.592
17.75,116.33,0.590
17.76,116.47,0.589
17.77,116.60,0.588
17.79,116.73,0.587
17.80,116.87,0.585
17.81,117.00,0.584
17.83,117.14,0.583
17.84,117.27,0.581
17.85,117.40,0.580
17.87,117.54,0.579
17.88,117.67,0.577
17.89,117.81,0.576
17.91,117.94,0.575
17.92,118.08,0.573
17.93,118.21,0.572
17.95,118.34,0.571
17.96,118.48,0.569
17.97,118.61,0.568
17.99,118.74,0.567
18.00,118.88,0.565
18.01,119.01,0.564
18.03,119.15,0.563
18.04,119.28,0.561
18.05,119.41,0.561
18.07,119.55,0.559
18.08,119.68,0.557
18.09,119.82,0.556
18.11,119.95,0.555
18.12,120.08,0.554
18.13,120.22,0.552
18.15,120.35,0.550
18.16,120.48,0.548
18.17,120.62,0.546
18.19,120.75,0.546
18.20,120.88,0.543
18.21,121.02,0.542
18.23,121.15,0.541
18.24,121.29,0.540
18.25,121.42,0.538
18.27,121.55,0.537
18.28,121.69,0.536
18.29,121.82,0.535
18.31,121.96,0.533
18.32,122.09,0.533
18.33,122.22,0.531
18.35,122.36,0.530
18.36,122.49,0.529
18.37,122.63,0.527
18.39,122.76,0.526
18.40,122.89,0.524
18.41,123.03,0.523
18.43,123.16,0.521
18.44,123.30,0.520
18.45,123.43,0.519
18.47,123.56,0.518
18.48,123.70,0.516
18.49,123.83,0.514
18.51,123.96,0.513
18.52,124.10,0.512
18.53,124.23,0.510
18.55,124.37,0.508
18.56,124.50,0.506
18.57,124.63,0.505
18.59,124.77,0.503
18.60,124.90,0.502
18.61,125.03,0.500
18.63,125.17,0.499
18.64,125.30,0.498
18.65,125.44,0.497
18.67,125.57,0.496
18.68,125.70,0.495
18.69,125.84,0.493
18.71,125.97,0.492
18.72,126.11,0.491
18.73,126.24,0.489
18.75,126.37,0.488
18.76,126.51,0.486
18.77,126.64,0.485
18.79,126.77,0.484
18.80,126.91,0.482
18.81,127.04,0.481
18.83,127.18,0.479
18.84,127.31,0.478
18.85,127.45,0.476
18.87,127.58,0.475
18.88,127.71,0.474
18.89,127.85,0.473
18.91,127.98,0.471
18.92,128.11,0.470
18.93,128.25,0.468
18.95,128.38,
18.96,128.52,
18.97,128.65,
18.99,,
18.99,,

[step]
Ramp 10.00 °C/min to -60.00 °C
Time,Temperature,Heat Flow (Normalized)
min,°C,W/g
20.99,130.14,0.003
21.01,130.14,0.003
21.02,130.13,0.003
21.03,130.13,0.002
21.05,130.12,0.002
21.06,130.10,0.002
21.07,130.06,0.003
21.09,130.02,0.003
21.10,129.95,-0.009
21.11,129.88,-0.036
21.13,129.79,-0.068
21.14,129.69,-0.103
21.15,129.59,-0.138
21.17,129.48,-0.170
21.18,129.37,-0.197
21.19,129.25,-0.219
21.21,129.14,-0.239
21.22,129.02,-0.254
21.23,128.90,-0.265
21.25,128.77,-0.276
21.26,128.65,-0.285
21.27,128.52,-0.293
21.29,128.40,-0.298
21.30,128.27,-0.304
21.31,128.14,-0.310
21.33,128.01,-0.312
21.34,127.88,-0.317
21.35,127.75,-0.320
21.37,127.62,-0.322
21.38,127.49,-0.326
21.39,127.36,-0.327
21.41,127.23,-0.328
21.42,127.10,-0.329
21.43,126.97,-0.331
21.45,126.84,-0.332
21.46,126.71,-0.333
21.47,126.57,-0.334
21.49,126.44,-0.335
21.50,126.31,-0.335
21.51,126.18,-0.336
21.53,126.05,-0.336
21.54,125.92,-0.337
21.55,125.78,-0.337
21.57,125.65,-0.337
21.58,125.52,-0.337
21.59,125.39,-0.338
21.61,125.25,-0.338
21.62,125.12,-0.338
21.63,124.99,-0.339
21.65,124.86,-0.339
21.66,124.72,-0.339
21.67,124.59,-0.339
21.69,124.46,-0.340
21.70,124.33,-0.340
21.71,124.19,-0.340
21.73,124.06,-0.340
21.74,123.93,-0.341
21.75,123.80,-0.341
21.77,123.66,-0.341
21.78,123.53,-0.341
21.79,123.40,-0.342
21.81,123.27,-0.342
21.82,123.13,-0.342
21.83,123.00,-0.342
21.85,122.87,-0.343
21.86,122.73,-0.343
21.87,122.60,-0.343
21.89,122.47,-0.343
21.90,122.34,-0.343
21.91,122.20,-0.344
21.93,122.07,-0.344
21.94,121.94,-0.344
21.95,121.81,-0.344
21.97,121.67,-0.344
21.98,121.54,-0.345
21.99,121.41,-0.345
22.01,121.27,-0.345
22.02,121.14,-0.345
22.03,121.01,-0.345
22.05,120.87,-0.346
22.06,120.74,-0.346
22.07,120.61,-0.346
22.09,120.48,-0.346
22.10,120.34,-0.346
22.11,120.21,-0.346
22.13,120.08,-0.346
22.14,119.94,-0.346
22.15,119.81,-0.347
22.17,119.68,-0.347
22.18,119.54,-0.347
22.19,119.41,-0.347
22.21,119.28,-0.347
22.22,119.14,-0.347
22.23,119.01,-0.347
22.25,118.88,-0.347
22.26,118.75,-0.348
22.27,118.61,-0.348
22.29,118.48,-0.348
22.30,118.35,-0.348
22.31,118.21,-0.348
22.33,118.08,-0.348
22.34,117.95,-0.348
22.35,117.81,-0.348
22.37,117.68,-0.348
22.38,117.55,-0.348
22.39,117.41,-0.348
22.41,117.28,-0.348
22.42,117.15,-0.348
22.43,117.01,-0.348
22.45,116.88,-0.348
22.46,116.75,-0.348
22.47,116.62,-0.348
22.49,116.48,-0.349
22.50,116.35,-0.349
22.51,116.22,-0.349
22.53,116.08,-0.349
22.54,115.95,-0.349
22.55,115.82,-0.349
22.57,115.68,-0.349
22.58,115.55,-0.349
22.59,115.42,-0.349
22.61,115.29,-0.349
22.62,115.15,-0.349
22.63,115.02,-0.349
22.65,114.89,-0.349
22.66,114.75,-0.349
22.67,114.62,-0.349
22.69,114.49,-0.349
22.70,114.35,-0.349
22.71,114.22,-0.349
22.73,114.09,-0.349
22.74,113.95,-0.349
22.75,113.82,-0.349
22.77,113.69,-0.349
22.78,113.55,-0.349
22.79,113.42,-0.349
22.81,113.29,-0.349
22.82,113.15,-0.349
22.83,113.02,-0.349
22.85,112.89,-0.349
22.86,112.75,-0.349
22.87,112.62,-0.349
22.89,112.49,-0.349
22.90,112.36,-0.349
22.91,112.22,-0.349
22.93,112.09,-0.349
22.94,111.96,-0.349
22.95,111.82,-0.349
22.97,111.69,-0.349
22.98,111.55,-0.349
22.99,111.42,-0.349
23.01,111.29,-0.349
23.02,111.15,-0.349
23.03,111.02,-0.349
23.05,110.89,-0.349
23.06,110.75,-0.349
23.07,110.62,-0.349
23.09,110.49,-0.349
23.10,110.35,-0.349
23.11,110.22,-0.349
23.13,110.09,-0.349
23.14,109.95,-0.348
23.15,109.82,-0.348
23.17,109.69,-0.348
23.18,109.55,-0.348
23.19,109.42,-0.348
23.21,109.29,-0.348
23.22,109.16,-0.348
23.23,109.02,-0.348
23.25,108.89,-0.348
23.26,108.76,-0.348
23.27,108.62,-0.348
23.29,108.49,-0.348
23.30,108.35,-0.348
23.31,108.22,-0.348
23.33,108.09,-0.348
23.34,107.95,-0.347
23.35,107.82,-0.347
23.37,107.69,-0.347
23.38,107.56,-0.347
23.39,107.42,-0.347
23.41,107.29,-0.347
23.42,107.16,-0.347
23.43,107.02,-0.347
23.45,106.89,-0.347
23.46,106.76,-0.347
23.47,106.62,-0.347
23.49,106.49,-0.347
23.50,106.36,-0.347
23.51,106.22,-0.347
23.53,106.09,-0.346
23.54,105.96,-0.346
23.55,105.82,-0.346
23.57,105.69,-0.346
23.58,105.56,-0.346
23.59,105.42,-0.346
23.61,105.29,-0.346
23.62,105.16,-0.346
23.63,105.02,-0.346
23.65,104.89,-0.346
23.66,104.76,-0.346
23.67,104.62,-0.345
23.69,104.49,-0.345
23.70,104.36,-0.345
23.71,104.22,-0.345
23.73,104.09,-0.345
23.74,103.96,-0.345
23.75,103.82,-0.345
23.77,103.69,-0.345
23.78,103.56,-0.344
23.79,103.42,-0.344
23.81,103.29,-0.344
23.82,103.16,-0.344
23.83,103.02,-0.344
23.85,102.89,-0.344
23.86,102.76,-0.344
23.87,102.62,-0.344
23.89,102.49,-0.344
23.90,102.36,-0.343
23.91,102.22,-0.343
23.93,102.09,-0.343
23.94,101.96,-0.343
23.95,101.82,-0.343
23.97,101.69,-0.342
23.98,101.56,-0.342
23.99,101.42,-0.342
24.01,101.29,-0.342
24.02,101.16,-0.342
24.03,101.02,-0.342
24.05,100.89,-0.341
24.06,100.76,-0.341
24.07,100.62,-0.341
24.09,100.49,-0.341
24.10,100.36,-0.341
24.11,100.22,-0.340
24.13,100.09,-0.340
24.14,99.96,-0.340
24.15,99.82,-0.340
24.17,99.69,-0.340
24.18,99.56,-0.339
24.19,99.42,-0.339
24.21,99.29,-0.339
24.22,99.16,-0.339
24.23,99.02,-0.338
24.25,98.89,-0.338
24.26,98.76,-0.338
24.27,98.62,-0.338
24.29,98.49,-0.338
24.30,98.36,-0.337
24.31,98.22,-0.337
24.33,98.09,-0.337
24.34,97.96,-0.337
24.35,97.82,-0.336
24.37,97.69,-0.336
24.38,97.56,-0.336
24.39,97.42,-0.336
24.41,97.29,-0.336
24.42,97.16,-0.335
24.43,97.02,-0.335
24.45,96.89,-0.335
24.46,96.76,-0.335
24.47,96.62,-0.334
24.49,96.49,-0.334
24.50,96.36,-0.334
24.51,96.22,-0.334
24.53,96.09,-0.333
24.54,95.96,-0.333
24.55,95.82,-0.333
24.57,95.69,-0.333
24.58,95.56,-0.332
24.59,95.42,-0.332
24.61,95.29,-0.332
24.62,95.16,-0.331
24.63,95.02,-0.331
24.65,94.89,-0.331
24.66,94.76,-0.331
24.67,94.62,-0.330
24.69,94.49,-0.330
24.70,94.36,-0.330
24.71,94.22,-0.330
24.73,94.09,-0.329
24.74,93.96,-0.329
24.75,93.82,-0.329
24.77,93.69,-0.329
24.78,93.56,-0.328
24.79,93.42,-0.328
24.81,93.29,-0.328
24.82,93.15,-0.327
24.83,93.02,-0.327
24.85,92.89,-0.327
24.86,92.76,-0.326
24.87,92.62,-0.326
24.89,92.49,-0.326
24.90,92.36,-0.326
24.91,92.22,-0.325
24.93,92.09,-0.325
24.94,91.95,-0.325
24.95,91.82,-0.324
24.97,91.69,-0.324
24.98,91.56,-0.324
24.99,91.42,-0.324
25.01,91.29,-0.323
25.02,91.15,-0.323
25.03,91.02,-0.323
25.05,90.89,-0.322
25.06,90.75,-0.322
25.07,90.62,-0.322
25.09,90.49,-0.321
25.10,90.35,-0.321
25.11,90.22,-0.321
25.13,90.09,-0.321
25.14,89.95,-0.320
25.15,89.82,-0.320
25.17,89.69,-0.320
25.18,89.55,-0.319
25.19,89.42,-0.319
25.21,89.29,-0.319
25.22,89.15,-0.318
25.23,89.02,-0.318
25.25,88.89,-0.318
25.26,88.76,-0.318
25.27,88.62,-0.317
25.29,88.49,-0.317
25.30,88.35,-0.317
25.31,88.22,-0.316
25.33,88.09,-0.316
25.34,87.95,-0.316
25.35,87.82,-0.315
25.37,87.69,-0.315
25.38,87.55,-0.315
25.39,87.42,-0.315
25.41,87.29,-0.314
25.42,87.15,-0.314
25.43,87.02,-0.314
25.45,86.89,-0.313
25.46,86.75,-0.313
25.47,86.62,-0.313
25.49,86.49,-0.312
25.50,86.35,-0.312
25.51,86.22,-0.312
25.53,86.09,-0.312
25.54,85.95,-0.311
25.55,85.82,-0.311
25.57,85.69,-0.311
25.58,85.55,-0.311
25.59,85.42,-0.310
25.61,85.29,-0.310
25.62,85.15,-0.310
25.63,85.02,-0.310
25.65,84.89,-0.309
25.66,84.75,-0.309
25.67,84.62,-0.309
25.69,84.49,-0.308
25.70,84.35,-0.308
25.71,84.22,-0.308
25.73,84.09,-0.308
25.74,83.95,-0.307
25.75,83.82,-0.307
25.77,83.68,-0.307
25.78,83.55,-0.307
25.79,83.42,-0.306
25.81,83.29,-0.306
25.82,83.15,-0.306
25.83,83.02,-0.306
25.85,82.89,-0.305
25.86,82.75,-0.305
25.87,82.62,-0.305
25.89,82.49,-0.305
25.90,82.35,-0.304
25.91,82.22,-0.304
25.93,82.09,-0.304
25.94,81.95,-0.304
25.95,81.82,-0.304
25.97,81.69,-0.303
25.98,81.55,-0.303
25.99,81.42,-0.303
26.01,81.29,-0.303
26.02,81.15,-0.303
26.03,81.02,-0.302
26.05,80.89,-0.302
26.06,80.75,-0.302
26.07,80.62,-0.302
26.09,80.49,-0.301
26.10,80.35,-0.301
26.11,80.22,-0.301
26.13,80.09,-0.301
26.14,79.95,-0.301
26.15,79.82,-0.300
26.17,79.69,-0.300
26.18,79.55,-0.300
26.19,79.42,-0.300
26.21,79.29,-0.299
26.22,79.15,-0.299
26.23,79.02,-0.299
26.25,78.89,-0.299
26.26,78.75,-0.298
26.27,78.62,-0.298
26.29,78.49,-0.298
26.30,78.35,-0.298
26.31,78.22,-0.298
26.33,78.09,-0.297
26.34,77.95,-0.297
26.35,77.82,-0.297
26.37,77.69,-0.297
26.38,77.55,-0.296
26.39,77.42,-0.296
26.41,77.29,-0.296
26.42,77.15,-0.296
26.43,77.02,-0.295
26.45,76.89,-0.295
26.46,76.75,-0.295
26.47,76.62,-0.295
26.49,76.49,-0.295
26.50,76.35,-0.294
26.51,76.22,-0.294
26.53,76.09,-0.294
26.54,75.95,-0.294
26.55,75.82,-0.294
26.57,75.69,-0.293
26.58,75.55,-0.293
26.59,75.42,-0.293
26.61,75.29,-0.293
26.62,75.15,-0.293
26.63,75.02,-0.292
26.65,74.89,-0.292
26.66,74.75,-0.292
[...]
88.49,-16.39,0.162
88.50,-16.25,0.162
88.51,-16.12,0.162
88.53,-15.98,0.162
88.54,-15.85,0.162
88.55,-15.72,0.162
88.57,-15.58,0.162
88.58,-15.45,0.162
88.59,-15.32,0.162
88.61,-15.19,0.162
88.62,-15.05,0.162
88.63,-14.92,0.162
88.65,-14.78,0.162
88.66,-14.65,0.162
88.67,-14.52,0.162
88.69,-14.38,0.162
88.70,-14.25,0.162
88.71,-14.12,0.162
88.73,-13.98,0.162
88.74,-13.85,0.162
88.75,-13.72,0.163
88.77,-13.58,0.163
88.78,-13.45,0.163
88.79,-13.32,0.163
88.81,-13.18,0.163
88.82,-13.05,0.163
88.83,-12.92,0.163
88.85,-12.78,0.163
88.86,-12.65,0.163
88.87,-12.51,0.163
88.89,-12.38,0.163
88.90,-12.25,0.163
88.91,-12.11,0.163
88.93,-11.98,0.163
88.94,-11.85,0.163
88.95,-11.71,0.163
88.97,-11.58,0.163
88.98,-11.45,0.163
88.99,-11.31,0.163
89.01,-11.18,0.163
89.02,-11.05,0.163
89.03,-10.91,0.164
89.05,-10.78,0.164
89.06,-10.65,0.164
89.07,-10.51,0.164
89.09,-10.38,0.164
89.10,-10.25,0.164
89.11,-10.11,0.164
89.13,-9.98,0.164
89.14,-9.85,0.164
89.15,-9.71,0.164
89.17,-9.58,0.164
89.18,-9.45,0.164
89.19,-9.31,0.164
89.21,-9.18,0.164
89.22,-9.05,0.164
89.23,-8.91,0.164
89.25,-8.78,0.164
89.26,-8.65,0.164
89.27,-8.51,0.164
89.29,-8.38,0.164
89.30,-8.25,0.164
89.31,-8.11,0.165
89.33,-7.98,0.165
89.34,-7.84,0.165
89.35,-7.71,0.165
89.37,-7.58,0.165
89.38,-7.44,0.165
89.39,-7.31,0.165
89.41,-7.18,0.165
89.42,-7.04,0.165
89.43,-6.91,0.165
89.45,-6.78,0.165
89.46,-6.64,0.165
89.47,-6.51,0.165
89.49,-6.38,0.165
89.50,-6.24,0.165
89.51,-6.11,0.165
89.53,-5.97,0.165
89.54,-5.84,0.165
89.55,-5.71,0.165
89.57,-5.58,0.166
89.58,-5.44,0.166
89.59,-5.31,0.166
89.61,-5.17,0.166
89.62,-5.04,0.166
89.63,-4.91,0.166
89.65,-4.77,0.166
89.66,-4.64,0.166
89.67,-4.51,0.166
89.69,-4.37,0.166
89.70,-4.24,0.166
89.71,-4.11,0.166
89.73,-3.97,0.166
89.74,-3.84,0.166
89.75,-3.71,0.166
89.77,-3.57,0.166
89.78,-3.44,0.166
89.79,-3.30,0.166
89.81,-3.17,0.166
89.82,-3.04,0.167
89.83,-2.91,0.167
89.85,-2.77,0.167
89.86,-2.64,0.167
89.87,-2.51,0.167
89.89,-2.37,0.167
89.90,-2.24,0.167
89.91,-2.10,0.167
89.93,-1.97,0.167
89.94,-1.84,0.167
89.95,-1.70,0.167
89.97,-1.57,0.167
89.98,-1.44,0.167
89.99,-1.30,0.167
90.01,-1.17,0.167
90.02,-1.04,0.167
90.03,-0.90,0.167
90.05,-0.77,0.168
90.06,-0.64,0.168
90.07,-0.50,0.168
90.09,-0.37,0.168
90.10,-0.24,0.168
90.11,-0.10,0.168
90.13,0.03,0.168
90.14,0.17,0.168
90.15,0.30,0.168
90.17,0.43,0.168
90.18,0.57,0.168
90.19,0.70,0.168
90.21,0.83,0.168
90.22,0.97,0.168
90.23,1.10,0.168
90.25,1.23,0.168
90.26,1.37,0.168
90.27,1.50,0.168
90.29,1.63,0.168
90.30,1.77,0.169
90.31,1.90,0.169
90.33,2.03,0.169
90.34,2.17,0.169
90.35,2.30,0.169
90.37,2.43,0.169
90.38,2.57,0.169
90.39,2.70,0.169
90.41,2.83,0.169
90.42,2.97,0.169
90.43,3.10,0.169
90.45,3.23,0.169
90.46,3.37,0.169
90.47,3.50,0.169
90.49,3.64,0.169
90.50,3.77,0.169
90.51,3.90,0.169
90.53,4.04,0.170
90.54,4.17,0.170
90.55,4.30,0.170
90.57,4.44,0.170
90.58,4.57,0.170
90.59,4.70,0.170
90.61,4.84,0.170
90.62,4.97,0.170
90.63,5.10,0.170
90.65,5.24,0.170
90.66,5.37,0.170
90.67,5.50,0.170
90.69,5.64,0.170
90.70,5.77,0.170
90.71,5.91,0.170
90.73,6.04,0.171
90.74,6.17,0.171
90.75,6.31,0.171
90.77,6.44,0.171
90.78,6.57,0.171
90.79,6.71,0.171
90.81,6.84,0.171
90.82,6.97,0.171
90.83,7.11,0.171
90.85,7.24,0.171
90.86,7.37,0.171
90.87,7.51,0.171
90.89,7.64,0.171
90.90,7.77,0.171
90.91,7.91,0.171
90.93,8.04,0.172
90.94,8.17,0.172
90.95,8.31,0.172
90.97,8.44,0.172
90.98,8.57,0.172
90.99,8.71,0.172
91.01,8.84,0.172
91.02,8.97,0.172
91.03,9.11,0.172
91.05,9.24,0.172
91.06,9.38,0.172
91.07,9.51,0.172
91.09,9.64,0.172
91.10,9.78,0.172
91.11,9.91,0.172
91.13,10.04,0.172
91.14,10.18,0.172
91.15,10.31,0.173
91.17,10.44,0.173
91.18,10.58,0.173
91.19,10.71,0.173
91.21,10.84,0.173
91.22,10.98,0.173
91.23,11.11,0.173
91.25,11.24,0.173
91.26,11.38,0.173
91.27,11.51,0.173
91.29,11.64,0.173
91.30,11.78,0.173
91.31,11.91,0.173
91.33,12.04,0.173
91.34,12.18,0.173
91.35,12.31,0.174
91.37,12.45,0.174
91.38,12.58,0.174
91.39,12.71,0.174
91.41,12.85,0.174
91.42,12.98,0.174
91.43,13.11,0.174
91.45,13.25,0.174
91.46,13.38,0.174
91.47,13.51,0.174
91.49,13.65,0.174
91.50,13.78,0.174
91.51,13.91,0.174
91.53,14.05,0.174
91.54,14.18,0.174
91.55,14.31,0.175
91.57,14.45,0.175
91.58,14.58,0.175
91.59,14.71,0.175
91.61,14.85,0.175
91.62,14.98,0.175
91.63,15.11,0.175
91.65,15.25,0.175
91.66,15.38,0.175
91.67,15.52,0.175
91.69,15.65,0.175
91.70,15.78,0.175
91.71,15.92,0.175
91.73,16.05,0.175
91.74,16.18,0.175
91.75,16.32,0.176
91.77,16.45,0.176
91.78,16.58,0.176
91.79,16.72,0.176
91.81,16.85,0.176
91.82,16.98,0.176
91.83,17.12,0.176
91.85,17.25,0.176
91.86,17.38,0.176
91.87,17.51,0.176
91.89,17.65,0.176
91.90,17.78,0.176
91.91,17.92,0.176
91.93,18.05,0.176
91.94,18.18,0.177
91.95,18.32,0.177
91.97,18.45,0.177
91.98,18.58,0.177
91.99,18.72,0.177
92.01,18.85,0.177
92.02,18.98,0.177
92.03,19.12,0.177
92.05,19.25,0.177
92.06,19.38,0.177
92.07,19.52,0.177
92.09,19.65,0.177
92.10,19.78,0.177
92.11,19.92,0.177
92.13,20.05,0.178
92.14,20.18,0.178
92.15,20.32,0.178
92.17,20.45,0.178
92.18,20.58,0.178
92.19,20.72,0.178
92.21,20.85,0.178
92.22,20.99,0.178
92.23,21.12,0.178
92.25,21.25,0.178
92.26,21.39,0.178
92.27,21.52,0.178
92.29,21.65,0.178
92.30,21.79,0.179
92.31,21.92,0.179
92.33,22.05,0.179
92.34,22.19,0.179
92.35,22.32,0.179
92.37,22.45,0.179
92.38,22.59,0.179
92.39,22.72,0.179
92.41,22.85,0.179
92.42,22.99,0.179
92.43,23.12,0.179
92.45,23.25,0.179
92.46,23.39,0.179
92.47,23.52,0.179
92.49,23.65,0.180
92.50,23.79,0.180
92.51,23.92,0.180
92.53,24.05,0.180
92.54,24.19,0.180
92.55,24.32,0.180
92.57,24.45,0.180
92.58,24.59,0.180
92.59,24.72,0.180
92.61,24.86,0.180
92.62,24.99,0.180
92.63,25.12,0.180
92.65,25.25,0.181
92.66,25.39,0.181
92.67,25.52,0.181
92.69,25.66,0.181
92.70,25.79,0.181
92.71,25.92,0.181
92.73,26.06,0.181
92.74,26.19,0.181
92.75,26.32,0.181
92.77,26.46,0.181
92.78,26.59,0.181
92.79,26.72,0.181
92.81,26.86,0.181
92.82,26.99,0.182
92.83,27.13,0.182
92.85,27.26,0.182
92.86,27.39,0.182
92.87,27.53,0.182
92.89,27.66,0.182
92.90,27.79,0.182
92.91,27.93,0.182
92.93,28.06,0.182
92.94,28.19,0.182
92.95,28.33,0.182
92.97,28.46,0.182
92.98,28.59,0.183
92.99,28.73,0.183
93.01,28.86,0.183
93.02,28.99,0.183
93.03,29.13,0.183
93.05,29.26,0.183
93.06,29.39,0.183
93.07,29.53,0.183
93.09,29.66,0.183
93.10,29.79,0.183
93.11,29.93,0.183
93.13,30.06,0.183
93.14,30.19,0.184
93.15,30.33,0.184
93.17,30.46,0.184
93.18,30.60,0.184
93.19,30.73,0.184
93.21,30.86,0.184
93.22,31.00,0.184
93.23,31.13,0.184
93.25,31.26,0.184
93.26,31.40,0.184
93.27,31.53,0.184
93.29,31.66,0.184
93.30,31.80,0.184
93.31,31.93,0.185
93.33,32.06,0.185
93.34,32.20,0.185
93.35,32.33,0.185
93.37,32.46,0.185
93.38,32.60,0.185
93.39,32.73,0.185
93.41,32.86,0.185
93.42,33.00,0.185
93.43,33.13,0.185
93.45,33.27,0.185
93.46,33.40,0.185
93.47,33.53,0.185
93.49,33.67,0.186
93.50,33.80,0.186
93.51,33.93,0.186
93.53,34.07,0.186
93.54,34.20,0.186
93.55,34.33,0.186
93.57,34.47,0.186
93.58,34.60,0.186
93.59,34.73,0.186
93.61,34.87,0.186
93.62,35.00,0.186
93.63,35.13,0.186
93.65,35.27,0.186
93.66,35.40,0.186
93.67,35.53,0.187
93.69,35.67,0.187
93.70,35.80,0.187
93.71,35.93,0.187
93.73,36.07,0.187
93.74,36.20,0.187
93.75,36.34,0.187
93.77,36.47,0.187
93.78,36.60,0.187
93.79,36.73,0.187
93.81,36.87,0.187
93.82,37.00,0.187
93.83,37.13,0.188
93.85,37.27,0.188
93.86,37.40,0.188
93.87,37.53,0.188
93.89,37.67,0.188
93.90,37.80,0.188
93.91,37.94,0.188
93.93,38.07,0.188
93.94,38.20,0.188
93.95,38.34,0.188
93.97,38.47,0.188
93.98,38.60,0.188
93.99,38.74,0.189
94.01,38.87,0.189
94.02,39.00,0.189
94.03,39.14,0.189
94.05,39.27,0.189
94.06,39.40,0.189
94.07,39.54,0.189
94.09,39.67,0.189
94.10,39.80,0.189
94.11,39.94,0.189
94.13,40.07,0.189
94.14,40.21,0.189
94.15,40.34,0.190
94.17,40.47,0.190
94.18,40.61,0.190
94.19,40.74,0.190
94.21,40.87,0.190
94.22,41.01,0.190
94.23,41.14,0.190
94.25,41.27,0.190
94.26,41.41,0.190
94.27,41.54,0.190
94.29,41.67,0.190
94.30,41.81,0.190
94.31,41.94,0.190
94.33,42.07,0.191
94.34,42.21,0.191
94.35,42.34,0.191
94.37,42.47,0.191
94.38,42.61,0.191
94.39,42.74,0.191
94.41,42.87,0.191
94.42,43.01,0.191
94.43,43.14,0.191
94.45,43.27,0.191
94.46,43.41,0.191
94.47,43.54,0.191
94.49,43.67,0.191
94.50,43.81,0.192
94.51,43.94,0.192
94.53,44.07,0.192
94.54,44.21,0.192
94.55,44.34,0.192
94.57,44.47,0.192
94.58,44.61,0.192
94.59,44.74,0.192
94.61,44.88,0.192
94.62,45.01,0.192
94.63,45.14,0.192
94.65,45.28,0.192
94.66,45.41,0.193
94.67,45.54,0.193
94.69,45.68,0.193
94.70,45.81,0.193
94.71,45.94,0.193
94.73,46.08,0.193
94.74,46.21,0.193
94.75,46.35,0.193
94.77,46.48,0.193
94.78,46.61,0.193
94.79,46.75,0.193
94.81,46.88,0.193
94.82,47.01,0.193
94.83,47.15,0.194
94.85,47.28,0.194
94.86,47.41,0.194
94.87,47.55,0.194
94.89,47.68,0.194
94.90,47.81,0.194
94.91,47.95,0.194
94.93,48.08,0.194
94.94,48.21,0.194
94.95,48.35,0.194
94.97,48.48,0.194
94.98,48.61,0.195
94.99,48.75,0.195
95.01,48.88,0.195
95.02,49.01,0.195
95.03,49.15,0.195
95.05,49.28,0.195
95.06,49.42,0.195
95.07,49.55,0.195
95.09,49.68,0.195
95.10,49.81,0.195
95.11,49.95,0.195
95.13,50.08,0.195
95.14,50.21,0.196
95.15,50.35,0.196
95.17,50.48,0.196
95.18,50.62,0.196
95.19,50.75,0.196
95.21,50.88,0.196
95.22,51.02,0.196
95.23,51.15,0.196
95.25,51.28,0.196
95.26,51.42,0.196
95.27,51.55,0.196
95.29,51.68,0.196
95.30,51.82,0.196
95.31,51.95,0.197
95.33,52.08,0.197
95.34,52.22,0.197
95.35,52.35,0.197
95.37,52.48,0.197
95.38,52.62,0.197
95.39,52.75,0.197
95.41,52.88,0.197
95.42,53.02,0.197
95.43,53.15,0.197
95.45,53.28,0.198
95.46,53.42,0.198
95.47,53.55,0.198
95.49,53.68,0.198
95.50,53.82,0.198
95.51,53.95,0.198
95.53,54.08,0.198
95.54,54.22,0.198
95.55,54.35,0.198
95.57,54.49,0.198
95.58,54.62,0.198
95.59,54.75,0.198
95.61,54.89,0.198
95.62,55.02,0.198
95.63,55.16,0.199
95.65,55.29,0.199
95.66,55.42,0.199
95.67,55.56,0.199
95.69,55.69,0.199
95.70,55.83,0.199
95.71,55.96,0.199
95.73,56.09,0.200
95.74,56.23,0.200
95.75,56.36,0.200
95.77,56.50,0.200
95.78,56.63,0.200
95.79,56.76,0.200
95.81,56.90,0.200
95.82,57.03,0.200
95.83,57.16,0.200
95.85,57.30,0.200
95.86,57.43,0.200
95.87,57.56,0.200
95.89,57.69,0.200
95.90,57.83,0.200
95.91,57.96,0.200
95.93,58.09,0.200
95.94,58.23,0.201
95.95,58.36,0.201
95.97,58.49,0.201
95.98,58.63,0.201
95.99,58.76,0.201
96.01,58.89,0.201
96.02,59.03,0.201
96.03,59.16,0.201
96.05,59.29,0.201
96.06,59.43,0.201
96.07,59.56,0.201
96.09,59.69,0.201
96.10,59.83,0.201
96.11,59.96,0.201
96.13,60.09,0.201
96.14,60.23,0.201
96.15,60.36,0.202
96.17,60.49,0.202
96.18,60.63,0.202
96.19,60.76,0.202
96.21,60.89,0.202
96.22,61.03,0.202
96.23,61.16,0.202
96.25,61.29,0.202
96.26,61.43,0.202
96.27,61.56,0.202
96.29,61.69,0.202
96.30,61.83,0.202
96.31,61.96,0.203
96.33,62.09,0.203
96.34,62.23,0.203
96.35,62.36,0.203
96.37,62.49,0.203
96.38,62.63,0.203
96.39,62.76,0.203
96.41,62.89,0.203
96.42,63.03,0.203
96.43,63.16,0.203
96.45,63.29,0.203
96.46,63.43,0.204
96.47,63.56,0.204
96.49,63.69,0.204
96.50,63.83,0.204
96.51,63.96,0.204
96.53,64.09,0.204
96.54,64.23,0.204
96.55,64.36,0.204
96.57,64.50,0.204
96.58,64.63,0.204
96.59,64.76,0.205
96.61,64.90,0.205
96.62,65.03,0.205
96.63,65.16,0.205
96.65,65.30,0.205
96.66,65.43,0.205
96.67,65.56,0.205
96.69,65.70,0.205
96.70,65.83,0.205
96.71,65.96,0.206
96.73,66.10,0.206
96.74,66.23,0.206
96.75,66.36,0.206
96.77,66.50,0.206
96.78,66.63,0.206
96.79,66.76,0.206
96.81,66.90,0.206
96.82,67.03,0.206
96.83,67.17,0.207
96.85,67.30,0.207
96.86,67.43,0.207
96.87,67.57,0.207
96.89,67.70,0.207
96.90,67.83,0.207
96.91,67.97,0.207
96.93,68.10,0.207
96.94,68.23,0.207
96.95,68.37,0.207
96.97,68.50,0.208
96.98,68.63,0.208
96.99,68.77,0.208
97.01,68.90,0.208
97.02,69.04,0.208
97.03,69.17,0.208
97.05,69.30,0.208
97.06,69.44,0.208
97.07,69.57,0.208
97.09,69.70,0.209
97.10,69.84,0.209
97.11,69.97,0.209
97.13,70.10,0.209
97.14,70.24,0.209
97.15,70.37,0.209
97.17,70.50,0.209
97.18,70.64,0.209
97.19,70.77,0.209
97.21,70.90,0.209
97.22,71.04,0.209
97.23,71.17,0.210
97.25,71.30,0.210
97.26,71.43,0.210
97.27,71.57,0.210
97.29,71.70,0.210
97.30,71.84,0.210
97.31,71.97,0.210
97.33,72.10,0.210
97.34,72.24,0.210
97.35,72.37,0.210
97.37,72.50,0.211
97.38,72.64,0.211
97.39,72.77,0.211
97.41,72.90,0.211
97.42,73.04,0.211
97.43,73.17,0.211
97.45,73.30,0.211
97.46,73.44,0.211
97.47,73.57,0.212
97.49,73.70,0.212
97.50,73.84,0.212
97.51,73.97,0.212
97.53,74.10,0.212
97.54,74.24,0.212
97.55,74.37,0.212
97.57,74.50,0.212
97.58,74.64,0.212
97.59,74.77,0.213
97.61,74.90,0.213
97.62,75.04,0.213
97.63,75.17,0.213
97.65,75.30,0.213
97.66,75.44,0.213
97.67,75.57,0.213
97.69,75.70,0.213
97.70,75.84,0.213
97.71,75.97,0.214
97.73,76.10,0.214
97.74,76.24,0.214
97.75,76.37,0.214
97.77,76.50,0.214
97.78,76.64,0.214
97.79,76.77,0.214
97.81,76.90,0.215
97.82,77.04,0.215
97.83,77.17,0.215
97.85,77.31,0.215
97.86,77.44,0.215
97.87,77.57,0.215
97.89,77.71,0.215
97.90,77.84,0.216
97.91,77.97,0.216
97.93,78.11,0.216
97.94,78.24,0.216
97.95,78.37,0.216
97.97,78.51,0.216
97.98,78.64,0.216
97.99,78.77,0.217
98.01,78.91,0.217
98.02,79.04,0.217
98.03,79.17,0.217
98.05,79.31,0.217
98.06,79.44,0.217
98.07,79.57,0.217
98.09,79.71,0.218
98.10,79.84,0.218
98.11,79.97,0.218
98.13,80.11,0.218
98.14,80.24,0.218
98.15,80.37,0.218
98.17,80.51,0.218
98.18,80.64,0.219
98.19,80.77,0.219
98.21,80.91,0.219
98.22,81.04,0.219
98.23,81.18,0.219
98.25,81.31,0.220
98.26,81.44,0.220
98.27,81.57,0.220
98.29,81.71,0.220
98.30,81.84,0.220
98.31,81.97,0.220
98.33,82.11,0.220
98.34,82.24,0.221
98.35,82.37,0.221
98.37,82.51,0.221
98.38,82.64,0.221
98.39,82.77,0.221
98.41,82.91,0.221
98.42,83.04,0.222
98.43,83.18,0.222
98.45,83.31,0.222
98.46,83.44,0.222
98.47,83.58,0.222
98.49,83.71,0.222
98.50,83.84,0.223
98.51,83.98,0.223
98.53,84.11,0.223
98.54,84.24,0.223
98.55,84.38,0.223
98.57,84.51,0.224
98.58,84.64,0.224
98.59,84.78,0.224
98.61,84.91,0.224
98.62,85.04,0.224
98.63,85.18,0.224
98.65,85.31,0.225
98.66,85.44,0.225
98.67,85.58,0.225
98.69,85.71,0.225
98.70,85.84,0.225
98.71,85.98,0.226
98.73,86.11,0.226
98.74,86.24,0.226
98.75,86.38,0.226
98.77,86.51,0.226
98.78,86.64,0.227
98.79,86.78,0.227
98.81,86.91,0.227
98.82,87.04,0.227
98.83,87.18,0.227
98.85,87.31,0.228
98.86,87.44,0.228
98.87,87.58,0.228
98.89,87.71,0.228
98.90,87.84,0.229
98.91,87.98,0.229
98.93,88.11,0.229
98.94,88.25,0.229
98.95,88.38,0.230
98.97,88.51,0.230
98.98,88.64,0.230
98.99,88.78,0.230
99.01,88.91,0.231
99.02,89.04,0.231
99.03,89.18,0.231
99.05,89.31,0.231
99.06,89.44,0.232
99.07,89.58,0.232
99.09,89.71,0.232
99.10,89.84,0.233
99.11,89.98,0.233
99.13,90.11,0.233
99.14,90.24,0.233
99.15,90.38,0.234
99.17,90.51,0.234
99.18,90.65,0.234
99.19,90.78,0.235
99.21,90.91,0.235
99.22,91.04,0.235
99.23,91.18,0.236
99.25,91.31,0.236
99.26,91.45,0.236
99.27,91.58,0.237
99.29,91.71,0.237
99.30,91.85,0.237
99.31,91.98,0.238
99.33,92.11,0.238
99.34,92.24,0.238
99.35,92.38,0.239
99.37,92.51,0.239
99.38,92.64,0.239
99.39,92.78,0.240
99.41,92.91,0.240
99.42,93.05,0.240
99.43,93.18,0.241
99.45,93.31,0.242
99.46,93.45,0.242
99.47,93.58,0.242
99.49,93.71,0.243
99.50,93.85,0.243
99.51,93.98,0.243
99.53,94.11,0.244
99.54,94.25,0.244
99.55,94.38,0.245
99.57,94.51,0.245
99.58,94.64,0.245
99.59,94.78,0.246
99.61,94.91,0.246
99.62,95.04,0.246
99.63,95.18,0.247
99.65,95.31,0.247
99.66,95.44,0.248
99.67,95.58,0.248
99.69,95.71,0.248
99.70,95.84,0.249
99.71,95.98,0.249
99.73,96.11,0.250
99.74,96.25,0.250
99.75,96.38,0.251
99.77,96.51,0.251
99.78,96.65,0.252
99.79,96.78,0.252
99.81,96.91,0.253
99.82,97.05,0.253
99.83,97.18,0.254
99.85,97.31,0.254
99.86,97.45,0.254
99.87,97.58,0.255
99.89,97.71,0.255
99.90,97.85,0.256
99.91,97.98,0.256
99.93,98.11,0.257
99.94,98.25,0.257
99.95,98.38,0.258
99.97,98.51,0.258
99.98,98.65,0.259
99.99,98.78,0.259
100.01,98.91,0.259
100.02,99.05,0.260
100.03,99.18,0.261
100.05,99.31,0.261
100.06,99.45,0.261
100.07,99.58,0.262
100.09,99.71,0.262
100.10,99.85,0.263
100.11,99.98,0.263
100.13,100.11,0.264
100.14,100.25,0.264
100.15,100.38,0.264
100.17,100.51,0.265
100.18,100.65,0.265
100.19,100.78,0.266
100.21,100.91,0.266
100.22,101.05,0.267
100.23,101.18,0.267
100.25,101.31,0.268
100.26,101.45,0.268
100.27,101.58,0.269
100.29,101.71,0.269
100.30,101.85,0.269
100.31,101.98,0.270
100.33,102.11,0.270
100.34,102.25,0.271
100.35,102.38,0.271
100.37,102.51,0.272
100.38,102.65,0.272
100.39,102.78,0.272
100.41,102.91,0.273
100.42,103.05,0.273
100.43,103.18,0.273
100.45,103.31,0.274
100.46,103.45,0.274
100.47,103.58,0.275
100.49,103.71,0.275
100.50,103.85,0.275
100.51,103.98,0.276
100.53,104.11,0.276
100.54,104.25,0.276
100.55,104.38,0.277
100.57,104.51,0.277
100.58,104.65,0.277
100.59,104.78,0.278
100.61,104.91,0.278
100.62,105.05,0.278
100.63,105.18,0.279
100.65,105.31,0.279
100.66,105.45,0.279
100.67,105.58,0.279
100.69,105.71,0.280
100.70,105.85,0.280
100.71,105.98,0.280
100.73,106.11,0.280
100.74,106.25,0.281
100.75,106.38,0.281
100.77,106.51,0.281
100.78,106.65,0.281
100.79,106.78,0.282
100.81,106.91,0.282
100.82,107.05,0.282
100.83,107.18,0.282
100.85,107.31,0.282
100.86,107.45,0.283
100.87,107.58,0.283
100.89,107.71,0.283
100.90,107.85,0.283
100.91,107.98,0.283
100.93,108.12,0.283
100.94,108.25,0.284
100.95,108.38,0.284
100.97,108.51,0.284
100.98,108.65,0.284
100.99,108.78,0.284
101.01,108.92,0.284
101.02,109.05,0.284
101.03,109.18,0.284
101.05,109.32,0.284
101.06,109.45,0.284
101.07,109.58,0.285
101.09,109.72,0.285
101.10,109.85,0.285
101.11,109.98,0.285
101.13,110.12,0.285
101.14,110.25,0.285
101.15,110.38,0.285
101.17,110.52,0.285
101.18,110.65,0.285
101.19,110.78,0.285
101.21,110.92,0.285
101.22,111.05,0.285
101.23,111.18,0.285
101.25,111.32,0.285
101.26,111.45,0.285
101.27,111.58,0.285
101.29,111.72,0.285
101.30,111.85,0.285
101.31,111.98,0.285
101.33,112.12,0.285
101.34,112.25,0.285
101.35,112.39,0.285
101.37,112.52,0.285
101.38,112.65,0.285
101.39,112.78,0.285
101.41,112.92,0.285
101.42,113.05,0.285
101.43,113.19,0.285
101.45,113.32,0.285
101.46,113.45,0.285
101.47,113.59,0.285
101.49,113.72,0.285
101.50,113.85,0.285
101.51,113.98,0.285
101.53,114.12,0.285
101.54,114.25,0.285
101.55,114.38,0.285
101.57,114.52,0.285
101.58,114.65,0.285
101.59,114.79,0.285
101.61,114.92,0.285
101.62,115.05,0.285
101.63,115.19,0.285
101.65,115.32,0.285
101.66,115.45,0.285
101.67,115.59,0.285
101.69,115.72,0.285
101.70,115.85,0.285
101.71,115.99,0.285
101.73,116.12,0.285
101.74,116.25,0.285
101.75,116.39,0.285
101.77,116.52,0.285
101.78,116.65,0.285
101.79,116.79,0.285
101.81,116.92,0.286
101.82,117.05,0.286
101.83,117.19,0.286
101.85,117.32,0.286
101.86,117.45,0.286
101.87,117.59,0.286
101.89,117.72,0.286
101.90,117.86,0.286
101.91,117.99,0.286
101.93,118.12,0.286
101.94,118.26,0.286
101.95,118.39,0.286
101.97,118.52,0.286
101.98,118.66,0.286
101.99,118.79,0.286
102.01,118.92,0.286
102.02,119.06,0.286
102.03,119.19,0.286
102.05,119.32,0.286
102.06,119.46,0.286
102.07,119.59,0.286
102.09,119.73,0.286
102.10,119.86,0.287
102.11,119.99,0.287
102.13,120.13,0.287
102.14,120.26,0.287
102.15,120.39,0.287
102.17,120.52,0.287
102.18,120.66,0.287
102.19,120.79,0.287
102.21,120.93,0.287
102.22,121.06,0.287
102.23,121.19,0.287
102.25,121.33,0.287
102.26,121.46,0.287
102.27,121.59,0.287
102.29,121.73,0.287
102.30,121.86,0.287
102.31,121.99,0.287
102.33,122.13,0.287
102.34,122.26,0.287
102.35,122.39,0.287
102.37,122.53,0.287
102.38,122.66,0.288
102.39,122.79,0.288
102.41,122.93,0.288
102.42,123.06,0.288
102.43,123.20,0.288
102.45,123.33,0.288
102.46,123.46,0.288
102.47,123.60,0.288
102.49,123.73,0.288
102.50,123.86,0.288
102.51,124.00,0.288
102.53,124.13,0.288
102.54,124.26,0.288
102.55,124.40,0.288
102.57,124.53,0.288
102.58,124.66,0.289
102.59,124.80,0.289
102.61,124.93,0.289
102.62,125.07,0.289
102.63,125.20,0.289
102.65,125.33,0.289
102.66,125.47,0.289
102.67,125.60,0.289
102.69,125.73,0.289
102.70,125.87,0.289
102.71,126.00,0.289
102.73,126.13,0.289
102.74,126.27,0.289
102.75,126.40,0.289
102.77,126.53,0.289
102.78,126.67,0.289
102.79,126.80,0.289
102.81,126.93,0.289
102.82,127.07,0.289
102.83,127.20,0.290
102.85,127.33,0.290
102.86,127.47,0.290
102.87,127.60,0.290
102.89,127.73,0.290
102.90,127.87,0.290
102.91,128.00,0.290
102.93,128.13,0.290
102.94,128.27,
102.95,128.40,
102.97,128.53,
102.98,128.67,
102.99,,