File: DSC/Olivia/2025_08_10_1CBN_3PVP40_MP_n60C_230C_10Cmin_x3.csv
Filename,2025_08_10_1CBN_3PVP40_MP_n60C_230C_10Cmin_x3
Instrument name,DSC2A-00468 (192.168.1.100)
Operator,Yarger
rundate,8/10/2025
Sample name,2025_08_10_1CBN_3PVP40_MP_n60C_230C_10Cmin_x3
proceduresegments,Data Off ; Equilibrate -60.00 °C; Data On ; Ramp 10.00 °C/min to 230.00 °C; Data Off ; Isothermal 2.0 min; Data On ; Ramp 10.00 °C/min to -60.00 °C; Data Off ; Isothermal 2.0 min; Data On ; Ramp 10.00 °C/min to 230.00 °C; Data Off ; Isothermal 2.0 min; Data On ; Ramp 10.00 °C/min to -60.00 °C; Data Off ; Isothermal 2.0 min; Data On ; Ramp 10.00 °C/min to 230.00 °C
[File Parameters]
Run date,8/10/2025 4:34:22 PM
Trios version,5.1.1.46572
Original File Name,
Current File Name,D:\DSC2500\JYarger\2025_08_10_1CBN_3PVP40_MP_n60C_230C_10Cmin_x3.tri
[Procedure]
Procedure Name,TS_n60C_230C_10Cmin_x3
Sample Name,2025_08_10_1CBN_3PVP40_MP_n60C_230C_10Cmin_x3
Sample Mass,33.09 mg
Reference Sample Mass,0 mg
Pan Mass,7.15 mg
Pan Number,16
Reference Pan Mass,32.42 mg
Reference Pan Number,10
Pan Type,Aluminum
Comments,Thermal support Al pans/lids. DSC_Samples_A2_Tray_August2025 google sheet.
Project Name,Pharma
Operator,Yarger
Test,Custom
Unload Max Temperature,30
Unload Min Temperature,30
Load Max Temperature,30
Load Min Temperature,30
Stop on Gas Flow Error,Yes
[Signal List]
Signal #1,Time (min)
Signal #2,Temperature (°C)
Signal #3,Heat Flow (mW)
Signal #4,Delta T (µV)
Signal #5,Delta Tzero (µV)
Signal #6,Tzero Temperature (°C)
Signal #7,Cell Purge (mL/min)
Signal #8,Heater Temp (°C)
Signal #9,Power Delivered (W)
Signal #10,Reference Junction Temperature (°C)
Signal #11,Flange Temperature (°C)
Signal #12,Heat Flow Phase (rad)
Signal #13,Total Heat Capacity (J/°C)
Signal #14,Heat Capacity (J/°C)
[Configuration]
Company Name,ASU
Instrument Name,DSC2A-00468
Instrument Type,DSC2500
Serial Number,DSC2A-00468
IP,192.168.1.100
Location of Instrument,MRRC
DisplayType,Unknown
Sample Interval ,0.1 s/pt
Selected Heat Flow,T4P
Exotherm Direction,Down
Cell Serial,DRC2-00792
Lid Type,Standard
Cooler,RCS 90
Leave Cooler on at End of Sequence,On
Gas 2,Nitrogen
Gas Selected,Channel 1
Flow Rate,50 mL/min
Secondary Purge,On
Licensed Heat Flow,Heat Flow T4P
Modulation Licensed,Yes
[Versions]
Common IDD Version,1
Cortex Version,VER 2.10.2.31
Driver,5.0.0.6
GDM Version,1.0.3.3
TouchscreenVersion,1.0.0.16145
FEP Version,1.2.1.21
FEP Bootloader,2.0.0.5
AutoSampler Version,2.1.1.26
Auto Sampler Bootloader,2.0.0.5
FCM Version,1.1.0.3
FCM Bootloader,2.0.0.5
[Experiment Logs]
Experiment Log Entry # 1,Data On set to 0
Experiment Log Entry # 3,Equilibrate Segment -60 (C) Started
Experiment Log Entry # 5,Air Cool is off.
Experiment Log Entry # 7,Data On set to 1
Experiment Log Entry # 9,Ramp Segment 10 C/min to 230 Started
Experiment Log Entry # 11,Data On set to 0
Experiment Log Entry # 13,Isothermal Segment 2 min started
Experiment Log Entry # 15,Data On set to 1
Experiment Log Entry # 17,Ramp Segment 10 C/min to -60 Started
Experiment Log Entry # 19,Data On set to 0
Experiment Log Entry # 21,Isothermal Segment 2 min started
Experiment Log Entry # 23,Data On set to 1
Experiment Log Entry # 25,Ramp Segment 10 C/min to 230 Started
Experiment Log Entry # 27,Data On set to 0
Experiment Log Entry # 29,Isothermal Segment 2 min started
Experiment Log Entry # 31,Data On set to 1
Experiment Log Entry # 33,Ramp Segment 10 C/min to -60 Started
Experiment Log Entry # 35,Data On set to 0
Experiment Log Entry # 37,Isothermal Segment 2 min started
Experiment Log Entry # 39,Data On set to 1
Experiment Log Entry # 41,Ramp Segment 10 C/min to 230 Started
[Method Log]
Method Log Entry # 1,Data Off
Method Log Entry # 2,Equilibrate -60 °C
Method Log Entry # 3,Data On
Method Log Entry # 4,(Ramp 1005231) Ramp 10 °C/minute to 230 °C
Method Log Entry # 5,Data Off
Method Log Entry # 6,Isothermal 2 minutes
Method Log Entry # 7,Data On
Method Log Entry # 8,(Ramp 1005235) Ramp 10 °C/minute to -60 °C
Method Log Entry # 9,Data Off
Method Log Entry # 10,Isothermal 2 minutes
Method Log Entry # 11,Data On
Method Log Entry # 12,(Ramp 1005239) Ramp 10 °C/minute to 230 °C
Method Log Entry # 13,Data Off
Method Log Entry # 14,Isothermal 2 minutes
Method Log Entry # 15,Data On
Method Log Entry # 16,(Ramp 1005243) Ramp 10 °C/minute to -60 °C
Method Log Entry # 17,Data Off
Method Log Entry # 18,Isothermal 2 minutes
Method Log Entry # 19,Data On
Method Log Entry # 20,(Ramp 1005247) Ramp 10 °C/minute to 230 °C
Cell Serial,DRC2-00792
[T1 Calibration]
Slope,-0.008529666
Offset,9.636258
Initial Temperature,98.23
GUID,f8bfdadc-4977-4fdf-ba6d-0ba9134940c3
[TZero Calibration]
Date Applied,11/29/2022 4:06:13 PM
Description,From -89.059 °C to 396.009 °C at 20.000°C/min
Gas Type,Nitrogen
Pan Type,None
Source Files 1,C:\Users\yargerlab\Desktop\DSC Data\General\TZero_calibration_11_29_22_2nd(2).tri
Source Files 2,C:\Users\yargerlab\Desktop\DSC Data\General\TZero_calibration_11_29_22_2nd(3).tri
Delta T Offset,13.05235
Delta T Slope,-0.007271007
Delta T0 Offset,-13.69128
Delta T0 Slope,0.06063341
[Temperature Calibration]
Date Applied,11/29/2022 7:12:28 PM
Description,From 106.590 °C to 186.590 °C at 10.000°C/min
Gas Type,Nitrogen
Pan Type,Tzero Aluminum Hermetic
Source Files 1,C:\Users\yargerlab\Desktop\DSC Data\General\Indium(6).tri
Measured 1,157.391
Known 1,156.598
[Cell Constant Calibration]
Date Applied,11/29/2022 7:12:29 PM
Description,From 106.590 °C to 186.590 °C at 10.000°C/min
Gas Type,Nitrogen
Pan Type,Tzero Aluminum Hermetic
Source Files 1,C:\Users\yargerlab\Desktop\DSC Data\General\Indium(6).tri
T4P KCell,1.006051
Onset Slope,63.26126 mW/°C
[Direct Cp Calibration]
Date Applied,11/30/2022 11:04:51 AM
Description,From -79.983 °C to 298.409 °C at 10.000°C/min
Gas Type,Nitrogen
Pan Type,Tzero Aluminum Hermetic
Source Files 1,C:\Users\yargerlab\Desktop\DSC Data\General\Sapphire_Heat_Capacity_11_30_22.tri
[Rev Cp Calibration]
Date Applied,11/30/2022 1:58:51 PM
Description,From -79.996 °C to 292.812 °C at 3.000°C/min
Gas Type,Nitrogen
Pan Type,Tzero Aluminum Hermetic
Source Files 1,C:\Users\yargerlab\Desktop\DSC Data\General\Sapphire_MDSC_Calibration_11_30_22.tri
[step]
Ramp 10.00 °C/min to 230.00 °C
Time,Temperature,Heat Flow (Normalized)
min,°C,W/g
0.00,-59.80,-0.009
0.02,-59.81,-0.008
0.04,-59.81,-0.008
0.06,-59.79,-0.007
0.08,-59.75,-0.006
0.10,-59.69,-0.004
0.12,-59.60,0.000
0.14,-59.48,0.005
0.16,-59.34,0.011
0.18,-59.19,0.017
0.20,-59.02,0.023
0.22,-58.85,0.027
0.24,-58.67,0.031
0.26,-58.49,0.034
0.28,-58.30,0.037
0.30,-58.12,0.039
0.32,-57.93,0.040
0.34,-57.74,0.042
0.36,-57.54,0.043
0.38,-57.35,0.043
0.40,-57.16,0.044
0.42,-56.97,0.044
0.44,-56.77,0.045
0.46,-56.58,0.045
0.48,-56.38,0.045
0.50,-56.18,0.045
0.52,-55.99,0.046
0.54,-55.79,0.046
0.56,-55.59,0.046
0.58,-55.40,0.046
0.60,-55.20,0.046
0.62,-55.00,0.046
0.64,-54.81,0.046
0.66,-54.61,0.046
0.68,-54.41,0.047
0.70,-54.22,0.047
0.72,-54.02,0.047
0.74,-53.82,0.047
0.76,-53.62,0.047
0.78,-53.42,0.047
0.80,-53.23,0.047
0.82,-53.03,0.047
0.84,-52.83,0.047
0.86,-52.63,0.047
0.88,-52.43,0.047
0.90,-52.24,0.047
0.92,-52.04,0.047
0.94,-51.84,0.048
0.96,-51.64,0.048
0.98,-51.44,0.048
1.00,-51.24,0.048
1.02,-51.04,0.048
1.04,-50.84,0.048
1.06,-50.64,0.048
1.08,-50.45,0.048
1.10,-50.25,0.048
1.12,-50.05,0.048
1.14,-49.85,0.048
1.16,-49.65,0.048
1.18,-49.45,0.048
1.20,-49.25,0.048
1.22,-49.05,0.048
1.24,-48.85,0.048
1.26,-48.65,0.048
1.28,-48.45,0.049
1.30,-48.25,0.049
1.32,-48.05,0.049
1.34,-47.85,0.049
1.36,-47.65,0.049
1.38,-47.45,0.049
1.40,-47.25,0.049
1.42,-47.05,0.049
1.44,-46.85,0.049
1.46,-46.65,0.049
1.48,-46.45,0.049
1.50,-46.25,0.049
1.52,-46.05,0.049
1.54,-45.85,0.049
1.56,-45.65,0.049
1.58,-45.45,0.049
1.60,-45.25,0.049
1.62,-45.05,0.049
1.64,-44.85,0.049
1.66,-44.65,0.049
1.68,-44.45,0.049
1.70,-44.25,0.049
1.72,-44.05,0.050
1.74,-43.85,0.050
1.76,-43.65,0.050
1.78,-43.45,0.050
1.80,-43.25,0.050
1.82,-43.05,0.050
1.84,-42.85,0.050
1.86,-42.65,0.050
1.88,-42.45,0.050
1.90,-42.25,0.050
1.92,-42.05,0.050
1.94,-41.85,0.050
1.96,-41.65,0.050
1.98,-41.45,0.050
2.00,-41.25,0.050
2.02,-41.05,0.050
2.04,-40.85,0.050
2.06,-40.65,0.050
2.08,-40.45,0.050
2.10,-40.25,0.050
2.12,-40.05,0.050
2.14,-39.85,0.050
2.16,-39.65,0.050
2.18,-39.45,0.050
2.20,-39.25,0.050
2.22,-39.05,0.050
2.24,-38.85,0.050
2.26,-38.65,0.050
2.28,-38.45,0.050
2.30,-38.25,0.051
2.32,-38.05,0.051
2.34,-37.85,0.051
2.36,-37.65,0.051
2.38,-37.45,0.051
2.40,-37.25,0.051
2.42,-37.05,0.051
2.44,-36.85,0.051
2.46,-36.65,0.051
2.48,-36.45,0.051
2.50,-36.25,0.051
2.52,-36.05,0.051
2.54,-35.85,0.051
2.56,-35.65,0.051
2.58,-35.45,0.051
2.60,-35.25,0.051
2.62,-35.05,0.051
2.64,-34.85,0.051
2.66,-34.64,0.051
2.68,-34.45,0.051
2.70,-34.24,0.051
2.72,-34.04,0.051
2.74,-33.84,0.051
2.76,-33.65,0.051
2.78,-33.44,0.051
2.80,-33.24,0.051
2.82,-33.04,0.051
2.84,-32.84,0.051
2.86,-32.64,0.051
2.88,-32.44,0.051
2.90,-32.24,0.051
2.92,-32.04,0.052
2.94,-31.84,0.052
2.96,-31.64,0.052
2.98,-31.44,0.052
3.00,-31.24,0.052
3.02,-31.04,0.052
3.04,-30.84,0.052
3.06,-30.64,0.052
3.08,-30.44,0.052
3.10,-30.24,0.052
3.12,-30.04,0.052
3.14,-29.84,0.052
3.16,-29.64,0.052
3.18,-29.44,0.052
3.20,-29.24,0.052
3.22,-29.04,0.052
3.24,-28.84,0.052
3.26,-28.64,0.052
3.28,-28.44,0.052
3.30,-28.24,0.052
3.32,-28.04,0.052
3.34,-27.84,0.052
3.36,-27.64,0.052
3.38,-27.44,0.052
3.40,-27.24,0.052
3.42,-27.04,0.052
3.44,-26.84,0.052
3.46,-26.64,0.052
3.48,-26.44,0.053
3.50,-26.24,0.053
3.52,-26.04,0.053
3.54,-25.84,0.053
3.56,-25.64,0.053
3.58,-25.44,0.053
3.60,-25.24,0.053
3.62,-25.03,0.053
3.64,-24.83,0.053
3.66,-24.64,0.053
3.68,-24.43,0.053
3.70,-24.24,0.053
3.72,-24.03,0.053
3.74,-23.83,0.053
3.76,-23.63,0.053
3.78,-23.43,0.053
3.80,-23.23,0.053
3.82,-23.03,0.053
3.84,-22.83,0.053
3.86,-22.63,0.053
3.88,-22.43,0.053
3.90,-22.23,0.053
3.92,-22.03,0.053
3.94,-21.83,0.053
3.96,-21.63,0.053
3.98,-21.43,0.054
4.00,-21.23,0.054
4.02,-21.03,0.054
4.04,-20.83,0.054
4.06,-20.63,0.054
4.08,-20.43,0.054
4.10,-20.23,0.054
4.12,-20.03,0.054
4.14,-19.83,0.054
4.16,-19.63,0.054
4.18,-19.43,0.054
4.20,-19.23,0.054
4.22,-19.03,0.054
4.24,-18.83,0.054
4.26,-18.63,0.054
4.28,-18.43,0.054
4.30,-18.23,0.054
4.32,-18.03,0.054
4.34,-17.83,0.054
4.36,-17.63,0.054
4.38,-17.43,0.054
4.40,-17.23,0.054
4.42,-17.03,0.054
4.44,-16.83,0.054
4.46,-16.63,0.054
4.48,-16.43,0.055
4.50,-16.23,0.055
4.52,-16.03,0.055
4.54,-15.83,0.055
4.56,-15.63,0.055
4.58,-15.43,0.055
4.60,-15.23,0.055
4.62,-15.03,0.055
4.64,-14.83,0.055
4.66,-14.63,0.055
4.68,-14.43,0.055
4.70,-14.23,0.055
4.72,-14.02,0.055
4.74,-13.83,0.055
4.76,-13.62,0.055
4.78,-13.43,0.055
4.80,-13.22,0.055
4.82,-13.02,0.055
4.84,-12.82,0.055
4.86,-12.62,0.055
4.88,-12.42,0.055
4.90,-12.22,0.055
4.92,-12.02,0.055
4.94,-11.82,0.056
4.96,-11.62,0.056
4.98,-11.42,0.056
5.00,-11.22,0.056
5.02,-11.02,0.056
5.04,-10.82,0.056
5.06,-10.62,0.056
5.08,-10.42,0.056
5.10,-10.22,0.056
5.12,-10.02,0.056
5.14,-9.82,0.056
5.16,-9.62,0.056
5.18,-9.42,0.056
5.20,-9.22,0.056
5.22,-9.02,0.056
5.24,-8.82,0.056
5.26,-8.62,0.056
5.28,-8.42,0.056
5.30,-8.22,0.056
5.32,-8.02,0.056
5.34,-7.82,0.056
5.36,-7.62,0.057
5.38,-7.42,0.057
5.40,-7.22,0.057
5.42,-7.02,0.057
5.44,-6.82,0.057
5.46,-6.62,0.057
5.48,-6.42,0.057
5.50,-6.22,0.057
5.52,-6.02,0.057
5.54,-5.82,0.057
5.56,-5.62,0.057
5.58,-5.42,0.057
5.60,-5.22,0.057
5.62,-5.02,0.057
5.64,-4.82,0.057
5.66,-4.62,0.057
5.68,-4.42,0.057
5.70,-4.22,0.057
5.72,-4.02,0.057
5.74,-3.82,0.057
5.76,-3.62,0.057
5.78,-3.42,0.058
5.80,-3.22,0.058
5.82,-3.02,0.058
5.84,-2.82,0.058
5.86,-2.62,0.058
5.88,-2.42,0.058
5.90,-2.22,0.058
5.92,-2.02,0.058
5.94,-1.82,0.058
5.96,-1.62,0.058
5.98,-1.41,0.058
6.00,-1.21,0.058
6.02,-1.02,0.058
6.04,-0.82,0.058
6.06,-0.61,0.058
6.08,-0.41,0.058
6.10,-0.21,0.058
6.12,-0.01,0.058
6.14,0.19,0.058
6.16,0.39,0.059
6.18,0.59,0.059
6.20,0.79,0.059
6.22,0.99,0.059
6.24,1.19,0.059
6.26,1.39,0.059
6.28,1.59,0.059
6.30,1.79,0.059
6.32,1.99,0.059
6.34,2.19,0.059
6.36,2.39,0.059
6.38,2.59,0.059
6.40,2.79,0.059
6.42,2.99,0.059
6.44,3.19,0.059
6.46,3.39,0.059
6.48,3.59,0.059
6.50,3.79,0.059
6.52,3.99,0.059
6.54,4.19,0.060
6.56,4.39,0.060
6.58,4.59,0.060
6.60,4.79,0.060
6.62,4.99,0.060
6.64,5.19,0.060
6.66,5.39,0.060
6.68,5.59,0.060
6.70,5.79,0.060
6.72,5.99,0.060
6.74,6.19,0.060
6.76,6.39,0.060
6.78,6.59,0.060
6.80,6.79,0.060
6.82,6.99,0.060
6.84,7.19,0.060
6.86,7.39,0.060
6.88,7.59,0.061
6.90,7.79,0.061
6.92,7.99,0.061
6.94,8.19,0.061
6.96,8.39,0.061
6.98,8.59,0.061
7.00,8.79,0.061
7.02,8.99,0.061
7.04,9.19,0.061
7.06,9.39,0.061
7.08,9.59,0.061
7.10,9.79,0.061
7.12,9.99,0.061
7.14,10.19,0.061
7.16,10.39,0.061
7.18,10.59,0.061
7.20,10.79,0.062
7.22,10.99,0.062
7.24,11.19,0.062
7.26,11.39,0.062
7.28,11.59,0.062
7.30,11.79,0.062
7.32,11.99,0.062
7.34,12.19,0.062
7.36,12.39,0.062
7.38,12.59,0.062
7.40,12.79,0.062
7.42,12.99,0.062
7.44,13.19,0.062
7.46,13.39,0.062
7.48,13.59,0.062
7.50,13.79,0.063
7.52,13.99,0.063
7.54,14.19,0.063
7.56,14.40,0.063
7.58,14.59,0.063
7.60,14.80,0.063
7.62,15.00,0.063
7.64,15.20,0.063
7.66,15.40,0.063
7.68,15.60,0.063
7.70,15.80,0.063
7.72,16.00,0.063
7.74,16.20,0.063
7.76,16.40,0.063
7.78,16.60,0.063
7.80,16.80,0.064
7.82,17.00,0.064
7.84,17.20,0.064
7.86,17.40,0.064
7.88,17.60,0.064
7.90,17.80,0.064
7.92,18.00,0.064
7.94,18.20,0.064
7.96,18.40,0.064
7.98,18.60,0.064
8.00,18.80,0.064
8.02,19.00,0.064
8.04,19.20,0.064
8.06,19.40,0.064
8.08,19.60,0.065
8.10,19.80,0.065
8.12,20.00,0.065
8.14,20.20,0.065
8.16,20.40,0.065
8.18,20.60,0.065
8.20,20.80,0.065
8.22,21.00,0.065
8.24,21.20,0.065
8.26,21.40,0.065
8.28,21.60,0.065
8.30,21.80,0.065
8.32,22.00,0.065
8.34,22.20,0.066
8.36,22.40,0.066
8.38,22.60,0.066
8.40,22.80,0.066
8.42,23.00,0.066
8.44,23.20,0.066
8.46,23.40,0.066
8.48,23.59,0.066
8.50,23.80,0.066
8.52,24.00,0.066
8.54,24.20,0.066
8.56,24.40,0.066
8.58,24.60,0.067
8.60,24.79,0.067
8.62,25.00,0.067
8.64,25.20,0.067
8.66,25.40,0.067
8.68,25.60,0.067
8.70,25.80,0.067
8.72,26.00,0.067
8.74,26.20,0.067
8.76,26.40,0.067
8.78,26.60,0.068
8.80,26.80,0.068
8.82,27.00,0.068
8.84,27.20,0.068
8.86,27.40,0.068
8.88,27.60,0.068
8.90,27.80,0.068
8.92,28.00,0.068
8.94,28.20,0.068
8.96,28.40,0.068
8.98,28.60,0.068
9.00,28.80,0.069
9.02,29.00,0.069
9.04,29.20,0.069
9.06,29.40,0.069
9.08,29.60,0.069
9.10,29.80,0.069
9.12,30.00,0.069
9.14,30.20,0.069
9.16,30.40,0.069
9.18,30.60,0.070
9.20,30.80,0.070
9.22,31.00,0.070
9.24,31.20,0.070
9.26,31.40,0.070
9.28,31.60,0.070
9.30,31.80,0.070
9.32,32.00,0.070
9.34,32.20,0.070
9.36,32.40,0.071
9.38,32.60,0.071
9.40,32.80,0.071
9.42,33.00,0.071
9.44,33.20,0.071
9.46,33.40,0.072
9.48,33.60,0.072
9.50,33.80,0.072
9.52,34.00,0.072
9.54,34.20,0.072
9.56,34.40,0.072
9.58,34.60,0.072
9.60,34.80,0.072
9.62,35.00,0.072
9.64,35.20,0.073
9.66,35.40,0.073
9.68,35.60,0.073
9.70,35.80,0.073
9.72,36.00,0.073
9.74,36.20,0.073
9.76,36.40,0.073
9.78,36.60,0.074
9.80,36.80,0.074
9.82,37.00,0.074
9.84,37.20,0.074
9.86,37.40,0.074
9.88,37.60,0.075
9.90,37.80,0.075
9.92,38.00,0.075
9.94,38.20,0.075
9.96,38.40,0.076
9.98,38.60,0.076
10.00,38.79,0.076
10.02,38.99,0.076
10.04,39.19,0.077
10.06,39.39,0.077
10.08,39.59,0.077
10.10,39.79,0.077
10.12,39.99,0.078
10.14,40.19,0.078
10.16,40.39,0.078
10.18,40.59,0.079
10.20,40.79,0.079
10.22,40.99,0.080
10.24,41.19,0.080
10.26,41.39,0.080
10.28,41.59,0.081
10.30,41.79,0.081
10.32,41.99,0.081
10.34,42.19,0.082
10.36,42.39,0.082
10.38,42.59,0.083
10.40,42.79,0.083
10.42,42.99,0.084
10.44,43.19,0.084
10.46,43.38,0.085
10.48,43.58,0.085
10.50,43.78,0.086
10.52,43.98,0.086
10.54,44.18,0.087
10.56,44.38,0.087
10.58,44.58,0.088
10.60,44.78,0.088
10.62,44.98,0.089
10.64,45.18,0.089
10.66,45.38,0.089
10.68,45.58,0.090
10.70,45.77,0.090
10.72,45.98,0.090
10.74,46.17,0.090
10.76,46.37,0.090
10.78,46.58,0.090
10.80,46.77,0.090
10.82,46.97,0.090
10.84,47.18,0.090
10.86,47.38,0.090
10.88,47.58,0.090
10.90,47.78,0.090
10.92,47.98,0.090
10.94,48.18,0.090
10.96,48.38,0.090
10.98,48.58,0.090
11.00,48.78,0.090
11.02,48.98,0.090
11.04,49.18,0.090
11.06,49.38,0.089
11.08,49.58,0.089
11.10,49.78,0.089
11.12,49.98,0.089
11.14,50.18,0.089
11.16,50.38,0.089
11.18,50.59,0.089
11.20,50.78,0.089
11.22,50.98,0.089
11.24,51.18,0.089
11.26,51.39,0.089
11.28,51.58,0.089
11.30,51.78,0.089
11.32,51.98,0.090
11.34,52.18,0.090
11.36,52.38,0.091
11.38,52.58,0.091
11.40,52.78,0.091
11.42,52.98,0.092
11.44,53.18,0.092
11.46,53.38,0.092
11.48,53.58,0.093
11.50,53.78,0.093
11.52,53.98,0.094
11.54,54.18,0.094
11.56,54.38,0.095
11.58,54.58,0.095
11.60,54.78,0.096
11.62,54.97,0.096
11.64,55.17,0.097
11.66,55.37,0.097
11.68,55.57,0.098
11.70,55.77,0.098
11.72,55.97,0.099
11.74,56.17,0.099
11.76,56.37,0.099
11.78,56.57,0.100
11.80,56.77,0.100
11.82,56.97,0.101
11.84,57.17,0.101
11.86,57.37,0.102
11.88,57.57,0.102
11.90,57.77,0.103
11.92,57.96,0.103
11.94,58.16,0.104
11.96,58.36,0.104
11.98,58.56,0.104
12.00,58.76,0.105
12.02,58.96,0.105
12.04,59.16,0.106
12.06,59.36,0.106
12.08,59.56,0.107
12.10,59.76,0.107
12.12,59.96,0.108
12.14,60.15,0.109
12.16,60.35,0.109
12.18,60.55,0.110
12.20,60.75,0.111
12.22,60.95,0.111
12.24,61.15,0.112
12.26,61.35,0.112
12.28,61.55,0.113
12.30,61.75,0.114
12.32,61.95,0.115
12.34,62.14,0.115
12.36,62.34,0.116
12.38,62.54,0.117
12.40,62.74,0.118
12.42,62.94,0.118
12.44,63.14,0.119
12.46,63.34,0.120
12.48,63.54,0.121
12.50,63.73,0.122
12.52,63.93,0.123
12.54,64.13,0.124
12.56,64.33,0.125
12.58,64.53,0.126
12.60,64.72,0.127
12.62,64.92,0.128
12.64,65.12,0.129
12.66,65.32,0.131
12.68,65.51,0.132
12.70,65.71,0.133
12.72,65.91,0.134
12.74,66.11,0.135
12.76,66.31,0.137
12.78,66.50,0.138
12.80,66.70,0.139
12.82,66.90,0.141
12.84,67.10,0.142
12.86,67.29,0.144
12.88,67.49,0.146
12.90,67.69,0.147
12.92,67.88,0.149
12.94,68.08,0.151
12.96,68.28,0.152
12.98,68.47,0.154
13.00,68.67,0.156
13.02,68.86,0.158
13.04,69.06,0.160
13.06,69.26,0.162
13.08,69.45,0.164
13.10,69.65,0.166
13.12,69.85,0.167
13.14,70.05,0.169
13.16,70.24,0.170
13.18,70.44,0.171
13.20,70.64,0.171
13.22,70.84,0.172
13.24,71.04,0.171
13.26,71.23,0.171
13.28,71.44,0.169
13.30,71.64,0.166
13.32,71.84,0.163
13.34,72.05,0.160
13.36,72.26,0.156
13.38,72.46,0.151
13.40,72.67,0.147
13.42,72.88,0.142
13.44,73.09,0.137
13.46,73.30,0.132
13.48,73.51,0.127
13.50,73.72,0.123
13.52,73.93,0.119
13.54,74.14,0.116
13.56,74.35,0.114
13.58,74.56,0.112
13.60,74.76,0.111
13.62,74.97,0.110
13.64,75.17,0.109
13.66,75.37,0.108
13.68,75.57,0.108
13.70,75.77,0.108
13.72,75.98,0.107
13.74,76.18,0.107
13.76,76.38,0.107
13.78,76.58,0.107
13.80,76.78,0.107
13.82,76.98,0.107
13.84,77.18,0.107
13.86,77.38,0.108
13.88,77.58,0.108
13.90,77.78,0.108
13.92,77.98,0.108
13.94,78.17,0.109
13.96,78.37,0.109
13.98,78.57,0.109
14.00,78.77,0.110
14.02,78.97,0.110
14.04,79.17,0.111
14.06,79.37,0.111
14.08,79.57,0.112
14.10,79.77,0.112
14.12,79.97,0.113
14.14,80.17,0.113
14.16,80.37,0.114
14.18,80.57,0.114
14.20,80.77,0.115
14.22,80.97,0.115
14.24,81.16,0.116
14.26,81.36,0.117
14.28,81.56,0.117
14.30,81.76,0.118
14.32,81.96,0.118
14.34,82.16,0.119
14.36,82.36,0.120
14.38,82.56,0.120
14.40,82.76,0.121
14.42,82.96,0.121
14.44,83.16,0.122
14.46,83.36,0.123
14.48,83.55,0.123
14.50,83.75,0.124
14.52,83.95,0.124
14.54,84.15,0.125
14.56,84.35,0.125
14.58,84.55,0.126
14.60,84.75,0.126
14.62,84.95,0.127
14.64,85.15,0.128
14.66,85.35,0.128
14.68,85.54,0.129
14.70,85.74,0.130
14.72,85.94,0.130
14.74,86.14,0.131
14.76,86.34,0.131
14.78,86.54,0.132
14.80,86.74,0.132
14.82,86.94,0.133
14.84,87.14,0.134
14.86,87.33,0.134
14.88,87.53,0.135
14.90,87.73,0.136
14.92,87.93,0.136
14.94,88.13,0.137
14.96,88.33,0.137
14.98,88.53,0.138
15.00,88.73,0.139
15.02,88.93,0.140
15.04,89.13,0.140
15.06,89.33,0.141
15.08,89.52,0.142
15.10,89.72,0.142
15.12,89.92,0.143
15.14,90.12,0.143
15.16,90.32,0.144
15.18,90.52,0.145
15.20,90.72,0.145
15.22,90.92,0.146
15.24,91.12,0.147
15.26,91.31,0.147
15.28,91.51,0.148
15.30,91.71,0.149
15.32,91.91,0.149
15.34,92.11,0.150
15.36,92.31,0.151
15.38,92.51,0.151
15.40,92.71,0.152
15.42,92.91,0.152
15.44,93.10,0.153
15.46,93.30,0.154
15.48,93.50,0.154
15.50,93.70,0.155
15.52,93.90,0.156
15.54,94.10,0.157
15.56,94.30,0.157
15.58,94.50,0.158
15.60,94.69,0.159
15.62,94.89,0.159
15.64,95.09,0.160
15.66,95.29,0.161
15.68,95.49,0.161
15.70,95.69,0.162
15.72,95.89,0.163
15.74,96.09,0.163
15.76,96.29,0.164
15.78,96.48,0.164
15.80,96.68,0.165
15.82,96.88,0.166
15.84,97.08,0.166
15.86,97.28,0.167
15.88,97.48,0.168
15.90,97.68,0.168
15.92,97.88,0.169
15.94,98.08,0.169
15.96,98.28,0.170
15.98,98.47,0.170
16.00,98.67,0.171
16.02,98.87,0.171
16.04,99.07,0.172
16.06,99.27,0.172
16.08,99.47,0.173
16.10,99.67,0.173
16.12,99.87,0.174
16.14,100.07,0.174
16.16,100.27,0.175
16.18,100.47,0.175
16.20,100.67,0.176
16.22,100.86,0.176
16.24,101.06,0.177
16.26,101.26,0.177
16.28,101.46,0.177
16.30,101.66,0.178
16.32,101.86,0.178
16.34,102.06,0.178
16.36,102.26,0.178
16.38,102.46,0.178
16.40,102.66,0.178
16.42,102.86,0.178
16.44,103.06,0.178
16.46,103.26,0.178
16.48,103.46,0.179
16.50,103.66,0.179
16.52,103.86,0.179
16.54,104.06,0.179
16.56,104.26,0.179
16.58,104.46,0.178
16.60,104.67,0.178
16.62,104.86,0.178
16.64,105.07,0.177
16.66,105.27,0.176
16.68,105.47,0.175
16.70,105.67,0.175
16.72,105.87,0.174
16.74,106.07,0.173
16.76,106.27,0.173
16.78,106.48,0.172
16.80,106.68,0.171
16.82,106.88,0.170
16.84,107.08,0.168
16.86,107.29,0.167
16.88,107.49,0.166
16.90,107.69,0.165
16.92,107.89,0.164
16.94,108.10,0.162
16.96,108.30,0.162
16.98,108.50,0.161
17.00,108.70,0.159
17.02,108.91,0.157
17.04,109.11,0.155
17.06,109.31,0.154
17.08,109.52,0.152
17.10,109.72,0.150
17.12,109.93,0.149
17.14,110.13,0.147
17.16,110.33,0.146
17.18,110.54,0.144
17.20,110.74,0.143
17.22,110.94,0.141
17.24,111.15,0.140
17.26,111.35,0.138
17.28,111.55,0.137
17.30,111.76,0.135
17.32,111.96,0.134
17.34,112.16,0.133
17.36,112.36,0.132
17.38,112.57,0.131
17.40,112.77,0.130
17.42,112.97,0.129
17.44,113.18,0.128
17.46,113.38,0.127
17.48,113.58,0.126
17.50,113.78,0.125
17.52,113.99,0.123
17.54,114.19,0.122
17.56,114.39,0.121
17.58,114.59,0.121
17.60,114.79,0.120
17.62,115.00,0.119
17.64,115.20,0.118
17.66,115.40,0.117
17.68,115.60,0.117
17.70,115.80,0.116
17.72,116.01,0.115
17.74,116.21,0.115
17.76,116.41,0.114
17.78,116.61,0.114
17.80,116.81,0.113
17.82,117.01,0.113
17.84,117.21,0.112
17.86,117.42,0.112
17.88,117.62,0.111
17.90,117.82,0.110
17.92,118.02,0.110
17.94,118.22,0.109
17.96,118.42,0.109
17.98,118.62,0.108
18.00,118.83,0.108
18.02,119.03,0.108
18.04,119.23,0.107
18.06,119.43,0.107
18.08,119.63,0.107
18.10,119.83,0.106
18.12,120.03,0.106
18.14,120.23,0.105
18.16,120.43,0.105
18.18,120.63,0.104
18.20,120.84,0.104
18.22,121.04,0.103
18.24,121.24,0.103
18.26,121.44,0.103
18.28,121.64,0.102
18.30,121.84,0.101
18.32,122.04,0.101
18.34,122.24,0.101
18.36,122.44,0.101
18.38,122.65,0.100
18.40,122.85,0.100
18.42,123.05,0.100
18.44,123.25,0.100
18.46,123.45,0.100
18.48,123.65,0.099
18.50,123.85,0.099
18.52,124.05,0.099
18.54,124.25,0.099
18.56,124.45,0.098
18.58,124.65,0.098
18.60,124.85,0.098
18.62,125.05,0.097
18.64,125.26,0.097
18.66,125.46,0.097
18.68,125.66,0.097
18.70,125.86,0.097
18.72,126.06,0.097
18.74,126.21,0.287
18.76,125.98,0.568
18.78,126.17,0.300
18.80,126.45,0.234
18.82,126.73,0.203
18.84,126.99,0.185
18.86,127.23,0.172
18.88,127.48,0.156
18.90,127.71,0.149
18.92,127.94,0.137
18.94,128.16,0.129
18.96,128.38,0.126
18.98,128.40,1.028
19.00,126.55,2.437
19.02,126.09,1.889
19.04,126.22,1.598
19.06,126.54,1.420
19.08,126.93,1.287
19.10,127.34,1.174
19.12,127.75,1.075
19.14,128.15,0.990
19.16,128.53,0.913
19.18,128.90,0.843
19.20,129.25,0.781
19.22,129.59,0.725
19.24,129.91,0.677
19.26,130.22,0.634
19.28,130.52,0.595
19.30,130.80,0.560
19.32,131.08,0.529
19.34,131.35,0.501
19.36,131.61,0.475
19.38,131.87,0.453
19.40,132.12,0.432
19.42,132.36,0.413
19.44,132.61,0.396
19.46,132.84,0.381
19.48,133.08,0.366
19.50,133.31,0.353
19.52,133.54,0.341
19.54,133.76,0.330
19.56,133.99,0.320
19.58,134.21,0.310
19.60,134.43,0.301
19.62,134.65,0.293
19.64,134.87,0.286
19.66,135.08,0.279
19.68,135.30,0.273
19.70,135.51,0.266
19.72,135.72,0.260
19.74,135.94,0.255
19.76,136.15,0.249
19.78,136.36,0.244
19.80,136.57,0.239
19.82,136.78,0.234
19.84,136.99,0.229
19.86,137.20,0.224
19.88,137.41,0.219
19.90,137.62,0.215
19.92,137.83,0.212
19.94,138.04,0.208
19.96,138.25,0.205
19.98,138.45,0.202
20.00,138.66,0.199
20.02,138.87,0.196
20.04,139.07,0.193
20.06,139.28,0.191
20.08,139.48,0.188
20.10,139.69,0.186
20.12,139.89,0.183
20.14,140.10,0.181
20.16,140.30,0.179
20.18,140.51,0.177
20.20,140.71,0.175
20.22,140.92,0.173
20.24,141.12,0.171
20.26,141.32,0.169
20.28,141.53,0.167
20.30,141.73,0.166
20.32,141.94,0.164
20.34,142.14,0.162
20.36,142.34,0.161
20.38,142.55,0.159
20.40,142.75,0.158
20.42,142.95,0.156
20.44,143.16,0.155
20.46,143.36,0.153
20.48,143.56,0.152
20.50,143.76,0.150
20.52,143.97,0.149
20.54,144.17,0.148
20.56,144.37,0.146
20.58,144.58,0.145
20.60,144.78,0.144
20.62,144.98,0.143
20.64,145.19,0.141
20.66,145.39,0.140
20.68,145.59,0.139
20.70,145.79,0.138
20.72,146.00,0.137
20.74,146.20,0.135
20.76,146.40,0.134
20.78,146.60,0.133
20.80,146.81,0.132
20.82,147.01,0.131
20.84,147.21,0.130
20.86,147.41,0.129
20.88,147.61,0.128
20.90,147.82,0.127
20.92,148.02,0.126
20.94,148.22,0.125
20.96,148.42,0.124
20.98,148.62,0.123
21.00,148.83,0.122
21.02,149.03,0.121
21.04,149.23,0.121
21.06,149.43,0.121
21.08,149.63,0.121
21.10,149.83,0.121
21.12,150.03,0.120
21.14,150.24,0.120
21.16,150.44,0.120
21.18,150.64,0.119
21.20,150.84,0.118
21.22,151.04,0.117
21.24,151.24,0.117
21.26,151.45,0.116
21.28,151.65,0.115
21.30,151.85,0.115
21.32,152.05,0.114
21.34,152.25,0.113
21.36,152.45,0.113
21.38,152.65,0.112
21.40,152.85,0.111
21.42,153.06,0.111
21.44,153.26,0.110
21.46,153.46,0.110
21.48,153.66,0.109
21.50,153.86,0.108
21.52,154.06,0.108
21.54,154.26,0.107
21.56,154.47,0.107
21.58,154.67,0.106
21.60,154.87,0.106
21.62,155.07,0.105
21.64,155.27,0.105
21.66,155.47,0.104
21.68,155.67,0.104
21.70,155.87,0.103
21.72,156.08,0.103
21.74,156.28,0.103
21.76,156.48,0.102
21.78,156.68,0.102
21.80,156.88,0.101
21.82,157.08,0.101
21.84,157.28,0.101
21.86,157.48,0.100
21.88,157.68,0.100
21.90,157.88,0.099
21.92,158.09,0.099
21.94,158.29,0.098
21.96,158.49,0.098
21.98,158.69,0.098
22.00,158.89,0.097
22.02,159.09,0.097
22.04,159.29,0.096
22.06,159.49,0.096
22.08,159.69,0.096
22.10,159.89,0.095
22.12,160.09,0.095
22.14,160.30,0.095
22.16,160.50,0.094
22.18,160.70,0.094
22.20,160.90,0.094
22.22,161.10,0.093
22.24,161.30,0.093
22.26,161.50,0.093
22.28,161.70,0.093
22.30,161.90,0.092
22.32,162.10,0.092
22.34,162.30,0.092
22.36,162.50,0.092
22.38,162.70,0.092
22.40,162.90,0.091
22.42,163.10,0.091
22.44,163.30,0.091
22.46,163.50,0.091
22.48,163.71,0.091
22.50,163.91,0.091
22.52,164.11,0.090
22.54,164.31,0.090
22.56,164.51,0.090
22.58,164.71,0.090
22.60,164.91,0.090
22.62,165.11,0.090
22.64,165.31,0.089
22.66,165.51,0.089
22.68,165.71,0.089
22.70,165.91,0.089
22.72,166.11,0.088
22.74,166.31,0.088
22.76,166.51,0.088
22.78,166.71,0.088
22.80,166.91,0.088
22.82,167.11,0.088
22.84,167.32,0.088
22.86,167.52,0.087
22.88,167.72,0.087
22.90,167.92,0.087
22.92,168.12,0.087
22.94,168.32,0.087
22.96,168.52,0.087
22.98,168.72,0.087
23.00,168.92,0.087
23.02,169.12,0.087
23.04,169.32,0.086
23.06,169.52,0.086
23.08,169.72,0.086
23.10,169.92,0.086
23.12,170.12,0.086
23.14,170.32,0.086
23.16,170.52,0.086
23.18,170.72,0.086
23.20,170.92,0.086
23.22,171.12,0.086
23.24,171.32,0.085
23.26,171.52,0.085
23.28,171.73,0.085
23.30,171.93,0.085
23.32,172.13,0.085
23.34,172.33,0.085
23.36,172.53,0.085
23.38,172.73,0.085
23.40,172.93,0.085
23.42,173.13,0.085
23.44,173.33,0.085
23.46,173.53,0.085
23.48,173.73,0.084
23.50,173.93,0.084
23.52,174.13,0.084
23.54,174.33,0.084
23.56,174.53,0.084
23.58,174.73,0.084
23.60,174.93,0.084
23.62,175.13,0.084
23.64,175.33,0.084
23.66,175.53,0.084
23.68,175.73,0.084
23.70,175.93,0.084
23.72,176.13,0.084
23.74,176.33,0.084
23.76,176.53,0.084
23.78,176.73,0.084
23.80,176.93,0.084
23.82,177.13,0.084
23.84,177.33,0.084
23.86,177.53,0.083
23.88,177.73,0.083
23.90,177.93,0.083
23.92,178.13,0.083
23.94,178.33,0.083
23.96,178.53,0.083
23.98,178.73,0.083
24.00,178.93,0.083
24.02,179.13,0.083
24.04,179.33,0.083
24.06,179.53,0.083
24.08,179.74,0.083
24.10,179.93,0.083
24.12,180.13,0.083
24.14,180.33,0.083
24.16,180.53,0.083
24.18,180.74,0.083
24.20,180.94,0.083
24.22,181.14,0.083
24.24,181.34,0.083
24.26,181.54,0.083
24.28,181.74,0.083
24.30,181.94,0.083
24.32,182.14,0.083
24.34,182.34,0.083
24.36,182.54,0.083
24.38,182.74,0.083
24.40,182.94,0.083
24.42,183.14,0.083
24.44,183.34,0.083
24.46,183.54,0.083
24.48,183.74,0.083
24.50,183.94,0.083
24.52,184.14,0.083
24.54,184.34,0.083
24.56,184.54,0.083
24.58,184.74,0.083
24.60,184.94,0.083
24.62,185.14,0.083
24.64,185.34,0.083
24.66,185.54,0.083
24.68,185.74,0.083
24.70,185.94,0.083
24.72,186.14,0.083
24.74,186.34,0.083
24.76,186.54,0.083
24.78,186.74,0.083
24.80,186.94,0.083
24.82,187.14,0.083
24.84,187.34,0.083
24.86,187.54,0.083
24.88,187.74,0.083
24.90,187.94,0.083
24.92,188.14,0.083
24.94,188.34,0.083
24.96,188.54,0.083
24.98,188.74,0.083
25.00,188.94,0.083
25.02,189.14,0.083
25.04,189.34,0.083
25.06,189.54,0.083
25.08,189.74,0.083
25.10,189.94,0.083
25.12,190.14,0.084
25.14,190.34,0.084
25.16,190.54,0.084
25.18,190.74,0.084
25.20,190.94,0.084
25.22,191.14,0.084
25.24,191.34,0.084
25.26,191.54,0.084
25.28,191.74,0.084
25.30,191.95,0.084
25.32,192.15,0.084
25.34,192.34,0.084
25.36,192.55,0.084
25.38,192.75,0.084
25.40,192.95,0.084
25.42,193.15,0.084
25.44,193.35,0.084
25.46,193.55,0.084
25.48,193.75,0.084
25.50,193.95,0.084
25.52,194.15,0.084
25.54,194.34,0.084
25.56,194.55,0.084
25.58,194.75,0.084
25.60,194.95,0.084
25.62,195.15,0.084
25.64,195.35,0.084
25.66,195.55,0.084
25.68,195.75,0.084
25.70,195.95,0.084
25.72,196.15,0.084
25.74,196.35,0.084
25.76,196.55,0.084
25.78,196.75,0.084
25.80,196.95,0.084
25.82,197.15,0.084
25.84,197.35,0.084
25.86,197.55,0.084
25.88,197.75,0.084
25.90,197.95,0.084
25.92,198.15,0.084
25.94,198.35,0.085
25.96,198.55,0.085
25.98,198.75,0.085
26.00,198.95,0.085
26.02,199.15,0.085
26.04,199.35,0.085
26.06,199.55,0.085
26.08,199.75,0.085
26.10,199.95,0.085
26.12,200.15,0.085
26.14,200.35,0.085
26.16,200.55,0.085
26.18,200.75,0.085
26.20,200.95,0.085
26.22,201.15,0.085
26.24,201.35,0.085
26.26,201.55,0.085
26.28,201.75,0.085
26.30,201.95,0.085
26.32,202.15,0.085
26.34,202.35,0.085
26.36,202.55,0.085
26.38,202.75,0.085
26.40,202.95,0.085
26.42,203.15,0.085
26.44,203.35,0.085
26.46,203.55,0.085
26.48,203.75,0.085
26.50,203.95,0.085
26.52,204.15,0.085
26.54,204.35,0.085
26.56,204.55,0.085
26.58,204.75,0.085
26.60,204.95,0.085
26.62,205.15,0.085
26.64,205.35,0.085
26.66,205.55,0.085
26.68,205.75,0.085
26.70,205.95,0.085
26.72,206.15,0.085
26.74,206.35,0.085
26.76,206.55,0.085
26.78,206.75,0.085
26.80,206.95,0.085
26.82,207.15,0.085
26.84,207.35,0.085
26.86,207.55,0.085
26.88,207.75,0.085
26.90,207.95,0.085
26.92,208.16,0.085
26.94,208.35,0.085
26.96,208.56,0.085
26.98,208.76,0.085
27.00,208.96,0.085
27.02,209.15,0.085
27.04,209.36,0.085
27.06,209.56,0.085
27.08,209.76,0.085
27.10,209.96,0.085
27.12,210.16,0.085
27.14,210.36,0.085
27.16,210.56,0.085
27.18,210.76,0.085
27.20,210.96,0.085
27.22,211.16,0.085
27.24,211.36,0.085
27.26,211.56,0.085
27.28,211.76,0.085
27.30,211.96,0.085
27.32,212.16,0.085
27.34,212.36,0.085
27.36,212.56,0.085
27.38,212.76,0.085
27.40,212.96,0.085
27.42,213.16,0.085
27.44,213.36,0.085
27.46,213.56,0.085
27.48,213.76,0.085
27.50,213.96,0.085
27.52,214.16,0.085
27.54,214.36,0.085
27.56,214.56,0.085
27.58,214.76,0.085
27.60,214.96,0.085
27.62,215.16,0.085
27.64,215.36,0.085
27.66,215.56,0.085
27.68,215.76,0.085
27.70,215.96,0.086
27.72,216.16,0.086
27.74,216.36,0.086
27.76,216.56,0.086
27.78,216.76,0.086
27.80,216.96,0.086
27.82,217.16,0.086
27.84,217.36,0.086
27.86,217.56,0.086
27.88,217.76,0.086
27.90,217.96,0.086
27.92,218.16,0.086
27.94,218.36,0.086
27.96,218.56,0.086
27.98,218.76,0.086
28.00,218.96,0.086
28.02,219.16,0.086
28.04,219.36,0.086
28.06,219.56,0.086
28.08,219.76,0.086
28.10,219.96,0.086
28.12,220.16,0.086
28.14,220.36,0.086
28.16,220.56,0.086
28.18,220.76,0.086
28.20,220.96,0.086
28.22,221.16,0.086
28.24,221.36,0.086
28.26,221.56,0.086
28.28,221.76,0.086
28.30,221.96,0.086
28.32,222.16,0.086
28.34,222.36,0.086
28.36,222.56,0.086
28.38,222.76,0.086
28.40,222.96,0.086
28.42,223.16,0.086
28.44,223.37,0.086
28.46,223.57,0.086
28.48,223.77,0.086
28.50,223.97,0.086
28.52,224.17,0.086
28.54,224.37,0.086
28.56,224.57,0.086
28.58,224.77,0.086
28.60,224.97,0.086
28.62,225.17,0.086
28.64,225.37,0.086
28.66,225.57,0.086
28.68,225.77,0.086
28.70,225.97,0.086
28.72,226.17,0.086
28.74,226.37,0.086
28.76,226.57,0.086
28.78,226.77,0.086
28.80,226.97,0.086
28.82,227.17,0.086
28.84,227.37,0.086
28.86,227.57,0.087
28.88,227.77,0.087
28.90,227.97,0.087
28.92,228.17,0.087
28.94,228.37,
28.96,228.57,
28.98,228.77,
28.99,,

[step]
Ramp 10.00 °C/min to -60.00 °C
Time,Temperature,Heat Flow (Normalized)
min,°C,W/g
30.99,230.15,0.004
31.01,230.15,0.004
31.03,230.15,0.004
31.05,230.13,0.004
31.07,230.09,0.002
31.09,230.03,-0.004
31.11,229.94,-0.013
31.13,229.82,-0.024
31.15,229.68,-0.036
31.17,229.52,-0.046
31.19,229.35,-0.055
31.21,229.18,-0.061
31.23,228.99,-0.066
31.25,228.81,-0.069
31.27,228.62,-0.072
31.29,228.43,-0.073
31.31,228.23,-0.075
31.33,228.04,-0.075
31.35,227.84,-0.076
31.37,227.65,-0.077
31.39,227.45,-0.077
31.41,227.25,-0.078
31.43,227.06,-0.078
31.45,226.86,-0.079
31.47,226.66,-0.079
31.49,226.46,-0.079
31.51,226.27,-0.079
31.53,226.07,-0.079
31.55,225.87,-0.079
31.57,225.67,-0.079
31.59,225.47,-0.079
31.61,225.28,-0.080
31.63,225.08,-0.080
31.65,224.88,-0.080
31.67,224.68,-0.080
31.69,224.48,-0.080
31.71,224.28,-0.080
31.73,224.08,-0.080
31.75,223.88,-0.080
31.77,223.69,-0.080
31.79,223.49,-0.080
31.81,223.29,-0.080
31.83,223.09,-0.080
31.85,222.89,-0.080
31.87,222.69,-0.080
31.89,222.49,-0.080
31.91,222.29,-0.080
31.93,222.10,-0.081
31.95,221.90,-0.081
31.97,221.70,-0.081
31.99,221.50,-0.081
32.01,221.30,-0.081
32.03,221.10,-0.081
32.05,220.90,-0.081
32.07,220.70,-0.081
32.09,220.50,-0.081
32.11,220.30,-0.081
32.13,220.10,-0.081
32.15,219.90,-0.081
32.17,219.70,-0.081
32.19,219.50,-0.081
32.21,219.30,-0.081
32.23,219.11,-0.081
32.25,218.91,-0.081
32.27,218.71,-0.081
32.29,218.51,-0.081
32.31,218.31,-0.081
32.33,218.11,-0.081
32.35,217.91,-0.081
32.37,217.71,-0.081
32.39,217.51,-0.081
32.41,217.31,-0.081
32.43,217.11,-0.081
32.45,216.91,-0.081
32.47,216.71,-0.081
32.49,216.51,-0.081
32.51,216.31,-0.081
32.53,216.11,-0.081
32.55,215.91,-0.081
32.57,215.71,-0.081
32.59,215.51,-0.081
32.61,215.31,-0.081
32.63,215.11,-0.081
32.65,214.92,-0.081
32.67,214.72,-0.081
32.69,214.52,-0.081
32.71,214.32,-0.081
32.73,214.12,-0.081
32.75,213.92,-0.081
32.77,213.72,-0.081
32.79,213.52,-0.081
32.81,213.32,-0.081
32.83,213.12,-0.081
32.85,212.92,-0.081
32.87,212.72,-0.081
32.89,212.52,-0.081
32.91,212.32,-0.081
32.93,212.12,-0.081
32.95,211.92,-0.081
32.97,211.72,-0.081
32.99,211.52,-0.081
33.01,211.32,-0.081
33.03,211.12,-0.081
33.05,210.92,-0.081
33.07,210.72,-0.081
33.09,210.52,-0.081
33.11,210.32,-0.081
33.13,210.12,-0.081
33.15,209.92,-0.081
33.17,209.72,-0.081
33.19,209.52,-0.081
33.21,209.32,-0.081
33.23,209.12,-0.081
33.25,208.92,-0.081
33.27,208.72,-0.081
33.29,208.52,-0.081
33.31,208.32,-0.081
33.33,208.12,-0.081
33.35,207.92,-0.081
33.37,207.72,-0.081
33.39,207.52,-0.081
33.41,207.32,-0.081
33.43,207.12,-0.081
33.45,206.92,-0.081
33.47,206.72,-0.081
33.49,206.52,-0.081
33.51,206.32,-0.081
33.53,206.12,-0.081
33.55,205.92,-0.081
33.57,205.72,-0.081
33.59,205.52,-0.081
33.61,205.32,-0.081
33.63,205.12,-0.081
33.65,204.92,-0.081
33.67,204.72,-0.081
33.69,204.52,-0.081
33.71,204.32,-0.081
33.73,204.12,-0.081
33.75,203.92,-0.081
33.77,203.72,-0.081
33.79,203.52,-0.081
33.81,203.32,-0.081
33.83,203.12,-0.081
33.85,202.92,-0.081
33.87,202.72,-0.081
33.89,202.52,-0.081
33.91,202.32,-0.081
33.93,202.12,-0.081
33.95,201.92,-0.081
33.97,201.72,-0.081
33.99,201.52,-0.081
34.01,201.32,-0.081
34.03,201.12,-0.081
34.05,200.93,-0.081
34.07,200.73,-0.081
34.09,200.53,-0.081
34.11,200.33,-0.081
34.13,200.13,-0.081
34.15,199.93,-0.081
34.17,199.73,-0.081
34.19,199.53,-0.081
34.21,199.33,-0.081
34.23,199.13,-0.081
34.25,198.93,-0.081
34.27,198.73,-0.081
34.29,198.53,-0.081
34.31,198.33,-0.081
34.33,198.13,-0.081
34.35,197.93,-0.081
34.37,197.73,-0.081
34.39,197.53,-0.081
34.41,197.33,-0.081
34.43,197.13,-0.081
34.45,196.93,-0.081
34.47,196.73,-0.081
34.49,196.53,-0.081
34.51,196.33,-0.081
34.53,196.13,-0.081
34.55,195.93,-0.081
34.57,195.73,-0.081
34.59,195.53,-0.081
34.61,195.33,-0.081
34.63,195.13,-0.081
34.65,194.93,-0.081
34.67,194.73,-0.081
34.69,194.53,-0.081
34.71,194.33,-0.081
34.73,194.13,-0.081
34.75,193.93,-0.081
34.77,193.73,-0.081
34.79,193.53,-0.081
34.81,193.33,-0.081
34.83,193.13,-0.081
34.85,192.93,-0.081
34.87,192.73,-0.081
34.89,192.53,-0.081
34.91,192.33,-0.081
34.93,192.13,-0.081
34.95,191.93,-0.081
34.97,191.73,-0.081
34.99,191.53,-0.081
35.01,191.33,-0.081
35.03,191.13,-0.081
35.05,190.93,-0.081
35.07,190.73,-0.081
35.09,190.53,-0.081
35.11,190.33,-0.081
35.13,190.13,-0.081
35.15,189.93,-0.081
35.17,189.73,-0.081
35.19,189.53,-0.081
35.21,189.33,-0.081
35.23,189.13,-0.081
35.25,188.93,-0.081
35.27,188.73,-0.081
35.29,188.53,-0.081
35.31,188.33,-0.081
35.33,188.13,-0.081
35.35,187.93,-0.081
35.37,187.73,-0.081
35.39,187.53,-0.081
35.41,187.33,-0.081
35.43,187.13,-0.081
35.45,186.93,-0.081
35.47,186.73,-0.081
35.49,186.53,-0.081
35.51,186.33,-0.081
35.53,186.13,-0.081
35.55,185.93,-0.081
35.57,185.73,-0.081
35.59,185.53,-0.081
35.61,185.33,-0.081
35.63,185.13,-0.081
35.65,184.93,-0.081
35.67,184.73,-0.081
35.69,184.53,-0.081
35.71,184.33,-0.081
35.73,184.13,-0.081
35.75,183.93,-0.081
35.77,183.73,-0.081
35.79,183.53,-0.081
35.81,183.33,-0.081
35.83,183.13,-0.081
35.85,182.93,-0.081
35.87,182.73,-0.081
35.89,182.53,-0.081
35.91,182.33,-0.081
35.93,182.13,-0.081
35.95,181.93,-0.081
35.97,181.73,-0.081
35.99,181.53,-0.081
36.01,181.33,-0.081
36.03,181.13,-0.081
36.05,180.93,-0.081
36.07,180.73,-0.081
36.09,180.53,-0.081
36.11,180.33,-0.081
36.13,180.13,-0.081
36.15,179.93,-0.081
36.17,179.73,-0.081
36.19,179.53,-0.081
36.21,179.33,-0.081
36.23,179.13,-0.081
36.25,178.93,-0.081
36.27,178.74,-0.081
36.29,178.53,-0.081
36.31,178.33,-0.081
36.33,178.14,-0.081
36.35,177.93,-0.081
36.37,177.73,-0.081
36.39,177.53,-0.081
36.41,177.33,-0.081
36.43,177.13,-0.081
36.45,176.94,-0.081
36.47,176.74,-0.081
36.49,176.53,-0.081
36.51,176.33,-0.081
36.53,176.14,-0.081
36.55,175.93,-0.081
36.57,175.73,-0.081
36.59,175.53,-0.081
36.61,175.33,-0.081
36.63,175.13,-0.081
36.65,174.94,-0.081
36.67,174.74,-0.081
36.69,174.53,-0.081
36.71,174.34,-0.081
36.73,174.13,-0.081
36.75,173.94,-0.081
36.77,173.74,-0.081
36.79,173.54,-0.081
36.81,173.34,-0.081
36.83,173.14,-0.081
36.85,172.94,-0.081
36.87,172.74,-0.081
36.89,172.54,-0.081
36.91,172.34,-0.081
36.93,172.14,-0.081
36.95,171.94,-0.081
36.97,171.74,-0.081
36.99,171.54,-0.081
37.01,171.34,-0.081
37.03,171.14,-0.081
37.05,170.94,-0.081
37.07,170.74,-0.081
37.09,170.54,-0.081
37.11,170.34,-0.081
37.13,170.14,-0.081
37.15,169.94,-0.081
37.17,169.74,-0.081
37.19,169.54,-0.080
37.21,169.34,-0.080
37.23,169.14,-0.080
37.25,168.94,-0.080
37.27,168.74,-0.080
37.29,168.54,-0.080
37.31,168.34,-0.080
37.33,168.14,-0.080
37.35,167.94,-0.080
37.37,167.74,-0.080
37.39,167.54,-0.080
37.41,167.34,-0.080
37.43,167.14,-0.080
37.45,166.94,-0.080
37.47,166.74,-0.080
37.49,166.54,-0.080
37.51,166.34,-0.080
37.53,166.14,-0.080
37.55,165.94,-0.080
37.57,165.74,-0.080
37.59,165.54,-0.080
37.61,165.34,-0.080
37.63,165.14,-0.080
37.65,164.94,-0.080
37.67,164.74,-0.080
37.69,164.54,-0.080
37.71,164.34,-0.080
37.73,164.14,-0.080
37.75,163.94,-0.080
37.77,163.74,-0.080
37.79,163.54,-0.080
37.81,163.34,-0.080
37.83,163.14,-0.080
37.85,162.94,-0.080
37.87,162.74,-0.080
37.89,162.54,-0.080
37.91,162.34,-0.080
37.93,162.14,-0.080
37.95,161.94,-0.080
37.97,161.74,-0.080
37.99,161.54,-0.080
38.01,161.34,-0.080
38.03,161.14,-0.080
38.05,160.94,-0.080
38.07,160.74,-0.080
38.09,160.54,-0.080
38.11,160.34,-0.080
38.13,160.14,-0.080
38.15,159.94,-0.080
38.17,159.74,-0.080
38.19,159.54,-0.080
38.21,159.34,-0.080
38.23,159.14,-0.080
38.25,158.94,-0.080
[...]
132.64,25.09,0.045
132.65,25.30,0.045
132.68,25.50,0.045
132.70,25.70,0.045
132.71,25.90,0.045
132.74,26.10,0.045
132.75,26.30,0.045
132.78,26.50,0.046
132.80,26.70,0.046
132.81,26.90,0.046
132.84,27.10,0.046
132.85,27.30,0.046
132.88,27.50,0.046
132.90,27.70,0.046
132.91,27.90,0.046
132.94,28.10,0.046
132.95,28.30,0.046
132.98,28.50,0.046
133.00,28.70,0.046
133.01,28.90,0.046
133.04,29.10,0.046
133.05,29.30,0.046
133.08,29.50,0.046
133.10,29.70,0.046
133.11,29.90,0.046
133.14,30.10,0.046
133.15,30.30,0.046
133.18,30.50,0.046
133.20,30.70,0.046
133.21,30.90,0.046
133.24,31.10,0.046
133.25,31.30,0.046
133.28,31.50,0.046
133.30,31.70,0.046
133.31,31.90,0.046
133.34,32.10,0.046
133.35,32.31,0.046
133.38,32.50,0.046
133.40,32.70,0.046
133.41,32.90,0.047
133.44,33.10,0.047
133.45,33.30,0.047
133.48,33.50,0.047
133.50,33.71,0.047
133.51,33.90,0.047
133.54,34.11,0.047
133.55,34.30,0.047
133.58,34.51,0.047
133.60,34.71,0.047
133.61,34.91,0.047
133.64,35.11,0.047
133.65,35.31,0.047
133.68,35.51,0.047
133.70,35.71,0.047
133.71,35.91,0.047
133.74,36.11,0.047
133.75,36.31,0.047
133.78,36.51,0.047
133.80,36.71,0.047
133.81,36.91,0.047
133.84,37.11,0.047
133.85,37.31,0.047
133.88,37.51,0.047
133.90,37.71,0.047
133.91,37.91,0.047
133.94,38.11,0.047
133.95,38.31,0.047
133.98,38.51,0.047
134.00,38.71,0.047
134.01,38.91,0.047
134.04,39.11,0.047
134.05,39.31,0.047
134.08,39.51,0.047
134.10,39.71,0.048
134.11,39.91,0.048
134.14,40.11,0.048
134.15,40.31,0.048
134.18,40.51,0.048
134.20,40.71,0.048
134.21,40.91,0.048
134.24,41.11,0.048
134.25,41.31,0.048
134.28,41.51,0.048
134.30,41.71,0.048
134.31,41.91,0.048
134.34,42.11,0.048
134.35,42.31,0.048
134.38,42.51,0.048
134.40,42.71,0.048
134.41,42.91,0.048
134.44,43.11,0.048
134.45,43.31,0.048
134.48,43.52,0.048
134.50,43.72,0.048
134.51,43.92,0.048
134.54,44.12,0.048
134.55,44.32,0.048
134.58,44.52,0.048
134.60,44.72,0.048
134.61,44.92,0.048
134.64,45.12,0.048
134.65,45.32,0.048
134.68,45.52,0.048
134.70,45.72,0.048
134.71,45.92,0.048
134.74,46.12,0.048
134.75,46.32,0.049
134.78,46.52,0.049
134.80,46.72,0.049
134.81,46.92,0.049
134.84,47.12,0.049
134.85,47.32,0.049
134.88,47.52,0.049
134.90,47.72,0.049
134.91,47.92,0.049
134.94,48.12,0.049
134.95,48.32,0.049
134.98,48.52,0.049
135.00,48.72,0.049
135.01,48.92,0.049
135.04,49.12,0.049
135.05,49.32,0.049
135.08,49.52,0.049
135.10,49.72,0.049
135.11,49.92,0.049
135.14,50.12,0.049
135.15,50.32,0.049
135.18,50.52,0.049
135.20,50.72,0.049
135.21,50.92,0.049
135.24,51.12,0.049
135.25,51.32,0.049
135.28,51.52,0.049
135.30,51.72,0.049
135.31,51.92,0.049
135.34,52.12,0.049
135.35,52.32,0.049
135.38,52.52,0.049
135.40,52.72,0.049
135.41,52.92,0.050
135.44,53.12,0.050
135.45,53.32,0.050
135.48,53.52,0.050
135.50,53.72,0.050
135.51,53.92,0.050
135.54,54.12,0.050
135.55,54.32,0.050
135.58,54.52,0.050
135.60,54.72,0.050
135.61,54.92,0.050
135.64,55.12,0.050
135.65,55.32,0.050
135.68,55.52,0.050
135.70,55.72,0.050
135.71,55.92,0.050
135.74,56.12,0.050
135.75,56.32,0.050
135.78,56.53,0.050
135.80,56.73,0.050
135.81,56.92,0.050
135.84,57.13,0.050
135.85,57.33,0.050
135.88,57.53,0.050
135.90,57.73,0.050
135.91,57.93,0.050
135.94,58.13,0.050
135.95,58.33,0.050
135.98,58.53,0.050
136.00,58.73,0.050
136.01,58.93,0.050
136.04,59.13,0.051
136.05,59.33,0.051
136.08,59.53,0.051
136.10,59.73,0.051
136.11,59.93,0.051
136.14,60.13,0.051
136.15,60.33,0.051
136.18,60.53,0.051
136.20,60.73,0.051
136.21,60.93,0.051
136.24,61.13,0.051
136.25,61.33,0.051
136.28,61.53,0.051
136.30,61.73,0.051
136.31,61.93,0.051
136.34,62.13,0.051
136.35,62.33,0.051
136.38,62.53,0.051
136.40,62.73,0.051
136.41,62.93,0.051
136.44,63.13,0.051
136.45,63.33,0.051
136.48,63.53,0.051
136.50,63.73,0.051
136.51,63.93,0.051
136.53,64.13,0.051
136.55,64.33,0.051
136.58,64.53,0.051
136.60,64.73,0.051
136.62,64.93,0.051
136.63,65.13,0.051
136.65,65.33,0.051
136.68,65.53,0.052
136.70,65.73,0.052
136.72,65.93,0.052
136.73,66.13,0.052
136.75,66.33,0.052
136.78,66.53,0.052
136.80,66.73,0.052
136.82,66.93,0.052
136.83,67.13,0.052
136.85,67.33,0.052
136.88,67.53,0.052
136.90,67.73,0.052
136.92,67.94,0.052
136.93,68.13,0.052
136.95,68.33,0.052
136.98,68.54,0.052
137.00,68.74,0.052
137.02,68.94,0.052
137.03,69.14,0.052
137.05,69.34,0.052
137.08,69.54,0.052
137.10,69.74,0.052
137.12,69.94,0.052
137.13,70.14,0.052
137.15,70.34,0.052
137.18,70.54,0.052
137.20,70.74,0.052
137.22,70.94,0.052
137.23,71.14,0.052
137.25,71.34,0.052
137.28,71.54,0.053
137.30,71.74,0.053
137.32,71.94,0.053
137.33,72.14,0.053
137.35,72.34,0.053
137.38,72.54,0.053
137.40,72.74,0.053
137.42,72.94,0.053
137.43,73.14,0.053
137.45,73.34,0.053
137.48,73.54,0.053
137.50,73.74,0.053
137.52,73.94,0.053
137.53,74.14,0.053
137.55,74.34,0.053
137.58,74.54,0.053
137.60,74.74,0.053
137.62,74.94,0.053
137.63,75.14,0.053
137.65,75.34,0.053
137.68,75.54,0.053
137.70,75.74,0.053
137.72,75.94,0.053
137.73,76.14,0.053
137.75,76.34,0.053
137.78,76.54,0.053
137.80,76.74,0.053
137.82,76.94,0.053
137.83,77.14,0.053
137.85,77.34,0.054
137.88,77.54,0.054
137.90,77.74,0.054
137.92,77.94,0.054
137.93,78.14,0.054
137.95,78.34,0.054
137.98,78.54,0.054
138.00,78.74,0.054
138.02,78.94,0.054
138.03,79.14,0.054
138.05,79.34,0.054
138.08,79.54,0.054
138.10,79.74,0.054
138.12,79.94,0.054
138.13,80.14,0.054
138.15,80.34,0.054
138.18,80.54,0.054
138.20,80.74,0.054
138.22,80.94,0.054
138.23,81.14,0.054
138.25,81.34,0.054
138.28,81.54,0.054
138.30,81.74,0.054
138.32,81.94,0.054
138.33,82.14,0.054
138.35,82.34,0.054
138.38,82.55,0.054
138.40,82.75,0.054
138.42,82.95,0.054
138.43,83.14,0.055
138.45,83.35,0.055
138.48,83.55,0.055
138.50,83.75,0.055
138.52,83.95,0.055
138.53,84.15,0.055
138.55,84.35,0.055
138.58,84.55,0.055
138.60,84.75,0.055
138.62,84.95,0.055
138.63,85.15,0.055
138.65,85.35,0.055
138.68,85.55,0.055
138.70,85.75,0.055
138.72,85.95,0.055
138.73,86.15,0.055
138.75,86.35,0.055
138.78,86.55,0.055
138.80,86.75,0.055
138.82,86.95,0.055
138.83,87.15,0.055
138.85,87.35,0.055
138.88,87.55,0.055
138.90,87.75,0.055
138.92,87.95,0.055
138.93,88.15,0.055
138.95,88.35,0.055
138.98,88.55,0.056
139.00,88.75,0.056
139.02,88.95,0.056
139.03,89.15,0.056
139.05,89.35,0.056
139.08,89.55,0.056
139.10,89.75,0.056
139.12,89.95,0.056
139.13,90.15,0.056
139.15,90.35,0.056
139.18,90.55,0.056
139.20,90.75,0.056
139.22,90.95,0.056
139.23,91.15,0.056
139.25,91.35,0.056
139.28,91.55,0.056
139.30,91.75,0.056
139.32,91.95,0.056
139.33,92.15,0.056
139.35,92.35,0.056
139.38,92.55,0.056
139.40,92.75,0.056
139.42,92.95,0.057
139.43,93.15,0.057
139.45,93.35,0.057
139.48,93.55,0.057
139.50,93.75,0.057
139.52,93.95,0.057
139.53,94.15,0.057
139.55,94.35,0.057
139.58,94.55,0.057
139.60,94.75,0.057
139.62,94.95,0.057
139.63,95.15,0.057
139.65,95.35,0.057
139.68,95.55,0.057
139.70,95.75,0.057
139.72,95.95,0.057
139.73,96.15,0.057
139.75,96.35,0.057
139.78,96.55,0.057
139.80,96.75,0.058
139.82,96.95,0.058
139.83,97.15,0.058
139.85,97.35,0.058
139.88,97.55,0.058
139.90,97.75,0.058
139.92,97.95,0.058
139.93,98.15,0.058
139.95,98.35,0.058
139.98,98.55,0.058
140.00,98.75,0.058
140.02,98.95,0.058
140.03,99.15,0.058
140.05,99.35,0.058
140.08,99.55,0.058
140.10,99.75,0.058
140.12,99.95,0.058
140.13,100.16,0.058
140.15,100.35,0.059
140.18,100.55,0.059
140.20,100.75,0.059
140.22,100.95,0.059
140.23,101.15,0.059
140.25,101.36,0.059
140.28,101.56,0.059
140.30,101.75,0.059
140.32,101.95,0.059
140.33,102.16,0.059
140.35,102.36,0.059
140.38,102.56,0.059
140.40,102.76,0.059
140.42,102.95,0.059
140.43,103.15,0.059
140.45,103.35,0.060
140.48,103.55,0.060
140.50,103.75,0.060
140.52,103.95,0.060
140.53,104.15,0.060
140.55,104.35,0.060
140.58,104.55,0.060
140.60,104.75,0.060
140.62,104.95,0.060
140.63,105.15,0.060
140.65,105.36,0.060
140.68,105.55,0.060
140.70,105.75,0.061
140.72,105.95,0.061
140.73,106.15,0.061
140.75,106.35,0.061
140.78,106.56,0.061
140.80,106.76,0.061
140.82,106.96,0.061
140.83,107.16,0.061
140.85,107.36,0.061
140.88,107.55,0.062
140.90,107.76,0.062
140.92,107.96,0.062
140.93,108.15,0.062
140.95,108.35,0.062
140.98,108.55,0.062
141.00,108.75,0.062
141.02,108.95,0.062
141.03,109.15,0.063
141.05,109.35,0.063
141.08,109.55,0.063
141.10,109.75,0.063
141.12,109.95,0.063
141.13,110.15,0.063
141.15,110.35,0.063
141.18,110.55,0.064
141.20,110.75,0.064
141.22,110.95,0.064
141.23,111.15,0.064
141.25,111.35,0.064
141.28,111.55,0.064
141.30,111.75,0.065
141.32,111.95,0.065
141.33,112.15,0.065
141.35,112.35,0.065
141.38,112.55,0.065
141.40,112.75,0.065
141.42,112.95,0.066
141.43,113.15,0.066
141.45,113.35,0.066
141.48,113.55,0.066
141.50,113.75,0.066
141.52,113.95,0.066
141.53,114.15,0.067
141.55,114.35,0.067
141.58,114.55,0.067
141.60,114.75,0.067
141.62,114.95,0.067
141.63,115.15,0.068
141.65,115.35,0.068
141.68,115.55,0.068
141.70,115.75,0.068
141.72,115.95,0.068
141.73,116.15,0.068
141.75,116.35,0.069
141.78,116.55,0.069
141.80,116.75,0.069
141.82,116.95,0.069
141.83,117.15,0.069
141.85,117.35,0.069
141.88,117.55,0.069
141.90,117.75,0.069
141.92,117.95,0.070
141.93,118.15,0.070
141.95,118.35,0.070
141.98,118.55,0.070
142.00,118.75,0.070
142.02,118.95,0.070
142.03,119.15,0.070
142.05,119.35,0.071
142.08,119.55,0.071
142.10,119.75,0.071
142.12,119.95,0.071
142.13,120.15,0.071
142.15,120.35,0.071
142.18,120.55,0.071
142.20,120.75,0.071
142.22,120.95,0.071
142.23,121.15,0.071
142.25,121.35,0.071
142.28,121.55,0.072
142.30,121.75,0.072
142.32,121.95,0.072
142.33,122.15,0.072
142.35,122.35,0.072
142.38,122.55,0.072
142.40,122.75,0.072
142.42,122.95,0.072
142.43,123.15,0.072
142.45,123.35,0.072
142.48,123.55,0.072
142.50,123.75,0.072
142.52,123.95,0.072
142.53,124.15,0.072
142.55,124.35,0.072
142.58,124.55,0.072
142.60,124.75,0.072
142.62,124.95,0.072
142.63,125.15,0.072
142.65,125.35,0.072
142.68,125.55,0.072
142.70,125.75,0.072
142.72,125.95,0.072
142.73,126.15,0.072
142.75,126.35,0.072
142.78,126.55,0.073
142.80,126.75,0.073
142.82,126.95,0.073
142.83,127.16,0.073
142.85,127.35,0.073
142.88,127.55,0.073
142.90,127.76,0.073
142.92,127.96,0.073
142.93,128.16,0.073
142.95,128.36,0.073
142.98,128.56,0.073
143.00,128.76,0.073
143.02,128.96,0.073
143.03,129.16,0.073
143.05,129.36,0.073
143.08,129.56,0.073
143.10,129.76,0.073
143.12,129.96,0.073
143.13,130.16,0.073
143.15,130.36,0.073
143.18,130.56,0.073
143.20,130.76,0.073
143.22,130.96,0.073
143.23,131.16,0.073
143.25,131.36,0.073
143.28,131.56,0.073
143.30,131.76,0.073
143.32,131.96,0.073
143.33,132.16,0.073
143.35,132.36,0.073
143.38,132.56,0.073
143.40,132.76,0.073
143.42,132.96,0.073
143.43,133.16,0.073
143.45,133.36,0.073
143.48,133.56,0.073
143.50,133.76,0.073
143.52,133.96,0.073
143.53,134.16,0.073
143.55,134.36,0.073
143.58,134.56,0.073
143.60,134.76,0.073
143.62,134.96,0.073
143.63,135.16,0.073
143.65,135.36,0.073
143.68,135.56,0.073
143.70,135.76,0.073
143.72,135.96,0.073
143.73,136.16,0.073
143.75,136.36,0.073
143.78,136.56,0.073
143.80,136.76,0.073
143.82,136.96,0.073
143.83,137.16,0.073
143.85,137.36,0.073
143.88,137.56,0.073
143.90,137.76,0.073
143.92,137.96,0.074
143.93,138.16,0.074
143.95,138.36,0.074
143.98,138.56,0.074
144.00,138.76,0.074
144.02,138.96,0.074
144.03,139.16,0.074
144.05,139.36,0.074
144.08,139.56,0.074
144.10,139.76,0.074
144.12,139.96,0.074
144.13,140.16,0.074
144.15,140.36,0.074
144.18,140.56,0.074
144.20,140.76,0.074
144.22,140.96,0.074
144.23,141.16,0.074
144.25,141.36,0.074
144.28,141.56,0.074
144.30,141.76,0.074
144.32,141.96,0.074
144.33,142.17,0.074
144.35,142.37,0.074
144.38,142.57,0.074
144.40,142.77,0.074
144.42,142.97,0.074
144.43,143.17,0.074
144.45,143.37,0.074
144.48,143.57,0.074
144.50,143.77,0.074
144.52,143.97,0.074
144.53,144.17,0.074
144.55,144.37,0.074
144.58,144.57,0.074
144.60,144.77,0.074
144.62,144.97,0.074
144.63,145.17,0.074
144.65,145.37,0.075
144.68,145.57,0.075
144.70,145.77,0.075
144.72,145.97,0.075
144.73,146.17,0.075
144.75,146.37,0.075
144.78,146.57,0.075
144.80,146.77,0.075
144.82,146.97,0.075
144.83,147.17,0.075
144.85,147.37,0.075
144.88,147.57,0.075
144.90,147.77,0.075
144.92,147.97,0.075
144.93,148.17,0.075
144.95,148.37,0.075
144.98,148.57,0.075
145.00,148.77,0.075
145.02,148.97,0.075
145.03,149.17,0.075
145.05,149.37,0.075
145.08,149.57,0.075
145.10,149.77,0.075
145.12,149.97,0.075
145.13,150.17,0.075
145.15,150.37,0.075
145.18,150.57,0.075
145.20,150.77,0.075
145.22,150.97,0.075
145.23,151.17,0.075
145.25,151.37,0.075
145.28,151.57,0.076
145.30,151.77,0.076
145.32,151.97,0.076
145.33,152.17,0.076
145.35,152.37,0.076
145.38,152.57,0.076
145.40,152.77,0.076
145.42,152.97,0.076
145.43,153.17,0.076
145.45,153.37,0.076
145.48,153.57,0.076
145.50,153.77,0.076
145.52,153.97,0.076
145.53,154.17,0.076
145.55,154.37,0.076
145.58,154.57,0.076
145.60,154.77,0.076
145.62,154.97,0.076
145.63,155.17,0.076
145.65,155.37,0.076
145.68,155.57,0.076
145.70,155.77,0.076
145.72,155.97,0.076
145.73,156.17,0.076
145.75,156.37,0.076
145.78,156.57,0.076
145.80,156.77,0.076
145.82,156.97,0.076
145.83,157.17,0.076
145.85,157.37,0.076
145.88,157.58,0.077
145.90,157.77,0.077
145.92,157.98,0.077
145.93,158.18,0.077
145.95,158.37,0.077
145.98,158.58,0.077
146.00,158.78,0.077
146.02,158.98,0.077
146.03,159.18,0.077
146.05,159.38,0.077
146.08,159.58,0.077
146.10,159.78,0.077
146.12,159.98,0.077
146.13,160.18,0.077
146.15,160.38,0.077
146.18,160.58,0.077
146.20,160.78,0.077
146.22,160.98,0.077
146.23,161.18,0.077
146.25,161.38,0.077
146.28,161.58,0.077
146.30,161.78,0.077
146.32,161.98,0.077
146.33,162.18,0.077
146.35,162.38,0.077
146.38,162.58,0.077
146.40,162.78,0.077
146.42,162.98,0.077
146.43,163.18,0.077
146.45,163.38,0.077
146.48,163.58,0.077
146.50,163.78,0.077
146.52,163.98,0.077
146.53,164.18,0.077
146.55,164.38,0.077
146.58,164.58,0.077
146.60,164.78,0.077
146.62,164.98,0.078
146.63,165.18,0.078
146.65,165.38,0.078
146.68,165.58,0.078
146.70,165.78,0.078
146.72,165.98,0.078
146.73,166.18,0.078
146.75,166.38,0.078
146.78,166.58,0.078
146.80,166.78,0.078
146.82,166.98,0.078
146.83,167.18,0.078
146.85,167.38,0.078
146.88,167.58,0.078
146.90,167.78,0.078
146.92,167.98,0.078
146.93,168.18,0.078
146.95,168.38,0.078
146.98,168.58,0.078
147.00,168.78,0.078
147.02,168.98,0.078
147.03,169.18,0.078
147.05,169.38,0.078
147.08,169.58,0.078
147.10,169.78,0.078
147.12,169.98,0.078
147.13,170.18,0.078
147.15,170.38,0.078
147.18,170.58,0.078
147.20,170.78,0.078
147.22,170.98,0.078
147.23,171.18,0.078
147.25,171.38,0.078
147.28,171.58,0.078
147.30,171.78,0.078
147.32,171.98,0.078
147.33,172.18,0.079
147.35,172.38,0.079
147.38,172.59,0.079
147.40,172.78,0.079
147.42,172.98,0.079
147.43,173.18,0.079
147.45,173.38,0.079
147.48,173.58,0.079
147.50,173.78,0.079
147.52,173.98,0.079
147.53,174.18,0.079
147.55,174.38,0.079
147.58,174.59,0.079
147.60,174.78,0.079
147.62,174.99,0.079
147.63,175.19,0.079
147.65,175.39,0.079
147.68,175.59,0.079
147.70,175.79,0.079
147.72,175.98,0.079
147.73,176.19,0.079
147.75,176.39,0.079
147.78,176.59,0.079
147.80,176.79,0.079
147.82,176.99,0.079
147.83,177.19,0.079
147.85,177.39,0.079
147.88,177.59,0.079
147.90,177.79,0.079
147.92,177.99,0.079
147.93,178.19,0.079
147.95,178.39,0.079
147.98,178.59,0.079
148.00,178.79,0.079
148.02,178.99,0.080
148.03,179.19,0.080
148.05,179.39,0.080
148.08,179.59,0.080
148.10,179.79,0.080
148.12,179.99,0.080
148.13,180.19,0.080
148.15,180.39,0.080
148.18,180.59,0.080
148.20,180.79,0.080
148.22,180.99,0.080
148.23,181.19,0.080
148.25,181.39,0.080
148.28,181.59,0.080
148.30,181.79,0.080
148.32,181.99,0.080
148.33,182.19,0.080
148.35,182.39,0.080
148.38,182.59,0.080
148.40,182.79,0.080
148.42,182.99,0.080
148.43,183.19,0.080
148.45,183.39,0.080
148.48,183.59,0.080
148.50,183.79,0.080
148.52,183.99,0.080
148.53,184.19,0.080
148.55,184.39,0.080
148.58,184.59,0.080
148.60,184.79,0.080
148.62,184.99,0.080
148.63,185.19,0.080
148.65,185.39,0.081
148.68,185.59,0.081
148.70,185.79,0.081
148.72,185.99,0.081
148.73,186.19,0.081
148.75,186.39,0.081
148.78,186.59,0.081
148.80,186.79,0.081
148.82,186.99,0.081
148.83,187.19,0.081
148.85,187.39,0.081
148.88,187.59,0.081
148.90,187.79,0.081
148.92,187.99,0.081
148.93,188.19,0.081
148.95,188.39,0.081
148.98,188.59,0.081
149.00,188.79,0.081
149.02,188.99,0.081
149.03,189.19,0.081
149.05,189.39,0.081
149.08,189.59,0.081
149.10,189.79,0.081
149.12,189.99,0.081
149.13,190.19,0.081
149.15,190.39,0.081
149.18,190.60,0.081
149.20,190.79,0.081
149.22,190.99,0.081
149.23,191.19,0.082
149.25,191.39,0.082
149.28,191.60,0.082
149.30,191.79,0.082
149.32,192.00,0.082
149.33,192.20,0.082
149.35,192.40,0.082
149.38,192.60,0.082
149.40,192.80,0.082
149.42,193.00,0.082
149.43,193.20,0.082
149.45,193.40,0.082
149.48,193.60,0.082
149.50,193.80,0.082
149.52,194.00,0.082
149.53,194.20,0.082
149.55,194.40,0.082
149.58,194.60,0.082
149.60,194.80,0.082
149.62,195.00,0.082
149.63,195.20,0.082
149.65,195.40,0.082
149.68,195.60,0.082
149.70,195.80,0.082
149.72,196.00,0.082
149.73,196.20,0.082
149.75,196.40,0.082
149.78,196.60,0.082
149.80,196.80,0.082
149.82,197.00,0.083
149.83,197.20,0.083
149.85,197.40,0.083
149.88,197.60,0.083
149.90,197.80,0.083
149.92,198.00,0.083
149.93,198.20,0.083
149.95,198.40,0.083
149.98,198.60,0.083
150.00,198.80,0.083
150.02,199.00,0.083
150.03,199.20,0.083
150.05,199.40,0.083
150.08,199.60,0.083
150.10,199.80,0.083
150.12,200.00,0.083
150.13,200.20,0.083
150.15,200.40,0.083
150.18,200.60,0.083
150.20,200.80,0.083
150.22,201.00,0.083
150.23,201.20,0.083
150.25,201.40,0.083
150.28,201.60,0.083
150.30,201.80,0.083
150.32,202.00,0.084
150.33,202.20,0.084
150.35,202.40,0.084
150.38,202.60,0.084
150.40,202.80,0.084
150.42,203.00,0.084
150.43,203.20,0.084
150.45,203.40,0.084
150.48,203.60,0.084
150.50,203.80,0.084
150.52,204.00,0.084
150.53,204.20,0.084
150.55,204.40,0.084
150.58,204.60,0.084
150.60,204.80,0.084
150.62,205.00,0.084
150.63,205.20,0.084
150.65,205.40,0.084
150.68,205.60,0.084
150.70,205.80,0.084
150.72,206.00,0.084
150.73,206.20,0.084
150.75,206.40,0.084
150.78,206.60,0.084
150.80,206.80,0.084
150.82,207.00,0.084
150.83,207.20,0.084
150.85,207.40,0.084
150.88,207.60,0.084
150.90,207.80,0.084
150.92,208.00,0.085
150.93,208.20,0.085
150.95,208.41,0.085
150.98,208.61,0.085
151.00,208.81,0.085
151.02,209.00,0.085
151.03,209.21,0.085
151.05,209.41,0.085
151.08,209.61,0.085
151.10,209.81,0.085
151.12,210.00,0.085
151.13,210.20,0.085
151.15,210.40,0.085
151.18,210.60,0.085
151.20,210.80,0.085
151.22,211.00,0.085
151.23,211.21,0.085
151.25,211.40,0.085
151.28,211.61,0.085
151.30,211.80,0.085
151.32,212.01,0.085
151.33,212.20,0.085
151.35,212.40,0.085
151.38,212.61,0.085
151.40,212.81,0.085
151.42,213.01,0.085
151.43,213.21,0.085
151.45,213.41,0.086
151.48,213.61,0.086
151.50,213.81,0.086
151.52,214.01,0.086
151.53,214.21,0.086
151.55,214.41,0.086
151.58,214.61,0.086
151.60,214.80,0.086
151.62,215.00,0.086
151.63,215.20,0.086
151.65,215.40,0.086
151.68,215.61,0.086
151.70,215.81,0.086
151.72,216.01,0.086
151.73,216.21,0.086
151.75,216.41,0.086
151.78,216.61,0.086
151.80,216.81,0.086
151.82,217.01,0.086
151.83,217.21,0.086
151.85,217.41,0.086
151.88,217.61,0.086
151.90,217.81,0.086
151.92,218.01,0.087
151.93,218.21,0.087
151.95,218.41,0.087
151.98,218.61,0.087
152.00,218.81,0.087
152.02,219.01,0.087
152.03,219.21,0.087
152.05,219.41,0.087
152.08,219.61,0.087
152.10,219.81,0.087
152.12,220.01,0.087
152.13,220.21,0.087
152.15,220.41,0.087
152.18,220.61,0.087
152.20,220.81,0.087
152.22,221.01,0.087
152.23,221.21,0.087
152.25,221.41,0.087
152.28,221.61,0.087
152.30,221.81,0.087
152.32,222.01,0.087
152.33,222.21,0.087
152.35,222.41,0.087
152.38,222.61,0.088
152.40,222.81,0.088
152.42,223.01,0.088
152.43,223.21,0.088
152.45,223.41,0.088
152.48,223.61,0.088
152.50,223.81,0.088
152.52,224.01,0.088
152.53,224.21,0.088
152.55,224.41,0.088
152.58,224.61,0.088
152.60,224.81,0.088
152.62,225.01,0.088
152.63,225.21,0.088
152.65,225.41,0.088
152.68,225.61,0.088
152.70,225.81,0.088
152.72,226.01,0.088
152.73,226.21,0.088
152.75,226.41,0.088
152.78,226.61,0.088
152.80,226.81,0.088
152.82,227.01,0.088
152.83,227.21,0.088
152.85,227.41,0.089
152.88,227.61,0.089
152.90,227.81,0.089
152.92,228.01,0.089
152.93,228.21,0.089
152.95,228.41,
152.98,228.61,
152.99,,