File: DSC/Olivia/2025_08_02_1CBN_3PVP_MP_n60C_130C_10Cmin_x3.csv
Filename,2025_08_02_1CBN_3PVP_MP_n60C_130C_10Cmin_x3
Instrument name,DSC2A-00468 (192.168.1.100)
Operator,Yarger
rundate,8/2/2025
Sample name,2025_08_02_1CBN_3PVP_MP_n60C_130C_10Cmin_x3
proceduresegments,Data Off ; Equilibrate -60.00 °C; Data On ; Ramp 10.00 °C/min to 130.00 °C; Data Off ; Isothermal 2.0 min; Data On ; Ramp 10.00 °C/min to -60.00 °C; Data Off ; Isothermal 2.0 min; Data On ; Ramp 10.00 °C/min to 130.00 °C; Data Off ; Isothermal 2.0 min; Data On ; Ramp 10.00 °C/min to -60.00 °C; Data Off ; Isothermal 2.0 min; Data On ; Ramp 10.00 °C/min to 130.00 °C
[File Parameters]
Run date,8/2/2025 3:17:13 AM
Trios version,5.1.1.46572
Original File Name,
Current File Name,D:\DSC2500\Gibbons\2025_08_02_1CBN_3PVP_MP_n60C_130C_10Cmin_x3.tri
[Procedure]
Procedure Name,CBNPVP_n60C_130C_10Cmin_x3
Sample Name,2025_08_02_1CBN_3PVP_MP_n60C_130C_10Cmin_x3
Sample Mass,7.7 mg
Reference Sample Mass,0 mg
Pan Mass,32.46 mg
Pan Number,50
Reference Pan Mass,32.73 mg
Reference Pan Number,46
Pan Type,Aluminum
Comments,Thermal support Al pans/lids. DSC_Samples_A2_Tray_July2025 google sheet.
Project Name,Pharma - Cocrystals
Operator,Yarger
Test,Custom
Unload Max Temperature,30
Unload Min Temperature,30
Load Max Temperature,30
Load Min Temperature,30
Stop on Gas Flow Error,Yes
[Signal List]
Signal #1,Time (min)
Signal #2,Temperature (°C)
Signal #3,Heat Flow (mW)
Signal #4,Delta T (µV)
Signal #5,Delta Tzero (µV)
Signal #6,Tzero Temperature (°C)
Signal #7,Cell Purge (mL/min)
Signal #8,Heater Temp (°C)
Signal #9,Power Delivered (W)
Signal #10,Reference Junction Temperature (°C)
Signal #11,Flange Temperature (°C)
Signal #12,Heat Flow Phase (rad)
Signal #13,Total Heat Capacity (J/°C)
Signal #14,Heat Capacity (J/°C)
[Configuration]
Company Name,ASU
Instrument Name,DSC2A-00468
Instrument Type,DSC2500
Serial Number,DSC2A-00468
IP,192.168.1.100
Location of Instrument,MRRC
DisplayType,Unknown
Sample Interval ,0.1 s/pt
Selected Heat Flow,T4P
Exotherm Direction,Down
Cell Serial,DRC2-00792
Lid Type,Standard
Cooler,RCS 90
Leave Cooler on at End of Sequence,On
Gas 2,Nitrogen
Gas Selected,Channel 1
Flow Rate,50 mL/min
Secondary Purge,On
Licensed Heat Flow,Heat Flow T4P
Modulation Licensed,Yes
[Versions]
Common IDD Version,1
Cortex Version,VER 2.10.2.31
Driver,5.0.0.6
GDM Version,1.0.3.3
TouchscreenVersion,1.0.0.16145
FEP Version,1.2.1.21
FEP Bootloader,2.0.0.5
AutoSampler Version,2.1.1.26
Auto Sampler Bootloader,2.0.0.5
FCM Version,1.1.0.3
FCM Bootloader,2.0.0.5
[Experiment Logs]
Experiment Log Entry # 1,Data On set to 0
Experiment Log Entry # 3,Equilibrate Segment -60 (C) Started
Experiment Log Entry # 5,Air Cool is off.
Experiment Log Entry # 7,Data On set to 1
Experiment Log Entry # 9,Ramp Segment 10 C/min to 130 Started
Experiment Log Entry # 11,Data On set to 0
Experiment Log Entry # 13,Isothermal Segment 2 min started
Experiment Log Entry # 15,Data On set to 1
Experiment Log Entry # 17,Ramp Segment 10 C/min to -60 Started
Experiment Log Entry # 19,Data On set to 0
Experiment Log Entry # 21,Isothermal Segment 2 min started
Experiment Log Entry # 23,Data On set to 1
Experiment Log Entry # 25,Ramp Segment 10 C/min to 130 Started
Experiment Log Entry # 27,Data On set to 0
Experiment Log Entry # 29,Isothermal Segment 2 min started
Experiment Log Entry # 31,Data On set to 1
Experiment Log Entry # 33,Ramp Segment 10 C/min to -60 Started
Experiment Log Entry # 35,Data On set to 0
Experiment Log Entry # 37,Isothermal Segment 2 min started
Experiment Log Entry # 39,Data On set to 1
Experiment Log Entry # 41,Ramp Segment 10 C/min to 130 Started
[Method Log]
Method Log Entry # 1,Data Off
Method Log Entry # 2,Equilibrate -60 °C
Method Log Entry # 3,Data On
Method Log Entry # 4,(Ramp 134106) Ramp 10 °C/minute to 130 °C
Method Log Entry # 5,Data Off
Method Log Entry # 6,Isothermal 2 minutes
Method Log Entry # 7,Data On
Method Log Entry # 8,(Ramp 134110) Ramp 10 °C/minute to -60 °C
Method Log Entry # 9,Data Off
Method Log Entry # 10,Isothermal 2 minutes
Method Log Entry # 11,Data On
Method Log Entry # 12,(Ramp 134114) Ramp 10 °C/minute to 130 °C
Method Log Entry # 13,Data Off
Method Log Entry # 14,Isothermal 2 minutes
Method Log Entry # 15,Data On
Method Log Entry # 16,(Ramp 134118) Ramp 10 °C/minute to -60 °C
Method Log Entry # 17,Data Off
Method Log Entry # 18,Isothermal 2 minutes
Method Log Entry # 19,Data On
Method Log Entry # 20,(Ramp 134122) Ramp 10 °C/minute to 130 °C
Cell Serial,DRC2-00792
[T1 Calibration]
Slope,-0.008529666
Offset,9.636258
Initial Temperature,98.23
GUID,f8bfdadc-4977-4fdf-ba6d-0ba9134940c3
[TZero Calibration]
Date Applied,11/29/2022 4:06:13 PM
Description,From -89.059 °C to 396.009 °C at 20.000°C/min
Gas Type,Nitrogen
Pan Type,None
Source Files 1,C:\Users\yargerlab\Desktop\DSC Data\General\TZero_calibration_11_29_22_2nd(2).tri
Source Files 2,C:\Users\yargerlab\Desktop\DSC Data\General\TZero_calibration_11_29_22_2nd(3).tri
Delta T Offset,13.05235
Delta T Slope,-0.007271007
Delta T0 Offset,-13.69128
Delta T0 Slope,0.06063341
[Temperature Calibration]
Date Applied,11/29/2022 7:12:28 PM
Description,From 106.590 °C to 186.590 °C at 10.000°C/min
Gas Type,Nitrogen
Pan Type,Tzero Aluminum Hermetic
Source Files 1,C:\Users\yargerlab\Desktop\DSC Data\General\Indium(6).tri
Measured 1,157.391
Known 1,156.598
[Cell Constant Calibration]
Date Applied,11/29/2022 7:12:29 PM
Description,From 106.590 °C to 186.590 °C at 10.000°C/min
Gas Type,Nitrogen
Pan Type,Tzero Aluminum Hermetic
Source Files 1,C:\Users\yargerlab\Desktop\DSC Data\General\Indium(6).tri
T4P KCell,1.006051
Onset Slope,63.26126 mW/°C
[Direct Cp Calibration]
Date Applied,11/30/2022 11:04:51 AM
Description,From -79.983 °C to 298.409 °C at 10.000°C/min
Gas Type,Nitrogen
Pan Type,Tzero Aluminum Hermetic
Source Files 1,C:\Users\yargerlab\Desktop\DSC Data\General\Sapphire_Heat_Capacity_11_30_22.tri
[Rev Cp Calibration]
Date Applied,11/30/2022 1:58:51 PM
Description,From -79.996 °C to 292.812 °C at 3.000°C/min
Gas Type,Nitrogen
Pan Type,Tzero Aluminum Hermetic
Source Files 1,C:\Users\yargerlab\Desktop\DSC Data\General\Sapphire_MDSC_Calibration_11_30_22.tri
[step]
Ramp 10.00 °C/min to 130.00 °C
Time,Temperature,Heat Flow (Normalized)
min,°C,W/g
0.00,-59.81,-0.038
0.01,-59.81,-0.037
0.03,-59.82,-0.034
0.04,-59.81,-0.032
0.05,-59.81,-0.031
0.07,-59.79,-0.030
0.08,-59.76,-0.028
0.09,-59.72,-0.024
0.11,-59.67,-0.016
0.12,-59.60,-0.008
0.13,-59.52,0.004
0.15,-59.44,0.017
0.16,-59.34,0.031
0.17,-59.24,0.046
0.19,-59.13,0.061
0.20,-59.03,0.075
0.21,-58.91,0.088
0.23,-58.79,0.099
0.24,-58.67,0.111
0.25,-58.55,0.120
0.27,-58.43,0.128
0.28,-58.31,0.135
0.29,-58.18,0.141
0.31,-58.06,0.146
0.32,-57.93,0.151
0.33,-57.81,0.154
0.35,-57.68,0.157
0.36,-57.55,0.161
0.37,-57.42,0.163
0.39,-57.30,0.165
0.40,-57.17,0.166
0.41,-57.04,0.168
0.43,-56.91,0.170
0.44,-56.78,0.171
0.45,-56.65,0.172
0.47,-56.52,0.173
0.48,-56.39,0.174
0.49,-56.26,0.175
0.51,-56.13,0.176
0.52,-56.00,0.176
0.53,-55.87,0.177
0.55,-55.74,0.177
0.56,-55.61,0.178
0.57,-55.48,0.178
0.59,-55.34,0.179
0.60,-55.22,0.179
0.61,-55.08,0.180
0.63,-54.95,0.180
0.64,-54.82,0.180
0.65,-54.69,0.180
0.67,-54.56,0.181
0.68,-54.43,0.181
0.69,-54.29,0.181
0.71,-54.16,0.182
0.72,-54.03,0.182
0.73,-53.90,0.182
0.75,-53.77,0.182
0.76,-53.63,0.182
0.77,-53.51,0.183
0.79,-53.37,0.183
0.80,-53.24,0.183
0.81,-53.11,0.183
0.83,-52.97,0.184
0.84,-52.84,0.184
0.85,-52.71,0.184
0.87,-52.58,0.184
0.88,-52.45,0.184
0.89,-52.31,0.185
0.91,-52.18,0.185
0.92,-52.05,0.185
0.93,-51.92,0.185
0.95,-51.78,0.186
0.96,-51.65,0.186
0.97,-51.52,0.186
0.99,-51.39,0.186
1.00,-51.25,0.186
1.01,-51.12,0.187
1.03,-50.99,0.187
1.04,-50.86,0.187
1.05,-50.72,0.187
1.07,-50.59,0.187
1.08,-50.46,0.188
1.09,-50.32,0.188
1.11,-50.19,0.188
1.12,-50.06,0.188
1.13,-49.93,0.188
1.15,-49.79,0.188
1.16,-49.66,0.189
1.17,-49.53,0.189
1.19,-49.40,0.189
1.20,-49.26,0.189
1.21,-49.13,0.189
1.23,-48.99,0.189
1.24,-48.86,0.190
1.25,-48.73,0.190
1.27,-48.60,0.190
1.28,-48.47,0.190
1.29,-48.33,0.190
1.31,-48.20,0.190
1.32,-48.07,0.191
1.33,-47.93,0.191
1.35,-47.80,0.191
1.36,-47.67,0.191
1.37,-47.53,0.191
1.39,-47.40,0.191
1.40,-47.27,0.191
1.41,-47.13,0.192
1.43,-47.00,0.192
1.44,-46.87,0.192
1.45,-46.73,0.192
1.47,-46.60,0.192
1.48,-46.47,0.192
1.49,-46.33,0.192
1.51,-46.20,0.193
1.52,-46.07,0.193
1.53,-45.93,0.193
1.55,-45.80,0.193
1.56,-45.67,0.193
1.57,-45.53,0.193
1.59,-45.40,0.193
1.60,-45.27,0.193
1.61,-45.13,0.193
1.63,-45.00,0.194
1.64,-44.87,0.194
1.65,-44.73,0.194
1.67,-44.60,0.194
1.68,-44.47,0.194
1.69,-44.33,0.194
1.71,-44.20,0.194
1.72,-44.07,0.194
1.73,-43.93,0.195
1.75,-43.80,0.195
1.76,-43.67,0.195
1.77,-43.53,0.195
1.79,-43.40,0.195
1.80,-43.27,0.195
1.81,-43.13,0.195
1.83,-43.00,0.195
1.84,-42.87,0.195
1.85,-42.73,0.196
1.87,-42.60,0.196
1.88,-42.47,0.196
1.89,-42.33,0.196
1.91,-42.20,0.196
1.92,-42.07,0.196
1.93,-41.93,0.196
1.95,-41.80,0.196
1.96,-41.67,0.196
1.97,-41.53,0.196
1.99,-41.40,0.197
2.00,-41.27,0.197
2.01,-41.13,0.197
2.03,-41.00,0.197
2.04,-40.87,0.197
2.05,-40.73,0.197
2.07,-40.60,0.197
2.08,-40.47,0.197
2.09,-40.33,0.197
2.11,-40.20,0.197
2.12,-40.06,0.197
2.13,-39.93,0.198
2.15,-39.80,0.198
2.16,-39.67,0.198
2.17,-39.53,0.198
2.19,-39.40,0.198
2.20,-39.27,0.198
2.21,-39.13,0.198
2.23,-39.00,0.198
2.24,-38.86,0.198
2.25,-38.73,0.198
2.27,-38.60,0.198
2.28,-38.46,0.199
2.29,-38.33,0.199
2.31,-38.20,0.199
2.32,-38.06,0.199
2.33,-37.93,0.199
2.35,-37.80,0.199
2.36,-37.66,0.199
2.37,-37.53,0.199
2.39,-37.40,0.199
2.40,-37.26,0.199
2.41,-37.13,0.199
2.43,-36.99,0.200
2.44,-36.86,0.200
2.45,-36.73,0.200
2.47,-36.59,0.200
2.48,-36.46,0.200
2.49,-36.33,0.200
2.51,-36.19,0.200
2.52,-36.06,0.200
2.53,-35.93,0.200
2.55,-35.79,0.200
2.56,-35.66,0.200
2.57,-35.53,0.201
2.59,-35.39,0.201
2.60,-35.26,0.201
2.61,-35.13,0.201
2.63,-34.99,0.201
2.64,-34.86,0.201
2.65,-34.73,0.201
2.67,-34.59,0.201
2.68,-34.46,0.201
2.69,-34.33,0.201
2.71,-34.19,0.201
2.72,-34.06,0.201
2.73,-33.93,0.202
2.75,-33.79,0.202
2.76,-33.66,0.202
2.77,-33.53,0.202
2.79,-33.39,0.202
2.80,-33.26,0.202
2.81,-33.12,0.202
2.83,-32.99,0.202
2.84,-32.86,0.202
2.85,-32.72,0.202
2.87,-32.59,0.202
2.88,-32.46,0.203
2.89,-32.32,0.203
2.91,-32.19,0.203
2.92,-32.06,0.203
2.93,-31.92,0.203
2.95,-31.79,0.203
2.96,-31.65,0.203
2.97,-31.52,0.203
2.99,-31.39,0.203
3.00,-31.26,0.203
3.01,-31.12,0.203
3.03,-30.99,0.203
3.04,-30.86,0.204
3.05,-30.72,0.204
3.07,-30.59,0.204
3.08,-30.45,0.204
3.09,-30.32,0.204
3.11,-30.19,0.204
3.12,-30.05,0.204
3.13,-29.92,0.204
3.15,-29.79,0.204
3.16,-29.65,0.204
3.17,-29.52,0.205
3.19,-29.39,0.205
3.20,-29.25,0.205
3.21,-29.12,0.205
3.23,-28.99,0.205
3.24,-28.85,0.205
3.25,-28.72,0.205
3.27,-28.59,0.205
3.28,-28.45,0.205
3.29,-28.32,0.205
3.31,-28.19,0.205
3.32,-28.05,0.206
3.33,-27.92,0.206
3.35,-27.79,0.206
3.36,-27.65,0.206
3.37,-27.52,0.206
3.39,-27.38,0.206
3.40,-27.25,0.206
3.41,-27.12,0.206
3.43,-26.98,0.206
3.44,-26.85,0.207
3.45,-26.72,0.207
3.47,-26.58,0.207
3.48,-26.45,0.207
3.49,-26.32,0.207
3.51,-26.19,0.207
3.52,-26.05,0.207
3.53,-25.92,0.207
3.55,-25.78,0.207
3.56,-25.65,0.207
3.57,-25.52,0.208
3.59,-25.38,0.208
3.60,-25.25,0.208
3.61,-25.12,0.208
3.63,-24.98,0.208
3.64,-24.85,0.208
3.65,-24.72,0.208
3.67,-24.58,0.208
3.68,-24.45,0.208
3.69,-24.32,0.208
3.71,-24.18,0.209
3.72,-24.05,0.209
3.73,-23.91,0.209
3.75,-23.78,0.209
3.76,-23.65,0.209
3.77,-23.52,0.209
3.79,-23.38,0.209
3.80,-23.25,0.209
3.81,-23.11,0.209
3.83,-22.98,0.209
3.84,-22.85,0.210
3.85,-22.71,0.210
3.87,-22.58,0.210
3.88,-22.45,0.210
3.89,-22.31,0.210
3.91,-22.18,0.210
3.92,-22.05,0.210
3.93,-21.91,0.210
3.95,-21.78,0.210
3.96,-21.65,0.211
3.97,-21.51,0.211
3.99,-21.38,0.211
4.00,-21.25,0.211
4.01,-21.11,0.211
4.03,-20.98,0.211
4.04,-20.85,0.211
4.05,-20.71,0.211
4.07,-20.58,0.211
4.08,-20.45,0.212
4.09,-20.31,0.212
4.11,-20.18,0.212
4.12,-20.05,0.212
4.13,-19.91,0.212
4.15,-19.78,0.212
4.16,-19.64,0.212
4.17,-19.51,0.212
4.19,-19.38,0.212
4.20,-19.24,0.212
4.21,-19.11,0.213
4.23,-18.98,0.213
4.24,-18.84,0.213
4.25,-18.71,0.213
4.27,-18.58,0.213
4.28,-18.44,0.213
4.29,-18.31,0.213
4.31,-18.18,0.213
4.32,-18.04,0.214
4.33,-17.91,0.214
4.35,-17.78,0.214
4.36,-17.64,0.214
4.37,-17.51,0.214
4.39,-17.38,0.214
4.40,-17.24,0.214
4.41,-17.11,0.214
4.43,-16.97,0.214
4.44,-16.84,0.215
4.45,-16.71,0.215
4.47,-16.58,0.215
4.48,-16.44,0.215
4.49,-16.31,0.215
4.51,-16.17,0.215
4.52,-16.04,0.215
4.53,-15.91,0.215
4.55,-15.77,0.216
4.56,-15.64,0.216
4.57,-15.51,0.216
4.59,-15.37,0.216
4.60,-15.24,0.216
4.61,-15.11,0.216
4.63,-14.97,0.216
4.64,-14.84,0.216
4.65,-14.71,0.217
4.67,-14.57,0.217
4.68,-14.44,0.217
4.69,-14.31,0.217
4.71,-14.17,0.217
4.72,-14.04,0.217
4.73,-13.91,0.217
4.75,-13.77,0.217
4.76,-13.64,0.217
4.77,-13.50,0.218
4.79,-13.37,0.218
4.80,-13.24,0.218
4.81,-13.11,0.218
4.83,-12.97,0.218
4.84,-12.84,0.218
4.85,-12.71,0.218
4.87,-12.57,0.218
4.88,-12.44,0.218
4.89,-12.31,0.219
4.91,-12.17,0.219
4.92,-12.04,0.219
4.93,-11.90,0.219
4.95,-11.77,0.219
4.96,-11.64,0.219
4.97,-11.50,0.219
4.99,-11.37,0.219
5.00,-11.24,0.220
5.01,-11.10,0.220
5.03,-10.97,0.220
5.04,-10.84,0.220
5.05,-10.70,0.220
5.07,-10.57,0.220
5.08,-10.43,0.220
5.09,-10.30,0.220
5.11,-10.17,0.221
5.12,-10.04,0.221
5.13,-9.90,0.221
5.15,-9.77,0.221
5.16,-9.64,0.221
5.17,-9.50,0.221
5.19,-9.37,0.221
5.20,-9.24,0.222
5.21,-9.10,0.222
5.23,-8.97,0.222
5.24,-8.84,0.222
5.25,-8.70,0.222
5.27,-8.57,0.222
5.28,-8.44,0.222
5.29,-8.30,0.222
5.31,-8.17,0.223
5.32,-8.03,0.223
5.33,-7.90,0.223
5.35,-7.77,0.223
5.36,-7.64,0.223
5.37,-7.50,0.223
5.39,-7.37,0.223
5.40,-7.23,0.223
5.41,-7.10,0.224
5.43,-6.97,0.224
5.44,-6.83,0.224
5.45,-6.70,0.224
5.47,-6.57,0.224
5.48,-6.43,0.224
5.49,-6.30,0.224
5.51,-6.17,0.225
5.52,-6.03,0.225
5.53,-5.90,0.225
5.55,-5.77,0.225
5.56,-5.63,0.225
5.57,-5.50,0.225
5.59,-5.37,0.225
5.60,-5.23,0.226
5.61,-5.10,0.226
5.63,-4.97,0.226
5.64,-4.83,0.226
5.65,-4.70,0.226
5.67,-4.57,0.226
5.68,-4.43,0.226
5.69,-4.30,0.227
5.71,-4.17,0.227
5.72,-4.03,0.227
5.73,-3.90,0.227
5.75,-3.76,0.227
5.76,-3.63,0.227
5.77,-3.50,0.227
5.79,-3.37,0.228
5.80,-3.23,0.228
5.81,-3.10,0.228
5.83,-2.96,0.228
5.84,-2.83,0.228
5.85,-2.70,0.228
5.87,-2.56,0.228
5.88,-2.43,0.229
5.89,-2.30,0.229
5.91,-2.16,0.229
5.92,-2.03,0.229
5.93,-1.90,0.229
5.95,-1.76,0.230
5.96,-1.63,0.230
5.97,-1.50,0.230
5.99,-1.36,0.230
6.00,-1.23,0.230
6.01,-1.10,0.230
6.03,-0.96,0.230
6.04,-0.83,0.231
6.05,-0.70,0.231
6.07,-0.56,0.231
6.08,-0.43,0.231
6.09,-0.30,0.231
6.11,-0.16,0.231
6.12,-0.03,0.232
6.13,0.10,0.232
6.15,0.24,0.232
6.16,0.37,0.232
6.17,0.50,0.232
6.19,0.64,0.232
6.20,0.77,0.232
6.21,0.91,0.233
6.23,1.04,0.233
6.24,1.17,0.233
6.25,1.31,0.233
6.27,1.44,0.233
6.28,1.57,0.233
6.29,1.71,0.233
6.31,1.84,0.234
6.32,1.97,0.234
6.33,2.11,0.234
6.35,2.24,0.234
6.36,2.37,0.234
6.37,2.51,0.234
6.39,2.64,0.235
6.40,2.77,0.235
6.41,2.91,0.235
6.43,3.04,0.235
6.44,3.17,0.235
6.45,3.31,0.235
6.47,3.44,0.236
6.48,3.57,0.236
6.49,3.71,0.236
6.51,3.84,0.236
6.52,3.98,0.236
6.53,4.11,0.236
6.55,4.24,0.237
6.56,4.37,0.237
6.57,4.51,0.237
6.59,4.64,0.237
6.60,4.78,0.237
6.61,4.91,0.237
6.63,5.04,0.238
6.64,5.17,0.238
6.65,5.31,0.238
6.67,5.44,0.238
6.68,5.57,0.238
6.69,5.71,0.238
6.71,5.84,0.239
6.72,5.98,0.239
6.73,6.11,0.239
6.75,6.24,0.239
6.76,6.38,0.239
6.77,6.51,0.239
6.79,6.64,0.240
6.80,6.78,0.240
6.81,6.91,0.240
6.83,7.04,0.240
6.84,7.18,0.240
6.85,7.31,0.241
6.87,7.44,0.241
6.88,7.58,0.241
6.89,7.71,0.241
6.91,7.84,0.241
6.92,7.98,0.241
6.93,8.11,0.242
6.95,8.24,0.242
6.96,8.38,0.242
6.97,8.51,0.242
6.99,8.64,0.242
7.00,8.78,0.242
7.01,8.91,0.243
7.03,9.04,0.243
7.04,9.18,0.243
7.05,9.31,0.243
7.07,9.44,0.243
7.08,9.58,0.244
7.09,9.71,0.244
7.11,9.84,0.244
7.12,9.98,0.244
7.13,10.11,0.244
7.15,10.24,0.245
7.16,10.38,0.245
7.17,10.51,0.245
7.19,10.64,0.245
7.20,10.78,0.245
7.21,10.91,0.246
7.23,11.04,0.246
7.24,11.18,0.246
7.25,11.31,0.246
7.27,11.44,0.246
7.28,11.58,0.247
7.29,11.71,0.247
7.31,11.84,0.247
7.32,11.98,0.247
7.33,12.11,0.247
7.35,12.25,0.248
7.36,12.38,0.248
7.37,12.51,0.248
7.39,12.65,0.248
7.40,12.78,0.249
7.41,12.91,0.249
7.43,13.05,0.249
7.44,13.18,0.249
7.45,13.31,0.250
7.47,13.45,0.250
7.48,13.58,0.250
7.49,13.71,0.250
7.51,13.85,0.250
7.52,13.98,0.251
7.53,14.11,0.251
7.55,14.25,0.251
7.56,14.38,0.251
7.57,14.51,0.251
7.59,14.65,0.252
7.60,14.78,0.252
7.61,14.91,0.252
7.63,15.05,0.252
7.64,15.18,0.252
7.65,15.31,0.253
7.67,15.45,0.253
7.68,15.58,0.253
7.69,15.72,0.253
7.71,15.85,0.254
7.72,15.98,0.254
7.73,16.11,0.254
7.75,16.25,0.254
7.76,16.38,0.254
7.77,16.51,0.255
7.79,16.65,0.255
7.80,16.78,0.255
7.81,16.91,0.255
7.83,17.05,0.255
7.84,17.18,0.256
7.85,17.31,0.256
7.87,17.45,0.256
7.88,17.58,0.256
7.89,17.71,0.257
7.91,17.85,0.257
7.92,17.98,0.257
7.93,18.11,0.257
7.95,18.25,0.258
7.96,18.38,0.258
7.97,18.51,0.258
7.99,18.65,0.258
8.00,18.78,0.258
8.01,18.92,0.259
8.03,19.05,0.259
8.04,19.18,0.259
8.05,19.31,0.259
8.07,19.45,0.260
8.08,19.58,0.260
8.09,19.72,0.260
8.11,19.85,0.260
8.12,19.98,0.261
8.13,20.12,0.261
8.15,20.25,0.261
8.16,20.38,0.261
8.17,20.52,0.262
8.19,20.65,0.262
8.20,20.78,0.262
8.21,20.91,0.262
8.23,21.05,0.263
8.24,21.18,0.263
8.25,21.32,0.263
8.27,21.45,0.264
8.28,21.58,0.264
8.29,21.72,0.264
8.31,21.85,0.264
8.32,21.98,0.265
8.33,22.11,0.265
8.35,22.25,0.265
8.36,22.38,0.265
8.37,22.52,0.266
8.39,22.65,0.266
8.40,22.78,0.266
8.41,22.91,0.266
8.43,23.05,0.267
8.44,23.18,0.267
8.45,23.32,0.267
8.47,23.45,0.268
8.48,23.58,0.268
8.49,23.72,0.268
8.51,23.85,0.269
8.52,23.98,0.269
8.53,24.12,0.269
8.55,24.25,0.269
8.56,24.38,0.270
8.57,24.52,0.270
8.59,24.65,0.270
8.60,24.78,0.271
8.61,24.91,0.271
8.63,25.05,0.271
8.64,25.18,0.272
8.65,25.31,0.272
8.67,25.45,0.272
8.68,25.58,0.273
8.69,25.72,0.273
8.71,25.85,0.273
8.72,25.98,0.274
8.73,26.11,0.274
8.75,26.25,0.274
8.76,26.38,0.275
8.77,26.52,0.275
8.79,26.65,0.275
8.80,26.78,0.275
8.81,26.91,0.276
8.83,27.05,0.276
8.84,27.18,0.276
8.85,27.31,0.277
8.87,27.45,0.277
8.88,27.58,0.277
8.89,27.71,0.278
8.91,27.85,0.278
8.92,27.98,0.278
8.93,28.11,0.279
8.95,28.25,0.279
8.96,28.38,0.280
8.97,28.51,0.280
8.99,28.65,0.280
9.00,28.78,0.281
9.01,28.91,0.281
9.03,29.05,0.282
9.04,29.18,0.282
9.05,29.31,0.283
9.07,29.45,0.283
9.08,29.58,0.284
9.09,29.71,0.284
9.11,29.85,0.284
9.12,29.98,0.285
9.13,30.11,0.285
9.15,30.25,0.285
9.16,30.38,0.286
9.17,30.51,0.286
9.19,30.65,0.287
9.20,30.78,0.287
9.21,30.92,0.288
9.23,31.05,0.288
9.24,31.18,0.289
9.25,31.32,0.289
9.27,31.45,0.290
9.28,31.58,0.290
9.29,31.72,0.291
9.31,31.85,0.291
9.32,31.98,0.291
9.33,32.12,0.292
9.35,32.25,0.292
9.36,32.38,0.293
9.37,32.51,0.293
9.39,32.65,0.294
9.40,32.78,0.294
9.41,32.91,0.295
9.43,33.05,0.295
9.44,33.18,0.296
9.45,33.31,0.296
9.47,33.45,0.297
9.48,33.58,0.298
9.49,33.71,0.299
9.51,33.85,0.299
9.52,33.98,0.300
9.53,34.11,0.301
9.55,34.25,0.302
9.56,34.38,0.302
9.57,34.51,0.303
9.59,34.65,0.304
9.60,34.78,0.304
9.61,34.91,0.305
9.63,35.04,0.306
9.64,35.18,0.306
9.65,35.31,0.307
9.67,35.44,0.308
9.68,35.58,0.308
9.69,35.71,0.309
9.71,35.84,0.310
9.72,35.98,0.311
9.73,36.11,0.312
9.75,36.24,0.313
9.76,36.38,0.314
9.77,36.51,0.315
9.79,36.64,0.316
9.80,36.77,0.317
9.81,36.91,0.318
9.83,37.04,0.319
9.84,37.18,0.320
9.85,37.31,0.321
9.87,37.44,0.322
9.88,37.57,0.323
9.89,37.71,0.325
9.91,37.84,0.326
9.92,37.97,0.327
9.93,38.11,0.328
9.95,38.24,0.330
9.96,38.37,0.331
9.97,38.50,0.333
9.99,38.64,0.334
10.00,38.77,0.336
10.01,38.90,0.337
10.03,39.04,0.339
10.04,39.17,0.340
10.05,39.30,0.341
10.07,39.43,0.343
10.08,39.57,0.345
10.09,39.70,0.347
10.11,39.83,0.349
10.12,39.96,0.350
10.13,40.10,0.353
10.15,40.23,0.355
10.16,40.36,0.357
10.17,40.49,0.359
10.19,40.63,0.362
10.20,40.76,0.364
10.21,40.89,0.366
10.23,41.02,0.369
10.24,41.15,0.372
10.25,41.29,0.374
10.27,41.42,0.377
10.28,41.55,0.379
10.29,41.68,0.383
10.31,41.82,0.385
10.32,41.95,0.388
10.33,42.08,0.390
10.35,42.21,0.393
10.36,42.34,0.396
10.37,42.48,0.398
10.39,42.61,0.401
10.40,42.74,0.403
10.41,42.87,0.405
10.43,43.00,0.407
10.44,43.14,0.409
10.45,43.27,0.410
10.47,43.40,0.412
10.48,43.53,0.413
10.49,43.67,0.414
10.51,43.80,0.414
10.52,43.93,0.415
10.53,44.07,0.415
10.55,44.20,0.415
10.56,44.33,0.415
10.57,44.47,0.415
10.59,44.60,0.415
10.60,44.73,0.415
10.61,44.87,0.415
10.63,45.00,0.414
10.64,45.14,0.413
10.65,45.27,0.411
10.67,45.40,0.409
10.68,45.54,0.407
10.69,45.67,0.405
10.71,45.81,0.404
10.72,45.94,0.402
10.73,46.07,0.401
10.75,46.21,0.399
10.76,46.34,0.398
10.77,46.48,0.397
10.79,46.61,0.396
10.80,46.75,0.395
10.81,46.88,0.394
10.83,47.01,0.393
10.84,47.15,0.392
10.85,47.28,0.392
10.87,47.42,0.391
10.88,47.55,0.391
10.89,47.68,0.391
10.91,47.82,0.391
10.92,47.95,0.391
10.93,48.09,0.390
10.95,48.22,0.390
10.96,48.35,0.390
10.97,48.48,0.390
10.99,48.62,0.390
11.00,48.75,0.390
11.01,48.89,0.390
11.03,49.02,0.390
11.04,49.15,0.390
11.05,49.29,0.390
11.07,49.42,0.390
11.08,49.55,0.391
11.09,49.69,0.391
11.11,49.82,0.391
11.12,49.95,0.391
11.13,50.09,0.392
11.15,50.22,0.392
11.16,50.35,0.393
11.17,50.49,0.393
11.19,50.62,0.394
11.20,50.75,0.394
11.21,50.89,0.394
11.23,51.02,0.395
11.24,51.15,0.395
11.25,51.29,0.396
11.27,51.42,0.396
11.28,51.55,0.397
11.29,51.68,0.398
11.31,51.82,0.398
11.32,51.95,0.399
11.33,52.08,0.399
11.35,52.22,0.400
11.36,52.35,0.401
11.37,52.48,0.402
11.39,52.62,0.403
11.40,52.75,0.403
11.41,52.88,0.404
11.43,53.02,0.405
11.44,53.15,0.406
11.45,53.28,0.406
11.47,53.42,0.407
11.48,53.55,0.408
11.49,53.68,0.408
11.51,53.82,0.409
11.52,53.95,0.410
11.53,54.08,0.411
11.55,54.22,0.411
11.56,54.35,0.412
11.57,54.48,0.413
11.59,54.61,0.414
11.60,54.75,0.415
11.61,54.88,0.416
11.63,55.01,0.416
11.64,55.15,0.417
11.65,55.28,0.418
11.67,55.41,0.419
11.68,55.55,0.420
11.69,55.68,0.421
11.71,55.81,0.421
11.72,55.95,0.422
11.73,56.08,0.423
11.75,56.21,0.424
11.76,56.34,0.425
11.77,56.48,0.426
11.79,56.61,0.427
11.80,56.74,0.428
11.81,56.88,0.428
11.83,57.01,0.430
11.84,57.14,0.431
11.85,57.27,0.431
11.87,57.41,0.432
11.88,57.54,0.433
11.89,57.67,0.434
11.91,57.81,0.435
11.92,57.94,0.436
11.93,58.07,0.438
11.95,58.21,0.439
11.96,58.34,0.440
11.97,58.47,0.441
11.99,58.61,0.442
12.00,58.74,0.443
12.01,58.87,0.444
12.03,59.00,0.445
12.04,59.14,0.447
12.05,59.27,0.448
12.07,59.40,0.449
12.08,59.54,0.450
12.09,59.67,0.451
12.11,59.80,0.452
12.12,59.93,0.453
12.13,60.07,0.455
12.15,60.20,0.457
12.16,60.33,0.458
12.17,60.47,0.458
12.19,60.60,0.460
12.20,60.73,0.461
12.21,60.87,0.462
12.23,61.00,0.463
12.24,61.13,0.465
12.25,61.26,0.467
12.27,61.40,0.468
12.28,61.53,0.470
12.29,61.66,0.471
12.31,61.79,0.474
12.32,61.93,0.475
12.33,62.06,0.476
12.35,62.19,0.478
12.36,62.33,0.479
12.37,62.46,0.481
12.39,62.59,0.483
12.40,62.72,0.484
12.41,62.86,0.486
12.43,62.99,0.487
12.44,63.12,0.489
12.45,63.25,0.491
12.47,63.39,0.493
12.48,63.52,0.495
12.49,63.65,0.497
12.51,63.78,0.499
12.52,63.92,0.500
12.53,64.05,0.503
12.55,64.18,0.505
12.56,64.32,0.507
12.57,64.45,0.510
12.59,64.58,0.511
12.60,64.71,0.514
12.61,64.85,0.516
12.63,64.98,0.519
12.64,65.11,0.521
12.65,65.24,0.524
12.67,65.37,0.526
12.68,65.51,0.529
12.69,65.64,0.532
12.71,65.77,0.534
12.72,65.90,0.537
12.73,66.04,0.540
12.75,66.17,0.543
12.76,66.30,0.546
12.77,66.43,0.549
12.79,66.56,0.552
12.80,66.70,0.557
12.81,66.83,0.560
12.83,66.96,0.563
12.84,67.09,0.568
12.85,67.22,0.571
12.87,67.36,0.575
12.88,67.49,0.580
12.89,67.62,0.583
12.91,67.75,0.587
12.92,67.88,0.592
12.93,68.01,0.597
12.95,68.14,0.602
12.96,68.27,0.608
12.97,68.41,0.612
12.99,68.54,0.618
13.00,68.67,0.623
13.01,68.80,0.630
13.03,68.93,0.636
13.04,69.06,0.642
13.05,69.19,0.649
13.07,69.32,0.656
13.08,69.45,0.665
13.09,69.58,0.673
13.11,69.71,0.682
13.12,69.84,0.691
13.13,69.97,0.701
13.15,70.10,0.713
13.16,70.23,0.724
13.17,70.35,0.736
13.19,70.48,0.751
13.20,70.61,0.765
13.21,70.74,0.781
13.23,70.86,0.797
13.24,70.99,0.817
13.25,71.11,0.838
13.27,71.24,0.858
13.28,71.36,0.879
13.29,71.49,0.897
13.31,71.61,0.914
13.32,71.74,0.928
13.33,71.86,0.939
13.35,71.99,0.947
13.36,72.12,0.952
13.37,72.25,0.952
13.39,72.38,0.948
13.40,72.51,0.941
13.41,72.64,0.930
13.43,72.78,0.916
13.44,72.92,0.900
13.45,73.05,0.882
13.47,73.20,0.863
13.48,73.34,0.843
13.49,73.48,0.822
13.51,73.62,0.801
13.52,73.76,0.778
13.53,73.91,0.756
13.55,74.05,0.735
13.56,74.19,0.716
13.57,74.34,0.698
13.59,74.48,0.679
13.60,74.62,0.660
13.61,74.77,0.642
13.63,74.91,0.625
13.64,75.05,0.610
13.65,75.20,0.596
13.67,75.34,0.584
13.68,75.48,0.574
13.69,75.62,0.563
13.71,75.76,0.554
13.72,75.90,0.546
13.73,76.03,0.539
13.75,76.17,0.533
13.76,76.31,0.527
13.77,76.45,0.522
13.79,76.58,0.517
13.80,76.72,0.512
13.81,76.86,0.507
13.83,76.99,0.504
13.84,77.13,0.500
13.85,77.26,0.496
13.87,77.40,0.493
13.88,77.53,0.491
13.89,77.67,0.490
13.91,77.80,0.488
13.92,77.94,0.487
13.93,78.07,0.487
13.95,78.21,0.486
13.96,78.34,0.486
13.97,78.48,0.486
13.99,78.61,0.486
14.00,78.74,0.486
14.01,78.88,0.486
14.03,79.01,0.486
14.04,79.14,0.486
14.05,79.28,0.487
14.07,79.41,0.487
14.08,79.54,0.487
14.09,79.68,0.487
14.11,79.81,0.488
14.12,79.94,0.489
14.13,80.08,0.489
14.15,80.21,0.490
14.16,80.34,0.491
14.17,80.48,0.491
14.19,80.61,0.492
14.20,80.74,0.492
14.21,80.88,0.492
14.23,81.01,0.492
14.24,81.14,0.492
14.25,81.28,0.492
14.27,81.41,0.493
14.28,81.54,0.493
14.29,81.68,0.493
14.31,81.81,0.493
14.32,81.94,0.493
14.33,82.08,0.493
14.35,82.21,0.493
14.36,82.34,0.493
14.37,82.48,0.493
14.39,82.61,0.492
14.40,82.75,0.492
14.41,82.88,0.492
14.43,83.01,0.491
14.44,83.15,0.491
14.45,83.28,0.490
14.47,83.41,0.490
14.48,83.55,0.489
14.49,83.68,0.489
14.51,83.82,0.489
14.52,83.95,0.489
14.53,84.08,0.488
14.55,84.22,0.488
14.56,84.35,0.488
14.57,84.48,0.488
14.59,84.62,0.488
14.60,84.75,0.488
14.61,84.88,0.487
14.63,85.02,0.487
14.64,85.15,0.487
14.65,85.28,0.486
14.67,85.42,0.486
14.68,85.55,0.486
14.69,85.69,0.485
14.71,85.82,0.484
14.72,85.95,0.484
14.73,86.09,0.483
14.75,86.22,0.482
14.76,86.35,0.481
14.77,86.49,0.480
14.79,86.62,0.480
14.80,86.76,0.479
14.81,86.89,0.479
14.83,87.02,0.479
14.84,87.16,0.479
14.85,87.29,0.479
14.87,87.42,0.478
14.88,87.56,0.478
14.89,87.69,0.478
14.91,87.83,0.478
14.92,87.96,0.478
14.93,88.09,0.478
14.95,88.23,0.478
14.96,88.36,0.478
14.97,88.49,0.478
14.99,88.63,0.478
15.00,88.76,0.478
15.01,88.89,0.478
15.03,89.03,0.478
15.04,89.16,0.478
15.05,89.29,0.479
15.07,89.43,0.479
15.08,89.56,0.479
15.09,89.69,0.479
15.11,89.83,0.479
15.12,89.96,0.479
15.13,90.09,0.479
15.15,90.23,0.479
15.16,90.36,0.480
15.17,90.49,0.480
15.19,90.62,0.480
15.20,90.76,0.480
15.21,90.89,0.481
15.23,91.03,0.483
15.24,91.16,0.487
15.25,91.29,0.489
15.27,91.42,0.490
15.28,91.56,0.491
15.29,91.69,0.492
15.31,91.82,0.492
15.32,91.96,0.492
15.33,92.09,0.493
15.35,92.22,0.493
15.36,92.35,0.493
15.37,92.49,0.494
15.39,92.62,0.494
15.40,92.76,0.495
15.41,92.89,0.495
15.43,93.02,0.495
15.44,93.16,0.495
15.45,93.29,0.495
15.47,93.42,0.495
15.48,93.56,0.495
15.49,93.69,0.496
15.51,93.82,0.496
15.52,93.96,0.496
15.53,94.09,0.495
15.55,94.22,0.495
15.56,94.36,0.495
15.57,94.49,0.495
15.59,94.62,0.494
15.60,94.76,0.494
15.61,94.89,0.493
15.63,95.03,0.492
15.64,95.16,0.491
15.65,95.29,0.490
15.67,95.43,0.488
15.68,95.56,0.486
15.69,95.70,0.485
15.71,95.83,0.485
15.72,95.96,0.484
15.73,96.10,0.484
15.75,96.23,0.484
15.76,96.37,0.483
15.77,96.50,0.483
15.79,96.63,0.483
15.80,96.77,0.483
15.81,96.90,0.483
15.83,97.03,0.483
15.84,97.17,0.483
15.85,97.30,0.483
15.87,97.43,0.483
15.88,97.57,0.483
15.89,97.70,0.483
15.91,97.83,0.483
15.92,97.97,0.482
15.93,98.10,0.481
15.95,98.24,0.479
15.96,98.37,0.478
15.97,98.51,0.478
15.99,98.64,0.477
16.00,98.77,0.476
16.01,98.91,0.473
16.03,99.04,0.472
16.04,99.18,0.469
16.05,99.31,0.467
16.07,99.44,0.466
16.08,99.58,0.465
16.09,99.71,0.463
16.11,99.85,0.462
16.12,99.98,0.461
16.13,100.12,0.460
16.15,100.25,0.460
16.16,100.38,0.459
16.17,100.52,0.459
16.19,100.65,0.459
16.20,100.79,0.458
16.21,100.92,0.458
16.23,101.05,0.458
16.24,101.18,0.458
16.25,101.32,0.457
16.27,101.45,0.456
16.28,101.59,0.453
16.29,101.72,0.449
16.31,101.86,0.446
16.32,101.99,0.443
16.33,102.13,0.438
16.35,102.26,0.434
16.36,102.39,0.431
16.37,102.53,0.428
16.39,102.66,0.426
16.40,102.80,0.425
16.41,102.93,0.423
16.43,103.07,0.419
16.44,103.20,0.413
16.45,103.34,0.409
16.47,103.47,0.405
16.48,103.61,0.402
16.49,103.74,0.400
16.51,103.88,0.396
16.52,104.01,0.393
16.53,104.15,0.390
16.55,104.29,0.386
16.56,104.42,0.385
16.57,104.55,0.388
16.59,104.69,0.384
16.60,104.82,0.384
16.61,104.96,0.384
16.63,105.09,0.382
16.64,105.22,0.384
16.65,105.36,0.381
16.67,105.49,0.381
16.68,105.63,0.383
16.69,105.76,0.380
16.71,105.90,0.379
16.72,106.03,0.380
16.73,106.16,0.382
16.75,106.29,0.382
16.76,106.43,0.384
16.77,106.56,0.383
16.79,106.69,0.383
16.80,106.83,0.383
16.81,106.96,0.382
16.83,107.09,0.381
16.84,107.23,0.387
16.85,107.36,0.388
16.87,107.49,0.388
16.88,107.63,0.388
16.89,107.76,0.388
16.91,107.89,0.388
16.92,108.03,0.389
16.93,108.16,0.389
16.95,108.29,0.390
16.96,108.42,0.391
16.97,108.56,0.392
16.99,108.69,0.393
17.00,108.82,0.393
17.01,108.96,0.393
17.03,109.09,0.395
17.04,109.22,0.396
17.05,109.35,0.396
17.07,109.49,0.397
17.08,109.62,0.400
17.09,109.75,0.403
17.11,109.89,0.404
17.12,110.02,0.406
17.13,110.15,0.408
17.15,110.29,0.410
17.16,110.42,0.412
17.17,110.55,0.413
17.19,110.68,0.413
17.20,110.82,0.407
17.21,110.95,0.398
17.23,111.09,0.394
17.24,111.22,0.391
17.25,111.36,0.389
17.27,111.49,0.389
17.28,111.63,0.390
17.29,111.76,0.387
17.31,111.89,0.385
17.32,112.03,0.384
17.33,112.16,0.383
17.35,112.30,0.383
17.36,112.43,0.382
17.37,112.57,0.382
17.39,112.70,0.381
17.40,112.83,0.381
17.41,112.97,0.381
17.43,113.10,0.381
17.44,113.23,0.381
17.45,113.37,0.381
17.47,113.50,0.381
17.48,113.64,0.381
17.49,113.77,0.380
17.51,113.90,0.380
17.52,114.04,0.380
17.53,114.17,0.380
17.55,114.30,0.389
17.56,114.43,0.389
17.57,114.57,0.389
17.59,114.70,0.389
17.60,114.83,0.388
17.61,114.97,0.392
17.63,115.10,0.395
17.64,115.23,0.393
17.65,115.37,0.392
17.67,115.50,0.391
17.68,115.63,0.389
17.69,115.77,0.389
17.71,115.90,0.388
17.72,116.04,0.388
17.73,116.17,0.388
17.75,116.30,0.388
17.76,116.44,0.387
17.77,116.57,0.387
17.79,116.70,0.387
17.80,116.84,0.387
17.81,116.97,0.387
17.83,117.10,0.387
17.84,117.24,0.387
17.85,117.37,0.387
17.87,117.50,0.387
17.88,117.64,0.387
17.89,117.77,0.387
17.91,117.90,0.387
17.92,118.04,0.387
17.93,118.17,0.388
17.95,118.30,0.388
17.96,118.44,0.388
17.97,118.57,0.388
17.99,118.70,0.388
18.00,118.84,0.388
18.01,118.97,0.388
18.03,119.10,0.388
18.04,119.24,0.388
18.05,119.37,0.388
18.07,119.50,0.389
18.08,119.62,0.952
18.09,118.89,8.342
18.11,118.20,6.922
18.12,118.08,5.763
18.13,118.06,5.543
18.15,118.12,5.302
18.16,118.23,5.073
18.17,118.38,4.867
18.19,118.55,4.677
18.20,118.73,4.499
18.21,118.93,4.328
18.23,119.13,4.165
18.24,119.33,4.009
18.25,119.53,3.861
18.27,119.73,3.722
18.28,119.93,3.588
18.29,120.13,3.462
18.31,120.33,3.342
18.32,120.52,3.227
18.33,120.72,3.117
18.35,120.91,3.015
18.36,121.09,2.944
18.37,121.27,2.869
18.39,121.45,2.770
18.40,121.63,2.676
18.41,121.81,2.588
18.43,121.98,2.504
18.44,122.16,2.423
18.45,122.33,2.348
18.47,122.51,2.273
18.48,122.68,2.202
18.49,122.85,2.135
18.51,123.02,2.071
18.52,123.18,2.008
18.53,123.35,1.949
18.55,123.51,1.892
18.56,123.68,1.838
18.57,123.84,1.785
18.59,124.00,1.735
18.60,124.16,1.686
18.61,124.32,1.640
18.63,124.48,1.595
18.64,124.63,1.553
18.65,124.79,1.512
18.67,124.94,1.473
18.68,125.10,1.435
18.69,125.25,1.400
18.71,125.40,1.364
18.72,125.55,1.331
18.73,125.70,1.299
18.75,125.85,1.269
18.76,126.00,1.238
18.77,126.15,1.210
18.79,126.30,1.182
18.80,126.44,1.155
18.81,126.59,1.129
18.83,126.74,1.105
18.84,126.88,1.081
18.85,127.03,1.058
18.87,127.17,1.035
18.88,127.32,1.015
18.89,127.46,0.994
18.91,127.61,0.974
18.92,127.75,0.955
18.93,127.89,0.936
18.95,128.04,
18.96,128.18,
18.97,128.32,
18.99,,
18.99,,

[step]
Ramp 10.00 °C/min to -60.00 °C
Time,Temperature,Heat Flow (Normalized)
min,°C,W/g
20.99,130.12,0.044
21.01,130.12,0.043
21.02,130.11,0.042
21.03,130.11,0.042
21.05,130.10,0.041
21.06,130.08,0.042
21.07,130.04,0.048
21.09,129.99,0.055
21.10,129.93,0.058
21.11,129.85,0.058
21.13,129.76,0.055
21.14,129.66,0.040
21.15,129.55,0.026
21.17,129.44,0.009
21.18,129.32,-0.007
21.19,129.21,-0.023
21.21,129.09,-0.037
21.22,128.97,-0.052
21.23,128.85,-0.063
21.25,128.73,-0.074
21.26,128.61,-0.084
21.27,128.48,-0.093
21.29,128.36,-0.101
21.30,128.23,-0.109
21.31,128.10,-0.116
21.33,127.98,-0.123
21.34,127.85,-0.128
21.35,127.72,-0.133
21.37,127.59,-0.138
21.38,127.46,-0.143
21.39,127.33,-0.146
21.41,127.21,-0.150
21.42,127.08,-0.153
21.43,126.95,-0.156
21.45,126.82,-0.158
21.46,126.68,-0.161
21.47,126.56,-0.163
21.49,126.42,-0.165
21.50,126.29,-0.168
21.51,126.16,-0.169
21.53,126.03,-0.171
21.54,125.90,-0.173
21.55,125.77,-0.173
21.57,125.64,-0.175
21.58,125.50,-0.176
21.59,125.37,-0.178
21.61,125.24,-0.179
21.62,125.11,-0.180
21.63,124.98,-0.181
21.65,124.85,-0.182
21.66,124.71,-0.182
21.67,124.58,-0.183
21.69,124.45,-0.184
21.70,124.32,-0.184
21.71,124.19,-0.185
21.73,124.05,-0.185
21.74,123.92,-0.186
21.75,123.79,-0.186
21.77,123.66,-0.187
21.78,123.52,-0.187
21.79,123.39,-0.188
21.81,123.26,-0.189
21.82,123.13,-0.189
21.83,122.99,-0.190
21.85,122.86,-0.190
21.86,122.73,-0.190
21.87,122.60,-0.190
21.89,122.46,-0.191
21.90,122.33,-0.191
21.91,122.20,-0.192
21.93,122.06,-0.192
21.94,121.93,-0.192
21.95,121.80,-0.192
21.97,121.67,-0.193
21.98,121.53,-0.193
21.99,121.40,-0.193
22.01,121.27,-0.193
22.02,121.14,-0.194
22.03,121.00,-0.194
22.05,120.87,-0.194
22.06,120.74,-0.194
22.07,120.60,-0.194
22.09,120.47,-0.195
22.10,120.34,-0.195
22.11,120.21,-0.195
22.13,120.07,-0.195
22.14,119.94,-0.196
22.15,119.81,-0.196
22.17,119.67,-0.196
22.18,119.54,-0.196
22.19,119.41,-0.196
22.21,119.28,-0.197
22.22,119.14,-0.197
22.23,119.01,-0.197
22.25,118.88,-0.197
22.26,118.74,-0.197
22.27,118.61,-0.198
22.29,118.48,-0.198
22.30,118.34,-0.198
22.31,118.21,-0.198
22.33,118.08,-0.198
22.34,117.95,-0.198
22.35,117.81,-0.198
22.37,117.68,-0.199
22.38,117.55,-0.199
22.39,117.41,-0.199
22.41,117.28,-0.199
22.42,117.15,-0.199
22.43,117.01,-0.199
22.45,116.88,-0.200
22.46,116.75,-0.200
22.47,116.61,-0.200
22.49,116.48,-0.200
22.50,116.35,-0.200
22.51,116.21,-0.200
22.53,116.08,-0.200
22.54,115.95,-0.200
22.55,115.81,-0.200
22.57,115.68,-0.200
22.58,115.55,-0.201
22.59,115.41,-0.201
22.61,115.28,-0.201
22.62,115.15,-0.201
22.63,115.02,-0.201
22.65,114.88,-0.201
22.66,114.75,-0.201
22.67,114.62,-0.201
22.69,114.48,-0.201
22.70,114.35,-0.201
22.71,114.22,-0.201
22.73,114.08,-0.201
22.74,113.95,-0.201
22.75,113.82,-0.201
22.77,113.68,-0.202
22.78,113.55,-0.202
22.79,113.42,-0.202
22.81,113.28,-0.202
22.82,113.15,-0.202
22.83,113.02,-0.202
22.85,112.88,-0.202
22.86,112.75,-0.202
22.87,112.62,-0.202
22.89,112.48,-0.202
22.90,112.35,-0.202
22.91,112.22,-0.202
22.93,112.08,-0.202
22.94,111.95,-0.202
22.95,111.82,-0.202
22.97,111.69,-0.202
22.98,111.55,-0.202
22.99,111.42,-0.202
23.01,111.28,-0.202
23.02,111.15,-0.202
23.03,111.02,-0.202
23.05,110.89,-0.202
23.06,110.75,-0.202
23.07,110.62,-0.202
23.09,110.49,-0.202
23.10,110.35,-0.202
23.11,110.22,-0.202
23.13,110.09,-0.202
23.14,109.95,-0.202
23.15,109.82,-0.202
23.17,109.69,-0.202
23.18,109.55,-0.202
23.19,109.42,-0.202
23.21,109.29,-0.202
23.22,109.15,-0.202
23.23,109.02,-0.202
23.25,108.89,-0.202
23.26,108.75,-0.202
23.27,108.62,-0.202
23.29,108.49,-0.202
23.30,108.35,-0.202
23.31,108.22,-0.202
23.33,108.09,-0.202
23.34,107.95,-0.202
23.35,107.82,-0.202
23.37,107.69,-0.202
23.38,107.56,-0.202
23.39,107.42,-0.202
23.41,107.29,-0.202
23.42,107.16,-0.201
23.43,107.02,-0.201
23.45,106.89,-0.201
23.46,106.75,-0.201
23.47,106.62,-0.201
23.49,106.49,-0.201
23.50,106.36,-0.201
23.51,106.22,-0.201
23.53,106.09,-0.201
23.54,105.95,-0.201
23.55,105.82,-0.201
23.57,105.69,-0.201
23.58,105.55,-0.201
23.59,105.42,-0.201
23.61,105.29,-0.201
23.62,105.15,-0.201
23.63,105.02,-0.201
23.65,104.89,-0.201
23.66,104.75,-0.201
23.67,104.62,-0.201
23.69,104.49,-0.201
23.70,104.35,-0.200
23.71,104.22,-0.200
23.73,104.09,-0.200
23.74,103.95,-0.200
23.75,103.82,-0.200
23.77,103.69,-0.200
23.78,103.56,-0.200
23.79,103.42,-0.200
23.81,103.29,-0.200
23.82,103.15,-0.200
23.83,103.02,-0.200
23.85,102.89,-0.200
23.86,102.75,-0.200
23.87,102.62,-0.200
23.89,102.49,-0.199
23.90,102.35,-0.199
23.91,102.22,-0.199
23.93,102.09,-0.199
23.94,101.95,-0.199
23.95,101.82,-0.199
23.97,101.69,-0.199
23.98,101.55,-0.199
23.99,101.42,-0.199
24.01,101.29,-0.199
24.02,101.15,-0.199
24.03,101.02,-0.199
24.05,100.89,-0.198
24.06,100.76,-0.198
24.07,100.62,-0.198
24.09,100.49,-0.198
24.10,100.35,-0.198
24.11,100.22,-0.198
24.13,100.09,-0.198
24.14,99.96,-0.198
24.15,99.82,-0.198
24.17,99.69,-0.198
24.18,99.55,-0.197
24.19,99.42,-0.197
24.21,99.29,-0.197
24.22,99.16,-0.197
24.23,99.02,-0.197
24.25,98.89,-0.197
24.26,98.75,-0.197
24.27,98.62,-0.197
24.29,98.49,-0.197
24.30,98.35,-0.197
24.31,98.22,-0.196
24.33,98.09,-0.196
24.34,97.95,-0.196
24.35,97.82,-0.196
24.37,97.69,-0.196
24.38,97.55,-0.196
24.39,97.42,-0.196
24.41,97.29,-0.196
24.42,97.15,-0.195
24.43,97.02,-0.195
24.45,96.89,-0.195
24.46,96.75,-0.195
24.47,96.62,-0.195
24.49,96.49,-0.195
24.50,96.35,-0.195
24.51,96.22,-0.195
24.53,96.09,-0.195
24.54,95.95,-0.194
24.55,95.82,-0.194
24.57,95.69,-0.194
24.58,95.55,-0.194
24.59,95.42,-0.194
24.61,95.29,-0.194
24.62,95.15,-0.194
24.63,95.02,-0.193
24.65,94.89,-0.193
24.66,94.76,-0.193
24.67,94.62,-0.193
24.69,94.49,-0.193
24.70,94.35,-0.193
24.71,94.22,-0.193
24.73,94.09,-0.192
24.74,93.95,-0.192
24.75,93.82,-0.192
24.77,93.69,-0.192
24.78,93.55,-0.192
24.79,93.42,-0.192
24.81,93.29,-0.192
24.82,93.15,-0.191
24.83,93.02,-0.191
24.85,92.89,-0.191
24.86,92.75,-0.191
24.87,92.62,-0.191
24.89,92.49,-0.191
24.90,92.35,-0.191
24.91,92.22,-0.190
24.93,92.09,-0.190
24.94,91.95,-0.190
24.95,91.82,-0.190
24.97,91.69,-0.190
24.98,91.55,-0.190
24.99,91.42,-0.189
25.01,91.29,-0.189
25.02,91.15,-0.189
25.03,91.02,-0.189
25.05,90.89,-0.189
25.06,90.75,-0.189
25.07,90.62,-0.189
25.09,90.49,-0.188
25.10,90.35,-0.188
25.11,90.22,-0.188
25.13,90.08,-0.188
25.14,89.95,-0.187
25.15,89.82,-0.187
25.17,89.68,-0.187
25.18,89.55,-0.187
25.19,89.42,-0.187
25.21,89.28,-0.187
25.22,89.15,-0.187
25.23,89.01,-0.187
25.25,88.88,-0.186
25.26,88.75,-0.186
25.27,88.61,-0.186
25.29,88.48,-0.186
25.30,88.35,-0.186
25.31,88.22,-0.186
25.33,88.09,-0.186
25.34,87.95,-0.185
25.35,87.82,-0.185
25.37,87.69,-0.185
25.38,87.56,-0.184
25.39,87.42,-0.184
25.41,87.29,-0.184
25.42,87.16,-0.184
25.43,87.02,-0.184
25.45,86.89,-0.183
25.46,86.75,-0.183
25.47,86.62,-0.183
25.49,86.49,-0.183
25.50,86.35,-0.183
25.51,86.22,-0.183
25.53,86.09,-0.182
25.54,85.95,-0.182
25.55,85.82,-0.182
25.57,85.69,-0.182
25.58,85.55,-0.182
25.59,85.42,-0.182
25.61,85.29,-0.181
25.62,85.15,-0.181
25.63,85.02,-0.181
25.65,84.89,-0.181
25.66,84.75,-0.181
25.67,84.62,-0.181
25.69,84.49,-0.181
25.70,84.35,-0.180
25.71,84.22,-0.180
25.73,84.09,-0.180
25.74,83.95,-0.180
25.75,83.82,-0.180
25.77,83.69,-0.180
25.78,83.55,-0.180
25.79,83.42,-0.179
25.81,83.29,-0.179
25.82,83.15,-0.179
25.83,83.02,-0.179
25.85,82.89,-0.179
25.86,82.75,-0.179
25.87,82.62,-0.179
25.89,82.49,-0.178
25.90,82.35,-0.178
25.91,82.22,-0.178
25.93,82.08,-0.178
25.94,81.95,-0.178
25.95,81.82,-0.178
25.97,81.68,-0.177
25.98,81.55,-0.177
25.99,81.42,-0.177
26.01,81.28,-0.177
26.02,81.15,-0.177
26.03,81.02,-0.177
26.05,80.88,-0.177
26.06,80.75,-0.176
26.07,80.62,-0.176
26.09,80.48,-0.176
26.10,80.35,-0.176
26.11,80.22,-0.176
26.13,80.08,-0.176
26.14,79.95,-0.176
26.15,79.82,-0.175
26.17,79.68,-0.175
26.18,79.55,-0.175
26.19,79.42,-0.175
26.21,79.28,-0.175
26.22,79.15,-0.175
26.23,79.02,-0.175
26.25,78.88,-0.174
26.26,78.75,-0.174
26.27,78.62,-0.174
26.29,78.48,-0.174
26.30,78.35,-0.174
26.31,78.22,-0.174
26.33,78.08,-0.173
26.34,77.95,-0.173
26.35,77.82,-0.173
26.37,77.68,-0.173
26.38,77.55,-0.173
26.39,77.42,-0.173
26.41,77.28,-0.173
26.42,77.15,-0.172
26.43,77.02,-0.172
26.45,76.88,-0.172
26.46,76.75,-0.172
26.47,76.62,-0.172
26.49,76.48,-0.172
26.50,76.35,-0.171
26.51,76.22,-0.171
26.53,76.08,-0.171
26.54,75.95,-0.171
26.55,75.82,-0.171
26.57,75.68,-0.171
26.58,75.55,-0.170
26.59,75.42,-0.170
26.61,75.28,-0.170
26.62,75.15,-0.170
26.63,75.02,-0.170
26.65,74.88,-0.170
[...]
88.49,-16.37,0.084
88.50,-16.23,0.084
88.51,-16.10,0.084
88.53,-15.97,0.084
88.54,-15.83,0.084
88.55,-15.70,0.084
88.57,-15.57,0.084
88.58,-15.43,0.084
88.60,-15.30,0.084
88.61,-15.17,0.085
88.62,-15.03,0.085
88.64,-14.90,0.085
88.65,-14.77,0.085
88.66,-14.63,0.085
88.68,-14.50,0.085
88.69,-14.37,0.085
88.70,-14.23,0.085
88.71,-14.10,0.085
88.73,-13.97,0.085
88.74,-13.83,0.085
88.75,-13.70,0.085
88.77,-13.57,0.085
88.78,-13.43,0.085
88.80,-13.30,0.085
88.81,-13.17,0.085
88.82,-13.03,0.085
88.84,-12.90,0.085
88.85,-12.76,0.085
88.86,-12.63,0.085
88.88,-12.50,0.085
88.89,-12.36,0.085
88.90,-12.23,0.085
88.91,-12.10,0.085
88.93,-11.96,0.086
88.94,-11.83,0.086
88.95,-11.70,0.086
88.97,-11.56,0.086
88.98,-11.43,0.086
89.00,-11.30,0.086
89.01,-11.16,0.086
89.02,-11.03,0.086
89.04,-10.90,0.086
89.05,-10.76,0.086
89.06,-10.63,0.086
89.08,-10.49,0.086
89.09,-10.36,0.086
89.10,-10.23,0.086
89.11,-10.10,0.086
89.13,-9.96,0.086
89.14,-9.83,0.086
89.15,-9.70,0.086
89.17,-9.56,0.086
89.18,-9.43,0.086
89.20,-9.30,0.087
89.21,-9.16,0.087
89.22,-9.03,0.087
89.24,-8.90,0.087
89.25,-8.76,0.087
89.26,-8.63,0.087
89.28,-8.49,0.087
89.29,-8.36,0.087
89.30,-8.23,0.087
89.31,-8.09,0.087
89.33,-7.96,0.087
89.34,-7.83,0.087
89.35,-7.69,0.087
89.37,-7.56,0.087
89.38,-7.43,0.087
89.40,-7.29,0.087
89.41,-7.16,0.087
89.42,-7.03,0.087
89.44,-6.89,0.087
89.45,-6.76,0.088
89.46,-6.62,0.088
89.48,-6.49,0.088
89.49,-6.36,0.088
89.50,-6.22,0.088
89.51,-6.09,0.088
89.53,-5.96,0.088
89.54,-5.82,0.088
89.55,-5.69,0.088
89.57,-5.56,0.088
89.58,-5.42,0.088
89.60,-5.29,0.088
89.61,-5.16,0.088
89.62,-5.02,0.088
89.64,-4.89,0.088
89.65,-4.76,0.088
89.66,-4.62,0.088
89.68,-4.49,0.088
89.69,-4.36,0.089
89.70,-4.22,0.089
89.71,-4.09,0.089
89.73,-3.96,0.089
89.74,-3.82,0.089
89.75,-3.69,0.089
89.77,-3.56,0.089
89.78,-3.42,0.089
89.80,-3.29,0.089
89.81,-3.16,0.089
89.82,-3.02,0.089
89.84,-2.89,0.089
89.85,-2.76,0.089
89.86,-2.62,0.089
89.88,-2.49,0.089
89.89,-2.35,0.089
89.90,-2.22,0.090
89.91,-2.09,0.090
89.93,-1.95,0.090
89.94,-1.82,0.090
89.95,-1.69,0.090
89.97,-1.55,0.090
89.98,-1.42,0.090
90.00,-1.29,0.090
90.01,-1.15,0.090
90.02,-1.02,0.090
90.04,-0.89,0.090
90.05,-0.75,0.090
90.06,-0.62,0.090
90.08,-0.49,0.090
90.09,-0.35,0.091
90.10,-0.22,0.091
90.11,-0.08,0.091
90.13,0.05,0.091
90.14,0.18,0.091
90.15,0.32,0.091
90.17,0.45,0.091
90.18,0.58,0.091
90.20,0.71,0.091
90.21,0.85,0.091
90.22,0.98,0.091
90.24,1.12,0.091
90.25,1.25,0.091
90.26,1.38,0.091
90.28,1.52,0.091
90.29,1.65,0.091
90.30,1.78,0.092
90.31,1.92,0.092
90.33,2.05,0.092
90.34,2.18,0.092
90.35,2.32,0.092
90.37,2.45,0.092
90.38,2.59,0.092
90.40,2.72,0.092
90.41,2.85,0.092
90.42,2.99,0.092
90.44,3.12,0.092
90.45,3.25,0.092
90.46,3.38,0.092
90.48,3.52,0.092
90.49,3.65,0.093
90.50,3.78,0.093
90.51,3.92,0.093
90.53,4.05,0.093
90.54,4.19,0.093
90.55,4.32,0.093
90.57,4.45,0.093
90.58,4.59,0.093
90.60,4.72,0.093
90.61,4.85,0.093
90.62,4.99,0.093
90.64,5.12,0.093
90.65,5.25,0.093
90.66,5.39,0.093
90.68,5.52,0.093
90.69,5.65,0.094
90.70,5.79,0.094
90.71,5.92,0.094
90.73,6.05,0.094
90.74,6.19,0.094
90.75,6.32,0.094
90.77,6.45,0.094
90.78,6.59,0.094
90.80,6.72,0.094
90.81,6.86,0.094
90.82,6.99,0.094
90.84,7.12,0.094
90.85,7.25,0.095
90.86,7.39,0.095
90.88,7.52,0.095
90.89,7.65,0.095
90.90,7.79,0.095
90.91,7.92,0.095
90.93,8.05,0.095
90.94,8.19,0.095
90.95,8.32,0.095
90.97,8.46,0.095
90.98,8.59,0.095
91.00,8.72,0.095
91.01,8.86,0.095
91.02,8.99,0.096
91.04,9.12,0.096
91.05,9.26,0.096
91.06,9.39,0.096
91.08,9.52,0.096
91.09,9.66,0.096
91.10,9.79,0.096
91.11,9.92,0.096
91.13,10.06,0.096
91.14,10.19,0.096
91.15,10.32,0.096
91.17,10.46,0.096
91.18,10.59,0.096
91.20,10.72,0.097
91.21,10.86,0.097
91.22,10.99,0.097
91.24,11.12,0.097
91.25,11.26,0.097
91.26,11.39,0.097
91.28,11.52,0.097
91.29,11.66,0.097
91.30,11.79,0.097
91.31,11.92,0.097
91.33,12.06,0.097
91.34,12.19,0.097
91.35,12.32,0.097
91.37,12.46,0.097
91.38,12.59,0.098
91.40,12.72,0.098
91.41,12.86,0.098
91.42,12.99,0.098
91.44,13.13,0.098
91.45,13.26,0.098
91.46,13.39,0.098
91.48,13.53,0.098
91.49,13.66,0.098
91.50,13.79,0.098
91.51,13.93,0.098
91.53,14.06,0.098
91.54,14.19,0.098
91.55,14.33,0.098
91.57,14.46,0.098
91.58,14.59,0.099
91.60,14.73,0.099
91.61,14.86,0.099
91.62,14.99,0.099
91.64,15.13,0.099
91.65,15.26,0.099
91.66,15.40,0.099
91.68,15.53,0.099
91.69,15.66,0.099
91.70,15.80,0.099
91.71,15.93,0.099
91.73,16.06,0.099
91.74,16.19,0.099
91.75,16.33,0.099
91.77,16.46,0.100
91.78,16.60,0.100
91.80,16.73,0.100
91.81,16.86,0.100
91.82,17.00,0.100
91.84,17.13,0.100
91.85,17.26,0.100
91.86,17.40,0.100
91.88,17.53,0.100
91.89,17.66,0.100
91.90,17.80,0.100
91.91,17.93,0.100
91.93,18.06,0.100
91.94,18.20,0.100
91.95,18.33,0.101
91.97,18.46,0.101
91.98,18.60,0.101
92.00,18.73,0.101
92.01,18.86,0.101
92.02,19.00,0.101
92.04,19.13,0.101
92.05,19.26,0.101
92.06,19.40,0.101
92.08,19.53,0.101
92.09,19.67,0.101
92.10,19.80,0.101
92.11,19.93,0.101
92.13,20.07,0.101
92.14,20.20,0.101
92.15,20.33,0.102
92.17,20.47,0.102
92.18,20.60,0.102
92.20,20.73,0.102
92.21,20.87,0.102
92.22,21.00,0.102
92.24,21.13,0.102
92.25,21.27,0.102
92.26,21.40,0.102
92.28,21.53,0.102
92.29,21.67,0.102
92.30,21.80,0.102
92.31,21.93,0.102
92.33,22.07,0.102
92.34,22.20,0.103
92.35,22.33,0.103
92.37,22.47,0.103
92.38,22.60,0.103
92.40,22.73,0.103
92.41,22.87,0.103
92.42,23.00,0.103
92.44,23.14,0.103
92.45,23.27,0.103
92.46,23.40,0.103
92.48,23.54,0.103
92.49,23.67,0.103
92.50,23.80,0.103
92.51,23.93,0.104
92.53,24.07,0.104
92.54,24.20,0.104
92.55,24.34,0.104
92.57,24.47,0.104
92.58,24.60,0.104
92.60,24.74,0.104
92.61,24.87,0.104
92.62,25.00,0.104
92.64,25.14,0.104
92.65,25.27,0.104
92.66,25.40,0.104
92.68,25.54,0.104
92.69,25.67,0.104
92.70,25.80,0.105
92.71,25.94,0.105
92.73,26.07,0.105
92.74,26.20,0.105
92.75,26.34,0.105
92.77,26.47,0.105
92.78,26.61,0.105
92.80,26.74,0.105
92.81,26.87,0.105
92.82,27.01,0.105
92.84,27.14,0.105
92.85,27.27,0.105
92.86,27.41,0.105
92.88,27.54,0.105
92.89,27.67,0.106
92.90,27.81,0.106
92.91,27.94,0.106
92.93,28.07,0.106
92.94,28.21,0.106
92.95,28.34,0.106
92.97,28.47,0.106
92.98,28.61,0.106
93.00,28.74,0.106
93.01,28.87,0.106
93.02,29.01,0.106
93.04,29.14,0.106
93.05,29.27,0.106
93.06,29.41,0.106
93.08,29.54,0.107
93.09,29.67,0.107
93.10,29.81,0.107
93.11,29.94,0.107
93.13,30.08,0.107
93.14,30.21,0.107
93.15,30.34,0.107
93.17,30.48,0.107
93.18,30.61,0.107
93.20,30.74,0.107
93.21,30.88,0.107
93.22,31.01,0.107
93.24,31.14,0.107
93.25,31.28,0.108
93.26,31.41,0.108
93.28,31.54,0.108
93.29,31.68,0.108
93.30,31.81,0.108
93.31,31.94,0.108
93.33,32.08,0.108
93.34,32.21,0.108
93.35,32.34,0.108
93.37,32.48,0.108
93.38,32.61,0.108
93.40,32.74,0.108
93.41,32.88,0.109
93.42,33.01,0.109
93.44,33.14,0.109
93.45,33.28,0.109
93.46,33.41,0.109
93.48,33.55,0.109
93.49,33.68,0.109
93.50,33.81,0.109
93.51,33.95,0.109
93.53,34.08,0.109
93.54,34.21,0.109
93.55,34.35,0.109
93.57,34.48,0.109
93.58,34.61,0.109
93.60,34.75,0.110
93.61,34.88,0.110
93.62,35.01,0.110
93.64,35.15,0.110
93.65,35.28,0.110
93.66,35.41,0.110
93.68,35.55,0.110
93.69,35.68,0.110
93.70,35.81,0.110
93.71,35.95,0.110
93.73,36.08,0.110
93.74,36.21,0.111
93.75,36.35,0.111
93.77,36.48,0.111
93.78,36.61,0.111
93.80,36.75,0.111
93.81,36.88,0.111
93.82,37.01,0.111
93.84,37.15,0.111
93.85,37.28,0.111
93.86,37.41,0.111
93.88,37.55,0.111
93.89,37.68,0.111
93.90,37.81,0.111
93.91,37.95,0.111
93.93,38.08,0.112
93.94,38.22,0.112
93.95,38.35,0.112
93.97,38.48,0.112
93.98,38.61,0.112
94.00,38.75,0.112
94.01,38.88,0.112
94.02,39.02,0.112
94.04,39.15,0.112
94.05,39.28,0.112
94.06,39.42,0.112
94.08,39.55,0.112
94.09,39.68,0.112
94.10,39.82,0.112
94.11,39.95,0.113
94.13,40.08,0.113
94.14,40.22,0.113
94.15,40.35,0.113
94.17,40.48,0.113
94.18,40.62,0.113
94.20,40.75,0.113
94.21,40.88,0.113
94.22,41.02,0.113
94.24,41.15,0.113
94.25,41.29,0.113
94.26,41.42,0.113
94.28,41.55,0.113
94.29,41.69,0.114
94.30,41.82,0.114
94.31,41.95,0.114
94.33,42.08,0.114
94.34,42.22,0.114
94.35,42.35,0.114
94.37,42.48,0.114
94.38,42.62,0.114
94.40,42.75,0.114
94.41,42.89,0.114
94.42,43.02,0.114
94.44,43.15,0.114
94.45,43.29,0.115
94.46,43.42,0.115
94.48,43.55,0.115
94.49,43.69,0.115
94.50,43.82,0.115
94.51,43.95,0.115
94.53,44.09,0.115
94.54,44.22,0.115
94.55,44.35,0.115
94.57,44.49,0.115
94.58,44.62,0.115
94.60,44.75,0.115
94.61,44.89,0.115
94.62,45.02,0.116
94.64,45.15,0.116
94.65,45.29,0.116
94.66,45.42,0.116
94.68,45.55,0.116
94.69,45.69,0.116
94.70,45.82,0.116
94.71,45.95,0.116
94.73,46.09,0.116
94.74,46.22,0.116
94.75,46.35,0.116
94.77,46.49,0.116
94.78,46.62,0.117
94.80,46.76,0.117
94.81,46.89,0.117
94.82,47.02,0.117
94.84,47.16,0.117
94.85,47.29,0.117
94.86,47.42,0.117
94.88,47.56,0.117
94.89,47.69,0.117
94.90,47.82,0.117
94.91,47.96,0.117
94.93,48.09,0.117
94.94,48.22,0.118
94.95,48.36,0.118
94.97,48.49,0.118
94.98,48.62,0.118
95.00,48.76,0.118
95.01,48.89,0.118
95.02,49.02,0.118
95.04,49.16,0.118
95.05,49.29,0.118
95.06,49.42,0.118
95.08,49.56,0.118
95.09,49.69,0.118
95.10,49.83,0.119
95.11,49.96,0.119
95.13,50.09,0.119
95.14,50.23,0.119
95.15,50.36,0.119
95.17,50.49,0.119
95.18,50.63,0.119
95.20,50.76,0.119
95.21,50.89,0.119
95.22,51.03,0.119
95.24,51.16,0.119
95.25,51.29,0.120
95.26,51.43,0.120
95.28,51.56,0.120
95.29,51.69,0.120
95.30,51.83,0.120
95.31,51.96,0.120
95.33,52.09,0.120
95.34,52.23,0.120
95.35,52.36,0.120
95.37,52.49,0.120
95.38,52.63,0.120
95.40,52.76,0.120
95.41,52.89,0.120
95.42,53.03,0.121
95.44,53.16,0.121
95.45,53.29,0.121
95.46,53.43,0.121
95.48,53.56,0.121
95.49,53.69,0.121
95.50,53.83,0.121
95.51,53.96,0.121
95.53,54.09,0.121
95.54,54.23,0.121
95.55,54.36,0.121
95.57,54.49,0.121
95.58,54.63,0.122
95.60,54.76,0.122
95.61,54.89,0.122
95.62,55.03,0.122
95.64,55.16,0.122
95.65,55.29,0.122
95.66,55.43,0.122
95.68,55.56,0.122
95.69,55.69,0.122
95.70,55.83,0.122
95.71,55.96,0.122
95.73,56.10,0.123
95.74,56.23,0.123
95.75,56.36,0.123
95.77,56.49,0.123
95.78,56.63,0.123
95.80,56.76,0.123
95.81,56.90,0.123
95.82,57.03,0.123
95.84,57.16,0.123
95.85,57.30,0.123
95.86,57.43,0.123
95.88,57.56,0.124
95.89,57.70,0.124
95.90,57.83,0.124
95.91,57.96,0.124
95.93,58.10,0.124
95.94,58.23,0.124
95.95,58.36,0.124
95.97,58.50,0.124
95.98,58.63,0.124
96.00,58.76,0.124
96.01,58.90,0.124
96.02,59.03,0.125
96.04,59.17,0.125
96.05,59.30,0.125
96.06,59.43,0.125
96.08,59.57,0.125
96.09,59.70,0.125
96.10,59.83,0.125
96.11,59.96,0.125
96.13,60.10,0.125
96.14,60.23,0.125
96.15,60.37,0.125
96.17,60.50,0.126
96.18,60.63,0.126
96.20,60.76,0.126
96.21,60.90,0.126
96.22,61.03,0.126
96.24,61.17,0.126
96.25,61.30,0.126
96.26,61.43,0.126
96.28,61.57,0.126
96.29,61.70,0.126
96.30,61.83,0.126
96.31,61.97,0.127
96.33,62.10,0.127
96.34,62.23,0.127
96.35,62.37,0.127
96.37,62.50,0.127
96.38,62.63,0.127
96.40,62.77,0.127
96.41,62.90,0.127
96.42,63.03,0.127
96.44,63.17,0.127
96.45,63.30,0.128
96.46,63.43,0.128
96.48,63.57,0.128
96.49,63.70,0.128
96.50,63.83,0.128
96.51,63.97,0.128
96.53,64.10,0.128
96.54,64.24,0.128
96.55,64.37,0.128
96.57,64.50,0.128
96.58,64.63,0.129
96.60,64.77,0.129
96.61,64.90,0.129
96.62,65.04,0.129
96.64,65.17,0.129
96.65,65.30,0.129
96.66,65.44,0.129
96.68,65.57,0.129
96.69,65.70,0.129
96.70,65.84,0.129
96.71,65.97,0.130
96.73,66.10,0.130
96.74,66.24,0.130
96.75,66.37,0.130
96.77,66.50,0.130
96.78,66.64,0.130
96.80,66.77,0.130
96.81,66.90,0.130
96.82,67.04,0.130
96.84,67.17,0.130
96.85,67.30,0.131
96.86,67.44,0.131
96.88,67.57,0.131
96.89,67.70,0.131
96.90,67.84,0.131
96.91,67.97,0.131
96.93,68.10,0.131
96.94,68.24,0.131
96.95,68.37,0.131
96.97,68.50,0.132
96.98,68.64,0.132
97.00,68.77,0.132
97.01,68.90,0.132
97.02,69.04,0.132
97.04,69.17,0.132
97.05,69.31,0.132
97.06,69.44,0.132
97.08,69.57,0.133
97.09,69.70,0.133
97.10,69.84,0.133
97.11,69.97,0.133
97.13,70.11,0.133
97.14,70.24,0.133
97.15,70.37,0.133
97.17,70.51,0.133
97.18,70.64,0.134
97.20,70.77,0.134
97.21,70.91,0.134
97.22,71.04,0.134
97.24,71.17,0.134
97.25,71.31,0.134
97.26,71.44,0.134
97.28,71.57,0.134
97.29,71.71,0.134
97.30,71.84,0.135
97.31,71.97,0.135
97.33,72.11,0.135
97.34,72.24,0.135
97.35,72.37,0.135
97.37,72.51,0.135
97.38,72.64,0.135
97.40,72.77,0.135
97.41,72.91,0.136
97.42,73.04,0.136
97.44,73.17,0.136
97.45,73.31,0.136
97.46,73.44,0.136
97.48,73.57,0.136
97.49,73.71,0.136
97.50,73.84,0.137
97.51,73.97,0.137
97.53,74.11,0.137
97.54,74.24,0.137
97.55,74.37,0.137
97.57,74.51,0.137
97.58,74.64,0.137
97.60,74.78,0.138
97.61,74.91,0.138
97.62,75.04,0.138
97.64,75.18,0.138
97.65,75.31,0.138
97.66,75.44,0.138
97.68,75.58,0.138
97.69,75.71,0.139
97.70,75.84,0.139
97.71,75.98,0.139
97.73,76.11,0.139
97.74,76.24,0.139
97.75,76.38,0.139
97.77,76.51,0.139
97.78,76.64,0.140
97.80,76.78,0.140
97.81,76.91,0.140
97.82,77.04,0.140
97.84,77.18,0.140
97.85,77.31,0.140
97.86,77.44,0.141
97.88,77.58,0.141
97.89,77.71,0.141
97.90,77.84,0.141
97.91,77.98,0.141
97.93,78.11,0.141
97.94,78.24,0.142
97.95,78.38,0.142
97.97,78.51,0.142
97.98,78.64,0.142
98.00,78.78,0.142
98.01,78.91,0.142
98.02,79.04,0.143
98.04,79.18,0.143
98.05,79.31,0.143
98.06,79.44,0.143
98.08,79.58,0.143
98.09,79.71,0.143
98.10,79.84,0.143
98.11,79.98,0.144
98.13,80.11,0.144
98.14,80.24,0.144
98.15,80.38,0.144
98.17,80.51,0.144
98.18,80.65,0.144
98.20,80.78,0.145
98.21,80.91,0.145
98.22,81.05,0.145
98.24,81.18,0.145
98.25,81.31,0.145
98.26,81.45,0.146
98.28,81.58,0.146
98.29,81.71,0.146
98.30,81.85,0.146
98.31,81.98,0.146
98.33,82.11,0.146
98.34,82.25,0.147
98.35,82.38,0.147
98.37,82.51,0.147
98.38,82.65,0.147
98.40,82.78,0.147
98.41,82.91,0.148
98.42,83.05,0.148
98.44,83.18,0.148
98.45,83.31,0.148
98.46,83.45,0.148
98.48,83.58,0.149
98.49,83.71,0.149
98.50,83.85,0.149
98.51,83.98,0.149
98.53,84.11,0.149
98.54,84.25,0.149
98.55,84.38,0.150
98.57,84.51,0.150
98.58,84.65,0.150
98.60,84.78,0.150
98.61,84.91,0.150
98.62,85.05,0.151
98.64,85.18,0.151
98.65,85.31,0.151
98.66,85.45,0.151
98.68,85.58,0.151
98.69,85.71,0.152
98.70,85.85,0.152
98.71,85.98,0.152
98.73,86.11,0.152
98.74,86.25,0.152
98.75,86.38,0.153
98.77,86.51,0.153
98.78,86.65,0.153
98.80,86.78,0.153
98.81,86.92,0.153
98.82,87.05,0.154
98.84,87.18,0.154
98.85,87.31,0.154
98.86,87.45,0.154
98.88,87.58,0.155
98.89,87.71,0.155
98.90,87.85,0.155
98.91,87.98,0.155
98.93,88.11,0.155
98.94,88.25,0.156
98.95,88.38,0.156
98.97,88.51,0.156
98.98,88.65,0.156
99.00,88.78,0.157
99.01,88.91,0.157
99.02,89.05,0.157
99.04,89.18,0.157
99.05,89.31,0.157
99.06,89.45,0.158
99.08,89.58,0.158
99.09,89.71,0.158
99.10,89.85,0.158
99.11,89.98,0.159
99.13,90.11,0.159
99.14,90.25,0.159
99.15,90.38,0.159
99.17,90.51,0.159
99.18,90.65,0.160
99.20,90.78,0.160
99.21,90.91,0.160
99.22,91.05,0.160
99.24,91.18,0.161
99.25,91.31,0.161
99.26,91.45,0.161
99.28,91.58,0.161
99.29,91.71,0.161
99.30,91.85,0.162
99.31,91.98,0.162
99.33,92.11,0.162
99.34,92.25,0.162
99.35,92.38,0.163
99.37,92.51,0.163
99.38,92.65,0.163
99.40,92.78,0.163
99.41,92.91,0.164
99.42,93.05,0.164
99.44,93.18,0.164
99.45,93.31,0.164
99.46,93.45,0.165
99.48,93.58,0.165
99.49,93.71,0.165
99.50,93.85,0.165
99.51,93.98,0.165
99.53,94.11,0.166
99.54,94.25,0.166
99.55,94.38,0.166
99.57,94.51,0.166
99.58,94.65,0.167
99.60,94.78,0.167
99.61,94.91,0.167
99.62,95.05,0.167
99.64,95.18,0.168
99.65,95.31,0.168
99.66,95.45,0.168
99.68,95.58,0.168
99.69,95.71,0.169
99.70,95.85,0.169
99.71,95.98,0.169
99.73,96.11,0.169
99.74,96.25,0.169
99.75,96.38,0.170
99.77,96.51,0.170
99.78,96.65,0.170
99.80,96.78,0.170
99.81,96.91,0.171
99.82,97.05,0.171
99.84,97.18,0.171
99.85,97.32,0.171
99.86,97.45,0.171
99.88,97.58,0.172
99.89,97.72,0.172
99.90,97.85,0.172
99.91,97.99,0.172
99.93,98.12,0.172
99.94,98.26,0.173
99.95,98.39,0.174
99.97,98.52,0.174
99.98,98.66,0.174
100.00,98.79,0.175
100.01,98.93,0.175
100.02,99.06,0.175
100.04,99.19,0.175
100.05,99.32,0.176
100.06,99.46,0.176
100.08,99.59,0.176
100.09,99.72,0.176
100.10,99.86,0.176
100.11,99.99,0.177
100.13,100.12,0.177
100.14,100.26,0.177
100.15,100.39,0.177
100.17,100.52,0.177
100.18,100.65,0.177
100.20,100.79,0.178
100.21,100.92,0.178
100.22,101.05,0.178
100.24,101.19,0.178
100.25,101.32,0.178
100.26,101.45,0.178
100.28,101.59,0.179
100.29,101.72,0.179
100.30,101.85,0.179
100.31,101.98,0.179
100.33,102.12,0.179
100.34,102.25,0.179
100.35,102.38,0.180
100.37,102.52,0.180
100.38,102.65,0.180
100.40,102.78,0.180
100.41,102.92,0.180
100.42,103.05,0.180
100.44,103.18,0.180
100.45,103.32,0.181
100.46,103.45,0.181
100.48,103.58,0.181
100.49,103.72,0.181
100.50,103.85,0.181
100.51,103.99,0.181
100.53,104.12,0.182
100.54,104.25,0.182
100.55,104.39,0.182
100.57,104.52,0.182
100.58,104.65,0.182
100.60,104.79,0.183
100.61,104.92,0.183
100.62,105.05,0.183
100.64,105.19,0.183
100.65,105.32,0.183
100.66,105.45,0.183
100.68,105.59,0.184
100.69,105.72,0.184
100.70,105.85,0.184
100.71,105.99,0.184
100.73,106.12,0.184
100.74,106.25,0.184
100.75,106.38,0.185
100.77,106.52,0.185
100.78,106.65,0.185
100.80,106.78,0.185
100.81,106.92,0.185
100.82,107.05,0.185
100.84,107.18,0.186
100.85,107.32,0.186
100.86,107.45,0.186
100.88,107.58,0.186
100.89,107.72,0.186
100.90,107.85,0.186
100.91,107.98,0.187
100.93,108.12,0.187
100.94,108.25,0.187
100.95,108.38,0.187
100.97,108.52,0.187
100.98,108.65,0.187
101.00,108.78,0.188
101.01,108.92,0.188
101.02,109.05,0.188
101.04,109.19,0.188
101.05,109.32,0.188
101.06,109.45,0.188
101.08,109.59,0.189
101.09,109.72,0.189
101.10,109.85,0.189
101.11,109.98,0.189
101.13,110.12,0.189
101.14,110.25,0.189
101.15,110.38,0.190
101.17,110.52,0.190
101.18,110.65,0.190
101.20,110.78,0.190
101.21,110.92,0.190
101.22,111.05,0.190
101.24,111.18,0.190
101.25,111.32,0.191
101.26,111.45,0.191
101.28,111.59,0.191
101.29,111.72,0.191
101.30,111.85,0.191
101.31,111.99,0.191
101.33,112.12,0.191
101.34,112.25,0.192
101.35,112.39,0.192
101.37,112.52,0.192
101.38,112.65,0.192
101.40,112.79,0.192
101.41,112.92,0.192
101.42,113.06,0.192
101.44,113.19,0.193
101.45,113.32,0.193
101.46,113.45,0.193
101.48,113.59,0.193
101.49,113.72,0.193
101.50,113.86,0.193
101.51,113.99,0.193
101.53,114.12,0.194
101.54,114.25,0.194
101.55,114.39,0.194
101.57,114.52,0.194
101.58,114.65,0.194
101.60,114.79,0.194
101.61,114.92,0.194
101.62,115.05,0.195
101.64,115.19,0.195
101.65,115.32,0.195
101.66,115.45,0.195
101.68,115.59,0.195
101.69,115.72,0.195
101.70,115.85,0.195
101.71,115.99,0.195
101.73,116.12,0.196
101.74,116.25,0.196
101.75,116.39,0.196
101.77,116.52,0.196
101.78,116.65,0.196
101.80,116.79,0.196
101.81,116.92,0.196
101.82,117.05,0.196
101.84,117.19,0.197
101.85,117.32,0.197
101.86,117.46,0.197
101.88,117.59,0.197
101.89,117.72,0.197
101.90,117.85,0.197
101.91,117.99,0.197
101.93,118.12,0.197
101.94,118.26,0.198
101.95,118.39,0.198
101.97,118.52,0.198
101.98,118.66,0.198
102.00,118.79,0.198
102.01,118.92,0.198
102.02,119.06,0.198
102.04,119.19,0.198
102.05,119.32,0.198
102.06,119.46,0.199
102.08,119.59,0.199
102.09,119.72,0.199
102.10,119.86,0.199
102.11,119.99,0.199
102.13,120.12,0.199
102.14,120.26,0.199
102.15,120.39,0.199
102.17,120.52,0.200
102.18,120.66,0.200
102.20,120.79,0.200
102.21,120.92,0.200
102.22,121.06,0.200
102.24,121.19,0.200
102.25,121.33,0.200
102.26,121.46,0.200
102.28,121.59,0.201
102.29,121.73,0.201
102.30,121.86,0.201
102.31,121.99,0.201
102.33,122.13,0.201
102.34,122.26,0.201
102.35,122.39,0.201
102.37,122.53,0.201
102.38,122.66,0.201
102.40,122.79,0.202
102.41,122.93,0.202
102.42,123.06,0.202
102.44,123.19,0.202
102.45,123.33,0.202
102.46,123.46,0.202
102.48,123.59,0.202
102.49,123.73,0.202
102.50,123.86,0.202
102.51,123.99,0.203
102.53,124.13,0.203
102.54,124.26,0.203
102.55,124.39,0.203
102.57,124.52,0.203
102.58,124.66,0.203
102.60,124.79,0.203
102.61,124.92,0.203
102.62,125.06,0.203
102.64,125.19,0.203
102.65,125.33,0.203
102.66,125.46,0.204
102.68,125.59,0.204
102.69,125.73,0.204
102.70,125.86,0.204
102.71,125.99,0.204
102.73,126.13,0.204
102.74,126.26,0.204
102.75,126.39,0.204
102.77,126.53,0.204
102.78,126.66,0.205
102.80,126.79,0.205
102.81,126.93,0.205
102.82,127.06,0.205
102.84,127.19,0.205
102.85,127.33,0.205
102.86,127.46,0.205
102.88,127.59,0.205
102.89,127.73,0.205
102.90,127.86,0.206
102.91,127.99,0.206
102.93,128.13,0.206
102.94,128.26,
102.95,128.39,
102.97,128.53,
102.98,128.66,
102.99,,