File: DSC/Olivia/2025_08_09_1CBN_3PVP10_MP_n60C_200C_10Cmin_x3.csv
Filename,2025_08_09_1CBN_3PVP10_MP_n60C_200C_10Cmin_x3
Instrument name,DSC2A-00468 (192.168.1.100)
Operator,Yarger
rundate,8/10/2025
Sample name,2025_08_09_1CBN_3PVP10_MP_n60C_200C_10Cmin_x3
proceduresegments,Data Off ; Equilibrate -60.00 °C; Data On ; Ramp 10.00 °C/min to 200.00 °C; Data Off ; Isothermal 2.0 min; Data On ; Ramp 10.00 °C/min to -60.00 °C; Data Off ; Isothermal 2.0 min; Data On ; Ramp 10.00 °C/min to 200.00 °C; Data Off ; Isothermal 2.0 min; Data On ; Ramp 10.00 °C/min to -60.00 °C; Data Off ; Isothermal 2.0 min; Data On ; Ramp 10.00 °C/min to 200.00 °C
[File Parameters]
Run date,8/10/2025 12:38:38 AM
Trios version,5.1.1.46572
Original File Name,
Current File Name,D:\DSC2500\JYarger\2025_08_09_1CBN_3PVP10_MP_n60C_200C_10Cmin_x3.tri
[Procedure]
Procedure Name,CBN_PVP_TS_n60C_200C_10Cmin_x3
Sample Name,2025_08_09_1CBN_3PVP10_MP_n60C_200C_10Cmin_x3
Sample Mass,32.51 mg
Reference Sample Mass,0 mg
Pan Mass,8.54 mg
Pan Number,12
Reference Pan Mass,32.42 mg
Reference Pan Number,10
Pan Type,Aluminum
Comments,Thermal support Al pans/lids. DSC_Samples_A2_Tray_August2025 google sheet.
Project Name,Pharma
Operator,Yarger
Test,Custom
Unload Max Temperature,30
Unload Min Temperature,30
Load Max Temperature,30
Load Min Temperature,30
Stop on Gas Flow Error,Yes
[Signal List]
Signal #1,Time (min)
Signal #2,Temperature (°C)
Signal #3,Heat Flow (mW)
Signal #4,Delta T (µV)
Signal #5,Delta Tzero (µV)
Signal #6,Tzero Temperature (°C)
Signal #7,Cell Purge (mL/min)
Signal #8,Heater Temp (°C)
Signal #9,Power Delivered (W)
Signal #10,Reference Junction Temperature (°C)
Signal #11,Flange Temperature (°C)
Signal #12,Heat Flow Phase (rad)
Signal #13,Total Heat Capacity (J/°C)
Signal #14,Heat Capacity (J/°C)
[Configuration]
Company Name,ASU
Instrument Name,DSC2A-00468
Instrument Type,DSC2500
Serial Number,DSC2A-00468
IP,192.168.1.100
Location of Instrument,MRRC
DisplayType,Unknown
Sample Interval ,0.1 s/pt
Selected Heat Flow,T4P
Exotherm Direction,Down
Cell Serial,DRC2-00792
Lid Type,Standard
Cooler,RCS 90
Leave Cooler on at End of Sequence,On
Gas 2,Nitrogen
Gas Selected,Channel 1
Flow Rate,50 mL/min
Secondary Purge,On
Licensed Heat Flow,Heat Flow T4P
Modulation Licensed,Yes
[Versions]
Common IDD Version,1
Cortex Version,VER 2.10.2.31
Driver,5.0.0.6
GDM Version,1.0.3.3
TouchscreenVersion,1.0.0.16145
FEP Version,1.2.1.21
FEP Bootloader,2.0.0.5
AutoSampler Version,2.1.1.26
Auto Sampler Bootloader,2.0.0.5
FCM Version,1.1.0.3
FCM Bootloader,2.0.0.5
[Experiment Logs]
Experiment Log Entry # 1,Air Cool is off.
Experiment Log Entry # 3,Data On set to 0
Experiment Log Entry # 5,Equilibrate Segment -60 (C) Started
Experiment Log Entry # 7,Data On set to 1
Experiment Log Entry # 9,Ramp Segment 10 C/min to 200 Started
Experiment Log Entry # 11,Data On set to 0
Experiment Log Entry # 13,Isothermal Segment 2 min started
Experiment Log Entry # 15,Data On set to 1
Experiment Log Entry # 17,Ramp Segment 10 C/min to -60 Started
Experiment Log Entry # 19,Data On set to 0
Experiment Log Entry # 21,Isothermal Segment 2 min started
Experiment Log Entry # 23,Data On set to 1
Experiment Log Entry # 25,Ramp Segment 10 C/min to 200 Started
Experiment Log Entry # 27,Data On set to 0
Experiment Log Entry # 29,Isothermal Segment 2 min started
Experiment Log Entry # 31,Data On set to 1
Experiment Log Entry # 33,Ramp Segment 10 C/min to -60 Started
Experiment Log Entry # 35,Data On set to 0
Experiment Log Entry # 37,Isothermal Segment 2 min started
Experiment Log Entry # 39,Data On set to 1
Experiment Log Entry # 41,Ramp Segment 10 C/min to 200 Started
[Method Log]
Method Log Entry # 1,Data Off
Method Log Entry # 2,Equilibrate -60 °C
Method Log Entry # 3,Data On
Method Log Entry # 4,(Ramp 799657) Ramp 10 °C/minute to 200 °C
Method Log Entry # 5,Data Off
Method Log Entry # 6,Isothermal 2 minutes
Method Log Entry # 7,Data On
Method Log Entry # 8,(Ramp 799661) Ramp 10 °C/minute to -60 °C
Method Log Entry # 9,Data Off
Method Log Entry # 10,Isothermal 2 minutes
Method Log Entry # 11,Data On
Method Log Entry # 12,(Ramp 799665) Ramp 10 °C/minute to 200 °C
Method Log Entry # 13,Data Off
Method Log Entry # 14,Isothermal 2 minutes
Method Log Entry # 15,Data On
Method Log Entry # 16,(Ramp 799669) Ramp 10 °C/minute to -60 °C
Method Log Entry # 17,Data Off
Method Log Entry # 18,Isothermal 2 minutes
Method Log Entry # 19,Data On
Method Log Entry # 20,(Ramp 799673) Ramp 10 °C/minute to 200 °C
Cell Serial,DRC2-00792
[T1 Calibration]
Slope,-0.008529666
Offset,9.636258
Initial Temperature,98.23
GUID,f8bfdadc-4977-4fdf-ba6d-0ba9134940c3
[TZero Calibration]
Date Applied,11/29/2022 4:06:13 PM
Description,From -89.059 °C to 396.009 °C at 20.000°C/min
Gas Type,Nitrogen
Pan Type,None
Source Files 1,C:\Users\yargerlab\Desktop\DSC Data\General\TZero_calibration_11_29_22_2nd(2).tri
Source Files 2,C:\Users\yargerlab\Desktop\DSC Data\General\TZero_calibration_11_29_22_2nd(3).tri
Delta T Offset,13.05235
Delta T Slope,-0.007271007
Delta T0 Offset,-13.69128
Delta T0 Slope,0.06063341
[Temperature Calibration]
Date Applied,11/29/2022 7:12:28 PM
Description,From 106.590 °C to 186.590 °C at 10.000°C/min
Gas Type,Nitrogen
Pan Type,Tzero Aluminum Hermetic
Source Files 1,C:\Users\yargerlab\Desktop\DSC Data\General\Indium(6).tri
Measured 1,157.391
Known 1,156.598
[Cell Constant Calibration]
Date Applied,11/29/2022 7:12:29 PM
Description,From 106.590 °C to 186.590 °C at 10.000°C/min
Gas Type,Nitrogen
Pan Type,Tzero Aluminum Hermetic
Source Files 1,C:\Users\yargerlab\Desktop\DSC Data\General\Indium(6).tri
T4P KCell,1.006051
Onset Slope,63.26126 mW/°C
[Direct Cp Calibration]
Date Applied,11/30/2022 11:04:51 AM
Description,From -79.983 °C to 298.409 °C at 10.000°C/min
Gas Type,Nitrogen
Pan Type,Tzero Aluminum Hermetic
Source Files 1,C:\Users\yargerlab\Desktop\DSC Data\General\Sapphire_Heat_Capacity_11_30_22.tri
[Rev Cp Calibration]
Date Applied,11/30/2022 1:58:51 PM
Description,From -79.996 °C to 292.812 °C at 3.000°C/min
Gas Type,Nitrogen
Pan Type,Tzero Aluminum Hermetic
Source Files 1,C:\Users\yargerlab\Desktop\DSC Data\General\Sapphire_MDSC_Calibration_11_30_22.tri
[step]
Ramp 10.00 °C/min to 200.00 °C
Time,Temperature,Heat Flow (Normalized)
min,°C,W/g
0.00,-59.80,-0.009
0.02,-59.81,-0.008
0.04,-59.81,-0.007
0.05,-59.80,-0.006
0.07,-59.78,-0.003
0.09,-59.73,0.000
0.11,-59.66,0.005
0.13,-59.57,0.011
0.15,-59.46,0.017
0.16,-59.33,0.023
0.18,-59.19,0.029
0.20,-59.04,0.034
0.22,-58.88,0.038
0.24,-58.72,0.042
0.26,-58.55,0.045
0.28,-58.38,0.047
0.29,-58.21,0.048
0.31,-58.04,0.050
0.33,-57.86,0.051
0.35,-57.69,0.051
0.37,-57.51,0.052
0.39,-57.33,0.053
0.40,-57.16,0.053
0.42,-56.98,0.054
0.44,-56.80,0.054
0.46,-56.62,0.054
0.48,-56.44,0.054
0.50,-56.26,0.055
0.51,-56.08,0.055
0.53,-55.90,0.055
0.55,-55.72,0.055
0.57,-55.54,0.055
0.59,-55.36,0.055
0.60,-55.18,0.055
0.62,-55.00,0.055
0.64,-54.82,0.056
0.66,-54.64,0.056
0.68,-54.46,0.056
0.70,-54.28,0.056
0.72,-54.10,0.056
0.73,-53.91,0.056
0.75,-53.73,0.056
0.77,-53.55,0.056
0.79,-53.37,0.056
0.81,-53.19,0.056
0.83,-53.01,0.056
0.84,-52.82,0.056
0.86,-52.64,0.056
0.88,-52.46,0.057
0.90,-52.28,0.057
0.92,-52.10,0.057
0.93,-51.92,0.057
0.95,-51.73,0.057
0.97,-51.55,0.057
0.99,-51.37,0.057
1.01,-51.18,0.057
1.03,-51.00,0.057
1.05,-50.82,0.057
1.06,-50.64,0.057
1.08,-50.45,0.057
1.10,-50.27,0.057
1.12,-50.09,0.057
1.14,-49.91,0.057
1.16,-49.72,0.058
1.17,-49.54,0.058
1.19,-49.36,0.058
1.21,-49.18,0.058
1.23,-48.99,0.058
1.25,-48.81,0.058
1.27,-48.63,0.058
1.28,-48.45,0.058
1.30,-48.26,0.058
1.32,-48.08,0.058
1.34,-47.90,0.058
1.36,-47.71,0.058
1.38,-47.53,0.058
1.39,-47.35,0.058
1.41,-47.16,0.058
1.43,-46.98,0.058
1.45,-46.80,0.058
1.47,-46.61,0.058
1.48,-46.43,0.058
1.50,-46.25,0.059
1.52,-46.07,0.059
1.54,-45.88,0.059
1.56,-45.70,0.059
1.58,-45.51,0.059
1.59,-45.33,0.059
1.61,-45.15,0.059
1.63,-44.97,0.059
1.65,-44.78,0.059
1.67,-44.60,0.059
1.69,-44.42,0.059
1.71,-44.23,0.059
1.72,-44.05,0.059
1.74,-43.86,0.059
1.76,-43.68,0.059
1.78,-43.50,0.059
1.80,-43.32,0.059
1.82,-43.13,0.059
1.83,-42.95,0.059
1.85,-42.76,0.059
1.87,-42.58,0.059
1.89,-42.40,0.059
1.91,-42.22,0.059
1.93,-42.03,0.059
1.94,-41.85,0.060
1.96,-41.66,0.060
1.98,-41.48,0.060
2.00,-41.30,0.060
2.02,-41.11,0.060
2.03,-40.93,0.060
2.05,-40.75,0.060
2.07,-40.56,0.060
2.09,-40.38,0.060
2.11,-40.20,0.060
2.13,-40.01,0.060
2.14,-39.83,0.060
2.16,-39.65,0.060
2.18,-39.46,0.060
2.20,-39.28,0.060
2.22,-39.10,0.060
2.24,-38.91,0.060
2.26,-38.73,0.060
2.27,-38.55,0.060
2.29,-38.36,0.060
2.31,-38.18,0.060
2.33,-37.99,0.060
2.35,-37.81,0.060
2.36,-37.63,0.060
2.38,-37.44,0.060
2.40,-37.26,0.060
2.42,-37.08,0.060
2.44,-36.89,0.061
2.46,-36.71,0.061
2.48,-36.53,0.061
2.49,-36.34,0.061
2.51,-36.16,0.061
2.53,-35.98,0.061
2.55,-35.79,0.061
2.57,-35.61,0.061
2.59,-35.42,0.061
2.60,-35.24,0.061
2.62,-35.06,0.061
2.64,-34.87,0.061
2.66,-34.69,0.061
2.68,-34.51,0.061
2.69,-34.32,0.061
2.71,-34.14,0.061
2.73,-33.96,0.061
2.75,-33.77,0.061
2.77,-33.59,0.061
2.79,-33.41,0.061
2.81,-33.22,0.061
2.82,-33.04,0.061
2.84,-32.85,0.061
2.86,-32.67,0.061
2.88,-32.49,0.061
2.90,-32.30,0.061
2.91,-32.12,0.061
2.93,-31.94,0.061
2.95,-31.75,0.062
2.97,-31.57,0.062
2.99,-31.39,0.062
3.01,-31.20,0.062
3.03,-31.02,0.062
3.04,-30.84,0.062
3.06,-30.65,0.062
3.08,-30.47,0.062
3.10,-30.29,0.062
3.12,-30.10,0.062
3.14,-29.92,0.062
3.15,-29.74,0.062
3.17,-29.55,0.062
3.19,-29.37,0.062
3.21,-29.19,0.062
3.23,-29.00,0.062
3.24,-28.82,0.062
3.26,-28.63,0.062
3.28,-28.45,0.062
3.30,-28.27,0.062
3.32,-28.09,0.062
3.34,-27.90,0.062
3.36,-27.72,0.062
3.37,-27.53,0.062
3.39,-27.35,0.062
3.41,-27.17,0.062
3.43,-26.98,0.063
3.45,-26.80,0.063
3.46,-26.62,0.063
3.48,-26.43,0.063
3.50,-26.25,0.063
3.52,-26.07,0.063
3.54,-25.88,0.063
3.56,-25.70,0.063
3.58,-25.51,0.063
3.59,-25.33,0.063
3.61,-25.15,0.063
3.63,-24.96,0.063
3.65,-24.78,0.063
3.67,-24.60,0.063
3.69,-24.41,0.063
3.70,-24.23,0.063
3.72,-24.05,0.063
3.74,-23.86,0.063
3.76,-23.68,0.063
3.78,-23.50,0.063
3.79,-23.31,0.063
3.81,-23.13,0.063
3.83,-22.95,0.063
3.85,-22.76,0.063
3.87,-22.58,0.064
3.89,-22.39,0.064
3.91,-22.21,0.064
3.92,-22.03,0.064
3.94,-21.84,0.064
3.96,-21.66,0.064
3.98,-21.48,0.064
4.00,-21.29,0.064
4.01,-21.11,0.064
4.03,-20.93,0.064
4.05,-20.74,0.064
4.07,-20.56,0.064
4.09,-20.38,0.064
4.11,-20.19,0.064
4.13,-20.01,0.064
4.14,-19.83,0.064
4.16,-19.64,0.064
4.18,-19.46,0.064
4.20,-19.28,0.064
4.22,-19.09,0.064
4.24,-18.91,0.064
4.25,-18.72,0.064
4.27,-18.54,0.065
4.29,-18.36,0.065
4.31,-18.18,0.065
4.33,-17.99,0.065
4.35,-17.81,0.065
4.36,-17.62,0.065
4.38,-17.44,0.065
4.40,-17.26,0.065
4.42,-17.07,0.065
4.44,-16.89,0.065
4.45,-16.71,0.065
4.47,-16.52,0.065
4.49,-16.34,0.065
4.51,-16.16,0.065
4.53,-15.97,0.065
4.55,-15.79,0.065
4.56,-15.61,0.065
4.58,-15.42,0.065
4.60,-15.24,0.065
4.62,-15.06,0.065
4.64,-14.87,0.065
4.66,-14.69,0.065
4.68,-14.50,0.066
4.69,-14.32,0.066
4.71,-14.14,0.066
4.73,-13.95,0.066
4.75,-13.77,0.066
4.77,-13.59,0.066
4.79,-13.40,0.066
4.80,-13.22,0.066
4.82,-13.04,0.066
4.84,-12.85,0.066
4.86,-12.67,0.066
4.88,-12.49,0.066
4.90,-12.30,0.066
4.91,-12.12,0.066
4.93,-11.94,0.066
4.95,-11.75,0.066
4.97,-11.57,0.066
4.99,-11.39,0.066
5.00,-11.20,0.066
5.02,-11.02,0.066
5.04,-10.84,0.066
5.06,-10.65,0.067
5.08,-10.47,0.067
5.10,-10.29,0.067
5.11,-10.10,0.067
5.13,-9.92,0.067
5.15,-9.74,0.067
5.17,-9.55,0.067
5.19,-9.37,0.067
5.21,-9.18,0.067
5.23,-9.00,0.067
5.24,-8.82,0.067
5.26,-8.64,0.067
5.28,-8.45,0.067
5.30,-8.27,0.067
5.32,-8.08,0.067
5.34,-7.90,0.067
5.35,-7.72,0.067
5.37,-7.53,0.067
5.39,-7.35,0.067
5.41,-7.17,0.068
5.43,-6.98,0.068
5.45,-6.80,0.068
5.46,-6.62,0.068
5.48,-6.43,0.068
5.50,-6.25,0.068
5.52,-6.07,0.068
5.54,-5.88,0.068
5.55,-5.70,0.068
5.57,-5.52,0.068
5.59,-5.33,0.068
5.61,-5.15,0.068
5.63,-4.97,0.068
5.65,-4.78,0.068
5.66,-4.60,0.068
5.68,-4.42,0.068
5.70,-4.23,0.068
5.72,-4.05,0.069
5.74,-3.86,0.069
5.76,-3.68,0.069
5.78,-3.50,0.069
5.79,-3.31,0.069
5.81,-3.13,0.069
5.83,-2.95,0.069
5.85,-2.76,0.069
5.87,-2.58,0.069
5.89,-2.40,0.069
5.90,-2.21,0.069
5.92,-2.03,0.069
5.94,-1.85,0.069
5.96,-1.66,0.069
5.98,-1.48,0.069
6.00,-1.30,0.069
6.01,-1.11,0.069
6.03,-0.93,0.069
6.05,-0.75,0.070
6.07,-0.56,0.070
6.09,-0.38,0.070
6.10,-0.20,0.070
6.12,-0.01,0.070
6.14,0.17,0.070
6.16,0.35,0.070
6.18,0.54,0.070
6.20,0.72,0.070
6.21,0.91,0.070
6.23,1.09,0.070
6.25,1.27,0.070
6.27,1.46,0.070
6.29,1.64,0.070
6.31,1.82,0.070
6.33,2.01,0.070
6.34,2.19,0.071
6.36,2.37,0.071
6.38,2.56,0.071
6.40,2.74,0.071
6.42,2.92,0.071
6.44,3.11,0.071
6.45,3.29,0.071
6.47,3.47,0.071
6.49,3.66,0.071
6.51,3.84,0.071
6.53,4.02,0.071
6.55,4.21,0.071
6.56,4.39,0.071
6.58,4.58,0.071
6.60,4.76,0.071
6.62,4.94,0.071
6.64,5.13,0.072
6.65,5.31,0.072
6.67,5.49,0.072
6.69,5.68,0.072
6.71,5.86,0.072
6.73,6.04,0.072
6.75,6.23,0.072
6.76,6.41,0.072
6.78,6.59,0.072
6.80,6.78,0.072
6.82,6.96,0.072
6.84,7.14,0.072
6.86,7.33,0.072
6.88,7.51,0.072
6.89,7.69,0.073
6.91,7.88,0.073
6.93,8.06,0.073
6.95,8.24,0.073
6.97,8.43,0.073
6.99,8.61,0.073
7.00,8.79,0.073
7.02,8.98,0.073
7.04,9.16,0.073
7.06,9.34,0.073
7.08,9.53,0.073
7.10,9.71,0.073
7.11,9.89,0.073
7.13,10.08,0.073
7.15,10.26,0.074
7.17,10.44,0.074
7.19,10.63,0.074
7.20,10.81,0.074
7.22,11.00,0.074
7.24,11.18,0.074
7.26,11.36,0.074
7.28,11.54,0.074
7.30,11.73,0.074
7.31,11.91,0.074
7.33,12.09,0.074
7.35,12.28,0.074
7.37,12.46,0.074
7.39,12.64,0.075
7.41,12.83,0.075
7.43,13.01,0.075
7.44,13.20,0.075
7.46,13.38,0.075
7.48,13.56,0.075
7.50,13.75,0.075
7.52,13.93,0.075
7.54,14.11,0.075
7.55,14.30,0.075
7.57,14.48,0.075
7.59,14.66,0.075
7.61,14.85,0.076
7.63,15.03,0.076
7.65,15.21,0.076
7.66,15.39,0.076
7.68,15.58,0.076
7.70,15.76,0.076
7.72,15.94,0.076
7.74,16.13,0.076
7.75,16.31,0.076
7.77,16.49,0.076
7.79,16.68,0.076
7.81,16.86,0.077
7.83,17.05,0.077
7.85,17.23,0.077
7.86,17.41,0.077
7.88,17.59,0.077
7.90,17.78,0.077
7.92,17.96,0.077
7.94,18.14,0.077
7.96,18.33,0.077
7.98,18.51,0.077
7.99,18.69,0.077
8.01,18.88,0.078
8.03,19.06,0.078
8.05,19.24,0.078
8.07,19.43,0.078
8.09,19.61,0.078
8.10,19.79,0.078
8.12,19.98,0.078
8.14,20.16,0.078
8.16,20.35,0.078
8.18,20.53,0.078
8.20,20.71,0.079
8.21,20.90,0.079
8.23,21.08,0.079
8.25,21.26,0.079
8.27,21.44,0.079
8.29,21.63,0.079
8.30,21.81,0.079
8.32,21.99,0.079
8.34,22.18,0.079
8.36,22.36,0.080
8.38,22.54,0.080
8.40,22.73,0.080
8.41,22.91,0.080
8.43,23.10,0.080
8.45,23.28,0.080
8.47,23.46,0.080
8.49,23.64,0.080
8.51,23.83,0.080
8.53,24.01,0.081
8.54,24.20,0.081
8.56,24.38,0.081
8.58,24.56,0.081
8.60,24.75,0.081
8.62,24.93,0.081
8.63,25.11,0.081
8.65,25.29,0.081
8.67,25.48,0.081
8.69,25.66,0.082
8.71,25.85,0.082
8.73,26.03,0.082
8.75,26.21,0.082
8.76,26.40,0.082
8.78,26.58,0.082
8.80,26.76,0.082
8.82,26.94,0.082
8.84,27.13,0.083
8.85,27.31,0.083
8.87,27.49,0.083
8.89,27.68,0.083
8.91,27.86,0.083
8.93,28.04,0.083
8.95,28.23,0.084
8.97,28.41,0.084
8.98,28.59,0.084
9.00,28.78,0.084
9.02,28.96,0.084
9.04,29.14,0.084
9.06,29.33,0.084
9.08,29.51,0.085
9.09,29.69,0.085
9.11,29.88,0.085
9.13,30.06,0.085
9.15,30.24,0.085
9.17,30.43,0.086
9.18,30.61,0.086
9.20,30.79,0.086
9.22,30.98,0.086
9.24,31.16,0.086
9.26,31.34,0.086
9.28,31.53,0.087
9.30,31.71,0.087
9.31,31.89,0.087
9.33,32.08,0.087
9.35,32.26,0.087
9.37,32.44,0.088
9.39,32.63,0.088
9.40,32.81,0.088
9.42,32.99,0.088
9.44,33.17,0.089
9.46,33.36,0.089
9.48,33.54,0.089
9.50,33.72,0.089
9.52,33.91,0.090
9.53,34.09,0.090
9.55,34.27,0.090
9.57,34.46,0.091
9.59,34.64,0.091
9.61,34.82,0.091
9.63,35.00,0.091
9.64,35.19,0.092
9.66,35.37,0.092
9.68,35.55,0.093
9.70,35.74,0.093
9.72,35.92,0.093
9.73,36.10,0.094
9.75,36.29,0.094
9.77,36.47,0.095
9.79,36.65,0.095
9.81,36.83,0.095
9.83,37.01,0.096
9.85,37.20,0.096
9.86,37.38,0.097
9.88,37.56,0.098
9.90,37.74,0.098
9.92,37.93,0.099
9.94,38.11,0.099
9.95,38.29,0.100
9.97,38.48,0.101
9.99,38.66,0.101
10.01,38.84,0.102
10.03,39.02,0.103
10.05,39.20,0.104
10.07,39.39,0.105
10.08,39.57,0.105
10.10,39.75,0.106
10.12,39.93,0.107
10.14,40.11,0.108
10.16,40.29,0.109
10.18,40.47,0.110
10.19,40.66,0.112
10.21,40.84,0.113
10.23,41.02,0.113
10.25,41.20,0.115
10.27,41.38,0.116
10.28,41.56,0.117
10.30,41.74,0.118
10.32,41.92,0.119
10.34,42.11,0.120
10.36,42.29,0.120
10.38,42.47,0.121
10.40,42.65,0.121
10.41,42.83,0.122
10.43,43.02,0.122
10.45,43.20,0.122
10.47,43.38,0.122
10.49,43.57,0.122
10.50,43.75,0.122
10.52,43.93,0.122
10.54,44.12,0.122
10.56,44.30,0.121
10.58,44.49,0.121
10.60,44.67,0.120
10.62,44.86,0.119
10.63,45.04,0.118
10.65,45.23,0.118
10.67,45.41,0.117
10.69,45.60,0.117
10.71,45.78,0.116
10.73,45.96,0.116
10.74,46.15,0.116
10.76,46.33,0.115
10.78,46.52,0.115
10.80,46.70,0.115
10.82,46.89,0.115
10.83,47.07,0.115
10.85,47.25,0.115
10.87,47.44,0.115
10.89,47.63,0.115
10.91,47.81,0.114
10.93,47.99,0.114
10.95,48.17,0.114
10.96,48.36,0.114
10.98,48.54,0.114
11.00,48.72,0.114
11.02,48.91,0.114
11.04,49.09,0.114
11.05,49.27,0.114
11.07,49.46,0.114
11.09,49.64,0.114
11.11,49.82,0.115
11.13,50.01,0.115
11.15,50.19,0.115
11.17,50.37,0.115
11.18,50.56,0.115
11.20,50.74,0.115
11.22,50.92,0.115
11.24,51.11,0.116
11.26,51.29,0.116
11.28,51.47,0.116
11.29,51.65,0.116
11.31,51.84,0.116
11.33,52.02,0.117
11.35,52.20,0.117
11.37,52.39,0.117
11.38,52.57,0.118
11.40,52.75,0.118
11.42,52.94,0.118
11.44,53.12,0.118
11.46,53.30,0.119
11.48,53.49,0.119
11.50,53.67,0.119
11.51,53.85,0.119
11.53,54.03,0.120
11.55,54.22,0.120
11.57,54.40,0.120
11.59,54.58,0.121
11.60,54.77,0.121
11.62,54.95,0.121
11.64,55.13,0.122
11.66,55.32,0.122
11.68,55.50,0.122
11.70,55.68,0.123
11.72,55.86,0.123
11.73,56.05,0.123
11.75,56.23,0.124
11.77,56.41,0.124
11.79,56.60,0.124
11.81,56.78,0.125
11.83,56.96,0.125
11.84,57.14,0.125
11.86,57.33,0.126
11.88,57.51,0.126
11.90,57.69,0.127
11.92,57.88,0.127
11.93,58.06,0.127
11.95,58.24,0.128
11.97,58.42,0.128
11.99,58.61,0.129
12.01,58.79,0.129
12.03,58.97,0.130
12.05,59.15,0.130
12.06,59.34,0.131
12.08,59.52,0.131
12.10,59.70,0.131
12.12,59.89,0.132
12.14,60.07,0.132
12.15,60.25,0.133
12.17,60.43,0.134
12.19,60.62,0.134
12.21,60.80,0.135
12.23,60.98,0.135
12.25,61.16,0.136
12.27,61.35,0.137
12.28,61.53,0.137
12.30,61.71,0.138
12.32,61.89,0.138
12.34,62.08,0.139
12.36,62.26,0.140
12.38,62.44,0.140
12.39,62.62,0.141
12.41,62.80,0.142
12.43,62.99,0.143
12.45,63.17,0.143
12.47,63.35,0.144
12.48,63.53,0.145
12.50,63.71,0.146
12.52,63.90,0.147
12.54,64.08,0.148
12.56,64.26,0.149
12.58,64.44,0.149
12.60,64.62,0.151
12.61,64.80,0.151
12.63,64.98,0.153
12.65,65.17,0.154
12.67,65.35,0.155
12.69,65.53,0.156
12.70,65.71,0.157
12.72,65.89,0.159
12.74,66.07,0.160
12.76,66.26,0.161
12.78,66.44,0.163
12.80,66.62,0.164
12.82,66.80,0.165
12.83,66.98,0.167
12.85,67.16,0.168
12.87,67.34,0.170
12.89,67.52,0.172
12.91,67.70,0.174
12.93,67.88,0.175
12.94,68.06,0.177
12.96,68.24,0.180
12.98,68.42,0.182
13.00,68.60,0.184
13.02,68.77,0.186
13.03,68.95,0.189
13.05,69.13,0.192
13.07,69.31,0.196
13.09,69.48,0.199
13.11,69.66,0.203
13.13,69.84,0.208
13.15,70.01,0.213
13.16,70.19,0.218
13.18,70.36,0.224
13.20,70.53,0.231
13.22,70.70,0.238
13.24,70.87,0.245
13.25,71.04,0.251
13.27,71.21,0.257
13.29,71.38,0.261
13.31,71.56,0.264
13.33,71.73,0.264
13.35,71.91,0.262
13.37,72.10,0.259
13.38,72.28,0.254
13.40,72.48,0.247
13.42,72.67,0.240
13.44,72.86,0.232
13.46,73.06,0.224
13.48,73.26,0.216
13.49,73.46,0.208
13.51,73.66,0.200
13.53,73.86,0.192
13.55,74.06,0.185
13.57,74.26,0.179
13.58,74.46,0.172
13.60,74.65,0.167
13.62,74.85,0.162
13.64,75.04,0.158
13.66,75.24,0.154
13.68,75.43,0.151
13.70,75.62,0.148
13.71,75.81,0.145
13.73,76.00,0.143
13.75,76.19,0.142
13.77,76.38,0.140
13.79,76.57,0.140
13.80,76.75,0.139
13.82,76.94,0.138
13.84,77.13,0.138
13.86,77.31,0.138
13.88,77.50,0.137
13.90,77.68,0.137
13.92,77.86,0.137
13.93,78.05,0.137
13.95,78.23,0.136
13.97,78.42,0.136
13.99,78.60,0.136
14.01,78.79,0.135
14.03,78.97,0.135
14.04,79.15,0.135
14.06,79.34,0.134
14.08,79.52,0.134
14.10,79.71,0.133
14.12,79.89,0.133
14.13,80.08,0.132
14.15,80.26,0.132
14.17,80.45,0.132
14.19,80.63,0.132
14.21,80.81,0.132
14.23,80.99,0.132
14.25,81.18,0.132
14.26,81.36,0.132
14.28,81.55,0.132
14.30,81.73,0.132
14.32,81.92,0.131
14.34,82.10,0.131
14.35,82.28,0.131
14.37,82.47,0.131
14.39,82.65,0.131
14.41,82.83,0.131
14.43,83.02,0.131
14.45,83.20,0.131
14.47,83.38,0.131
14.48,83.57,0.131
14.50,83.75,0.131
14.52,83.94,0.131
14.54,84.12,0.131
14.56,84.30,0.131
14.58,84.49,0.131
14.59,84.67,0.131
14.61,84.85,0.131
14.63,85.04,0.131
14.65,85.22,0.131
14.67,85.40,0.131
14.68,85.59,0.131
14.70,85.77,0.131
14.72,85.95,0.131
14.74,86.14,0.131
14.76,86.32,0.131
14.78,86.51,0.131
14.80,86.69,0.131
14.81,86.87,0.131
14.83,87.06,0.131
14.85,87.24,0.131
14.87,87.42,0.131
14.89,87.61,0.131
14.90,87.79,0.131
14.92,87.98,0.131
14.94,88.16,0.130
14.96,88.34,0.130
14.98,88.53,0.130
15.00,88.71,0.130
15.02,88.90,0.130
15.03,89.08,0.129
15.05,89.26,0.129
15.07,89.45,0.129
15.09,89.63,0.128
15.11,89.82,0.128
15.13,90.00,0.128
15.14,90.18,0.127
15.16,90.37,0.127
15.18,90.55,0.126
15.20,90.74,0.126
15.22,90.92,0.126
15.23,91.11,0.125
15.25,91.29,0.124
15.27,91.48,0.124
15.29,91.66,0.123
15.31,91.85,0.123
15.33,92.03,0.122
15.35,92.21,0.122
15.36,92.40,0.121
15.38,92.58,0.120
15.40,92.77,0.120
15.42,92.95,0.119
15.44,93.14,0.119
15.45,93.32,0.119
15.47,93.51,0.118
15.49,93.69,0.118
15.51,93.88,0.117
15.53,94.06,0.116
15.55,94.25,0.116
15.57,94.43,0.116
15.58,94.61,0.115
15.60,94.80,0.114
15.62,94.98,0.114
15.64,95.17,0.114
15.66,95.35,0.113
15.68,95.54,0.113
15.69,95.72,0.113
15.71,95.90,0.112
15.73,96.09,0.112
15.75,96.27,0.112
15.77,96.46,0.112
15.78,96.64,0.112
15.80,96.82,0.112
15.82,97.01,0.112
15.84,97.19,0.112
15.86,97.37,0.112
15.88,97.56,0.112
15.90,97.74,0.112
15.91,97.93,0.111
15.93,98.11,0.111
15.95,98.29,0.111
15.97,98.48,0.111
15.99,98.66,0.111
16.00,98.84,0.111
16.02,99.03,0.111
16.04,99.21,0.111
16.06,99.40,0.111
16.08,99.58,0.111
16.10,99.76,0.111
16.12,99.95,0.110
16.13,100.13,0.110
16.15,100.32,0.110
16.17,100.50,0.108
16.19,100.68,0.107
16.21,100.87,0.106
16.23,101.06,0.106
16.24,101.24,0.106
16.26,101.42,0.106
16.28,101.61,0.106
16.30,101.79,0.106
16.32,101.98,0.106
16.33,102.16,0.106
16.35,102.34,0.106
16.37,102.53,0.106
16.39,102.71,0.106
16.41,102.89,0.106
16.43,103.08,0.106
16.45,103.26,0.106
16.46,103.44,0.106
16.48,103.63,0.106
16.50,103.81,0.106
16.52,103.99,0.106
16.54,104.18,0.106
16.55,104.36,0.106
16.57,104.54,0.106
16.59,104.73,0.106
16.61,104.91,0.106
16.63,105.09,0.106
16.65,105.28,0.106
16.67,105.46,0.106
16.68,105.64,0.106
16.70,105.83,0.107
16.72,106.01,0.107
16.74,106.19,0.107
16.76,106.38,0.107
16.78,106.56,0.107
16.79,106.74,0.107
16.81,106.93,0.107
16.83,107.11,0.107
16.85,107.29,0.107
16.87,107.48,0.107
16.88,107.66,0.107
16.90,107.84,0.107
16.92,108.03,0.107
16.94,108.21,0.107
16.96,108.39,0.108
16.98,108.58,0.108
17.00,108.76,0.108
17.01,108.95,0.108
17.03,109.13,0.108
17.05,109.31,0.108
17.07,109.50,0.108
17.09,109.68,0.108
17.11,109.86,0.108
17.12,110.05,0.108
17.14,110.23,0.108
17.16,110.41,0.108
17.18,110.60,0.108
17.20,110.78,0.108
17.22,110.96,0.108
17.23,111.15,0.108
17.25,111.33,0.108
17.27,111.51,0.138
17.29,111.14,1.118
17.31,110.91,0.834
17.33,110.96,0.761
17.34,111.03,0.832
17.36,111.08,0.895
17.38,111.14,0.943
17.40,111.23,0.961
17.42,111.35,0.964
17.43,111.50,0.955
17.45,111.68,0.940
17.47,111.87,0.923
17.49,112.07,0.905
17.51,112.28,0.886
17.53,112.49,0.866
17.54,112.71,0.846
17.56,112.93,0.826
17.58,113.15,0.806
17.60,113.37,0.786
17.62,113.60,0.767
17.64,113.82,0.748
17.66,114.04,0.729
17.67,114.26,0.711
17.69,114.49,0.693
17.71,114.71,0.676
17.73,114.93,0.660
17.75,115.14,0.644
17.77,115.36,0.628
17.78,115.58,0.614
17.80,115.79,0.599
17.82,116.00,0.585
17.84,116.22,0.572
17.86,116.43,0.559
17.88,116.64,0.546
17.89,116.85,0.533
17.91,117.06,0.522
17.93,117.27,0.511
17.95,117.48,0.501
17.97,117.68,0.490
17.98,117.89,0.480
18.00,118.09,0.471
18.02,118.30,0.461
18.04,118.50,0.452
18.06,118.70,0.443
18.08,118.90,0.434
18.09,119.11,0.426
18.11,119.31,0.419
18.13,119.51,0.411
18.15,119.71,0.403
18.17,119.91,0.396
18.19,120.10,0.388
18.21,120.30,0.382
18.22,120.50,0.375
18.24,120.70,0.369
18.26,120.90,0.363
18.28,121.09,0.357
18.30,121.29,0.351
18.32,121.48,0.346
18.33,121.68,0.340
18.35,121.87,0.334
18.37,122.07,0.329
18.39,122.26,0.324
18.41,122.46,0.318
18.43,122.65,0.314
18.44,122.84,0.309
18.46,123.04,0.304
18.48,123.23,0.300
18.50,123.42,0.295
18.52,123.62,0.291
18.53,123.81,0.287
18.55,124.00,0.282
18.57,124.19,0.278
18.59,124.39,0.274
18.61,124.58,0.270
18.63,124.77,0.267
18.64,124.96,0.264
18.66,125.15,0.260
18.68,125.34,0.257
18.70,125.53,0.253
18.72,125.72,0.250
18.74,125.91,0.246
18.76,126.10,0.243
18.77,126.29,0.240
18.79,126.48,0.237
18.81,126.67,0.234
18.83,126.86,0.231
18.85,127.05,0.229
18.87,127.24,0.226
18.88,127.43,0.223
18.90,127.62,0.221
18.92,127.81,0.218
18.94,128.00,0.220
18.96,128.17,0.238
18.98,128.34,0.238
18.99,128.52,0.237
19.01,128.70,0.236
19.03,128.89,0.235
19.05,129.07,0.232
19.07,129.26,0.229
19.08,129.45,0.227
19.10,129.63,0.224
19.12,129.82,0.221
19.14,130.01,0.218
19.16,130.20,0.215
19.18,130.39,0.213
19.19,130.58,0.210
19.21,130.77,0.207
19.23,130.96,0.204
19.25,131.15,0.202
19.27,131.34,0.199
19.29,131.52,0.197
19.31,131.71,0.194
19.32,131.90,0.192
19.34,132.09,0.189
19.36,132.28,0.187
19.38,132.47,0.185
19.40,132.65,0.182
19.42,132.84,0.180
19.43,133.03,0.178
19.45,133.22,0.176
19.47,133.41,0.174
19.49,133.59,0.173
19.51,133.78,0.171
19.53,133.97,0.169
19.54,134.15,0.167
19.56,134.34,0.166
19.58,134.53,0.164
19.60,134.72,0.162
19.62,134.90,0.161
19.63,135.09,0.159
19.65,135.27,0.158
19.67,135.46,0.156
19.69,135.65,0.155
19.71,135.83,0.153
19.73,136.02,0.152
19.74,136.20,0.151
19.76,136.39,0.149
19.78,136.58,0.148
19.80,136.76,0.147
19.82,136.95,0.146
19.84,137.14,0.145
19.86,137.32,0.143
19.87,137.51,0.142
19.89,137.69,0.141
19.91,137.88,0.140
19.93,138.06,0.139
19.95,138.25,0.138
19.97,138.44,0.137
19.98,138.62,0.136
20.00,138.81,0.135
20.02,138.99,0.134
20.04,139.18,0.133
20.06,139.36,0.132
20.08,139.55,0.132
20.09,139.73,0.131
20.11,139.92,0.130
20.13,140.10,0.129
20.15,140.29,0.128
20.17,140.47,0.128
20.18,140.66,0.127
20.20,140.84,0.126
20.22,141.03,0.126
20.24,141.21,0.125
20.26,141.40,0.124
20.28,141.58,0.124
20.29,141.77,0.123
20.31,141.95,0.122
20.33,142.14,0.122
20.35,142.32,0.121
20.37,142.51,0.121
20.39,142.69,0.120
20.41,142.88,0.120
20.42,143.06,0.119
20.44,143.24,0.118
20.46,143.43,0.118
20.48,143.61,0.117
20.50,143.80,0.117
20.52,143.98,0.117
20.53,144.17,0.116
20.55,144.35,0.116
20.57,144.54,0.115
20.59,144.72,0.115
20.61,144.91,0.114
20.63,145.09,0.114
20.64,145.27,0.114
20.66,145.46,0.113
20.68,145.64,0.113
20.70,145.83,0.113
20.72,146.01,0.112
20.73,146.19,0.112
20.75,146.38,0.112
20.77,146.56,0.111
20.79,146.75,0.111
20.81,146.93,0.111
20.83,147.12,0.110
20.84,147.30,0.110
20.86,147.48,0.110
20.88,147.67,0.110
20.90,147.85,0.109
20.92,148.04,0.109
20.94,148.22,0.109
20.96,148.40,0.109
20.97,148.59,0.108
20.99,148.77,0.108
21.01,148.96,0.108
21.03,149.14,0.108
21.05,149.32,0.108
21.07,149.51,0.107
21.08,149.69,0.107
21.10,149.88,0.107
21.12,150.06,0.107
21.14,150.24,0.107
21.16,150.43,0.106
21.18,150.61,0.106
21.19,150.80,0.106
21.21,150.98,0.106
21.23,151.16,0.106
21.25,151.35,0.106
21.27,151.53,0.106
21.28,151.72,0.106
21.30,151.90,0.105
21.32,152.08,0.105
21.34,152.27,0.105
21.36,152.45,0.105
21.38,152.63,0.105
21.39,152.82,0.105
21.41,153.00,0.105
21.43,153.19,0.105
21.45,153.37,0.104
21.47,153.55,0.104
21.49,153.74,0.104
21.51,153.92,0.104
21.52,154.10,0.104
21.54,154.29,0.104
21.56,154.47,0.104
21.58,154.66,0.104
21.60,154.84,0.104
21.62,155.02,0.104
21.63,155.21,0.103
21.65,155.39,0.103
21.67,155.57,0.103
21.69,155.76,0.103
21.71,155.94,0.103
21.73,156.12,0.103
21.74,156.31,0.103
21.76,156.49,0.103
21.78,156.68,0.103
21.80,156.86,0.103
21.82,157.04,0.103
21.83,157.23,0.102
21.85,157.41,0.102
21.87,157.59,0.102
21.89,157.78,0.102
21.91,157.96,0.102
21.93,158.15,0.102
21.94,158.33,0.102
21.96,158.51,0.102
21.98,158.70,0.102
22.00,158.88,0.102
22.02,159.06,0.102
22.04,159.25,0.102
22.06,159.43,0.102
22.07,159.61,0.102
22.09,159.80,0.102
22.11,159.98,0.101
22.13,160.16,0.101
22.15,160.35,0.101
22.17,160.53,0.101
22.18,160.72,0.101
22.20,160.90,0.101
22.22,161.08,0.101
22.24,161.27,0.101
22.26,161.45,0.101
22.28,161.63,0.101
22.29,161.82,0.101
22.31,162.00,0.101
22.33,162.18,0.101
22.35,162.37,0.101
22.37,162.55,0.101
22.38,162.73,0.100
22.40,162.92,0.100
22.42,163.10,0.100
22.44,163.29,0.100
22.46,163.47,0.100
22.48,163.65,0.100
22.49,163.84,0.100
22.51,164.02,0.099
22.53,164.21,0.099
22.55,164.39,0.098
22.57,164.57,0.098
22.59,164.76,0.098
22.61,164.94,0.098
22.62,165.13,0.098
22.64,165.31,0.098
22.66,165.49,0.098
22.68,165.68,0.098
22.70,165.86,0.098
22.72,166.04,0.098
22.73,166.23,0.098
22.75,166.41,0.098
22.77,166.59,0.098
22.79,166.78,0.098
22.81,166.96,0.098
22.83,167.14,0.098
22.84,167.33,0.098
22.86,167.51,0.098
22.88,167.69,0.098
22.90,167.88,0.098
22.92,168.06,0.098
22.93,168.25,0.098
22.95,168.43,0.098
22.97,168.61,0.098
22.99,168.79,0.098
23.01,168.98,0.098
23.03,169.16,0.098
23.04,169.34,0.098
23.06,169.53,0.098
23.08,169.71,0.098
23.10,169.89,0.098
23.12,170.08,0.098
23.14,170.26,0.098
23.16,170.44,0.098
23.17,170.63,0.098
23.19,170.81,0.098
23.21,170.99,0.098
23.23,171.18,0.098
23.25,171.36,0.098
23.27,171.54,0.098
23.28,171.73,0.098
23.30,171.91,0.098
23.32,172.09,0.099
23.34,172.28,0.099
23.36,172.46,0.099
23.38,172.64,0.099
23.39,172.83,0.099
23.41,173.01,0.099
23.43,173.19,0.099
23.45,173.38,0.099
23.47,173.56,0.099
23.48,173.74,0.099
23.50,173.93,0.099
23.52,174.11,0.099
23.54,174.30,0.099
23.56,174.48,0.099
23.58,174.66,0.099
23.59,174.85,0.099
23.61,175.03,0.100
23.63,175.21,0.100
23.65,175.40,0.100
23.67,175.58,0.100
23.69,175.76,0.100
23.71,175.95,0.100
23.72,176.13,0.100
23.74,176.31,0.100
23.76,176.50,0.100
23.78,176.68,0.100
23.80,176.86,0.100
23.82,177.05,0.100
23.83,177.23,0.100
23.85,177.41,0.101
23.87,177.60,0.101
23.89,177.78,0.101
23.91,177.96,0.101
23.93,178.15,0.101
23.94,178.33,0.101
23.96,178.51,0.101
23.98,178.70,0.101
24.00,178.88,0.101
24.02,179.06,0.101
24.03,179.25,0.101
24.05,179.43,0.101
24.07,179.61,0.099
24.09,179.80,0.100
24.11,179.98,0.101
24.13,180.16,0.102
24.14,180.35,0.102
24.16,180.53,0.102
24.18,180.71,0.102
24.20,180.90,0.102
24.22,181.08,0.102
24.24,181.26,0.102
24.26,181.45,0.102
24.27,181.63,0.102
24.29,181.82,0.103
24.31,182.00,0.103
24.33,182.18,0.103
24.35,182.36,0.103
24.37,182.55,0.103
24.38,182.73,0.103
24.40,182.91,0.103
24.42,183.10,0.103
24.44,183.28,0.103
24.46,183.46,0.103
24.48,183.65,0.103
24.49,183.83,0.104
24.51,184.01,0.104
24.53,184.20,0.104
24.55,184.38,0.104
24.57,184.56,0.104
24.58,184.75,0.104
24.60,184.93,0.104
24.62,185.11,0.104
24.64,185.30,0.104
24.66,185.48,0.104
24.68,185.66,0.105
24.69,185.85,0.105
24.71,186.03,0.105
24.73,186.21,0.105
24.75,186.40,0.105
24.77,186.58,0.105
24.79,186.77,0.105
24.81,186.95,0.105
24.82,187.13,0.105
24.84,187.31,0.105
24.86,187.50,0.105
24.88,187.68,0.106
24.90,187.86,0.106
24.92,188.05,0.106
24.93,188.23,0.106
24.95,188.41,0.106
24.97,188.60,0.106
24.99,188.78,0.106
25.01,188.96,0.106
25.03,189.15,0.106
25.04,189.33,0.107
25.06,189.51,0.107
25.08,189.70,0.107
25.10,189.88,0.107
25.12,190.06,0.107
25.13,190.25,0.107
25.15,190.43,0.107
25.17,190.61,0.108
25.19,190.80,0.108
25.21,190.98,0.108
25.23,191.16,0.108
25.24,191.35,0.108
25.26,191.53,0.108
25.28,191.71,0.108
25.30,191.90,0.108
25.32,192.08,0.109
25.34,192.26,0.109
25.36,192.45,0.109
25.37,192.63,0.109
25.39,192.81,0.109
25.41,193.00,0.109
25.43,193.18,0.109
25.45,193.36,0.109
25.47,193.54,0.109
25.48,193.73,0.110
25.50,193.91,0.110
25.52,194.09,0.110
25.54,194.28,0.110
25.56,194.46,0.110
25.58,194.65,0.110
25.59,194.83,0.111
25.61,195.01,0.111
25.63,195.19,0.111
25.65,195.38,0.111
25.67,195.56,0.111
25.68,195.74,0.111
25.70,195.93,0.111
25.72,196.11,0.112
25.74,196.29,0.112
25.76,196.48,0.112
25.78,196.66,0.112
25.79,196.84,0.112
25.81,197.03,0.112
25.83,197.21,0.113
25.85,197.39,0.113
25.87,197.58,0.113
25.89,197.76,0.113
25.91,197.94,0.113
25.92,198.13,0.113
25.94,198.31,
25.96,198.49,
25.98,198.68,
25.99,,

[step]
Ramp 10.00 °C/min to -60.00 °C
Time,Temperature,Heat Flow (Normalized)
min,°C,W/g
27.99,200.12,0.022
28.01,200.12,0.022
28.03,200.11,0.022
28.05,200.10,0.022
28.07,200.07,0.020
28.08,200.03,0.015
28.10,199.96,0.008
28.12,199.86,-0.002
28.14,199.74,-0.013
28.16,199.61,-0.024
28.18,199.46,-0.033
28.19,199.31,-0.041
28.21,199.15,-0.047
28.23,198.98,-0.052
28.25,198.81,-0.056
28.27,198.64,-0.058
28.29,198.47,-0.061
28.31,198.29,-0.063
28.32,198.12,-0.065
28.34,197.94,-0.066
28.36,197.76,-0.067
28.38,197.58,-0.068
28.40,197.40,-0.069
28.42,197.22,-0.070
28.43,197.04,-0.070
28.45,196.86,-0.071
28.47,196.68,-0.072
28.49,196.50,-0.072
28.51,196.32,-0.072
28.53,196.14,-0.073
28.54,195.96,-0.073
28.56,195.78,-0.073
28.58,195.60,-0.074
28.60,195.42,-0.074
28.62,195.24,-0.074
28.63,195.05,-0.075
28.65,194.87,-0.075
28.67,194.69,-0.075
28.69,194.51,-0.075
28.71,194.33,-0.076
28.73,194.14,-0.076
28.74,193.96,-0.076
28.76,193.78,-0.076
28.78,193.60,-0.076
28.80,193.42,-0.077
28.82,193.24,-0.077
28.84,193.05,-0.077
28.86,192.87,-0.077
28.87,192.69,-0.077
28.89,192.51,-0.077
28.91,192.32,-0.077
28.93,192.14,-0.077
28.95,191.96,-0.078
28.97,191.78,-0.078
28.98,191.60,-0.078
29.00,191.41,-0.078
29.02,191.23,-0.078
29.04,191.05,-0.078
29.06,190.86,-0.078
29.08,190.68,-0.079
29.09,190.50,-0.079
29.11,190.32,-0.079
29.13,190.14,-0.079
29.15,189.95,-0.079
29.17,189.77,-0.079
29.18,189.59,-0.079
29.20,189.40,-0.079
29.22,189.22,-0.080
29.24,189.04,-0.080
29.26,188.86,-0.080
29.28,188.67,-0.080
29.29,188.49,-0.080
29.31,188.31,-0.080
29.33,188.13,-0.080
29.35,187.94,-0.080
29.37,187.76,-0.080
29.39,187.58,-0.080
29.41,187.39,-0.081
29.42,187.21,-0.081
29.44,187.03,-0.081
29.46,186.85,-0.081
29.48,186.66,-0.081
29.50,186.48,-0.081
29.52,186.30,-0.081
29.53,186.11,-0.081
29.55,185.93,-0.081
29.57,185.75,-0.081
29.59,185.56,-0.082
29.61,185.38,-0.082
29.63,185.20,-0.082
29.64,185.02,-0.082
29.66,184.83,-0.082
29.68,184.65,-0.082
29.70,184.47,-0.082
29.72,184.28,-0.082
29.73,184.10,-0.082
29.75,183.92,-0.082
29.77,183.74,-0.082
29.79,183.55,-0.083
29.81,183.37,-0.083
29.83,183.19,-0.083
29.84,183.00,-0.083
29.86,182.82,-0.083
29.88,182.64,-0.083
29.90,182.45,-0.083
29.92,182.27,-0.083
29.94,182.09,-0.083
29.96,181.91,-0.083
29.97,181.72,-0.083
29.99,181.54,-0.083
30.01,181.36,-0.083
30.03,181.17,-0.083
30.05,180.99,-0.084
30.07,180.81,-0.084
30.08,180.62,-0.084
30.10,180.44,-0.084
30.12,180.26,-0.084
30.14,180.07,-0.084
30.16,179.89,-0.084
30.18,179.71,-0.084
30.19,179.52,-0.084
30.21,179.34,-0.084
30.23,179.16,-0.084
30.25,178.98,-0.084
30.27,178.79,-0.084
30.28,178.61,-0.084
30.30,178.42,-0.085
30.32,178.24,-0.085
30.34,178.06,-0.085
30.36,177.88,-0.085
30.38,177.69,-0.085
30.39,177.51,-0.085
30.41,177.33,-0.085
30.43,177.15,-0.085
30.45,176.96,-0.085
30.47,176.78,-0.085
30.49,176.60,-0.085
30.51,176.41,-0.085
30.52,176.23,-0.085
30.54,176.05,-0.085
30.56,175.86,-0.085
30.58,175.68,-0.085
30.60,175.50,-0.085
30.62,175.31,-0.086
30.63,175.13,-0.086
30.65,174.95,-0.086
30.67,174.76,-0.086
30.69,174.58,-0.086
30.71,174.40,-0.086
30.73,174.21,-0.086
30.74,174.03,-0.086
30.76,173.85,-0.086
30.78,173.66,-0.086
30.80,173.48,-0.086
30.82,173.30,-0.086
30.83,173.11,-0.086
30.85,172.93,-0.086
30.87,172.75,-0.086
30.89,172.57,-0.086
30.91,172.38,-0.086
30.93,172.20,-0.086
30.94,172.02,-0.086
30.96,171.83,-0.086
30.98,171.65,-0.087
31.00,171.47,-0.087
31.02,171.28,-0.087
31.04,171.10,-0.087
31.06,170.92,-0.087
31.07,170.73,-0.087
31.09,170.55,-0.087
31.11,170.37,-0.087
31.13,170.19,-0.087
31.15,170.00,-0.087
31.17,169.82,-0.087
31.18,169.63,-0.087
31.20,169.45,-0.087
31.22,169.27,-0.087
31.24,169.08,-0.087
31.26,168.90,-0.087
31.28,168.72,-0.087
31.29,168.54,-0.087
31.31,168.35,-0.087
31.33,168.17,-0.087
31.35,167.99,-0.087
31.37,167.80,-0.087
31.38,167.62,-0.087
31.40,167.44,-0.088
31.42,167.25,-0.088
31.44,167.07,-0.088
31.46,166.89,-0.088
31.48,166.70,-0.088
31.49,166.52,-0.088
31.51,166.34,-0.088
31.53,166.15,-0.088
31.55,165.97,-0.088
31.57,165.79,-0.088
31.59,165.60,-0.088
31.61,165.42,-0.088
31.62,165.24,-0.088
31.64,165.06,-0.088
31.66,164.87,-0.088
31.68,164.69,-0.088
31.70,164.51,-0.088
31.72,164.32,-0.088
31.73,164.14,-0.088
31.75,163.96,-0.088
31.77,163.77,-0.088
31.79,163.59,-0.088
31.81,163.41,-0.088
31.83,163.22,-0.088
31.84,163.04,-0.088
31.86,162.86,-0.088
31.88,162.67,-0.088
31.90,162.49,-0.088
31.92,162.31,-0.088
31.93,162.12,-0.088
31.95,161.94,-0.088
31.97,161.76,-0.089
31.99,161.57,-0.089
32.01,161.39,-0.089
32.03,161.21,-0.089
32.04,161.02,-0.089
32.06,160.84,-0.089
32.08,160.66,-0.089
32.10,160.48,-0.089
32.12,160.29,-0.089
32.14,160.11,-0.089
32.16,159.93,-0.089
32.17,159.74,-0.089
32.19,159.56,-0.089
32.21,159.38,-0.089
32.23,159.19,-0.089
32.25,159.01,-0.089
32.27,158.83,-0.089
32.28,158.64,-0.089
32.30,158.46,-0.089
32.32,158.28,-0.089
32.34,158.09,-0.089
32.36,157.91,-0.089
32.38,157.73,-0.089
32.39,157.54,-0.089
32.41,157.36,-0.089
32.43,157.18,-0.089
32.45,156.99,-0.089
32.47,156.81,-0.089
32.48,156.63,-0.089
32.50,156.44,-0.089
32.52,156.26,-0.089
32.54,156.08,-0.089
32.56,155.90,-0.089
32.58,155.71,-0.089
32.59,155.53,-0.089
32.61,155.35,-0.089
32.63,155.16,-0.089
32.65,154.98,-0.089
32.67,154.80,-0.089
32.69,154.61,-0.089
32.71,154.43,-0.089
32.72,154.25,-0.089
32.74,154.06,-0.089
32.76,153.88,-0.089
32.78,153.70,-0.089
32.80,153.51,-0.090
32.82,153.33,-0.090
32.83,153.15,-0.090
32.85,152.96,-0.090
32.87,152.78,-0.090
32.89,152.60,-0.090
32.91,152.41,-0.090
32.93,152.23,-0.090
32.94,152.05,-0.090
32.96,151.86,-0.090
32.98,151.68,-0.090
33.00,151.50,-0.090
33.02,151.32,-0.090
33.03,151.13,-0.090
33.05,150.95,-0.090
33.07,150.77,-0.090
33.09,150.58,-0.090
33.11,150.40,-0.090
33.13,150.21,-0.090
33.14,150.03,-0.090
33.16,149.85,-0.090
33.18,149.67,-0.090
33.20,149.48,-0.090
33.22,149.30,-0.090
33.24,149.12,-0.090
33.26,148.93,-0.090
33.27,148.75,-0.090
33.29,148.57,-0.090
33.31,148.38,-0.090
33.33,148.20,-0.090
33.35,148.02,-0.090
33.37,147.83,-0.090
33.38,147.65,-0.090
33.40,147.47,-0.090
33.42,147.28,-0.090
33.44,147.10,-0.090
33.46,146.92,-0.090
33.48,146.73,-0.090
33.49,146.55,-0.090
33.51,146.37,-0.090
33.53,146.18,-0.090
33.55,146.00,-0.090
33.57,145.82,-0.090
33.58,145.64,-0.090
33.60,145.45,-0.090
33.62,145.27,-0.090
33.64,145.09,-0.090
33.66,144.90,-0.090
33.68,144.72,-0.090
33.69,144.53,-0.090
33.71,144.35,-0.090
33.73,144.17,-0.090
33.75,143.99,-0.090
33.77,143.80,-0.090
33.79,143.62,-0.090
33.81,143.44,-0.090
33.82,143.25,-0.090
33.84,143.07,-0.090
33.86,142.89,-0.090
33.88,142.70,-0.090
33.90,142.52,-0.090
33.92,142.34,-0.090
33.93,142.15,-0.090
33.95,141.97,-0.090
33.97,141.79,-0.090
33.99,141.60,-0.090
34.01,141.42,-0.090
34.03,141.24,-0.090
34.04,141.05,-0.090
34.06,140.87,-0.090
34.08,140.69,-0.090
34.10,140.50,-0.090
34.12,140.32,-0.090
34.14,140.14,-0.090
34.15,139.95,-0.090
34.17,139.77,-0.090
34.19,139.59,-0.090
34.21,139.40,-0.090
34.23,139.22,-0.090
34.24,139.04,-0.090
34.26,138.85,-0.090
34.28,138.67,-0.090
34.30,138.49,-0.090
34.32,138.30,-0.090
34.34,138.12,-0.090
34.36,137.94,-0.090
34.37,137.75,-0.090
34.39,137.57,-0.090
34.41,137.39,-0.090
34.43,137.21,-0.090
34.45,137.02,-0.090
34.46,136.84,-0.090
34.48,136.66,-0.090
34.50,136.47,-0.090
34.52,136.29,-0.090
34.54,136.11,-0.090
34.56,135.92,-0.090
34.58,135.74,-0.090
34.59,135.55,-0.090
34.61,135.37,-0.090
34.63,135.19,-0.090
34.65,135.01,-0.090
34.67,134.82,-0.090
34.69,134.64,-0.090
34.70,134.46,-0.090
34.72,134.27,-0.090
34.74,134.09,-0.090
34.76,133.91,-0.090
34.78,133.72,-0.090
34.79,133.54,-0.090
34.81,133.36,-0.090
34.83,133.17,-0.090
34.85,132.99,-0.090
34.87,132.81,-0.090
34.89,132.62,-0.090
34.91,132.44,-0.090
34.92,132.26,-0.090
34.94,132.07,-0.090
34.96,131.89,-0.090
34.98,131.71,-0.090
35.00,131.52,-0.090
35.01,131.34,-0.090
35.03,131.16,-0.090
35.05,130.97,-0.090
35.07,130.79,-0.090
35.09,130.61,-0.090
35.11,130.42,-0.090
35.13,130.24,-0.090
35.14,130.06,-0.090
35.16,129.87,-0.090
35.18,129.69,-0.090
35.20,129.51,-0.090
35.22,129.32,-0.090
35.24,129.14,-0.090
35.25,128.96,-0.090
35.27,128.78,-0.090
35.29,128.59,-0.090
[...]
119.22,10.90,0.050
119.24,11.09,0.050
119.25,11.27,0.050
119.27,11.45,0.050
119.29,11.64,0.050
119.31,11.82,0.050
119.33,12.00,0.050
119.35,12.19,0.050
119.36,12.37,0.050
119.38,12.55,0.050
119.40,12.74,0.050
119.42,12.92,0.050
119.44,13.10,0.050
119.46,13.29,0.050
119.48,13.47,0.050
119.49,13.65,0.050
119.51,13.84,0.050
119.53,14.02,0.050
119.55,14.20,0.050
119.57,14.39,0.050
119.59,14.57,0.050
119.60,14.75,0.050
119.62,14.94,0.050
119.64,15.12,0.050
119.66,15.30,0.050
119.68,15.49,0.050
119.70,15.67,0.050
119.71,15.86,0.050
119.73,16.04,0.050
119.75,16.22,0.051
119.77,16.41,0.051
119.79,16.59,0.051
119.80,16.77,0.051
119.82,16.96,0.051
119.84,17.14,0.051
119.86,17.32,0.051
119.88,17.51,0.051
119.90,17.69,0.051
119.91,17.87,0.051
119.93,18.06,0.051
119.95,18.24,0.051
119.97,18.43,0.051
119.99,18.61,0.051
120.01,18.79,0.051
120.03,18.98,0.051
120.04,19.16,0.051
120.06,19.34,0.051
120.08,19.53,0.051
120.10,19.71,0.051
120.12,19.89,0.051
120.14,20.08,0.051
120.15,20.26,0.051
120.17,20.44,0.051
120.19,20.63,0.051
120.21,20.81,0.051
120.23,20.99,0.051
120.25,21.18,0.051
120.26,21.36,0.051
120.28,21.55,0.051
120.30,21.73,0.052
120.32,21.91,0.052
120.34,22.10,0.052
120.35,22.28,0.052
120.37,22.46,0.052
120.39,22.65,0.052
120.41,22.83,0.052
120.43,23.01,0.052
120.45,23.20,0.052
120.46,23.38,0.052
120.48,23.56,0.052
120.50,23.75,0.052
120.52,23.93,0.052
120.54,24.11,0.052
120.56,24.30,0.052
120.58,24.48,0.052
120.59,24.67,0.052
120.61,24.85,0.052
120.63,25.03,0.052
120.65,25.22,0.052
120.67,25.40,0.052
120.69,25.58,0.052
120.70,25.77,0.052
120.72,25.95,0.052
120.74,26.13,0.052
120.76,26.32,0.052
120.78,26.50,0.052
120.80,26.68,0.052
120.81,26.87,0.052
120.83,27.05,0.052
120.85,27.23,0.053
120.87,27.42,0.053
120.89,27.60,0.053
120.90,27.79,0.053
120.92,27.97,0.053
120.94,28.15,0.053
120.96,28.34,0.053
120.98,28.52,0.053
121.00,28.70,0.053
121.01,28.89,0.053
121.03,29.07,0.053
121.05,29.25,0.053
121.07,29.44,0.053
121.09,29.62,0.053
121.11,29.80,0.053
121.13,29.99,0.053
121.14,30.17,0.053
121.16,30.35,0.053
121.18,30.54,0.053
121.20,30.72,0.053
121.22,30.90,0.053
121.24,31.09,0.053
121.25,31.27,0.053
121.27,31.46,0.053
121.29,31.64,0.053
121.31,31.82,0.053
121.33,32.01,0.053
121.35,32.19,0.053
121.36,32.37,0.053
121.38,32.56,0.054
121.40,32.74,0.054
121.42,32.92,0.054
121.44,33.11,0.054
121.45,33.29,0.054
121.47,33.47,0.054
121.49,33.66,0.054
121.51,33.84,0.054
121.53,34.02,0.054
121.55,34.21,0.054
121.56,34.39,0.054
121.58,34.57,0.054
121.60,34.76,0.054
121.62,34.94,0.054
121.64,35.12,0.054
121.66,35.31,0.054
121.68,35.49,0.054
121.69,35.68,0.054
121.71,35.86,0.054
121.73,36.04,0.054
121.75,36.23,0.054
121.77,36.41,0.054
121.79,36.59,0.054
121.80,36.78,0.054
121.82,36.96,0.054
121.84,37.14,0.054
121.86,37.33,0.054
121.88,37.51,0.054
121.90,37.69,0.054
121.91,37.88,0.054
121.93,38.06,0.055
121.95,38.24,0.055
121.97,38.43,0.055
121.99,38.61,0.055
122.00,38.79,0.055
122.02,38.98,0.055
122.04,39.16,0.055
122.06,39.34,0.055
122.08,39.53,0.055
122.10,39.71,0.055
122.11,39.90,0.055
122.13,40.08,0.055
122.15,40.26,0.055
122.17,40.44,0.055
122.19,40.63,0.055
122.21,40.81,0.055
122.23,41.00,0.055
122.24,41.18,0.055
122.26,41.36,0.055
122.28,41.55,0.055
122.30,41.73,0.055
122.32,41.91,0.055
122.34,42.10,0.055
122.35,42.28,0.055
122.37,42.46,0.055
122.39,42.65,0.055
122.41,42.83,0.055
122.43,43.01,0.055
122.45,43.20,0.056
122.46,43.38,0.056
122.48,43.56,0.056
122.50,43.75,0.056
122.52,43.93,0.056
122.54,44.11,0.056
122.55,44.30,0.056
122.57,44.48,0.056
122.59,44.66,0.056
122.61,44.85,0.056
122.63,45.03,0.056
122.65,45.22,0.056
122.66,45.40,0.056
122.68,45.58,0.056
122.70,45.77,0.056
122.72,45.95,0.056
122.74,46.13,0.056
122.76,46.32,0.056
122.78,46.50,0.056
122.79,46.68,0.056
122.81,46.87,0.056
122.83,47.05,0.056
122.85,47.23,0.056
122.87,47.42,0.056
122.89,47.60,0.056
122.90,47.79,0.056
122.92,47.97,0.056
122.94,48.15,0.057
122.96,48.33,0.057
122.98,48.52,0.057
123.00,48.70,0.057
123.01,48.89,0.057
123.03,49.07,0.057
123.05,49.25,0.057
123.07,49.44,0.057
123.09,49.62,0.057
123.10,49.80,0.057
123.12,49.99,0.057
123.14,50.17,0.057
123.16,50.35,0.057
123.18,50.54,0.057
123.20,50.72,0.057
123.21,50.90,0.057
123.23,51.09,0.057
123.25,51.27,0.057
123.27,51.45,0.057
123.29,51.64,0.057
123.31,51.82,0.057
123.33,52.01,0.057
123.34,52.19,0.057
123.36,52.37,0.057
123.38,52.56,0.057
123.40,52.74,0.057
123.42,52.92,0.057
123.44,53.11,0.058
123.45,53.29,0.058
123.47,53.47,0.058
123.49,53.66,0.058
123.51,53.84,0.058
123.53,54.02,0.058
123.55,54.21,0.058
123.56,54.39,0.058
123.58,54.57,0.058
123.60,54.76,0.058
123.62,54.94,0.058
123.64,55.12,0.058
123.65,55.31,0.058
123.67,55.49,0.058
123.69,55.67,0.058
123.71,55.86,0.058
123.73,56.04,0.058
123.75,56.22,0.058
123.76,56.41,0.058
123.78,56.59,0.058
123.80,56.77,0.058
123.82,56.96,0.058
123.84,57.14,0.058
123.86,57.32,0.058
123.88,57.51,0.058
123.89,57.69,0.058
123.91,57.88,0.058
123.93,58.06,0.059
123.95,58.24,0.059
123.97,58.43,0.059
123.99,58.61,0.059
124.00,58.79,0.059
124.02,58.98,0.059
124.04,59.16,0.059
124.06,59.34,0.059
124.08,59.53,0.059
124.10,59.71,0.059
124.11,59.89,0.059
124.13,60.08,0.059
124.15,60.26,0.059
124.17,60.44,0.059
124.19,60.63,0.059
124.20,60.81,0.059
124.22,61.00,0.059
124.24,61.18,0.059
124.26,61.36,0.059
124.28,61.55,0.059
124.30,61.73,0.059
124.31,61.91,0.059
124.33,62.10,0.059
124.35,62.28,0.060
124.37,62.46,0.060
124.39,62.65,0.060
124.41,62.83,0.060
124.43,63.01,0.060
124.44,63.20,0.060
124.46,63.38,0.060
124.48,63.56,0.060
124.50,63.75,0.060
124.52,63.93,0.060
124.54,64.12,0.060
124.55,64.30,0.060
124.57,64.48,0.060
124.59,64.66,0.060
124.61,64.85,0.060
124.63,65.03,0.060
124.65,65.22,0.060
124.66,65.40,0.060
124.68,65.58,0.060
124.70,65.77,0.060
124.72,65.95,0.060
124.74,66.13,0.060
124.75,66.32,0.060
124.77,66.50,0.061
124.79,66.68,0.061
124.81,66.87,0.061
124.83,67.05,0.061
124.85,67.23,0.061
124.86,67.42,0.061
124.88,67.60,0.061
124.90,67.78,0.061
124.92,67.97,0.061
124.94,68.15,0.061
124.96,68.33,0.061
124.98,68.52,0.061
124.99,68.70,0.061
125.01,68.88,0.061
125.03,69.07,0.061
125.05,69.25,0.061
125.07,69.43,0.061
125.09,69.62,0.061
125.10,69.80,0.061
125.12,69.98,0.061
125.14,70.17,0.061
125.16,70.35,0.061
125.18,70.54,0.062
125.20,70.72,0.062
125.21,70.90,0.062
125.23,71.08,0.062
125.25,71.27,0.062
125.27,71.45,0.062
125.29,71.64,0.062
125.30,71.82,0.062
125.32,72.00,0.062
125.34,72.19,0.062
125.36,72.37,0.062
125.38,72.55,0.062
125.40,72.74,0.062
125.41,72.92,0.062
125.43,73.10,0.062
125.45,73.29,0.062
125.47,73.47,0.062
125.49,73.65,0.062
125.51,73.84,0.062
125.53,74.02,0.063
125.54,74.20,0.063
125.56,74.39,0.063
125.58,74.57,0.063
125.60,74.75,0.063
125.62,74.94,0.063
125.64,75.12,0.063
125.65,75.30,0.063
125.67,75.49,0.063
125.69,75.67,0.063
125.71,75.85,0.063
125.73,76.04,0.063
125.75,76.22,0.063
125.76,76.40,0.063
125.78,76.59,0.063
125.80,76.77,0.063
125.82,76.95,0.063
125.84,77.14,0.064
125.85,77.32,0.064
125.87,77.50,0.064
125.89,77.69,0.064
125.91,77.87,0.064
125.93,78.05,0.064
125.95,78.24,0.064
125.96,78.42,0.064
125.98,78.60,0.064
126.00,78.79,0.064
126.02,78.97,0.064
126.04,79.15,0.064
126.06,79.34,0.064
126.08,79.52,0.064
126.09,79.70,0.065
126.11,79.89,0.065
126.13,80.07,0.065
126.15,80.25,0.065
126.17,80.44,0.065
126.19,80.62,0.065
126.20,80.80,0.065
126.22,80.99,0.065
126.24,81.17,0.065
126.26,81.35,0.065
126.28,81.54,0.065
126.30,81.72,0.065
126.31,81.90,0.065
126.33,82.09,0.066
126.35,82.27,0.066
126.37,82.45,0.066
126.39,82.64,0.066
126.40,82.82,0.066
126.42,83.00,0.066
126.44,83.19,0.066
126.46,83.37,0.066
126.48,83.55,0.066
126.50,83.74,0.066
126.51,83.92,0.066
126.53,84.11,0.066
126.55,84.29,0.067
126.57,84.47,0.067
126.59,84.65,0.067
126.61,84.84,0.067
126.63,85.02,0.067
126.64,85.20,0.067
126.66,85.39,0.067
126.68,85.57,0.067
126.70,85.75,0.067
126.72,85.94,0.068
126.74,86.12,0.068
126.75,86.30,0.068
126.77,86.49,0.068
126.79,86.67,0.068
126.81,86.85,0.068
126.83,87.04,0.068
126.85,87.22,0.068
126.86,87.40,0.069
126.88,87.59,0.069
126.90,87.77,0.069
126.92,87.95,0.069
126.94,88.14,0.069
126.95,88.32,0.069
126.97,88.50,0.069
126.99,88.69,0.070
127.01,88.87,0.070
127.03,89.05,0.070
127.05,89.24,0.070
127.06,89.42,0.070
127.08,89.60,0.070
127.10,89.79,0.071
127.12,89.97,0.071
127.14,90.15,0.071
127.16,90.34,0.071
127.18,90.52,0.071
127.19,90.70,0.072
127.21,90.88,0.072
127.23,91.07,0.072
127.25,91.25,0.072
127.27,91.43,0.072
127.29,91.62,0.072
127.30,91.80,0.073
127.32,91.98,0.073
127.34,92.17,0.073
127.36,92.35,0.073
127.38,92.53,0.073
127.40,92.71,0.074
127.41,92.90,0.074
127.43,93.08,0.074
127.45,93.27,0.074
127.47,93.45,0.074
127.49,93.63,0.074
127.50,93.82,0.075
127.52,94.00,0.075
127.54,94.18,0.075
127.56,94.37,0.075
127.58,94.55,0.075
127.60,94.73,0.075
127.61,94.92,0.076
127.63,95.10,0.076
127.65,95.28,0.076
127.67,95.47,0.076
127.69,95.65,0.076
127.71,95.83,0.076
127.73,96.01,0.076
127.74,96.20,0.077
127.76,96.38,0.077
127.78,96.57,0.077
127.80,96.75,0.077
127.82,96.93,0.077
127.84,97.11,0.077
127.85,97.30,0.077
127.87,97.48,0.077
127.89,97.66,0.077
127.91,97.85,0.078
127.93,98.03,0.078
127.95,98.21,0.078
127.96,98.40,0.078
127.98,98.58,0.078
128.00,98.76,0.078
128.02,98.95,0.078
128.04,99.13,0.078
128.05,99.31,0.079
128.07,99.50,0.079
128.09,99.68,0.079
128.11,99.86,0.079
128.13,100.05,0.079
128.15,100.23,0.079
128.16,100.41,0.079
128.18,100.60,0.079
128.20,100.78,0.079
128.22,100.96,0.079
128.24,101.15,0.079
128.26,101.33,0.079
128.28,101.51,0.080
128.29,101.70,0.080
128.31,101.88,0.080
128.33,102.06,0.080
128.35,102.25,0.080
128.37,102.43,0.080
128.39,102.61,0.080
128.40,102.80,0.080
128.42,102.98,0.080
128.44,103.16,0.080
128.46,103.35,0.080
128.48,103.53,0.080
128.50,103.71,0.080
128.51,103.90,0.080
128.53,104.08,0.080
128.55,104.26,0.080
128.57,104.45,0.081
128.59,104.63,0.081
128.60,104.81,0.081
128.62,105.00,0.081
128.64,105.18,0.081
128.66,105.36,0.081
128.68,105.55,0.081
128.70,105.73,0.081
128.71,105.92,0.081
128.73,106.10,0.081
128.75,106.28,0.081
128.77,106.47,0.081
128.79,106.65,0.081
128.81,106.83,0.081
128.83,107.02,0.081
128.84,107.20,0.081
128.86,107.38,0.081
128.88,107.57,0.081
128.90,107.75,0.081
128.92,107.93,0.081
128.94,108.12,0.081
128.95,108.30,0.081
128.97,108.48,0.081
128.99,108.67,0.081
129.01,108.85,0.081
129.03,109.03,0.081
129.05,109.22,0.081
129.06,109.40,0.081
129.08,109.59,0.081
129.10,109.77,0.081
129.12,109.95,0.081
129.14,110.13,0.082
129.15,110.32,0.082
129.17,110.50,0.082
129.19,110.68,0.082
129.21,110.87,0.082
129.23,111.05,0.082
129.25,111.24,0.082
129.26,111.42,0.082
129.28,111.60,0.082
129.30,111.79,0.082
129.32,111.97,0.082
129.34,112.15,0.082
129.36,112.34,0.082
129.38,112.52,0.082
129.39,112.70,0.082
129.41,112.89,0.082
129.43,113.07,0.082
129.45,113.25,0.082
129.47,113.44,0.082
129.49,113.62,0.082
129.50,113.81,0.082
129.52,113.99,0.082
129.54,114.17,0.082
129.56,114.36,0.082
129.58,114.54,0.082
129.60,114.72,0.082
129.61,114.91,0.082
129.63,115.09,0.082
129.65,115.27,0.082
129.67,115.46,0.082
129.69,115.64,0.082
129.70,115.82,0.082
129.72,116.01,0.082
129.74,116.19,0.082
129.76,116.37,0.082
129.78,116.56,0.082
129.80,116.74,0.082
129.81,116.93,0.082
129.83,117.11,0.082
129.85,117.29,0.082
129.87,117.48,0.082
129.89,117.66,0.083
129.91,117.84,0.083
129.93,118.03,0.083
129.94,118.21,0.083
129.96,118.39,0.083
129.98,118.58,0.083
130.00,118.76,0.083
130.02,118.94,0.083
130.04,119.13,0.083
130.05,119.31,0.083
130.07,119.49,0.083
130.09,119.68,0.083
130.11,119.86,0.083
130.13,120.04,0.083
130.15,120.23,0.083
130.16,120.41,0.083
130.18,120.59,0.083
130.20,120.78,0.083
130.22,120.96,0.083
130.24,121.15,0.083
130.25,121.33,0.083
130.27,121.51,0.083
130.29,121.70,0.083
130.31,121.88,0.083
130.33,122.06,0.083
130.35,122.25,0.083
130.36,122.43,0.083
130.38,122.61,0.083
130.40,122.80,0.083
130.42,122.98,0.083
130.44,123.16,0.083
130.46,123.35,0.084
130.48,123.53,0.084
130.49,123.71,0.084
130.51,123.90,0.084
130.53,124.08,0.084
130.55,124.26,0.084
130.57,124.45,0.084
130.59,124.63,0.084
130.60,124.81,0.084
130.62,125.00,0.084
130.64,125.18,0.084
130.66,125.36,0.084
130.68,125.55,0.084
130.70,125.73,0.084
130.71,125.91,0.084
130.73,126.10,0.084
130.75,126.28,0.084
130.77,126.47,0.084
130.79,126.65,0.084
130.80,126.83,0.084
130.82,127.01,0.084
130.84,127.20,0.084
130.86,127.38,0.084
130.88,127.57,0.084
130.90,127.75,0.084
130.91,127.93,0.085
130.93,128.12,0.085
130.95,128.30,0.085
130.97,128.48,0.085
130.99,128.67,0.085
131.01,128.85,0.085
131.03,129.03,0.085
131.04,129.22,0.085
131.06,129.40,0.085
131.08,129.58,0.085
131.10,129.77,0.085
131.12,129.95,0.085
131.14,130.13,0.085
131.15,130.32,0.085
131.17,130.50,0.085
131.19,130.69,0.085
131.21,130.87,0.085
131.23,131.05,0.085
131.25,131.24,0.085
131.26,131.42,0.085
131.28,131.60,0.085
131.30,131.79,0.086
131.32,131.97,0.086
131.34,132.15,0.086
131.35,132.34,0.086
131.37,132.52,0.086
131.39,132.70,0.086
131.41,132.89,0.086
131.43,133.07,0.086
131.45,133.25,0.086
131.46,133.44,0.086
131.48,133.62,0.086
131.50,133.80,0.086
131.52,133.99,0.086
131.54,134.17,0.086
131.56,134.35,0.086
131.58,134.54,0.086
131.59,134.72,0.086
131.61,134.90,0.086
131.63,135.09,0.086
131.65,135.27,0.086
131.67,135.45,0.087
131.69,135.64,0.087
131.70,135.82,0.087
131.72,136.01,0.087
131.74,136.19,0.087
131.76,136.37,0.087
131.78,136.56,0.087
131.80,136.74,0.087
131.81,136.92,0.087
131.83,137.11,0.087
131.85,137.29,0.087
131.87,137.47,0.087
131.89,137.66,0.087
131.90,137.84,0.087
131.92,138.02,0.087
131.94,138.21,0.087
131.96,138.39,0.087
131.98,138.58,0.087
132.00,138.76,0.087
132.01,138.94,0.087
132.03,139.12,0.087
132.05,139.31,0.088
132.07,139.49,0.088
132.09,139.67,0.088
132.11,139.86,0.088
132.13,140.04,0.088
132.14,140.22,0.088
132.16,140.41,0.088
132.18,140.59,0.088
132.20,140.77,0.088
132.22,140.96,0.088
132.24,141.14,0.088
132.25,141.32,0.088
132.27,141.51,0.088
132.29,141.69,0.088
132.31,141.87,0.088
132.33,142.06,0.088
132.35,142.24,0.088
132.36,142.42,0.088
132.38,142.61,0.088
132.40,142.79,0.088
132.42,142.97,0.088
132.44,143.16,0.088
132.45,143.34,0.088
132.47,143.52,0.088
132.49,143.71,0.088
132.51,143.89,0.088
132.53,144.08,0.089
132.55,144.26,0.089
132.56,144.44,0.089
132.58,144.62,0.089
132.60,144.81,0.089
132.62,144.99,0.089
132.64,145.17,0.089
132.66,145.36,0.089
132.68,145.54,0.089
132.69,145.72,0.089
132.71,145.91,0.089
132.73,146.09,0.089
132.75,146.28,0.089
132.77,146.46,0.089
132.79,146.64,0.089
132.80,146.83,0.089
132.82,147.01,0.089
132.84,147.19,0.089
132.86,147.38,0.089
132.88,147.56,0.089
132.90,147.74,0.089
132.91,147.93,0.089
132.93,148.11,0.089
132.95,148.29,0.089
132.97,148.47,0.089
132.99,148.66,0.089
133.00,148.84,0.090
133.02,149.03,0.090
133.04,149.21,0.090
133.06,149.39,0.090
133.08,149.58,0.090
133.10,149.76,0.090
133.11,149.94,0.090
133.13,150.13,0.090
133.15,150.31,0.090
133.17,150.50,0.090
133.19,150.68,0.090
133.21,150.86,0.090
133.23,151.05,0.090
133.24,151.23,0.090
133.26,151.42,0.090
133.28,151.60,0.090
133.30,151.79,0.090
133.32,151.97,0.090
133.34,152.15,0.091
133.35,152.34,0.091
133.37,152.52,0.091
133.39,152.70,0.091
133.41,152.89,0.091
133.43,153.07,0.091
133.45,153.25,0.091
133.46,153.44,0.091
133.48,153.62,0.091
133.50,153.80,0.091
133.52,153.99,0.091
133.54,154.17,0.091
133.55,154.35,0.091
133.57,154.54,0.091
133.59,154.72,0.091
133.61,154.90,0.091
133.63,155.09,0.091
133.65,155.27,0.091
133.66,155.45,0.091
133.68,155.63,0.091
133.70,155.82,0.091
133.72,156.00,0.091
133.74,156.18,0.091
133.76,156.37,0.091
133.78,156.55,0.091
133.79,156.73,0.091
133.81,156.92,0.091
133.83,157.10,0.091
133.85,157.28,0.091
133.87,157.47,0.091
133.89,157.65,0.092
133.90,157.83,0.092
133.92,158.02,0.092
133.94,158.20,0.092
133.96,158.38,0.092
133.98,158.57,0.092
134.00,158.75,0.092
134.01,158.93,0.092
134.03,159.12,0.092
134.05,159.30,0.092
134.07,159.48,0.092
134.09,159.67,0.092
134.10,159.85,0.092
134.12,160.03,0.092
134.14,160.22,0.092
134.16,160.40,0.092
134.18,160.58,0.092
134.20,160.77,0.092
134.21,160.95,0.092
134.23,161.13,0.092
134.25,161.32,0.092
134.27,161.50,0.093
134.29,161.68,0.093
134.31,161.87,0.093
134.33,162.05,0.093
134.34,162.23,0.093
134.36,162.42,0.093
134.38,162.60,0.093
134.40,162.78,0.093
134.42,162.97,0.093
134.44,163.15,0.093
134.45,163.33,0.093
134.47,163.52,0.093
134.49,163.70,0.093
134.51,163.88,0.093
134.53,164.07,0.093
134.55,164.25,0.093
134.56,164.43,0.093
134.58,164.62,0.093
134.60,164.80,0.093
134.62,164.99,0.093
134.64,165.17,0.094
134.65,165.35,0.094
134.67,165.54,0.094
134.69,165.72,0.094
134.71,165.90,0.094
134.73,166.09,0.094
134.75,166.27,0.094
134.76,166.45,0.094
134.78,166.64,0.094
134.80,166.82,0.094
134.82,167.00,0.094
134.84,167.19,0.094
134.86,167.37,0.094
134.88,167.55,0.094
134.89,167.74,0.094
134.91,167.92,0.094
134.93,168.10,0.094
134.95,168.29,0.094
134.97,168.47,0.094
134.99,168.65,0.094
135.00,168.84,0.095
135.02,169.02,0.095
135.04,169.21,0.095
135.06,169.39,0.095
135.08,169.57,0.095
135.10,169.76,0.095
135.11,169.94,0.095
135.13,170.12,0.095
135.15,170.30,0.095
135.17,170.49,0.095
135.19,170.67,0.095
135.20,170.85,0.095
135.22,171.04,0.095
135.24,171.22,0.095
135.26,171.40,0.095
135.28,171.59,0.095
135.30,171.77,0.095
135.31,171.95,0.095
135.33,172.14,0.095
135.35,172.32,0.095
135.37,172.50,0.096
135.39,172.69,0.096
135.41,172.87,0.096
135.43,173.06,0.096
135.44,173.24,0.096
135.46,173.42,0.096
135.48,173.61,0.096
135.50,173.79,0.096
135.52,173.97,0.096
135.54,174.16,0.096
135.55,174.34,0.096
135.57,174.52,0.096
135.59,174.71,0.096
135.61,174.89,0.096
135.63,175.07,0.096
135.65,175.26,0.096
135.66,175.44,0.096
135.68,175.62,0.097
135.70,175.80,0.097
135.72,175.99,0.097
135.74,176.17,0.097
135.75,176.35,0.097
135.77,176.54,0.097
135.79,176.72,0.097
135.81,176.90,0.097
135.83,177.09,0.097
135.85,177.27,0.097
135.86,177.45,0.097
135.88,177.64,0.097
135.90,177.82,0.097
135.92,178.01,0.097
135.94,178.19,0.097
135.96,178.37,0.098
135.98,178.56,0.098
135.99,178.74,0.098
136.01,178.92,0.098
136.03,179.11,0.098
136.05,179.29,0.098
136.07,179.47,0.098
136.09,179.66,0.098
136.10,179.84,0.098
136.12,180.02,0.098
136.14,180.21,0.098
136.16,180.39,0.098
136.18,180.57,0.098
136.20,180.76,0.098
136.21,180.94,0.098
136.23,181.12,0.098
136.25,181.31,0.099
136.27,181.49,0.099
136.29,181.67,0.099
136.30,181.86,0.099
136.32,182.04,0.099
136.34,182.22,0.099
136.36,182.41,0.099
136.38,182.59,0.099
136.40,182.77,0.099
136.41,182.96,0.099
136.43,183.14,0.099
136.45,183.32,0.099
136.47,183.51,0.099
136.49,183.69,0.100
136.51,183.88,0.100
136.53,184.06,0.100
136.54,184.24,0.100
136.56,184.43,0.100
136.58,184.61,0.100
136.60,184.79,0.100
136.62,184.98,0.100
136.63,185.16,0.100
136.65,185.34,0.100
136.67,185.52,0.100
136.69,185.71,0.100
136.71,185.89,0.100
136.73,186.07,0.101
136.75,186.26,0.101
136.76,186.44,0.101
136.78,186.62,0.101
136.80,186.81,0.101
136.82,186.99,0.101
136.84,187.18,0.101
136.85,187.36,0.101
136.87,187.54,0.101
136.89,187.73,0.101
136.91,187.91,0.101
136.93,188.09,0.101
136.95,188.28,0.101
136.97,188.46,0.101
136.98,188.64,0.102
137.00,188.83,0.102
137.02,189.01,0.102
137.04,189.19,0.102
137.06,189.38,0.102
137.08,189.56,0.102
137.09,189.74,0.102
137.11,189.93,0.102
137.13,190.11,0.102
137.15,190.29,0.102
137.17,190.48,0.102
137.18,190.66,0.102
137.20,190.84,0.102
137.22,191.02,0.102
137.24,191.21,0.103
137.26,191.39,0.103
137.28,191.58,0.103
137.30,191.76,0.103
137.31,191.94,0.103
137.33,192.12,0.103
137.35,192.31,0.103
137.37,192.49,0.103
137.39,192.67,0.103
137.40,192.86,0.103
137.42,193.04,0.103
137.44,193.22,0.103
137.46,193.41,0.104
137.48,193.59,0.104
137.50,193.78,0.104
137.52,193.96,0.104
137.53,194.14,0.104
137.55,194.33,0.104
137.57,194.51,0.104
137.59,194.69,0.104
137.61,194.88,0.104
137.63,195.06,0.104
137.64,195.24,0.104
137.66,195.43,0.104
137.68,195.61,0.104
137.70,195.79,0.105
137.72,195.98,0.105
137.73,196.16,0.105
137.75,196.34,0.105
137.77,196.53,0.105
137.79,196.71,0.105
137.81,196.89,0.105
137.83,197.08,0.105
137.85,197.26,0.105
137.86,197.44,0.105
137.88,197.63,0.105
137.90,197.81,0.106
137.92,197.99,0.106
137.94,198.18,
137.95,198.36,
137.97,198.54,
137.99,,
137.99,,