File: DSC/Earl/2025_10_13_1CBN_2PVP29_ASD_5Cmin_n60C_150C_x3.csv
Filename,2025_10_13_1CBN_2PVP29_ASD_5Cmin_n60C_150C_x3
Instrument name,DSC2A-00468 (192.168.1.100)
Operator,JLY
rundate,10/14/2025
Sample name,2025_10_13_1CBN_2PVP29_ASD_5Cmin_n60C_150C_x3
proceduresegments,Data Off ; Equilibrate -60.00 °C; Data On ; Ramp 5.00 °C/min to 150.00 °C; Data Off ; Isothermal 1.0 min; Data On ; Ramp 5.00 °C/min to -60.00 °C; Data Off ; Isothermal 1.0 min; Data On ; Ramp 5.00 °C/min to 150.00 °C; Data Off ; Isothermal 1.0 min; Data On ; Ramp 5.00 °C/min to -60.00 °C; Data Off ; Isothermal 1.0 min; Data On ; Ramp 5.00 °C/min to 150.00 °C
[File Parameters]
Run date,10/14/2025 10:02:09 AM
Trios version,5.1.1.46572
Original File Name,
Current File Name,D:\DSC2500\JYarger\2025_10_13_1CBN_2PVP29_ASD_5Cmin_n60C_150C_x3.tri
[Procedure]
Procedure Name,ASD_n60C_150C_5Cmin_x3
Sample Name,2025_10_13_1CBN_2PVP29_ASD_5Cmin_n60C_150C_x3
Sample Mass,5.87 mg
Reference Sample Mass,0 mg
Pan Mass,32.44 mg
Pan Number,17
Reference Pan Mass,32.55 mg
Reference Pan Number,1
Pan Type,Aluminum
Comments,DSC_Samples_Y2_Tray_ASDs_Pharma_Oct2025 Google Sheet.
Project Name,Amorphous Pharma
Operator,JLY
Test,Custom
Unload Max Temperature,30
Unload Min Temperature,30
Load Max Temperature,30
Load Min Temperature,30
Stop on Gas Flow Error,Yes
[Signal List]
Signal #1,Time (min)
Signal #2,Temperature (°C)
Signal #3,Heat Flow (mW)
Signal #4,Delta T (µV)
Signal #5,Delta Tzero (µV)
Signal #6,Tzero Temperature (°C)
Signal #7,Cell Purge (mL/min)
Signal #8,Heater Temp (°C)
Signal #9,Power Delivered (W)
Signal #10,Reference Junction Temperature (°C)
Signal #11,Flange Temperature (°C)
Signal #12,Heat Flow Phase (rad)
Signal #13,Total Heat Capacity (J/°C)
Signal #14,Heat Capacity (J/°C)
[Configuration]
Company Name,ASU
Instrument Name,DSC2A-00468
Instrument Type,DSC2500
Serial Number,DSC2A-00468
IP,192.168.1.100
Location of Instrument,MRRC
DisplayType,Unknown
Sample Interval ,0.1 s/pt
Selected Heat Flow,T4P
Exotherm Direction,Down
Cell Serial,DRC2-00792
Lid Type,Standard
Cooler,RCS 90
Leave Cooler on at End of Sequence,On
Gas 2,Nitrogen
Gas Selected,Channel 1
Flow Rate,50 mL/min
Secondary Purge,On
Licensed Heat Flow,Heat Flow T4P
Modulation Licensed,Yes
[Versions]
Common IDD Version,1
Cortex Version,VER 2.10.2.31
Driver,5.0.0.6
GDM Version,1.0.3.3
TouchscreenVersion,1.0.0.16145
FEP Version,1.2.1.21
FEP Bootloader,2.0.0.5
AutoSampler Version,2.1.1.26
Auto Sampler Bootloader,2.0.0.5
FCM Version,1.1.0.3
FCM Bootloader,2.0.0.5
[Experiment Logs]
Experiment Log Entry # 1,Air Cool is off.
Experiment Log Entry # 3,Data On set to 0
Experiment Log Entry # 5,Equilibrate Segment -60 (C) Started
Experiment Log Entry # 7,Data On set to 1
Experiment Log Entry # 9,Ramp Segment 5 C/min to 150 Started
Experiment Log Entry # 11,Data On set to 0
Experiment Log Entry # 13,Isothermal Segment 1 min started
Experiment Log Entry # 15,Data On set to 1
Experiment Log Entry # 17,Ramp Segment 5 C/min to -60 Started
Experiment Log Entry # 19,Data On set to 0
Experiment Log Entry # 21,Isothermal Segment 1 min started
Experiment Log Entry # 23,Data On set to 1
Experiment Log Entry # 25,Ramp Segment 5 C/min to 150 Started
Experiment Log Entry # 27,Data On set to 0
Experiment Log Entry # 29,Isothermal Segment 1 min started
Experiment Log Entry # 31,Data On set to 1
Experiment Log Entry # 33,Ramp Segment 5 C/min to -60 Started
Experiment Log Entry # 35,Data On set to 0
Experiment Log Entry # 37,Isothermal Segment 1 min started
Experiment Log Entry # 39,Data On set to 1
Experiment Log Entry # 41,Ramp Segment 5 C/min to 150 Started
[Method Log]
Method Log Entry # 1,Data Off
Method Log Entry # 2,Equilibrate -60 °C
Method Log Entry # 3,Data On
Method Log Entry # 4,(Ramp 553958) Ramp 5 °C/minute to 150 °C
Method Log Entry # 5,Data Off
Method Log Entry # 6,Isothermal 1 minutes
Method Log Entry # 7,Data On
Method Log Entry # 8,(Ramp 553962) Ramp 5 °C/minute to -60 °C
Method Log Entry # 9,Data Off
Method Log Entry # 10,Isothermal 1 minutes
Method Log Entry # 11,Data On
Method Log Entry # 12,(Ramp 553966) Ramp 5 °C/minute to 150 °C
Method Log Entry # 13,Data Off
Method Log Entry # 14,Isothermal 1 minutes
Method Log Entry # 15,Data On
Method Log Entry # 16,(Ramp 553970) Ramp 5 °C/minute to -60 °C
Method Log Entry # 17,Data Off
Method Log Entry # 18,Isothermal 1 minutes
Method Log Entry # 19,Data On
Method Log Entry # 20,(Ramp 553974) Ramp 5 °C/minute to 150 °C
Cell Serial,DRC2-00792
[T1 Calibration]
Slope,-0.008529666
Offset,9.636258
Initial Temperature,98.23
GUID,f8bfdadc-4977-4fdf-ba6d-0ba9134940c3
[TZero Calibration]
Date Applied,11/29/2022 4:06:13 PM
Description,From -89.059 °C to 396.009 °C at 20.000°C/min
Gas Type,Nitrogen
Pan Type,None
Source Files 1,C:\Users\yargerlab\Desktop\DSC Data\General\TZero_calibration_11_29_22_2nd(2).tri
Source Files 2,C:\Users\yargerlab\Desktop\DSC Data\General\TZero_calibration_11_29_22_2nd(3).tri
Delta T Offset,13.05235
Delta T Slope,-0.007271007
Delta T0 Offset,-13.69128
Delta T0 Slope,0.06063341
[Temperature Calibration]
Date Applied,11/29/2022 7:12:28 PM
Description,From 106.590 °C to 186.590 °C at 10.000°C/min
Gas Type,Nitrogen
Pan Type,Tzero Aluminum Hermetic
Source Files 1,C:\Users\yargerlab\Desktop\DSC Data\General\Indium(6).tri
Measured 1,157.391
Known 1,156.598
[Cell Constant Calibration]
Date Applied,11/29/2022 7:12:29 PM
Description,From 106.590 °C to 186.590 °C at 10.000°C/min
Gas Type,Nitrogen
Pan Type,Tzero Aluminum Hermetic
Source Files 1,C:\Users\yargerlab\Desktop\DSC Data\General\Indium(6).tri
T4P KCell,1.006051
Onset Slope,63.26126 mW/°C
[Direct Cp Calibration]
Date Applied,11/30/2022 11:04:51 AM
Description,From -79.983 °C to 298.409 °C at 10.000°C/min
Gas Type,Nitrogen
Pan Type,Tzero Aluminum Hermetic
Source Files 1,C:\Users\yargerlab\Desktop\DSC Data\General\Sapphire_Heat_Capacity_11_30_22.tri
[Rev Cp Calibration]
Date Applied,11/30/2022 1:58:51 PM
Description,From -79.996 °C to 292.812 °C at 3.000°C/min
Gas Type,Nitrogen
Pan Type,Tzero Aluminum Hermetic
Source Files 1,C:\Users\yargerlab\Desktop\DSC Data\General\Sapphire_MDSC_Calibration_11_30_22.tri
[step]
Ramp 5.00 °C/min to 150.00 °C
Time,Temperature,Heat Flow (Normalized)
min,°C,W/g
0.00,-59.80,-0.038
0.03,-59.81,-0.036
0.06,-59.80,-0.030
0.08,-59.76,-0.023
0.11,-59.69,-0.011
0.14,-59.59,0.006
0.17,-59.47,0.023
0.20,-59.35,0.039
0.23,-59.22,0.050
0.26,-59.10,0.058
0.28,-58.97,0.064
0.31,-58.83,0.069
0.34,-58.70,0.072
0.37,-58.56,0.074
0.40,-58.43,0.076
0.43,-58.29,0.078
0.45,-58.15,0.078
0.48,-58.01,0.079
0.51,-57.87,0.080
0.54,-57.73,0.080
0.57,-57.59,0.081
0.60,-57.46,0.081
0.62,-57.31,0.081
0.65,-57.17,0.082
0.68,-57.03,0.082
0.71,-56.89,0.082
0.74,-56.75,0.083
0.77,-56.61,0.083
0.79,-56.47,0.083
0.82,-56.33,0.084
0.85,-56.19,0.084
0.88,-56.05,0.084
0.91,-55.91,0.084
0.93,-55.77,0.084
0.96,-55.63,0.084
0.99,-55.49,0.085
1.02,-55.35,0.085
1.05,-55.21,0.085
1.08,-55.07,0.085
1.11,-54.92,0.085
1.13,-54.78,0.085
1.16,-54.64,0.085
1.19,-54.50,0.085
1.22,-54.36,0.085
1.25,-54.22,0.085
1.28,-54.08,0.085
1.30,-53.94,0.085
1.33,-53.79,0.085
1.36,-53.65,0.085
1.39,-53.51,0.085
1.42,-53.37,0.085
1.44,-53.23,0.085
1.47,-53.09,0.085
1.50,-52.95,0.085
1.53,-52.80,0.086
1.56,-52.66,0.086
1.59,-52.52,0.086
1.62,-52.38,0.085
1.64,-52.24,0.086
1.67,-52.10,0.085
1.70,-51.95,0.085
1.73,-51.82,0.085
1.76,-51.67,0.085
1.78,-51.53,0.085
1.81,-51.39,0.085
1.84,-51.25,0.085
1.87,-51.11,0.085
1.90,-50.97,0.085
1.93,-50.82,0.085
1.96,-50.68,0.085
1.98,-50.54,0.085
2.01,-50.40,0.085
2.04,-50.26,0.085
2.07,-50.11,0.085
2.10,-49.97,0.085
2.13,-49.83,0.085
2.15,-49.69,0.085
2.18,-49.55,0.085
2.21,-49.41,0.085
2.24,-49.27,0.085
2.27,-49.12,0.085
2.29,-48.98,0.085
2.32,-48.84,0.085
2.35,-48.70,0.085
2.38,-48.56,0.085
2.41,-48.42,0.085
2.44,-48.27,0.085
2.46,-48.13,0.085
2.49,-47.99,0.085
2.52,-47.85,0.085
2.55,-47.71,0.085
2.58,-47.57,0.085
2.61,-47.43,0.085
2.64,-47.28,0.085
2.66,-47.14,0.085
2.69,-47.00,0.085
2.72,-46.86,0.085
2.75,-46.72,0.085
2.78,-46.58,0.085
2.81,-46.43,0.085
2.83,-46.29,0.085
2.86,-46.15,0.085
2.89,-46.01,0.085
2.92,-45.87,0.085
2.95,-45.73,0.085
2.98,-45.58,0.085
3.00,-45.44,0.085
3.03,-45.30,0.085
3.06,-45.16,0.085
3.09,-45.02,0.085
3.12,-44.88,0.085
3.14,-44.74,0.085
3.17,-44.59,0.085
3.20,-44.45,0.085
3.23,-44.31,0.085
3.26,-44.17,0.085
3.29,-44.03,0.085
3.31,-43.89,0.085
3.34,-43.74,0.085
3.37,-43.60,0.085
3.40,-43.46,0.085
3.43,-43.32,0.085
3.46,-43.18,0.085
3.49,-43.03,0.085
3.51,-42.89,0.085
3.54,-42.75,0.085
3.57,-42.61,0.085
3.60,-42.47,0.085
3.63,-42.33,0.085
3.66,-42.18,0.085
3.68,-42.04,0.085
3.71,-41.90,0.085
3.74,-41.76,0.085
3.77,-41.62,0.085
3.80,-41.48,0.085
3.83,-41.33,0.085
3.85,-41.19,0.085
3.88,-41.05,0.085
3.91,-40.91,0.085
3.94,-40.77,0.085
3.97,-40.63,0.085
3.99,-40.49,0.085
4.02,-40.34,0.085
4.05,-40.20,0.085
4.08,-40.06,0.085
4.11,-39.92,0.085
4.14,-39.78,0.085
4.16,-39.63,0.085
4.19,-39.49,0.085
4.22,-39.35,0.085
4.25,-39.21,0.085
4.28,-39.07,0.085
4.31,-38.93,0.085
4.34,-38.78,0.086
4.36,-38.64,0.086
4.39,-38.50,0.086
4.42,-38.36,0.086
4.45,-38.21,0.086
4.48,-38.07,0.086
4.50,-37.93,0.086
4.53,-37.79,0.086
4.56,-37.65,0.086
4.59,-37.51,0.086
4.62,-37.36,0.086
4.65,-37.22,0.086
4.68,-37.08,0.086
4.70,-36.94,0.086
4.73,-36.79,0.086
4.76,-36.65,0.086
4.79,-36.51,0.086
4.82,-36.37,0.086
4.85,-36.23,0.086
4.87,-36.09,0.086
4.90,-35.94,0.086
4.93,-35.80,0.086
4.96,-35.66,0.086
4.99,-35.52,0.086
5.01,-35.38,0.086
5.04,-35.24,0.086
5.07,-35.09,0.086
5.10,-34.95,0.086
5.13,-34.81,0.086
5.16,-34.67,0.086
5.19,-34.53,0.086
5.21,-34.38,0.086
5.24,-34.24,0.086
5.27,-34.10,0.086
5.30,-33.96,0.086
5.33,-33.82,0.086
5.35,-33.68,0.086
5.38,-33.54,0.086
5.41,-33.39,0.086
5.44,-33.25,0.086
5.47,-33.11,0.086
5.50,-32.97,0.086
5.53,-32.82,0.086
5.55,-32.68,0.086
5.58,-32.54,0.086
5.61,-32.40,0.086
5.64,-32.26,0.086
5.67,-32.11,0.086
5.70,-31.97,0.086
5.72,-31.83,0.086
5.75,-31.69,0.086
5.78,-31.55,0.086
5.81,-31.40,0.086
5.84,-31.26,0.086
5.86,-31.12,0.086
5.89,-30.98,0.086
5.92,-30.84,0.086
5.95,-30.70,0.087
5.98,-30.55,0.087
6.01,-30.41,0.087
6.04,-30.27,0.086
6.06,-30.13,0.087
6.09,-29.99,0.087
6.12,-29.84,0.087
6.15,-29.70,0.087
6.18,-29.56,0.087
6.20,-29.42,0.087
6.23,-29.28,0.087
6.26,-29.14,0.087
6.29,-28.99,0.087
6.32,-28.85,0.087
6.35,-28.71,0.087
6.38,-28.57,0.087
6.40,-28.43,0.087
6.43,-28.29,0.087
6.46,-28.15,0.087
6.49,-28.01,0.087
6.52,-27.86,0.087
6.55,-27.72,0.087
6.57,-27.58,0.087
6.60,-27.44,0.087
6.63,-27.29,0.087
6.66,-27.15,0.087
6.69,-27.01,0.087
6.71,-26.87,0.087
6.74,-26.73,0.087
6.77,-26.58,0.087
6.80,-26.44,0.087
6.83,-26.30,0.087
6.86,-26.16,0.087
6.89,-26.02,0.087
6.91,-25.87,0.087
6.94,-25.73,0.087
6.97,-25.59,0.087
7.00,-25.45,0.087
7.03,-25.31,0.087
7.05,-25.17,0.087
7.08,-25.02,0.088
7.11,-24.88,0.088
7.14,-24.74,0.088
7.17,-24.60,0.088
7.20,-24.46,0.088
7.23,-24.31,0.088
7.25,-24.17,0.088
7.28,-24.03,0.088
7.31,-23.89,0.088
7.34,-23.75,0.088
7.37,-23.60,0.088
7.40,-23.46,0.088
7.42,-23.32,0.088
7.45,-23.18,0.088
7.48,-23.04,0.088
7.51,-22.90,0.088
7.54,-22.75,0.088
7.56,-22.61,0.088
7.59,-22.47,0.088
7.62,-22.33,0.088
7.65,-22.19,0.088
7.68,-22.05,0.088
7.71,-21.91,0.088
7.74,-21.76,0.088
7.76,-21.62,0.088
7.79,-21.48,0.088
7.82,-21.34,0.088
7.85,-21.20,0.088
7.88,-21.05,0.088
7.90,-20.91,0.088
7.93,-20.77,0.088
7.96,-20.63,0.088
7.99,-20.49,0.088
8.02,-20.35,0.088
8.05,-20.20,0.088
8.08,-20.06,0.088
8.10,-19.92,0.088
8.13,-19.78,0.088
8.16,-19.64,0.089
8.19,-19.49,0.089
8.22,-19.35,0.089
8.25,-19.21,0.089
8.27,-19.07,0.089
8.30,-18.93,0.089
8.33,-18.78,0.089
8.36,-18.64,0.089
8.39,-18.50,0.089
8.41,-18.36,0.089
8.44,-18.22,0.089
8.47,-18.07,0.089
8.50,-17.93,0.089
8.53,-17.79,0.089
8.56,-17.65,0.089
8.58,-17.51,0.089
8.61,-17.37,0.089
8.64,-17.22,0.089
8.67,-17.08,0.089
8.70,-16.94,0.089
8.73,-16.80,0.089
8.75,-16.66,0.089
8.78,-16.51,0.089
8.81,-16.37,0.089
8.84,-16.23,0.089
8.87,-16.09,0.089
8.90,-15.95,0.089
8.93,-15.81,0.090
8.95,-15.66,0.090
8.98,-15.52,0.090
9.01,-15.38,0.090
9.04,-15.24,0.090
9.07,-15.10,0.090
9.10,-14.96,0.090
9.12,-14.81,0.090
9.15,-14.67,0.090
9.18,-14.53,0.090
9.21,-14.39,0.090
9.24,-14.25,0.090
9.27,-14.11,0.090
9.29,-13.96,0.090
9.32,-13.82,0.090
9.35,-13.68,0.090
9.38,-13.54,0.090
9.41,-13.40,0.090
9.43,-13.25,0.090
9.46,-13.11,0.090
9.49,-12.97,0.090
9.52,-12.83,0.090
9.55,-12.69,0.090
9.58,-12.55,0.090
9.60,-12.40,0.090
9.63,-12.26,0.090
9.66,-12.12,0.090
9.69,-11.98,0.090
9.72,-11.84,0.090
9.75,-11.70,0.090
9.78,-11.56,0.090
9.80,-11.41,0.090
9.83,-11.27,0.090
9.86,-11.13,0.090
9.89,-10.99,0.090
9.92,-10.85,0.090
9.95,-10.70,0.090
9.97,-10.56,0.091
10.00,-10.42,0.091
10.03,-10.28,0.091
10.06,-10.14,0.091
10.09,-10.00,0.091
10.12,-9.85,0.091
10.14,-9.71,0.091
10.17,-9.57,0.091
10.20,-9.43,0.091
10.23,-9.29,0.091
10.26,-9.14,0.091
10.28,-9.00,0.091
10.31,-8.86,0.091
10.34,-8.72,0.091
10.37,-8.58,0.091
10.40,-8.44,0.091
10.43,-8.29,0.091
10.45,-8.15,0.091
10.48,-8.01,0.091
10.51,-7.87,0.092
10.54,-7.73,0.092
10.57,-7.58,0.092
10.60,-7.44,0.092
10.63,-7.30,0.092
10.65,-7.16,0.092
10.68,-7.02,0.092
10.71,-6.87,0.092
10.74,-6.73,0.092
10.77,-6.59,0.092
10.80,-6.45,0.092
10.82,-6.31,0.092
10.85,-6.17,0.092
10.88,-6.02,0.092
10.91,-5.88,0.092
10.94,-5.74,0.092
10.97,-5.60,0.092
10.99,-5.46,0.092
11.02,-5.31,0.092
11.05,-5.17,0.092
11.08,-5.03,0.092
11.11,-4.89,0.092
11.13,-4.75,0.092
11.16,-4.61,0.093
11.19,-4.46,0.093
11.22,-4.32,0.093
11.25,-4.18,0.093
11.28,-4.04,0.093
11.30,-3.90,0.093
11.33,-3.76,0.093
11.36,-3.61,0.093
11.39,-3.47,0.093
11.42,-3.33,0.093
11.45,-3.19,0.093
11.48,-3.05,0.093
11.50,-2.90,0.093
11.53,-2.76,0.093
11.56,-2.62,0.093
11.59,-2.48,0.093
11.62,-2.34,0.093
11.65,-2.20,0.093
11.67,-2.05,0.093
11.70,-1.91,0.093
11.73,-1.77,0.093
11.76,-1.63,0.093
11.79,-1.48,0.094
11.82,-1.34,0.094
11.84,-1.20,0.094
11.87,-1.06,0.094
11.90,-0.92,0.094
11.93,-0.78,0.094
11.96,-0.63,0.094
11.98,-0.49,0.094
12.01,-0.35,0.094
12.04,-0.21,0.094
12.07,-0.07,0.094
12.10,0.07,0.094
12.13,0.22,0.094
12.15,0.36,0.094
12.18,0.50,0.094
12.21,0.64,0.094
12.24,0.78,0.094
12.27,0.93,0.094
12.30,1.07,0.094
12.33,1.21,0.094
12.35,1.35,0.094
12.38,1.49,0.095
12.41,1.63,0.095
12.44,1.78,0.095
12.47,1.92,0.095
12.50,2.06,0.095
12.52,2.20,0.095
12.55,2.34,0.095
12.58,2.48,0.095
12.61,2.63,0.095
12.64,2.77,0.095
12.67,2.91,0.095
12.69,3.05,0.095
12.72,3.19,0.095
12.75,3.34,0.095
12.78,3.48,0.095
12.81,3.62,0.095
12.83,3.76,0.095
12.86,3.90,0.095
12.89,4.05,0.095
12.92,4.18,0.096
12.95,4.33,0.096
12.98,4.47,0.096
13.00,4.61,0.096
13.03,4.75,0.096
13.06,4.89,0.096
13.09,5.04,0.096
13.12,5.18,0.096
13.15,5.32,0.096
13.18,5.46,0.096
13.20,5.60,0.096
13.23,5.75,0.096
13.26,5.89,0.096
13.29,6.03,0.096
13.32,6.17,0.097
13.35,6.31,0.097
13.37,6.45,0.097
13.40,6.60,0.097
13.43,6.74,0.097
13.46,6.88,0.097
13.49,7.02,0.097
13.52,7.16,0.097
13.54,7.31,0.097
13.57,7.45,0.097
13.60,7.59,0.097
13.63,7.73,0.097
13.66,7.87,0.097
13.68,8.01,0.097
13.71,8.16,0.097
13.74,8.30,0.098
13.77,8.44,0.098
13.80,8.58,0.098
13.83,8.72,0.098
13.85,8.87,0.098
13.88,9.01,0.098
13.91,9.15,0.098
13.94,9.29,0.098
13.97,9.43,0.098
14.00,9.57,0.098
14.03,9.72,0.098
14.05,9.86,0.098
14.08,10.00,0.098
14.11,10.14,0.098
14.14,10.28,0.099
14.17,10.42,0.099
14.20,10.57,0.099
14.22,10.71,0.099
14.25,10.85,0.099
14.28,10.99,0.099
14.31,11.13,0.099
14.34,11.27,0.099
14.37,11.42,0.099
14.39,11.56,0.099
14.42,11.70,0.099
14.45,11.84,0.099
14.48,11.98,0.100
14.51,12.12,0.100
14.53,12.27,0.100
14.56,12.41,0.100
14.59,12.55,0.100
14.62,12.69,0.100
14.65,12.84,0.100
14.68,12.98,0.100
14.70,13.12,0.100
14.73,13.26,0.100
14.76,13.40,0.100
14.79,13.54,0.100
14.82,13.69,0.101
14.85,13.83,0.101
14.88,13.97,0.101
14.90,14.11,0.101
14.93,14.25,0.101
14.96,14.40,0.101
14.99,14.54,0.101
15.02,14.68,0.101
15.05,14.82,0.101
15.07,14.96,0.101
15.10,15.10,0.101
15.13,15.24,0.102
15.16,15.39,0.102
15.19,15.53,0.102
15.22,15.67,0.102
15.24,15.81,0.102
15.27,15.95,0.102
15.30,16.10,0.102
15.33,16.24,0.102
15.36,16.38,0.102
15.38,16.52,0.102
15.41,16.66,0.102
15.44,16.81,0.103
15.47,16.95,0.103
15.50,17.09,0.103
15.53,17.23,0.103
15.55,17.37,0.103
15.58,17.51,0.103
15.61,17.66,0.103
15.64,17.80,0.103
15.67,17.94,0.103
15.70,18.08,0.103
15.73,18.22,0.104
15.75,18.36,0.104
15.78,18.51,0.104
15.81,18.65,0.104
15.84,18.79,0.104
15.87,18.93,0.104
15.90,19.07,0.104
15.92,19.22,0.104
15.95,19.36,0.104
15.98,19.50,0.104
16.01,19.64,0.105
16.04,19.78,0.105
16.07,19.92,0.105
16.09,20.07,0.105
16.12,20.21,0.105
16.15,20.35,0.105
16.18,20.49,0.105
16.21,20.63,0.105
16.23,20.77,0.105
16.26,20.92,0.105
16.29,21.06,0.105
16.32,21.20,0.106
16.35,21.34,0.106
16.38,21.48,0.106
16.40,21.62,0.106
16.43,21.77,0.106
16.46,21.91,0.106
16.49,22.05,0.106
16.52,22.19,0.106
16.55,22.33,0.107
16.58,22.47,0.107
16.60,22.62,0.107
16.63,22.76,0.107
16.66,22.90,0.107
16.69,23.04,0.107
16.72,23.18,0.107
16.75,23.32,0.107
16.77,23.47,0.107
16.80,23.61,0.108
16.83,23.75,0.108
16.86,23.89,0.108
16.89,24.03,0.108
16.92,24.17,0.108
16.94,24.32,0.108
16.97,24.46,0.108
17.00,24.60,0.108
17.03,24.74,0.109
17.06,24.88,0.109
17.08,25.03,0.109
17.11,25.17,0.109
17.14,25.31,0.109
17.17,25.45,0.109
17.20,25.59,0.109
17.23,25.73,0.110
17.26,25.87,0.110
17.28,26.02,0.110
17.31,26.16,0.110
17.34,26.30,0.110
17.37,26.44,0.110
17.40,26.58,0.110
17.43,26.73,0.111
17.45,26.87,0.111
17.48,27.01,0.111
17.51,27.15,0.111
17.54,27.29,0.111
17.57,27.43,0.111
17.59,27.58,0.112
17.62,27.72,0.112
17.65,27.86,0.112
17.68,28.00,0.112
17.71,28.14,0.112
17.74,28.29,0.112
17.77,28.43,0.112
17.79,28.57,0.113
17.82,28.71,0.113
17.85,28.85,0.113
17.88,28.99,0.113
17.91,29.14,0.113
17.93,29.28,0.113
17.96,29.42,0.114
17.99,29.56,0.114
18.02,29.70,0.114
18.05,29.84,0.114
18.08,29.98,0.114
18.11,30.13,0.114
18.13,30.27,0.114
18.16,30.41,0.115
18.19,30.55,0.115
18.22,30.69,0.115
18.25,30.84,0.115
18.28,30.98,0.115
18.30,31.12,0.115
18.33,31.26,0.116
18.36,31.40,0.116
18.39,31.54,0.116
18.42,31.69,0.116
18.44,31.83,0.116
18.47,31.97,0.116
18.50,32.11,0.117
18.53,32.25,0.117
18.56,32.39,0.117
18.59,32.53,0.117
18.62,32.68,0.117
18.64,32.82,0.118
18.67,32.96,0.118
18.70,33.10,0.118
18.73,33.24,0.118
18.76,33.39,0.118
18.78,33.53,0.118
18.81,33.67,0.119
18.84,33.81,0.119
18.87,33.95,0.119
18.90,34.09,0.119
18.93,34.24,0.119
18.96,34.38,0.120
18.98,34.52,0.120
19.01,34.66,0.120
19.04,34.80,0.120
19.07,34.95,0.120
19.10,35.09,0.121
19.13,35.23,0.121
19.15,35.37,0.121
19.18,35.51,0.121
19.21,35.65,0.121
19.24,35.80,0.122
19.27,35.94,0.122
19.29,36.08,0.122
19.32,36.22,0.122
19.35,36.36,0.122
19.38,36.50,0.123
19.41,36.65,0.123
19.44,36.79,0.123
19.47,36.93,0.123
19.49,37.07,0.124
19.52,37.21,0.124
19.55,37.35,0.124
19.58,37.49,0.124
19.61,37.64,0.125
19.63,37.78,0.125
19.66,37.92,0.125
19.69,38.06,0.125
19.72,38.20,0.126
19.75,38.35,0.126
19.78,38.49,0.126
19.81,38.63,0.126
19.83,38.77,0.127
19.86,38.91,0.127
19.89,39.05,0.127
19.92,39.20,0.127
19.95,39.34,0.128
19.98,39.48,0.128
20.00,39.62,0.128
20.03,39.76,0.129
20.06,39.90,0.129
20.09,40.05,0.129
20.12,40.19,0.129
20.14,40.33,0.130
20.17,40.47,0.130
20.20,40.61,0.130
20.23,40.75,0.131
20.26,40.89,0.131
20.29,41.04,0.131
20.32,41.18,0.132
20.34,41.32,0.132
20.37,41.46,0.132
20.40,41.60,0.133
20.43,41.75,0.133
20.46,41.89,0.133
20.48,42.03,0.134
20.51,42.17,0.134
20.54,42.31,0.134
20.57,42.45,0.135
20.60,42.60,0.135
20.63,42.74,0.135
20.66,42.88,0.136
20.68,43.02,0.136
20.71,43.16,0.137
20.74,43.30,0.137
20.77,43.44,0.137
20.80,43.59,0.138
20.83,43.73,0.138
20.85,43.87,0.139
20.88,44.01,0.139
20.91,44.15,0.140
20.94,44.29,0.140
20.97,44.44,0.140
20.99,44.58,0.141
21.02,44.72,0.141
21.05,44.86,0.142
21.08,45.00,0.142
21.11,45.14,0.143
21.14,45.28,0.143
21.17,45.43,0.144
21.19,45.57,0.145
21.22,45.71,0.145
21.25,45.85,0.146
21.28,45.99,0.146
21.31,46.13,0.147
21.33,46.28,0.147
21.36,46.42,0.148
21.39,46.56,0.149
21.42,46.70,0.149
21.45,46.84,0.150
21.48,46.98,0.151
21.51,47.12,0.151
21.53,47.27,0.152
21.56,47.41,0.153
21.59,47.55,0.154
21.62,47.69,0.155
21.65,47.83,0.155
21.68,47.97,0.156
21.70,48.12,0.157
21.73,48.26,0.158
21.76,48.40,0.159
21.79,48.54,0.160
21.82,48.68,0.161
21.84,48.82,0.162
21.87,48.96,0.162
21.90,49.10,0.164
21.93,49.25,0.165
21.96,49.39,0.166
21.99,49.53,0.167
22.02,49.67,0.169
22.04,49.81,0.170
22.07,49.95,0.171
22.10,50.09,0.172
22.13,50.24,0.172
22.16,50.38,0.174
22.18,50.52,0.175
22.21,50.66,0.176
22.24,50.80,0.176
22.27,50.94,0.177
22.30,51.08,0.178
22.33,51.23,0.179
22.36,51.37,0.179
22.38,51.51,0.180
22.41,51.65,0.181
22.44,51.79,0.181
22.47,51.93,0.182
22.50,52.08,0.182
22.53,52.22,0.183
22.55,52.36,0.183
22.58,52.50,0.183
22.61,52.64,0.184
22.64,52.79,0.184
22.67,52.93,0.184
22.69,53.07,0.184
22.72,53.21,0.184
22.75,53.35,0.184
22.78,53.50,0.183
22.81,53.64,0.183
22.84,53.78,0.183
22.87,53.92,0.183
22.89,54.06,0.182
22.92,54.21,0.182
22.95,54.35,0.182
22.98,54.49,0.181
23.01,54.63,0.181
23.03,54.77,0.180
23.06,54.92,0.180
23.09,55.06,0.180
23.12,55.20,0.180
23.15,55.34,0.179
23.18,55.48,0.179
23.21,55.62,0.179
23.23,55.77,0.179
23.26,55.91,0.179
23.29,56.05,0.179
23.32,56.19,0.178
23.35,56.33,0.178
23.38,56.47,0.178
23.40,56.62,0.178
23.43,56.76,0.179
23.46,56.90,0.179
23.49,57.04,0.179
23.52,57.18,0.179
23.54,57.32,0.179
23.57,57.47,0.180
23.60,57.61,0.180
23.63,57.75,0.180
23.66,57.89,0.181
23.69,58.03,0.181
23.72,58.17,0.181
23.74,58.31,0.182
23.77,58.46,0.182
23.80,58.60,0.183
23.83,58.74,0.183
23.86,58.88,0.184
23.88,59.02,0.184
23.91,59.16,0.185
23.94,59.31,0.185
23.97,59.45,0.186
24.00,59.59,0.186
24.03,59.73,0.187
24.06,59.87,0.187
24.08,60.01,0.188
24.11,60.15,0.188
24.14,60.30,0.189
24.17,60.44,0.190
24.20,60.58,0.190
24.23,60.72,0.191
24.25,60.86,0.191
24.28,61.00,0.192
24.31,61.15,0.192
24.34,61.29,0.193
24.37,61.43,0.193
24.39,61.57,0.194
24.42,61.71,0.194
24.45,61.85,0.195
24.48,62.00,0.195
24.51,62.14,0.196
24.54,62.28,0.196
24.57,62.42,0.197
24.59,62.56,0.197
24.62,62.70,0.198
24.65,62.85,0.198
24.68,62.99,0.198
24.71,63.13,0.199
24.73,63.27,0.199
24.76,63.41,0.200
24.79,63.55,0.200
24.82,63.70,0.200
24.85,63.84,0.201
24.88,63.98,0.201
24.91,64.12,0.202
24.93,64.26,0.202
24.96,64.40,0.202
24.99,64.54,0.203
25.02,64.69,0.203
25.05,64.83,0.203
25.08,64.97,0.204
25.10,65.11,0.204
25.13,65.25,0.204
25.16,65.39,0.205
25.19,65.54,0.205
25.22,65.68,0.205
25.24,65.82,0.206
25.27,65.96,0.206
25.30,66.10,0.206
25.33,66.24,0.207
25.36,66.39,0.207
25.39,66.53,0.207
25.42,66.67,0.208
25.44,66.81,0.208
25.47,66.95,0.208
25.50,67.09,0.209
25.53,67.24,0.209
25.56,67.38,0.209
25.58,67.52,0.210
25.61,67.66,0.210
25.64,67.80,0.210
25.67,67.94,0.211
25.70,68.09,0.211
25.73,68.23,0.211
25.76,68.37,0.212
25.78,68.51,0.212
25.81,68.65,0.212
25.84,68.79,0.212
25.87,68.94,0.213
25.90,69.08,0.213
25.93,69.22,0.213
25.95,69.36,0.214
25.98,69.50,0.214
26.01,69.65,0.214
26.04,69.79,0.215
26.07,69.93,0.215
26.09,70.07,0.215
26.12,70.21,0.216
26.15,70.35,0.216
26.18,70.49,0.216
26.21,70.64,0.217
26.24,70.78,0.217
26.27,70.92,0.217
26.29,71.06,0.217
26.32,71.20,0.218
26.35,71.35,0.218
26.38,71.49,0.218
26.41,71.63,0.219
26.43,71.77,0.219
26.46,71.91,0.219
26.49,72.05,0.220
26.52,72.20,0.220
26.55,72.34,0.220
26.58,72.48,0.220
26.61,72.62,0.221
26.63,72.76,0.221
26.66,72.90,0.221
26.69,73.05,0.222
26.72,73.19,0.222
26.75,73.33,0.222
26.78,73.47,0.223
26.80,73.61,0.223
26.83,73.75,0.223
26.86,73.89,0.224
26.89,74.04,0.224
26.92,74.18,0.224
26.94,74.32,0.224
26.97,74.46,0.225
27.00,74.60,0.225
27.03,74.75,0.225
27.06,74.89,0.226
27.09,75.03,0.226
27.12,75.17,0.226
27.14,75.31,0.227
27.17,75.45,0.227
27.20,75.59,0.227
27.23,75.74,0.227
27.26,75.88,0.228
27.28,76.02,0.228
27.31,76.16,0.228
27.34,76.30,0.229
27.37,76.45,0.229
27.40,76.59,0.229
27.43,76.73,0.230
27.46,76.87,0.230
27.48,77.01,0.230
27.51,77.15,0.231
27.54,77.30,0.231
27.57,77.44,0.231
27.60,77.58,0.231
27.63,77.72,0.232
27.65,77.86,0.232
27.68,78.00,0.232
27.71,78.14,0.233
27.74,78.29,0.233
27.77,78.43,0.233
27.79,78.57,0.234
27.82,78.71,0.234
27.85,78.85,0.234
27.88,78.99,0.234
27.91,79.14,0.235
27.94,79.28,0.235
27.97,79.42,0.235
27.99,79.56,0.236
28.02,79.70,0.236
28.05,79.85,0.236
28.08,79.99,0.237
28.11,80.13,0.237
28.13,80.27,0.237
28.16,80.41,0.237
28.19,80.55,0.238
28.22,80.70,0.238
28.25,80.84,0.238
28.28,80.98,0.238
28.31,81.12,0.239
28.33,81.26,0.239
28.36,81.41,0.239
28.39,81.55,0.240
28.42,81.69,0.240
28.45,81.83,0.240
28.48,81.97,0.240
28.50,82.12,0.241
28.53,82.26,0.241
28.56,82.40,0.241
28.59,82.54,0.241
28.62,82.68,0.242
28.64,82.82,0.242
28.67,82.96,0.242
28.70,83.11,0.242
28.73,83.25,0.243
28.76,83.39,0.243
28.79,83.53,0.243
28.82,83.67,0.243
28.84,83.81,0.244
28.87,83.96,0.244
28.90,84.10,0.244
28.93,84.24,0.244
28.96,84.38,0.244
28.98,84.52,0.245
29.01,84.66,0.245
29.04,84.81,0.245
29.07,84.95,0.245
29.10,85.09,0.246
29.13,85.23,0.246
29.16,85.37,0.246
29.18,85.51,0.246
29.21,85.66,0.247
29.24,85.80,0.247
29.27,85.94,0.247
29.30,86.08,0.247
29.33,86.22,0.248
29.35,86.36,0.248
29.38,86.51,0.248
29.41,86.65,0.248
29.44,86.79,0.248
29.47,86.93,0.249
29.49,87.07,0.249
29.52,87.21,0.249
29.55,87.36,0.249
29.58,87.50,0.249
29.61,87.64,0.250
29.64,87.78,0.250
29.67,87.92,0.250
29.69,88.06,0.250
29.72,88.20,0.250
29.75,88.35,0.251
29.78,88.49,0.251
29.81,88.63,0.251
29.83,88.77,0.251
29.86,88.91,0.251
29.89,89.06,0.252
29.92,89.20,0.252
29.95,89.34,0.252
29.98,89.48,0.252
30.01,89.62,0.252
30.03,89.76,0.253
30.06,89.90,0.253
30.09,90.05,0.253
30.12,90.19,0.253
30.15,90.33,0.253
30.18,90.47,0.254
30.20,90.61,0.254
30.23,90.76,0.254
30.26,90.90,0.254
30.29,91.04,0.254
30.32,91.18,0.254
30.34,91.32,0.255
30.37,91.46,0.255
30.40,91.61,0.255
30.43,91.75,0.255
30.46,91.89,0.255
30.49,92.03,0.255
30.52,92.17,0.255
30.54,92.31,0.256
30.57,92.46,0.256
30.60,92.60,0.256
30.63,92.74,0.256
30.66,92.88,0.256
30.68,93.02,0.256
30.71,93.16,0.256
30.74,93.31,0.257
30.77,93.45,0.257
30.80,93.59,0.257
30.83,93.73,0.257
30.86,93.87,0.257
30.88,94.02,0.257
30.91,94.16,0.257
30.94,94.30,0.257
30.97,94.44,0.257
31.00,94.58,0.258
31.03,94.72,0.258
31.05,94.87,0.258
31.08,95.01,0.258
31.11,95.15,0.258
31.14,95.29,0.258
31.17,95.43,0.258
31.19,95.57,0.258
31.22,95.72,0.258
31.25,95.86,0.259
31.28,96.00,0.259
31.31,96.14,0.259
31.34,96.28,0.259
31.37,96.42,0.259
31.39,96.57,0.259
31.42,96.71,0.259
31.45,96.85,0.259
31.48,96.99,0.259
31.51,97.13,0.259
31.53,97.28,0.259
31.56,97.42,0.259
31.59,97.56,0.260
31.62,97.70,0.260
31.65,97.84,0.260
31.68,97.99,0.260
31.71,98.13,0.260
31.73,98.27,0.260
31.76,98.41,0.260
31.79,98.55,0.260
31.82,98.69,0.260
31.85,98.83,0.260
31.88,98.98,0.260
31.90,99.12,0.260
31.93,99.26,0.260
31.96,99.40,0.260
31.99,99.54,0.260
32.02,99.69,0.260
32.04,99.83,0.260
32.07,99.97,0.260
32.10,100.11,0.260
32.13,100.25,0.260
32.16,100.39,0.260
32.19,100.54,0.260
32.22,100.68,0.260
32.24,100.82,0.260
32.27,100.96,0.260
32.30,101.10,0.260
32.33,101.24,0.260
32.36,101.39,0.260
32.38,101.53,0.260
32.41,101.67,0.260
32.44,101.81,0.260
32.47,101.95,0.260
32.50,102.10,0.260
32.53,102.24,0.260
32.56,102.38,0.260
32.58,102.52,0.260
32.61,102.66,0.260
32.64,102.81,0.260
32.67,102.95,0.260
32.70,103.09,0.260
32.73,103.23,0.260
32.75,103.37,0.260
32.78,103.51,0.260
32.81,103.65,0.260
32.84,103.80,0.260
32.87,103.94,0.260
32.89,104.08,0.260
32.92,104.22,0.260
32.95,104.36,0.260
32.98,104.51,0.260
33.01,104.65,0.260
33.04,104.79,0.260
33.07,104.93,0.260
33.09,105.07,0.259
33.12,105.22,0.259
33.15,105.36,0.259
33.18,105.50,0.259
33.21,105.64,0.259
33.23,105.78,0.259
33.26,105.93,0.259
33.29,106.07,0.259
33.32,106.21,0.259
33.35,106.35,0.259
33.38,106.49,0.259
33.41,106.63,0.259
33.43,106.78,0.258
33.46,106.92,0.258
33.49,107.06,0.258
33.52,107.20,0.258
33.55,107.34,0.258
33.58,107.48,0.258
33.60,107.63,0.257
33.63,107.77,0.257
33.66,107.91,0.257
33.69,108.05,0.257
33.72,108.19,0.257
33.74,108.33,0.257
33.77,108.48,0.257
33.80,108.62,0.257
33.83,108.76,0.256
33.86,108.90,0.256
33.89,109.04,0.256
33.92,109.19,0.256
33.94,109.33,0.256
33.97,109.47,0.256
34.00,109.61,0.255
34.03,109.75,0.255
34.06,109.89,0.255
34.08,110.04,0.255
34.11,110.18,0.255
34.14,110.32,0.255
34.17,110.46,0.255
34.20,110.60,0.254
34.23,110.75,0.254
34.26,110.89,0.254
34.28,111.03,0.254
34.31,111.17,0.254
34.34,111.31,0.254
34.37,111.46,0.253
34.40,111.60,0.253
34.43,111.74,0.253
34.45,111.88,0.253
34.48,112.02,0.253
34.51,112.16,0.252
34.54,112.31,0.252
34.57,112.45,0.252
34.59,112.59,0.252
34.62,112.73,0.252
34.65,112.87,0.251
34.68,113.02,0.251
34.71,113.16,0.251
34.74,113.30,0.251
34.76,113.44,0.250
34.79,113.58,0.250
34.82,113.73,0.250
34.85,113.87,0.250
34.88,114.01,0.250
34.91,114.15,0.249
34.94,114.29,0.249
34.96,114.44,0.249
34.99,114.58,0.249
35.02,114.72,0.248
35.05,114.86,0.248
35.08,115.00,0.248
35.11,115.14,0.248
35.13,115.29,0.247
35.16,115.43,0.247
35.19,115.57,0.247
35.22,115.71,0.246
35.25,115.85,0.246
35.28,116.00,0.246
35.30,116.14,0.246
35.33,116.28,0.245
35.36,116.42,0.245
35.39,116.56,0.245
35.42,116.70,0.244
35.44,116.85,0.244
35.47,116.99,0.244
35.50,117.13,0.244
35.53,117.27,0.243
35.56,117.41,0.243
35.59,117.56,0.243
35.61,117.70,0.242
35.64,117.84,0.242
35.67,117.98,0.242
35.70,118.12,0.241
35.73,118.27,0.241
35.76,118.41,0.240
35.79,118.55,0.240
35.81,118.69,0.240
35.84,118.83,0.239
35.87,118.98,0.239
35.90,119.12,0.238
35.93,119.26,0.238
35.96,119.40,0.238
35.98,119.54,0.237
36.01,119.69,0.237
36.04,119.83,0.236
36.07,119.97,0.236
36.10,120.11,0.235
36.13,120.25,0.235
36.15,120.39,0.234
36.18,120.54,0.234
36.21,120.68,0.234
36.24,120.82,0.233
36.27,120.96,0.233
36.29,121.10,0.232
36.32,121.25,0.232
36.35,121.39,0.231
36.38,121.53,0.231
36.41,121.67,0.230
36.44,121.81,0.230
36.46,121.96,0.229
36.49,122.10,0.229
36.52,122.24,0.228
36.55,122.38,0.228
36.58,122.52,0.227
36.61,122.67,0.227
36.64,122.81,0.227
36.66,122.95,0.226
36.69,123.09,0.226
36.72,123.23,0.225
36.75,123.38,0.225
36.78,123.52,0.225
36.81,123.66,0.224
36.83,123.80,0.224
36.86,123.94,0.223
36.89,124.08,0.223
36.92,124.23,0.222
36.95,124.37,0.222
36.98,124.51,0.222
37.00,124.65,0.221
37.03,124.80,0.221
37.06,124.94,0.220
37.09,125.08,0.220
37.12,125.22,0.220
37.14,125.36,0.219
37.17,125.51,0.219
37.20,125.65,0.218
37.23,125.79,0.218
37.26,125.93,0.218
37.29,126.07,0.217
37.31,126.21,0.217
37.34,126.36,0.216
37.37,126.50,0.216
37.40,126.64,0.216
37.43,126.78,0.215
37.46,126.92,0.215
37.49,127.07,0.215
37.51,127.21,0.214
37.54,127.35,0.214
37.57,127.49,0.214
37.60,127.63,0.213
37.63,127.77,0.213
37.66,127.92,0.213
37.68,128.06,0.212
37.71,128.20,0.212
37.74,128.34,0.212
37.77,128.48,0.211
37.80,128.62,0.211
37.83,128.77,0.210
37.85,128.91,0.210
37.88,129.05,0.210
37.91,129.19,0.210
37.94,129.33,0.209
37.97,129.48,0.209
37.99,129.62,0.208
38.02,129.76,0.208
38.05,129.90,0.208
38.08,130.04,0.207
38.11,130.19,0.207
38.14,130.33,0.207
38.16,130.47,0.206
38.19,130.61,0.206
38.22,130.75,0.206
38.25,130.90,0.205
38.28,131.04,0.205
38.31,131.18,0.204
38.34,131.32,0.204
38.36,131.46,0.204
38.39,131.60,0.203
38.42,131.75,0.203
38.45,131.89,0.203
38.48,132.03,0.202
38.51,132.17,0.202
38.53,132.31,0.201
38.56,132.46,0.201
38.59,132.60,0.200
38.62,132.74,0.200
38.65,132.88,0.199
38.68,133.02,0.199
38.70,133.16,0.198
38.73,133.31,0.198
38.76,133.45,0.198
38.79,133.59,0.197
38.82,133.73,0.196
38.84,133.87,0.196
38.87,134.02,0.195
38.90,134.16,0.195
38.93,134.30,0.194
38.96,134.44,0.194
38.99,134.58,0.193
39.01,134.73,0.193
39.04,134.87,0.192
39.07,135.01,0.192
39.10,135.15,0.191
39.13,135.29,0.190
39.16,135.44,0.190
39.19,135.58,0.189
39.21,135.72,0.189
39.24,135.86,0.188
39.27,136.00,0.188
39.30,136.15,0.187
39.33,136.29,0.187
39.36,136.43,0.186
39.38,136.57,0.186
39.41,136.72,0.185
39.44,136.86,0.185
39.47,137.00,0.184
39.50,137.14,0.184
39.53,137.28,0.183
39.55,137.42,0.183
39.58,137.57,0.182
39.61,137.71,0.182
39.64,137.85,0.182
39.67,137.99,0.181
39.69,138.13,0.181
39.72,138.27,0.180
39.75,138.42,0.180
39.78,138.56,0.179
39.81,138.70,0.179
39.84,138.84,0.178
39.86,138.98,0.178
39.89,139.13,0.178
39.92,139.27,0.177
39.95,139.41,0.177
39.98,139.55,0.176
40.01,139.69,0.176
40.04,139.84,0.176
40.06,139.98,0.175
40.09,140.12,0.175
40.12,140.26,0.175
40.15,140.40,0.174
40.18,140.54,0.174
40.21,140.69,0.174
40.23,140.83,0.174
40.26,140.97,0.173
40.29,141.11,0.173
40.32,141.25,0.173
40.35,141.40,0.172
40.38,141.54,0.172
40.40,141.68,0.172
40.43,141.82,0.171
40.46,141.96,0.171
40.49,142.10,0.170
40.52,142.25,0.170
40.54,142.39,0.170
40.57,142.53,0.169
40.60,142.67,0.169
40.63,142.81,0.169
40.66,142.96,0.168
40.69,143.10,0.168
40.71,143.24,0.168
40.74,143.38,0.167
40.77,143.53,0.167
40.80,143.67,0.167
40.83,143.81,0.166
40.86,143.95,0.166
40.89,144.09,0.166
40.91,144.23,0.165
40.94,144.38,0.165
40.97,144.52,0.165
41.00,144.66,0.164
41.03,144.80,0.164
41.06,144.94,0.164
41.08,145.08,0.163
41.11,145.23,0.163
41.14,145.37,0.163
41.17,145.51,0.163
41.20,145.65,0.162
41.23,145.79,0.162
41.25,145.93,0.162
41.28,146.08,0.161
41.31,146.22,0.161
41.34,146.36,0.161
41.37,146.50,0.161
41.39,146.64,0.160
41.42,146.79,0.160
41.45,146.93,0.160
41.48,147.07,0.160
41.51,147.21,0.159
41.54,147.35,0.159
41.56,147.50,0.159
41.59,147.64,0.159
41.62,147.78,0.159
41.65,147.92,0.158
41.68,148.06,0.158
41.71,148.20,0.158
41.74,148.35,0.158
41.76,148.49,0.157
41.79,148.63,0.157
41.82,148.77,0.157
41.85,148.91,0.157
41.88,149.06,0.157
41.91,149.20,0.156
41.93,149.34,
41.96,149.48,
41.98,,

[step]
Ramp 5.00 °C/min to -60.00 °C
Time,Temperature,Heat Flow (Normalized)
min,°C,W/g
42.99,150.16,-0.029
43.01,150.16,-0.029
43.04,150.15,-0.029
43.07,150.12,-0.033
43.10,150.06,-0.060
43.13,149.97,-0.093
43.16,149.86,-0.126
43.18,149.74,-0.152
43.21,149.61,-0.168
43.24,149.48,-0.179
43.27,149.35,-0.186
43.30,149.22,-0.193
43.33,149.08,-0.196
43.35,148.94,-0.198
43.38,148.80,-0.200
43.41,148.66,-0.200
43.44,148.53,-0.201
43.47,148.39,-0.202
43.49,148.24,-0.202
43.52,148.10,-0.203
43.55,147.96,-0.203
43.58,147.82,-0.203
43.61,147.68,-0.203
43.64,147.54,-0.203
43.66,147.40,-0.204
43.69,147.26,-0.204
43.72,147.12,-0.204
43.75,146.98,-0.204
43.78,146.84,-0.204
43.81,146.70,-0.204
43.84,146.56,-0.204
43.86,146.41,-0.204
43.89,146.27,-0.204
43.92,146.13,-0.203
43.95,145.99,-0.203
43.98,145.85,-0.203
44.01,145.71,-0.203
44.03,145.57,-0.203
44.06,145.42,-0.202
44.09,145.28,-0.202
44.12,145.14,-0.201
44.15,145.00,-0.201
44.18,144.86,-0.200
44.20,144.72,-0.200
44.23,144.58,-0.199
44.26,144.43,-0.198
44.29,144.29,-0.198
44.32,144.15,-0.197
44.34,144.01,-0.196
44.37,143.87,-0.195
44.40,143.72,-0.195
44.43,143.58,-0.194
44.46,143.44,-0.193
44.49,143.30,-0.193
44.51,143.16,-0.192
44.54,143.02,-0.191
44.57,142.87,-0.191
44.60,142.73,-0.190
44.63,142.59,-0.189
44.66,142.45,-0.189
44.69,142.31,-0.188
44.71,142.17,-0.188
44.74,142.02,-0.187
44.77,141.88,-0.187
44.80,141.74,-0.186
44.83,141.60,-0.186
44.86,141.46,-0.185
44.88,141.31,-0.184
44.91,141.17,-0.184
44.94,141.03,-0.181
44.97,140.89,-0.178
45.00,140.75,-0.177
45.03,140.60,-0.177
45.05,140.46,-0.176
45.08,140.32,-0.176
45.11,140.18,-0.176
45.14,140.04,-0.175
45.17,139.90,-0.175
45.19,139.75,-0.175
45.22,139.61,-0.174
45.25,139.47,-0.174
45.28,139.33,-0.174
45.31,139.19,-0.173
45.34,139.05,-0.173
45.36,138.90,-0.173
45.39,138.76,-0.173
45.42,138.62,-0.172
45.45,138.48,-0.146
45.48,138.33,-0.139
45.51,138.19,-0.141
45.54,138.04,-0.141
45.56,137.90,-0.142
45.59,137.76,-0.142
45.62,137.62,-0.143
45.65,137.48,-0.145
45.68,137.34,-0.146
45.71,137.20,-0.147
45.73,137.05,-0.148
45.76,136.91,-0.150
45.79,136.77,-0.151
45.82,136.63,-0.152
45.85,136.49,-0.154
45.88,136.35,-0.155
45.90,136.21,-0.156
45.93,136.07,-0.158
45.96,135.92,-0.159
45.99,135.78,-0.159
46.02,135.64,-0.160
46.04,135.50,-0.161
46.07,135.36,-0.162
46.10,135.22,-0.163
46.13,135.08,-0.164
46.16,134.93,-0.165
46.19,134.79,-0.166
46.21,134.65,-0.166
46.24,134.51,-0.167
46.27,134.37,-0.168
46.30,134.23,-0.168
46.33,134.09,-0.169
46.36,133.95,-0.169
46.39,133.81,-0.170
46.41,133.66,-0.171
46.44,133.52,-0.171
46.47,133.38,-0.172
46.50,133.24,-0.172
46.53,133.10,-0.173
46.56,132.96,-0.174
46.58,132.82,-0.174
46.61,132.67,-0.174
46.64,132.53,-0.175
46.67,132.39,-0.176
46.70,132.25,-0.176
46.73,132.11,-0.176
46.75,131.97,-0.177
46.78,131.82,-0.177
46.81,131.68,-0.178
46.84,131.54,-0.178
46.87,131.40,-0.179
46.89,131.26,-0.179
46.92,131.12,-0.179
46.95,130.97,-0.180
46.98,130.83,-0.180
47.01,130.69,-0.180
47.04,130.55,-0.181
47.06,130.41,-0.181
47.09,130.27,-0.181
47.12,130.13,-0.182
47.15,129.98,-0.182
47.18,129.84,-0.182
47.21,129.70,-0.183
47.24,129.56,-0.183
47.26,129.42,-0.183
47.29,129.28,-0.183
47.32,129.13,-0.184
47.35,128.99,-0.184
47.38,128.85,-0.184
47.41,128.71,-0.184
47.43,128.57,-0.184
47.46,128.43,-0.185
47.49,128.28,-0.185
47.52,128.14,-0.185
47.55,128.00,-0.185
47.58,127.86,-0.186
47.60,127.72,-0.186
47.63,127.58,-0.186
47.66,127.44,-0.186
47.69,127.29,-0.186
47.72,127.15,-0.186
47.74,127.01,-0.187
47.77,126.87,-0.187
47.80,126.73,-0.187
47.83,126.59,-0.187
47.86,126.44,-0.187
47.89,126.30,-0.187
47.91,126.16,-0.187
47.94,126.02,-0.188
47.97,125.88,-0.188
48.00,125.74,-0.188
48.03,125.59,-0.188
48.06,125.45,-0.188
48.09,125.31,-0.188
48.11,125.17,-0.188
48.14,125.03,-0.189
48.17,124.89,-0.189
48.20,124.74,-0.189
48.23,124.60,-0.189
48.26,124.46,-0.189
48.28,124.32,-0.189
48.31,124.18,-0.189
48.34,124.04,-0.189
48.37,123.89,-0.189
48.40,123.75,-0.189
48.43,123.61,-0.190
48.45,123.47,-0.190
48.48,123.33,-0.190
48.51,123.19,-0.190
48.54,123.04,-0.190
48.57,122.90,-0.190
48.59,122.76,-0.190
48.62,122.62,-0.190
48.65,122.48,-0.190
48.68,122.34,-0.190
48.71,122.19,-0.190
48.74,122.05,-0.190
48.76,121.91,-0.190
48.79,121.77,-0.190
48.82,121.63,-0.191
48.85,121.49,-0.191
48.88,121.35,-0.191
48.91,121.20,-0.191
48.94,121.06,-0.191
48.96,120.92,-0.191
48.99,120.78,-0.191
49.02,120.64,-0.191
49.05,120.50,-0.191
49.08,120.35,-0.191
49.11,120.21,-0.191
49.13,120.07,-0.191
49.16,119.93,-0.191
49.19,119.79,-0.191
49.22,119.65,-0.191
49.25,119.51,-0.191
49.28,119.36,-0.191
49.30,119.22,-0.191
49.33,119.08,-0.191
49.36,118.94,-0.192
49.39,118.80,-0.192
49.42,118.65,-0.192
49.44,118.51,-0.192
49.47,118.37,-0.192
49.50,118.23,-0.192
49.53,118.09,-0.192
49.56,117.95,-0.192
49.59,117.80,-0.192
49.61,117.66,-0.192
49.64,117.52,-0.192
49.67,117.38,-0.192
49.70,117.24,-0.192
49.73,117.10,-0.192
49.76,116.95,-0.192
49.79,116.81,-0.192
49.81,116.67,-0.192
49.84,116.53,-0.192
49.87,116.39,-0.192
49.90,116.25,-0.192
49.93,116.10,-0.192
49.96,115.96,-0.192
49.98,115.82,-0.192
50.01,115.68,-0.192
50.04,115.54,-0.192
50.07,115.40,-0.192
50.10,115.25,-0.192
50.13,115.11,-0.192
50.15,114.97,-0.192
50.18,114.83,-0.192
50.21,114.69,-0.192
50.24,114.55,-0.192
50.27,114.40,-0.192
50.29,114.26,-0.192
50.32,114.12,-0.192
50.35,113.98,-0.192
50.38,113.84,-0.192
50.41,113.70,-0.192
50.44,113.55,-0.192
50.46,113.41,-0.192
50.49,113.27,-0.192
50.52,113.13,-0.192
50.55,112.99,-0.192
50.58,112.85,-0.192
50.61,112.71,-0.192
50.64,112.56,-0.192
50.66,112.42,-0.192
50.69,112.28,-0.192
50.72,112.14,-0.192
50.75,112.00,-0.192
50.78,111.85,-0.192
50.81,111.71,-0.192
50.83,111.57,-0.192
50.86,111.43,-0.192
50.89,111.29,-0.192
50.92,111.15,-0.192
50.95,111.00,-0.192
50.98,110.86,-0.192
51.00,110.72,-0.192
51.03,110.58,-0.192
51.06,110.44,-0.192
51.09,110.30,-0.192
51.12,110.16,-0.192
51.14,110.01,-0.192
51.17,109.87,-0.192
51.20,109.73,-0.192
51.23,109.59,-0.192
51.26,109.45,-0.192
51.29,109.30,-0.192
51.31,109.16,-0.192
51.34,109.02,-0.192
51.37,108.88,-0.192
51.40,108.74,-0.192
51.43,108.60,-0.192
51.46,108.45,-0.192
51.49,108.31,-0.192
51.51,108.17,-0.192
51.54,108.03,-0.192
51.57,107.89,-0.192
51.60,107.74,-0.192
51.63,107.60,-0.192
51.66,107.46,-0.192
51.68,107.32,-0.191
51.71,107.18,-0.191
51.74,107.04,-0.191
51.77,106.90,-0.191
51.80,106.75,-0.191
51.83,106.61,-0.191
51.85,106.47,-0.191
51.88,106.33,-0.191
51.91,106.19,-0.191
51.94,106.05,-0.191
51.97,105.90,-0.191
51.99,105.76,-0.191
52.02,105.62,-0.191
52.05,105.48,-0.191
52.08,105.34,-0.191
52.11,105.20,-0.191
52.14,105.05,-0.191
52.16,104.91,-0.191
52.19,104.77,-0.191
52.22,104.63,-0.191
52.25,104.49,-0.191
52.28,104.35,-0.191
52.31,104.20,-0.191
52.34,104.06,-0.191
52.36,103.92,-0.191
52.39,103.78,-0.191
52.42,103.64,-0.191
52.45,103.49,-0.191
52.48,103.35,-0.190
52.51,103.21,-0.190
52.53,103.07,-0.190
52.56,102.93,-0.190
52.59,102.79,-0.190
[...]
191.73,38.23,0.089,0.953
191.76,38.37,0.089,0.954
191.79,38.51,0.089,0.955
191.82,38.65,0.089,0.955
191.85,38.79,0.090,0.956
191.88,38.93,0.090,0.957
191.90,39.08,0.090,0.958
191.93,39.22,0.090,0.958
191.96,39.36,0.090,0.957
191.99,39.50,0.090,0.958
192.02,39.64,0.090,0.958
192.05,39.79,0.090,0.959
192.08,39.93,0.090,0.958
192.10,40.07,0.090,0.959
192.13,40.21,0.090,0.960
192.16,40.35,0.090,0.961
192.19,40.49,0.090,0.961
192.22,40.64,0.090,0.960
192.25,40.78,0.090,0.960
192.27,40.92,0.090,0.961
192.30,41.06,0.090,0.961
192.33,41.20,0.090,0.962
192.36,41.35,0.090,0.963
192.39,41.49,0.090,0.962
192.42,41.63,0.090,0.963
192.44,41.77,0.090,0.964
192.47,41.91,0.090,0.964
192.50,42.05,0.090,0.964
192.53,42.20,0.090,0.965
192.56,42.34,0.091,0.965
192.58,42.48,0.091,0.966
192.61,42.62,0.091,0.966
192.64,42.76,0.091,0.966
192.67,42.90,0.091,0.966
192.70,43.05,0.091,0.966
192.73,43.19,0.091,0.967
192.75,43.33,0.091,0.967
192.78,43.47,0.091,0.968
192.81,43.61,0.091,0.968
192.84,43.75,0.091,0.969
192.87,43.90,0.091,0.969
192.90,44.04,0.091,0.969
192.93,44.18,0.091,0.969
192.95,44.32,0.091,0.970
192.98,44.46,0.091,0.970
193.01,44.61,0.091,0.970
193.04,44.75,0.091,0.971
193.07,44.89,0.091,0.971
193.10,45.03,0.091,0.972
193.12,45.17,0.091,0.972
193.15,45.31,0.091,0.972
193.18,45.46,0.091,0.973
193.21,45.60,0.091,0.974
193.24,45.74,0.091,0.973
193.27,45.88,0.092,0.974
193.29,46.02,0.092,0.975
193.32,46.17,0.092,0.977
193.35,46.31,0.092,0.978
193.38,46.45,0.092,0.979
193.41,46.59,0.092,0.979
193.43,46.73,0.092,0.981
193.46,46.87,0.092,0.981
193.49,47.02,0.092,0.981
193.52,47.16,0.092,0.981
193.55,47.30,0.092,0.980
193.58,47.44,0.092,0.980
193.60,47.58,0.092,0.980
193.63,47.72,0.092,0.979
193.66,47.86,0.092,0.979
193.69,48.01,0.092,0.980
193.72,48.15,0.092,0.979
193.75,48.29,0.092,0.980
193.78,48.43,0.092,0.981
193.80,48.57,0.092,0.981
193.83,48.72,0.092,0.981
193.86,48.86,0.092,0.980
193.89,49.00,0.092,0.980
193.92,49.14,0.092,0.982
193.95,49.28,0.092,0.983
193.97,49.42,0.092,0.983
194.00,49.57,0.092,0.983
194.03,49.71,0.092,0.982
194.06,49.85,0.092,0.983
194.09,49.99,0.092,0.984
194.12,50.13,0.092,0.984
194.14,50.27,0.093,0.984
194.17,50.42,0.093,0.985
194.20,50.56,0.093,0.985
194.23,50.70,0.093,0.986
194.26,50.84,0.093,0.987
194.28,50.99,0.093,0.988
194.31,51.13,0.093,0.988
194.34,51.27,0.093,0.989
194.37,51.41,0.093,0.989
194.40,51.55,0.093,0.990
194.43,51.69,0.093,0.991
194.45,51.84,0.093,0.991
194.48,51.98,0.093,0.991
194.51,52.12,0.093,0.991
194.54,52.26,0.093,0.991
194.57,52.40,0.093,0.992
194.60,52.54,0.093,0.992
194.63,52.69,0.093,0.992
194.65,52.83,0.093,0.993
194.68,52.97,0.093,0.994
194.71,53.11,0.093,0.996
194.74,53.25,0.093,0.996
194.77,53.39,0.093,0.996
194.80,53.54,0.093,0.997
194.82,53.68,0.093,0.997
194.85,53.82,0.094,0.998
194.88,53.96,0.094,0.998
194.91,54.10,0.094,0.998
194.94,54.24,0.094,1.000
194.97,54.39,0.094,1.000
194.99,54.53,0.094,1.000
195.02,54.67,0.094,1.000
195.05,54.81,0.094,1.000
195.08,54.95,0.094,1.001
195.11,55.10,0.094,1.002
195.13,55.24,0.094,1.001
195.16,55.38,0.094,1.003
195.19,55.52,0.094,1.003
195.22,55.66,0.094,1.004
195.25,55.80,0.094,1.004
195.28,55.95,0.094,1.005
195.30,56.09,0.094,1.005
195.33,56.23,0.094,1.006
195.36,56.37,0.094,1.006
195.39,56.51,0.094,1.007
195.42,56.66,0.094,1.007
195.45,56.80,0.094,1.008
195.48,56.94,0.094,1.008
195.50,57.08,0.094,1.008
195.53,57.22,0.095,1.009
195.56,57.36,0.095,1.009
195.59,57.50,0.095,1.009
195.62,57.65,0.095,1.009
195.65,57.79,0.095,1.009
195.67,57.93,0.095,1.011
195.70,58.07,0.095,1.011
195.73,58.21,0.095,1.012
195.76,58.36,0.095,1.013
195.79,58.50,0.095,1.013
195.82,58.64,0.095,1.013
195.84,58.78,0.095,1.014
195.87,58.92,0.095,1.014
195.90,59.06,0.095,1.015
195.93,59.21,0.095,1.015
195.96,59.35,0.095,1.015
195.98,59.49,0.095,1.015
196.01,59.63,0.095,1.016
196.04,59.77,0.095,1.016
196.07,59.91,0.095,1.016
196.10,60.06,0.095,1.016
196.13,60.20,0.095,1.017
196.15,60.34,0.095,1.018
196.18,60.48,0.095,1.019
196.21,60.62,0.095,1.019
196.24,60.77,0.095,1.021
196.27,60.91,0.096,1.021
196.30,61.05,0.096,1.021
196.33,61.19,0.096,1.022
196.35,61.33,0.096,1.021
196.38,61.47,0.096,1.021
196.41,61.62,0.096,1.022
196.44,61.76,0.096,1.023
196.47,61.90,0.096,1.023
196.50,62.04,0.096,1.024
196.52,62.18,0.096,1.024
196.55,62.32,0.096,1.025
196.58,62.46,0.096,1.026
196.61,62.61,0.096,1.025
196.64,62.75,0.096,1.025
196.67,62.89,0.096,1.026
196.69,63.03,0.096,1.027
196.72,63.17,0.096,1.026
196.75,63.32,0.096,1.028
196.78,63.46,0.096,1.028
196.81,63.60,0.096,1.028
196.83,63.74,0.096,1.028
196.86,63.88,0.096,1.028
196.89,64.02,0.096,1.028
196.92,64.17,0.096,1.029
196.95,64.31,0.097,1.028
196.98,64.45,0.097,1.029
197.00,64.59,0.097,1.030
197.03,64.73,0.097,1.031
197.06,64.88,0.097,1.032
197.09,65.02,0.097,1.032
197.12,65.16,0.097,1.033
197.15,65.30,0.097,1.035
197.18,65.44,0.097,1.036
197.20,65.58,0.097,1.037
197.23,65.73,0.097,1.037
197.26,65.87,0.097,1.038
197.29,66.01,0.097,1.039
197.32,66.15,0.097,1.039
197.35,66.29,0.097,1.040
197.37,66.44,0.097,1.039
197.40,66.58,0.097,1.040
197.43,66.72,0.097,1.040
197.46,66.86,0.098,1.040
197.49,67.00,0.098,1.041
197.52,67.14,0.098,1.041
197.54,67.29,0.098,1.041
197.57,67.43,0.098,1.042
197.60,67.57,0.098,1.043
197.63,67.71,0.098,1.044
197.66,67.85,0.098,1.045
197.68,68.00,0.098,1.045
197.71,68.14,0.098,1.046
197.74,68.28,0.098,1.046
197.77,68.42,0.098,1.046
197.80,68.56,0.098,1.047
197.83,68.70,0.098,1.047
197.85,68.85,0.098,1.048
197.88,68.99,0.098,1.048
197.91,69.13,0.098,1.049
197.94,69.27,0.098,1.049
197.97,69.41,0.098,1.050
198.00,69.55,0.098,1.051
198.03,69.70,0.099,1.051
198.05,69.84,0.099,1.051
198.08,69.98,0.099,1.052
198.11,70.12,0.099,1.052
198.14,70.26,0.099,1.053
198.17,70.40,0.099,1.053
198.20,70.55,0.099,1.054
198.22,70.69,0.099,1.054
198.25,70.83,0.099,1.055
198.28,70.97,0.099,1.056
198.31,71.11,0.099,1.057
198.34,71.26,0.099,1.057
198.37,71.40,0.099,1.058
198.39,71.54,0.099,1.058
198.42,71.68,0.099,1.059
198.45,71.82,0.099,1.059
198.48,71.96,0.099,1.059
198.51,72.11,0.099,1.059
198.53,72.25,0.099,1.060
198.56,72.39,0.099,1.060
198.59,72.53,0.099,1.060
198.62,72.67,0.100,1.060
198.65,72.82,0.100,1.061
198.68,72.96,0.100,1.062
198.70,73.10,0.100,1.063
198.73,73.24,0.100,1.064
198.76,73.38,0.100,1.066
198.79,73.52,0.100,1.067
198.82,73.67,0.100,1.068
198.85,73.81,0.100,1.069
198.88,73.95,0.100,1.068
198.90,74.09,0.100,1.069
198.93,74.23,0.100,1.069
198.96,74.37,0.100,1.069
198.99,74.52,0.100,1.070
199.02,74.66,0.100,1.070
199.05,74.80,0.100,1.070
199.07,74.94,0.101,1.071
199.10,75.08,0.101,1.072
199.13,75.22,0.101,1.072
199.16,75.37,0.101,1.072
199.19,75.51,0.101,1.073
199.22,75.65,0.101,1.075
199.24,75.79,0.101,1.077
199.27,75.93,0.101,1.078
199.30,76.08,0.101,1.079
199.33,76.22,0.101,1.079
199.36,76.36,0.101,1.080
199.38,76.50,0.101,1.081
199.41,76.64,0.101,1.081
199.44,76.79,0.101,1.082
199.47,76.93,0.102,1.083
199.50,77.07,0.102,1.083
199.53,77.21,0.102,1.085
199.55,77.35,0.102,1.086
199.58,77.49,0.102,1.087
199.61,77.63,0.102,1.086
199.64,77.78,0.102,1.087
199.67,77.92,0.102,1.086
199.70,78.06,0.102,1.088
199.73,78.20,0.102,1.088
199.75,78.34,0.102,1.089
199.78,78.49,0.102,1.090
199.81,78.63,0.102,1.092
199.84,78.77,0.102,1.092
199.87,78.91,0.103,1.093
199.90,79.05,0.103,1.093
199.92,79.19,0.103,1.094
199.95,79.34,0.103,1.095
199.98,79.48,0.103,1.097
200.01,79.62,0.103,1.098
200.04,79.76,0.103,1.099
200.07,79.90,0.103,1.099
200.09,80.05,0.103,1.099
200.12,80.19,0.103,1.100
200.15,80.33,0.103,1.101
200.18,80.47,0.103,1.102
200.21,80.61,0.104,1.103
200.23,80.76,0.104,1.105
200.26,80.90,0.104,1.107
200.29,81.04,0.104,1.110
200.32,81.18,0.104,1.110
200.35,81.32,0.104,1.112
200.38,81.46,0.104,1.113
200.40,81.61,0.104,1.114
200.43,81.75,0.104,1.114
200.46,81.89,0.104,1.116
200.49,82.03,0.105,1.116
200.52,82.17,0.105,1.117
200.55,82.31,0.105,1.118
200.58,82.46,0.105,1.118
200.60,82.60,0.105,1.120
200.63,82.74,0.105,1.121
200.66,82.88,0.105,1.122
200.69,83.02,0.105,1.122
200.72,83.16,0.105,1.125
200.75,83.31,0.105,1.126
200.77,83.45,0.106,1.128
200.80,83.59,0.106,1.129
200.83,83.73,0.106,1.130
200.86,83.87,0.106,1.131
200.89,84.01,0.106,1.133
200.92,84.15,0.106,1.132
200.94,84.30,0.106,1.133
200.97,84.44,0.106,1.134
201.00,84.58,0.106,1.134
201.03,84.72,0.106,1.136
201.06,84.86,0.106,1.136
201.08,85.00,0.107,1.138
201.11,85.15,0.107,1.139
201.14,85.29,0.107,1.140
201.17,85.43,0.107,1.143
201.20,85.57,0.107,1.145
201.23,85.71,0.107,1.146
201.25,85.85,0.107,1.147
201.28,86.00,0.108,1.149
201.31,86.14,0.108,1.150
201.34,86.28,0.108,1.152
201.37,86.42,0.108,1.153
201.40,86.56,0.108,1.153
201.43,86.71,0.108,1.155
201.45,86.85,0.108,1.156
201.48,86.99,0.108,1.158
201.51,87.13,0.109,1.158
201.54,87.27,0.109,1.160
201.57,87.41,0.109,1.161
201.60,87.56,0.109,1.164
201.62,87.70,0.109,1.166
201.65,87.84,0.109,1.168
201.68,87.98,0.110,1.169
201.71,88.12,0.110,1.172
201.74,88.26,0.110,1.172
201.77,88.41,0.110,1.175
201.79,88.55,0.110,1.175
201.82,88.69,0.110,1.177
201.85,88.83,0.110,1.179
201.88,88.97,0.111,1.181
201.91,89.11,0.111,1.183
201.93,89.26,0.111,1.187
201.96,89.40,0.111,1.189
201.99,89.54,0.111,1.191
202.02,89.68,0.112,1.193
202.05,89.82,0.112,1.195
202.08,89.96,0.112,1.197
202.10,90.10,0.112,1.198
202.13,90.25,0.112,1.200
202.16,90.39,0.113,1.201
202.19,90.53,0.113,1.204
202.22,90.67,0.113,1.206
202.25,90.81,0.113,1.210
202.28,90.96,0.114,1.213
202.30,91.10,0.114,1.215
202.33,91.24,0.114,1.217
202.36,91.38,0.114,1.220
202.39,91.52,0.114,1.222
202.42,91.66,0.115,1.224
202.45,91.80,0.115,1.226
202.47,91.95,0.115,1.227
202.50,92.09,0.115,1.229
202.53,92.23,0.116,1.231
202.56,92.37,0.116,1.234
202.59,92.51,0.116,1.238
202.62,92.66,0.116,1.240
202.64,92.80,0.117,1.244
202.67,92.94,0.117,1.247
202.70,93.08,0.117,1.251
202.73,93.22,0.118,1.255
202.76,93.37,0.118,1.258
202.78,93.51,0.118,1.260
202.81,93.65,0.118,1.264
202.84,93.79,0.119,1.266
202.87,93.93,0.119,1.269
202.90,94.07,0.119,1.272
202.93,94.21,0.119,1.274
202.95,94.36,0.120,1.277
202.98,94.50,0.120,1.281
203.01,94.64,0.120,1.283
203.04,94.78,0.120,1.285
203.07,94.92,0.121,1.288
203.10,95.06,0.121,1.291
203.13,95.21,0.121,1.293
203.15,95.35,0.122,1.297
203.18,95.49,0.122,1.300
203.21,95.63,0.122,1.303
203.24,95.77,0.122,1.307
203.27,95.91,0.123,1.310
203.30,96.06,0.123,1.313
203.32,96.20,0.123,1.317
203.35,96.34,0.124,1.320
203.38,96.48,0.124,1.323
203.41,96.62,0.124,1.325
203.44,96.76,0.124,1.327
203.47,96.91,0.125,1.330
203.49,97.05,0.125,1.333
203.52,97.19,0.125,1.336
203.55,97.33,0.125,1.337
203.58,97.47,0.126,1.341
203.61,97.61,0.126,1.344
203.63,97.76,0.126,1.347
203.66,97.90,0.127,1.350
203.69,98.04,0.127,1.351
203.72,98.18,0.127,1.354
203.75,98.32,0.127,1.358
203.78,98.46,0.127,1.359
203.80,98.61,0.128,1.362
203.83,98.75,0.128,1.365
203.86,98.89,0.128,1.367
203.89,99.03,0.128,1.370
203.92,99.17,0.129,1.372
203.95,99.31,0.129,1.373
203.98,99.46,0.129,1.376
204.00,99.60,0.129,1.378
204.03,99.74,0.130,1.379
204.06,99.88,0.130,1.381
204.09,100.02,0.130,1.384
204.12,100.16,0.130,1.386
204.15,100.31,0.130,1.389
204.17,100.45,0.131,1.391
204.20,100.59,0.131,1.392
204.23,100.73,0.131,1.394
204.26,100.87,0.131,1.396
204.29,101.02,0.131,1.398
204.32,101.16,0.131,1.399
204.34,101.30,0.131,1.401
204.37,101.44,0.132,1.402
204.40,101.58,0.132,1.403
204.43,101.72,0.132,1.403
204.46,101.87,0.132,1.405
204.48,102.01,0.132,1.406
204.51,102.15,0.132,1.407
204.54,102.29,0.132,1.408
204.57,102.43,0.132,1.410
204.60,102.57,0.132,1.412
204.63,102.72,0.133,1.413
204.65,102.86,0.133,1.412
204.68,103.00,0.133,1.414
204.71,103.14,0.133,1.414
204.74,103.28,0.133,1.413
204.77,103.42,0.133,1.413
204.80,103.57,0.133,1.411
204.83,103.71,0.133,1.412
204.85,103.85,0.133,1.413
204.88,103.99,0.133,1.413
204.91,104.13,0.133,1.414
204.94,104.28,0.133,1.415
204.97,104.42,0.133,1.416
205.00,104.56,0.133,1.417
205.02,104.70,0.133,1.416
205.05,104.84,0.133,1.416
205.08,104.98,0.133,1.416
205.11,105.13,0.133,1.415
205.14,105.27,0.133,1.415
205.17,105.41,0.133,1.414
205.19,105.55,0.133,1.414
205.22,105.69,0.133,1.415
205.25,105.84,0.133,1.415
205.28,105.98,0.133,1.415
205.31,106.12,0.133,1.415
205.33,106.26,0.133,1.416
205.36,106.40,0.133,1.416
205.39,106.54,0.133,1.416
205.42,106.69,0.133,1.414
205.45,106.83,0.133,1.413
205.48,106.97,0.133,1.412
205.50,107.11,0.133,1.412
205.53,107.25,0.133,1.413
205.56,107.40,0.133,1.413
205.59,107.54,0.133,1.413
205.62,107.68,0.133,1.413
205.65,107.82,0.133,1.413
205.68,107.96,0.133,1.413
205.70,108.10,0.133,1.412
205.73,108.24,0.133,1.411
205.76,108.39,0.133,1.411
205.79,108.53,0.133,1.410
205.82,108.67,0.133,1.410
205.85,108.81,0.133,1.410
205.87,108.95,0.132,1.409
205.90,109.10,0.132,1.409
205.93,109.24,0.132,1.409
205.96,109.38,0.132,1.408
205.99,109.52,0.132,1.409
206.02,109.66,0.132,1.408
206.04,109.80,0.132,1.409
206.07,109.95,0.132,1.407
206.10,110.09,0.132,1.407
206.13,110.23,0.132,1.408
206.16,110.37,0.132,1.408
206.18,110.51,0.132,1.408
206.21,110.65,0.132,1.408
206.24,110.80,0.132,1.409
206.27,110.94,0.132,1.409
206.30,111.08,0.132,1.410
206.33,111.22,0.132,1.409
206.35,111.36,0.132,1.409
206.38,111.50,0.132,1.408
206.41,111.65,0.132,1.408
206.44,111.79,0.132,1.408
206.47,111.93,0.132,1.407
206.50,112.07,0.132,1.408
206.53,112.21,0.132,1.407
206.55,112.36,0.132,1.407
206.58,112.50,0.132,1.408
206.61,112.64,0.132,1.408
206.64,112.78,0.132,1.408
206.67,112.92,0.133,1.408
206.70,113.06,0.133,1.408
206.72,113.21,0.133,1.407
206.75,113.35,0.133,1.408
206.78,113.49,0.133,1.407
206.81,113.63,0.133,1.408
206.84,113.77,0.133,1.408
206.87,113.92,0.133,1.410
206.89,114.06,0.133,1.410
206.92,114.20,0.133,1.412
206.95,114.34,0.133,1.412
206.98,114.48,0.133,1.413
207.01,114.62,0.133,1.414
207.03,114.77,0.133,1.412
207.06,114.91,0.133,1.411
207.09,115.05,0.133,1.411
207.12,115.19,0.133,1.410
207.15,115.33,0.133,1.409
207.18,115.47,0.133,1.409
207.20,115.62,0.133,1.408
207.23,115.76,0.133,1.410
207.26,115.90,0.133,1.410
207.29,116.04,0.133,1.412
207.32,116.18,0.133,1.412
207.35,116.33,0.133,1.414
207.38,116.47,0.133,1.414
207.40,116.61,0.133,1.414
207.43,116.75,0.133,1.414
207.46,116.89,0.133,1.414
207.49,117.03,0.133,1.413
207.52,117.18,0.133,1.413
207.55,117.32,0.133,1.413
207.57,117.46,0.133,1.412
207.60,117.60,0.133,1.414
207.63,117.74,0.133,1.413
207.66,117.88,0.133,1.414
207.69,118.03,0.133,1.414
207.72,118.17,0.133,1.416
207.74,118.31,0.133,1.417
207.77,118.45,0.133,1.418
207.80,118.59,0.133,1.417
207.83,118.73,0.133,1.418
207.86,118.88,0.133,1.417
207.88,119.02,0.133,1.418
207.91,119.16,0.133,1.416
207.94,119.30,0.133,1.416
207.97,119.44,0.133,1.416
208.00,119.59,0.133,1.417
208.03,119.73,0.134,1.418
208.05,119.87,0.134,1.418
208.08,120.01,0.134,1.419
208.11,120.15,0.134,1.419
208.14,120.29,0.134,1.420
208.17,120.44,0.134,1.420
208.20,120.58,0.134,1.421
208.23,120.72,0.134,1.421
208.25,120.86,0.134,1.421
208.28,121.00,0.134,1.420
208.31,121.14,0.134,1.421
208.34,121.29,0.134,1.422
208.37,121.43,0.134,1.421
208.40,121.57,0.134,1.421
208.42,121.71,0.134,1.421
208.45,121.85,0.134,1.422
208.48,122.00,0.134,1.423
208.51,122.14,0.134,1.423
208.54,122.28,0.134,1.423
208.57,122.42,0.134,1.424
208.59,122.56,0.134,1.424
208.62,122.70,0.134,1.424
208.65,122.85,0.134,1.424
208.68,122.99,0.134,1.425
208.71,123.13,0.134,1.426
208.73,123.27,0.134,1.426
208.76,123.41,0.134,1.427
208.79,123.55,0.134,1.428
208.82,123.70,0.134,1.428
208.85,123.84,0.135,1.427
208.88,123.98,0.135,1.428
208.90,124.12,0.135,1.428
208.93,124.26,0.135,1.429
208.96,124.41,0.135,1.429
208.99,124.55,0.135,1.430
209.02,124.69,0.135,1.432
209.05,124.83,0.135,1.432
209.08,124.97,0.135,1.434
209.10,125.11,0.135,1.433
209.13,125.25,0.135,1.432
209.16,125.40,0.135,1.432
209.19,125.54,0.135,1.432
209.22,125.68,0.135,1.432
209.25,125.82,0.135,1.431
209.27,125.96,0.135,1.430
209.30,126.11,0.135,1.431
209.33,126.25,0.135,1.432
209.36,126.39,0.135,1.433
209.39,126.53,0.135,1.434
209.42,126.67,0.135,1.436
209.44,126.82,0.135,1.438
209.47,126.96,0.135,1.438
209.50,127.10,0.135,1.439
209.53,127.24,0.135,1.440
209.56,127.38,0.135,1.439
209.58,127.52,0.135,1.439
209.61,127.66,0.135,1.439
209.64,127.81,0.135,1.438
209.67,127.95,0.135,1.438
209.70,128.09,0.136,1.437
209.73,128.23,0.136,1.437
209.75,128.37,0.136,1.438
209.78,128.52,0.136,1.439
209.81,128.66,0.136,1.440
209.84,128.80,0.136,1.439
209.87,128.94,0.136,1.441
209.90,129.08,0.136,1.440
209.93,129.22,0.136,1.440
209.95,129.36,0.136,1.440
209.98,129.51,0.136,1.440
210.01,129.65,0.136,1.440
210.04,129.79,0.136,1.442
210.07,129.93,0.136,1.441
210.10,130.07,0.136,1.441
210.12,130.22,0.136,1.441
210.15,130.36,0.136,1.443
210.18,130.50,0.136,1.442
210.21,130.64,0.136,1.443
210.24,130.78,0.136,1.443
210.27,130.92,0.136,1.443
210.29,131.07,0.136,1.443
210.32,131.21,0.136,1.443
210.35,131.35,0.136,1.444
210.38,131.49,0.136,1.444
210.41,131.63,0.136,1.445
210.43,131.78,0.136,1.446
210.46,131.92,0.136,1.448
210.49,132.06,0.137,1.450
210.52,132.20,0.137,1.449
210.55,132.34,0.137,1.449
210.58,132.48,0.137,1.449
210.60,132.62,0.137,1.449
210.63,132.77,0.137,1.448
210.66,132.91,0.137,1.447
210.69,133.05,0.137,1.448
210.72,133.19,0.137,1.448
210.75,133.33,0.137,1.448
210.78,133.48,0.137,1.448
210.80,133.62,0.137,1.449
210.83,133.76,0.137,1.448
210.86,133.90,0.137,1.448
210.89,134.04,0.137,1.449
210.92,134.18,0.137,1.448
210.95,134.33,0.137,1.448
210.97,134.47,0.137,1.449
211.00,134.61,0.137,1.449
211.03,134.75,0.137,1.451
211.06,134.89,0.137,1.452
211.09,135.04,0.137,1.452
211.12,135.18,0.137,1.453
211.14,135.32,0.137,1.454
211.17,135.46,0.137,1.452
211.20,135.60,0.137,1.453
211.23,135.74,0.137,1.455
211.26,135.89,0.137,1.454
211.28,136.03,0.137,1.454
211.31,136.17,0.137,1.455
211.34,136.31,0.137,1.455
211.37,136.45,0.137,1.456
211.40,136.59,0.137,1.456
211.43,136.74,0.137,1.456
211.45,136.88,0.137,1.456
211.48,137.02,0.137,1.457
211.51,137.16,0.137,1.457
211.54,137.30,0.137,1.457
211.57,137.44,0.138,1.457
211.60,137.58,0.138,1.455
211.63,137.73,0.138,1.455
211.65,137.87,0.138,1.453
211.68,138.01,0.138,1.454
211.71,138.15,0.138,1.454
211.74,138.30,0.138,1.454
211.77,138.44,0.138,1.456
211.80,138.58,0.138,1.457
211.82,138.72,0.138,1.458
211.85,138.86,0.138,1.462
211.88,139.01,0.138,1.463
211.91,139.15,0.138,1.464
211.94,139.29,0.138,1.463
211.97,139.43,0.138,1.463
211.99,139.57,0.138,1.464
212.02,139.71,0.138,1.465
212.05,139.86,0.138,1.464
212.08,140.00,0.138,1.465
212.11,140.14,0.138,1.465
212.13,140.28,0.138,1.467
212.16,140.42,0.138,1.466
212.19,140.56,0.138,1.465
212.22,140.70,0.138,1.466
212.25,140.85,0.138,1.465
212.28,140.99,0.138,1.464
212.30,141.13,0.138,1.465
212.33,141.27,0.138,1.466
212.36,141.41,0.139,1.467
212.39,141.56,0.139,1.468
212.42,141.70,0.139,1.469
212.45,141.84,0.139,1.469
212.48,141.98,0.139,1.468
212.50,142.12,0.139,1.468
212.53,142.26,0.139,1.467
212.56,142.40,0.139,1.466
212.59,142.55,0.139,1.465
212.62,142.69,0.139,1.465
212.65,142.83,0.139,1.465
212.67,142.97,0.139,1.466
212.70,143.11,0.139,1.467
212.73,143.26,0.139,1.470
212.76,143.40,0.139,1.472
212.79,143.54,0.139,1.472
212.82,143.68,0.139,1.474
212.84,143.82,0.139,1.475
212.87,143.96,0.139,1.475
212.90,144.11,0.139,1.475
212.93,144.25,0.139,1.474
212.96,144.39,0.139,1.474
212.98,144.53,0.139,1.475
213.01,144.67,0.139,1.473
213.04,144.81,0.139,1.473
213.07,144.96,0.139,1.473
213.10,145.10,0.139,1.473
213.13,145.24,0.140,1.475
213.15,145.38,0.140,1.475
213.18,145.52,0.140,1.475
213.21,145.66,0.140,1.476
213.24,145.81,0.140,1.477
213.27,145.95,0.140,1.478
213.30,146.09,0.140,1.479
213.33,146.23,0.140,1.479
213.35,146.37,0.140,1.479
213.38,146.52,0.140,1.481
213.41,146.66,0.140,1.482
213.44,146.80,0.140,1.482
213.47,146.94,0.140,1.482
213.50,147.08,0.140,1.481
213.52,147.22,0.140,1.481
213.55,147.37,0.140,1.481
213.58,147.51,0.140,1.481
213.61,147.65,0.140,1.480
213.64,147.79,0.140,1.480
213.67,147.93,0.140,1.480
213.69,148.07,0.140,1.481
213.72,148.22,0.140,1.482
213.75,148.36,0.141,1.484
213.78,148.50,0.141,1.486
213.81,148.64,0.141,1.487
213.83,148.78,0.141,1.488
213.86,148.92,0.141,1.489
213.89,149.07,0.141,
213.92,149.21,0.141,
213.95,149.35,,
213.98,149.49,,
213.98,,,