File: DSC/Earl/2025_10_13_CBG_5Cmin_n90C_80C_x3.csv
Filename,2025_10_13_CBG_5Cmin_n90C_80C_x3
Instrument name,DSC2A-00468 (192.168.1.100)
Operator,JLY
rundate,10/12/2025
Sample name,2025_10_13_CBG_5Cmin_n90C_80C_x3
proceduresegments,Data Off ; Equilibrate -90.00 °C; Data On ; Ramp 5.00 °C/min to 80.00 °C; Data Off ; Isothermal 1.0 min; Data On ; Ramp 40.00 °C/min to -90.00 °C; Data Off ; Isothermal 5.0 min; Data On ; Ramp 5.00 °C/min to 80.00 °C; Data Off ; Isothermal 1.0 min; Data On ; Ramp 5.00 °C/min to -90.00 °C; Data Off ; Isothermal 1.0 min; Data On ; Ramp 5.00 °C/min to 80.00 °C
[File Parameters]
Run date,10/12/2025 11:12:13 PM
Trios version,5.1.1.46572
Original File Name,
Current File Name,D:\DSC2500\JYarger\2025_10_13_CBG_5Cmin_n90C_80C_x3.tri
[Procedure]
Procedure Name,CBG_n90C_80C_5Cmin_x3
Sample Name,2025_10_13_CBG_5Cmin_n90C_80C_x3
Sample Mass,3.45 mg
Reference Sample Mass,0 mg
Pan Mass,32.82 mg
Pan Number,29
Reference Pan Mass,32.55 mg
Reference Pan Number,1
Pan Type,Aluminum
Comments,DSC_Samples_Y2_Tray_ASDs_Pharma_Oct2025 Google Sheet.
Project Name,Amorphous Pharma
Operator,JLY
Test,Custom
Unload Max Temperature,30
Unload Min Temperature,30
Load Max Temperature,30
Load Min Temperature,30
Stop on Gas Flow Error,Yes
[Signal List]
Signal #1,Time (min)
Signal #2,Temperature (°C)
Signal #3,Heat Flow (mW)
Signal #4,Delta T (µV)
Signal #5,Delta Tzero (µV)
Signal #6,Tzero Temperature (°C)
Signal #7,Cell Purge (mL/min)
Signal #8,Heater Temp (°C)
Signal #9,Power Delivered (W)
Signal #10,Reference Junction Temperature (°C)
Signal #11,Flange Temperature (°C)
Signal #12,Heat Flow Phase (rad)
Signal #13,Total Heat Capacity (J/°C)
Signal #14,Heat Capacity (J/°C)
[Configuration]
Company Name,ASU
Instrument Name,DSC2A-00468
Instrument Type,DSC2500
Serial Number,DSC2A-00468
IP,192.168.1.100
Location of Instrument,MRRC
DisplayType,Unknown
Sample Interval ,0.1 s/pt
Selected Heat Flow,T4P
Exotherm Direction,Down
Cell Serial,DRC2-00792
Lid Type,Standard
Cooler,RCS 90
Leave Cooler on at End of Sequence,On
Gas 2,Nitrogen
Gas Selected,Channel 1
Flow Rate,50 mL/min
Secondary Purge,On
Licensed Heat Flow,Heat Flow T4P
Modulation Licensed,Yes
[Versions]
Common IDD Version,1
Cortex Version,VER 2.10.2.31
Driver,5.0.0.6
GDM Version,1.0.3.3
TouchscreenVersion,1.0.0.16145
FEP Version,1.2.1.21
FEP Bootloader,2.0.0.5
AutoSampler Version,2.1.1.26
Auto Sampler Bootloader,2.0.0.5
FCM Version,1.1.0.3
FCM Bootloader,2.0.0.5
[Experiment Logs]
Experiment Log Entry # 1,Data On set to 0
Experiment Log Entry # 3,Equilibrate Segment -90 (C) Started
Experiment Log Entry # 5,Air Cool is off.
Experiment Log Entry # 7,Data On set to 1
Experiment Log Entry # 9,Ramp Segment 5 C/min to 80 Started
Experiment Log Entry # 11,Data On set to 0
Experiment Log Entry # 13,Isothermal Segment 1 min started
Experiment Log Entry # 15,Data On set to 1
Experiment Log Entry # 17,Ramp Segment 40 C/min to -90 Started
Experiment Log Entry # 19,Data On set to 0
Experiment Log Entry # 21,Isothermal Segment 5 min started
Experiment Log Entry # 23,Data On set to 1
Experiment Log Entry # 25,Ramp Segment 5 C/min to 80 Started
Experiment Log Entry # 27,Data On set to 0
Experiment Log Entry # 29,Isothermal Segment 1 min started
Experiment Log Entry # 31,Data On set to 1
Experiment Log Entry # 33,Ramp Segment 5 C/min to -90 Started
Experiment Log Entry # 35,Data On set to 0
Experiment Log Entry # 37,Isothermal Segment 1 min started
Experiment Log Entry # 39,Data On set to 1
Experiment Log Entry # 41,Ramp Segment 5 C/min to 80 Started
[Method Log]
Method Log Entry # 1,Data Off
Method Log Entry # 2,Equilibrate -90 °C
Method Log Entry # 3,Data On
Method Log Entry # 4,(Ramp 105672) Ramp 5 °C/minute to 80 °C
Method Log Entry # 5,Data Off
Method Log Entry # 6,Isothermal 1 minutes
Method Log Entry # 7,Data On
Method Log Entry # 8,(Ramp 105676) Ramp 40 °C/minute to -90 °C
Method Log Entry # 9,Data Off
Method Log Entry # 10,Isothermal 5 minutes
Method Log Entry # 11,Data On
Method Log Entry # 12,(Ramp 105680) Ramp 5 °C/minute to 80 °C
Method Log Entry # 13,Data Off
Method Log Entry # 14,Isothermal 1 minutes
Method Log Entry # 15,Data On
Method Log Entry # 16,(Ramp 105684) Ramp 5 °C/minute to -90 °C
Method Log Entry # 17,Data Off
Method Log Entry # 18,Isothermal 1 minutes
Method Log Entry # 19,Data On
Method Log Entry # 20,(Ramp 105688) Ramp 5 °C/minute to 80 °C
Cell Serial,DRC2-00792
[T1 Calibration]
Slope,-0.008529666
Offset,9.636258
Initial Temperature,98.23
GUID,f8bfdadc-4977-4fdf-ba6d-0ba9134940c3
[TZero Calibration]
Date Applied,11/29/2022 4:06:13 PM
Description,From -89.059 °C to 396.009 °C at 20.000°C/min
Gas Type,Nitrogen
Pan Type,None
Source Files 1,C:\Users\yargerlab\Desktop\DSC Data\General\TZero_calibration_11_29_22_2nd(2).tri
Source Files 2,C:\Users\yargerlab\Desktop\DSC Data\General\TZero_calibration_11_29_22_2nd(3).tri
Delta T Offset,13.05235
Delta T Slope,-0.007271007
Delta T0 Offset,-13.69128
Delta T0 Slope,0.06063341
[Temperature Calibration]
Date Applied,11/29/2022 7:12:28 PM
Description,From 106.590 °C to 186.590 °C at 10.000°C/min
Gas Type,Nitrogen
Pan Type,Tzero Aluminum Hermetic
Source Files 1,C:\Users\yargerlab\Desktop\DSC Data\General\Indium(6).tri
Measured 1,157.391
Known 1,156.598
[Cell Constant Calibration]
Date Applied,11/29/2022 7:12:29 PM
Description,From 106.590 °C to 186.590 °C at 10.000°C/min
Gas Type,Nitrogen
Pan Type,Tzero Aluminum Hermetic
Source Files 1,C:\Users\yargerlab\Desktop\DSC Data\General\Indium(6).tri
T4P KCell,1.006051
Onset Slope,63.26126 mW/°C
[Direct Cp Calibration]
Date Applied,11/30/2022 11:04:51 AM
Description,From -79.983 °C to 298.409 °C at 10.000°C/min
Gas Type,Nitrogen
Pan Type,Tzero Aluminum Hermetic
Source Files 1,C:\Users\yargerlab\Desktop\DSC Data\General\Sapphire_Heat_Capacity_11_30_22.tri
[Rev Cp Calibration]
Date Applied,11/30/2022 1:58:51 PM
Description,From -79.996 °C to 292.812 °C at 3.000°C/min
Gas Type,Nitrogen
Pan Type,Tzero Aluminum Hermetic
Source Files 1,C:\Users\yargerlab\Desktop\DSC Data\General\Sapphire_MDSC_Calibration_11_30_22.tri
[step]
Ramp 5.00 °C/min to 80.00 °C
Time,Temperature,Heat Flow (Normalized)
min,°C,W/g
0.00,-89.99,-0.068
0.02,-89.99,-0.063
0.05,-89.99,-0.056
0.07,-89.99,-0.052
0.09,-89.95,-0.053
0.12,-89.89,-0.059
0.14,-89.81,-0.059
0.16,-89.72,-0.043
0.19,-89.63,-0.020
0.21,-89.54,-0.006
0.23,-89.44,0.004
0.26,-89.33,0.013
0.28,-89.23,0.025
0.30,-89.12,0.032
0.33,-89.01,0.038
0.35,-88.90,0.043
0.37,-88.79,0.047
0.40,-88.68,0.050
0.42,-88.56,0.053
0.44,-88.45,0.055
0.47,-88.34,0.056
0.49,-88.22,0.057
0.51,-88.11,0.059
0.54,-87.99,0.059
0.56,-87.88,0.060
0.58,-87.76,0.061
0.61,-87.65,0.062
0.63,-87.53,0.063
0.65,-87.42,0.063
0.68,-87.30,0.064
0.70,-87.19,0.064
0.72,-87.07,0.065
0.75,-86.96,0.065
0.77,-86.84,0.066
0.79,-86.72,0.066
0.82,-86.61,0.067
0.84,-86.49,0.067
0.86,-86.38,0.068
0.89,-86.26,0.068
0.91,-86.14,0.068
0.93,-86.03,0.069
0.96,-85.91,0.069
0.98,-85.80,0.069
1.00,-85.68,0.069
1.03,-85.56,0.070
1.05,-85.45,0.070
1.07,-85.33,0.070
1.10,-85.21,0.070
1.12,-85.10,0.071
1.14,-84.98,0.071
1.17,-84.87,0.071
1.19,-84.75,0.071
1.21,-84.63,0.071
1.24,-84.52,0.071
1.26,-84.40,0.071
1.28,-84.28,0.071
1.31,-84.17,0.072
1.33,-84.05,0.072
1.35,-83.93,0.072
1.38,-83.82,0.072
1.40,-83.70,0.072
1.42,-83.58,0.072
1.45,-83.47,0.072
1.47,-83.35,0.072
1.49,-83.23,0.072
1.52,-83.12,0.072
1.54,-83.00,0.072
1.56,-82.88,0.072
1.59,-82.77,0.072
1.61,-82.65,0.072
1.63,-82.53,0.073
1.66,-82.42,0.073
1.68,-82.30,0.072
1.70,-82.18,0.073
1.73,-82.07,0.073
1.75,-81.95,0.073
1.77,-81.83,0.073
1.80,-81.72,0.073
1.82,-81.60,0.073
1.84,-81.49,0.073
1.87,-81.37,0.073
1.89,-81.25,0.073
1.91,-81.14,0.073
1.94,-81.02,0.073
1.96,-80.90,0.073
1.98,-80.78,0.073
2.01,-80.67,0.073
2.03,-80.55,0.073
2.05,-80.43,0.073
2.08,-80.32,0.073
2.10,-80.20,0.073
2.12,-80.08,0.073
2.15,-79.97,0.073
2.17,-79.85,0.073
2.19,-79.73,0.073
2.22,-79.62,0.073
2.24,-79.50,0.073
2.26,-79.38,0.073
2.29,-79.27,0.073
2.31,-79.15,0.073
2.33,-79.03,0.073
2.36,-78.92,0.073
2.38,-78.80,0.073
2.40,-78.68,0.073
2.43,-78.57,0.073
2.45,-78.45,0.073
2.47,-78.33,0.073
2.50,-78.22,0.073
2.52,-78.10,0.073
2.54,-77.98,0.074
2.57,-77.86,0.074
2.59,-77.75,0.074
2.61,-77.63,0.074
2.64,-77.51,0.074
2.66,-77.40,0.074
2.68,-77.28,0.074
2.71,-77.17,0.074
2.73,-77.05,0.074
2.75,-76.93,0.074
2.78,-76.81,0.074
2.80,-76.70,0.074
2.82,-76.58,0.074
2.85,-76.46,0.074
2.87,-76.35,0.074
2.89,-76.23,0.074
2.92,-76.11,0.074
2.94,-76.00,0.074
2.96,-75.88,0.074
2.99,-75.76,0.074
3.01,-75.65,0.074
3.03,-75.53,0.074
3.06,-75.41,0.074
3.08,-75.30,0.074
3.10,-75.18,0.074
3.13,-75.06,0.074
3.15,-74.95,0.074
3.17,-74.83,0.074
3.20,-74.71,0.074
3.22,-74.60,0.074
3.24,-74.48,0.074
3.27,-74.36,0.074
3.29,-74.25,0.074
3.31,-74.13,0.075
3.34,-74.01,0.074
3.36,-73.90,0.074
3.38,-73.78,0.075
3.41,-73.66,0.075
3.43,-73.55,0.075
3.45,-73.43,0.075
3.48,-73.31,0.075
3.50,-73.20,0.075
3.52,-73.08,0.075
3.55,-72.96,0.075
3.57,-72.84,0.075
3.59,-72.73,0.075
3.62,-72.61,0.075
3.64,-72.50,0.075
3.66,-72.38,0.075
3.69,-72.26,0.075
3.71,-72.14,0.075
3.73,-72.03,0.075
3.76,-71.91,0.076
3.78,-71.79,0.076
3.80,-71.68,0.076
3.83,-71.56,0.076
3.85,-71.44,0.076
3.87,-71.33,0.076
3.90,-71.21,0.076
3.92,-71.09,0.076
3.94,-70.98,0.076
3.97,-70.86,0.076
3.99,-70.74,0.076
4.01,-70.63,0.076
4.04,-70.51,0.076
4.06,-70.39,0.076
4.08,-70.28,0.076
4.11,-70.16,0.076
4.13,-70.04,0.076
4.15,-69.93,0.076
4.18,-69.81,0.076
4.20,-69.69,0.076
4.22,-69.58,0.076
4.25,-69.46,0.077
4.27,-69.34,0.077
4.29,-69.23,0.077
4.32,-69.11,0.077
4.34,-68.99,0.077
4.36,-68.88,0.077
4.39,-68.76,0.077
4.41,-68.64,0.077
4.43,-68.53,0.077
4.46,-68.41,0.077
4.48,-68.29,0.077
4.50,-68.17,0.077
4.53,-68.06,0.077
4.55,-67.94,0.077
4.57,-67.82,0.077
4.60,-67.71,0.077
4.62,-67.59,0.077
4.64,-67.47,0.077
4.67,-67.36,0.077
4.69,-67.24,0.077
4.71,-67.12,0.077
4.74,-67.01,0.077
4.76,-66.89,0.078
4.78,-66.78,0.078
4.81,-66.66,0.078
4.83,-66.54,0.078
4.85,-66.42,0.078
4.88,-66.31,0.078
4.90,-66.19,0.078
4.92,-66.07,0.078
4.95,-65.96,0.078
4.97,-65.84,0.078
4.99,-65.72,0.078
5.02,-65.61,0.078
5.04,-65.49,0.078
5.06,-65.37,0.078
5.09,-65.26,0.078
5.11,-65.14,0.078
5.13,-65.02,0.078
5.16,-64.91,0.078
5.18,-64.79,0.078
5.20,-64.67,0.078
5.23,-64.56,0.078
5.25,-64.44,0.079
5.27,-64.32,0.079
5.30,-64.21,0.079
5.32,-64.09,0.079
5.34,-63.97,0.079
5.37,-63.86,0.079
5.39,-63.74,0.079
5.41,-63.62,0.079
5.44,-63.51,0.079
5.46,-63.39,0.079
5.48,-63.27,0.079
5.51,-63.16,0.079
5.53,-63.04,0.079
5.55,-62.92,0.079
5.58,-62.81,0.079
5.60,-62.69,0.079
5.62,-62.57,0.079
5.65,-62.46,0.079
5.67,-62.34,0.079
5.69,-62.22,0.079
5.72,-62.11,0.079
5.74,-61.99,0.079
5.76,-61.87,0.079
5.79,-61.76,0.079
5.81,-61.64,0.079
5.83,-61.52,0.079
5.86,-61.41,0.079
5.88,-61.29,0.079
5.90,-61.17,0.080
5.93,-61.06,0.080
5.95,-60.94,0.080
5.97,-60.82,0.080
6.00,-60.70,0.080
6.02,-60.59,0.080
6.04,-60.47,0.080
6.07,-60.35,0.080
6.09,-60.24,0.080
6.11,-60.12,0.080
6.14,-60.00,0.080
6.16,-59.89,0.080
6.18,-59.77,0.080
6.21,-59.65,0.080
6.23,-59.54,0.080
6.25,-59.42,0.080
6.28,-59.30,0.080
6.30,-59.19,0.080
6.32,-59.07,0.080
6.35,-58.96,0.080
6.37,-58.84,0.080
6.39,-58.72,0.080
6.42,-58.60,0.080
6.44,-58.49,0.080
6.46,-58.37,0.080
6.49,-58.25,0.080
6.51,-58.14,0.080
6.53,-58.02,0.081
6.56,-57.90,0.080
6.58,-57.79,0.081
6.60,-57.67,0.081
6.63,-57.56,0.081
6.65,-57.44,0.081
6.67,-57.32,0.081
6.70,-57.20,0.081
6.72,-57.09,0.081
6.74,-56.97,0.081
6.77,-56.85,0.081
6.79,-56.74,0.081
6.81,-56.62,0.081
6.84,-56.50,0.081
6.86,-56.39,0.081
6.88,-56.27,0.081
6.91,-56.15,0.081
6.93,-56.04,0.081
6.95,-55.92,0.081
6.98,-55.80,0.081
7.00,-55.69,0.081
7.02,-55.57,0.081
7.05,-55.45,0.081
7.07,-55.34,0.081
7.09,-55.22,0.082
7.12,-55.11,0.081
7.14,-54.99,0.082
7.16,-54.87,0.082
7.19,-54.76,0.082
7.21,-54.64,0.081
7.23,-54.52,0.082
7.26,-54.41,0.082
7.28,-54.29,0.082
7.30,-54.17,0.082
7.33,-54.06,0.082
7.35,-53.94,0.082
7.37,-53.83,0.082
7.40,-53.71,0.082
7.42,-53.59,0.082
7.44,-53.48,0.082
7.47,-53.36,0.082
7.49,-53.24,0.082
7.51,-53.13,0.082
7.54,-53.01,0.082
7.56,-52.89,0.082
7.58,-52.78,0.082
7.61,-52.66,0.082
7.63,-52.54,0.082
7.65,-52.42,0.082
7.68,-52.31,0.082
7.70,-52.19,0.082
7.72,-52.07,0.082
7.75,-51.96,0.082
7.77,-51.84,0.082
7.79,-51.72,0.083
7.82,-51.61,0.083
7.84,-51.49,0.083
7.86,-51.37,0.083
7.89,-51.26,0.083
7.91,-51.14,0.083
7.93,-51.02,0.083
7.96,-50.91,0.083
7.98,-50.79,0.083
8.00,-50.67,0.083
8.03,-50.56,0.083
8.05,-50.44,0.083
8.07,-50.32,0.083
8.10,-50.21,0.083
8.12,-50.09,0.083
8.14,-49.97,0.083
8.17,-49.86,0.083
8.19,-49.74,0.083
8.21,-49.62,0.083
8.24,-49.51,0.083
8.26,-49.39,0.083
8.28,-49.27,0.083
8.31,-49.16,0.083
8.33,-49.04,0.083
8.35,-48.92,0.083
8.38,-48.81,0.083
8.40,-48.69,0.083
8.42,-48.57,0.083
8.45,-48.46,0.083
8.47,-48.34,0.083
8.49,-48.22,0.083
8.52,-48.11,0.083
8.54,-47.99,0.083
8.56,-47.87,0.083
8.59,-47.76,0.083
8.61,-47.64,0.083
8.63,-47.52,0.083
8.66,-47.41,0.083
8.68,-47.29,0.084
8.70,-47.17,0.083
8.73,-47.06,0.083
8.75,-46.94,0.084
8.77,-46.82,0.084
8.80,-46.71,0.084
8.82,-46.59,0.084
8.84,-46.47,0.084
8.87,-46.36,0.084
8.89,-46.24,0.084
8.91,-46.12,0.084
8.94,-46.01,0.084
8.96,-45.89,0.084
8.98,-45.77,0.084
9.01,-45.66,0.084
9.03,-45.54,0.084
9.05,-45.42,0.084
9.08,-45.31,0.084
9.10,-45.19,0.084
9.12,-45.07,0.084
9.15,-44.96,0.084
9.17,-44.84,0.084
9.19,-44.72,0.084
9.22,-44.61,0.084
9.24,-44.49,0.084
9.26,-44.37,0.084
9.29,-44.25,0.084
9.31,-44.14,0.084
9.33,-44.02,0.084
9.36,-43.91,0.084
9.38,-43.79,0.084
9.40,-43.67,0.084
9.43,-43.56,0.084
9.45,-43.44,0.084
9.47,-43.32,0.084
9.50,-43.21,0.084
9.52,-43.09,0.084
9.54,-42.97,0.084
9.57,-42.86,0.084
9.59,-42.74,0.084
9.61,-42.62,0.084
9.64,-42.51,0.084
9.66,-42.39,0.084
9.68,-42.27,0.084
9.71,-42.16,0.084
9.73,-42.04,0.084
9.75,-41.92,0.084
9.78,-41.81,0.084
9.80,-41.69,0.085
9.82,-41.57,0.085
9.85,-41.45,0.085
9.87,-41.34,0.085
9.89,-41.22,0.085
9.92,-41.10,0.085
9.94,-40.99,0.085
9.96,-40.87,0.085
9.99,-40.75,0.085
10.01,-40.64,0.085
10.03,-40.52,0.085
10.06,-40.40,0.085
10.08,-40.29,0.085
10.10,-40.17,0.085
10.13,-40.05,0.085
10.15,-39.94,0.085
10.17,-39.82,0.085
10.20,-39.70,0.085
10.22,-39.59,0.085
10.24,-39.47,0.085
10.27,-39.35,0.085
10.29,-39.23,0.085
10.31,-39.12,0.085
10.34,-39.00,0.085
10.36,-38.88,0.085
10.38,-38.76,0.085
10.41,-38.64,0.085
10.43,-38.53,0.085
10.45,-38.41,0.085
10.48,-38.29,0.085
10.50,-38.17,0.085
10.52,-38.06,0.085
10.55,-37.94,0.086
10.57,-37.82,0.086
10.59,-37.71,0.086
10.62,-37.59,0.086
10.64,-37.48,0.086
10.66,-37.36,0.086
10.69,-37.25,0.085
10.71,-37.14,0.085
10.73,-37.02,0.085
10.76,-36.90,0.085
10.78,-36.79,0.085
10.80,-36.67,0.084
10.83,-36.55,0.084
10.85,-36.44,0.084
10.87,-36.32,0.084
10.90,-36.20,0.084
10.92,-36.08,0.084
10.94,-35.96,0.084
10.97,-35.85,0.084
10.99,-35.73,0.084
11.01,-35.61,0.085
11.04,-35.49,0.085
11.06,-35.37,0.085
11.08,-35.25,0.085
11.11,-35.14,0.085
11.13,-35.02,0.086
11.15,-34.91,0.086
11.18,-34.79,0.086
11.20,-34.67,0.086
11.22,-34.56,0.086
11.25,-34.44,0.086
11.27,-34.33,0.085
11.29,-34.21,0.085
11.32,-34.09,0.085
11.34,-33.98,0.085
11.36,-33.86,0.085
11.39,-33.75,0.085
11.41,-33.63,0.085
11.43,-33.51,0.085
11.46,-33.39,0.085
11.48,-33.28,0.085
11.50,-33.16,0.085
11.53,-33.04,0.085
11.55,-32.92,0.085
11.57,-32.81,0.085
11.60,-32.69,0.085
11.62,-32.57,0.085
11.64,-32.46,0.085
11.67,-32.34,0.085
11.69,-32.22,0.085
11.71,-32.11,0.085
11.74,-31.99,0.085
11.76,-31.87,0.085
11.78,-31.76,0.085
11.81,-31.64,0.085
11.83,-31.52,0.085
11.85,-31.41,0.085
11.88,-31.29,0.085
11.90,-31.17,0.085
11.92,-31.06,0.086
11.95,-30.94,0.086
11.97,-30.82,0.086
11.99,-30.71,0.085
12.02,-30.59,0.086
12.04,-30.47,0.086
12.06,-30.35,0.086
12.09,-30.24,0.086
12.11,-30.12,0.086
12.13,-30.00,0.086
12.16,-29.89,0.086
12.18,-29.77,0.086
12.20,-29.65,0.086
12.23,-29.54,0.086
12.25,-29.42,0.086
12.27,-29.30,0.086
12.30,-29.19,0.086
12.32,-29.07,0.086
12.34,-28.95,0.086
12.37,-28.84,0.086
12.39,-28.72,0.086
12.41,-28.61,0.086
12.44,-28.49,0.086
12.46,-28.37,0.086
12.48,-28.25,0.086
12.51,-28.14,0.086
12.53,-28.02,0.086
12.55,-27.91,0.086
12.58,-27.79,0.086
12.60,-27.67,0.086
12.62,-27.56,0.086
12.65,-27.44,0.086
12.67,-27.32,0.086
12.69,-27.21,0.086
12.72,-27.09,0.086
12.74,-26.97,0.086
12.76,-26.86,0.086
12.79,-26.74,0.086
12.81,-26.62,0.086
12.83,-26.51,0.086
12.86,-26.39,0.086
12.88,-26.27,0.086
12.90,-26.15,0.086
12.93,-26.04,0.086
12.95,-25.92,0.086
12.97,-25.80,0.086
13.00,-25.69,0.086
13.02,-25.57,0.086
13.04,-25.45,0.086
13.07,-25.34,0.086
13.09,-25.22,0.086
13.11,-25.10,0.086
13.14,-24.99,0.086
13.16,-24.87,0.086
13.18,-24.76,0.086
13.21,-24.64,0.086
13.23,-24.52,0.086
13.25,-24.40,0.086
13.28,-24.29,0.086
13.30,-24.17,0.086
13.32,-24.05,0.087
13.35,-23.94,0.087
13.37,-23.82,0.087
13.39,-23.70,0.087
13.42,-23.58,0.087
13.44,-23.47,0.087
13.46,-23.35,0.087
13.49,-23.23,0.087
13.51,-23.12,0.087
13.53,-23.00,0.087
13.56,-22.88,0.087
13.58,-22.77,0.087
13.60,-22.65,0.087
13.63,-22.53,0.087
13.65,-22.42,0.087
13.67,-22.30,0.087
13.70,-22.18,0.087
13.72,-22.06,0.087
13.74,-21.95,0.087
13.77,-21.83,0.087
13.79,-21.71,0.087
13.81,-21.60,0.087
13.84,-21.48,0.087
13.86,-21.36,0.087
13.88,-21.25,0.087
13.91,-21.13,0.087
13.93,-21.01,0.087
13.95,-20.90,0.087
13.98,-20.78,0.087
14.00,-20.66,0.087
14.02,-20.55,0.087
14.05,-20.43,0.087
14.07,-20.31,0.087
14.09,-20.20,0.087
14.12,-20.08,0.087
14.14,-19.96,0.087
14.16,-19.85,0.087
14.19,-19.73,0.087
14.21,-19.61,0.087
14.23,-19.49,0.087
14.26,-19.38,0.087
14.28,-19.26,0.087
14.30,-19.14,0.087
14.33,-19.03,0.087
14.35,-18.91,0.087
14.37,-18.79,0.088
14.40,-18.68,0.088
14.42,-18.56,0.088
14.44,-18.45,0.087
14.47,-18.33,0.087
14.49,-18.21,0.087
14.51,-18.09,0.087
14.54,-17.98,0.087
14.56,-17.86,0.087
14.58,-17.74,0.087
14.61,-17.63,0.087
14.63,-17.51,0.087
14.65,-17.39,0.087
14.68,-17.28,0.087
14.70,-17.16,0.087
14.72,-17.04,0.087
14.75,-16.93,0.088
14.77,-16.81,0.088
14.79,-16.69,0.088
14.82,-16.58,0.088
14.84,-16.46,0.088
14.86,-16.34,0.088
14.89,-16.23,0.088
14.91,-16.11,0.088
14.93,-15.99,0.088
14.96,-15.88,0.088
14.98,-15.76,0.088
15.00,-15.64,0.088
15.03,-15.53,0.088
15.05,-15.41,0.088
15.07,-15.29,0.088
15.10,-15.17,0.088
15.12,-15.06,0.088
15.14,-14.94,0.088
15.17,-14.82,0.088
15.19,-14.71,0.088
15.21,-14.59,0.088
15.24,-14.47,0.088
15.26,-14.36,0.088
15.28,-14.24,0.088
15.31,-14.12,0.088
15.33,-14.00,0.088
15.35,-13.89,0.088
15.38,-13.77,0.088
15.40,-13.65,0.088
15.42,-13.54,0.088
15.45,-13.42,0.088
15.47,-13.30,0.088
15.49,-13.19,0.088
15.52,-13.07,0.088
15.54,-12.95,0.088
15.56,-12.84,0.088
15.59,-12.72,0.088
15.61,-12.60,0.088
15.63,-12.49,0.088
15.66,-12.37,0.088
15.68,-12.25,0.088
15.70,-12.14,0.088
15.73,-12.02,0.088
15.75,-11.90,0.088
15.77,-11.79,0.088
15.80,-11.67,0.088
15.82,-11.55,0.088
15.84,-11.44,0.088
15.87,-11.32,0.088
15.89,-11.20,0.088
15.91,-11.09,0.088
15.94,-10.97,0.088
15.96,-10.85,0.088
15.98,-10.74,0.088
16.01,-10.62,0.088
16.03,-10.50,0.088
16.05,-10.39,0.088
16.08,-10.27,0.089
16.10,-10.15,0.089
16.12,-10.04,0.089
16.15,-9.92,0.089
16.17,-9.80,0.089
16.19,-9.69,0.089
16.22,-9.57,0.089
16.24,-9.45,0.089
16.26,-9.34,0.089
16.29,-9.22,0.089
16.31,-9.10,0.089
16.33,-8.98,0.089
16.36,-8.87,0.089
16.38,-8.75,0.089
16.40,-8.63,0.089
16.43,-8.52,0.089
16.45,-8.40,0.089
16.47,-8.28,0.089
16.50,-8.17,0.089
16.52,-8.05,0.089
16.54,-7.93,0.089
16.57,-7.82,0.089
16.59,-7.70,0.089
16.61,-7.58,0.089
16.64,-7.47,0.089
16.66,-7.35,0.089
16.68,-7.23,0.089
16.71,-7.12,0.089
16.73,-7.00,0.089
16.75,-6.88,0.089
16.78,-6.77,0.089
16.80,-6.65,0.089
16.82,-6.53,0.089
16.85,-6.42,0.089
16.87,-6.30,0.089
16.89,-6.18,0.089
16.92,-6.07,0.089
16.94,-5.95,0.090
16.96,-5.83,0.090
16.99,-5.71,0.090
17.01,-5.60,0.090
17.03,-5.48,0.090
17.06,-5.37,0.090
17.08,-5.25,0.090
17.10,-5.13,0.090
17.13,-5.01,0.090
17.15,-4.90,0.090
17.17,-4.78,0.090
17.20,-4.67,0.090
17.22,-4.55,0.090
17.24,-4.43,0.090
17.27,-4.31,0.090
17.29,-4.20,0.090
17.31,-4.08,0.090
17.34,-3.96,0.090
17.36,-3.85,0.090
17.38,-3.73,0.090
17.41,-3.61,0.090
17.43,-3.50,0.090
17.45,-3.38,0.090
17.48,-3.26,0.090
17.50,-3.15,0.090
17.52,-3.03,0.090
17.55,-2.91,0.090
17.57,-2.80,0.090
17.59,-2.68,0.090
17.62,-2.56,0.090
17.64,-2.45,0.090
17.66,-2.33,0.090
17.69,-2.21,0.090
17.71,-2.10,0.090
17.73,-1.98,0.090
17.76,-1.86,0.090
17.78,-1.74,0.090
17.80,-1.63,0.090
17.83,-1.51,0.090
17.85,-1.39,0.091
17.87,-1.28,0.091
17.90,-1.16,0.091
17.92,-1.04,0.091
17.94,-0.93,0.091
17.97,-0.81,0.091
17.99,-0.70,0.091
18.01,-0.58,0.091
18.04,-0.46,0.091
18.06,-0.34,0.091
18.08,-0.23,0.091
18.11,-0.11,0.091
18.13,0.01,0.091
18.15,0.12,0.091
18.18,0.24,0.091
18.20,0.36,0.091
18.22,0.47,0.091
18.25,0.59,0.091
18.27,0.71,0.091
18.29,0.82,0.091
18.32,0.94,0.091
18.34,1.06,0.091
18.36,1.17,0.091
18.39,1.29,0.091
18.41,1.41,0.091
18.43,1.52,0.091
18.46,1.64,0.091
18.48,1.76,0.091
18.50,1.87,0.091
18.53,1.99,0.091
18.55,2.11,0.091
18.57,2.23,0.091
18.60,2.34,0.091
18.62,2.46,0.092
18.64,2.58,0.092
18.67,2.69,0.092
18.69,2.81,0.092
18.71,2.92,0.092
18.74,3.04,0.092
18.76,3.16,0.092
18.78,3.28,0.092
18.81,3.39,0.092
18.83,3.51,0.092
18.85,3.63,0.092
18.88,3.74,0.092
18.90,3.86,0.092
18.92,3.98,0.092
18.95,4.09,0.092
18.97,4.21,0.092
18.99,4.33,0.092
19.02,4.44,0.092
19.04,4.56,0.092
19.06,4.68,0.092
19.09,4.79,0.092
19.11,4.91,0.092
19.13,5.03,0.092
19.16,5.14,0.092
19.18,5.26,0.092
19.20,5.38,0.092
19.23,5.49,0.092
19.25,5.61,0.092
19.27,5.73,0.092
19.30,5.84,0.092
19.32,5.96,0.092
19.34,6.08,0.092
19.37,6.20,0.092
19.39,6.31,0.092
19.41,6.43,0.092
19.44,6.55,0.093
19.46,6.66,0.092
19.48,6.78,0.093
19.51,6.90,0.093
19.53,7.01,0.093
19.55,7.13,0.093
19.58,7.25,0.093
19.60,7.36,0.093
19.62,7.48,0.093
19.65,7.60,0.093
19.67,7.71,0.093
19.69,7.83,0.093
19.72,7.95,0.093
19.74,8.06,0.093
19.76,8.18,0.093
19.79,8.30,0.093
19.81,8.41,0.093
19.83,8.53,0.093
19.86,8.65,0.093
19.88,8.77,0.093
19.90,8.88,0.093
19.93,9.00,0.093
19.95,9.11,0.093
19.97,9.23,0.093
20.00,9.35,0.093
20.02,9.47,0.093
20.04,9.58,0.093
20.07,9.70,0.093
20.09,9.82,0.094
20.11,9.93,0.094
20.14,10.05,0.094
20.16,10.17,0.094
20.18,10.28,0.094
20.21,10.40,0.094
20.23,10.52,0.094
20.25,10.63,0.094
20.28,10.75,0.094
20.30,10.87,0.094
20.32,10.98,0.094
20.35,11.10,0.094
20.37,11.22,0.094
20.39,11.33,0.094
20.42,11.45,0.094
20.44,11.57,0.094
20.46,11.68,0.094
20.49,11.80,0.094
20.51,11.92,0.094
20.53,12.03,0.094
20.56,12.15,0.094
20.58,12.27,0.094
20.60,12.38,0.094
20.63,12.50,0.094
20.65,12.62,0.094
20.67,12.73,0.095
20.70,12.85,0.095
20.72,12.97,0.095
20.74,13.08,0.095
20.77,13.20,0.095
20.79,13.32,0.095
20.81,13.44,0.095
20.84,13.55,0.095
20.86,13.67,0.095
20.88,13.79,0.095
20.91,13.90,0.095
20.93,14.02,0.095
20.95,14.14,0.095
20.98,14.25,0.095
21.00,14.37,0.095
21.02,14.49,0.095
21.05,14.60,0.095
21.07,14.72,0.095
21.09,14.84,0.095
21.12,14.95,0.095
21.14,15.07,0.095
21.16,15.19,0.095
21.19,15.30,0.096
21.21,15.42,0.096
21.23,15.54,0.096
21.26,15.65,0.096
21.28,15.77,0.096
21.30,15.89,0.096
21.33,16.00,0.096
21.35,16.12,0.096
21.37,16.24,0.096
21.40,16.36,0.096
21.42,16.47,0.096
21.44,16.59,0.096
21.47,16.70,0.096
21.49,16.82,0.096
21.51,16.94,0.096
21.54,17.05,0.096
21.56,17.17,0.096
21.58,17.29,0.096
21.61,17.40,0.096
21.63,17.52,0.096
21.65,17.64,0.096
21.68,17.76,0.096
21.70,17.87,0.096
21.72,17.99,0.097
21.75,18.11,0.097
21.77,18.22,0.097
21.79,18.34,0.097
21.82,18.46,0.097
21.84,18.57,0.097
21.86,18.69,0.097
21.89,18.81,0.097
21.91,18.92,0.097
21.93,19.04,0.097
21.96,19.16,0.097
21.98,19.28,0.097
22.00,19.39,0.097
22.03,19.51,0.097
22.05,19.62,0.097
22.07,19.74,0.097
22.10,19.86,0.097
22.12,19.97,0.097
22.14,20.09,0.097
22.17,20.21,0.097
22.19,20.32,0.098
22.21,20.44,0.098
22.24,20.56,0.098
22.26,20.67,0.098
22.28,20.79,0.098
22.31,20.91,0.098
22.33,21.02,0.098
22.35,21.14,0.098
22.38,21.26,0.098
22.40,21.37,0.098
22.42,21.49,0.098
22.45,21.61,0.098
22.47,21.73,0.098
22.49,21.84,0.098
22.52,21.96,0.098
22.54,22.08,0.098
22.56,22.19,0.098
22.59,22.31,0.098
22.61,22.43,0.098
22.63,22.54,0.098
22.66,22.66,0.098
22.68,22.78,0.099
22.70,22.89,0.099
22.73,23.01,0.099
22.75,23.13,0.099
22.77,23.24,0.099
22.80,23.36,0.099
22.82,23.48,0.099
22.84,23.59,0.099
22.87,23.71,0.099
22.89,23.83,0.099
22.91,23.94,0.099
22.94,24.06,0.099
22.96,24.18,0.099
22.98,24.29,0.099
23.01,24.41,0.099
23.03,24.53,0.100
23.05,24.64,0.100
23.08,24.76,0.100
23.10,24.88,0.100
23.12,24.99,0.100
23.15,25.11,0.100
23.17,25.23,0.100
23.19,25.34,0.100
23.22,25.46,0.100
23.24,25.58,0.100
23.26,25.70,0.100
23.29,25.81,0.100
23.31,25.93,0.100
23.33,26.05,0.101
23.36,26.16,0.101
23.38,26.28,0.101
23.40,26.39,0.101
23.43,26.51,0.101
23.45,26.63,0.101
23.47,26.75,0.101
23.50,26.86,0.101
23.52,26.98,0.101
23.54,27.10,0.101
23.57,27.21,0.101
23.59,27.33,0.101
23.61,27.45,0.101
23.64,27.56,0.101
23.66,27.68,0.102
23.68,27.80,0.102
23.71,27.91,0.102
23.73,28.03,0.102
23.75,28.15,0.102
23.78,28.26,0.102
23.80,28.38,0.102
23.82,28.50,0.102
23.85,28.61,0.102
23.87,28.73,0.102
23.89,28.85,0.102
23.92,28.96,0.102
23.94,29.08,0.102
23.96,29.20,0.102
23.99,29.31,0.102
24.01,29.43,0.102
24.03,29.55,0.103
24.06,29.66,0.103
24.08,29.78,0.103
24.10,29.90,0.103
24.13,30.01,0.103
24.15,30.13,0.103
24.17,30.25,0.103
24.20,30.36,0.103
24.22,30.48,0.103
24.24,30.60,0.103
24.27,30.71,0.103
24.29,30.83,0.104
24.31,30.95,0.104
24.34,31.07,0.104
24.36,31.18,0.104
24.38,31.30,0.104
24.41,31.42,0.104
24.43,31.53,0.104
24.45,31.65,0.105
24.48,31.77,0.105
24.50,31.88,0.105
24.52,32.00,0.105
24.55,32.12,0.105
24.57,32.23,0.105
24.59,32.35,0.105
24.62,32.47,0.106
24.64,32.58,0.106
24.66,32.70,0.106
24.69,32.82,0.106
24.71,32.93,0.106
24.73,33.05,0.107
24.76,33.17,0.107
24.78,33.28,0.107
24.80,33.40,0.107
24.83,33.52,0.107
24.85,33.63,0.107
24.87,33.75,0.108
24.90,33.87,0.108
24.92,33.98,0.108
24.94,34.10,0.108
24.97,34.22,0.108
24.99,34.33,0.108
25.01,34.45,0.109
25.04,34.57,0.109
25.06,34.68,0.109
25.08,34.80,0.109
25.11,34.92,0.109
25.13,35.04,0.109
25.15,35.15,0.109
25.18,35.27,0.110
25.20,35.38,0.110
25.22,35.50,0.110
25.25,35.62,0.110
25.27,35.73,0.110
25.29,35.85,0.110
25.32,35.97,0.111
25.34,36.08,0.111
25.36,36.20,0.111
25.39,36.32,0.111
25.41,36.44,0.111
25.43,36.55,0.112
25.46,36.67,0.112
25.48,36.78,0.112
25.50,36.90,0.112
25.53,37.02,0.112
25.55,37.14,0.112
25.57,37.25,0.113
25.60,37.37,0.113
25.62,37.49,0.113
25.64,37.60,0.113
25.67,37.72,0.113
25.69,37.84,0.113
25.71,37.95,0.114
25.74,38.07,0.114
25.76,38.19,0.114
25.78,38.30,0.114
25.81,38.42,0.114
25.83,38.54,0.115
25.85,38.65,0.115
25.88,38.77,0.115
25.90,38.89,0.116
25.92,39.00,0.116
25.95,39.12,0.116
25.97,39.24,0.116
25.99,39.35,0.117
26.02,39.47,0.117
26.04,39.59,0.117
26.06,39.70,0.117
26.09,39.82,0.118
26.11,39.94,0.118
26.13,40.05,0.118
26.16,40.17,0.119
26.18,40.29,0.119
26.20,40.40,0.119
26.23,40.52,0.120
26.25,40.64,0.120
26.27,40.75,0.120
26.30,40.87,0.121
26.32,40.99,0.121
26.34,41.10,0.122
26.37,41.22,0.122
26.39,41.34,0.122
26.41,41.45,0.123
26.44,41.57,0.123
26.46,41.69,0.124
26.48,41.80,0.124
26.51,41.92,0.125
26.53,42.04,0.125
26.55,42.15,0.126
26.58,42.27,0.126
26.60,42.39,0.127
26.62,42.50,0.127
26.65,42.62,0.128
26.67,42.74,0.128
26.69,42.85,0.129
26.72,42.97,0.130
26.74,43.09,0.130
26.76,43.20,0.131
26.79,43.32,0.132
26.81,43.43,0.133
26.83,43.55,0.133
26.86,43.67,0.134
26.88,43.78,0.135
26.90,43.90,0.136
26.93,44.02,0.137
26.95,44.13,0.137
26.97,44.25,0.139
27.00,44.37,0.139
27.02,44.48,0.140
27.04,44.60,0.142
27.07,44.72,0.143
27.09,44.83,0.144
27.11,44.95,0.145
27.14,45.07,0.147
27.16,45.18,0.148
27.18,45.30,0.150
27.21,45.41,0.152
27.23,45.53,0.154
27.25,45.65,0.156
27.28,45.76,0.159
27.30,45.88,0.162
27.32,46.00,0.165
27.35,46.11,0.167
27.37,46.23,0.171
27.39,46.34,0.174
27.42,46.46,0.178
27.44,46.58,0.181
27.46,46.69,0.185
27.49,46.81,0.190
27.51,46.92,0.195
27.53,47.04,0.200
27.56,47.16,0.205
27.58,47.27,0.210
27.60,47.39,0.216
27.63,47.50,0.222
27.65,47.62,0.229
27.67,47.73,0.236
27.70,47.85,0.243
27.72,47.96,0.252
27.74,48.08,0.258
27.77,48.19,0.268
27.79,48.31,0.278
27.81,48.42,0.288
27.84,48.54,0.299
27.86,48.65,0.312
27.88,48.76,0.324
27.91,48.88,0.339
27.93,48.99,0.355
27.95,49.10,0.372
27.98,49.22,0.391
28.00,49.33,0.412
28.02,49.44,0.434
28.05,49.55,0.459
28.07,49.67,0.484
28.09,49.78,0.514
28.12,49.89,0.546
28.14,50.00,0.581
28.16,50.10,0.620
28.19,50.21,0.663
28.21,50.32,0.710
28.23,50.42,0.759
28.26,50.53,0.816
28.28,50.63,0.879
28.30,50.74,0.945
28.33,50.84,1.019
28.35,50.94,1.098
28.37,51.04,1.183
28.40,51.13,1.275
28.42,51.23,1.371
28.44,51.32,1.477
28.47,51.42,1.587
28.49,51.51,1.706
28.51,51.60,1.823
28.54,51.69,1.960
28.56,51.77,2.088
28.58,51.86,2.229
28.61,51.94,2.373
28.63,52.03,2.522
28.65,52.11,2.671
28.68,52.19,2.823
28.70,52.27,2.975
28.72,52.36,3.126
28.75,52.44,3.271
28.77,52.52,3.406
28.79,52.61,3.517
28.82,52.70,3.603
28.84,52.79,3.638
28.86,52.90,3.593
28.89,53.03,3.406
28.91,53.19,3.023
28.93,53.39,2.451
28.96,53.61,1.858
28.98,53.84,1.410
29.00,54.06,1.096
29.03,54.25,0.865
29.05,54.43,0.691
29.07,54.60,0.561
29.10,54.75,0.462
29.12,54.90,0.387
29.14,55.04,0.327
29.17,55.17,0.285
29.19,55.30,0.252
29.21,55.43,0.225
29.24,55.55,0.206
29.26,55.67,0.192
29.28,55.79,0.180
29.31,55.91,0.172
29.33,56.03,0.167
29.35,56.15,0.161
29.38,56.27,0.158
29.40,56.39,0.155
29.42,56.51,0.154
29.45,56.63,0.153
29.47,56.74,0.152
29.49,56.86,0.151
29.52,56.98,0.150
29.54,57.09,0.150
29.56,57.21,0.149
29.59,57.33,0.149
29.61,57.44,0.149
29.63,57.56,0.148
29.66,57.68,0.148
29.68,57.79,0.147
29.70,57.91,0.147
29.73,58.03,0.147
29.75,58.15,0.146
29.77,58.26,0.146
29.80,58.38,0.146
29.82,58.49,0.146
29.84,58.61,0.146
29.87,58.73,0.145
29.89,58.85,0.145
29.91,58.96,0.145
29.94,59.08,0.145
29.96,59.20,0.145
29.98,59.31,0.145
30.01,59.43,0.145
30.03,59.55,0.145
30.05,59.66,0.145
30.08,59.78,0.145
30.10,59.90,0.144
30.12,60.01,0.144
30.15,60.13,0.144
30.17,60.25,0.144
30.19,60.36,0.144
30.22,60.48,0.144
30.24,60.60,0.144
30.26,60.71,0.144
30.29,60.83,0.144
30.31,60.95,0.144
30.33,61.06,0.144
30.36,61.18,0.144
30.38,61.30,0.144
30.40,61.41,0.144
30.43,61.53,0.144
30.45,61.65,0.144
30.47,61.76,0.144
30.50,61.88,0.144
30.52,62.00,0.144
30.54,62.11,0.144
30.57,62.23,0.144
30.59,62.35,0.144
30.61,62.46,0.144
30.64,62.58,0.144
30.66,62.70,0.144
30.68,62.81,0.144
30.71,62.93,0.144
30.73,63.05,0.144
30.75,63.17,0.144
30.78,63.28,0.144
30.80,63.40,0.144
30.82,63.52,0.144
30.85,63.63,0.144
30.87,63.75,0.144
30.89,63.87,0.144
30.92,63.98,0.144
30.94,64.10,0.144
30.96,64.22,0.144
30.99,64.33,0.144
31.01,64.45,0.145
31.03,64.57,0.145
31.06,64.68,0.145
31.08,64.80,0.145
31.10,64.92,0.145
31.13,65.03,0.145
31.15,65.15,0.145
31.17,65.27,0.145
31.20,65.38,0.145
31.22,65.50,0.145
31.24,65.62,0.145
31.27,65.73,0.145
31.29,65.85,0.145
31.31,65.97,0.145
31.34,66.08,0.145
31.36,66.20,0.145
31.38,66.32,0.145
31.41,66.43,0.145
31.43,66.55,0.145
31.45,66.67,0.145
31.48,66.79,0.145
31.50,66.90,0.145
31.52,67.02,0.145
31.55,67.14,0.145
31.57,67.25,0.145
31.59,67.37,0.145
31.62,67.49,0.145
31.64,67.60,0.145
31.66,67.72,0.145
31.69,67.84,0.145
31.71,67.95,0.145
31.73,68.07,0.145
31.76,68.18,0.145
31.78,68.30,0.145
31.80,68.42,0.145
31.83,68.54,0.145
31.85,68.65,0.145
31.87,68.77,0.145
31.90,68.89,0.145
31.92,69.00,0.146
31.94,69.12,0.146
31.97,69.24,0.146
31.99,69.35,0.146
32.01,69.47,0.146
32.04,69.59,0.146
32.06,69.70,0.146
32.08,69.82,0.146
32.11,69.94,0.146
32.13,70.05,0.146
32.15,70.17,0.146
32.18,70.29,0.146
32.20,70.40,0.146
32.22,70.52,0.146
32.25,70.64,0.146
32.27,70.75,0.146
32.29,70.87,0.146
32.32,70.99,0.146
32.34,71.10,0.146
32.36,71.22,0.146
32.39,71.34,0.146
32.41,71.45,0.146
32.43,71.57,0.146
32.46,71.69,0.146
32.48,71.80,0.146
32.50,71.92,0.146
32.53,72.04,0.146
32.55,72.15,0.146
32.57,72.27,0.146
32.60,72.39,0.146
32.62,72.50,0.146
32.64,72.62,0.146
32.67,72.74,0.146
32.69,72.86,0.146
32.71,72.97,0.146
32.74,73.09,0.146
32.76,73.20,0.146
32.78,73.32,0.146
32.81,73.44,0.146
32.83,73.55,0.146
32.85,73.67,0.146
32.88,73.79,0.146
32.90,73.91,0.146
32.92,74.02,0.146
32.95,74.14,0.146
32.97,74.26,0.146
32.99,74.37,0.146
33.02,74.49,0.146
33.04,74.61,0.146
33.06,74.72,0.147
33.09,74.84,0.147
33.11,74.96,0.147
33.13,75.07,0.147
33.16,75.19,0.147
33.18,75.31,0.147
33.20,75.42,0.147
33.23,75.54,0.147
33.25,75.66,0.147
33.27,75.77,0.147
33.30,75.89,0.147
33.32,76.01,0.147
33.34,76.12,0.147
33.37,76.24,0.147
33.39,76.36,0.147
33.41,76.47,0.147
33.44,76.59,0.147
33.46,76.71,0.147
33.48,76.82,0.147
33.51,76.94,0.147
33.53,77.06,0.147
33.55,77.17,0.147
33.58,77.29,0.147
33.60,77.41,0.147
33.62,77.52,0.147
33.65,77.64,0.147
33.67,77.76,0.147
33.69,77.88,0.147
33.72,77.99,0.147
33.74,78.11,0.147
33.76,78.22,0.147
33.79,78.34,0.147
33.81,78.46,0.147
33.83,78.58,0.147
33.86,78.69,0.147
33.88,78.81,0.147
33.90,78.92,0.147
33.93,79.04,0.147
33.95,79.16,0.147
33.97,79.28,
34.00,79.39,
34.01,,

[step]
Ramp 40.00 °C/min to -90.00 °C
Time,Temperature,Heat Flow (Normalized)
min,°C,W/g
35.01,80.13,-0.041
35.02,80.13,-0.041
35.02,80.13,-0.041
35.02,80.13,-0.041
35.03,80.13,-0.041
35.03,80.13,-0.041
35.03,80.12,-0.041
35.04,80.12,-0.041
35.04,80.12,-0.041
35.04,80.12,-0.042
35.05,80.11,-0.042
35.05,80.11,-0.042
35.05,80.10,-0.042
35.06,80.09,-0.042
35.06,80.08,-0.042
35.06,80.07,-0.042
35.07,80.06,-0.041
35.07,80.04,-0.040
35.07,80.03,-0.037
35.08,80.01,-0.032
35.08,79.98,-0.026
35.08,79.96,-0.020
35.09,79.93,-0.016
35.09,79.90,-0.014
35.09,79.86,-0.012
35.10,79.83,-0.012
35.10,79.79,-0.013
35.10,79.74,-0.014
35.11,79.70,-0.015
35.11,79.65,-0.016
35.11,79.60,-0.018
35.12,79.54,-0.030
35.12,79.48,-0.052
35.12,79.42,-0.066
35.13,79.36,-0.080
35.13,79.29,-0.095
35.13,79.22,-0.112
35.14,79.15,-0.129
35.14,79.08,-0.148
35.14,79.00,-0.169
35.15,78.92,-0.190
35.15,78.84,-0.213
35.15,78.76,-0.236
35.16,78.67,-0.260
35.16,78.58,-0.285
35.16,78.50,-0.311
35.17,78.40,-0.338
35.17,78.31,-0.365
35.17,78.21,-0.391
35.18,78.12,-0.418
35.18,78.02,-0.446
35.18,77.92,-0.473
35.19,77.81,-0.502
35.19,77.71,-0.529
35.19,77.61,-0.557
35.20,77.50,-0.585
35.20,77.39,-0.613
35.20,77.28,-0.641
35.21,77.17,-0.670
35.21,77.05,-0.696
35.21,76.94,-0.723
35.22,76.82,-0.749
35.22,76.71,-0.776
35.22,76.59,-0.801
35.23,76.47,-0.827
35.23,76.35,-0.852
35.23,76.23,-0.876
35.24,76.11,-0.900
35.24,75.98,-0.925
35.24,75.86,-0.949
35.25,75.73,-0.972
35.25,75.61,-0.995
35.25,75.48,-1.016
35.26,75.35,-1.035
35.26,75.22,-1.055
35.26,75.10,-1.076
35.27,74.97,-1.096
35.27,74.84,-1.118
35.27,74.71,-1.138
35.28,74.58,-1.158
35.28,74.45,-1.177
35.28,74.31,-1.196
35.29,74.18,-1.214
35.29,74.05,-1.231
35.29,73.92,-1.250
35.30,73.79,-1.267
35.30,73.66,-1.283
35.30,73.53,-1.299
35.31,73.40,-1.314
35.31,73.27,-1.329
35.31,73.13,-1.343
35.32,73.00,-1.354
35.32,72.87,-1.366
35.32,72.74,-1.376
35.33,72.61,-1.384
35.33,72.48,-1.394
35.33,72.35,-1.401
35.34,72.22,-1.409
35.34,72.09,-1.416
35.34,71.96,-1.422
35.35,71.83,-1.428
35.35,71.70,-1.433
35.35,71.57,-1.436
35.36,71.44,-1.439
35.36,71.31,-1.442
35.36,71.18,-1.445
35.37,71.05,-1.448
35.37,70.92,-1.453
35.37,70.79,-1.456
35.38,70.66,-1.458
35.38,70.53,-1.461
35.38,70.39,-1.464
35.39,70.26,-1.466
35.39,70.13,-1.470
35.39,70.00,-1.472
35.40,69.87,-1.475
35.40,69.74,-1.477
35.40,69.61,-1.480
35.41,69.48,-1.483
35.41,69.34,-1.486
35.41,69.21,-1.488
35.42,69.08,-1.490
35.42,68.95,-1.494
35.42,68.82,-1.495
35.43,68.69,-1.497
35.43,68.55,-1.498
35.43,68.42,-1.500
35.44,68.29,-1.502
35.44,68.16,-1.505
35.44,68.03,-1.506
35.45,67.90,-1.507
35.45,67.76,-1.507
35.45,67.63,-1.508
35.46,67.50,-1.509
35.46,67.37,-1.511
35.46,67.24,-1.511
35.47,67.11,-1.511
35.47,66.97,-1.512
35.47,66.84,-1.513
35.48,66.71,-1.515
35.48,66.58,-1.516
35.48,66.45,-1.517
35.49,66.32,-1.517
35.49,66.19,-1.517
35.49,66.05,-1.517
35.50,65.92,-1.518
35.50,65.79,-1.518
35.50,65.66,-1.519
35.51,65.53,-1.519
35.51,65.39,-1.519
35.51,65.26,-1.519
35.52,65.13,-1.520
35.52,65.00,-1.520
35.52,64.87,-1.521
35.53,64.74,-1.521
35.53,64.60,-1.522
35.53,64.47,-1.522
35.54,64.34,-1.523
35.54,64.20,-1.523
35.54,64.07,-1.523
35.55,63.94,-1.523
35.55,63.81,-1.524
35.55,63.68,-1.524
35.56,63.55,-1.524
35.56,63.41,-1.525
35.56,63.28,-1.525
35.57,63.15,-1.525
35.57,63.02,-1.525
35.57,62.89,-1.526
35.58,62.75,-1.526
35.58,62.62,-1.526
35.58,62.49,-1.526
35.59,62.36,-1.526
35.59,62.22,-1.526
35.59,62.09,-1.526
35.60,61.96,-1.526
35.60,61.83,-1.527
35.60,61.70,-1.527
35.61,61.56,-1.527
35.61,61.43,-1.527
35.61,61.30,-1.527
35.62,61.17,-1.527
35.62,61.04,-1.527
35.62,60.90,-1.527
35.63,60.77,-1.527
35.63,60.64,-1.527
35.63,60.51,-1.527
35.64,60.37,-1.527
35.64,60.24,-1.527
35.64,60.11,-1.527
35.65,59.98,-1.528
35.65,59.84,-1.528
35.65,59.71,-1.528
35.66,59.58,-1.528
35.66,59.45,-1.528
35.66,59.31,-1.528
35.67,59.18,-1.528
35.67,59.05,-1.528
35.67,58.92,-1.528
35.68,58.79,-1.528
35.68,58.65,-1.528
35.68,58.52,-1.528
35.69,58.39,-1.528
35.69,58.26,-1.528
35.69,58.12,-1.528
35.70,57.99,-1.528
35.70,57.86,-1.528
35.70,57.73,-1.528
35.71,57.59,-1.528
35.71,57.46,-1.528
35.71,57.33,-1.529
35.72,57.20,-1.529
35.72,57.06,-1.529
35.72,56.93,-1.529
35.73,56.80,-1.529
35.73,56.67,-1.529
35.73,56.53,-1.529
35.74,56.40,-1.529
35.74,56.27,-1.529
35.74,56.14,-1.529
35.75,56.00,-1.529
35.75,55.87,-1.529
35.75,55.74,-1.529
35.76,55.61,-1.529
35.76,55.47,-1.529
35.76,55.34,-1.529
35.77,55.21,-1.529
35.77,55.08,-1.529
35.77,54.94,-1.529
35.78,54.81,-1.529
35.78,54.68,-1.529
35.78,54.55,-1.529
35.79,54.41,-1.529
35.79,54.28,-1.529
35.79,54.15,-1.529
35.80,54.02,-1.529
35.80,53.88,-1.529
35.80,53.75,-1.529
35.81,53.62,-1.529
35.81,53.49,-1.529
35.81,53.35,-1.529
35.82,53.22,-1.529
35.82,53.09,-1.529
35.82,52.96,-1.529
35.83,52.82,-1.529
35.83,52.69,-1.529
35.83,52.56,-1.529
35.84,52.42,-1.529
35.84,52.29,-1.529
35.84,52.16,-1.529
35.85,52.03,-1.529
35.85,51.90,-1.529
35.85,51.76,-1.529
35.86,51.63,-1.529
35.86,51.50,-1.529
35.86,51.36,-1.529
35.87,51.23,-1.529
35.87,51.10,-1.529
35.87,50.97,-1.529
35.88,50.83,-1.528
35.88,50.70,-1.528
35.88,50.57,-1.528
35.89,50.44,-1.528
35.89,50.30,-1.528
35.89,50.17,-1.528
35.90,50.04,-1.528
35.90,49.91,-1.528
35.90,49.77,-1.528
35.91,49.64,-1.528
35.91,49.51,-1.528
35.91,49.37,-1.528
35.92,49.24,-1.528
35.92,49.11,-1.528
35.92,48.98,-1.528
35.93,48.84,-1.528
35.93,48.71,-1.527
35.93,48.58,-1.527
35.94,48.45,-1.527
35.94,48.31,-1.527
35.94,48.18,-1.527
35.95,48.05,-1.527
35.95,47.92,-1.527
35.95,47.78,-1.527
35.96,47.65,-1.527
35.96,47.52,-1.527
35.96,47.38,-1.526
35.97,47.25,-1.526
35.97,47.12,-1.526
35.97,46.99,-1.526
35.98,46.85,-1.526
35.98,46.72,-1.526
35.98,46.59,-1.526
35.99,46.46,-1.526
35.99,46.32,-1.525
35.99,46.19,-1.525
36.00,46.06,-1.525
36.00,45.92,-1.525
36.00,45.79,-1.525
36.01,45.66,-1.525
36.01,45.53,-1.525
36.01,45.39,-1.525
36.02,45.26,-1.525
36.02,45.13,-1.524
36.02,45.00,-1.524
36.03,44.86,-1.524
36.03,44.73,-1.523
36.03,44.60,-1.523
36.04,44.46,-1.523
36.04,44.33,-1.523
36.04,44.20,-1.523
36.05,44.07,-1.523
36.05,43.93,-1.523
36.05,43.80,-1.522
36.06,43.67,-1.522
36.06,43.53,-1.522
36.06,43.40,-1.522
36.07,43.27,-1.522
36.07,43.14,-1.522
36.07,43.00,-1.522
36.08,42.87,-1.522
36.08,42.74,-1.521
36.08,42.61,-1.521
36.09,42.47,-1.521
36.09,42.34,-1.521
36.09,42.21,-1.520
36.10,42.07,-1.520
36.10,41.94,-1.520
36.10,41.81,-1.520
36.11,41.68,-1.520
36.11,41.54,-1.520
36.11,41.41,-1.519
36.12,41.28,-1.519
36.12,41.15,-1.519
36.12,41.01,-1.518
36.13,40.88,-1.518
36.13,40.75,-1.518
36.13,40.62,-1.518
36.14,40.48,-1.518
36.14,40.35,-1.518
36.14,40.22,-1.518
36.15,40.09,-1.517
36.15,39.95,-1.517
36.15,39.82,-1.517
36.16,39.69,-1.517
36.16,39.55,-1.517
36.16,39.42,-1.516
36.17,39.29,-1.516
36.17,39.16,-1.516
36.17,39.02,-1.516
36.18,38.89,-1.516
36.18,38.76,-1.516
36.18,38.63,-1.515
36.19,38.50,-1.515
36.19,38.36,-1.515
36.19,38.23,-1.515
36.20,38.10,-1.514
36.20,37.97,-1.514
36.20,37.83,-1.514
36.21,37.70,-1.513
36.21,37.57,-1.513
36.21,37.44,-1.513
36.22,37.30,-1.513
36.22,37.17,-1.512
36.22,37.04,-1.512
36.23,36.91,-1.512
36.23,36.78,-1.512
36.23,36.64,-1.512
36.24,36.51,-1.511
36.24,36.38,-1.511
36.24,36.25,-1.510
36.25,36.12,-1.510
36.25,35.98,-1.510
36.25,35.85,-1.510
36.26,35.72,-1.509
36.26,35.59,-1.509
36.26,35.46,-1.509
36.27,35.32,-1.508
36.27,35.19,-1.508
36.27,35.06,-1.508
36.28,34.93,-1.508
36.28,34.80,-1.507
36.28,34.67,-1.507
36.29,34.53,-1.507
36.29,34.40,-1.506
36.29,34.27,-1.505
36.30,34.14,-1.504
36.30,34.01,-1.503
36.30,33.88,-1.502
36.31,33.75,-1.501
[...]
129.40,-13.70,0.099,1.060
129.42,-13.58,0.099,1.059
129.44,-13.46,0.099,1.060
129.47,-13.35,0.099,1.060
129.49,-13.23,0.099,1.059
129.51,-13.11,0.099,1.060
129.54,-13.00,0.099,1.059
129.56,-12.88,0.099,1.059
129.58,-12.76,0.099,1.059
129.61,-12.65,0.099,1.059
129.63,-12.53,0.100,1.059
129.65,-12.41,0.100,1.059
129.68,-12.30,0.100,1.060
129.70,-12.18,0.100,1.061
129.72,-12.06,0.100,1.063
129.75,-11.94,0.100,1.063
129.77,-11.83,0.100,1.064
129.79,-11.71,0.100,1.064
129.82,-11.60,0.100,1.064
129.84,-11.48,0.100,1.064
129.86,-11.36,0.100,1.064
129.89,-11.25,0.100,1.064
129.91,-11.13,0.100,1.065
129.93,-11.01,0.100,1.064
129.96,-10.89,0.100,1.064
129.98,-10.78,0.100,1.065
130.00,-10.66,0.100,1.065
130.03,-10.54,0.100,1.066
130.05,-10.43,0.100,1.067
130.07,-10.31,0.100,1.067
130.10,-10.19,0.100,1.067
130.12,-10.08,0.100,1.067
130.14,-9.96,0.100,1.067
130.17,-9.84,0.100,1.067
130.19,-9.73,0.100,1.067
130.21,-9.61,0.100,1.067
130.24,-9.49,0.100,1.068
130.26,-9.38,0.100,1.068
130.28,-9.26,0.100,1.068
130.31,-9.14,0.100,1.068
130.33,-9.03,0.100,1.067
130.35,-8.91,0.100,1.068
130.38,-8.79,0.100,1.069
130.40,-8.68,0.100,1.069
130.42,-8.56,0.100,1.069
130.45,-8.44,0.100,1.069
130.47,-8.33,0.100,1.069
130.49,-8.21,0.100,1.070
130.52,-8.09,0.100,1.069
130.54,-7.98,0.100,1.071
130.56,-7.86,0.100,1.071
130.59,-7.74,0.100,1.071
130.61,-7.62,0.100,1.072
130.63,-7.51,0.100,1.071
130.66,-7.39,0.100,1.072
130.68,-7.27,0.100,1.072
130.70,-7.16,0.100,1.072
130.73,-7.04,0.100,1.072
130.75,-6.92,0.100,1.071
130.77,-6.81,0.100,1.071
130.80,-6.69,0.100,1.071
130.82,-6.57,0.100,1.071
130.84,-6.46,0.100,1.072
130.87,-6.34,0.100,1.072
130.89,-6.22,0.101,1.073
130.91,-6.11,0.101,1.075
130.94,-5.99,0.101,1.074
130.96,-5.87,0.101,1.076
130.98,-5.75,0.101,1.077
131.01,-5.64,0.101,1.075
131.03,-5.52,0.101,1.076
131.05,-5.41,0.101,1.077
131.08,-5.29,0.101,1.076
131.10,-5.17,0.101,1.077
131.12,-5.06,0.101,1.076
131.15,-4.94,0.101,1.077
131.17,-4.82,0.101,1.077
131.19,-4.71,0.101,1.077
131.22,-4.59,0.101,1.077
131.24,-4.47,0.101,1.078
131.26,-4.35,0.101,1.076
131.29,-4.24,0.101,1.077
131.31,-4.12,0.101,1.078
131.33,-4.00,0.101,1.078
131.36,-3.89,0.101,1.078
131.38,-3.77,0.101,1.078
131.40,-3.66,0.101,1.078
131.43,-3.54,0.101,1.078
131.45,-3.42,0.101,1.079
131.47,-3.30,0.101,1.079
131.50,-3.19,0.101,1.079
131.52,-3.07,0.101,1.078
131.54,-2.95,0.101,1.080
131.57,-2.84,0.101,1.079
131.59,-2.72,0.101,1.080
131.61,-2.60,0.101,1.082
131.64,-2.49,0.101,1.082
131.66,-2.37,0.101,1.082
131.68,-2.25,0.101,1.082
131.71,-2.14,0.101,1.082
131.73,-2.02,0.101,1.082
131.75,-1.90,0.101,1.082
131.78,-1.79,0.101,1.083
131.80,-1.67,0.101,1.083
131.82,-1.55,0.101,1.083
131.85,-1.43,0.101,1.084
131.87,-1.32,0.101,1.084
131.89,-1.20,0.101,1.085
131.92,-1.08,0.101,1.085
131.94,-0.97,0.101,1.086
131.96,-0.85,0.101,1.086
131.99,-0.73,0.101,1.086
132.01,-0.62,0.101,1.085
132.03,-0.50,0.101,1.086
132.06,-0.38,0.101,1.086
132.08,-0.27,0.101,1.085
132.10,-0.15,0.101,1.086
132.13,-0.03,0.101,1.085
132.15,0.08,0.101,1.085
132.17,0.20,0.101,1.087
132.20,0.32,0.102,1.087
132.22,0.43,0.102,1.086
132.24,0.55,0.102,1.086
132.27,0.67,0.102,1.086
132.29,0.78,0.102,1.087
132.31,0.90,0.102,1.087
132.34,1.02,0.102,1.088
132.36,1.13,0.102,1.087
132.38,1.25,0.102,1.088
132.41,1.37,0.102,1.088
132.43,1.48,0.102,1.089
132.45,1.60,0.102,1.089
132.48,1.72,0.102,1.089
132.50,1.84,0.102,1.089
132.52,1.95,0.102,1.091
132.55,2.07,0.102,1.090
132.57,2.19,0.102,1.091
132.59,2.30,0.102,1.091
132.62,2.42,0.102,1.092
132.64,2.54,0.102,1.092
132.66,2.65,0.102,1.093
132.69,2.77,0.102,1.093
132.71,2.89,0.102,1.094
132.73,3.00,0.102,1.093
132.76,3.12,0.102,1.093
132.78,3.24,0.102,1.093
132.80,3.35,0.102,1.092
132.83,3.47,0.102,1.092
132.85,3.59,0.102,1.094
132.87,3.70,0.102,1.095
132.90,3.82,0.102,1.094
132.92,3.94,0.102,1.095
132.94,4.05,0.102,1.095
132.97,4.17,0.102,1.096
132.99,4.29,0.102,1.096
133.01,4.41,0.102,1.097
133.04,4.52,0.103,1.098
133.06,4.64,0.103,1.097
133.08,4.76,0.102,1.097
133.11,4.87,0.103,1.096
133.13,4.99,0.103,1.098
133.15,5.10,0.103,1.098
133.18,5.22,0.103,1.099
133.20,5.34,0.103,1.099
133.22,5.45,0.103,1.099
133.25,5.57,0.103,1.097
133.27,5.69,0.103,1.098
133.29,5.81,0.103,1.098
133.32,5.92,0.103,1.097
133.34,6.04,0.103,1.097
133.36,6.16,0.103,1.098
133.39,6.27,0.103,1.099
133.41,6.39,0.103,1.099
133.43,6.51,0.103,1.099
133.46,6.62,0.103,1.100
133.48,6.74,0.103,1.100
133.50,6.86,0.103,1.102
133.53,6.97,0.103,1.102
133.55,7.09,0.103,1.104
133.57,7.21,0.103,1.104
133.60,7.32,0.103,1.104
133.62,7.44,0.103,1.105
133.64,7.56,0.103,1.104
133.67,7.67,0.103,1.105
133.69,7.79,0.103,1.105
133.71,7.91,0.103,1.105
133.74,8.02,0.103,1.105
133.76,8.14,0.103,1.104
133.78,8.26,0.103,1.106
133.81,8.37,0.103,1.106
133.83,8.49,0.104,1.107
133.85,8.61,0.104,1.107
133.88,8.72,0.104,1.108
133.90,8.84,0.104,1.108
133.92,8.96,0.104,1.109
133.95,9.07,0.104,1.109
133.97,9.19,0.104,1.109
133.99,9.31,0.104,1.110
134.02,9.43,0.104,1.110
134.04,9.54,0.104,1.112
134.06,9.66,0.104,1.111
134.09,9.78,0.104,1.111
134.11,9.89,0.104,1.111
134.13,10.01,0.104,1.112
134.16,10.13,0.104,1.112
134.18,10.24,0.104,1.113
134.20,10.36,0.104,1.114
134.23,10.48,0.104,1.114
134.25,10.59,0.104,1.113
134.27,10.71,0.104,1.114
134.30,10.83,0.104,1.116
134.32,10.94,0.104,1.115
134.34,11.06,0.104,1.115
134.37,11.18,0.104,1.116
134.39,11.29,0.104,1.116
134.41,11.41,0.104,1.115
134.44,11.53,0.104,1.116
134.46,11.64,0.104,1.117
134.48,11.76,0.104,1.117
134.51,11.88,0.104,1.117
134.53,11.99,0.104,1.117
134.55,12.11,0.105,1.117
134.58,12.23,0.105,1.117
134.60,12.34,0.105,1.119
134.62,12.46,0.105,1.120
134.65,12.58,0.105,1.119
134.67,12.69,0.105,1.119
134.69,12.81,0.105,1.120
134.72,12.93,0.105,1.122
134.74,13.05,0.105,1.122
134.76,13.16,0.105,1.122
134.79,13.28,0.105,1.123
134.81,13.40,0.105,1.124
134.83,13.51,0.105,1.124
134.86,13.63,0.105,1.126
134.88,13.75,0.105,1.126
134.90,13.86,0.105,1.126
134.93,13.98,0.105,1.126
134.95,14.10,0.105,1.126
134.97,14.21,0.105,1.126
135.00,14.33,0.105,1.127
135.02,14.45,0.105,1.127
135.04,14.56,0.106,1.128
135.07,14.68,0.106,1.129
135.09,14.80,0.106,1.129
135.11,14.91,0.106,1.130
135.14,15.03,0.106,1.131
135.16,15.15,0.106,1.132
135.18,15.26,0.106,1.133
135.21,15.38,0.106,1.133
135.23,15.50,0.106,1.135
135.25,15.61,0.106,1.137
135.28,15.73,0.106,1.137
135.30,15.85,0.106,1.138
135.32,15.96,0.106,1.138
135.35,16.08,0.107,1.139
135.37,16.20,0.107,1.138
135.39,16.31,0.107,1.139
135.42,16.43,0.107,1.140
135.44,16.55,0.107,1.140
135.46,16.67,0.107,1.142
135.49,16.78,0.107,1.142
135.51,16.90,0.107,1.143
135.53,17.02,0.107,1.145
135.56,17.13,0.107,1.145
135.58,17.25,0.107,1.147
135.60,17.37,0.107,1.146
135.63,17.48,0.107,1.147
135.65,17.60,0.107,1.148
135.67,17.72,0.107,1.149
135.70,17.83,0.107,1.150
135.72,17.95,0.108,1.152
135.74,18.07,0.108,1.152
135.77,18.18,0.108,1.152
135.79,18.30,0.108,1.153
135.81,18.42,0.108,1.154
135.84,18.53,0.108,1.154
135.86,18.65,0.108,1.155
135.88,18.77,0.108,1.157
135.91,18.88,0.108,1.158
135.93,19.00,0.108,1.160
135.95,19.12,0.109,1.161
135.98,19.23,0.109,1.164
136.00,19.35,0.109,1.164
136.02,19.47,0.109,1.168
136.05,19.58,0.109,1.167
136.07,19.70,0.109,1.168
136.09,19.82,0.109,1.170
136.12,19.93,0.109,1.171
136.14,20.05,0.110,1.172
136.16,20.17,0.110,1.172
136.19,20.28,0.110,1.172
136.21,20.40,0.110,1.175
136.23,20.52,0.110,1.176
136.26,20.64,0.110,1.179
136.28,20.75,0.110,1.181
136.30,20.87,0.110,1.182
136.33,20.98,0.110,1.183
136.35,21.10,0.111,1.183
136.37,21.22,0.111,1.184
136.40,21.33,0.111,1.186
136.42,21.45,0.111,1.187
136.44,21.57,0.111,1.190
136.47,21.68,0.111,1.191
136.49,21.80,0.111,1.193
136.51,21.92,0.112,1.194
136.54,22.03,0.112,1.195
136.56,22.15,0.112,1.197
136.58,22.27,0.112,1.199
136.61,22.39,0.112,1.201
136.63,22.50,0.112,1.202
136.65,22.62,0.113,1.204
136.68,22.74,0.113,1.206
136.70,22.85,0.113,1.207
136.72,22.97,0.113,1.210
136.75,23.09,0.113,1.211
136.77,23.20,0.113,1.214
136.79,23.32,0.114,1.214
136.82,23.44,0.114,1.218
136.84,23.55,0.114,1.219
136.86,23.67,0.114,1.221
136.89,23.79,0.114,1.224
136.91,23.90,0.115,1.226
136.93,24.02,0.115,1.227
136.96,24.14,0.115,1.230
136.98,24.25,0.115,1.231
137.00,24.37,0.115,1.234
137.03,24.49,0.116,1.237
137.05,24.60,0.116,1.240
137.07,24.72,0.116,1.242
137.10,24.84,0.116,1.243
137.12,24.95,0.116,1.246
137.14,25.07,0.117,1.248
137.17,25.19,0.117,1.250
137.19,25.30,0.117,1.253
137.21,25.42,0.117,1.255
137.24,25.54,0.118,1.258
137.26,25.65,0.118,1.261
137.28,25.77,0.118,1.264
137.31,25.89,0.119,1.266
137.33,26.00,0.119,1.270
137.35,26.12,0.119,1.275
137.38,26.24,0.120,1.279
137.40,26.35,0.120,1.282
137.42,26.47,0.120,1.286
137.45,26.59,0.121,1.290
137.47,26.70,0.121,1.295
137.49,26.82,0.121,1.299
137.52,26.94,0.122,1.303
137.54,27.05,0.122,1.308
137.56,27.17,0.123,1.313
137.59,27.29,0.123,1.316
137.61,27.40,0.123,1.322
137.63,27.52,0.124,1.327
137.66,27.64,0.124,1.332
137.68,27.75,0.125,1.338
137.70,27.87,0.125,1.344
137.73,27.99,0.126,1.350
137.75,28.10,0.127,1.356
137.77,28.22,0.127,1.362
137.80,28.34,0.128,1.370
137.82,28.45,0.129,1.377
137.84,28.57,0.129,1.384
137.87,28.69,0.130,1.391
137.89,28.80,0.131,1.399
137.91,28.92,0.132,1.410
137.94,29.03,0.132,1.419
137.96,29.15,0.133,1.429
137.98,29.27,0.134,1.444
138.01,29.38,0.136,1.457
138.03,29.50,0.137,1.465
138.05,29.62,0.138,1.477
138.08,29.73,0.139,1.487
138.10,29.85,0.140,1.506
138.12,29.97,0.142,1.522
138.15,30.08,0.144,1.542
138.17,30.20,0.146,1.566
138.19,30.32,0.148,1.586
138.22,30.43,0.150,1.607
138.24,30.55,0.152,1.634
138.26,30.66,0.155,1.667
138.29,30.78,0.158,1.701
138.31,30.90,0.162,1.738
138.33,31.01,0.165,1.775
138.36,31.13,0.170,1.826
138.38,31.25,0.174,1.870
138.40,31.36,0.179,1.929
138.43,31.48,0.184,1.985
138.45,31.59,0.188,2.031
138.47,31.71,0.194,2.093
138.50,31.82,0.199,2.152
138.52,31.94,0.205,2.216
138.54,32.06,0.211,2.287
138.57,32.17,0.218,2.358
138.59,32.29,0.225,2.445
138.61,32.40,0.234,2.540
138.64,32.52,0.242,2.630
138.66,32.63,0.251,2.734
138.68,32.75,0.260,2.838
138.71,32.86,0.271,2.955
138.73,32.97,0.282,3.082
138.75,33.09,0.295,3.235
138.78,33.20,0.308,3.379
138.80,33.32,0.322,3.537
138.82,33.43,0.335,3.692
138.85,33.54,0.353,3.894
138.87,33.66,0.371,4.103
138.89,33.77,0.387,4.291
138.92,33.88,0.407,4.521
138.94,33.99,0.428,4.770
138.96,34.11,0.449,5.018
138.99,34.22,0.473,5.299
139.01,34.33,0.497,5.586
139.03,34.44,0.525,5.921
139.06,34.55,0.553,6.259
139.08,34.66,0.583,6.625
139.10,34.77,0.614,7.010
139.13,34.88,0.646,7.412
139.15,34.99,0.684,7.883
139.17,35.10,0.722,8.358
139.20,35.21,0.763,8.882
139.22,35.31,0.806,9.435
139.24,35.42,0.852,10.025
139.27,35.52,0.900,10.652
139.29,35.63,0.952,11.342
139.31,35.73,1.007,12.051
139.34,35.84,1.064,12.799
139.36,35.94,1.122,13.545
139.38,36.04,1.183,14.313
139.41,36.15,1.241,15.036
139.43,36.25,1.302,15.738
139.45,36.35,1.360,16.370
139.48,36.45,1.415,16.868
139.50,36.56,1.463,17.219
139.52,36.66,1.503,17.430
139.55,36.77,1.532,17.392
139.57,36.88,1.546,17.146
139.59,36.99,1.541,16.666
139.62,37.11,1.520,16.026
139.64,37.23,1.481,15.224
139.66,37.35,1.430,14.341
139.69,37.48,1.369,13.444
139.71,37.61,1.301,12.547
139.73,37.74,1.226,11.649
139.76,37.88,1.147,10.773
139.78,38.01,1.067,9.953
139.80,38.15,0.988,9.168
139.83,38.28,0.908,8.399
139.85,38.42,0.832,7.697
139.87,38.55,0.758,7.015
139.90,38.69,0.683,6.331
139.92,38.82,0.611,5.670
139.94,38.96,0.539,5.010
139.97,39.09,0.469,4.362
139.99,39.22,0.400,3.725
140.01,39.36,0.330,3.073
140.04,39.49,0.262,2.447
140.06,39.62,0.193,1.800
140.08,39.76,0.124,1.160
140.11,39.89,0.055,0.512
140.13,40.03,-0.015,-0.138
140.15,40.16,-0.082,-0.769
140.18,40.29,-0.148,-1.394
140.20,40.42,-0.211,-1.991
140.22,40.56,-0.272,-2.580
140.25,40.69,-0.331,-3.159
140.27,40.82,-0.383,-3.682
140.29,40.95,-0.430,-4.166
140.32,41.08,-0.474,-4.631
140.34,41.20,-0.509,-5.028
140.36,41.33,-0.540,-5.399
140.39,41.45,-0.561,-5.678
140.41,41.58,-0.576,-5.906
140.43,41.70,-0.583,-6.071
140.46,41.82,-0.582,-6.150
140.48,41.93,-0.573,-6.145
140.50,42.05,-0.556,-6.049
140.53,42.16,-0.527,-5.822
140.55,42.27,-0.495,-5.545
140.57,42.38,-0.459,-5.197
140.60,42.49,-0.417,-4.774
140.62,42.60,-0.372,-4.301
140.64,42.70,-0.327,-3.798
140.67,42.81,-0.280,-3.257
140.69,42.92,-0.236,-2.750
140.71,43.02,-0.191,-2.230
140.74,43.13,-0.149,-1.736
140.76,43.24,-0.114,-1.314
140.78,43.34,-0.078,-0.898
140.81,43.45,-0.047,-0.542
140.83,43.56,-0.018,-0.204
140.85,43.67,0.007,0.083
140.88,43.78,0.031,0.345
140.90,43.89,0.051,0.573
140.92,44.00,0.069,0.766
140.95,44.12,0.084,0.933
140.97,44.23,0.099,1.090
140.99,44.34,0.112,1.228
141.02,44.46,0.122,1.333
141.04,44.57,0.133,1.451
141.06,44.69,0.141,1.533
141.09,44.80,0.149,1.620
141.11,44.91,0.156,1.694
141.13,45.03,0.162,1.754
141.16,45.14,0.167,1.807
141.18,45.26,0.172,1.854
141.20,45.37,0.176,1.900
141.23,45.49,0.180,1.935
141.25,45.61,0.183,1.969
141.27,45.72,0.187,2.005
141.30,45.84,0.189,2.024
141.32,45.95,0.191,2.047
141.34,46.07,0.193,2.071
141.37,46.18,0.195,2.085
141.39,46.30,0.197,2.105
141.41,46.42,0.199,2.125
141.44,46.53,0.200,2.139
141.46,46.65,0.202,2.159
141.48,46.77,0.203,2.176
141.51,46.88,0.205,2.195
141.53,47.00,0.207,2.219
141.55,47.12,0.209,2.241
141.58,47.23,0.212,2.273
141.60,47.35,0.215,2.306
141.62,47.46,0.219,2.345
141.65,47.58,0.223,2.395
141.67,47.69,0.230,2.468
141.69,47.81,0.237,2.547
141.72,47.93,0.245,2.640
141.74,48.04,0.253,2.741
141.76,48.16,0.263,2.852
141.79,48.27,0.274,2.975
141.81,48.38,0.286,3.127
141.83,48.50,0.301,3.301
141.86,48.61,0.318,3.499
141.88,48.73,0.337,3.728
141.90,48.84,0.360,3.997
141.93,48.95,0.387,4.334
141.95,49.06,0.416,4.699
141.97,49.17,0.450,5.130
142.00,49.28,0.490,5.624
142.02,49.39,0.535,6.219
142.04,49.49,0.585,6.869
142.07,49.60,0.641,7.620
142.09,49.70,0.703,8.454
142.11,49.81,0.770,9.391
142.14,49.91,0.845,10.408
142.16,50.01,0.923,11.495
142.18,50.11,1.007,12.662
142.21,50.21,1.093,13.817
142.23,50.30,1.181,15.001
142.25,50.40,1.268,16.146
142.28,50.49,1.354,17.267
142.30,50.59,1.435,18.278
142.32,50.69,1.515,19.144
142.35,50.79,1.593,19.583
142.37,50.89,1.668,19.348
142.39,50.98,1.732,18.542
142.42,51.09,1.766,17.606
142.44,51.20,1.702,16.013
142.46,51.34,1.426,12.787
142.49,51.51,1.054,9.077
142.51,51.68,0.832,6.938
142.53,51.85,0.683,5.569
142.56,52.00,0.554,4.512
142.58,52.15,0.449,3.750
142.60,52.30,0.376,3.265
142.63,52.44,0.320,2.883
142.65,52.57,0.278,2.587
142.67,52.70,0.247,2.369
142.70,52.82,0.222,2.176
142.72,52.95,0.204,2.034
142.74,53.07,0.191,1.933
142.77,53.19,0.180,1.849
142.79,53.31,0.172,1.777
142.81,53.43,0.167,1.738
142.84,53.55,0.162,1.696
142.86,53.67,0.159,1.677
142.88,53.78,0.156,1.653
142.91,53.90,0.155,1.639
142.93,54.02,0.153,1.628
142.95,54.14,0.153,1.624
142.98,54.25,0.152,1.616
143.00,54.37,0.151,1.611
143.02,54.49,0.151,1.606
143.05,54.60,0.150,1.601
143.07,54.72,0.150,1.597
143.09,54.84,0.149,1.593
143.12,54.95,0.149,1.590
143.14,55.07,0.149,1.585
143.16,55.19,0.148,1.581
143.19,55.30,0.148,1.578
143.21,55.42,0.148,1.575
143.23,55.54,0.148,1.574
143.26,55.65,0.147,1.571
143.28,55.77,0.147,1.568
143.30,55.89,0.147,1.566
143.33,56.01,0.147,1.565
143.35,56.12,0.147,1.564
143.37,56.24,0.147,1.562
143.40,56.36,0.146,1.561
143.42,56.47,0.146,1.560
143.44,56.59,0.146,1.559
143.47,56.71,0.146,1.558
143.49,56.82,0.146,1.557
143.51,56.94,0.146,1.556
143.54,57.06,0.146,1.555
143.56,57.17,0.146,1.555
143.58,57.29,0.146,1.555
143.61,57.41,0.146,1.553
143.63,57.52,0.146,1.553
143.65,57.64,0.146,1.552
143.68,57.76,0.145,1.552
143.70,57.87,0.145,1.551
143.72,57.99,0.145,1.553
143.75,58.11,0.145,1.551
143.77,58.22,0.145,1.552
143.79,58.34,0.145,1.552
143.82,58.46,0.145,1.550
143.84,58.57,0.145,1.552
143.86,58.69,0.145,1.552
143.89,58.81,0.145,1.551
143.91,58.92,0.145,1.550
143.93,59.04,0.145,1.551
143.96,59.16,0.145,1.550
143.98,59.27,0.145,1.550
144.00,59.39,0.145,1.550
144.03,59.51,0.145,1.551
144.05,59.62,0.145,1.552
144.07,59.74,0.145,1.551
144.10,59.86,0.145,1.553
144.12,59.98,0.146,1.553
144.14,60.09,0.146,1.553
144.17,60.21,0.146,1.553
144.19,60.33,0.146,1.555
144.21,60.44,0.146,1.556
144.24,60.56,0.146,1.556
144.26,60.68,0.146,1.555
144.28,60.79,0.146,1.555
144.31,60.91,0.146,1.555
144.33,61.03,0.146,1.554
144.35,61.14,0.146,1.554
144.38,61.26,0.146,1.554
144.40,61.38,0.146,1.555
144.42,61.49,0.146,1.554
144.45,61.61,0.146,1.555
144.47,61.73,0.146,1.556
144.49,61.84,0.146,1.557
144.52,61.96,0.146,1.557
144.54,62.08,0.146,1.558
144.56,62.19,0.146,1.557
144.59,62.31,0.146,1.558
144.61,62.43,0.146,1.559
144.63,62.54,0.146,1.560
144.66,62.66,0.146,1.559
144.68,62.78,0.146,1.558
144.70,62.89,0.146,1.557
144.73,63.01,0.146,1.558
144.75,63.13,0.146,1.558
144.77,63.24,0.146,1.558
144.80,63.36,0.146,1.557
144.82,63.48,0.146,1.558
144.84,63.59,0.146,1.559
144.87,63.71,0.146,1.559
144.89,63.83,0.146,1.559
144.91,63.95,0.146,1.561
144.94,64.06,0.146,1.559
144.96,64.18,0.146,1.560
144.98,64.29,0.146,1.560
145.01,64.41,0.146,1.561
145.03,64.53,0.146,1.561
145.05,64.65,0.146,1.560
145.08,64.76,0.146,1.560
145.10,64.88,0.146,1.560
145.12,65.00,0.146,1.560
145.15,65.11,0.146,1.561
145.17,65.23,0.146,1.559
145.19,65.35,0.146,1.559
145.22,65.46,0.146,1.559
145.24,65.58,0.146,1.559
145.26,65.70,0.146,1.559
145.29,65.81,0.146,1.558
145.31,65.93,0.146,1.557
145.33,66.05,0.146,1.559
145.36,66.16,0.146,1.559
145.38,66.28,0.146,1.559
145.40,66.40,0.146,1.559
145.43,66.51,0.146,1.558
145.45,66.63,0.146,1.560
145.47,66.75,0.146,1.561
145.50,66.86,0.146,1.563
145.52,66.98,0.146,1.564
145.54,67.10,0.146,1.565
145.57,67.21,0.146,1.564
145.59,67.33,0.146,1.565
145.61,67.45,0.146,1.565
145.64,67.56,0.146,1.564
145.66,67.68,0.146,1.564
145.68,67.80,0.146,1.561
145.71,67.91,0.146,1.561
145.73,68.03,0.146,1.560
145.75,68.15,0.146,1.560
145.78,68.26,0.146,1.560
145.80,68.38,0.146,1.561
145.82,68.50,0.146,1.561
145.85,68.61,0.146,1.563
145.87,68.73,0.146,1.562
145.89,68.85,0.147,1.564
145.92,68.96,0.147,1.563
145.94,69.08,0.147,1.564
145.96,69.20,0.147,1.564
145.99,69.31,0.147,1.564
146.01,69.43,0.147,1.563
146.03,69.55,0.147,1.563
146.06,69.66,0.147,1.564
146.08,69.78,0.147,1.565
146.10,69.90,0.147,1.565
146.13,70.01,0.147,1.565
146.15,70.13,0.147,1.567
146.17,70.25,0.147,1.569
146.20,70.37,0.147,1.568
146.22,70.48,0.147,1.567
146.24,70.60,0.147,1.568
146.27,70.72,0.147,1.568
146.29,70.83,0.147,1.569
146.31,70.95,0.147,1.569
146.34,71.07,0.147,1.568
146.36,71.18,0.147,1.569
146.38,71.30,0.147,1.569
146.41,71.42,0.147,1.570
146.43,71.53,0.147,1.571
146.45,71.65,0.147,1.572
146.48,71.77,0.147,1.572
146.50,71.88,0.147,1.572
146.52,72.00,0.148,1.573
146.55,72.12,0.148,1.574
146.57,72.23,0.148,1.575
146.59,72.35,0.148,1.574
146.62,72.47,0.148,1.573
146.64,72.58,0.148,1.576
146.66,72.70,0.148,1.575
146.69,72.82,0.148,1.575
146.71,72.93,0.148,1.575
146.73,73.05,0.148,1.574
146.76,73.17,0.148,1.574
146.78,73.28,0.148,1.574
146.80,73.40,0.148,1.574
146.83,73.52,0.148,1.575
146.85,73.64,0.148,1.575
146.87,73.75,0.148,1.575
146.90,73.87,0.148,1.574
146.92,73.99,0.148,1.574
146.94,74.10,0.148,1.577
146.97,74.22,0.148,1.576
146.99,74.34,0.148,1.576
147.01,74.45,0.148,1.576
147.04,74.57,0.148,1.576
147.06,74.69,0.148,1.576
147.08,74.80,0.148,1.577
147.11,74.92,0.148,1.578
147.13,75.04,0.148,1.577
147.15,75.15,0.148,1.578
147.18,75.27,0.148,1.579
147.20,75.39,0.148,1.578
147.22,75.50,0.148,1.578
147.25,75.62,0.148,1.579
147.27,75.74,0.148,1.579
147.29,75.85,0.148,1.577
147.32,75.97,0.148,1.578
147.34,76.09,0.148,1.578
147.36,76.20,0.148,1.579
147.39,76.32,0.148,1.580
147.41,76.44,0.148,1.581
147.43,76.56,0.148,1.580
147.46,76.67,0.148,1.582
147.48,76.79,0.148,1.582
147.50,76.90,0.148,1.582
147.53,77.02,0.148,1.582
147.55,77.14,0.148,1.582
147.57,77.25,0.148,1.582
147.60,77.37,0.148,1.583
147.62,77.49,0.149,1.583
147.64,77.60,0.149,1.584
147.67,77.72,0.149,1.584
147.69,77.84,0.149,1.585
147.71,77.96,0.149,1.585
147.74,78.07,0.149,1.586
147.76,78.19,0.149,1.585
147.78,78.31,0.149,1.586
147.81,78.42,0.149,1.586
147.83,78.54,0.149,1.586
147.85,78.66,0.149,1.587
147.88,78.77,0.149,1.587
147.90,78.89,0.149,1.586
147.92,79.01,0.149,
147.95,79.12,0.149,
147.97,79.24,,
147.99,79.36,,
148.02,,,
148.02,,,