File: DSC/Earl/2025_10_12_CBN_5Cmin_n60C_150C_x3.csv
Filename,2025_10_12_CBN_5Cmin_n60C_150C_x3
Instrument name,DSC2A-00468 (192.168.1.100)
Operator,JLY
rundate,10/12/2025
Sample name,2025_10_12_CBN_5Cmin_n60C_150C_x3
proceduresegments,Data Off ; Equilibrate -60.00 °C; Data On ; Ramp 5.00 °C/min to 150.00 °C; Data Off ; Isothermal 1.0 min; Data On ; Ramp 50.00 °C/min to -60.00 °C; Data Off ; Isothermal 5.0 min; Data On ; Ramp 5.00 °C/min to 150.00 °C; Data Off ; Isothermal 1.0 min; Data On ; Ramp 5.00 °C/min to -60.00 °C; Data Off ; Isothermal 1.0 min; Data On ; Ramp 5.00 °C/min to 150.00 °C
[File Parameters]
Run date,10/12/2025 8:02:27 PM
Trios version,5.1.1.46572
Original File Name,
Current File Name,D:\DSC2500\JYarger\2025_10_12_CBN_5Cmin_n60C_150C_x3.tri
[Procedure]
Procedure Name,CBN_n60C_150C_5Cmin_x3
Sample Name,2025_10_12_CBN_5Cmin_n60C_150C_x3
Sample Mass,4.67 mg
Reference Sample Mass,0 mg
Pan Mass,32.81 mg
Pan Number,35
Reference Pan Mass,32.55 mg
Reference Pan Number,1
Pan Type,Aluminum
Comments,DSC_Samples_Y2_Tray_ASDs_Pharma_Oct2025 Google Sheet.
Project Name,Amorphous Pharma
Operator,JLY
Test,Custom
Unload Max Temperature,30
Unload Min Temperature,30
Load Max Temperature,30
Load Min Temperature,30
Stop on Gas Flow Error,Yes
[Signal List]
Signal #1,Time (min)
Signal #2,Temperature (°C)
Signal #3,Heat Flow (mW)
Signal #4,Delta T (µV)
Signal #5,Delta Tzero (µV)
Signal #6,Tzero Temperature (°C)
Signal #7,Cell Purge (mL/min)
Signal #8,Heater Temp (°C)
Signal #9,Power Delivered (W)
Signal #10,Reference Junction Temperature (°C)
Signal #11,Flange Temperature (°C)
Signal #12,Heat Flow Phase (rad)
Signal #13,Total Heat Capacity (J/°C)
Signal #14,Heat Capacity (J/°C)
[Configuration]
Company Name,ASU
Instrument Name,DSC2A-00468
Instrument Type,DSC2500
Serial Number,DSC2A-00468
IP,192.168.1.100
Location of Instrument,MRRC
DisplayType,Unknown
Sample Interval ,0.1 s/pt
Selected Heat Flow,T4P
Exotherm Direction,Down
Cell Serial,DRC2-00792
Lid Type,Standard
Cooler,RCS 90
Leave Cooler on at End of Sequence,On
Gas 2,Nitrogen
Gas Selected,Channel 1
Flow Rate,50 mL/min
Secondary Purge,On
Licensed Heat Flow,Heat Flow T4P
Modulation Licensed,Yes
[Versions]
Common IDD Version,1
Cortex Version,VER 2.10.2.31
Driver,5.0.0.6
GDM Version,1.0.3.3
TouchscreenVersion,1.0.0.16145
FEP Version,1.2.1.21
FEP Bootloader,2.0.0.5
AutoSampler Version,2.1.1.26
Auto Sampler Bootloader,2.0.0.5
FCM Version,1.1.0.3
FCM Bootloader,2.0.0.5
[Experiment Logs]
Experiment Log Entry # 1,Data On set to 0
Experiment Log Entry # 3,Equilibrate Segment -60 (C) Started
Experiment Log Entry # 5,Air Cool is off.
Experiment Log Entry # 7,Data On set to 1
Experiment Log Entry # 9,Ramp Segment 5 C/min to 150 Started
Experiment Log Entry # 11,Data On set to 0
Experiment Log Entry # 13,Isothermal Segment 1 min started
Experiment Log Entry # 15,Data On set to 1
Experiment Log Entry # 17,Ramp Segment 50 C/min to -60 Started
Experiment Log Entry # 19,Data On set to 0
Experiment Log Entry # 21,Isothermal Segment 5 min started
Experiment Log Entry # 23,Data On set to 1
Experiment Log Entry # 25,Ramp Segment 5 C/min to 150 Started
Experiment Log Entry # 27,Data On set to 0
Experiment Log Entry # 29,Isothermal Segment 1 min started
Experiment Log Entry # 31,Data On set to 1
Experiment Log Entry # 33,Ramp Segment 5 C/min to -60 Started
Experiment Log Entry # 35,Data On set to 0
Experiment Log Entry # 37,Isothermal Segment 1 min started
Experiment Log Entry # 39,Data On set to 1
Experiment Log Entry # 41,Ramp Segment 5 C/min to 150 Started
[Method Log]
Method Log Entry # 1,Data Off
Method Log Entry # 2,Equilibrate -60 °C
Method Log Entry # 3,Data On
Method Log Entry # 4,(Ramp 63939) Ramp 5 °C/minute to 150 °C
Method Log Entry # 5,Data Off
Method Log Entry # 6,Isothermal 1 minutes
Method Log Entry # 7,Data On
Method Log Entry # 8,(Ramp 63943) Ramp 50 °C/minute to -60 °C
Method Log Entry # 9,Data Off
Method Log Entry # 10,Isothermal 5 minutes
Method Log Entry # 11,Data On
Method Log Entry # 12,(Ramp 63947) Ramp 5 °C/minute to 150 °C
Method Log Entry # 13,Data Off
Method Log Entry # 14,Isothermal 1 minutes
Method Log Entry # 15,Data On
Method Log Entry # 16,(Ramp 63951) Ramp 5 °C/minute to -60 °C
Method Log Entry # 17,Data Off
Method Log Entry # 18,Isothermal 1 minutes
Method Log Entry # 19,Data On
Method Log Entry # 20,(Ramp 63955) Ramp 5 °C/minute to 150 °C
Cell Serial,DRC2-00792
[T1 Calibration]
Slope,-0.008529666
Offset,9.636258
Initial Temperature,98.23
GUID,f8bfdadc-4977-4fdf-ba6d-0ba9134940c3
[TZero Calibration]
Date Applied,11/29/2022 4:06:13 PM
Description,From -89.059 °C to 396.009 °C at 20.000°C/min
Gas Type,Nitrogen
Pan Type,None
Source Files 1,C:\Users\yargerlab\Desktop\DSC Data\General\TZero_calibration_11_29_22_2nd(2).tri
Source Files 2,C:\Users\yargerlab\Desktop\DSC Data\General\TZero_calibration_11_29_22_2nd(3).tri
Delta T Offset,13.05235
Delta T Slope,-0.007271007
Delta T0 Offset,-13.69128
Delta T0 Slope,0.06063341
[Temperature Calibration]
Date Applied,11/29/2022 7:12:28 PM
Description,From 106.590 °C to 186.590 °C at 10.000°C/min
Gas Type,Nitrogen
Pan Type,Tzero Aluminum Hermetic
Source Files 1,C:\Users\yargerlab\Desktop\DSC Data\General\Indium(6).tri
Measured 1,157.391
Known 1,156.598
[Cell Constant Calibration]
Date Applied,11/29/2022 7:12:29 PM
Description,From 106.590 °C to 186.590 °C at 10.000°C/min
Gas Type,Nitrogen
Pan Type,Tzero Aluminum Hermetic
Source Files 1,C:\Users\yargerlab\Desktop\DSC Data\General\Indium(6).tri
T4P KCell,1.006051
Onset Slope,63.26126 mW/°C
[Direct Cp Calibration]
Date Applied,11/30/2022 11:04:51 AM
Description,From -79.983 °C to 298.409 °C at 10.000°C/min
Gas Type,Nitrogen
Pan Type,Tzero Aluminum Hermetic
Source Files 1,C:\Users\yargerlab\Desktop\DSC Data\General\Sapphire_Heat_Capacity_11_30_22.tri
[Rev Cp Calibration]
Date Applied,11/30/2022 1:58:51 PM
Description,From -79.996 °C to 292.812 °C at 3.000°C/min
Gas Type,Nitrogen
Pan Type,Tzero Aluminum Hermetic
Source Files 1,C:\Users\yargerlab\Desktop\DSC Data\General\Sapphire_MDSC_Calibration_11_30_22.tri
[step]
Ramp 5.00 °C/min to 150.00 °C
Time,Temperature,Heat Flow (Normalized)
min,°C,W/g
0.00,-59.81,-0.042
0.03,-59.82,-0.039
0.06,-59.81,-0.034
0.08,-59.77,-0.032
0.11,-59.69,-0.028
0.14,-59.59,-0.012
0.17,-59.47,0.008
0.20,-59.35,0.025
0.23,-59.22,0.040
0.26,-59.10,0.051
0.28,-58.97,0.057
0.31,-58.83,0.063
0.34,-58.70,0.067
0.37,-58.56,0.070
0.40,-58.42,0.072
0.43,-58.29,0.074
0.45,-58.15,0.075
0.48,-58.01,0.076
0.51,-57.87,0.077
0.54,-57.73,0.077
0.57,-57.59,0.078
0.60,-57.45,0.078
0.62,-57.31,0.079
0.65,-57.17,0.079
0.68,-57.03,0.080
0.71,-56.89,0.080
0.74,-56.75,0.080
0.77,-56.61,0.081
0.79,-56.47,0.081
0.82,-56.33,0.081
0.85,-56.19,0.082
0.88,-56.05,0.082
0.91,-55.91,0.082
0.93,-55.77,0.082
0.96,-55.63,0.082
0.99,-55.49,0.082
1.02,-55.35,0.083
1.05,-55.21,0.083
1.08,-55.07,0.083
1.11,-54.93,0.083
1.13,-54.79,0.083
1.16,-54.65,0.083
1.19,-54.50,0.083
1.22,-54.36,0.083
1.25,-54.22,0.083
1.28,-54.08,0.083
1.30,-53.94,0.083
1.33,-53.80,0.083
1.36,-53.66,0.083
1.39,-53.51,0.083
1.42,-53.37,0.083
1.44,-53.23,0.083
1.47,-53.09,0.083
1.50,-52.95,0.083
1.53,-52.81,0.083
1.56,-52.66,0.083
1.59,-52.52,0.083
1.62,-52.38,0.083
1.64,-52.24,0.083
1.67,-52.10,0.083
1.70,-51.96,0.083
1.73,-51.81,0.083
1.76,-51.67,0.083
1.78,-51.53,0.083
1.81,-51.39,0.083
1.84,-51.25,0.083
1.87,-51.11,0.083
1.90,-50.97,0.083
1.93,-50.82,0.083
1.96,-50.68,0.083
1.98,-50.54,0.083
2.01,-50.40,0.083
2.04,-50.26,0.083
2.07,-50.12,0.083
2.10,-49.97,0.083
2.13,-49.83,0.083
2.15,-49.69,0.083
2.18,-49.55,0.083
2.21,-49.41,0.083
2.24,-49.27,0.083
2.27,-49.13,0.083
2.29,-48.98,0.083
2.32,-48.84,0.083
2.35,-48.70,0.083
2.38,-48.56,0.083
2.41,-48.42,0.083
2.44,-48.28,0.083
2.46,-48.13,0.083
2.49,-47.99,0.083
2.52,-47.85,0.083
2.55,-47.71,0.083
2.58,-47.57,0.083
2.61,-47.43,0.083
2.64,-47.28,0.083
2.66,-47.14,0.083
2.69,-47.00,0.083
2.72,-46.86,0.083
2.75,-46.72,0.083
2.78,-46.58,0.082
2.81,-46.44,0.082
2.83,-46.29,0.082
2.86,-46.15,0.082
2.89,-46.01,0.082
2.92,-45.87,0.082
2.95,-45.73,0.082
2.98,-45.59,0.082
3.00,-45.45,0.082
3.03,-45.30,0.082
3.06,-45.16,0.082
3.09,-45.02,0.082
3.12,-44.88,0.082
3.14,-44.74,0.082
3.17,-44.59,0.082
3.20,-44.45,0.082
3.23,-44.31,0.082
3.26,-44.17,0.082
3.29,-44.03,0.082
3.31,-43.89,0.082
3.34,-43.74,0.082
3.37,-43.60,0.082
3.40,-43.46,0.082
3.43,-43.32,0.082
3.46,-43.18,0.082
3.49,-43.03,0.082
3.51,-42.89,0.082
3.54,-42.75,0.082
3.57,-42.61,0.082
3.60,-42.47,0.082
3.63,-42.33,0.082
3.66,-42.18,0.082
3.68,-42.04,0.082
3.71,-41.90,0.082
3.74,-41.76,0.082
3.77,-41.62,0.082
3.80,-41.48,0.082
3.83,-41.33,0.082
3.85,-41.19,0.082
3.88,-41.05,0.082
3.91,-40.91,0.082
3.94,-40.76,0.082
3.97,-40.62,0.082
3.99,-40.47,0.082
4.02,-40.33,0.083
4.05,-40.19,0.083
4.08,-40.04,0.083
4.11,-39.90,0.083
4.14,-39.76,0.083
4.16,-39.62,0.083
4.19,-39.48,0.083
4.22,-39.33,0.083
4.25,-39.19,0.083
4.28,-39.05,0.083
4.31,-38.91,0.083
4.34,-38.77,0.083
4.36,-38.63,0.083
4.39,-38.49,0.082
4.42,-38.35,0.082
4.45,-38.21,0.082
4.48,-38.07,0.082
4.50,-37.93,0.082
4.53,-37.79,0.082
4.56,-37.65,0.082
4.59,-37.50,0.082
4.62,-37.36,0.082
4.65,-37.22,0.082
4.68,-37.08,0.082
4.70,-36.94,0.082
4.73,-36.79,0.082
4.76,-36.65,0.082
4.79,-36.51,0.082
4.82,-36.37,0.082
4.85,-36.23,0.082
4.87,-36.08,0.082
4.90,-35.94,0.082
4.93,-35.80,0.082
4.96,-35.66,0.082
4.99,-35.52,0.082
5.01,-35.38,0.082
5.04,-35.23,0.082
5.07,-35.09,0.082
5.10,-34.95,0.082
5.13,-34.81,0.082
5.16,-34.66,0.082
5.19,-34.52,0.082
5.21,-34.38,0.082
5.24,-34.24,0.082
5.27,-34.10,0.082
5.30,-33.95,0.082
5.33,-33.81,0.083
5.35,-33.67,0.083
5.38,-33.53,0.083
5.41,-33.39,0.083
5.44,-33.24,0.083
5.47,-33.10,0.083
5.50,-32.96,0.083
5.53,-32.82,0.083
5.55,-32.68,0.083
5.58,-32.54,0.083
5.61,-32.39,0.083
5.64,-32.25,0.083
5.67,-32.11,0.083
5.70,-31.97,0.083
5.72,-31.83,0.083
5.75,-31.69,0.083
5.78,-31.54,0.083
5.81,-31.40,0.083
5.84,-31.26,0.083
5.86,-31.12,0.083
5.89,-30.98,0.083
5.92,-30.84,0.083
5.95,-30.70,0.083
5.98,-30.55,0.083
6.01,-30.41,0.083
6.04,-30.27,0.083
6.06,-30.13,0.083
6.09,-29.99,0.083
6.12,-29.84,0.083
6.15,-29.70,0.083
6.18,-29.56,0.083
6.20,-29.42,0.083
6.23,-29.27,0.083
6.26,-29.13,0.083
6.29,-28.99,0.083
6.32,-28.85,0.083
6.35,-28.71,0.083
6.38,-28.56,0.083
6.40,-28.42,0.083
6.43,-28.28,0.083
6.46,-28.14,0.083
6.49,-28.00,0.083
6.52,-27.86,0.083
6.55,-27.71,0.083
6.57,-27.57,0.083
6.60,-27.43,0.083
6.63,-27.29,0.083
6.66,-27.15,0.083
6.69,-27.01,0.083
6.71,-26.86,0.083
6.74,-26.72,0.083
6.77,-26.58,0.083
6.80,-26.44,0.083
6.83,-26.30,0.083
6.86,-26.15,0.083
6.89,-26.01,0.083
6.91,-25.87,0.083
6.94,-25.73,0.083
6.97,-25.59,0.083
7.00,-25.45,0.083
7.03,-25.31,0.083
7.05,-25.16,0.083
7.08,-25.02,0.083
7.11,-24.88,0.083
7.14,-24.74,0.083
7.17,-24.59,0.083
7.20,-24.45,0.084
7.23,-24.31,0.084
7.25,-24.17,0.084
7.28,-24.03,0.084
7.31,-23.88,0.084
7.34,-23.74,0.084
7.37,-23.60,0.084
7.40,-23.46,0.084
7.42,-23.32,0.084
7.45,-23.18,0.084
7.48,-23.04,0.084
7.51,-22.90,0.084
7.54,-22.75,0.084
7.56,-22.61,0.084
7.59,-22.47,0.084
7.62,-22.33,0.084
7.65,-22.19,0.084
7.68,-22.05,0.084
7.71,-21.90,0.084
7.74,-21.76,0.084
7.76,-21.62,0.084
7.79,-21.47,0.084
7.82,-21.33,0.084
7.85,-21.19,0.084
7.88,-21.05,0.084
7.90,-20.91,0.084
7.93,-20.76,0.084
7.96,-20.62,0.084
7.99,-20.48,0.084
8.02,-20.34,0.084
8.05,-20.20,0.084
8.08,-20.06,0.085
8.10,-19.91,0.085
8.13,-19.77,0.085
8.16,-19.63,0.085
8.19,-19.49,0.085
8.22,-19.35,0.085
8.25,-19.21,0.085
8.27,-19.06,0.085
8.30,-18.92,0.085
8.33,-18.78,0.085
8.36,-18.64,0.085
8.39,-18.50,0.085
8.41,-18.36,0.085
8.44,-18.21,0.085
8.47,-18.07,0.085
8.50,-17.93,0.085
8.53,-17.79,0.085
8.56,-17.65,0.085
8.58,-17.50,0.085
8.61,-17.36,0.085
8.64,-17.22,0.085
8.67,-17.08,0.085
8.70,-16.94,0.085
8.73,-16.80,0.085
8.75,-16.65,0.085
8.78,-16.51,0.085
8.81,-16.37,0.085
8.84,-16.23,0.085
8.87,-16.09,0.085
8.90,-15.94,0.085
8.93,-15.80,0.085
8.95,-15.66,0.085
8.98,-15.52,0.085
9.01,-15.38,0.085
9.04,-15.24,0.085
9.07,-15.09,0.085
9.10,-14.95,0.085
9.12,-14.81,0.085
9.15,-14.67,0.085
9.18,-14.53,0.085
9.21,-14.39,0.085
9.24,-14.24,0.085
9.27,-14.10,0.085
9.29,-13.96,0.085
9.32,-13.82,0.085
9.35,-13.68,0.085
9.38,-13.53,0.085
9.41,-13.39,0.086
9.43,-13.25,0.086
9.46,-13.11,0.086
9.49,-12.97,0.086
9.52,-12.83,0.086
9.55,-12.68,0.086
9.58,-12.54,0.086
9.60,-12.40,0.086
9.63,-12.26,0.086
9.66,-12.12,0.086
9.69,-11.98,0.086
9.72,-11.83,0.086
9.75,-11.69,0.086
9.78,-11.55,0.086
9.80,-11.41,0.086
9.83,-11.27,0.086
9.86,-11.12,0.086
9.89,-10.98,0.086
9.92,-10.84,0.086
9.95,-10.70,0.086
9.97,-10.56,0.086
10.00,-10.42,0.086
10.03,-10.27,0.086
10.06,-10.13,0.086
10.09,-9.99,0.086
10.12,-9.85,0.086
10.14,-9.71,0.086
10.17,-9.56,0.086
10.20,-9.42,0.086
10.23,-9.28,0.086
10.26,-9.14,0.086
10.28,-9.00,0.086
10.31,-8.86,0.087
10.34,-8.71,0.087
10.37,-8.57,0.087
10.40,-8.43,0.087
10.43,-8.29,0.087
10.45,-8.14,0.087
10.48,-8.00,0.087
10.51,-7.86,0.087
10.54,-7.72,0.087
10.57,-7.58,0.087
10.60,-7.44,0.087
10.63,-7.29,0.087
10.65,-7.15,0.087
10.68,-7.01,0.087
10.71,-6.87,0.087
10.74,-6.73,0.087
10.77,-6.59,0.087
10.80,-6.44,0.087
10.82,-6.30,0.087
10.85,-6.16,0.087
10.88,-6.02,0.087
10.91,-5.88,0.087
10.94,-5.73,0.087
10.97,-5.59,0.087
10.99,-5.45,0.087
11.02,-5.31,0.087
11.05,-5.17,0.087
11.08,-5.03,0.087
11.11,-4.88,0.087
11.13,-4.74,0.088
11.16,-4.60,0.088
11.19,-4.46,0.088
11.22,-4.32,0.088
11.25,-4.18,0.088
11.28,-4.03,0.088
11.30,-3.89,0.088
11.33,-3.75,0.088
11.36,-3.61,0.088
11.39,-3.47,0.088
11.42,-3.33,0.088
11.45,-3.18,0.088
11.48,-3.04,0.088
11.50,-2.90,0.088
11.53,-2.76,0.088
11.56,-2.62,0.088
11.59,-2.47,0.088
11.62,-2.33,0.088
11.65,-2.19,0.088
11.67,-2.05,0.088
11.70,-1.91,0.088
11.73,-1.77,0.088
11.76,-1.62,0.088
11.79,-1.48,0.088
11.82,-1.34,0.089
11.84,-1.20,0.089
11.87,-1.06,0.089
11.90,-0.92,0.089
11.93,-0.77,0.089
11.96,-0.63,0.089
11.98,-0.49,0.089
12.01,-0.35,0.089
12.04,-0.21,0.089
12.07,-0.06,0.089
12.10,0.08,0.089
12.13,0.22,0.089
12.15,0.36,0.089
12.18,0.50,0.089
12.21,0.65,0.089
12.24,0.79,0.089
12.27,0.93,0.089
12.30,1.07,0.089
12.33,1.21,0.089
12.35,1.35,0.089
12.38,1.50,0.089
12.41,1.64,0.089
12.44,1.78,0.089
12.47,1.92,0.089
12.50,2.06,0.089
12.52,2.21,0.089
12.55,2.35,0.089
12.58,2.49,0.089
12.61,2.63,0.089
12.64,2.77,0.089
12.67,2.91,0.089
12.69,3.05,0.090
12.72,3.20,0.090
12.75,3.34,0.090
12.78,3.48,0.090
12.81,3.62,0.090
12.83,3.76,0.090
12.86,3.91,0.090
12.89,4.05,0.090
12.92,4.19,0.090
12.95,4.33,0.090
12.98,4.47,0.090
13.00,4.61,0.090
13.03,4.76,0.090
13.06,4.90,0.090
13.09,5.04,0.090
13.12,5.18,0.090
13.15,5.32,0.090
13.18,5.47,0.090
13.20,5.61,0.090
13.23,5.75,0.090
13.26,5.89,0.090
13.29,6.03,0.090
13.32,6.17,0.090
13.35,6.32,0.090
13.37,6.46,0.090
13.40,6.60,0.090
13.43,6.74,0.090
13.46,6.88,0.091
13.49,7.03,0.091
13.52,7.17,0.091
13.54,7.31,0.091
13.57,7.45,0.091
13.60,7.59,0.091
13.63,7.74,0.091
13.66,7.88,0.091
13.68,8.02,0.091
13.71,8.16,0.091
13.74,8.30,0.091
13.77,8.44,0.091
13.80,8.59,0.091
13.83,8.73,0.091
13.85,8.87,0.091
13.88,9.01,0.091
13.91,9.15,0.091
13.94,9.30,0.091
13.97,9.44,0.091
14.00,9.58,0.091
14.03,9.72,0.091
14.05,9.86,0.091
14.08,10.00,0.091
14.11,10.14,0.092
14.14,10.29,0.092
14.17,10.43,0.092
14.20,10.57,0.092
14.22,10.71,0.092
14.25,10.85,0.092
14.28,11.00,0.092
14.31,11.14,0.092
14.34,11.28,0.092
14.37,11.42,0.092
14.39,11.56,0.092
14.42,11.70,0.092
14.45,11.85,0.092
14.48,11.99,0.092
14.51,12.13,0.092
14.53,12.27,0.092
14.56,12.41,0.092
14.59,12.56,0.092
14.62,12.70,0.092
14.65,12.84,0.092
14.68,12.98,0.092
14.70,13.12,0.092
14.73,13.26,0.092
14.76,13.41,0.092
14.79,13.55,0.092
14.82,13.69,0.093
14.85,13.83,0.093
14.88,13.97,0.093
14.90,14.12,0.093
14.93,14.26,0.093
14.96,14.40,0.093
14.99,14.54,0.093
15.02,14.68,0.093
15.05,14.82,0.093
15.07,14.96,0.093
15.10,15.11,0.093
15.13,15.25,0.093
15.16,15.39,0.093
15.19,15.53,0.093
15.22,15.67,0.093
15.24,15.82,0.093
15.27,15.96,0.093
15.30,16.10,0.093
15.33,16.24,0.093
15.36,16.38,0.093
15.38,16.52,0.093
15.41,16.67,0.093
15.44,16.81,0.093
15.47,16.95,0.093
15.50,17.09,0.094
15.53,17.24,0.094
15.55,17.38,0.094
15.58,17.52,0.094
15.61,17.66,0.094
15.64,17.80,0.094
15.67,17.94,0.094
15.70,18.08,0.094
15.73,18.23,0.094
15.75,18.37,0.094
15.78,18.51,0.094
15.81,18.65,0.094
15.84,18.79,0.094
15.87,18.93,0.094
15.90,19.08,0.094
15.92,19.22,0.094
15.95,19.36,0.094
15.98,19.50,0.094
16.01,19.64,0.094
16.04,19.79,0.094
16.07,19.93,0.094
16.09,20.07,0.094
16.12,20.21,0.094
16.15,20.35,0.095
16.18,20.50,0.095
16.21,20.64,0.095
16.23,20.78,0.095
16.26,20.92,0.095
16.29,21.06,0.095
16.32,21.20,0.095
16.35,21.35,0.095
16.38,21.49,0.095
16.40,21.63,0.095
16.43,21.77,0.095
16.46,21.91,0.095
16.49,22.05,0.095
16.52,22.20,0.095
16.55,22.34,0.095
16.58,22.48,0.095
16.60,22.62,0.095
16.63,22.76,0.095
16.66,22.90,0.095
16.69,23.05,0.095
16.72,23.19,0.095
16.75,23.33,0.095
16.77,23.47,0.095
16.80,23.61,0.095
16.83,23.76,0.096
16.86,23.90,0.096
16.89,24.04,0.096
16.92,24.18,0.096
16.94,24.32,0.096
16.97,24.46,0.096
17.00,24.61,0.096
17.03,24.75,0.096
17.06,24.89,0.096
17.08,25.03,0.096
17.11,25.17,0.096
17.14,25.31,0.096
17.17,25.46,0.096
17.20,25.60,0.096
17.23,25.74,0.096
17.26,25.88,0.096
17.28,26.02,0.096
17.31,26.17,0.096
17.34,26.31,0.096
17.37,26.45,0.096
17.40,26.59,0.097
17.43,26.73,0.097
17.45,26.88,0.097
17.48,27.02,0.097
17.51,27.16,0.097
17.54,27.30,0.097
17.57,27.44,0.097
17.59,27.58,0.097
17.62,27.73,0.097
17.65,27.87,0.097
17.68,28.01,0.097
17.71,28.15,0.097
17.74,28.29,0.097
17.77,28.43,0.097
17.79,28.58,0.097
17.82,28.72,0.097
17.85,28.86,0.097
17.88,29.00,0.097
17.91,29.14,0.097
17.93,29.28,0.097
17.96,29.43,0.097
17.99,29.57,0.098
18.02,29.71,0.098
18.05,29.85,0.098
18.08,29.99,0.098
18.11,30.14,0.098
18.13,30.28,0.098
18.16,30.42,0.098
18.19,30.56,0.098
18.22,30.70,0.098
18.25,30.84,0.098
18.28,30.99,0.098
18.30,31.13,0.098
18.33,31.27,0.098
18.36,31.41,0.098
18.39,31.56,0.098
18.42,31.70,0.098
18.44,31.84,0.098
18.47,31.98,0.098
18.50,32.12,0.098
18.53,32.26,0.098
18.56,32.40,0.098
18.59,32.55,0.098
18.62,32.69,0.098
18.64,32.83,0.099
18.67,32.97,0.099
18.70,33.11,0.099
18.73,33.25,0.099
18.76,33.40,0.099
18.78,33.54,0.099
18.81,33.68,0.099
18.84,33.82,0.099
18.87,33.96,0.099
18.90,34.11,0.099
18.93,34.25,0.099
18.96,34.39,0.099
18.98,34.53,0.099
19.01,34.67,0.099
19.04,34.82,0.099
19.07,34.96,0.099
19.10,35.10,0.099
19.13,35.24,0.099
19.15,35.38,0.099
19.18,35.52,0.099
19.21,35.66,0.099
19.24,35.81,0.099
19.27,35.95,0.099
19.29,36.09,0.099
19.32,36.23,0.100
19.35,36.38,0.100
19.38,36.52,0.100
19.41,36.66,0.100
19.44,36.80,0.100
19.47,36.94,0.100
19.49,37.08,0.100
19.52,37.23,0.100
19.55,37.37,0.100
19.58,37.51,0.100
19.61,37.65,0.100
19.63,37.79,0.100
19.66,37.93,0.100
19.69,38.08,0.100
19.72,38.22,0.100
19.75,38.36,0.100
19.78,38.50,0.100
19.81,38.64,0.100
19.83,38.78,0.100
19.86,38.93,0.100
19.89,39.07,0.100
19.92,39.21,0.100
19.95,39.35,0.100
19.98,39.49,0.100
20.00,39.63,0.100
20.03,39.78,0.101
20.06,39.92,0.101
20.09,40.06,0.101
20.12,40.20,0.101
20.14,40.34,0.101
20.17,40.49,0.101
20.20,40.63,0.101
20.23,40.77,0.101
20.26,40.91,0.101
20.29,41.05,0.101
20.32,41.19,0.101
20.34,41.34,0.101
20.37,41.48,0.101
20.40,41.62,0.101
20.43,41.76,0.101
20.46,41.90,0.101
20.48,42.05,0.101
20.51,42.19,0.101
20.54,42.33,0.101
20.57,42.47,0.101
20.60,42.61,0.101
20.63,42.75,0.101
20.66,42.89,0.101
20.68,43.04,0.101
20.71,43.18,0.102
20.74,43.32,0.102
20.77,43.46,0.102
20.80,43.60,0.102
20.83,43.75,0.102
20.85,43.89,0.102
20.88,44.03,0.102
20.91,44.17,0.102
20.94,44.31,0.102
20.97,44.45,0.102
20.99,44.60,0.102
21.02,44.74,0.102
21.05,44.88,0.102
21.08,45.02,0.102
21.11,45.16,0.102
21.14,45.31,0.102
21.17,45.45,0.102
21.19,45.59,0.102
21.22,45.73,0.102
21.25,45.87,0.102
21.28,46.01,0.102
21.31,46.16,0.103
21.33,46.30,0.103
21.36,46.44,0.103
21.39,46.58,0.103
21.42,46.72,0.103
21.45,46.86,0.103
21.48,47.01,0.103
21.51,47.15,0.103
21.53,47.29,0.103
21.56,47.43,0.103
21.59,47.57,0.103
21.62,47.71,0.103
21.65,47.86,0.103
21.68,48.00,0.103
21.70,48.14,0.103
21.73,48.28,0.103
21.76,48.42,0.103
21.79,48.57,0.103
21.82,48.71,0.103
21.84,48.85,0.103
21.87,48.99,0.103
21.90,49.13,0.103
21.93,49.27,0.103
21.96,49.42,0.104
21.99,49.56,0.104
22.02,49.70,0.104
22.04,49.84,0.104
22.07,49.98,0.104
22.10,50.13,0.104
22.13,50.27,0.104
22.16,50.41,0.104
22.18,50.55,0.104
22.21,50.69,0.104
22.24,50.83,0.104
22.27,50.98,0.104
22.30,51.12,0.104
22.33,51.26,0.104
22.36,51.40,0.104
22.38,51.54,0.104
22.41,51.69,0.104
22.44,51.83,0.104
22.47,51.97,0.104
22.50,52.11,0.104
22.53,52.25,0.104
22.55,52.39,0.104
22.58,52.54,0.104
22.61,52.68,0.104
22.64,52.82,0.104
22.67,52.96,0.104
22.69,53.10,0.104
22.72,53.25,0.104
22.75,53.39,0.104
22.78,53.53,0.104
22.81,53.67,0.105
22.84,53.81,0.105
22.87,53.95,0.105
22.89,54.10,0.105
22.92,54.24,0.105
22.95,54.38,0.105
22.98,54.52,0.105
23.01,54.66,0.105
23.03,54.80,0.105
23.06,54.95,0.105
23.09,55.09,0.105
23.12,55.23,0.105
23.15,55.37,0.105
23.18,55.51,0.105
23.21,55.65,0.105
23.23,55.80,0.105
23.26,55.94,0.105
23.29,56.08,0.106
23.32,56.22,0.106
23.35,56.36,0.106
23.38,56.50,0.106
23.40,56.65,0.106
23.43,56.79,0.106
23.46,56.93,0.106
23.49,57.07,0.106
23.52,57.21,0.106
23.54,57.36,0.106
23.57,57.50,0.106
23.60,57.64,0.106
23.63,57.78,0.106
23.66,57.92,0.106
23.69,58.06,0.106
23.72,58.21,0.106
23.74,58.35,0.106
23.77,58.49,0.106
23.80,58.63,0.106
23.83,58.77,0.106
23.86,58.92,0.106
23.88,59.06,0.106
23.91,59.20,0.107
23.94,59.34,0.107
23.97,59.48,0.107
24.00,59.62,0.107
24.03,59.77,0.107
24.06,59.91,0.107
24.08,60.05,0.107
24.11,60.19,0.107
24.14,60.33,0.107
24.17,60.47,0.107
24.20,60.62,0.107
24.23,60.76,0.107
24.25,60.90,0.107
24.28,61.04,0.107
24.31,61.18,0.107
24.34,61.33,0.107
24.37,61.47,0.107
24.39,61.61,0.107
24.42,61.75,0.107
24.45,61.89,0.107
24.48,62.03,0.107
24.51,62.18,0.107
24.54,62.32,0.107
24.57,62.46,0.108
24.59,62.60,0.108
24.62,62.74,0.108
24.65,62.88,0.108
24.68,63.02,0.108
24.71,63.17,0.108
24.73,63.31,0.108
24.76,63.45,0.108
24.79,63.59,0.108
24.82,63.73,0.108
24.85,63.88,0.108
24.88,64.02,0.108
24.91,64.16,0.108
24.93,64.30,0.109
24.96,64.44,0.109
24.99,64.59,0.109
25.02,64.73,0.109
25.05,64.87,0.109
25.08,65.01,0.109
25.10,65.15,0.109
25.13,65.29,0.109
25.16,65.44,0.109
25.19,65.58,0.109
25.22,65.72,0.109
25.24,65.86,0.109
25.27,66.00,0.110
25.30,66.14,0.110
25.33,66.29,0.110
25.36,66.43,0.110
25.39,66.57,0.110
25.42,66.71,0.110
25.44,66.85,0.110
25.47,66.99,0.110
25.50,67.14,0.110
25.53,67.28,0.110
25.56,67.42,0.111
25.58,67.56,0.111
25.61,67.70,0.111
25.64,67.84,0.111
25.67,67.99,0.111
25.70,68.13,0.111
25.73,68.27,0.111
25.76,68.41,0.112
25.78,68.55,0.112
25.81,68.70,0.112
25.84,68.84,0.112
25.87,68.98,0.112
25.90,69.12,0.113
25.93,69.26,0.113
25.95,69.40,0.113
25.98,69.54,0.113
26.01,69.69,0.114
26.04,69.83,0.114
26.07,69.97,0.114
26.09,70.11,0.115
26.12,70.25,0.115
26.15,70.40,0.116
26.18,70.54,0.116
26.21,70.68,0.116
26.24,70.82,0.117
26.27,70.96,0.118
26.29,71.10,0.118
26.32,71.24,0.119
26.35,71.38,0.120
26.38,71.53,0.120
26.41,71.67,0.122
26.43,71.81,0.123
26.46,71.95,0.124
26.49,72.09,0.127
26.52,72.23,0.130
26.55,72.37,0.134
26.58,72.51,0.138
26.61,72.66,0.142
26.63,72.80,0.148
26.66,72.94,0.155
26.69,73.08,0.163
26.72,73.22,0.172
26.75,73.36,0.182
26.78,73.49,0.193
26.80,73.63,0.210
26.83,73.77,0.229
26.86,73.90,0.253
26.89,74.04,0.283
26.92,74.17,0.320
26.94,74.30,0.365
26.97,74.43,0.418
27.00,74.55,0.482
27.03,74.68,0.555
27.06,74.80,0.637
27.09,74.91,0.730
27.12,75.03,0.832
27.14,75.14,0.942
27.17,75.25,1.057
27.20,75.35,1.180
27.23,75.46,1.318
27.26,75.56,1.458
27.28,75.66,1.596
27.31,75.76,1.741
27.34,75.86,1.880
27.37,75.96,2.019
27.40,76.06,2.141
27.43,76.16,2.251
27.46,76.27,2.340
27.48,76.39,2.401
27.51,76.51,2.427
27.54,76.65,2.411
27.57,76.79,2.348
27.60,76.96,2.224
27.63,77.14,2.031
27.65,77.34,1.772
27.68,77.56,1.472
27.71,77.79,1.171
27.74,78.01,0.911
27.77,78.23,0.705
27.79,78.43,0.550
27.82,78.62,0.436
27.85,78.80,0.353
27.88,78.97,0.292
27.91,79.13,0.248
27.94,79.29,0.217
27.97,79.44,0.195
27.99,79.59,0.179
28.02,79.73,0.169
28.05,79.88,0.162
28.08,80.02,0.155
28.11,80.17,0.151
28.13,80.31,0.149
28.16,80.45,0.147
28.19,80.60,0.146
28.22,80.74,0.146
28.25,80.88,0.145
28.28,81.02,0.144
28.31,81.17,0.144
28.33,81.31,0.144
28.36,81.45,0.143
28.39,81.59,0.143
28.42,81.73,0.142
28.45,81.87,0.142
28.48,82.02,0.142
28.50,82.16,0.141
28.53,82.30,0.141
28.56,82.44,0.141
28.59,82.58,0.141
28.62,82.72,0.141
28.64,82.87,0.141
28.67,83.01,0.141
28.70,83.15,0.140
28.73,83.29,0.140
28.76,83.43,0.140
28.79,83.58,0.140
28.82,83.72,0.140
28.84,83.86,0.140
28.87,84.00,0.140
28.90,84.14,0.140
28.93,84.28,0.140
28.96,84.42,0.140
28.98,84.57,0.140
29.01,84.71,0.140
29.04,84.85,0.140
29.07,84.99,0.140
29.10,85.13,0.140
29.13,85.27,0.140
29.16,85.42,0.140
29.18,85.56,0.140
29.21,85.70,0.140
29.24,85.84,0.140
29.27,85.99,0.140
29.30,86.13,0.140
29.33,86.27,0.140
29.35,86.41,0.140
29.38,86.55,0.140
29.41,86.69,0.140
29.44,86.83,0.140
29.47,86.98,0.140
29.49,87.12,0.140
29.52,87.26,0.140
29.55,87.40,0.140
29.58,87.54,0.140
29.61,87.68,0.140
29.64,87.83,0.140
29.67,87.97,0.140
29.69,88.11,0.140
29.72,88.25,0.140
29.75,88.39,0.140
29.78,88.54,0.140
29.81,88.68,0.140
29.83,88.82,0.140
29.86,88.96,0.141
29.89,89.10,0.141
29.92,89.24,0.141
29.95,89.39,0.141
29.98,89.53,0.141
30.01,89.67,0.141
30.03,89.81,0.141
30.06,89.95,0.141
30.09,90.09,0.141
30.12,90.24,0.141
30.15,90.38,0.141
30.18,90.52,0.141
30.20,90.66,0.141
30.23,90.80,0.141
30.26,90.95,0.141
30.29,91.09,0.141
30.32,91.23,0.141
30.34,91.37,0.141
30.37,91.51,0.141
30.40,91.65,0.141
30.43,91.80,0.141
30.46,91.94,0.141
30.49,92.08,0.141
30.52,92.22,0.141
30.54,92.36,0.141
30.57,92.50,0.141
30.60,92.65,0.141
30.63,92.79,0.141
30.66,92.93,0.141
30.68,93.07,0.142
30.71,93.21,0.142
30.74,93.36,0.142
30.77,93.50,0.142
30.80,93.64,0.142
30.83,93.78,0.142
30.86,93.92,0.142
30.88,94.06,0.142
30.91,94.21,0.142
30.94,94.35,0.142
30.97,94.49,0.142
31.00,94.63,0.142
31.03,94.77,0.142
31.05,94.91,0.142
31.08,95.06,0.142
31.11,95.20,0.142
31.14,95.34,0.142
31.17,95.48,0.142
31.19,95.62,0.142
31.22,95.76,0.142
31.25,95.91,0.142
31.28,96.05,0.142
31.31,96.19,0.142
31.34,96.33,0.142
31.37,96.47,0.142
31.39,96.62,0.142
31.42,96.76,0.142
31.45,96.90,0.142
31.48,97.04,0.142
31.51,97.18,0.143
31.53,97.33,0.143
31.56,97.47,0.143
31.59,97.61,0.143
31.62,97.75,0.143
31.65,97.89,0.143
31.68,98.03,0.143
31.71,98.18,0.143
31.73,98.32,0.143
31.76,98.46,0.143
31.79,98.60,0.143
31.82,98.74,0.143
31.85,98.88,0.143
31.88,99.02,0.143
31.90,99.17,0.143
31.93,99.31,0.143
31.96,99.45,0.143
31.99,99.59,0.143
32.02,99.73,0.143
32.04,99.88,0.143
32.07,100.02,0.143
32.10,100.16,0.143
32.13,100.30,0.143
32.16,100.44,0.143
32.19,100.58,0.144
32.22,100.73,0.144
32.24,100.87,0.144
32.27,101.01,0.144
32.30,101.15,0.144
32.33,101.29,0.144
32.36,101.44,0.144
32.38,101.58,0.144
32.41,101.72,0.144
32.44,101.86,0.144
32.47,102.00,0.144
32.50,102.14,0.144
32.53,102.29,0.144
32.56,102.43,0.144
32.58,102.57,0.144
32.61,102.71,0.144
32.64,102.85,0.144
32.67,102.99,0.144
32.70,103.14,0.144
32.73,103.28,0.144
32.75,103.42,0.144
32.78,103.56,0.144
32.81,103.70,0.144
32.84,103.84,0.144
32.87,103.99,0.144
32.89,104.13,0.144
32.92,104.27,0.144
32.95,104.41,0.145
32.98,104.55,0.145
33.01,104.70,0.145
33.04,104.84,0.145
33.07,104.98,0.145
33.09,105.12,0.145
33.12,105.26,0.145
33.15,105.40,0.145
33.18,105.55,0.145
33.21,105.69,0.145
33.23,105.83,0.145
33.26,105.97,0.145
33.29,106.11,0.145
33.32,106.26,0.145
33.35,106.40,0.145
33.38,106.54,0.145
33.41,106.68,0.145
33.43,106.82,0.146
33.46,106.96,0.146
33.49,107.10,0.146
33.52,107.25,0.146
33.55,107.39,0.146
33.58,107.53,0.146
33.60,107.67,0.146
33.63,107.81,0.146
33.66,107.96,0.146
33.69,108.10,0.146
33.72,108.24,0.146
33.74,108.38,0.146
33.77,108.52,0.146
33.80,108.66,0.146
33.83,108.81,0.146
33.86,108.95,0.146
33.89,109.09,0.147
33.92,109.23,0.147
33.94,109.37,0.147
33.97,109.51,0.147
34.00,109.66,0.147
34.03,109.80,0.147
34.06,109.94,0.147
34.08,110.08,0.147
34.11,110.22,0.147
34.14,110.36,0.147
34.17,110.51,0.147
34.20,110.65,0.147
34.23,110.79,0.147
34.26,110.93,0.147
34.28,111.07,0.147
34.31,111.22,0.147
34.34,111.36,0.147
34.37,111.50,0.147
34.40,111.64,0.147
34.43,111.78,0.147
34.45,111.92,0.147
34.48,112.07,0.148
34.51,112.21,0.148
34.54,112.35,0.148
34.57,112.49,0.148
34.59,112.63,0.148
34.62,112.78,0.148
34.65,112.92,0.148
34.68,113.06,0.148
34.71,113.20,0.148
34.74,113.34,0.148
34.76,113.48,0.148
34.79,113.63,0.148
34.82,113.77,0.148
34.85,113.91,0.148
34.88,114.05,0.148
34.91,114.19,0.148
34.94,114.33,0.148
34.96,114.48,0.148
34.99,114.62,0.148
35.02,114.76,0.148
35.05,114.90,0.148
35.08,115.04,0.148
35.11,115.18,0.148
35.13,115.33,0.148
35.16,115.47,0.149
35.19,115.61,0.149
35.22,115.75,0.149
35.25,115.89,0.149
35.28,116.04,0.149
35.30,116.18,0.149
35.33,116.32,0.149
35.36,116.46,0.149
35.39,116.60,0.149
35.42,116.74,0.149
35.44,116.88,0.149
35.47,117.03,0.149
35.50,117.17,0.149
35.53,117.31,0.149
35.56,117.45,0.149
35.59,117.59,0.149
35.61,117.74,0.149
35.64,117.88,0.149
35.67,118.02,0.150
35.70,118.16,0.150
35.73,118.30,0.150
35.76,118.44,0.150
35.79,118.59,0.150
35.81,118.73,0.150
35.84,118.87,0.150
35.87,119.01,0.150
35.90,119.15,0.150
35.93,119.29,0.150
35.96,119.43,0.150
35.98,119.58,0.150
36.01,119.72,0.150
36.04,119.86,0.150
36.07,120.00,0.150
36.10,120.14,0.150
36.13,120.29,0.150
36.15,120.43,0.150
36.18,120.57,0.150
36.21,120.71,0.150
36.24,120.85,0.150
36.27,121.00,0.150
36.29,121.14,0.150
36.32,121.28,0.151
36.35,121.42,0.151
36.38,121.56,0.151
36.41,121.70,0.151
36.44,121.84,0.151
36.46,121.99,0.151
36.49,122.13,0.151
36.52,122.27,0.151
36.55,122.41,0.151
36.58,122.55,0.151
36.61,122.70,0.151
36.64,122.84,0.151
36.66,122.98,0.151
36.69,123.12,0.151
36.72,123.26,0.151
36.75,123.41,0.152
36.78,123.55,0.152
36.81,123.69,0.152
36.83,123.83,0.152
36.86,123.97,0.152
36.89,124.12,0.152
36.92,124.26,0.152
36.95,124.40,0.152
36.98,124.54,0.152
37.00,124.68,0.152
37.03,124.82,0.152
37.06,124.96,0.152
37.09,125.11,0.152
37.12,125.25,0.152
37.14,125.39,0.152
37.17,125.53,0.152
37.20,125.67,0.152
37.23,125.82,0.152
37.26,125.96,0.152
37.29,126.10,0.152
37.31,126.24,0.152
37.34,126.38,0.153
37.37,126.52,0.153
37.40,126.67,0.153
37.43,126.81,0.153
37.46,126.95,0.153
37.49,127.09,0.153
37.51,127.23,0.153
37.54,127.37,0.153
37.57,127.52,0.153
37.60,127.66,0.153
37.63,127.80,0.153
37.66,127.94,0.153
37.68,128.08,0.153
37.71,128.23,0.153
37.74,128.37,0.153
37.77,128.51,0.153
37.80,128.65,0.153
37.83,128.79,0.154
37.85,128.93,0.154
37.88,129.07,0.154
37.91,129.22,0.154
37.94,129.36,0.154
37.97,129.50,0.154
37.99,129.64,0.154
38.02,129.78,0.154
38.05,129.93,0.154
38.08,130.07,0.154
38.11,130.21,0.154
38.14,130.35,0.154
38.16,130.49,0.154
38.19,130.63,0.154
38.22,130.78,0.154
38.25,130.92,0.154
38.28,131.06,0.154
38.31,131.20,0.154
38.34,131.34,0.154
38.36,131.48,0.154
38.39,131.63,0.155
38.42,131.77,0.155
38.45,131.91,0.155
38.48,132.05,0.155
38.51,132.19,0.155
38.53,132.34,0.155
38.56,132.48,0.155
38.59,132.62,0.155
38.62,132.76,0.155
38.65,132.90,0.155
38.68,133.04,0.155
38.70,133.19,0.155
38.73,133.33,0.155
38.76,133.47,0.155
38.79,133.61,0.155
38.82,133.75,0.155
38.84,133.90,0.156
38.87,134.04,0.156
38.90,134.18,0.156
38.93,134.32,0.156
38.96,134.46,0.156
38.99,134.60,0.156
39.01,134.74,0.156
39.04,134.89,0.156
39.07,135.03,0.156
39.10,135.17,0.156
39.13,135.31,0.156
39.16,135.45,0.156
39.19,135.60,0.156
39.21,135.74,0.156
39.24,135.88,0.156
39.27,136.02,0.156
39.30,136.16,0.156
39.33,136.30,0.156
39.36,136.45,0.157
39.38,136.59,0.157
39.41,136.73,0.157
39.44,136.87,0.157
39.47,137.01,0.157
39.50,137.15,0.157
39.53,137.30,0.157
39.55,137.44,0.157
39.58,137.58,0.157
39.61,137.72,0.157
39.64,137.86,0.157
39.67,138.00,0.157
39.69,138.15,0.157
39.72,138.29,0.157
39.75,138.43,0.157
39.78,138.57,0.158
39.81,138.71,0.158
39.84,138.85,0.158
39.86,139.00,0.158
39.89,139.14,0.158
39.92,139.28,0.158
39.95,139.42,0.158
39.98,139.56,0.158
40.01,139.71,0.158
40.04,139.85,0.158
40.06,139.99,0.158
40.09,140.13,0.158
40.12,140.27,0.158
40.15,140.41,0.158
40.18,140.56,0.158
40.21,140.70,0.158
40.23,140.84,0.158
40.26,140.98,0.158
40.29,141.12,0.159
40.32,141.26,0.159
40.35,141.41,0.159
40.38,141.55,0.159
40.40,141.69,0.159
40.43,141.83,0.159
40.46,141.97,0.159
40.49,142.11,0.159
40.52,142.26,0.159
40.54,142.40,0.159
40.57,142.54,0.159
40.60,142.68,0.159
40.63,142.82,0.160
40.66,142.97,0.160
40.69,143.11,0.160
40.71,143.25,0.160
40.74,143.39,0.160
40.77,143.53,0.160
40.80,143.68,0.160
40.83,143.82,0.160
40.86,143.96,0.160
40.89,144.10,0.160
40.91,144.24,0.160
40.94,144.38,0.161
40.97,144.52,0.161
41.00,144.67,0.161
41.03,144.81,0.161
41.06,144.95,0.161
41.08,145.09,0.161
41.11,145.23,0.161
41.14,145.38,0.161
41.17,145.52,0.161
41.20,145.66,0.161
41.23,145.80,0.161
41.25,145.94,0.161
41.28,146.08,0.161
41.31,146.23,0.162
41.34,146.37,0.162
41.37,146.51,0.162
41.39,146.65,0.162
41.42,146.79,0.162
41.45,146.93,0.162
41.48,147.08,0.162
41.51,147.22,0.162
41.54,147.36,0.162
41.56,147.50,0.162
41.59,147.64,0.162
41.62,147.78,0.163
41.65,147.93,0.163
41.68,148.07,0.163
41.71,148.21,0.163
41.74,148.35,0.163
41.76,148.49,0.163
41.79,148.63,0.163
41.82,148.78,0.163
41.85,148.92,0.163
41.88,149.06,0.163
41.91,149.20,0.164
41.93,149.34,
41.96,149.48,
41.99,,

[step]
Ramp 50.00 °C/min to -60.00 °C
Time,Temperature,Heat Flow (Normalized)
min,°C,W/g
42.99,150.16,-0.021
42.99,150.16,-0.021
42.99,150.16,-0.021
43.00,150.16,-0.021
43.00,150.16,-0.021
43.00,150.15,-0.021
43.01,150.15,-0.021
43.01,150.15,-0.021
43.01,150.15,-0.021
43.02,150.14,-0.021
43.02,150.14,-0.021
43.02,150.13,-0.021
43.03,150.12,-0.022
43.03,150.11,-0.022
43.03,150.10,-0.022
43.04,150.08,-0.023
43.04,150.07,-0.023
43.04,150.05,-0.024
43.05,150.02,-0.025
43.05,150.00,-0.027
43.05,149.97,-0.030
43.06,149.94,-0.037
43.06,149.90,-0.046
43.06,149.86,-0.053
43.07,149.81,-0.061
43.07,149.76,-0.070
43.07,149.71,-0.082
43.08,149.65,-0.095
43.08,149.59,-0.110
43.08,149.53,-0.128
43.09,149.46,-0.148
43.09,149.38,-0.169
43.09,149.31,-0.192
43.10,149.22,-0.217
43.10,149.14,-0.243
43.10,149.05,-0.269
43.11,148.96,-0.298
43.11,148.87,-0.329
43.11,148.77,-0.360
43.12,148.67,-0.393
43.12,148.56,-0.426
43.12,148.45,-0.459
43.13,148.34,-0.494
43.13,148.23,-0.529
43.13,148.11,-0.564
43.14,147.99,-0.601
43.14,147.87,-0.638
43.14,147.74,-0.674
43.15,147.62,-0.710
43.15,147.49,-0.746
43.15,147.36,-0.782
43.16,147.22,-0.819
43.16,147.09,-0.854
43.16,146.95,-0.889
43.17,146.81,-0.924
43.17,146.67,-0.958
43.17,146.52,-0.992
43.18,146.38,-1.027
43.18,146.23,-1.060
43.18,146.08,-1.092
43.19,145.94,-1.124
43.19,145.79,-1.155
43.19,145.64,-1.186
43.20,145.49,-1.215
43.20,145.34,-1.244
43.20,145.18,-1.271
43.21,145.03,-1.298
43.21,144.88,-1.323
43.21,144.73,-1.347
43.22,144.57,-1.369
43.22,144.42,-1.391
43.22,144.27,-1.410
43.23,144.11,-1.430
43.23,143.96,-1.448
43.23,143.80,-1.465
43.24,143.65,-1.481
43.24,143.49,-1.495
43.24,143.34,-1.508
43.25,143.18,-1.522
43.25,143.03,-1.534
43.25,142.87,-1.547
43.26,142.71,-1.558
43.26,142.56,-1.568
43.26,142.40,-1.578
43.27,142.24,-1.587
43.27,142.08,-1.597
43.27,141.93,-1.606
43.28,141.77,-1.614
43.28,141.61,-1.622
43.28,141.45,-1.630
43.29,141.29,-1.637
43.29,141.13,-1.644
43.29,140.97,-1.651
43.30,140.81,-1.658
43.30,140.65,-1.665
43.30,140.49,-1.671
43.31,140.33,-1.677
43.31,140.17,-1.684
43.31,140.01,-1.689
43.32,139.85,-1.696
43.32,139.69,-1.702
43.32,139.52,-1.707
43.33,139.36,-1.713
43.33,139.20,-1.717
43.33,139.04,-1.721
43.34,138.88,-1.726
43.34,138.72,-1.730
43.34,138.55,-1.734
43.35,138.39,-1.739
43.35,138.23,-1.743
43.35,138.07,-1.747
43.36,137.90,-1.750
43.36,137.74,-1.754
43.36,137.58,-1.757
43.37,137.42,-1.760
43.37,137.25,-1.763
43.37,137.09,-1.765
43.38,136.93,-1.768
43.38,136.76,-1.771
43.38,136.60,-1.775
43.39,136.44,-1.777
43.39,136.28,-1.779
43.39,136.11,-1.780
43.40,135.95,-1.782
43.40,135.78,-1.784
43.40,135.62,-1.786
43.41,135.46,-1.789
43.41,135.29,-1.791
43.41,135.13,-1.793
43.42,134.97,-1.795
43.42,134.80,-1.797
43.42,134.64,-1.799
43.43,134.48,-1.800
43.43,134.31,-1.801
43.43,134.15,-1.803
43.44,133.98,-1.804
43.44,133.82,-1.805
43.44,133.66,-1.806
43.45,133.49,-1.807
43.45,133.33,-1.808
43.45,133.16,-1.810
43.46,133.00,-1.812
43.46,132.83,-1.812
43.46,132.67,-1.813
43.47,132.51,-1.814
43.47,132.34,-1.816
43.47,132.18,-1.817
43.48,132.01,-1.819
43.48,131.85,-1.819
43.48,131.68,-1.820
43.49,131.52,-1.820
43.49,131.35,-1.820
43.49,131.19,-1.821
43.50,131.03,-1.821
43.50,130.86,-1.822
43.50,130.70,-1.823
43.51,130.53,-1.823
43.51,130.37,-1.825
43.51,130.20,-1.826
43.52,130.04,-1.826
43.52,129.87,-1.827
43.52,129.71,-1.827
43.53,129.54,-1.827
43.53,129.38,-1.828
43.53,129.21,-1.828
43.54,129.05,-1.828
43.54,128.88,-1.829
43.54,128.72,-1.829
43.55,128.55,-1.829
43.55,128.39,-1.829
43.55,128.22,-1.830
43.56,128.06,-1.830
43.56,127.89,-1.831
43.56,127.73,-1.831
43.57,127.56,-1.832
43.57,127.40,-1.832
43.57,127.23,-1.832
43.58,127.07,-1.832
43.58,126.90,-1.832
43.58,126.74,-1.833
43.59,126.57,-1.833
43.59,126.41,-1.833
43.59,126.24,-1.834
43.60,126.08,-1.834
43.60,125.91,-1.834
43.60,125.75,-1.834
43.61,125.58,-1.834
43.61,125.42,-1.834
43.61,125.25,-1.835
43.62,125.08,-1.835
43.62,124.92,-1.835
43.62,124.75,-1.835
43.63,124.59,-1.835
43.63,124.42,-1.835
43.63,124.26,-1.835
43.64,124.09,-1.835
43.64,123.93,-1.835
43.64,123.76,-1.835
43.65,123.60,-1.835
43.65,123.43,-1.835
43.65,123.27,-1.835
43.66,123.10,-1.836
43.66,122.94,-1.836
43.66,122.77,-1.836
43.67,122.61,-1.836
43.67,122.44,-1.836
43.67,122.28,-1.836
43.68,122.11,-1.836
43.68,121.94,-1.836
43.68,121.78,-1.836
43.69,121.61,-1.836
43.69,121.45,-1.836
43.69,121.28,-1.836
43.70,121.12,-1.836
43.70,120.95,-1.836
43.70,120.79,-1.836
43.71,120.62,-1.836
43.71,120.45,-1.836
43.71,120.29,-1.836
43.72,120.12,-1.836
43.72,119.96,-1.836
43.72,119.79,-1.836
43.73,119.63,-1.836
43.73,119.46,-1.836
43.73,119.30,-1.836
43.74,119.13,-1.836
43.74,118.97,-1.836
43.74,118.80,-1.837
43.75,118.63,-1.837
43.75,118.47,-1.837
43.75,118.30,-1.837
43.76,118.14,-1.837
43.76,117.97,-1.837
43.76,117.81,-1.837
43.77,117.64,-1.837
43.77,117.47,-1.837
43.77,117.31,-1.837
43.78,117.14,-1.837
43.78,116.98,-1.837
43.78,116.81,-1.837
43.79,116.65,-1.837
43.79,116.48,-1.837
43.79,116.32,-1.837
43.80,116.15,-1.837
43.80,115.98,-1.837
43.80,115.82,-1.837
43.81,115.65,-1.837
43.81,115.49,-1.837
43.81,115.32,-1.837
43.82,115.15,-1.837
43.82,114.99,-1.837
43.82,114.82,-1.837
43.83,114.66,-1.837
43.83,114.49,-1.837
43.83,114.33,-1.837
43.84,114.16,-1.837
43.84,114.00,-1.837
43.84,113.83,-1.837
43.85,113.66,-1.837
43.85,113.50,-1.837
43.85,113.33,-1.837
43.86,113.17,-1.837
43.86,113.00,-1.837
43.86,112.84,-1.837
43.87,112.67,-1.837
43.87,112.50,-1.837
43.87,112.34,-1.837
43.88,112.17,-1.837
43.88,112.01,-1.837
43.88,111.84,-1.837
43.89,111.68,-1.837
43.89,111.51,-1.836
43.89,111.34,-1.836
43.90,111.18,-1.836
43.90,111.01,-1.836
43.90,110.85,-1.836
43.91,110.68,-1.836
43.91,110.51,-1.836
43.91,110.35,-1.836
43.92,110.18,-1.836
43.92,110.02,-1.836
43.92,109.85,-1.836
43.93,109.69,-1.836
43.93,109.52,-1.836
43.93,109.36,-1.836
43.94,109.19,-1.836
43.94,109.02,-1.835
43.94,108.86,-1.835
43.95,108.69,-1.835
43.95,108.53,-1.835
43.95,108.36,-1.835
43.96,108.19,-1.835
43.96,108.03,-1.835
43.96,107.86,-1.835
43.97,107.70,-1.835
43.97,107.53,-1.835
43.97,107.37,-1.835
43.98,107.20,-1.834
43.98,107.03,-1.834
43.98,106.87,-1.833
43.99,106.70,-1.833
43.99,106.54,-1.832
43.99,106.37,-1.832
44.00,106.21,-1.832
44.00,106.04,-1.832
44.00,105.88,-1.832
44.01,105.71,-1.831
44.01,105.54,-1.831
44.01,105.38,-1.831
44.02,105.21,-1.831
44.02,105.05,-1.830
44.02,104.88,-1.830
44.03,104.72,-1.830
44.03,104.55,-1.829
44.03,104.39,-1.829
44.04,104.22,-1.829
44.04,104.05,-1.828
44.04,103.89,-1.828
44.05,103.72,-1.828
44.05,103.56,-1.828
44.05,103.39,-1.827
44.06,103.23,-1.827
44.06,103.06,-1.827
44.06,102.89,-1.826
44.07,102.73,-1.826
44.07,102.56,-1.826
44.07,102.40,-1.826
44.08,102.23,-1.825
44.08,102.07,-1.825
44.08,101.90,-1.824
44.09,101.74,-1.823
44.09,101.57,-1.823
44.09,101.41,-1.823
44.10,101.24,-1.823
44.10,101.07,-1.823
44.10,100.91,-1.822
44.11,100.74,-1.822
44.11,100.58,-1.822
44.11,100.41,-1.821
44.12,100.25,-1.821
44.12,100.08,-1.821
44.12,99.91,-1.820
[...]
157.94,38.22,0.136,1.450
157.97,38.36,0.136,1.450
158.00,38.50,0.136,1.451
158.02,38.64,0.136,1.451
158.05,38.79,0.136,1.452
158.08,38.93,0.136,1.452
158.11,39.07,0.136,1.452
158.14,39.21,0.136,1.452
158.17,39.35,0.136,1.452
158.19,39.49,0.136,1.450
158.22,39.64,0.136,1.450
158.25,39.78,0.136,1.450
158.28,39.92,0.136,1.450
158.31,40.06,0.136,1.452
158.33,40.20,0.136,1.451
158.36,40.34,0.136,1.451
158.39,40.49,0.136,1.452
158.42,40.63,0.136,1.452
158.45,40.77,0.136,1.453
158.48,40.91,0.136,1.452
158.50,41.06,0.136,1.452
158.53,41.20,0.136,1.453
158.56,41.34,0.136,1.454
158.59,41.48,0.136,1.454
158.62,41.62,0.136,1.455
158.65,41.76,0.136,1.456
158.68,41.90,0.136,1.457
158.70,42.05,0.136,1.456
158.73,42.19,0.136,1.457
158.76,42.33,0.136,1.455
158.79,42.47,0.137,1.456
158.82,42.61,0.137,1.456
158.85,42.76,0.137,1.457
158.87,42.90,0.137,1.457
158.90,43.04,0.137,1.457
158.93,43.18,0.137,1.456
158.96,43.32,0.137,1.457
158.99,43.47,0.137,1.459
159.02,43.61,0.137,1.458
159.04,43.75,0.137,1.458
159.07,43.89,0.137,1.459
159.10,44.03,0.137,1.459
159.13,44.17,0.137,1.460
159.16,44.31,0.137,1.460
159.18,44.46,0.137,1.458
159.21,44.60,0.137,1.459
159.24,44.74,0.137,1.459
159.27,44.88,0.137,1.459
159.30,45.02,0.137,1.459
159.33,45.17,0.137,1.459
159.35,45.31,0.137,1.461
159.38,45.45,0.137,1.462
159.41,45.59,0.137,1.462
159.44,45.73,0.137,1.463
159.47,45.87,0.137,1.463
159.50,46.02,0.137,1.464
159.53,46.16,0.137,1.465
159.55,46.30,0.137,1.465
159.58,46.44,0.138,1.469
159.61,46.58,0.143,1.520
159.64,46.72,0.142,1.516
159.67,46.87,0.142,1.512
159.70,47.01,0.142,1.507
159.72,47.15,0.141,1.505
159.75,47.29,0.141,1.500
159.78,47.43,0.141,1.497
159.81,47.58,0.141,1.494
159.84,47.72,0.140,1.492
159.87,47.86,0.140,1.493
159.89,48.00,0.140,1.491
159.92,48.14,0.140,1.487
159.95,48.28,0.140,1.489
159.98,48.43,0.140,1.488
160.01,48.57,0.140,1.488
160.03,48.71,0.139,1.486
160.06,48.85,0.139,1.482
160.09,48.99,0.139,1.481
160.12,49.13,0.139,1.483
160.15,49.28,0.139,1.482
160.18,49.42,0.139,1.480
160.20,49.56,0.139,1.480
160.23,49.70,0.139,1.480
160.26,49.84,0.139,1.483
160.29,49.99,0.139,1.483
160.32,50.13,0.139,1.483
160.35,50.27,0.139,1.483
160.38,50.41,0.139,1.483
160.40,50.55,0.139,1.482
160.43,50.69,0.139,1.482
160.46,50.83,0.139,1.482
160.49,50.98,0.139,1.482
160.52,51.12,0.139,1.483
160.55,51.26,0.139,1.483
160.57,51.40,0.139,1.483
160.60,51.55,0.139,1.484
160.63,51.69,0.139,1.484
160.66,51.83,0.139,1.485
160.69,51.97,0.139,1.484
160.72,52.11,0.139,1.485
160.74,52.25,0.139,1.485
160.77,52.40,0.139,1.486
160.80,52.54,0.139,1.486
160.83,52.68,0.139,1.485
160.86,52.82,0.139,1.485
160.88,52.96,0.139,1.485
160.91,53.10,0.139,1.486
160.94,53.25,0.139,1.486
160.97,53.39,0.139,1.486
161.00,53.53,0.140,1.487
161.03,53.67,0.140,1.487
161.05,53.81,0.140,1.488
161.08,53.95,0.140,1.489
161.11,54.10,0.140,1.488
161.14,54.24,0.140,1.489
161.17,54.38,0.140,1.489
161.20,54.52,0.140,1.490
161.23,54.66,0.140,1.490
161.25,54.81,0.140,1.491
161.28,54.95,0.140,1.490
161.31,55.09,0.140,1.491
161.34,55.23,0.140,1.491
161.37,55.37,0.140,1.492
161.40,55.52,0.140,1.491
161.42,55.66,0.140,1.492
161.45,55.80,0.140,1.493
161.48,55.94,0.140,1.494
161.51,56.08,0.140,1.494
161.54,56.22,0.140,1.493
161.57,56.36,0.140,1.494
161.59,56.51,0.140,1.494
161.62,56.65,0.140,1.496
161.65,56.79,0.140,1.496
161.68,56.93,0.140,1.497
161.71,57.07,0.140,1.497
161.73,57.22,0.140,1.498
161.76,57.36,0.140,1.499
161.79,57.50,0.140,1.499
161.82,57.64,0.140,1.498
161.85,57.78,0.140,1.499
161.88,57.92,0.140,1.497
161.90,58.07,0.140,1.498
161.93,58.21,0.140,1.498
161.96,58.35,0.140,1.498
161.99,58.49,0.140,1.499
162.02,58.63,0.141,1.499
162.05,58.78,0.141,1.499
162.08,58.92,0.141,1.499
162.10,59.06,0.141,1.499
162.13,59.20,0.141,1.500
162.16,59.34,0.141,1.500
162.19,59.49,0.141,1.501
162.22,59.63,0.141,1.501
162.25,59.77,0.141,1.501
162.27,59.91,0.141,1.501
162.30,60.05,0.141,1.502
162.33,60.19,0.141,1.502
162.36,60.34,0.141,1.502
162.39,60.48,0.141,1.502
162.42,60.62,0.141,1.503
162.44,60.76,0.141,1.503
162.47,60.90,0.141,1.503
162.50,61.04,0.141,1.504
162.53,61.19,0.141,1.504
162.56,61.33,0.141,1.505
162.58,61.47,0.141,1.506
162.61,61.61,0.141,1.505
162.64,61.75,0.141,1.506
162.67,61.89,0.141,1.507
162.70,62.04,0.141,1.508
162.73,62.18,0.141,1.508
162.75,62.32,0.141,1.508
162.78,62.46,0.141,1.509
162.81,62.60,0.141,1.510
162.84,62.74,0.141,1.510
162.87,62.89,0.141,1.510
162.90,63.03,0.141,1.511
162.93,63.17,0.141,1.512
162.95,63.31,0.142,1.512
162.98,63.45,0.142,1.513
163.01,63.59,0.142,1.512
163.04,63.74,0.142,1.512
163.07,63.88,0.142,1.512
163.10,64.02,0.142,1.511
163.12,64.16,0.142,1.510
163.15,64.30,0.142,1.510
163.18,64.44,0.142,1.510
163.21,64.59,0.142,1.511
163.24,64.73,0.142,1.510
163.27,64.87,0.142,1.510
163.29,65.01,0.142,1.512
163.32,65.16,0.142,1.513
163.35,65.30,0.142,1.515
163.38,65.44,0.142,1.516
163.41,65.58,0.142,1.518
163.43,65.72,0.142,1.519
163.46,65.86,0.142,1.519
163.49,66.01,0.142,1.519
163.52,66.15,0.142,1.519
163.55,66.29,0.142,1.518
163.58,66.43,0.142,1.518
163.60,66.57,0.142,1.518
163.63,66.71,0.142,1.517
163.66,66.86,0.142,1.518
163.69,67.00,0.142,1.518
163.72,67.14,0.142,1.518
163.75,67.28,0.142,1.518
163.78,67.42,0.143,1.519
163.80,67.56,0.143,1.519
163.83,67.71,0.143,1.521
163.86,67.85,0.143,1.522
163.89,67.99,0.143,1.523
163.92,68.13,0.143,1.522
163.95,68.27,0.143,1.524
163.97,68.42,0.143,1.524
164.00,68.56,0.143,1.524
164.03,68.70,0.143,1.523
164.06,68.84,0.143,1.523
164.09,68.98,0.143,1.522
164.12,69.13,0.143,1.524
164.14,69.27,0.143,1.524
164.17,69.41,0.143,1.525
164.20,69.55,0.143,1.525
164.23,69.69,0.143,1.527
164.26,69.83,0.143,1.527
164.28,69.98,0.143,1.526
164.31,70.12,0.143,1.526
164.34,70.26,0.143,1.526
164.37,70.40,0.143,1.527
164.40,70.54,0.143,1.526
164.43,70.68,0.143,1.527
164.45,70.83,0.143,1.526
164.48,70.97,0.143,1.529
164.51,71.11,0.143,1.528
164.54,71.25,0.143,1.530
164.57,71.39,0.143,1.528
164.60,71.53,0.143,1.530
164.63,71.68,0.143,1.530
164.65,71.82,0.143,1.530
164.68,71.96,0.143,1.529
164.71,72.10,0.143,1.530
164.74,72.24,0.143,1.529
164.77,72.38,0.143,1.530
164.80,72.53,0.144,1.530
164.82,72.67,0.144,1.530
164.85,72.81,0.144,1.531
164.88,72.95,0.144,1.532
164.91,73.09,0.144,1.532
164.94,73.24,0.144,1.533
164.97,73.38,0.144,1.534
164.99,73.52,0.144,1.535
165.02,73.66,0.144,1.534
165.05,73.80,0.144,1.535
165.08,73.94,0.144,1.535
165.11,74.09,0.144,1.535
165.13,74.23,0.144,1.535
165.16,74.37,0.144,1.535
165.19,74.51,0.144,1.535
165.22,74.65,0.144,1.534
165.25,74.79,0.144,1.535
165.28,74.94,0.144,1.534
165.30,75.08,0.144,1.534
165.33,75.22,0.144,1.536
165.36,75.36,0.144,1.535
165.39,75.50,0.144,1.535
165.42,75.65,0.144,1.536
165.45,75.79,0.144,1.536
165.48,75.93,0.144,1.536
165.50,76.07,0.144,1.537
165.53,76.21,0.144,1.537
165.56,76.36,0.144,1.540
165.59,76.50,0.144,1.540
165.62,76.64,0.145,1.542
165.65,76.78,0.144,1.542
165.67,76.92,0.145,1.543
165.70,77.06,0.145,1.543
165.73,77.21,0.145,1.544
165.76,77.35,0.145,1.543
165.79,77.49,0.145,1.543
165.82,77.63,0.145,1.543
165.84,77.77,0.145,1.544
165.87,77.91,0.145,1.545
165.90,78.05,0.145,1.544
165.93,78.20,0.145,1.544
165.96,78.34,0.145,1.543
165.98,78.48,0.145,1.544
166.01,78.62,0.145,1.543
166.04,78.76,0.145,1.544
166.07,78.91,0.145,1.545
166.10,79.05,0.145,1.546
166.13,79.19,0.145,1.547
166.15,79.33,0.145,1.548
166.18,79.47,0.145,1.549
166.21,79.62,0.145,1.549
166.24,79.76,0.145,1.550
166.27,79.90,0.145,1.549
166.30,80.04,0.145,1.549
166.33,80.18,0.145,1.550
166.35,80.32,0.145,1.550
166.38,80.47,0.145,1.550
166.41,80.61,0.145,1.551
166.44,80.75,0.145,1.552
166.47,80.89,0.145,1.552
166.50,81.03,0.145,1.551
166.52,81.17,0.145,1.551
166.55,81.32,0.145,1.552
166.58,81.46,0.145,1.551
166.61,81.60,0.145,1.551
166.64,81.74,0.145,1.550
166.67,81.88,0.145,1.551
166.69,82.02,0.145,1.551
166.72,82.17,0.145,1.552
166.75,82.31,0.146,1.553
166.78,82.45,0.146,1.552
166.81,82.59,0.146,1.553
166.83,82.73,0.146,1.553
166.86,82.88,0.146,1.552
166.89,83.02,0.146,1.552
166.92,83.16,0.146,1.551
166.95,83.30,0.146,1.550
166.98,83.44,0.146,1.551
167.00,83.59,0.146,1.551
167.03,83.73,0.146,1.552
167.06,83.87,0.146,1.554
167.09,84.01,0.146,1.554
167.12,84.15,0.146,1.555
167.15,84.30,0.146,1.556
167.18,84.44,0.146,1.556
167.20,84.58,0.146,1.556
167.23,84.72,0.146,1.557
167.26,84.86,0.146,1.557
167.29,85.00,0.146,1.557
167.32,85.15,0.146,1.558
167.35,85.29,0.146,1.560
167.37,85.43,0.146,1.561
167.40,85.57,0.146,1.561
167.43,85.71,0.146,1.559
167.46,85.85,0.146,1.558
167.49,86.00,0.146,1.559
167.52,86.14,0.146,1.559
167.54,86.28,0.146,1.560
167.57,86.42,0.146,1.559
167.60,86.56,0.146,1.559
167.63,86.70,0.146,1.560
167.66,86.85,0.146,1.561
167.68,86.99,0.146,1.562
167.71,87.13,0.146,1.561
167.74,87.27,0.146,1.560
167.77,87.41,0.146,1.561
167.80,87.56,0.146,1.561
167.83,87.70,0.146,1.562
167.85,87.84,0.146,1.561
167.88,87.98,0.146,1.560
167.91,88.12,0.146,1.561
167.94,88.26,0.146,1.560
167.97,88.41,0.146,1.561
168.00,88.55,0.146,1.561
168.03,88.69,0.146,1.561
168.05,88.83,0.146,1.563
168.08,88.97,0.146,1.564
168.11,89.11,0.146,1.563
168.14,89.26,0.146,1.564
168.17,89.40,0.147,1.565
168.20,89.54,0.147,1.564
168.22,89.68,0.147,1.565
168.25,89.82,0.147,1.564
168.28,89.96,0.147,1.565
168.31,90.11,0.147,1.565
168.34,90.25,0.147,1.566
168.37,90.39,0.147,1.567
168.39,90.53,0.147,1.567
168.42,90.67,0.147,1.567
168.45,90.81,0.147,1.568
168.48,90.96,0.147,1.568
168.51,91.10,0.147,1.567
168.53,91.24,0.147,1.567
168.56,91.38,0.147,1.567
168.59,91.52,0.147,1.566
168.62,91.66,0.147,1.566
168.65,91.81,0.147,1.567
168.68,91.95,0.147,1.567
168.70,92.09,0.147,1.569
168.73,92.23,0.147,1.569
168.76,92.37,0.147,1.571
168.79,92.52,0.147,1.573
168.82,92.66,0.147,1.574
168.85,92.80,0.147,1.573
168.88,92.94,0.147,1.574
168.90,93.08,0.147,1.573
168.93,93.22,0.147,1.573
168.96,93.37,0.147,1.572
168.99,93.51,0.147,1.571
169.02,93.65,0.147,1.570
169.05,93.79,0.147,1.570
169.07,93.93,0.147,1.571
169.10,94.07,0.147,1.571
169.13,94.22,0.148,1.572
169.16,94.36,0.148,1.573
169.19,94.50,0.148,1.574
169.22,94.64,0.148,1.575
169.24,94.78,0.148,1.575
169.27,94.92,0.148,1.574
169.30,95.07,0.148,1.575
169.33,95.21,0.148,1.576
169.36,95.35,0.148,1.576
169.38,95.49,0.148,1.577
169.41,95.64,0.148,1.578
169.44,95.78,0.148,1.579
169.47,95.92,0.148,1.581
169.50,96.06,0.148,1.581
169.53,96.20,0.148,1.580
169.55,96.34,0.148,1.579
169.58,96.48,0.148,1.579
169.61,96.63,0.148,1.578
169.64,96.77,0.148,1.578
169.67,96.91,0.148,1.578
169.70,97.05,0.148,1.578
169.73,97.19,0.148,1.579
169.75,97.34,0.148,1.581
169.78,97.48,0.148,1.580
169.81,97.62,0.148,1.581
169.84,97.76,0.148,1.581
169.87,97.90,0.148,1.581
169.90,98.04,0.148,1.582
169.92,98.19,0.149,1.582
169.95,98.33,0.149,1.584
169.98,98.47,0.149,1.584
170.01,98.61,0.149,1.585
170.04,98.75,0.149,1.585
170.07,98.89,0.149,1.585
170.09,99.04,0.149,1.585
170.12,99.18,0.149,1.585
170.15,99.32,0.149,1.585
170.18,99.46,0.149,1.585
170.21,99.60,0.149,1.586
170.23,99.75,0.149,1.586
170.26,99.89,0.149,1.587
170.29,100.03,0.149,1.588
170.32,100.17,0.149,1.587
170.35,100.31,0.149,1.588
170.38,100.45,0.149,1.588
170.40,100.60,0.149,1.588
170.43,100.74,0.149,1.590
170.46,100.88,0.149,1.591
170.49,101.02,0.149,1.590
170.52,101.16,0.149,1.590
170.55,101.30,0.149,1.590
170.58,101.45,0.149,1.591
170.60,101.59,0.149,1.593
170.63,101.73,0.149,1.592
170.66,101.87,0.149,1.592
170.69,102.01,0.149,1.592
170.72,102.15,0.150,1.591
170.75,102.30,0.150,1.591
170.77,102.44,0.150,1.591
170.80,102.58,0.150,1.590
170.83,102.72,0.150,1.592
170.86,102.86,0.150,1.593
170.89,103.01,0.150,1.595
170.92,103.15,0.150,1.597
170.94,103.29,0.150,1.598
170.97,103.43,0.150,1.597
171.00,103.57,0.150,1.597
171.03,103.71,0.150,1.595
171.06,103.86,0.150,1.594
171.08,104.00,0.150,1.595
171.11,104.14,0.150,1.594
171.14,104.28,0.150,1.595
171.17,104.42,0.150,1.597
171.20,104.57,0.150,1.598
171.23,104.71,0.150,1.599
171.25,104.85,0.150,1.600
171.28,104.99,0.150,1.599
171.31,105.13,0.150,1.600
171.34,105.27,0.150,1.600
171.37,105.42,0.150,1.600
171.40,105.56,0.150,1.601
171.43,105.70,0.150,1.599
171.45,105.84,0.150,1.599
171.48,105.98,0.150,1.599
171.51,106.12,0.150,1.601
171.54,106.27,0.150,1.601
171.57,106.41,0.150,1.601
171.60,106.55,0.150,1.601
171.62,106.69,0.151,1.602
171.65,106.83,0.151,1.603
171.68,106.98,0.151,1.602
171.71,107.12,0.151,1.603
171.74,107.26,0.151,1.604
171.77,107.40,0.151,1.602
171.79,107.54,0.151,1.603
171.82,107.68,0.151,1.603
171.85,107.82,0.151,1.603
171.88,107.97,0.151,1.603
171.91,108.11,0.151,1.604
171.93,108.25,0.151,1.603
171.96,108.39,0.151,1.605
171.99,108.53,0.151,1.605
172.02,108.68,0.151,1.605
172.05,108.82,0.151,1.607
172.08,108.96,0.151,1.608
172.10,109.10,0.151,1.607
172.13,109.24,0.151,1.606
172.16,109.38,0.151,1.607
172.19,109.53,0.151,1.607
172.22,109.67,0.151,1.607
172.25,109.81,0.151,1.607
172.28,109.95,0.151,1.607
172.30,110.09,0.151,1.606
172.33,110.23,0.151,1.607
172.36,110.38,0.151,1.607
172.39,110.52,0.151,1.610
172.42,110.66,0.151,1.610
172.45,110.80,0.151,1.612
172.47,110.94,0.152,1.614
172.50,111.09,0.152,1.615
172.53,111.23,0.152,1.615
172.56,111.37,0.152,1.615
172.59,111.51,0.152,1.614
172.62,111.65,0.152,1.614
172.64,111.79,0.152,1.612
172.67,111.93,0.152,1.612
172.70,112.08,0.152,1.612
172.73,112.22,0.152,1.611
172.76,112.36,0.152,1.612
172.78,112.50,0.152,1.611
172.81,112.64,0.152,1.612
172.84,112.79,0.152,1.613
172.87,112.93,0.152,1.613
172.90,113.07,0.152,1.614
172.93,113.21,0.152,1.616
172.95,113.35,0.152,1.616
172.98,113.49,0.152,1.617
173.01,113.64,0.152,1.618
173.04,113.78,0.152,1.618
173.07,113.92,0.152,1.620
173.10,114.06,0.152,1.620
173.13,114.20,0.152,1.620
173.15,114.34,0.152,1.621
173.18,114.49,0.152,1.620
173.21,114.63,0.152,1.620
173.24,114.77,0.152,1.620
173.27,114.91,0.152,1.620
173.30,115.05,0.152,1.621
173.32,115.20,0.152,1.622
173.35,115.34,0.153,1.622
173.38,115.48,0.153,1.622
173.41,115.62,0.153,1.622
173.44,115.76,0.153,1.621
173.47,115.90,0.153,1.622
173.49,116.05,0.153,1.623
173.52,116.19,0.153,1.622
173.55,116.33,0.153,1.624
173.58,116.47,0.153,1.623
173.61,116.61,0.153,1.625
173.63,116.75,0.153,1.626
173.66,116.90,0.153,1.625
173.69,117.04,0.153,1.626
173.72,117.18,0.153,1.626
173.75,117.32,0.153,1.627
173.78,117.46,0.153,1.629
173.80,117.61,0.153,1.630
173.83,117.75,0.153,1.631
173.86,117.89,0.153,1.632
173.89,118.03,0.154,1.631
173.92,118.17,0.154,1.633
173.95,118.31,0.154,1.632
173.98,118.46,0.154,1.632
174.00,118.60,0.154,1.631
174.03,118.74,0.154,1.631
174.06,118.88,0.154,1.631
174.09,119.02,0.154,1.632
174.12,119.16,0.154,1.633
174.15,119.31,0.154,1.634
174.17,119.45,0.154,1.635
174.20,119.59,0.154,1.635
174.23,119.73,0.154,1.636
174.26,119.87,0.154,1.636
174.29,120.02,0.154,1.636
174.32,120.16,0.154,1.637
174.34,120.30,0.154,1.637
174.37,120.44,0.154,1.638
174.40,120.58,0.154,1.639
174.43,120.72,0.154,1.639
174.46,120.86,0.154,1.641
174.48,121.01,0.154,1.641
174.51,121.15,0.154,1.640
174.54,121.29,0.155,1.641
174.57,121.43,0.155,1.641
174.60,121.57,0.155,1.642
174.63,121.72,0.155,1.642
174.65,121.86,0.155,1.642
174.68,122.00,0.155,1.643
174.71,122.14,0.155,1.643
174.74,122.28,0.155,1.644
174.77,122.43,0.155,1.645
174.80,122.57,0.155,1.647
174.83,122.71,0.155,1.647
174.85,122.85,0.155,1.648
174.88,122.99,0.155,1.649
174.91,123.13,0.155,1.650
174.94,123.28,0.155,1.649
174.97,123.42,0.155,1.649
175.00,123.56,0.155,1.650
175.02,123.70,0.155,1.649
175.05,123.84,0.156,1.649
175.08,123.98,0.156,1.650
175.11,124.13,0.156,1.651
175.14,124.27,0.156,1.652
175.17,124.41,0.156,1.653
175.19,124.55,0.156,1.655
175.22,124.69,0.156,1.655
175.25,124.84,0.156,1.657
175.28,124.98,0.156,1.656
175.31,125.12,0.156,1.658
175.33,125.26,0.156,1.658
175.36,125.40,0.156,1.658
175.39,125.54,0.156,1.657
175.42,125.68,0.156,1.658
175.45,125.83,0.156,1.658
175.48,125.97,0.156,1.658
175.50,126.11,0.157,1.658
175.53,126.25,0.157,1.659
175.56,126.40,0.157,1.659
175.59,126.54,0.157,1.661
175.62,126.68,0.157,1.661
175.65,126.82,0.157,1.662
175.68,126.96,0.157,1.663
175.70,127.10,0.157,1.665
175.73,127.25,0.157,1.668
175.76,127.39,0.157,1.669
175.79,127.53,0.157,1.669
175.82,127.67,0.157,1.670
175.85,127.81,0.157,1.670
175.87,127.95,0.157,1.669
175.90,128.10,0.157,1.669
175.93,128.24,0.157,1.668
175.96,128.38,0.157,1.669
175.99,128.52,0.157,1.670
176.02,128.66,0.157,1.671
176.04,128.80,0.158,1.672
176.07,128.95,0.158,1.674
176.10,129.09,0.158,1.674
176.13,129.23,0.158,1.674
176.16,129.37,0.158,1.673
176.18,129.51,0.158,1.673
176.21,129.65,0.158,1.673
176.24,129.79,0.158,1.673
176.27,129.94,0.158,1.674
176.30,130.08,0.158,1.674
176.33,130.22,0.158,1.674
176.35,130.36,0.158,1.675
176.38,130.50,0.158,1.676
176.41,130.65,0.158,1.678
176.44,130.79,0.158,1.679
176.47,130.93,0.159,1.680
176.50,131.07,0.159,1.681
176.53,131.21,0.159,1.682
176.55,131.36,0.159,1.682
176.58,131.50,0.159,1.683
176.61,131.64,0.159,1.684
176.64,131.78,0.159,1.685
176.67,131.92,0.159,1.686
176.70,132.06,0.159,1.685
176.72,132.20,0.159,1.684
176.75,132.35,0.159,1.685
176.78,132.49,0.159,1.685
176.81,132.63,0.159,1.685
176.84,132.77,0.159,1.687
176.87,132.91,0.159,1.689
176.89,133.06,0.160,1.694
176.92,133.20,0.160,1.695
176.95,133.34,0.160,1.696
176.98,133.48,0.160,1.696
177.01,133.62,0.160,1.697
177.03,133.76,0.160,1.697
177.06,133.90,0.160,1.695
177.09,134.05,0.160,1.694
177.12,134.19,0.160,1.694
177.15,134.33,0.160,1.694
177.18,134.47,0.160,1.697
177.20,134.61,0.160,1.699
177.23,134.76,0.160,1.699
177.26,134.90,0.160,1.701
177.29,135.04,0.160,1.701
177.32,135.18,0.160,1.702
177.35,135.32,0.161,1.703
177.38,135.46,0.161,1.702
177.40,135.61,0.161,1.702
177.43,135.75,0.161,1.702
177.46,135.89,0.161,1.703
177.49,136.03,0.161,1.703
177.52,136.17,0.161,1.704
177.55,136.31,0.161,1.704
177.57,136.46,0.161,1.704
177.60,136.60,0.161,1.706
177.63,136.74,0.161,1.706
177.66,136.88,0.161,1.706
177.69,137.02,0.161,1.708
177.72,137.17,0.162,1.709
177.74,137.31,0.162,1.711
177.77,137.45,0.162,1.714
177.80,137.59,0.162,1.715
177.83,137.73,0.162,1.718
177.86,137.87,0.162,1.719
177.88,138.02,0.162,1.719
177.91,138.16,0.162,1.719
177.94,138.30,0.162,1.718
177.97,138.44,0.162,1.717
178.00,138.58,0.162,1.718
178.03,138.72,0.162,1.718
178.05,138.86,0.162,1.718
178.08,139.01,0.162,1.719
178.11,139.15,0.163,1.720
178.14,139.29,0.163,1.720
178.17,139.43,0.163,1.720
178.20,139.57,0.163,1.720
178.23,139.72,0.163,1.723
178.25,139.86,0.163,1.726
178.28,140.00,0.163,1.726
178.31,140.14,0.163,1.726
178.34,140.28,0.163,1.727
178.37,140.42,0.163,1.728
178.40,140.57,0.163,1.729
178.42,140.71,0.163,1.730
178.45,140.85,0.163,1.730
178.48,140.99,0.164,1.731
178.51,141.13,0.164,1.732
178.54,141.28,0.164,1.734
178.57,141.42,0.164,1.734
178.59,141.56,0.164,1.736
178.62,141.70,0.164,1.736
178.65,141.84,0.164,1.737
178.68,141.98,0.164,1.738
178.71,142.12,0.164,1.737
178.73,142.27,0.164,1.737
178.76,142.41,0.164,1.737
178.79,142.55,0.164,1.738
178.82,142.69,0.164,1.737
178.85,142.83,0.164,1.737
178.88,142.98,0.164,1.738
178.90,143.12,0.165,1.740
178.93,143.26,0.165,1.741
178.96,143.40,0.165,1.742
178.99,143.54,0.165,1.744
179.02,143.68,0.165,1.746
179.05,143.83,0.165,1.746
179.08,143.97,0.165,1.746
179.10,144.11,0.165,1.748
179.13,144.25,0.165,1.749
179.16,144.39,0.165,1.748
179.19,144.53,0.165,1.748
179.22,144.68,0.165,1.749
179.25,144.82,0.165,1.751
179.27,144.96,0.166,1.752
179.30,145.10,0.166,1.752
179.33,145.24,0.166,1.752
179.36,145.38,0.166,1.753
179.39,145.53,0.166,1.753
179.42,145.67,0.166,1.754
179.44,145.81,0.166,1.754
179.47,145.95,0.166,1.754
179.50,146.09,0.166,1.756
179.53,146.24,0.166,1.757
179.56,146.38,0.167,1.760
179.58,146.52,0.167,1.762
179.61,146.66,0.167,1.764
179.64,146.80,0.167,1.767
179.67,146.94,0.167,1.768
179.70,147.09,0.167,1.767
179.73,147.23,0.167,1.768
179.75,147.37,0.167,1.768
179.78,147.51,0.167,1.769
179.81,147.65,0.167,1.768
179.84,147.79,0.167,1.768
179.87,147.94,0.168,1.770
179.90,148.08,0.168,1.773
179.93,148.22,0.168,1.774
179.95,148.36,0.168,1.777
179.98,148.50,0.168,1.778
180.01,148.64,0.168,1.780
180.04,148.79,0.168,1.779
180.07,148.93,0.168,1.777
180.10,149.07,0.168,
180.12,149.21,0.168,
180.15,149.35,,
180.18,149.49,,
180.19,,,