File: DSC/Earl/2025_10_04_Indium_Std_5Cmin.csv
Filename,2025_10_04_Indium_Std_5Cmin
Instrument name,DSC2A-00468 (192.168.1.100)
Operator,JLY
rundate,10/4/2025
Sample name,2025_10_04_Indium_Std_5Cmin
proceduresegments,Data Off ; Equilibrate -60.00 °C; Data On ; Ramp 5.00 °C/min to 200.00 °C; Data Off ; Isothermal 1.0 min; Data On ; Ramp 5.00 °C/min to -60.00 °C; Data Off ; Isothermal 1.0 min; Data On ; Ramp 5.00 °C/min to 200.00 °C; Data Off ; Isothermal 1.0 min; Ramp 5.00 °C/min to -60.00 °C; Data Off ; Isothermal 1.0 min; Data On ; Ramp 5.00 °C/min to 200.00 °C
[File Parameters]
Run date,10/4/2025 6:22:25 PM
Trios version,5.1.1.46572
Original File Name,D:\DSC2500\JYarger\2025_10_04_Indium_Std_5Cmin(1).tri
Current File Name,D:\DSC2500\JYarger\2025_10_04_Indium_Std_5Cmin.tri
[Procedure]
Procedure Name,Indium_n60C_200C_5Cmin_3
Sample Name,2025_10_04_Indium_Std_5Cmin
Sample Mass,5.57 mg
Reference Sample Mass,0 mg
Pan Mass,32.19 mg
Pan Number,3
Reference Pan Mass,32.55 mg
Reference Pan Number,1
Pan Type,Aluminum
Comments,DSC_Samples_Y2_Tray_ASDs_Pharma_Oct2025 Google Sheet.
Project Name,Amorphous Pharma
Operator,JLY
Test,Custom
Unload Max Temperature,30
Unload Min Temperature,30
Load Max Temperature,30
Load Min Temperature,30
Stop on Gas Flow Error,Yes
[Signal List]
Signal #1,Time (min)
Signal #2,Temperature (°C)
Signal #3,Heat Flow (mW)
Signal #4,Delta T (µV)
Signal #5,Delta Tzero (µV)
Signal #6,Tzero Temperature (°C)
Signal #7,Cell Purge (mL/min)
Signal #8,Heater Temp (°C)
Signal #9,Power Delivered (W)
Signal #10,Reference Junction Temperature (°C)
Signal #11,Flange Temperature (°C)
Signal #12,Heat Flow Phase (rad)
Signal #13,Total Heat Capacity (J/°C)
Signal #14,Heat Capacity (J/°C)
[Configuration]
Company Name,ASU
Instrument Name,DSC2A-00468
Instrument Type,DSC2500
Serial Number,DSC2A-00468
IP,192.168.1.100
Location of Instrument,MRRC
DisplayType,Unknown
Sample Interval ,0.1 s/pt
Selected Heat Flow,T4P
Exotherm Direction,Down
Cell Serial,DRC2-00792
Lid Type,Standard
Cooler,RCS 90
Leave Cooler on at End of Sequence,On
Gas 2,Nitrogen
Gas Selected,Channel 1
Flow Rate,50 mL/min
Secondary Purge,On
Licensed Heat Flow,Heat Flow T4P
Modulation Licensed,Yes
[Versions]
Common IDD Version,1
Cortex Version,VER 2.10.2.31
Driver,5.0.0.6
GDM Version,1.0.3.3
TouchscreenVersion,1.0.0.16145
FEP Version,1.2.1.21
FEP Bootloader,2.0.0.5
AutoSampler Version,2.1.1.26
Auto Sampler Bootloader,2.0.0.5
FCM Version,1.1.0.3
FCM Bootloader,2.0.0.5
[Experiment Logs]
Experiment Log Entry # 1,Data On set to 0
Experiment Log Entry # 3,Equilibrate Segment -60 (C) Started
Experiment Log Entry # 5,Air Cool is off.
Experiment Log Entry # 7,Data On set to 1
Experiment Log Entry # 9,Ramp Segment 5 C/min to 200 Started
Experiment Log Entry # 11,Data On set to 0
Experiment Log Entry # 13,Isothermal Segment 1 min started
Experiment Log Entry # 15,Data On set to 1
Experiment Log Entry # 17,Ramp Segment 5 C/min to -60 Started
Experiment Log Entry # 19,Data On set to 0
Experiment Log Entry # 21,Isothermal Segment 1 min started
Experiment Log Entry # 23,Data On set to 1
Experiment Log Entry # 25,Ramp Segment 5 C/min to 200 Started
Experiment Log Entry # 27,Data On set to 0
Experiment Log Entry # 29,Isothermal Segment 1 min started
Experiment Log Entry # 31,Ramp Segment 5 C/min to -60 Started
Experiment Log Entry # 33,Data On set to 0
Experiment Log Entry # 35,Isothermal Segment 1 min started
Experiment Log Entry # 37,Data On set to 1
Experiment Log Entry # 39,Ramp Segment 5 C/min to 200 Started
[Method Log]
Method Log Entry # 1,Data Off
Method Log Entry # 2,Equilibrate -60 °C
Method Log Entry # 3,Data On
Method Log Entry # 4,(Ramp 1766) Ramp 5 °C/minute to 200 °C
Method Log Entry # 5,Data Off
Method Log Entry # 6,Isothermal 1 minutes
Method Log Entry # 7,Data On
Method Log Entry # 8,(Ramp 1770) Ramp 5 °C/minute to -60 °C
Method Log Entry # 9,Data Off
Method Log Entry # 10,Isothermal 1 minutes
Method Log Entry # 11,Data On
Method Log Entry # 12,(Ramp 1774) Ramp 5 °C/minute to 200 °C
Method Log Entry # 13,Data Off
Method Log Entry # 14,Isothermal 1 minutes
Method Log Entry # 15,(Ramp 1777) Ramp 5 °C/minute to -60 °C
Method Log Entry # 16,Data Off
Method Log Entry # 17,Isothermal 1 minutes
Method Log Entry # 18,Data On
Method Log Entry # 19,(Ramp 1781) Ramp 5 °C/minute to 200 °C
Cell Serial,DRC2-00792
[T1 Calibration]
Slope,-0.008529666
Offset,9.636258
Initial Temperature,98.23
GUID,f8bfdadc-4977-4fdf-ba6d-0ba9134940c3
[TZero Calibration]
Date Applied,11/29/2022 4:06:13 PM
Description,From -89.059 °C to 396.009 °C at 20.000°C/min
Gas Type,Nitrogen
Pan Type,None
Source Files 1,C:\Users\yargerlab\Desktop\DSC Data\General\TZero_calibration_11_29_22_2nd(2).tri
Source Files 2,C:\Users\yargerlab\Desktop\DSC Data\General\TZero_calibration_11_29_22_2nd(3).tri
Delta T Offset,13.05235
Delta T Slope,-0.007271007
Delta T0 Offset,-13.69128
Delta T0 Slope,0.06063341
[Temperature Calibration]
Date Applied,11/29/2022 7:12:28 PM
Description,From 106.590 °C to 186.590 °C at 10.000°C/min
Gas Type,Nitrogen
Pan Type,Tzero Aluminum Hermetic
Source Files 1,C:\Users\yargerlab\Desktop\DSC Data\General\Indium(6).tri
Measured 1,157.391
Known 1,156.598
[Cell Constant Calibration]
Date Applied,11/29/2022 7:12:29 PM
Description,From 106.590 °C to 186.590 °C at 10.000°C/min
Gas Type,Nitrogen
Pan Type,Tzero Aluminum Hermetic
Source Files 1,C:\Users\yargerlab\Desktop\DSC Data\General\Indium(6).tri
T4P KCell,1.006051
Onset Slope,63.26126 mW/°C
[Direct Cp Calibration]
Date Applied,11/30/2022 11:04:51 AM
Description,From -79.983 °C to 298.409 °C at 10.000°C/min
Gas Type,Nitrogen
Pan Type,Tzero Aluminum Hermetic
Source Files 1,C:\Users\yargerlab\Desktop\DSC Data\General\Sapphire_Heat_Capacity_11_30_22.tri
[Rev Cp Calibration]
Date Applied,11/30/2022 1:58:51 PM
Description,From -79.996 °C to 292.812 °C at 3.000°C/min
Gas Type,Nitrogen
Pan Type,Tzero Aluminum Hermetic
Source Files 1,C:\Users\yargerlab\Desktop\DSC Data\General\Sapphire_MDSC_Calibration_11_30_22.tri
[step]
Ramp 5.00 °C/min to 200.00 °C
Time,Temperature,Heat Flow (Normalized)
min,°C,W/g
0.00,-59.85,-0.018
0.03,-59.86,-0.017
0.07,-59.83,-0.009
0.11,-59.76,0.006
0.14,-59.63,0.016
0.18,-59.49,0.023
0.21,-59.33,0.026
0.24,-59.17,0.028
0.28,-59.00,0.029
0.31,-58.83,0.030
0.35,-58.66,0.030
0.39,-58.49,0.031
0.42,-58.32,0.031
0.45,-58.15,0.032
0.49,-57.98,0.032
0.53,-57.81,0.032
0.56,-57.63,0.032
0.60,-57.46,0.033
0.63,-57.29,0.033
0.67,-57.12,0.033
0.70,-56.94,0.033
0.73,-56.77,0.033
0.77,-56.59,0.033
0.80,-56.42,0.033
0.84,-56.25,0.033
0.88,-56.08,0.033
0.91,-55.90,0.033
0.95,-55.73,0.033
0.98,-55.55,0.033
1.02,-55.38,0.033
1.05,-55.21,0.033
1.08,-55.03,0.033
1.12,-54.85,0.033
1.16,-54.68,0.033
1.19,-54.51,0.033
1.23,-54.33,0.033
1.26,-54.16,0.033
1.29,-53.98,0.033
1.33,-53.81,0.033
1.37,-53.63,0.033
1.40,-53.46,0.033
1.43,-53.28,0.033
1.47,-53.11,0.033
1.51,-52.93,0.032
1.54,-52.76,0.032
1.58,-52.58,0.032
1.61,-52.41,0.032
1.64,-52.24,0.032
1.68,-52.06,0.032
1.72,-51.88,0.032
1.75,-51.71,0.032
1.78,-51.54,0.032
1.82,-51.36,0.032
1.86,-51.19,0.032
1.89,-51.01,0.032
1.93,-50.83,0.031
1.96,-50.66,0.031
1.99,-50.49,0.031
2.03,-50.31,0.031
2.07,-50.14,0.031
2.10,-49.96,0.031
2.14,-49.79,0.031
2.17,-49.61,0.031
2.21,-49.44,0.031
2.24,-49.26,0.031
2.28,-49.09,0.031
2.31,-48.91,0.031
2.34,-48.74,0.031
2.38,-48.56,0.030
2.41,-48.39,0.030
2.45,-48.21,0.030
2.49,-48.04,0.030
2.52,-47.86,0.030
2.56,-47.69,0.030
2.59,-47.51,0.030
2.63,-47.34,0.030
2.66,-47.16,0.030
2.69,-46.99,0.030
2.73,-46.81,0.030
2.76,-46.64,0.030
2.80,-46.46,0.030
2.84,-46.29,0.030
2.87,-46.11,0.030
2.91,-45.94,0.030
2.94,-45.76,0.030
2.98,-45.59,0.030
3.01,-45.41,0.029
3.04,-45.24,0.029
3.08,-45.06,0.029
3.11,-44.89,0.029
3.15,-44.71,0.029
3.19,-44.54,0.029
3.22,-44.36,0.029
3.26,-44.19,0.029
3.29,-44.01,0.029
3.33,-43.84,0.029
3.36,-43.66,0.029
3.39,-43.49,0.029
3.43,-43.31,0.029
3.46,-43.14,0.029
3.50,-42.96,0.029
3.54,-42.79,0.029
3.57,-42.61,0.029
3.61,-42.44,0.029
3.64,-42.26,0.029
3.68,-42.09,0.028
3.71,-41.91,0.028
3.74,-41.74,0.028
3.78,-41.56,0.028
3.81,-41.39,0.028
3.85,-41.21,0.028
3.89,-41.04,0.028
3.92,-40.86,0.028
3.96,-40.69,0.028
3.99,-40.51,0.028
4.03,-40.33,0.028
4.06,-40.16,0.028
4.09,-39.98,0.028
4.13,-39.81,0.028
4.16,-39.64,0.028
4.20,-39.46,0.028
4.24,-39.29,0.028
4.27,-39.11,0.028
4.30,-38.94,0.028
4.34,-38.76,0.028
4.38,-38.59,0.028
4.41,-38.41,0.028
4.45,-38.23,0.028
4.48,-38.06,0.028
4.51,-37.89,0.028
4.55,-37.71,0.027
4.59,-37.53,0.027
4.62,-37.36,0.027
4.65,-37.18,0.027
4.69,-37.01,0.027
4.73,-36.83,0.027
4.76,-36.66,0.027
4.80,-36.48,0.027
4.83,-36.31,0.027
4.86,-36.13,0.027
4.90,-35.96,0.027
4.94,-35.78,0.027
4.97,-35.61,0.027
5.00,-35.43,0.027
5.04,-35.25,0.027
5.08,-35.08,0.027
5.11,-34.90,0.027
5.15,-34.73,0.027
5.18,-34.55,0.027
5.21,-34.38,0.027
5.25,-34.20,0.027
5.29,-34.03,0.027
5.32,-33.85,0.027
5.35,-33.68,0.027
5.39,-33.50,0.027
5.43,-33.33,0.027
5.46,-33.15,0.026
5.50,-32.98,0.026
5.53,-32.80,0.026
5.56,-32.62,0.026
5.60,-32.45,0.026
5.64,-32.28,0.026
5.67,-32.10,0.026
5.70,-31.93,0.026
5.74,-31.75,0.026
5.78,-31.57,0.026
5.81,-31.40,0.026
5.85,-31.22,0.026
5.88,-31.05,0.026
5.91,-30.87,0.026
5.95,-30.70,0.026
5.99,-30.52,0.026
6.02,-30.35,0.026
6.05,-30.17,0.026
6.09,-30.00,0.026
6.13,-29.82,0.026
6.16,-29.65,0.026
6.20,-29.47,0.026
6.23,-29.30,0.026
6.26,-29.12,0.026
6.30,-28.95,0.026
6.34,-28.77,0.026
6.37,-28.59,0.026
6.40,-28.42,0.026
6.44,-28.24,0.026
6.48,-28.07,0.026
6.51,-27.89,0.026
6.55,-27.72,0.025
6.58,-27.54,0.025
6.61,-27.37,0.025
6.65,-27.19,0.025
6.69,-27.02,0.025
6.72,-26.84,0.025
6.75,-26.67,0.025
6.79,-26.49,0.025
6.83,-26.32,0.025
6.86,-26.14,0.025
6.90,-25.97,0.025
6.93,-25.79,0.025
6.96,-25.62,0.025
7.00,-25.44,0.025
7.04,-25.27,0.025
7.07,-25.09,0.025
7.10,-24.92,0.025
7.14,-24.74,0.025
7.18,-24.57,0.025
7.21,-24.39,0.025
7.25,-24.21,0.025
7.28,-24.04,0.025
7.31,-23.86,0.025
7.35,-23.69,0.025
7.39,-23.51,0.025
7.42,-23.34,0.025
7.45,-23.16,0.025
7.49,-22.99,0.025
7.53,-22.81,0.025
7.56,-22.64,0.024
7.60,-22.46,0.024
7.63,-22.29,0.024
7.66,-22.11,0.024
7.70,-21.94,0.024
7.74,-21.76,0.024
7.77,-21.59,0.024
7.80,-21.41,0.024
7.84,-21.24,0.024
7.88,-21.06,0.024
7.91,-20.88,0.024
7.95,-20.71,0.024
7.98,-20.54,0.024
8.01,-20.36,0.024
8.05,-20.18,0.024
8.09,-20.01,0.024
8.12,-19.83,0.024
8.15,-19.66,0.024
8.19,-19.48,0.024
8.23,-19.31,0.024
8.26,-19.13,0.024
8.30,-18.96,0.024
8.33,-18.78,0.024
8.36,-18.61,0.024
8.40,-18.43,0.024
8.44,-18.26,0.024
8.47,-18.08,0.024
8.50,-17.91,0.024
8.54,-17.73,0.024
8.58,-17.56,0.024
8.61,-17.38,0.024
8.65,-17.21,0.024
8.68,-17.03,0.024
8.72,-16.86,0.024
8.75,-16.68,0.024
8.78,-16.51,0.024
8.82,-16.33,0.024
8.85,-16.15,0.024
8.89,-15.98,0.023
8.93,-15.81,0.023
8.96,-15.63,0.023
9.00,-15.45,0.023
9.03,-15.28,0.023
9.07,-15.10,0.023
9.10,-14.93,0.023
9.13,-14.75,0.023
9.17,-14.58,0.023
9.20,-14.40,0.023
9.24,-14.23,0.023
9.28,-14.06,0.023
9.31,-13.88,0.023
9.35,-13.70,0.023
9.38,-13.53,0.023
9.42,-13.35,0.023
9.45,-13.18,0.023
9.48,-13.00,0.023
9.52,-12.83,0.023
9.55,-12.65,0.023
9.59,-12.48,0.023
9.63,-12.30,0.023
9.66,-12.13,0.023
9.70,-11.95,0.023
9.73,-11.77,0.023
9.77,-11.60,0.023
9.80,-11.43,0.023
9.83,-11.25,0.023
9.87,-11.08,0.023
9.90,-10.90,0.023
9.94,-10.72,0.023
9.98,-10.55,0.023
10.01,-10.37,0.023
10.05,-10.20,0.023
10.08,-10.02,0.023
10.12,-9.85,0.023
10.15,-9.67,0.023
10.18,-9.50,0.023
10.22,-9.32,0.023
10.25,-9.15,0.023
10.29,-8.97,0.023
10.33,-8.80,0.023
10.36,-8.62,0.023
10.40,-8.45,0.023
10.43,-8.27,0.023
10.47,-8.10,0.023
10.50,-7.92,0.022
10.53,-7.75,0.022
10.57,-7.57,0.022
10.60,-7.40,0.022
10.64,-7.22,0.022
10.68,-7.05,0.022
10.71,-6.87,0.022
10.75,-6.70,0.022
10.78,-6.52,0.022
10.82,-6.35,0.022
10.85,-6.17,0.022
10.88,-5.99,0.022
10.92,-5.82,0.022
10.95,-5.65,0.022
10.99,-5.47,0.022
11.03,-5.30,0.022
11.06,-5.13,0.022
11.10,-4.95,0.022
11.13,-4.77,0.022
11.17,-4.60,0.022
11.20,-4.42,0.022
11.23,-4.25,0.022
11.27,-4.07,0.022
11.30,-3.90,0.022
11.34,-3.72,0.022
11.38,-3.55,0.022
11.41,-3.37,0.022
11.45,-3.20,0.022
11.48,-3.02,0.022
11.52,-2.85,0.022
11.55,-2.67,0.022
11.58,-2.50,0.022
11.62,-2.32,0.022
11.65,-2.14,0.022
11.69,-1.97,0.022
11.73,-1.79,0.022
11.76,-1.62,0.022
11.80,-1.44,0.022
11.83,-1.27,0.022
11.87,-1.09,0.022
11.90,-0.92,0.022
11.93,-0.74,0.022
11.97,-0.57,0.022
12.00,-0.39,0.022
12.04,-0.22,0.021
12.08,-0.04,0.021
12.11,0.13,0.021
12.15,0.31,0.021
12.18,0.49,0.021
12.22,0.66,0.021
12.25,0.84,0.021
12.28,1.02,0.021
12.32,1.19,0.021
12.35,1.37,0.021
12.39,1.54,0.021
12.43,1.72,0.021
12.46,1.89,0.021
12.50,2.07,0.021
12.53,2.24,0.021
12.57,2.42,0.021
12.60,2.59,0.021
12.63,2.77,0.021
12.67,2.94,0.021
12.70,3.12,0.021
12.74,3.29,0.021
12.78,3.47,0.021
12.81,3.64,0.021
12.85,3.82,0.021
12.88,3.99,0.021
12.92,4.17,0.021
12.95,4.34,0.021
12.98,4.52,0.021
13.02,4.69,0.021
13.05,4.87,0.021
13.09,5.04,0.021
13.13,5.22,0.021
13.16,5.39,0.021
13.20,5.57,0.021
13.23,5.74,0.021
13.27,5.92,0.021
13.30,6.09,0.021
13.33,6.27,0.021
13.37,6.44,0.021
13.40,6.62,0.021
13.44,6.79,0.021
13.48,6.97,0.020
13.51,7.14,0.020
13.55,7.32,0.020
13.58,7.49,0.020
13.62,7.67,0.020
13.65,7.84,0.020
13.68,8.02,0.020
13.72,8.19,0.020
13.75,8.37,0.020
13.79,8.54,0.020
13.83,8.72,0.020
13.86,8.89,0.020
13.90,9.07,0.020
13.93,9.25,0.020
13.97,9.42,0.020
14.00,9.59,0.020
14.03,9.77,0.020
14.07,9.95,0.020
14.10,10.12,0.020
14.14,10.30,0.020
14.18,10.47,0.020
14.21,10.65,0.020
14.25,10.82,0.020
14.28,11.00,0.020
14.32,11.17,0.020
14.35,11.35,0.020
14.38,11.52,0.020
14.42,11.70,0.020
14.45,11.87,0.020
14.49,12.05,0.020
14.53,12.23,0.020
14.56,12.40,0.020
14.60,12.57,0.020
14.63,12.75,0.020
14.67,12.93,0.020
14.70,13.10,0.020
14.73,13.28,0.020
14.77,13.45,0.020
14.80,13.63,0.020
14.84,13.80,0.020
14.88,13.98,0.020
14.91,14.15,0.020
14.95,14.33,0.020
14.98,14.50,0.020
15.02,14.68,0.020
15.05,14.85,0.020
15.08,15.03,0.020
15.12,15.20,0.020
15.15,15.38,0.020
15.19,15.55,0.020
15.23,15.73,0.020
15.26,15.90,0.020
15.30,16.08,0.020
15.33,16.25,0.020
15.37,16.43,0.020
15.40,16.60,0.020
15.43,16.78,0.020
15.47,16.96,0.020
15.50,17.13,0.020
15.54,17.31,0.019
15.58,17.48,0.019
15.61,17.66,0.019
15.65,17.83,0.019
15.68,18.00,0.019
15.72,18.18,0.019
15.75,18.35,0.019
15.78,18.53,0.019
15.82,18.71,0.019
15.85,18.88,0.019
15.89,19.06,0.019
15.93,19.23,0.019
15.96,19.41,0.019
16.00,19.58,0.019
16.03,19.76,0.019
16.07,19.93,0.019
16.10,20.11,0.019
16.13,20.28,0.019
16.17,20.46,0.019
16.20,20.63,0.019
16.24,20.81,0.019
16.28,20.98,0.019
16.31,21.16,0.019
16.35,21.33,0.019
16.38,21.51,0.019
16.42,21.68,0.019
16.45,21.86,0.019
16.48,22.03,0.019
16.52,22.21,0.019
16.55,22.38,0.019
16.59,22.56,0.019
16.63,22.73,0.019
16.66,22.91,0.019
16.70,23.08,0.019
16.73,23.26,0.019
16.77,23.43,0.019
16.80,23.61,0.019
16.83,23.78,0.019
16.87,23.96,0.019
16.90,24.13,0.019
16.94,24.31,0.019
16.98,24.49,0.019
17.01,24.66,0.019
17.05,24.84,0.019
17.08,25.01,0.019
17.12,25.19,0.019
17.15,25.36,0.019
17.18,25.54,0.019
17.22,25.71,0.019
17.26,25.89,0.019
17.29,26.06,0.019
17.33,26.24,0.019
17.36,26.41,0.019
17.39,26.59,0.019
17.43,26.76,0.019
17.47,26.94,0.019
17.50,27.11,0.019
17.53,27.29,0.019
17.57,27.46,0.019
17.61,27.64,0.019
17.64,27.81,0.019
17.68,27.99,0.019
17.71,28.16,0.019
17.74,28.34,0.019
17.78,28.51,0.019
17.82,28.69,0.019
17.85,28.86,0.019
17.88,29.04,0.019
17.92,29.21,0.019
17.96,29.39,0.019
17.99,29.56,0.019
18.03,29.74,0.019
18.06,29.92,0.018
18.09,30.09,0.018
18.13,30.27,0.019
18.17,30.44,0.018
18.20,30.62,0.018
18.23,30.79,0.018
18.27,30.97,0.018
18.31,31.14,0.018
18.34,31.32,0.018
18.38,31.49,0.018
18.41,31.67,0.018
18.44,31.84,0.018
18.48,32.02,0.018
18.52,32.19,0.018
18.55,32.37,0.018
18.58,32.54,0.018
18.62,32.72,0.018
18.66,32.89,0.018
18.69,33.07,0.018
18.73,33.24,0.018
18.76,33.42,0.018
18.79,33.59,0.018
18.83,33.77,0.018
18.87,33.94,0.018
18.90,34.12,0.018
18.93,34.29,0.018
18.97,34.47,0.018
19.01,34.64,0.018
19.04,34.82,0.018
19.08,34.99,0.018
19.11,35.17,0.018
19.14,35.35,0.018
19.18,35.52,0.018
19.22,35.70,0.018
19.25,35.87,0.018
19.28,36.05,0.018
19.32,36.22,0.018
19.36,36.40,0.018
19.39,36.57,0.018
19.43,36.75,0.018
19.46,36.92,0.018
19.49,37.10,0.018
19.53,37.27,0.018
19.57,37.45,0.018
19.60,37.62,0.018
19.63,37.80,0.018
19.67,37.97,0.018
19.71,38.15,0.018
19.74,38.32,0.018
19.78,38.50,0.018
19.81,38.67,0.018
19.84,38.85,0.018
19.88,39.02,0.018
19.92,39.20,0.018
19.95,39.37,0.018
19.98,39.55,0.018
20.02,39.72,0.018
20.06,39.90,0.018
20.09,40.07,0.018
20.13,40.25,0.018
20.16,40.42,0.018
20.19,40.60,0.018
20.23,40.77,0.018
20.27,40.95,0.018
20.30,41.12,0.018
20.33,41.30,0.018
20.37,41.47,0.018
20.41,41.65,0.018
20.44,41.82,0.018
20.48,42.00,0.018
20.51,42.17,0.018
20.54,42.35,0.018
20.58,42.52,0.018
20.62,42.70,0.018
20.65,42.87,0.018
20.68,43.05,0.018
20.72,43.22,0.018
20.76,43.40,0.018
20.79,43.58,0.018
20.83,43.75,0.018
20.86,43.93,0.018
20.89,44.10,0.018
20.93,44.28,0.018
20.97,44.45,0.018
21.00,44.63,0.018
21.03,44.80,0.018
21.07,44.98,0.018
21.11,45.15,0.018
21.14,45.33,0.018
21.18,45.50,0.018
21.21,45.68,0.018
21.24,45.85,0.018
21.28,46.03,0.018
21.32,46.20,0.018
21.35,46.38,0.017
21.38,46.55,0.017
21.42,46.73,0.017
21.46,46.90,0.017
21.49,47.08,0.017
21.53,47.25,0.017
21.56,47.43,0.017
21.59,47.60,0.017
21.63,47.78,0.017
21.67,47.96,0.017
21.70,48.13,0.017
21.73,48.31,0.017
21.77,48.48,0.017
21.81,48.66,0.017
21.84,48.83,0.017
21.88,49.00,0.017
21.91,49.18,0.017
21.94,49.36,0.017
21.98,49.53,0.017
22.02,49.71,0.017
22.05,49.88,0.017
22.08,50.06,0.017
22.12,50.23,0.017
22.16,50.41,0.017
22.19,50.58,0.017
22.23,50.76,0.017
22.26,50.93,0.017
22.29,51.11,0.017
22.33,51.28,0.017
22.37,51.46,0.017
22.40,51.63,0.017
22.43,51.81,0.017
22.47,51.98,0.017
22.51,52.16,0.017
22.54,52.33,0.017
22.58,52.51,0.017
22.61,52.68,0.017
22.64,52.86,0.017
22.68,53.03,0.017
22.72,53.21,0.017
22.75,53.38,0.017
22.78,53.56,0.017
22.82,53.74,0.017
22.86,53.91,0.017
22.89,54.09,0.017
22.93,54.26,0.017
22.96,54.44,0.017
22.99,54.61,0.017
23.03,54.79,0.017
23.07,54.96,0.017
23.10,55.14,0.017
23.13,55.31,0.017
23.17,55.49,0.017
23.21,55.66,0.017
23.24,55.84,0.017
23.28,56.01,0.017
23.31,56.19,0.017
23.34,56.36,0.017
23.38,56.54,0.017
23.42,56.71,0.017
23.45,56.89,0.017
23.48,57.06,0.017
23.52,57.24,0.017
23.56,57.41,0.017
23.59,57.59,0.017
23.63,57.76,0.017
23.66,57.94,0.017
23.69,58.11,0.017
23.73,58.29,0.017
23.77,58.46,0.017
23.80,58.64,0.017
23.83,58.81,0.017
23.87,58.99,0.017
23.91,59.16,0.017
23.94,59.34,0.017
23.98,59.52,0.017
24.01,59.69,0.017
24.04,59.87,0.017
24.08,60.04,0.017
24.12,60.22,0.017
24.15,60.39,0.017
24.18,60.57,0.016
24.22,60.74,0.016
24.26,60.92,0.016
24.29,61.09,0.016
24.33,61.27,0.016
24.36,61.44,0.016
24.39,61.62,0.016
24.43,61.79,0.016
24.47,61.97,0.016
24.50,62.14,0.016
24.53,62.32,0.016
24.57,62.49,0.016
24.61,62.67,0.016
24.64,62.84,0.016
24.68,63.02,0.016
24.71,63.19,0.016
24.74,63.37,0.016
24.78,63.54,0.016
24.82,63.72,0.016
24.85,63.89,0.016
24.88,64.07,0.016
24.92,64.24,0.016
24.96,64.42,0.016
24.99,64.59,0.016
25.03,64.77,0.016
25.06,64.94,0.016
25.09,65.12,0.016
25.13,65.29,0.016
25.17,65.47,0.016
25.20,65.64,0.016
25.23,65.82,0.016
25.27,65.99,0.016
25.31,66.17,0.016
25.34,66.35,0.016
25.38,66.52,0.016
25.41,66.69,0.016
25.44,66.87,0.016
25.48,67.04,0.016
25.52,67.22,0.016
25.55,67.39,0.016
25.58,67.57,0.016
25.62,67.75,0.016
25.66,67.92,0.016
25.69,68.10,0.016
25.73,68.27,0.016
25.76,68.45,0.016
25.79,68.62,0.016
25.83,68.80,0.015
25.87,68.97,0.015
25.90,69.15,0.015
25.93,69.32,0.015
25.97,69.50,0.015
26.01,69.67,0.015
26.04,69.85,0.015
26.08,70.02,0.015
26.11,70.20,0.015
26.14,70.37,0.015
26.18,70.55,0.015
26.22,70.72,0.015
26.25,70.90,0.015
26.28,71.07,0.015
26.32,71.25,0.015
26.36,71.42,0.015
26.39,71.60,0.015
26.43,71.77,0.015
26.46,71.95,0.015
26.49,72.12,0.015
26.53,72.30,0.015
26.57,72.47,0.015
26.60,72.65,0.015
26.63,72.82,0.015
26.67,73.00,0.015
26.71,73.17,0.015
26.74,73.35,0.015
26.78,73.52,0.015
26.81,73.70,0.015
26.84,73.87,0.015
26.88,74.05,0.015
26.92,74.23,0.015
26.95,74.40,0.015
26.98,74.58,0.015
27.02,74.75,0.015
27.06,74.93,0.015
27.09,75.10,0.015
27.13,75.27,0.015
27.16,75.45,0.015
27.19,75.63,0.015
27.23,75.80,0.015
27.27,75.98,0.015
27.30,76.15,0.015
27.33,76.33,0.015
27.37,76.50,0.015
27.41,76.68,0.015
27.44,76.85,0.015
27.48,77.03,0.015
27.51,77.20,0.015
27.54,77.38,0.015
27.58,77.55,0.015
27.62,77.73,0.015
27.65,77.90,0.015
27.68,78.08,0.015
27.72,78.25,0.015
27.76,78.43,0.015
27.79,78.60,0.015
27.83,78.78,0.015
27.86,78.95,0.015
27.89,79.13,0.015
27.93,79.30,0.015
27.97,79.48,0.015
28.00,79.65,0.015
28.03,79.83,0.015
28.07,80.01,0.015
28.11,80.18,0.015
28.14,80.36,0.015
28.18,80.53,0.015
28.21,80.71,0.015
28.24,80.88,0.015
28.28,81.06,0.015
28.32,81.23,0.015
28.35,81.41,0.015
28.38,81.58,0.015
28.42,81.75,0.015
28.46,81.93,0.015
28.49,82.11,0.015
28.53,82.28,0.015
28.56,82.46,0.015
28.59,82.63,0.015
28.63,82.81,0.015
28.67,82.98,0.015
28.70,83.16,0.015
28.73,83.33,0.015
28.77,83.51,0.015
28.81,83.69,0.015
28.84,83.86,0.015
28.88,84.04,0.015
28.91,84.21,0.015
28.94,84.38,0.015
28.98,84.56,0.015
29.02,84.74,0.015
29.05,84.91,0.015
29.08,85.09,0.015
29.12,85.26,0.015
29.16,85.44,0.015
29.19,85.61,0.015
29.23,85.79,0.015
29.26,85.96,0.015
29.29,86.14,0.015
29.33,86.31,0.015
29.37,86.49,0.014
29.40,86.66,0.014
29.43,86.84,0.014
29.47,87.01,0.014
29.51,87.19,0.014
29.54,87.36,0.014
29.58,87.54,0.014
29.61,87.71,0.014
29.64,87.89,0.014
29.68,88.06,0.014
29.72,88.24,0.014
29.75,88.41,0.014
29.78,88.59,0.014
29.82,88.76,0.014
29.86,88.94,0.014
29.89,89.11,0.014
29.93,89.29,0.014
29.96,89.46,0.014
29.99,89.64,0.014
30.03,89.81,0.014
30.07,89.98,0.014
30.10,90.16,0.014
30.13,90.34,0.014
30.17,90.51,0.014
30.21,90.69,0.014
30.24,90.86,0.015
30.28,91.04,0.015
30.31,91.21,0.015
30.34,91.39,0.015
30.38,91.56,0.015
30.42,91.74,0.015
30.45,91.91,0.015
30.48,92.09,0.015
30.52,92.26,0.015
30.56,92.44,0.015
30.59,92.61,0.015
30.63,92.79,0.015
30.66,92.97,0.015
30.69,93.14,0.015
30.73,93.31,0.014
30.77,93.49,0.014
30.80,93.66,0.014
30.83,93.84,0.014
30.87,94.02,0.014
30.91,94.19,0.014
30.94,94.37,0.014
30.98,94.54,0.014
31.01,94.72,0.014
31.04,94.89,0.014
31.08,95.07,0.014
31.12,95.24,0.014
31.15,95.42,0.014
31.18,95.59,0.014
31.22,95.77,0.014
31.26,95.94,0.014
31.29,96.12,0.014
31.33,96.29,0.014
31.36,96.47,0.014
31.39,96.64,0.014
31.43,96.82,0.014
31.47,96.99,0.014
31.50,97.17,0.014
31.53,97.34,0.014
31.57,97.52,0.014
31.61,97.69,0.014
31.64,97.87,0.014
31.68,98.04,0.014
31.71,98.22,0.014
31.74,98.39,0.014
31.78,98.57,0.014
31.82,98.74,0.014
31.85,98.92,0.014
31.88,99.09,0.014
31.92,99.27,0.014
31.96,99.44,0.014
31.99,99.62,0.014
32.03,99.79,0.014
32.06,99.97,0.014
32.09,100.14,0.014
32.13,100.32,0.014
32.17,100.49,0.014
32.20,100.67,0.014
32.23,100.85,0.014
32.27,101.02,0.014
32.31,101.19,0.014
32.34,101.37,0.014
32.38,101.54,0.014
32.41,101.72,0.014
32.44,101.89,0.014
32.48,102.07,0.014
32.52,102.24,0.014
32.55,102.42,0.014
32.58,102.60,0.014
32.62,102.77,0.014
32.66,102.94,0.014
32.69,103.12,0.014
32.73,103.30,0.014
32.76,103.47,0.014
32.79,103.65,0.014
32.83,103.82,0.014
32.87,104.00,0.014
32.90,104.17,0.014
32.93,104.35,0.014
32.97,104.52,0.014
33.01,104.70,0.014
33.04,104.87,0.014
33.08,105.05,0.014
33.11,105.22,0.014
33.14,105.40,0.014
33.18,105.57,0.014
33.22,105.75,0.014
33.25,105.92,0.014
33.28,106.10,0.014
33.32,106.27,0.014
33.36,106.45,0.014
33.39,106.62,0.014
33.43,106.80,0.014
33.46,106.97,0.014
33.49,107.15,0.014
33.53,107.32,0.014
33.57,107.50,0.014
33.60,107.67,0.014
33.63,107.85,0.014
33.67,108.02,0.014
33.71,108.20,0.014
33.74,108.37,0.014
33.78,108.55,0.014
33.81,108.72,0.014
33.84,108.90,0.014
33.88,109.08,0.014
33.92,109.25,0.014
33.95,109.43,0.014
33.98,109.60,0.014
34.02,109.78,0.014
34.06,109.95,0.014
34.09,110.13,0.014
34.13,110.30,0.014
34.16,110.48,0.014
34.19,110.65,0.014
34.23,110.83,0.014
34.26,111.00,0.014
34.30,111.18,0.014
34.34,111.35,0.014
34.37,111.53,0.014
34.41,111.70,0.014
34.44,111.88,0.014
34.48,112.05,0.014
34.51,112.23,0.014
34.54,112.40,0.014
34.58,112.58,0.014
34.61,112.75,0.013
34.65,112.93,0.013
34.69,113.10,0.013
34.72,113.28,0.013
34.76,113.45,0.013
34.79,113.63,0.013
34.83,113.80,0.013
34.86,113.98,0.013
34.89,114.15,0.013
34.93,114.33,0.013
34.96,114.50,0.013
35.00,114.68,0.013
35.04,114.85,0.013
35.07,115.03,0.013
35.11,115.20,0.013
35.14,115.38,0.013
35.18,115.55,0.014
35.21,115.73,0.014
35.24,115.90,0.014
35.28,116.08,0.014
35.31,116.25,0.014
35.35,116.43,0.014
35.39,116.60,0.014
35.42,116.78,0.014
35.46,116.96,0.014
35.49,117.13,0.014
35.53,117.30,0.014
35.56,117.48,0.014
35.59,117.66,0.014
35.63,117.83,0.014
35.66,118.01,0.014
35.70,118.18,0.014
35.74,118.36,0.014
35.77,118.53,0.014
35.81,118.71,0.014
35.84,118.88,0.014
35.88,119.06,0.014
35.91,119.23,0.014
35.94,119.41,0.014
35.98,119.58,0.014
36.01,119.75,0.014
36.05,119.93,0.014
36.09,120.11,0.014
36.12,120.28,0.014
36.16,120.46,0.014
36.19,120.63,0.014
36.23,120.81,0.014
36.26,120.98,0.014
36.29,121.16,0.014
36.33,121.33,0.014
36.36,121.51,0.014
36.40,121.68,0.014
36.44,121.86,0.014
36.47,122.03,0.014
36.51,122.21,0.014
36.54,122.38,0.014
36.58,122.56,0.014
36.61,122.73,0.014
36.64,122.91,0.014
36.68,123.08,0.014
36.71,123.26,0.014
36.75,123.43,0.014
36.79,123.61,0.014
36.82,123.78,0.014
36.86,123.96,0.014
36.89,124.13,0.014
36.93,124.31,0.013
36.96,124.48,0.014
36.99,124.66,0.014
37.03,124.83,0.014
37.06,125.01,0.014
37.10,125.18,0.014
37.14,125.36,0.014
37.17,125.53,0.014
37.21,125.71,0.014
37.24,125.88,0.014
37.28,126.06,0.014
37.31,126.24,0.013
37.34,126.41,0.013
37.38,126.58,0.014
37.41,126.76,0.014
37.45,126.93,0.014
37.49,127.11,0.014
37.52,127.28,0.013
37.56,127.46,0.013
37.59,127.64,0.013
37.63,127.81,0.013
37.66,127.99,0.013
37.69,128.16,0.013
37.73,128.34,0.013
37.76,128.51,0.013
37.80,128.69,0.013
37.84,128.86,0.013
37.87,129.04,0.013
37.91,129.21,0.013
37.94,129.39,0.013
37.98,129.56,0.013
38.01,129.74,0.013
38.04,129.91,0.013
38.08,130.09,0.013
38.11,130.26,0.013
38.15,130.44,0.013
38.19,130.61,0.013
38.22,130.79,0.013
38.26,130.96,0.013
38.29,131.14,0.013
38.33,131.31,0.013
38.36,131.49,0.013
38.39,131.66,0.013
38.43,131.84,0.013
38.46,132.01,0.013
38.50,132.19,0.013
38.54,132.36,0.013
38.57,132.54,0.013
38.61,132.71,0.013
38.64,132.89,0.013
38.68,133.06,0.013
38.71,133.24,0.013
38.74,133.41,0.013
38.78,133.59,0.013
38.81,133.76,0.013
38.85,133.94,0.013
38.89,134.11,0.013
38.92,134.29,0.013
38.96,134.46,0.013
38.99,134.64,0.013
39.03,134.81,0.013
39.06,134.99,0.013
39.09,135.17,0.013
39.13,135.34,0.013
39.16,135.52,0.013
39.20,135.69,0.013
39.24,135.87,0.013
39.27,136.04,0.013
39.31,136.22,0.013
39.34,136.39,0.013
39.38,136.57,0.013
39.41,136.74,0.013
39.44,136.92,0.013
39.48,137.09,0.013
39.51,137.27,0.013
39.55,137.44,0.013
39.59,137.62,0.013
39.62,137.79,0.013
39.66,137.96,0.013
39.69,138.14,0.013
39.73,138.32,0.013
39.76,138.49,0.013
39.79,138.67,0.013
39.83,138.84,0.013
39.86,139.02,0.013
39.90,139.19,0.013
39.94,139.37,0.013
39.97,139.54,0.013
40.01,139.72,0.013
40.04,139.89,0.013
40.08,140.07,0.013
40.11,140.24,0.013
40.14,140.42,0.013
40.18,140.59,0.013
40.21,140.77,0.013
40.25,140.94,0.013
40.29,141.12,0.013
40.32,141.29,0.013
40.36,141.47,0.013
40.39,141.64,0.013
40.43,141.82,0.013
40.46,141.99,0.013
40.49,142.17,0.013
40.53,142.34,0.013
40.56,142.52,0.013
40.60,142.69,0.013
40.64,142.87,0.013
40.67,143.04,0.013
40.71,143.22,0.013
40.74,143.40,0.013
40.78,143.57,0.013
40.81,143.75,0.013
40.84,143.92,0.013
40.88,144.10,0.013
40.91,144.27,0.013
40.95,144.45,0.013
40.99,144.62,0.013
41.02,144.80,0.013
41.06,144.97,0.013
41.09,145.15,0.013
41.13,145.32,0.013
41.16,145.49,0.013
41.19,145.67,0.013
41.23,145.84,0.013
41.26,146.02,0.013
41.30,146.20,0.013
41.34,146.37,0.013
41.37,146.55,0.013
41.41,146.72,0.013
41.44,146.90,0.013
41.48,147.07,0.013
41.51,147.25,0.013
41.54,147.42,0.013
41.58,147.60,0.013
41.61,147.77,0.013
41.65,147.95,0.013
41.69,148.12,0.013
41.72,148.30,0.013
41.76,148.47,0.013
41.79,148.65,0.013
41.83,148.82,0.013
41.86,149.00,0.013
41.89,149.17,0.013
41.93,149.35,0.013
41.96,149.52,0.013
42.00,149.70,0.013
42.04,149.87,0.013
42.07,150.05,0.013
42.11,150.22,0.013
42.14,150.40,0.013
42.18,150.57,0.013
42.21,150.75,0.013
42.24,150.92,0.013
42.28,151.10,0.013
42.31,151.27,0.013
42.35,151.45,0.013
42.39,151.62,0.013
42.42,151.80,0.013
42.46,151.98,0.013
42.49,152.15,0.013
42.53,152.33,0.013
42.56,152.50,0.013
42.59,152.68,0.013
42.63,152.85,0.013
42.66,153.02,0.013
42.70,153.20,0.013
42.74,153.37,0.013
42.77,153.55,0.013
42.81,153.72,0.013
42.84,153.90,0.013
42.88,154.07,0.013
42.91,154.25,0.013
42.94,154.43,0.013
42.98,154.60,0.013
43.01,154.78,0.013
43.05,154.95,0.013
43.09,155.13,0.013
43.12,155.30,0.013
43.16,155.48,0.013
43.19,155.65,0.013
43.23,155.83,0.013
43.26,156.00,0.014
43.29,156.18,0.014
43.33,156.35,0.014
43.36,156.53,0.019
43.40,156.66,0.341
43.44,156.72,0.735
43.47,156.78,1.093
43.51,156.84,1.449
43.54,156.90,1.787
43.58,156.98,2.087
43.61,157.06,2.308
43.64,157.20,2.126
43.68,157.66,0.789
43.71,158.03,0.431
43.75,158.32,0.245
43.79,158.55,0.142
43.82,158.76,0.084
43.86,158.96,0.052
43.89,159.14,0.035
43.93,159.32,0.026
43.96,159.50,0.020
43.99,159.67,0.018
44.03,159.85,0.017
44.06,160.03,0.016
44.10,160.20,0.015
44.14,160.38,0.015
44.17,160.55,0.015
44.21,160.73,0.014
44.24,160.90,0.014
44.28,161.08,0.014
44.31,161.25,0.014
44.34,161.43,0.014
44.38,161.60,0.014
44.41,161.78,0.014
44.45,161.95,0.014
44.49,162.13,0.014
44.52,162.30,0.014
44.56,162.48,0.014
44.59,162.65,0.013
44.63,162.83,0.013
44.66,163.00,0.013
44.69,163.18,0.013
44.73,163.35,0.013
44.76,163.53,0.013
44.80,163.70,0.013
44.84,163.88,0.013
44.87,164.06,0.013
44.91,164.23,0.013
44.94,164.40,0.013
44.98,164.58,0.013
45.01,164.75,0.013
45.04,164.93,0.013
45.08,165.10,0.013
45.11,165.28,0.013
45.15,165.46,0.013
45.19,165.63,0.013
45.22,165.80,0.013
45.26,165.98,0.013
45.29,166.16,0.013
45.33,166.33,0.013
45.36,166.51,0.013
45.39,166.68,0.013
45.43,166.86,0.013
45.46,167.03,0.013
45.50,167.21,0.013
45.54,167.38,0.013
45.57,167.56,0.013
45.61,167.73,0.013
45.64,167.91,0.013
45.68,168.08,0.013
45.71,168.26,0.013
45.74,168.43,0.013
45.78,168.61,0.013
45.81,168.78,0.013
45.85,168.96,0.013
45.89,169.13,0.013
45.92,169.31,0.013
45.96,169.48,0.013
45.99,169.66,0.013
46.03,169.83,0.013
46.06,170.01,0.013
46.09,170.18,0.013
46.13,170.36,0.013
46.16,170.53,0.013
46.20,170.71,0.013
46.24,170.88,0.013
46.27,171.06,0.013
46.31,171.23,0.013
46.34,171.41,0.013
46.38,171.58,0.013
46.41,171.76,0.013
46.44,171.94,0.013
46.48,172.11,0.013
46.51,172.29,0.013
46.55,172.46,0.013
46.59,172.64,0.013
46.62,172.81,0.013
46.66,172.99,0.013
46.69,173.16,0.013
46.73,173.34,0.013
46.76,173.51,0.013
46.79,173.68,0.013
46.83,173.86,0.013
46.86,174.03,0.013
46.90,174.21,0.013
46.94,174.38,0.013
46.97,174.56,0.013
47.01,174.73,0.013
47.04,174.91,0.013
47.08,175.08,0.013
47.11,175.26,0.013
47.14,175.44,0.013
47.18,175.61,0.013
47.21,175.79,0.013
47.25,175.96,0.013
47.29,176.14,0.013
47.32,176.31,0.013
47.36,176.49,0.013
47.39,176.66,0.013
47.43,176.84,0.013
47.46,177.01,0.013
47.49,177.19,0.013
47.53,177.36,0.013
47.56,177.54,0.013
47.60,177.71,0.013
47.64,177.89,0.013
47.67,178.06,0.013
47.71,178.24,0.013
47.74,178.41,0.013
47.78,178.59,0.013
47.81,178.76,0.013
47.84,178.94,0.013
47.88,179.11,0.013
47.91,179.29,0.013
47.95,179.46,0.013
47.99,179.64,0.013
48.02,179.81,0.013
48.06,179.99,0.013
48.09,180.16,0.013
48.13,180.34,0.013
48.16,180.51,0.013
48.19,180.69,0.013
48.23,180.86,0.013
48.26,181.04,0.013
48.30,181.21,0.013
48.34,181.39,0.013
48.37,181.56,0.013
48.41,181.74,0.013
48.44,181.91,0.013
48.48,182.09,0.013
48.51,182.26,0.013
48.54,182.44,0.013
48.58,182.61,0.013
48.61,182.79,0.013
48.65,182.96,0.013
48.69,183.14,0.013
48.72,183.31,0.013
48.76,183.49,0.013
48.79,183.66,0.013
48.83,183.84,0.013
48.86,184.01,0.013
48.89,184.19,0.013
48.93,184.36,0.013
48.96,184.54,0.013
49.00,184.72,0.013
49.04,184.89,0.013
49.07,185.06,0.013
49.11,185.24,0.013
49.14,185.41,0.013
49.18,185.59,0.013
49.21,185.76,0.013
49.24,185.94,0.013
49.28,186.11,0.013
49.31,186.29,0.013
49.35,186.46,0.013
49.39,186.64,0.013
49.42,186.81,0.013
49.46,186.99,0.013
49.49,187.16,0.013
49.53,187.34,0.013
49.56,187.52,0.013
49.59,187.69,0.013
49.63,187.87,0.013
49.66,188.04,0.013
49.70,188.22,0.013
49.74,188.39,0.013
49.77,188.57,0.013
49.81,188.74,0.013
49.84,188.91,0.013
49.88,189.09,0.013
49.91,189.27,0.013
49.94,189.44,0.013
49.98,189.62,0.013
50.01,189.79,0.013
50.05,189.97,0.013
50.09,190.14,0.013
50.12,190.32,0.013
50.16,190.49,0.013
50.19,190.67,0.013
50.23,190.84,0.013
50.26,191.02,0.013
50.29,191.19,0.013
50.33,191.37,0.013
50.36,191.54,0.013
50.40,191.72,0.013
50.44,191.89,0.013
50.47,192.07,0.013
50.51,192.24,0.013
50.54,192.42,0.013
50.58,192.59,0.013
50.61,192.77,0.013
50.64,192.94,0.013
50.68,193.12,0.013
50.71,193.29,0.013
50.75,193.47,0.013
50.79,193.64,0.013
50.82,193.82,0.013
50.86,193.99,0.013
50.89,194.17,0.013
50.93,194.34,0.013
50.96,194.52,0.013
50.99,194.69,0.013
51.03,194.87,0.013
51.06,195.04,0.013
51.10,195.22,0.013
51.14,195.39,0.013
51.17,195.57,0.013
51.21,195.74,0.013
51.24,195.92,0.013
51.28,196.09,0.013
51.31,196.27,0.013
51.34,196.44,0.013
51.38,196.62,0.013
51.41,196.79,0.013
51.45,196.97,0.013
51.49,197.14,0.013
51.52,197.32,0.013
51.56,197.49,0.013
51.59,197.67,0.013
51.63,197.84,0.013
51.66,198.02,0.013
51.69,198.19,0.013
51.73,198.37,0.013
51.76,198.54,0.013
51.80,198.72,0.013
51.84,198.89,0.013
51.87,199.07,0.013
51.91,199.25,0.013
51.94,199.42,
51.98,199.60,
51.99,,

[step]
Ramp 5.00 °C/min to -60.00 °C
Time,Temperature,Heat Flow (Normalized)
min,°C,W/g
52.99,200.15,-0.039
53.02,200.15,-0.039
53.06,200.13,-0.041
53.09,200.08,-0.058
53.13,199.97,-0.073
53.16,199.83,-0.081
53.20,199.67,-0.085
53.23,199.51,-0.087
53.27,199.34,-0.087
53.30,199.17,-0.087
53.34,198.99,-0.087
53.37,198.82,-0.088
53.41,198.65,-0.088
53.44,198.47,-0.088
53.48,198.30,-0.088
53.51,198.13,-0.088
53.55,197.95,-0.089
53.58,197.78,-0.089
53.62,197.60,-0.089
53.65,197.43,-0.089
53.69,197.26,-0.089
53.72,197.08,-0.089
53.76,196.91,-0.089
53.79,196.73,-0.089
53.83,196.56,-0.089
53.86,196.38,-0.089
53.90,196.21,-0.089
53.93,196.04,-0.089
53.97,195.86,-0.089
54.00,195.69,-0.089
54.04,195.51,-0.089
54.07,195.34,-0.089
54.11,195.16,-0.089
54.14,194.99,-0.089
54.18,194.82,-0.089
54.21,194.64,-0.088
54.25,194.47,-0.088
54.28,194.29,-0.088
54.32,194.12,-0.088
54.35,193.94,-0.088
54.39,193.77,-0.088
54.42,193.59,-0.088
54.46,193.42,-0.088
54.49,193.24,-0.088
54.53,193.07,-0.088
54.56,192.89,-0.088
54.60,192.72,-0.088
54.63,192.54,-0.088
54.67,192.37,-0.088
54.70,192.19,-0.088
54.74,192.02,-0.088
54.77,191.84,-0.088
54.81,191.67,-0.088
54.84,191.49,-0.088
54.88,191.32,-0.087
54.91,191.14,-0.087
54.95,190.97,-0.087
54.98,190.80,-0.087
55.02,190.62,-0.087
55.05,190.44,-0.087
55.09,190.27,-0.087
55.12,190.10,-0.087
55.16,189.92,-0.087
55.19,189.75,-0.087
55.23,189.57,-0.087
55.26,189.40,-0.087
55.30,189.22,-0.087
55.33,189.05,-0.087
55.37,188.87,-0.087
55.40,188.70,-0.087
55.44,188.52,-0.087
55.47,188.35,-0.087
55.51,188.17,-0.087
55.54,188.00,-0.087
55.58,187.82,-0.087
55.61,187.65,-0.087
55.65,187.47,-0.087
55.68,187.30,-0.086
55.72,187.12,-0.086
55.75,186.95,-0.086
55.79,186.77,-0.086
55.82,186.60,-0.086
55.86,186.42,-0.086
55.89,186.25,-0.086
55.93,186.07,-0.086
55.96,185.90,-0.086
56.00,185.72,-0.086
56.03,185.55,-0.086
56.07,185.37,-0.086
56.10,185.19,-0.086
56.14,185.02,-0.086
56.17,184.85,-0.086
56.21,184.67,-0.086
56.24,184.50,-0.086
56.28,184.32,-0.086
56.31,184.15,-0.086
56.35,183.97,-0.086
56.38,183.80,-0.086
56.42,183.62,-0.086
56.45,183.45,-0.086
56.49,183.27,-0.086
56.52,183.10,-0.086
56.56,182.92,-0.086
56.59,182.75,-0.086
56.63,182.57,-0.086
56.66,182.40,-0.086
56.70,182.22,-0.086
56.73,182.05,-0.086
56.77,181.87,-0.086
56.80,181.70,-0.086
56.84,181.52,-0.086
56.87,181.35,-0.086
56.91,181.17,-0.086
56.94,181.00,-0.086
56.98,180.82,-0.086
57.01,180.65,-0.086
57.05,180.47,-0.086
57.08,180.30,-0.086
57.12,180.12,-0.085
57.15,179.94,-0.085
57.19,179.77,-0.085
57.22,179.60,-0.085
57.26,179.42,-0.085
57.29,179.25,-0.085
57.33,179.07,-0.085
57.36,178.90,-0.085
57.40,178.72,-0.085
57.43,178.55,-0.085
57.47,178.37,-0.085
57.50,178.20,-0.085
57.54,178.02,-0.085
57.57,177.85,-0.085
57.61,177.67,-0.085
57.64,177.50,-0.085
57.68,177.32,-0.085
57.71,177.15,-0.085
57.75,176.97,-0.085
57.78,176.80,-0.085
57.82,176.62,-0.085
57.85,176.45,-0.085
57.89,176.27,-0.085
57.92,176.10,-0.085
57.96,175.92,-0.085
57.99,175.75,-0.085
58.03,175.57,-0.085
58.06,175.40,-0.085
58.10,175.22,-0.085
58.13,175.05,-0.085
58.17,174.87,-0.085
58.20,174.70,-0.085
58.24,174.52,-0.085
58.27,174.35,-0.085
58.31,174.17,-0.085
58.34,174.00,-0.085
58.38,173.82,-0.085
58.41,173.65,-0.085
58.45,173.47,-0.085
58.48,173.30,-0.085
58.52,173.12,-0.085
58.55,172.95,-0.085
58.59,172.77,-0.085
58.62,172.60,-0.085
58.66,172.42,-0.085
58.69,172.25,-0.084
58.73,172.07,-0.084
58.76,171.90,-0.084
58.80,171.72,-0.084
58.83,171.55,-0.084
58.87,171.37,-0.084
58.90,171.20,-0.084
58.94,171.02,-0.084
58.97,170.85,-0.084
59.01,170.67,-0.084
59.04,170.50,-0.084
59.08,170.32,-0.084
59.11,170.15,-0.084
59.15,169.97,-0.084
59.18,169.80,-0.084
59.22,169.62,-0.084
59.25,169.45,-0.084
59.29,169.27,-0.084
59.32,169.10,-0.084
59.36,168.92,-0.084
59.39,168.75,-0.084
59.43,168.57,-0.084
59.46,168.40,-0.084
59.50,168.22,-0.084
59.53,168.05,-0.084
59.57,167.87,-0.084
59.60,167.70,-0.084
59.64,167.52,-0.084
59.67,167.35,-0.084
59.71,167.17,-0.084
59.74,167.00,-0.084
59.78,166.82,-0.084
59.81,166.65,-0.084
59.85,166.47,-0.084
59.88,166.30,-0.084
59.92,166.12,-0.084
59.95,165.95,-0.084
59.99,165.77,-0.084
60.02,165.60,-0.084
60.06,165.42,-0.084
60.09,165.25,-0.084
60.13,165.07,-0.084
60.16,164.90,-0.084
60.20,164.72,-0.084
60.23,164.55,-0.084
60.27,164.37,-0.084
60.30,164.20,-0.084
60.34,164.02,-0.084
60.37,163.85,-0.084
60.41,163.67,-0.084
60.44,163.50,-0.084
60.48,163.32,-0.084
60.51,163.15,-0.084
60.55,162.97,-0.084
60.58,162.80,-0.084
60.62,162.62,-0.084
60.65,162.45,-0.084
60.69,162.27,-0.084
60.72,162.10,-0.084
60.76,161.92,-0.084
60.79,161.75,-0.084
60.83,161.57,-0.084
60.86,161.40,-0.084
60.90,161.22,-0.084
60.93,161.05,-0.084
60.97,160.87,-0.084
61.00,160.70,-0.084
61.04,160.52,-0.084
61.07,160.35,-0.084
61.11,160.17,-0.084
61.14,160.00,-0.084
61.18,159.82,-0.084
61.21,159.65,-0.084
61.25,159.47,-0.084
61.28,159.30,-0.084
61.32,159.12,-0.084
61.35,158.95,-0.084
61.39,158.77,-0.084
61.42,158.60,-0.084
61.46,158.42,-0.084
61.49,158.25,-0.083
61.53,158.07,-0.083
61.56,157.90,-0.083
61.60,157.72,-0.083
61.63,157.55,-0.083
61.67,157.37,-0.084
61.70,157.20,-0.084
61.74,157.02,-0.084
61.77,156.85,-0.084
61.81,156.67,-0.084
61.84,156.50,-0.084
61.88,156.32,-0.084
61.91,156.15,-0.084
61.95,155.97,-0.084
61.98,155.80,-0.084
62.02,155.62,-0.084
62.05,155.45,-0.084
62.09,155.27,-0.084
62.12,155.10,-0.084
62.16,154.92,-0.084
62.19,154.75,-0.084
62.23,155.21,-12.597
62.26,155.69,-4.892
62.30,155.34,-0.746
62.33,154.67,-0.128
62.37,154.22,-0.107
62.40,153.89,-0.098
62.44,153.63,-0.093
62.47,153.41,-0.089
62.51,153.20,-0.087
62.54,153.01,-0.086
62.58,152.83,-0.086
62.61,152.65,-0.085
62.65,152.48,-0.084
62.68,152.30,-0.084
62.72,152.12,-0.084
62.75,151.95,-0.084
62.79,151.77,-0.084
62.82,151.60,-0.084
62.86,151.42,-0.084
62.89,151.25,-0.084
62.93,151.07,-0.084
62.96,150.90,-0.084
63.00,150.72,-0.084
63.03,150.55,-0.084
63.07,150.37,-0.084
63.10,150.20,-0.084
63.14,150.02,-0.084
63.17,149.85,-0.084
63.21,149.67,-0.084
63.24,149.50,-0.083
63.28,149.32,-0.083
63.31,149.15,-0.083
63.35,148.97,-0.083
63.38,148.80,-0.083
63.42,148.62,-0.083
63.45,148.45,-0.083
63.49,148.27,-0.083
63.52,148.10,-0.083
63.56,147.92,-0.083
63.59,147.75,-0.083
63.63,147.57,-0.083
63.66,147.40,-0.083
63.70,147.22,-0.083
63.73,147.05,-0.083
63.77,146.87,-0.083
63.80,146.70,-0.083
63.84,146.52,-0.083
63.87,146.35,-0.083
63.91,146.17,-0.083
63.94,146.00,-0.083
63.98,145.82,-0.083
64.01,145.65,-0.083
64.05,145.47,-0.083
64.08,145.30,-0.083
64.12,145.12,-0.083
64.15,144.95,-0.082
64.19,144.77,-0.083
64.22,144.60,-0.083
64.26,144.42,-0.082
64.29,144.25,-0.083
64.33,144.07,-0.083
64.36,143.90,-0.082
64.40,143.72,-0.083
64.43,143.55,-0.083
64.47,143.37,-0.082
64.50,143.20,-0.082
[...]
236.80,63.60,0.016,0.168
236.84,63.78,0.016,0.168
236.87,63.95,0.016,0.168
236.91,64.13,0.016,0.168
236.94,64.30,0.016,0.169
236.98,64.48,0.016,0.168
237.01,64.65,0.016,0.168
237.05,64.82,0.016,0.168
237.08,65.00,0.016,0.168
237.12,65.17,0.016,0.168
237.15,65.35,0.016,0.168
237.19,65.53,0.016,0.167
237.22,65.70,0.016,0.167
237.26,65.88,0.016,0.167
237.29,66.05,0.016,0.167
237.33,66.23,0.016,0.167
237.36,66.40,0.016,0.166
237.40,66.58,0.016,0.167
237.43,66.75,0.016,0.166
237.47,66.93,0.016,0.166
237.50,67.10,0.016,0.166
237.54,67.28,0.016,0.166
237.57,67.45,0.016,0.166
237.61,67.63,0.016,0.166
237.64,67.80,0.016,0.166
237.68,67.98,0.016,0.166
237.71,68.15,0.016,0.166
237.75,68.33,0.016,0.166
237.78,68.50,0.016,0.166
237.82,68.68,0.016,0.166
237.85,68.85,0.016,0.166
237.89,69.03,0.016,0.166
237.92,69.20,0.016,0.166
237.96,69.38,0.016,0.166
237.99,69.55,0.016,0.165
238.03,69.73,0.016,0.166
238.06,69.90,0.016,0.166
238.10,70.08,0.016,0.165
238.13,70.25,0.015,0.165
238.17,70.43,0.015,0.165
238.20,70.60,0.015,0.164
238.24,70.78,0.015,0.164
238.27,70.96,0.015,0.164
238.31,71.13,0.015,0.163
238.34,71.31,0.015,0.163
238.38,71.48,0.015,0.163
238.41,71.66,0.015,0.164
238.45,71.83,0.015,0.163
238.48,72.01,0.015,0.163
238.52,72.18,0.015,0.163
238.55,72.36,0.015,0.163
238.59,72.53,0.015,0.163
238.62,72.71,0.015,0.163
238.66,72.88,0.015,0.163
238.69,73.06,0.015,0.163
238.73,73.23,0.015,0.163
238.76,73.41,0.015,0.163
238.80,73.58,0.015,0.163
238.83,73.76,0.015,0.162
238.87,73.93,0.015,0.162
238.90,74.11,0.015,0.162
238.94,74.28,0.015,0.162
238.97,74.46,0.015,0.162
239.01,74.63,0.015,0.162
239.04,74.81,0.015,0.162
239.08,74.98,0.015,0.161
239.11,75.16,0.015,0.161
239.15,75.33,0.015,0.161
239.18,75.51,0.015,0.161
239.22,75.68,0.015,0.161
239.25,75.86,0.015,0.161
239.29,76.04,0.015,0.161
239.32,76.21,0.015,0.161
239.36,76.38,0.015,0.161
239.39,76.56,0.015,0.161
239.43,76.74,0.015,0.161
239.46,76.91,0.015,0.161
239.50,77.08,0.015,0.161
239.53,77.26,0.015,0.161
239.57,77.44,0.015,0.161
239.60,77.61,0.015,0.161
239.64,77.79,0.015,0.161
239.67,77.96,0.015,0.161
239.71,78.13,0.015,0.161
239.74,78.31,0.015,0.161
239.78,78.49,0.015,0.161
239.81,78.66,0.015,0.161
239.85,78.84,0.015,0.161
239.88,79.01,0.015,0.162
239.92,79.19,0.015,0.162
239.95,79.36,0.015,0.162
239.99,79.54,0.015,0.162
240.02,79.71,0.015,0.162
240.06,79.89,0.015,0.162
240.09,80.06,0.015,0.162
240.13,80.24,0.015,0.162
240.16,80.41,0.015,0.162
240.20,80.59,0.015,0.162
240.23,80.76,0.015,0.162
240.27,80.94,0.015,0.162
240.30,81.11,0.015,0.161
240.34,81.29,0.015,0.161
240.37,81.46,0.015,0.161
240.41,81.64,0.015,0.161
240.44,81.81,0.015,0.160
240.48,81.99,0.015,0.160
240.51,82.16,0.015,0.160
240.55,82.34,0.015,0.160
240.58,82.51,0.015,0.161
240.62,82.69,0.015,0.160
240.65,82.87,0.015,0.160
240.69,83.04,0.015,0.160
240.72,83.21,0.015,0.160
240.76,83.39,0.015,0.160
240.79,83.56,0.015,0.159
240.83,83.74,0.015,0.159
240.86,83.91,0.015,0.159
240.90,84.09,0.015,0.159
240.93,84.26,0.015,0.159
240.97,84.44,0.015,0.159
241.00,84.61,0.015,0.159
241.04,84.79,0.015,0.159
241.07,84.97,0.015,0.159
241.11,85.14,0.015,0.158
241.14,85.32,0.015,0.158
241.18,85.49,0.015,0.158
241.21,85.67,0.015,0.158
241.25,85.84,0.015,0.158
241.28,86.02,0.015,0.158
241.32,86.19,0.015,0.158
241.35,86.37,0.015,0.158
241.39,86.54,0.015,0.158
241.42,86.72,0.015,0.158
241.46,86.89,0.015,0.157
241.49,87.07,0.015,0.157
241.53,87.24,0.015,0.157
241.56,87.42,0.015,0.157
241.60,87.59,0.015,0.157
241.63,87.77,0.015,0.156
241.67,87.94,0.015,0.156
241.70,88.12,0.015,0.156
241.74,88.29,0.015,0.156
241.77,88.47,0.015,0.155
241.81,88.64,0.015,0.155
241.84,88.82,0.015,0.155
241.88,88.99,0.015,0.155
241.91,89.17,0.015,0.155
241.95,89.34,0.015,0.155
241.98,89.52,0.015,0.155
242.02,89.70,0.015,0.156
242.05,89.87,0.015,0.155
242.09,90.04,0.015,0.155
242.12,90.22,0.015,0.155
242.16,90.39,0.015,0.156
242.19,90.57,0.015,0.155
242.23,90.75,0.015,0.155
242.26,90.92,0.015,0.155
242.30,91.10,0.015,0.155
242.33,91.27,0.015,0.156
242.37,91.45,0.015,0.156
242.40,91.62,0.015,0.156
242.44,91.80,0.015,0.156
242.47,91.97,0.015,0.156
242.51,92.15,0.015,0.156
242.54,92.32,0.015,0.155
242.58,92.50,0.015,0.155
242.61,92.67,0.015,0.155
242.65,92.85,0.015,0.155
242.68,93.02,0.015,0.155
242.72,93.20,0.015,0.156
242.75,93.37,0.015,0.156
242.79,93.55,0.015,0.156
242.82,93.72,0.015,0.156
242.86,93.90,0.015,0.155
242.89,94.07,0.015,0.155
242.93,94.25,0.015,0.155
242.96,94.42,0.015,0.155
243.00,94.60,0.015,0.155
243.03,94.77,0.015,0.156
243.07,94.95,0.015,0.156
243.10,95.12,0.015,0.155
243.14,95.30,0.015,0.155
243.17,95.47,0.015,0.155
243.21,95.65,0.015,0.155
243.24,95.82,0.015,0.155
243.28,96.00,0.015,0.155
243.31,96.17,0.014,0.154
243.35,96.35,0.014,0.154
243.38,96.52,0.014,0.154
243.42,96.70,0.014,0.154
243.45,96.87,0.014,0.154
243.49,97.05,0.014,0.154
243.52,97.22,0.014,0.154
243.56,97.40,0.015,0.155
243.59,97.58,0.015,0.155
243.63,97.75,0.015,0.155
243.66,97.93,0.015,0.155
243.70,98.10,0.015,0.155
243.73,98.28,0.015,0.155
243.77,98.45,0.014,0.154
243.80,98.63,0.014,0.154
243.84,98.80,0.014,0.154
243.87,98.98,0.014,0.154
243.91,99.15,0.014,0.154
243.94,99.33,0.014,0.154
243.98,99.50,0.014,0.154
244.01,99.68,0.014,0.154
244.05,99.85,0.014,0.153
244.08,100.03,0.014,0.153
244.12,100.20,0.014,0.153
244.15,100.38,0.014,0.153
244.19,100.55,0.014,0.153
244.22,100.73,0.014,0.153
244.26,100.90,0.014,0.153
244.29,101.08,0.014,0.153
244.33,101.25,0.014,0.152
244.36,101.43,0.014,0.153
244.40,101.60,0.014,0.152
244.43,101.78,0.014,0.152
244.47,101.95,0.014,0.153
244.50,102.13,0.014,0.153
244.54,102.30,0.014,0.153
244.57,102.48,0.014,0.153
244.61,102.65,0.014,0.153
244.64,102.83,0.014,0.152
244.68,103.00,0.014,0.152
244.71,103.18,0.014,0.153
244.75,103.35,0.014,0.152
244.78,103.53,0.014,0.153
244.82,103.70,0.014,0.153
244.85,103.88,0.014,0.153
244.89,104.05,0.014,0.153
244.92,104.23,0.014,0.153
244.96,104.40,0.014,0.153
244.99,104.58,0.014,0.152
245.03,104.76,0.014,0.152
245.06,104.93,0.014,0.152
245.10,105.10,0.014,0.152
245.13,105.28,0.014,0.152
245.17,105.46,0.014,0.152
245.20,105.63,0.014,0.151
245.24,105.81,0.014,0.152
245.27,105.98,0.014,0.152
245.31,106.16,0.014,0.152
245.34,106.33,0.014,0.152
245.38,106.51,0.014,0.152
245.41,106.68,0.014,0.152
245.45,106.86,0.014,0.152
245.48,107.03,0.014,0.152
245.52,107.21,0.014,0.152
245.55,107.38,0.014,0.152
245.59,107.56,0.014,0.152
245.62,107.73,0.014,0.153
245.66,107.91,0.014,0.152
245.69,108.08,0.014,0.152
245.73,108.26,0.014,0.152
245.76,108.43,0.014,0.152
245.80,108.61,0.014,0.152
245.83,108.78,0.014,0.152
245.87,108.96,0.014,0.151
245.90,109.13,0.014,0.151
245.94,109.31,0.014,0.151
245.97,109.48,0.014,0.151
246.01,109.66,0.014,0.151
246.04,109.83,0.014,0.151
246.08,110.01,0.014,0.150
246.11,110.18,0.014,0.150
246.15,110.36,0.014,0.149
246.18,110.53,0.014,0.149
246.22,110.71,0.014,0.149
246.25,110.88,0.014,0.149
246.29,111.06,0.014,0.149
246.32,111.23,0.014,0.149
246.36,111.41,0.014,0.149
246.39,111.58,0.014,0.150
246.43,111.76,0.014,0.150
246.46,111.93,0.014,0.150
246.50,112.11,0.014,0.150
246.53,112.28,0.014,0.150
246.57,112.46,0.014,0.150
246.60,112.63,0.014,0.150
246.64,112.81,0.014,0.150
246.67,112.98,0.014,0.150
246.71,113.16,0.014,0.150
246.74,113.33,0.014,0.150
246.78,113.51,0.014,0.150
246.81,113.68,0.014,0.150
246.85,113.86,0.014,0.150
246.88,114.03,0.014,0.150
246.92,114.21,0.014,0.150
246.95,114.39,0.014,0.150
246.99,114.56,0.014,0.150
247.02,114.74,0.014,0.150
247.06,114.91,0.014,0.150
247.09,115.09,0.014,0.150
247.13,115.26,0.014,0.150
247.16,115.44,0.014,0.150
247.20,115.61,0.014,0.150
247.23,115.79,0.014,0.150
247.27,115.96,0.014,0.150
247.30,116.14,0.014,0.150
247.34,116.31,0.014,0.150
247.37,116.49,0.014,0.149
247.41,116.66,0.014,0.149
247.44,116.84,0.014,0.149
247.48,117.01,0.014,0.149
247.51,117.19,0.014,0.149
247.55,117.36,0.014,0.149
247.58,117.54,0.014,0.149
247.62,117.71,0.014,0.149
247.65,117.89,0.014,0.148
247.69,118.06,0.014,0.148
247.72,118.24,0.014,0.148
247.76,118.41,0.014,0.148
247.79,118.59,0.014,0.148
247.83,118.76,0.014,0.148
247.86,118.94,0.014,0.148
247.90,119.11,0.014,0.149
247.93,119.29,0.014,0.149
247.97,119.46,0.014,0.149
248.00,119.64,0.014,0.149
248.04,119.81,0.014,0.149
248.07,119.99,0.014,0.149
248.11,120.16,0.014,0.149
248.14,120.34,0.014,0.149
248.18,120.51,0.014,0.149
248.21,120.69,0.014,0.148
248.25,120.86,0.014,0.148
248.28,121.04,0.014,0.148
248.32,121.21,0.014,0.148
248.35,121.39,0.014,0.148
248.39,121.56,0.014,0.148
248.42,121.74,0.014,0.148
248.46,121.91,0.014,0.149
248.49,122.09,0.014,0.148
248.53,122.27,0.014,0.148
248.56,122.44,0.014,0.148
248.60,122.61,0.014,0.148
248.63,122.79,0.014,0.148
248.67,122.96,0.014,0.148
248.70,123.14,0.014,0.148
248.74,123.31,0.014,0.148
248.77,123.49,0.014,0.148
248.81,123.66,0.014,0.148
248.84,123.84,0.014,0.148
248.88,124.02,0.014,0.148
248.91,124.19,0.014,0.148
248.95,124.37,0.014,0.149
248.98,124.54,0.014,0.148
249.02,124.72,0.014,0.148
249.05,124.89,0.014,0.148
249.09,125.07,0.014,0.148
249.12,125.24,0.014,0.148
249.16,125.42,0.014,0.149
249.19,125.59,0.014,0.148
249.23,125.77,0.014,0.148
249.26,125.94,0.014,0.148
249.30,126.12,0.014,0.148
249.33,126.29,0.014,0.147
249.37,126.47,0.014,0.147
249.40,126.64,0.014,0.147
249.44,126.82,0.014,0.147
249.47,126.99,0.014,0.147
249.51,127.17,0.014,0.147
249.54,127.34,0.014,0.147
249.58,127.52,0.014,0.147
249.61,127.69,0.014,0.147
249.65,127.87,0.014,0.146
249.68,128.04,0.014,0.146
249.72,128.22,0.014,0.146
249.75,128.39,0.014,0.146
249.79,128.57,0.014,0.146
249.82,128.74,0.014,0.146
249.86,128.92,0.014,0.146
249.89,129.09,0.014,0.146
249.93,129.27,0.014,0.146
249.96,129.44,0.014,0.146
250.00,129.62,0.014,0.145
250.03,129.79,0.014,0.146
250.07,129.97,0.014,0.145
250.10,130.14,0.014,0.145
250.14,130.32,0.014,0.145
250.17,130.49,0.014,0.146
250.21,130.67,0.014,0.146
250.24,130.84,0.014,0.146
250.28,131.02,0.014,0.146
250.31,131.19,0.014,0.146
250.35,131.37,0.014,0.146
250.38,131.54,0.014,0.145
250.42,131.72,0.014,0.145
250.45,131.89,0.014,0.145
250.49,132.07,0.014,0.145
250.52,132.24,0.014,0.145
250.56,132.42,0.014,0.145
250.59,132.60,0.014,0.145
250.63,132.77,0.014,0.145
250.66,132.95,0.014,0.145
250.70,133.12,0.014,0.145
250.73,133.30,0.014,0.145
250.77,133.47,0.014,0.145
250.80,133.65,0.014,0.145
250.84,133.82,0.014,0.145
250.87,134.00,0.014,0.144
250.91,134.17,0.014,0.144
250.94,134.35,0.014,0.144
250.98,134.52,0.014,0.144
251.01,134.70,0.014,0.144
251.05,134.87,0.014,0.144
251.08,135.05,0.014,0.143
251.12,135.22,0.014,0.144
251.15,135.40,0.014,0.143
251.19,135.58,0.014,0.143
251.22,135.75,0.014,0.143
251.26,135.92,0.014,0.143
251.29,136.10,0.013,0.143
251.33,136.27,0.014,0.143
251.36,136.45,0.014,0.143
251.40,136.62,0.014,0.144
251.43,136.80,0.014,0.143
251.47,136.97,0.013,0.143
251.50,137.15,0.014,0.143
251.54,137.33,0.013,0.143
251.57,137.50,0.014,0.143
251.61,137.68,0.013,0.143
251.64,137.85,0.013,0.143
251.68,138.02,0.013,0.143
251.71,138.20,0.013,0.143
251.75,138.38,0.013,0.143
251.78,138.55,0.013,0.142
251.82,138.72,0.013,0.142
251.85,138.90,0.013,0.142
251.89,139.08,0.013,0.142
251.92,139.25,0.013,0.142
251.96,139.43,0.013,0.142
251.99,139.60,0.013,0.142
252.03,139.77,0.013,0.142
252.06,139.95,0.013,0.142
252.10,140.13,0.013,0.142
252.13,140.30,0.013,0.142
252.17,140.47,0.013,0.142
252.20,140.65,0.013,0.141
252.24,140.82,0.013,0.141
252.27,141.00,0.013,0.141
252.31,141.18,0.013,0.141
252.34,141.35,0.013,0.141
252.38,141.53,0.013,0.141
252.41,141.70,0.013,0.141
252.45,141.88,0.013,0.141
252.48,142.05,0.013,0.142
252.52,142.23,0.013,0.141
252.55,142.40,0.013,0.141
252.59,142.58,0.013,0.141
252.62,142.75,0.013,0.141
252.66,142.93,0.013,0.141
252.69,143.10,0.013,0.141
252.73,143.28,0.013,0.141
252.76,143.45,0.013,0.141
252.80,143.63,0.013,0.141
252.83,143.80,0.013,0.141
252.87,143.98,0.013,0.141
252.90,144.15,0.013,0.141
252.94,144.33,0.013,0.142
252.97,144.50,0.013,0.142
253.01,144.68,0.013,0.142
253.04,144.85,0.013,0.142
253.08,145.03,0.013,0.141
253.11,145.20,0.013,0.141
253.15,145.38,0.013,0.141
253.18,145.55,0.013,0.141
253.22,145.73,0.013,0.141
253.25,145.90,0.013,0.141
253.29,146.08,0.013,0.141
253.32,146.25,0.013,0.141
253.36,146.43,0.013,0.141
253.39,146.60,0.013,0.142
253.43,146.78,0.013,0.141
253.46,146.95,0.013,0.141
253.50,147.13,0.013,0.141
253.53,147.30,0.013,0.141
253.57,147.48,0.013,0.141
253.60,147.65,0.013,0.141
253.64,147.83,0.013,0.141
253.67,148.00,0.013,0.141
253.71,148.18,0.013,0.141
253.74,148.35,0.013,0.141
253.78,148.53,0.013,0.141
253.81,148.70,0.013,0.141
253.85,148.88,0.013,0.141
253.88,149.05,0.013,0.141
253.92,149.23,0.013,0.141
253.95,149.40,0.013,0.141
253.99,149.58,0.013,0.141
254.02,149.75,0.013,0.141
254.06,149.93,0.013,0.141
254.09,150.11,0.013,0.140
254.13,150.28,0.013,0.140
254.16,150.46,0.013,0.141
254.20,150.63,0.013,0.141
254.23,150.80,0.013,0.141
254.27,150.98,0.013,0.141
254.30,151.16,0.013,0.141
254.34,151.33,0.013,0.141
254.37,151.50,0.013,0.141
254.41,151.68,0.013,0.141
254.44,151.86,0.013,0.141
254.48,152.03,0.013,0.140
254.51,152.21,0.013,0.140
254.55,152.38,0.013,0.141
254.58,152.56,0.013,0.140
254.62,152.73,0.013,0.141
254.65,152.91,0.013,0.141
254.69,153.08,0.013,0.141
254.72,153.26,0.013,0.141
254.76,153.43,0.013,0.141
254.79,153.61,0.013,0.141
254.83,153.78,0.013,0.141
254.86,153.96,0.013,0.141
254.90,154.13,0.013,0.141
254.93,154.31,0.013,0.141
254.97,154.48,0.013,0.141
255.00,154.66,0.013,0.141
255.04,154.83,0.013,0.141
255.07,155.01,0.013,0.142
255.11,155.18,0.013,0.142
255.14,155.36,0.013,0.142
255.18,155.53,0.013,0.142
255.21,155.71,0.013,0.143
255.25,155.88,0.014,0.143
255.28,156.06,0.014,0.144
255.32,156.23,0.014,0.156
255.35,156.41,0.014,0.182
255.39,156.58,0.050,0.754
255.42,156.67,0.510,9.205
255.46,156.73,0.882,19.763
255.49,156.79,1.241,35.255
255.53,156.85,1.597,45.732
255.56,156.91,1.942,35.737
255.60,156.98,2.247,24.463
255.63,157.06,2.467,20.872
255.67,157.38,1.204,8.772
255.70,157.82,0.593,3.902
255.74,158.15,0.332,2.043
255.77,158.41,0.188,1.284
255.81,158.63,0.110,0.889
255.84,158.83,0.066,0.597
255.88,159.02,0.042,0.408
255.91,159.20,0.029,0.290
255.95,159.38,0.022,0.226
255.98,159.56,0.018,0.190
256.02,159.73,0.017,0.176
256.05,159.91,0.016,0.168
256.09,160.08,0.016,0.165
256.12,160.26,0.015,0.157
256.16,160.44,0.015,0.153
256.19,160.61,0.014,0.151
256.23,160.79,0.014,0.149
256.26,160.96,0.014,0.147
256.30,161.14,0.014,0.146
256.33,161.31,0.014,0.145
256.37,161.49,0.014,0.143
256.40,161.66,0.013,0.142
256.44,161.84,0.013,0.141
256.47,162.01,0.013,0.140
256.51,162.19,0.013,0.139
256.54,162.36,0.013,0.139
256.58,162.54,0.013,0.138
256.61,162.71,0.013,0.137
256.65,162.89,0.013,0.136
256.68,163.06,0.013,0.136
256.72,163.24,0.013,0.136
256.75,163.41,0.013,0.136
256.79,163.59,0.013,0.135
256.82,163.76,0.013,0.135
256.86,163.94,0.013,0.135
256.89,164.11,0.013,0.135
256.93,164.29,0.013,0.134
256.96,164.46,0.013,0.134
257.00,164.64,0.013,0.134
257.03,164.81,0.013,0.133
257.07,164.99,0.013,0.133
257.10,165.16,0.013,0.133
257.14,165.34,0.013,0.133
257.17,165.51,0.013,0.133
257.21,165.69,0.013,0.133
257.24,165.86,0.013,0.132
257.28,166.04,0.013,0.132
257.31,166.21,0.013,0.132
257.35,166.39,0.012,0.131
257.38,166.56,0.012,0.131
257.42,166.74,0.012,0.131
257.45,166.91,0.013,0.131
257.49,167.09,0.012,0.131
257.52,167.26,0.012,0.131
257.56,167.44,0.012,0.131
257.59,167.61,0.012,0.131
257.63,167.79,0.012,0.131
257.66,167.96,0.012,0.131
257.70,168.14,0.013,0.131
257.73,168.32,0.013,0.132
257.77,168.49,0.013,0.132
257.80,168.66,0.013,0.132
257.84,168.84,0.012,0.131
257.87,169.02,0.012,0.131
257.91,169.19,0.012,0.131
257.94,169.36,0.012,0.131
257.98,169.54,0.012,0.130
258.01,169.71,0.012,0.130
258.05,169.89,0.012,0.130
258.08,170.06,0.012,0.130
258.12,170.24,0.012,0.130
258.15,170.41,0.012,0.130
258.19,170.59,0.012,0.130
258.22,170.77,0.012,0.131
258.26,170.94,0.012,0.131
258.29,171.12,0.012,0.131
258.33,171.29,0.012,0.131
258.36,171.46,0.012,0.131
258.40,171.64,0.013,0.131
258.43,171.81,0.012,0.131
258.47,171.99,0.013,0.132
258.50,172.17,0.012,0.131
258.54,172.34,0.012,0.131
258.57,172.51,0.012,0.131
258.61,172.69,0.013,0.131
258.64,172.86,0.013,0.131
258.68,173.04,0.013,0.132
258.71,173.22,0.013,0.132
258.75,173.39,0.013,0.132
258.78,173.57,0.013,0.132
258.82,173.74,0.013,0.132
258.85,173.92,0.013,0.132
258.89,174.09,0.013,0.132
258.92,174.27,0.013,0.132
258.96,174.44,0.013,0.132
258.99,174.62,0.013,0.132
259.03,174.79,0.013,0.132
259.06,174.97,0.013,0.132
259.10,175.14,0.013,0.132
259.13,175.32,0.012,0.131
259.17,175.49,0.012,0.131
259.20,175.67,0.012,0.131
259.24,175.84,0.012,0.131
259.27,176.02,0.012,0.130
259.31,176.19,0.012,0.130
259.34,176.37,0.012,0.130
259.38,176.54,0.012,0.129
259.41,176.72,0.012,0.129
259.45,176.89,0.012,0.128
259.48,177.07,0.012,0.128
259.52,177.24,0.012,0.128
259.55,177.42,0.012,0.128
259.59,177.59,0.012,0.129
259.62,177.77,0.012,0.129
259.66,177.94,0.012,0.129
259.69,178.12,0.012,0.129
259.73,178.29,0.012,0.129
259.76,178.47,0.012,0.129
259.80,178.64,0.012,0.129
259.83,178.82,0.012,0.129
259.87,178.99,0.012,0.129
259.90,179.17,0.012,0.129
259.94,179.34,0.012,0.129
259.97,179.52,0.012,0.129
260.01,179.69,0.012,0.128
260.04,179.87,0.012,0.128
260.08,180.04,0.012,0.128
260.11,180.22,0.012,0.128
260.15,180.39,0.012,0.129
260.18,180.57,0.012,0.128
260.22,180.74,0.012,0.128
260.25,180.92,0.012,0.128
260.29,181.09,0.012,0.129
260.32,181.27,0.012,0.129
260.36,181.45,0.012,0.129
260.39,181.62,0.012,0.129
260.43,181.80,0.012,0.129
260.46,181.97,0.012,0.129
260.50,182.15,0.012,0.130
260.53,182.32,0.012,0.129
260.57,182.50,0.012,0.129
260.60,182.67,0.012,0.129
260.64,182.84,0.012,0.129
260.67,183.02,0.012,0.129
260.71,183.20,0.012,0.129
260.74,183.37,0.012,0.129
260.78,183.55,0.012,0.129
260.81,183.72,0.012,0.129
260.85,183.90,0.012,0.129
260.88,184.07,0.012,0.129
260.92,184.25,0.012,0.129
260.95,184.42,0.012,0.129
260.99,184.60,0.012,0.129
261.02,184.77,0.012,0.129
261.06,184.94,0.012,0.129
261.09,185.12,0.012,0.129
261.13,185.30,0.012,0.129
261.16,185.47,0.012,0.129
261.20,185.65,0.012,0.129
261.23,185.82,0.012,0.130
261.27,186.00,0.012,0.130
261.30,186.17,0.012,0.129
261.34,186.35,0.012,0.130
261.37,186.52,0.012,0.130
261.41,186.70,0.012,0.130
261.44,186.87,0.012,0.130
261.48,187.05,0.012,0.129
261.51,187.22,0.012,0.129
261.55,187.40,0.012,0.129
261.58,187.57,0.012,0.129
261.62,187.75,0.012,0.129
261.65,187.92,0.012,0.129
261.69,188.10,0.012,0.130
261.72,188.27,0.012,0.129
261.76,188.45,0.012,0.129
261.79,188.62,0.012,0.129
261.83,188.80,0.012,0.129
261.86,188.97,0.012,0.129
261.90,189.15,0.012,0.129
261.93,189.32,0.012,0.128
261.97,189.50,0.012,0.128
262.00,189.67,0.012,0.128
262.04,189.85,0.012,0.128
262.07,190.02,0.012,0.128
262.11,190.20,0.012,0.128
262.14,190.37,0.012,0.128
262.18,190.55,0.012,0.127
262.21,190.72,0.012,0.128
262.25,190.90,0.012,0.127
262.28,191.07,0.012,0.127
262.32,191.25,0.012,0.127
262.35,191.42,0.012,0.127
262.39,191.60,0.012,0.127
262.42,191.77,0.012,0.127
262.46,191.95,0.012,0.127
262.49,192.13,0.012,0.127
262.53,192.30,0.012,0.128
262.56,192.48,0.012,0.128
262.60,192.65,0.012,0.128
262.63,192.83,0.012,0.127
262.67,193.00,0.012,0.127
262.70,193.18,0.012,0.127
262.74,193.35,0.012,0.127
262.77,193.53,0.012,0.127
262.81,193.70,0.012,0.126
262.84,193.88,0.012,0.126
262.88,194.05,0.012,0.126
262.91,194.23,0.012,0.126
262.95,194.40,0.012,0.126
262.98,194.58,0.012,0.125
263.02,194.75,0.012,0.125
263.05,194.93,0.012,0.125
263.09,195.10,0.012,0.125
263.12,195.28,0.012,0.125
263.16,195.45,0.012,0.125
263.19,195.62,0.012,0.125
263.23,195.80,0.012,0.125
263.26,195.98,0.012,0.125
263.30,196.15,0.012,0.126
263.33,196.33,0.012,0.126
263.37,196.50,0.012,0.126
263.40,196.68,0.012,0.126
263.44,196.85,0.012,0.126
263.47,197.03,0.012,0.126
263.51,197.20,0.012,0.125
263.54,197.38,0.012,0.125
263.58,197.55,0.012,0.125
263.61,197.73,0.012,0.125
263.65,197.90,0.012,0.125
263.68,198.08,0.012,0.125
263.72,198.25,0.012,0.125
263.75,198.43,0.012,0.125
263.79,198.60,0.012,0.125
263.82,198.78,0.012,0.124
263.86,198.95,0.012,0.124
263.89,199.13,0.012,
263.93,199.30,,
263.96,199.48,,
263.98,,,