File: DSC/Earl/2025_10_05_1CBN_1PVP29_ASD_5Cmin_n60C_150C_x3.csv
Filename,2025_10_05_1CBN_1PVP29_ASD_5Cmin_n60C_150C_x3
Instrument name,DSC2A-00468 (192.168.1.100)
Operator,JLY
rundate,10/5/2025
Sample name,2025_10_05_1CBN_1PVP29_ASD_5Cmin_n60C_150C_x3
proceduresegments,Data Off ; Equilibrate -60.00 °C; Data On ; Ramp 5.00 °C/min to 150.00 °C; Data Off ; Isothermal 1.0 min; Data On ; Ramp 5.00 °C/min to -60.00 °C; Data Off ; Isothermal 1.0 min; Data On ; Ramp 5.00 °C/min to 150.00 °C; Data Off ; Isothermal 1.0 min; Data On ; Ramp 5.00 °C/min to -60.00 °C; Data Off ; Isothermal 1.0 min; Data On ; Ramp 5.00 °C/min to 150.00 °C
[File Parameters]
Run date,10/5/2025 8:11:00 PM
Trios version,5.1.1.46572
Original File Name,
Current File Name,D:\DSC2500\JYarger\2025_10_05_1CBN_1PVP29_ASD_5Cmin_n60C_150C_x3.tri
[Procedure]
Procedure Name,ASD_n60C_150C_5Cmin_x3
Sample Name,2025_10_05_1CBN_1PVP29_ASD_5Cmin_n60C_150C_x3
Sample Mass,4.14 mg
Reference Sample Mass,0 mg
Pan Mass,32.71 mg
Pan Number,14
Reference Pan Mass,32.55 mg
Reference Pan Number,1
Pan Type,Aluminum
Comments,DSC_Samples_Y2_Tray_ASDs_Pharma_Oct2025 Google Sheet.
Project Name,Amorphous Pharma
Operator,JLY
Test,Custom
Unload Max Temperature,30
Unload Min Temperature,30
Load Max Temperature,30
Load Min Temperature,30
Stop on Gas Flow Error,Yes
[Signal List]
Signal #1,Time (min)
Signal #2,Temperature (°C)
Signal #3,Heat Flow (mW)
Signal #4,Delta T (µV)
Signal #5,Delta Tzero (µV)
Signal #6,Tzero Temperature (°C)
Signal #7,Cell Purge (mL/min)
Signal #8,Heater Temp (°C)
Signal #9,Power Delivered (W)
Signal #10,Reference Junction Temperature (°C)
Signal #11,Flange Temperature (°C)
Signal #12,Heat Flow Phase (rad)
Signal #13,Total Heat Capacity (J/°C)
Signal #14,Heat Capacity (J/°C)
[Configuration]
Company Name,ASU
Instrument Name,DSC2A-00468
Instrument Type,DSC2500
Serial Number,DSC2A-00468
IP,192.168.1.100
Location of Instrument,MRRC
DisplayType,Unknown
Sample Interval ,0.1 s/pt
Selected Heat Flow,T4P
Exotherm Direction,Down
Cell Serial,DRC2-00792
Lid Type,Standard
Cooler,RCS 90
Leave Cooler on at End of Sequence,On
Gas 2,Nitrogen
Gas Selected,Channel 1
Flow Rate,50 mL/min
Secondary Purge,On
Licensed Heat Flow,Heat Flow T4P
Modulation Licensed,Yes
[Versions]
Common IDD Version,1
Cortex Version,VER 2.10.2.31
Driver,5.0.0.6
GDM Version,1.0.3.3
TouchscreenVersion,1.0.0.16145
FEP Version,1.2.1.21
FEP Bootloader,2.0.0.5
AutoSampler Version,2.1.1.26
Auto Sampler Bootloader,2.0.0.5
FCM Version,1.1.0.3
FCM Bootloader,2.0.0.5
[Experiment Logs]
Experiment Log Entry # 1,Air Cool is off.
Experiment Log Entry # 3,Lid Close
Experiment Log Entry # 5,Data On set to 0
Experiment Log Entry # 7,Equilibrate Segment -60 (C) Started
Experiment Log Entry # 9,Data On set to 1
Experiment Log Entry # 11,Ramp Segment 5 C/min to 150 Started
Experiment Log Entry # 13,Data On set to 0
Experiment Log Entry # 15,Isothermal Segment 1 min started
Experiment Log Entry # 17,Data On set to 1
Experiment Log Entry # 19,Ramp Segment 5 C/min to -60 Started
Experiment Log Entry # 21,Data On set to 0
Experiment Log Entry # 23,Isothermal Segment 1 min started
Experiment Log Entry # 25,Data On set to 1
Experiment Log Entry # 27,Ramp Segment 5 C/min to 150 Started
Experiment Log Entry # 29,Data On set to 0
Experiment Log Entry # 31,Isothermal Segment 1 min started
Experiment Log Entry # 33,Data On set to 1
Experiment Log Entry # 35,Ramp Segment 5 C/min to -60 Started
Experiment Log Entry # 37,Data On set to 0
Experiment Log Entry # 39,Isothermal Segment 1 min started
Experiment Log Entry # 41,Data On set to 1
Experiment Log Entry # 43,Ramp Segment 5 C/min to 150 Started
[Method Log]
Method Log Entry # 1,Data Off
Method Log Entry # 2,Equilibrate -60 °C
Method Log Entry # 3,Data On
Method Log Entry # 4,(Ramp 333767) Ramp 5 °C/minute to 150 °C
Method Log Entry # 5,Data Off
Method Log Entry # 6,Isothermal 1 minutes
Method Log Entry # 7,Data On
Method Log Entry # 8,(Ramp 333771) Ramp 5 °C/minute to -60 °C
Method Log Entry # 9,Data Off
Method Log Entry # 10,Isothermal 1 minutes
Method Log Entry # 11,Data On
Method Log Entry # 12,(Ramp 333775) Ramp 5 °C/minute to 150 °C
Method Log Entry # 13,Data Off
Method Log Entry # 14,Isothermal 1 minutes
Method Log Entry # 15,Data On
Method Log Entry # 16,(Ramp 333779) Ramp 5 °C/minute to -60 °C
Method Log Entry # 17,Data Off
Method Log Entry # 18,Isothermal 1 minutes
Method Log Entry # 19,Data On
Method Log Entry # 20,(Ramp 333783) Ramp 5 °C/minute to 150 °C
Cell Serial,DRC2-00792
[T1 Calibration]
Slope,-0.008529666
Offset,9.636258
Initial Temperature,98.23
GUID,f8bfdadc-4977-4fdf-ba6d-0ba9134940c3
[TZero Calibration]
Date Applied,11/29/2022 4:06:13 PM
Description,From -89.059 °C to 396.009 °C at 20.000°C/min
Gas Type,Nitrogen
Pan Type,None
Source Files 1,C:\Users\yargerlab\Desktop\DSC Data\General\TZero_calibration_11_29_22_2nd(2).tri
Source Files 2,C:\Users\yargerlab\Desktop\DSC Data\General\TZero_calibration_11_29_22_2nd(3).tri
Delta T Offset,13.05235
Delta T Slope,-0.007271007
Delta T0 Offset,-13.69128
Delta T0 Slope,0.06063341
[Temperature Calibration]
Date Applied,11/29/2022 7:12:28 PM
Description,From 106.590 °C to 186.590 °C at 10.000°C/min
Gas Type,Nitrogen
Pan Type,Tzero Aluminum Hermetic
Source Files 1,C:\Users\yargerlab\Desktop\DSC Data\General\Indium(6).tri
Measured 1,157.391
Known 1,156.598
[Cell Constant Calibration]
Date Applied,11/29/2022 7:12:29 PM
Description,From 106.590 °C to 186.590 °C at 10.000°C/min
Gas Type,Nitrogen
Pan Type,Tzero Aluminum Hermetic
Source Files 1,C:\Users\yargerlab\Desktop\DSC Data\General\Indium(6).tri
T4P KCell,1.006051
Onset Slope,63.26126 mW/°C
[Direct Cp Calibration]
Date Applied,11/30/2022 11:04:51 AM
Description,From -79.983 °C to 298.409 °C at 10.000°C/min
Gas Type,Nitrogen
Pan Type,Tzero Aluminum Hermetic
Source Files 1,C:\Users\yargerlab\Desktop\DSC Data\General\Sapphire_Heat_Capacity_11_30_22.tri
[Rev Cp Calibration]
Date Applied,11/30/2022 1:58:51 PM
Description,From -79.996 °C to 292.812 °C at 3.000°C/min
Gas Type,Nitrogen
Pan Type,Tzero Aluminum Hermetic
Source Files 1,C:\Users\yargerlab\Desktop\DSC Data\General\Sapphire_MDSC_Calibration_11_30_22.tri
[step]
Ramp 5.00 °C/min to 150.00 °C
Time,Temperature,Heat Flow (Normalized)
min,°C,W/g
0.00,-59.82,-0.050
0.03,-59.83,-0.045
0.06,-59.82,-0.039
0.08,-59.78,-0.035
0.11,-59.70,-0.025
0.14,-59.60,-0.005
0.17,-59.48,0.016
0.20,-59.36,0.036
0.23,-59.23,0.049
0.26,-59.10,0.058
0.28,-58.97,0.065
0.31,-58.84,0.070
0.34,-58.70,0.073
0.37,-58.57,0.076
0.40,-58.43,0.078
0.43,-58.29,0.080
0.45,-58.15,0.081
0.48,-58.02,0.082
0.51,-57.88,0.082
0.54,-57.74,0.083
0.57,-57.60,0.083
0.60,-57.46,0.084
0.62,-57.32,0.084
0.65,-57.18,0.085
0.68,-57.04,0.085
0.71,-56.90,0.086
0.74,-56.76,0.086
0.77,-56.62,0.087
0.79,-56.48,0.087
0.82,-56.34,0.087
0.85,-56.20,0.087
0.88,-56.06,0.088
0.91,-55.91,0.088
0.93,-55.77,0.088
0.96,-55.63,0.088
0.99,-55.49,0.088
1.02,-55.35,0.089
1.05,-55.21,0.089
1.08,-55.07,0.089
1.11,-54.93,0.089
1.13,-54.79,0.089
1.16,-54.65,0.089
1.19,-54.50,0.089
1.22,-54.36,0.089
1.25,-54.22,0.089
1.28,-54.08,0.089
1.30,-53.94,0.089
1.33,-53.80,0.089
1.36,-53.66,0.089
1.39,-53.51,0.089
1.42,-53.37,0.089
1.44,-53.23,0.089
1.47,-53.09,0.089
1.50,-52.95,0.089
1.53,-52.81,0.089
1.56,-52.67,0.089
1.59,-52.53,0.089
1.62,-52.38,0.089
1.64,-52.24,0.089
1.67,-52.10,0.089
1.70,-51.96,0.089
1.73,-51.82,0.089
1.76,-51.68,0.089
1.78,-51.53,0.089
1.81,-51.39,0.089
1.84,-51.25,0.089
1.87,-51.11,0.089
1.90,-50.97,0.089
1.93,-50.83,0.089
1.96,-50.69,0.089
1.98,-50.54,0.088
2.01,-50.40,0.088
2.04,-50.26,0.088
2.07,-50.12,0.088
2.10,-49.98,0.088
2.13,-49.83,0.088
2.15,-49.69,0.088
2.18,-49.55,0.088
2.21,-49.41,0.088
2.24,-49.27,0.088
2.27,-49.13,0.088
2.29,-48.99,0.088
2.32,-48.84,0.088
2.35,-48.70,0.088
2.38,-48.56,0.088
2.41,-48.42,0.088
2.44,-48.28,0.088
2.46,-48.14,0.088
2.49,-47.99,0.088
2.52,-47.85,0.088
2.55,-47.71,0.088
2.58,-47.57,0.088
2.61,-47.43,0.088
2.64,-47.29,0.088
2.66,-47.14,0.088
2.69,-47.00,0.088
2.72,-46.86,0.088
2.75,-46.72,0.088
2.78,-46.58,0.088
2.81,-46.44,0.088
2.83,-46.29,0.088
2.86,-46.15,0.088
2.89,-46.01,0.088
2.92,-45.87,0.088
2.95,-45.73,0.088
2.98,-45.59,0.088
3.00,-45.45,0.088
3.03,-45.30,0.088
3.06,-45.16,0.088
3.09,-45.02,0.088
3.12,-44.88,0.088
3.14,-44.74,0.088
3.17,-44.60,0.088
3.20,-44.45,0.088
3.23,-44.31,0.088
3.26,-44.17,0.088
3.29,-44.03,0.087
3.31,-43.89,0.087
3.34,-43.75,0.087
3.37,-43.60,0.087
3.40,-43.46,0.087
3.43,-43.32,0.087
3.46,-43.18,0.087
3.49,-43.04,0.087
3.51,-42.90,0.087
3.54,-42.76,0.087
3.57,-42.61,0.087
3.60,-42.47,0.087
3.63,-42.33,0.087
3.66,-42.19,0.087
3.68,-42.05,0.087
3.71,-41.91,0.087
3.74,-41.76,0.087
3.77,-41.62,0.087
3.80,-41.48,0.087
3.83,-41.34,0.087
3.85,-41.20,0.087
3.88,-41.05,0.087
3.91,-40.91,0.087
3.94,-40.77,0.087
3.97,-40.63,0.087
3.99,-40.49,0.087
4.02,-40.35,0.087
4.05,-40.21,0.087
4.08,-40.06,0.087
4.11,-39.92,0.087
4.14,-39.78,0.087
4.16,-39.64,0.087
4.19,-39.50,0.087
4.22,-39.35,0.087
4.25,-39.21,0.087
4.28,-39.07,0.087
4.31,-38.93,0.088
4.34,-38.79,0.088
4.36,-38.64,0.088
4.39,-38.50,0.088
4.42,-38.36,0.088
4.45,-38.22,0.088
4.48,-38.08,0.088
4.50,-37.94,0.088
4.53,-37.79,0.088
4.56,-37.65,0.088
4.59,-37.51,0.088
4.62,-37.37,0.088
4.65,-37.23,0.088
4.68,-37.09,0.088
4.70,-36.94,0.088
4.73,-36.80,0.088
4.76,-36.66,0.088
4.79,-36.52,0.087
4.82,-36.38,0.088
4.85,-36.23,0.088
4.87,-36.09,0.088
4.90,-35.95,0.088
4.93,-35.81,0.088
4.96,-35.67,0.088
4.99,-35.52,0.088
5.01,-35.38,0.088
5.04,-35.24,0.088
5.07,-35.10,0.088
5.10,-34.96,0.088
5.13,-34.81,0.088
5.16,-34.67,0.088
5.19,-34.53,0.088
5.21,-34.39,0.088
5.24,-34.25,0.088
5.27,-34.10,0.088
5.30,-33.96,0.088
5.33,-33.82,0.088
5.35,-33.68,0.088
5.38,-33.54,0.088
5.41,-33.40,0.088
5.44,-33.25,0.088
5.47,-33.11,0.088
5.50,-32.97,0.088
5.53,-32.83,0.088
5.55,-32.69,0.088
5.58,-32.55,0.088
5.61,-32.40,0.088
5.64,-32.26,0.088
5.67,-32.12,0.088
5.70,-31.98,0.088
5.72,-31.84,0.088
5.75,-31.70,0.088
5.78,-31.55,0.088
5.81,-31.41,0.088
5.84,-31.27,0.088
5.86,-31.13,0.088
5.89,-30.98,0.088
5.92,-30.84,0.088
5.95,-30.70,0.088
5.98,-30.56,0.088
6.01,-30.42,0.088
6.04,-30.27,0.088
6.06,-30.13,0.088
6.09,-29.99,0.088
6.12,-29.85,0.088
6.15,-29.71,0.088
6.18,-29.57,0.088
6.20,-29.42,0.088
6.23,-29.28,0.088
6.26,-29.14,0.088
6.29,-29.00,0.088
6.32,-28.86,0.088
6.35,-28.72,0.088
6.38,-28.57,0.088
6.40,-28.43,0.088
6.43,-28.29,0.088
6.46,-28.15,0.088
6.49,-28.01,0.088
6.52,-27.87,0.088
6.55,-27.73,0.088
6.57,-27.58,0.088
6.60,-27.44,0.088
6.63,-27.30,0.088
6.66,-27.16,0.088
6.69,-27.02,0.088
6.71,-26.87,0.088
6.74,-26.73,0.088
6.77,-26.59,0.088
6.80,-26.45,0.088
6.83,-26.31,0.088
6.86,-26.16,0.088
6.89,-26.02,0.088
6.91,-25.88,0.088
6.94,-25.74,0.088
6.97,-25.60,0.088
7.00,-25.45,0.088
7.03,-25.31,0.088
7.05,-25.17,0.088
7.08,-25.03,0.088
7.11,-24.89,0.088
7.14,-24.74,0.088
7.17,-24.60,0.088
7.20,-24.46,0.088
7.23,-24.32,0.088
7.25,-24.18,0.088
7.28,-24.04,0.088
7.31,-23.89,0.088
7.34,-23.75,0.088
7.37,-23.61,0.088
7.40,-23.47,0.088
7.42,-23.33,0.088
7.45,-23.18,0.088
7.48,-23.04,0.088
7.51,-22.90,0.089
7.54,-22.76,0.089
7.56,-22.62,0.089
7.59,-22.47,0.089
7.62,-22.33,0.089
7.65,-22.19,0.089
7.68,-22.05,0.089
7.71,-21.91,0.089
7.74,-21.77,0.089
7.76,-21.62,0.089
7.79,-21.48,0.089
7.82,-21.34,0.089
7.85,-21.20,0.089
7.88,-21.06,0.089
7.90,-20.91,0.089
7.93,-20.77,0.089
7.96,-20.63,0.089
7.99,-20.49,0.089
8.02,-20.35,0.089
8.05,-20.21,0.089
8.08,-20.06,0.089
8.10,-19.92,0.089
8.13,-19.78,0.089
8.16,-19.64,0.089
8.19,-19.50,0.089
8.22,-19.36,0.089
8.25,-19.21,0.089
8.27,-19.07,0.089
8.30,-18.93,0.089
8.33,-18.79,0.089
8.36,-18.65,0.089
8.39,-18.50,0.089
8.41,-18.36,0.089
8.44,-18.22,0.089
8.47,-18.08,0.089
8.50,-17.94,0.089
8.53,-17.80,0.089
8.56,-17.65,0.089
8.58,-17.51,0.089
8.61,-17.37,0.089
8.64,-17.23,0.089
8.67,-17.09,0.089
8.70,-16.94,0.089
8.73,-16.80,0.089
8.75,-16.66,0.089
8.78,-16.52,0.089
8.81,-16.38,0.089
8.84,-16.24,0.089
8.87,-16.09,0.089
8.90,-15.95,0.089
8.93,-15.81,0.089
8.95,-15.67,0.089
8.98,-15.53,0.089
9.01,-15.39,0.089
9.04,-15.24,0.089
9.07,-15.10,0.090
9.10,-14.96,0.090
9.12,-14.82,0.090
9.15,-14.68,0.090
9.18,-14.53,0.090
9.21,-14.39,0.090
9.24,-14.25,0.090
9.27,-14.11,0.090
9.29,-13.97,0.090
9.32,-13.83,0.090
9.35,-13.68,0.090
9.38,-13.54,0.090
9.41,-13.40,0.090
9.43,-13.26,0.090
9.46,-13.12,0.090
9.49,-12.98,0.090
9.52,-12.83,0.090
9.55,-12.69,0.090
9.58,-12.55,0.090
9.60,-12.41,0.090
9.63,-12.27,0.090
9.66,-12.13,0.090
9.69,-11.98,0.090
9.72,-11.84,0.090
9.75,-11.70,0.090
9.78,-11.56,0.090
9.80,-11.42,0.090
9.83,-11.27,0.090
9.86,-11.13,0.090
9.89,-10.99,0.090
9.92,-10.85,0.090
9.95,-10.71,0.090
9.97,-10.57,0.090
10.00,-10.42,0.090
10.03,-10.28,0.090
10.06,-10.14,0.090
10.09,-10.00,0.090
10.12,-9.85,0.090
10.14,-9.71,0.091
10.17,-9.57,0.091
10.20,-9.43,0.091
10.23,-9.29,0.091
10.26,-9.14,0.091
10.28,-9.00,0.091
10.31,-8.86,0.091
10.34,-8.72,0.091
10.37,-8.58,0.091
10.40,-8.44,0.091
10.43,-8.29,0.091
10.45,-8.15,0.091
10.48,-8.01,0.091
10.51,-7.87,0.091
10.54,-7.73,0.091
10.57,-7.59,0.091
10.60,-7.44,0.091
10.63,-7.30,0.091
10.65,-7.16,0.091
10.68,-7.02,0.091
10.71,-6.88,0.091
10.74,-6.74,0.091
10.77,-6.59,0.091
10.80,-6.45,0.091
10.82,-6.31,0.091
10.85,-6.17,0.092
10.88,-6.03,0.092
10.91,-5.88,0.092
10.94,-5.74,0.092
10.97,-5.60,0.092
10.99,-5.46,0.092
11.02,-5.32,0.092
11.05,-5.18,0.092
11.08,-5.03,0.092
11.11,-4.89,0.092
11.13,-4.75,0.092
11.16,-4.61,0.092
11.19,-4.47,0.092
11.22,-4.33,0.092
11.25,-4.18,0.092
11.28,-4.04,0.092
11.30,-3.90,0.092
11.33,-3.76,0.092
11.36,-3.62,0.092
11.39,-3.47,0.092
11.42,-3.33,0.092
11.45,-3.19,0.092
11.48,-3.05,0.092
11.50,-2.91,0.092
11.53,-2.76,0.092
11.56,-2.62,0.092
11.59,-2.48,0.092
11.62,-2.34,0.093
11.65,-2.20,0.093
11.67,-2.06,0.093
11.70,-1.92,0.093
11.73,-1.77,0.093
11.76,-1.63,0.093
11.79,-1.49,0.093
11.82,-1.35,0.093
11.84,-1.21,0.093
11.87,-1.06,0.093
11.90,-0.92,0.093
11.93,-0.78,0.093
11.96,-0.64,0.093
11.98,-0.50,0.093
12.01,-0.35,0.093
12.04,-0.21,0.093
12.07,-0.07,0.093
12.10,0.07,0.093
12.13,0.21,0.093
12.15,0.35,0.093
12.18,0.50,0.093
12.21,0.64,0.093
12.24,0.78,0.093
12.27,0.92,0.093
12.30,1.06,0.093
12.33,1.21,0.093
12.35,1.35,0.093
12.38,1.49,0.093
12.41,1.63,0.094
12.44,1.77,0.094
12.47,1.91,0.094
12.50,2.06,0.094
12.52,2.20,0.094
12.55,2.34,0.094
12.58,2.48,0.094
12.61,2.62,0.094
12.64,2.77,0.094
12.67,2.91,0.094
12.69,3.05,0.094
12.72,3.19,0.094
12.75,3.33,0.094
12.78,3.47,0.094
12.81,3.62,0.094
12.83,3.76,0.094
12.86,3.90,0.094
12.89,4.04,0.094
12.92,4.18,0.094
12.95,4.32,0.094
12.98,4.47,0.094
13.00,4.61,0.095
13.03,4.75,0.095
13.06,4.89,0.095
13.09,5.03,0.095
13.12,5.18,0.095
13.15,5.32,0.095
13.18,5.46,0.095
13.20,5.60,0.095
13.23,5.74,0.095
13.26,5.88,0.095
13.29,6.03,0.095
13.32,6.17,0.095
13.35,6.31,0.095
13.37,6.45,0.095
13.40,6.59,0.095
13.43,6.73,0.095
13.46,6.88,0.095
13.49,7.02,0.096
13.52,7.16,0.096
13.54,7.30,0.096
13.57,7.44,0.096
13.60,7.59,0.096
13.63,7.73,0.096
13.66,7.87,0.096
13.68,8.01,0.096
13.71,8.16,0.096
13.74,8.30,0.096
13.77,8.44,0.096
13.80,8.58,0.096
13.83,8.72,0.096
13.85,8.86,0.097
13.88,9.00,0.097
13.91,9.15,0.097
13.94,9.29,0.097
13.97,9.43,0.097
14.00,9.57,0.097
14.03,9.71,0.097
14.05,9.86,0.097
14.08,10.00,0.097
14.11,10.14,0.097
14.14,10.28,0.097
14.17,10.42,0.097
14.20,10.56,0.097
14.22,10.71,0.097
14.25,10.85,0.098
14.28,10.99,0.098
14.31,11.13,0.098
14.34,11.27,0.098
14.37,11.42,0.098
14.39,11.56,0.098
14.42,11.70,0.098
14.45,11.84,0.098
14.48,11.98,0.098
14.51,12.12,0.098
14.53,12.26,0.098
14.56,12.41,0.098
14.59,12.55,0.098
14.62,12.69,0.098
14.65,12.83,0.098
14.68,12.97,0.098
14.70,13.12,0.099
14.73,13.26,0.099
14.76,13.40,0.099
14.79,13.54,0.099
14.82,13.68,0.099
14.85,13.82,0.099
14.88,13.97,0.099
14.90,14.11,0.099
14.93,14.25,0.099
14.96,14.39,0.099
14.99,14.53,0.099
15.02,14.68,0.099
15.05,14.82,0.099
15.07,14.96,0.099
15.10,15.10,0.099
15.13,15.24,0.100
15.16,15.38,0.100
15.19,15.53,0.100
15.22,15.67,0.100
15.24,15.81,0.100
15.27,15.95,0.100
15.30,16.09,0.100
15.33,16.23,0.100
15.36,16.38,0.100
15.38,16.52,0.100
15.41,16.66,0.100
15.44,16.80,0.100
15.47,16.94,0.101
15.50,17.09,0.101
15.53,17.23,0.101
15.55,17.37,0.101
15.58,17.51,0.101
15.61,17.65,0.101
15.64,17.79,0.101
15.67,17.93,0.101
15.70,18.08,0.101
15.73,18.22,0.101
15.75,18.36,0.102
15.78,18.50,0.102
15.81,18.65,0.102
15.84,18.79,0.102
15.87,18.93,0.102
15.90,19.07,0.102
15.92,19.21,0.102
15.95,19.35,0.102
15.98,19.49,0.102
16.01,19.64,0.102
16.04,19.78,0.103
16.07,19.92,0.103
16.09,20.06,0.103
16.12,20.20,0.103
16.15,20.35,0.103
16.18,20.49,0.103
16.21,20.63,0.103
16.23,20.77,0.103
16.26,20.91,0.103
16.29,21.06,0.104
16.32,21.20,0.104
16.35,21.34,0.104
16.38,21.48,0.104
16.40,21.62,0.104
16.43,21.76,0.104
16.46,21.91,0.104
16.49,22.05,0.104
16.52,22.19,0.104
16.55,22.33,0.104
16.58,22.47,0.104
16.60,22.61,0.105
16.63,22.76,0.105
16.66,22.90,0.105
16.69,23.04,0.105
16.72,23.18,0.105
16.75,23.32,0.105
16.77,23.46,0.105
16.80,23.61,0.105
16.83,23.75,0.105
16.86,23.89,0.105
16.89,24.03,0.106
16.92,24.17,0.106
16.94,24.31,0.106
16.97,24.46,0.106
17.00,24.60,0.106
17.03,24.74,0.106
17.06,24.88,0.106
17.08,25.02,0.106
17.11,25.16,0.106
17.14,25.31,0.106
17.17,25.45,0.107
17.20,25.59,0.107
17.23,25.73,0.107
17.26,25.87,0.107
17.28,26.02,0.107
17.31,26.16,0.107
17.34,26.30,0.107
17.37,26.44,0.108
17.40,26.58,0.108
17.43,26.73,0.108
17.45,26.87,0.108
17.48,27.01,0.108
17.51,27.15,0.108
17.54,27.29,0.108
17.57,27.43,0.108
17.59,27.58,0.108
17.62,27.72,0.109
17.65,27.86,0.109
17.68,28.00,0.109
17.71,28.14,0.109
17.74,28.28,0.109
17.77,28.42,0.109
17.79,28.57,0.109
17.82,28.71,0.109
17.85,28.85,0.110
17.88,28.99,0.110
17.91,29.14,0.110
17.93,29.28,0.110
17.96,29.42,0.110
17.99,29.56,0.110
18.02,29.70,0.110
18.05,29.84,0.110
18.08,29.98,0.111
18.11,30.13,0.111
18.13,30.27,0.111
18.16,30.41,0.111
18.19,30.55,0.111
18.22,30.69,0.112
18.25,30.84,0.112
18.28,30.98,0.112
18.30,31.12,0.112
18.33,31.26,0.112
18.36,31.40,0.112
18.39,31.54,0.113
18.42,31.69,0.113
18.44,31.83,0.113
18.47,31.97,0.113
18.50,32.11,0.113
18.53,32.25,0.113
18.56,32.39,0.114
18.59,32.54,0.114
18.62,32.68,0.114
18.64,32.82,0.114
18.67,32.96,0.114
18.70,33.10,0.114
18.73,33.25,0.114
18.76,33.39,0.115
18.78,33.53,0.115
18.81,33.67,0.115
18.84,33.81,0.115
18.87,33.95,0.115
18.90,34.09,0.115
18.93,34.24,0.116
18.96,34.38,0.116
18.98,34.52,0.116
19.01,34.66,0.116
19.04,34.80,0.116
19.07,34.95,0.116
19.10,35.09,0.117
19.13,35.23,0.117
19.15,35.37,0.117
19.18,35.51,0.117
19.21,35.66,0.117
19.24,35.80,0.117
19.27,35.94,0.118
19.29,36.08,0.118
19.32,36.22,0.118
19.35,36.36,0.118
19.38,36.51,0.118
19.41,36.65,0.118
19.44,36.79,0.119
19.47,36.93,0.119
19.49,37.07,0.119
19.52,37.21,0.119
19.55,37.36,0.119
19.58,37.50,0.120
19.61,37.64,0.120
19.63,37.78,0.120
19.66,37.92,0.120
19.69,38.06,0.120
19.72,38.21,0.121
19.75,38.35,0.121
19.78,38.49,0.121
19.81,38.63,0.121
19.83,38.77,0.121
19.86,38.91,0.122
19.89,39.06,0.122
19.92,39.20,0.122
19.95,39.34,0.122
19.98,39.48,0.123
20.00,39.62,0.123
20.03,39.77,0.123
20.06,39.91,0.123
20.09,40.05,0.123
20.12,40.19,0.124
20.14,40.33,0.124
20.17,40.47,0.124
20.20,40.62,0.124
20.23,40.76,0.125
20.26,40.90,0.125
20.29,41.04,0.125
20.32,41.18,0.125
20.34,41.32,0.125
20.37,41.47,0.126
20.40,41.61,0.126
20.43,41.75,0.126
20.46,41.89,0.126
20.48,42.03,0.127
20.51,42.18,0.127
20.54,42.32,0.127
20.57,42.46,0.128
20.60,42.60,0.128
20.63,42.74,0.128
20.66,42.88,0.128
20.68,43.02,0.129
20.71,43.17,0.129
20.74,43.31,0.129
20.77,43.45,0.129
20.80,43.59,0.130
20.83,43.73,0.130
20.85,43.88,0.130
20.88,44.02,0.130
20.91,44.16,0.131
20.94,44.30,0.131
20.97,44.44,0.131
20.99,44.58,0.132
21.02,44.73,0.132
21.05,44.87,0.132
21.08,45.01,0.132
21.11,45.15,0.133
21.14,45.29,0.133
21.17,45.43,0.133
21.19,45.58,0.134
21.22,45.72,0.134
21.25,45.86,0.134
21.28,46.00,0.135
21.31,46.14,0.135
21.33,46.28,0.135
21.36,46.43,0.136
21.39,46.57,0.136
21.42,46.71,0.136
21.45,46.85,0.137
21.48,46.99,0.137
21.51,47.13,0.137
21.53,47.27,0.138
21.56,47.42,0.138
21.59,47.56,0.139
21.62,47.70,0.139
21.65,47.84,0.139
21.68,47.98,0.140
21.70,48.13,0.140
21.73,48.27,0.141
21.76,48.41,0.141
21.79,48.55,0.141
21.82,48.69,0.142
21.84,48.83,0.142
21.87,48.98,0.143
21.90,49.12,0.143
21.93,49.26,0.143
21.96,49.40,0.144
21.99,49.54,0.144
22.02,49.68,0.145
22.04,49.82,0.145
22.07,49.97,0.146
22.10,50.11,0.146
22.13,50.25,0.147
22.16,50.39,0.147
22.18,50.53,0.148
22.21,50.68,0.148
22.24,50.82,0.149
22.27,50.96,0.149
22.30,51.10,0.150
22.33,51.24,0.151
22.36,51.38,0.151
22.38,51.52,0.152
22.41,51.66,0.152
22.44,51.81,0.153
22.47,51.95,0.153
22.50,52.09,0.154
22.53,52.23,0.155
22.55,52.37,0.155
22.58,52.52,0.156
22.61,52.66,0.157
22.64,52.80,0.157
22.67,52.94,0.158
22.69,53.08,0.159
22.72,53.22,0.160
22.75,53.36,0.161
22.78,53.51,0.161
22.81,53.65,0.162
22.84,53.79,0.163
22.87,53.93,0.164
22.89,54.07,0.165
22.92,54.21,0.166
22.95,54.35,0.167
22.98,54.49,0.168
23.01,54.64,0.169
23.03,54.78,0.170
23.06,54.92,0.171
23.09,55.06,0.172
23.12,55.20,0.173
23.15,55.34,0.175
23.18,55.49,0.176
23.21,55.63,0.177
23.23,55.77,0.179
23.26,55.91,0.181
23.29,56.05,0.182
23.32,56.19,0.184
23.35,56.33,0.186
23.38,56.47,0.189
23.40,56.62,0.191
23.43,56.76,0.193
23.46,56.90,0.195
23.49,57.04,0.198
23.52,57.18,0.200
23.54,57.32,0.204
23.57,57.46,0.206
23.60,57.60,0.210
23.63,57.75,0.213
23.66,57.89,0.217
23.69,58.03,0.221
23.72,58.17,0.224
23.74,58.31,0.228
23.77,58.45,0.232
23.80,58.59,0.235
23.83,58.73,0.240
23.86,58.87,0.245
23.88,59.01,0.248
23.91,59.15,0.253
23.94,59.29,0.256
23.97,59.43,0.260
24.00,59.58,0.264
24.03,59.72,0.268
24.06,59.86,0.271
24.08,60.00,0.274
24.11,60.14,0.277
24.14,60.28,0.278
24.17,60.42,0.280
24.20,60.56,0.282
24.23,60.70,0.282
24.25,60.85,0.283
24.28,60.99,0.284
24.31,61.13,0.284
24.34,61.27,0.285
24.37,61.41,0.285
24.39,61.55,0.285
24.42,61.70,0.285
24.45,61.84,0.284
24.48,61.98,0.282
24.51,62.12,0.281
24.54,62.27,0.279
24.57,62.41,0.277
24.59,62.55,0.274
24.62,62.69,0.271
24.65,62.83,0.269
24.68,62.98,0.267
24.71,63.12,0.264
24.73,63.26,0.262
24.76,63.40,0.260
24.79,63.55,0.259
24.82,63.69,0.257
24.85,63.83,0.256
24.88,63.97,0.255
24.91,64.11,0.253
24.93,64.26,0.252
24.96,64.40,0.251
24.99,64.54,0.250
25.02,64.68,0.249
25.05,64.83,0.248
25.08,64.97,0.247
25.10,65.11,0.246
25.13,65.25,0.245
25.16,65.39,0.244
25.19,65.54,0.243
25.22,65.68,0.242
25.24,65.82,0.241
25.27,65.96,0.240
25.30,66.10,0.240
25.33,66.25,0.239
25.36,66.39,0.238
25.39,66.53,0.238
25.42,66.67,0.237
25.44,66.81,0.237
25.47,66.95,0.236
25.50,67.10,0.236
25.53,67.24,0.235
25.56,67.38,0.235
25.58,67.52,0.235
25.61,67.67,0.234
25.64,67.81,0.234
25.67,67.95,0.234
25.70,68.09,0.234
25.73,68.23,0.233
25.76,68.37,0.233
25.78,68.51,0.233
25.81,68.66,0.233
25.84,68.80,0.233
25.87,68.94,0.233
25.90,69.08,0.233
25.93,69.23,0.233
25.95,69.37,0.232
25.98,69.51,0.232
26.01,69.65,0.232
26.04,69.79,0.232
26.07,69.93,0.232
26.09,70.08,0.232
26.12,70.22,0.232
26.15,70.36,0.232
26.18,70.50,0.232
26.21,70.64,0.232
26.24,70.78,0.232
26.27,70.93,0.232
26.29,71.07,0.232
26.32,71.21,0.232
26.35,71.35,0.232
26.38,71.49,0.232
26.41,71.63,0.232
26.43,71.78,0.232
26.46,71.92,0.232
26.49,72.06,0.232
26.52,72.20,0.232
26.55,72.34,0.232
26.58,72.49,0.232
26.61,72.63,0.232
26.63,72.77,0.232
26.66,72.91,0.232
26.69,73.05,0.232
26.72,73.19,0.232
26.75,73.34,0.233
26.78,73.48,0.233
26.80,73.62,0.233
26.83,73.76,0.233
26.86,73.90,0.233
26.89,74.05,0.233
26.92,74.19,0.233
26.94,74.33,0.233
26.97,74.47,0.233
27.00,74.61,0.233
27.03,74.75,0.233
27.06,74.90,0.233
27.09,75.04,0.233
27.12,75.18,0.233
27.14,75.32,0.233
27.17,75.46,0.233
27.20,75.61,0.233
27.23,75.75,0.232
27.26,75.89,0.232
27.28,76.03,0.232
27.31,76.17,0.232
27.34,76.31,0.232
27.37,76.46,0.232
27.40,76.60,0.232
27.43,76.74,0.232
27.46,76.88,0.232
27.48,77.02,0.232
27.51,77.17,0.232
27.54,77.31,0.232
27.57,77.45,0.232
27.60,77.59,0.232
27.63,77.73,0.232
27.65,77.87,0.231
27.68,78.02,0.231
27.71,78.16,0.231
27.74,78.30,0.231
27.77,78.44,0.231
27.79,78.58,0.231
27.82,78.73,0.231
27.85,78.87,0.231
27.88,79.01,0.230
27.91,79.15,0.230
27.94,79.29,0.230
27.97,79.43,0.230
27.99,79.58,0.230
28.02,79.72,0.229
28.05,79.86,0.229
28.08,80.00,0.229
28.11,80.14,0.229
28.13,80.28,0.229
28.16,80.43,0.229
28.19,80.57,0.228
28.22,80.71,0.228
28.25,80.85,0.228
28.28,81.00,0.228
28.31,81.14,0.228
28.33,81.28,0.227
28.36,81.42,0.227
28.39,81.56,0.227
28.42,81.70,0.227
28.45,81.85,0.227
28.48,81.99,0.226
28.50,82.13,0.226
28.53,82.27,0.226
28.56,82.41,0.225
28.59,82.55,0.225
28.62,82.70,0.225
28.64,82.84,0.225
28.67,82.98,0.224
28.70,83.12,0.224
28.73,83.26,0.224
28.76,83.41,0.223
28.79,83.55,0.223
28.82,83.69,0.223
28.84,83.83,0.223
28.87,83.97,0.222
28.90,84.11,0.222
28.93,84.26,0.222
28.96,84.40,0.221
28.98,84.54,0.221
29.01,84.68,0.221
29.04,84.82,0.220
29.07,84.97,0.220
29.10,85.11,0.219
29.13,85.25,0.219
29.16,85.39,0.219
29.18,85.53,0.218
29.21,85.68,0.218
29.24,85.82,0.223
29.27,85.96,0.226
29.30,86.10,0.227
29.33,86.24,0.226
29.35,86.38,0.226
29.38,86.53,0.225
29.41,86.67,0.225
29.44,86.81,0.224
29.47,86.95,0.223
29.49,87.09,0.223
29.52,87.24,0.222
29.55,87.38,0.221
29.58,87.52,0.221
29.61,87.66,0.220
29.64,87.80,0.220
29.67,87.94,0.219
29.69,88.09,0.219
29.72,88.23,0.218
29.75,88.37,0.218
29.78,88.51,0.217
29.81,88.66,0.216
29.83,88.80,0.216
29.86,88.94,0.215
29.89,89.08,0.215
29.92,89.22,0.214
29.95,89.36,0.214
29.98,89.51,0.214
30.01,89.65,0.213
30.03,89.79,0.213
30.06,89.93,0.212
30.09,90.07,0.212
30.12,90.22,0.211
30.15,90.36,0.211
30.18,90.50,0.210
30.20,90.64,0.210
30.23,90.79,0.210
30.26,90.93,0.209
30.29,91.07,0.209
30.32,91.21,0.208
30.34,91.35,0.208
30.37,91.49,0.207
30.40,91.64,0.207
30.43,91.78,0.206
30.46,91.92,0.206
30.49,92.06,0.205
30.52,92.20,0.205
30.54,92.34,0.204
30.57,92.49,0.204
30.60,92.63,0.203
30.63,92.77,0.203
30.66,92.91,0.203
30.68,93.05,0.202
30.71,93.20,0.202
30.74,93.34,0.201
30.77,93.48,0.201
30.80,93.62,0.200
30.83,93.76,0.200
30.86,93.90,0.199
30.88,94.05,0.199
30.91,94.19,0.198
30.94,94.33,0.198
30.97,94.47,0.197
31.00,94.61,0.197
31.03,94.76,0.197
31.05,94.90,0.196
31.08,95.04,0.196
31.11,95.18,0.195
31.14,95.32,0.195
31.17,95.47,0.195
31.19,95.61,0.194
31.22,95.75,0.194
31.25,95.89,0.193
31.28,96.03,0.193
31.31,96.17,0.192
31.34,96.32,0.192
31.37,96.46,0.191
31.39,96.60,0.191
31.42,96.74,0.190
31.45,96.88,0.190
31.48,97.03,0.190
31.51,97.17,0.189
31.53,97.31,0.189
31.56,97.45,0.188
31.59,97.59,0.188
31.62,97.73,0.187
31.65,97.88,0.187
31.68,98.02,0.187
31.71,98.16,0.186
31.73,98.30,0.186
31.76,98.44,0.185
31.79,98.59,0.185
31.82,98.73,0.184
31.85,98.87,0.184
31.88,99.01,0.184
31.90,99.15,0.183
31.93,99.29,0.183
31.96,99.44,0.182
31.99,99.58,0.182
32.02,99.72,0.182
32.04,99.86,0.181
32.07,100.00,0.181
32.10,100.15,0.180
32.13,100.29,0.180
32.16,100.43,0.180
32.19,100.57,0.179
32.22,100.71,0.179
32.24,100.85,0.178
32.27,101.00,0.178
32.30,101.14,0.178
32.33,101.28,0.177
32.36,101.42,0.177
32.38,101.56,0.177
32.41,101.71,0.176
32.44,101.85,0.176
32.47,101.99,0.176
32.50,102.13,0.175
32.53,102.27,0.175
32.56,102.42,0.175
32.58,102.56,0.174
32.61,102.70,0.174
32.64,102.84,0.174
32.67,102.98,0.173
32.70,103.13,0.173
32.73,103.27,0.173
32.75,103.41,0.172
32.78,103.55,0.172
32.81,103.69,0.172
32.84,103.83,0.171
32.87,103.98,0.171
32.89,104.12,0.171
32.92,104.26,0.171
32.95,104.40,0.170
32.98,104.54,0.170
33.01,104.69,0.170
33.04,104.83,0.169
33.07,104.97,0.169
33.09,105.11,0.169
33.12,105.25,0.168
33.15,105.39,0.168
33.18,105.53,0.168
33.21,105.68,0.168
33.23,105.82,0.167
33.26,105.96,0.167
33.29,106.10,0.167
33.32,106.25,0.167
33.35,106.39,0.166
33.38,106.53,0.166
33.41,106.67,0.166
33.43,106.81,0.166
33.46,106.95,0.166
33.49,107.10,0.165
33.52,107.24,0.165
33.55,107.38,0.165
33.58,107.52,0.165
33.60,107.66,0.164
33.63,107.80,0.164
33.66,107.95,0.164
33.69,108.09,0.164
33.72,108.23,0.164
33.74,108.37,0.163
33.77,108.51,0.163
33.80,108.66,0.163
33.83,108.80,0.163
33.86,108.94,0.163
33.89,109.08,0.163
33.92,109.22,0.162
33.94,109.37,0.162
33.97,109.51,0.162
34.00,109.65,0.162
34.03,109.79,0.162
34.06,109.93,0.161
34.08,110.07,0.161
34.11,110.21,0.161
34.14,110.36,0.161
34.17,110.50,0.161
34.20,110.64,0.161
34.23,110.78,0.161
34.26,110.93,0.160
34.28,111.07,0.160
34.31,111.21,0.160
34.34,111.35,0.160
34.37,111.49,0.160
34.40,111.63,0.160
34.43,111.78,0.160
34.45,111.92,0.159
34.48,112.06,0.159
34.51,112.20,0.159
34.54,112.34,0.159
34.57,112.49,0.159
34.59,112.63,0.159
34.62,112.77,0.159
34.65,112.91,0.159
34.68,113.05,0.158
34.71,113.19,0.158
34.74,113.33,0.158
34.76,113.48,0.158
34.79,113.62,0.158
34.82,113.76,0.158
34.85,113.90,0.158
34.88,114.04,0.158
34.91,114.19,0.158
34.94,114.33,0.158
34.96,114.47,0.158
34.99,114.61,0.158
35.02,114.75,0.157
35.05,114.90,0.157
35.08,115.04,0.157
35.11,115.18,0.157
35.13,115.32,0.157
35.16,115.46,0.157
35.19,115.60,0.157
35.22,115.75,0.157
35.25,115.89,0.157
35.28,116.03,0.157
35.30,116.17,0.157
35.33,116.31,0.157
35.36,116.45,0.157
35.39,116.60,0.157
35.42,116.74,0.157
35.44,116.88,0.157
35.47,117.02,0.157
35.50,117.16,0.156
35.53,117.30,0.156
35.56,117.44,0.156
35.59,117.59,0.156
35.61,117.73,0.156
35.64,117.87,0.156
35.67,118.01,0.156
35.70,118.16,0.156
35.73,118.30,0.156
35.76,118.44,0.156
35.79,118.58,0.156
35.81,118.72,0.156
35.84,118.86,0.156
35.87,119.00,0.156
35.90,119.15,0.156
35.93,119.29,0.156
35.96,119.43,0.156
35.98,119.57,0.156
36.01,119.71,0.156
36.04,119.86,0.156
36.07,120.00,0.156
36.10,120.14,0.156
36.13,120.28,0.156
36.15,120.42,0.156
36.18,120.57,0.156
36.21,120.71,0.156
36.24,120.85,0.156
36.27,120.99,0.156
36.29,121.13,0.156
36.32,121.27,0.156
36.35,121.42,0.156
36.38,121.56,0.156
36.41,121.70,0.156
36.44,121.84,0.156
36.46,121.98,0.156
36.49,122.12,0.156
36.52,122.27,0.156
36.55,122.41,0.156
36.58,122.55,0.156
36.61,122.69,0.157
36.64,122.83,0.157
36.66,122.97,0.157
36.69,123.12,0.157
36.72,123.26,0.157
36.75,123.40,0.157
36.78,123.54,0.157
36.81,123.68,0.157
36.83,123.82,0.157
36.86,123.97,0.157
36.89,124.11,0.157
36.92,124.25,0.157
36.95,124.39,0.157
36.98,124.53,0.157
37.00,124.68,0.157
37.03,124.82,0.157
37.06,124.96,0.157
37.09,125.10,0.157
37.12,125.24,0.157
37.14,125.39,0.157
37.17,125.53,0.157
37.20,125.67,0.157
37.23,125.81,0.157
37.26,125.95,0.157
37.29,126.09,0.157
37.31,126.23,0.157
37.34,126.38,0.157
37.37,126.52,0.158
37.40,126.66,0.158
37.43,126.80,0.158
37.46,126.94,0.158
37.49,127.09,0.158
37.51,127.23,0.158
37.54,127.37,0.158
37.57,127.51,0.158
37.60,127.65,0.158
37.63,127.79,0.158
37.66,127.93,0.158
37.68,128.08,0.158
37.71,128.22,0.158
37.74,128.36,0.158
37.77,128.50,0.158
37.80,128.65,0.158
37.83,128.79,0.158
37.85,128.93,0.158
37.88,129.07,0.158
37.91,129.21,0.158
37.94,129.35,0.158
37.97,129.49,0.158
37.99,129.64,0.158
38.02,129.78,0.158
38.05,129.92,0.158
38.08,130.06,0.158
38.11,130.20,0.158
38.14,130.34,0.159
38.16,130.49,0.159
38.19,130.63,0.159
38.22,130.77,0.159
38.25,130.91,0.159
38.28,131.05,0.159
38.31,131.20,0.159
38.34,131.34,0.159
38.36,131.48,0.159
38.39,131.62,0.159
38.42,131.76,0.159
38.45,131.90,0.159
38.48,132.04,0.159
38.51,132.19,0.159
38.53,132.33,0.159
38.56,132.47,0.159
38.59,132.61,0.159
38.62,132.75,0.159
38.65,132.90,0.159
38.68,133.04,0.159
38.70,133.18,0.159
38.73,133.32,0.159
38.76,133.46,0.159
38.79,133.60,0.159
38.82,133.74,0.159
38.84,133.89,0.160
38.87,134.03,0.160
38.90,134.17,0.160
38.93,134.31,0.160
38.96,134.46,0.160
38.99,134.60,0.160
39.01,134.74,0.160
39.04,134.88,0.160
39.07,135.02,0.160
39.10,135.16,0.160
39.13,135.31,0.160
39.16,135.45,0.160
39.19,135.59,0.160
39.21,135.73,0.160
39.24,135.87,0.160
39.27,136.01,0.160
39.30,136.16,0.160
39.33,136.30,0.160
39.36,136.44,0.160
39.38,136.58,0.160
39.41,136.72,0.160
39.44,136.86,0.160
39.47,137.01,0.160
39.50,137.15,0.161
39.53,137.29,0.161
39.55,137.43,0.161
39.58,137.57,0.161
39.61,137.72,0.161
39.64,137.86,0.161
39.67,138.00,0.161
39.69,138.14,0.161
39.72,138.28,0.161
39.75,138.42,0.161
39.78,138.57,0.161
39.81,138.71,0.161
39.84,138.85,0.161
39.86,138.99,0.161
39.89,139.13,0.161
39.92,139.27,0.161
39.95,139.42,0.161
39.98,139.56,0.161
40.01,139.70,0.161
40.04,139.84,0.161
40.06,139.98,0.161
40.09,140.12,0.161
40.12,140.27,0.161
40.15,140.41,0.161
40.18,140.55,0.161
40.21,140.69,0.161
40.23,140.83,0.161
40.26,140.98,0.162
40.29,141.12,0.162
40.32,141.26,0.162
40.35,141.40,0.162
40.38,141.54,0.162
40.40,141.68,0.162
40.43,141.83,0.162
40.46,141.97,0.162
40.49,142.11,0.162
40.52,142.25,0.162
40.54,142.39,0.162
40.57,142.53,0.162
40.60,142.68,0.162
40.63,142.82,0.162
40.66,142.96,0.162
40.69,143.10,0.163
40.71,143.24,0.163
40.74,143.38,0.163
40.77,143.53,0.163
40.80,143.67,0.163
40.83,143.81,0.163
40.86,143.95,0.163
40.89,144.09,0.163
40.91,144.23,0.163
40.94,144.38,0.163
40.97,144.52,0.163
41.00,144.66,0.163
41.03,144.80,0.163
41.06,144.94,0.163
41.08,145.09,0.163
41.11,145.23,0.163
41.14,145.37,0.163
41.17,145.51,0.163
41.20,145.65,0.163
41.23,145.79,0.163
41.25,145.94,0.163
41.28,146.08,0.163
41.31,146.22,0.163
41.34,146.36,0.164
41.37,146.50,0.164
41.39,146.64,0.164
41.42,146.79,0.164
41.45,146.93,0.164
41.48,147.07,0.164
41.51,147.21,0.164
41.54,147.35,0.164
41.56,147.50,0.164
41.59,147.64,0.164
41.62,147.78,0.164
41.65,147.92,0.164
41.68,148.06,0.164
41.71,148.20,0.164
41.74,148.34,0.164
41.76,148.49,0.164
41.79,148.63,0.164
41.82,148.77,0.164
41.85,148.91,0.164
41.88,149.05,0.165
41.91,149.20,0.165
41.93,149.34,
41.96,149.48,
41.99,,

[step]
Ramp 5.00 °C/min to -60.00 °C
Time,Temperature,Heat Flow (Normalized)
min,°C,W/g
42.99,150.15,-0.043
43.01,150.15,-0.043
43.04,150.14,-0.043
43.07,150.11,-0.059
43.10,150.05,-0.092
43.13,149.96,-0.134
43.16,149.85,-0.171
43.19,149.73,-0.197
43.21,149.60,-0.215
43.24,149.47,-0.224
43.27,149.34,-0.230
43.30,149.20,-0.234
43.33,149.06,-0.237
43.36,148.92,-0.239
43.38,148.79,-0.241
43.41,148.65,-0.241
43.44,148.51,-0.242
43.47,148.37,-0.242
43.50,148.23,-0.243
43.53,148.09,-0.243
43.55,147.95,-0.243
43.58,147.80,-0.244
43.61,147.66,-0.244
43.64,147.52,-0.244
43.67,147.38,-0.245
43.69,147.24,-0.245
43.72,147.10,-0.245
43.75,146.96,-0.245
43.78,146.82,-0.245
43.81,146.68,-0.245
43.84,146.54,-0.246
43.86,146.40,-0.246
43.89,146.25,-0.246
43.92,146.11,-0.246
43.95,145.97,-0.246
43.98,145.83,-0.246
44.01,145.69,-0.246
44.04,145.55,-0.246
44.06,145.41,-0.246
44.09,145.27,-0.246
44.12,145.12,-0.246
44.15,144.98,-0.246
44.18,144.84,-0.246
44.21,144.70,-0.246
44.23,144.56,-0.246
44.26,144.42,-0.246
44.29,144.28,-0.246
44.32,144.13,-0.246
44.35,143.99,-0.246
44.38,143.85,-0.246
44.40,143.71,-0.246
44.43,143.57,-0.246
44.46,143.43,-0.246
44.49,143.28,-0.246
44.52,143.14,-0.245
44.54,143.00,-0.245
44.57,142.86,-0.245
44.60,142.72,-0.245
44.63,142.58,-0.245
44.66,142.44,-0.245
44.69,142.29,-0.245
44.71,142.15,-0.245
44.74,142.01,-0.245
44.77,141.87,-0.245
44.80,141.73,-0.245
44.83,141.59,-0.245
44.86,141.44,-0.245
44.89,141.30,-0.245
44.91,141.16,-0.245
44.94,141.02,-0.245
44.97,140.88,-0.245
45.00,140.74,-0.244
45.03,140.59,-0.244
45.06,140.45,-0.244
45.08,140.31,-0.244
45.11,140.17,-0.244
45.14,140.03,-0.244
45.17,139.89,-0.244
45.20,139.74,-0.244
45.23,139.60,-0.244
45.25,139.46,-0.244
45.28,139.32,-0.244
45.31,139.18,-0.244
45.34,139.04,-0.244
45.37,138.89,-0.243
45.39,138.75,-0.243
45.42,138.61,-0.243
45.45,138.47,-0.243
45.48,138.33,-0.243
45.51,138.19,-0.243
45.54,138.05,-0.243
45.56,137.90,-0.243
45.59,137.76,-0.243
45.62,137.62,-0.243
45.65,137.48,-0.243
45.68,137.34,-0.243
45.71,137.20,-0.242
45.74,137.05,-0.242
45.76,136.91,-0.242
45.79,136.77,-0.242
45.82,136.63,-0.242
45.85,136.49,-0.242
45.88,136.35,-0.242
45.91,136.20,-0.242
45.93,136.06,-0.242
45.96,135.92,-0.242
45.99,135.78,-0.242
46.02,135.64,-0.242
46.05,135.50,-0.242
46.08,135.35,-0.242
46.10,135.21,-0.242
46.13,135.07,-0.242
46.16,134.93,-0.242
46.19,134.79,-0.242
46.22,134.65,-0.241
46.24,134.50,-0.241
46.27,134.36,-0.241
46.30,134.22,-0.241
46.33,134.08,-0.241
46.36,133.94,-0.241
46.39,133.80,-0.241
46.41,133.65,-0.241
46.44,133.51,-0.241
46.47,133.37,-0.241
46.50,133.23,-0.241
46.53,133.09,-0.241
46.56,132.94,-0.241
46.59,132.80,-0.241
46.61,132.66,-0.241
46.64,132.52,-0.241
46.67,132.38,-0.241
46.70,132.24,-0.240
46.73,132.09,-0.240
46.76,131.95,-0.240
46.78,131.81,-0.240
46.81,131.67,-0.240
46.84,131.53,-0.240
46.87,131.39,-0.240
46.90,131.25,-0.240
46.93,131.10,-0.240
46.95,130.96,-0.240
46.98,130.82,-0.240
47.01,130.68,-0.240
47.04,130.54,-0.240
47.07,130.40,-0.240
47.09,130.25,-0.239
47.12,130.11,-0.240
47.15,129.97,-0.239
47.18,129.83,-0.239
47.21,129.69,-0.239
47.24,129.55,-0.239
47.26,129.40,-0.239
47.29,129.26,-0.239
47.32,129.12,-0.239
47.35,128.98,-0.239
47.38,128.84,-0.239
47.41,128.69,-0.239
47.44,128.55,-0.239
47.46,128.41,-0.239
47.49,128.27,-0.239
47.52,128.13,-0.239
47.55,127.99,-0.239
47.58,127.85,-0.239
47.61,127.70,-0.239
47.63,127.56,-0.239
47.66,127.42,-0.239
47.69,127.28,-0.239
47.72,127.14,-0.239
47.75,127.00,-0.239
47.78,126.85,-0.239
47.80,126.71,-0.239
47.83,126.57,-0.238
47.86,126.43,-0.238
47.89,126.29,-0.238
47.92,126.15,-0.238
47.94,126.00,-0.238
47.97,125.86,-0.238
48.00,125.72,-0.238
48.03,125.58,-0.238
48.06,125.44,-0.238
48.09,125.30,-0.238
48.11,125.15,-0.238
48.14,125.01,-0.238
48.17,124.87,-0.238
48.20,124.73,-0.238
48.23,124.59,-0.238
48.26,124.45,-0.238
48.29,124.30,-0.238
48.31,124.16,-0.238
48.34,124.02,-0.238
48.37,123.88,-0.238
48.40,123.74,-0.237
48.43,123.60,-0.237
48.46,123.45,-0.237
48.48,123.31,-0.237
48.51,123.17,-0.237
48.54,123.03,-0.237
48.57,122.89,-0.237
48.60,122.75,-0.237
48.63,122.60,-0.237
48.65,122.46,-0.237
48.68,122.32,-0.237
48.71,122.18,-0.237
48.74,122.04,-0.237
48.77,121.89,-0.237
48.79,121.75,-0.237
48.82,121.61,-0.237
48.85,121.47,-0.237
48.88,121.33,-0.237
48.91,121.19,-0.237
48.94,121.04,-0.237
48.96,120.90,-0.237
48.99,120.76,-0.236
49.02,120.62,-0.237
49.05,120.48,-0.236
49.08,120.34,-0.236
49.11,120.20,-0.236
49.14,120.05,-0.236
49.16,119.91,-0.236
49.19,119.77,-0.236
49.22,119.63,-0.236
49.25,119.49,-0.236
49.28,119.34,-0.236
49.31,119.20,-0.236
49.33,119.06,-0.236
49.36,118.92,-0.236
49.39,118.78,-0.236
49.42,118.64,-0.236
49.45,118.50,-0.236
49.48,118.35,-0.236
49.50,118.21,-0.236
49.53,118.07,-0.236
49.56,117.93,-0.236
49.59,117.79,-0.235
49.62,117.65,-0.235
49.64,117.50,-0.235
49.67,117.36,-0.235
49.70,117.22,-0.235
49.73,117.08,-0.235
49.76,116.94,-0.235
49.79,116.80,-0.235
49.81,116.65,-0.235
49.84,116.51,-0.235
49.87,116.37,-0.235
49.90,116.23,-0.235
49.93,116.09,-0.235
49.96,115.95,-0.235
49.99,115.80,-0.235
50.01,115.66,-0.235
50.04,115.52,-0.235
50.07,115.38,-0.235
50.10,115.24,-0.235
50.13,115.10,-0.234
50.16,114.95,-0.234
50.18,114.81,-0.234
50.21,114.67,-0.234
50.24,114.53,-0.234
50.27,114.39,-0.234
50.30,114.25,-0.234
50.33,114.10,-0.234
50.35,113.96,-0.234
50.38,113.82,-0.234
50.41,113.68,-0.234
50.44,113.54,-0.234
50.47,113.39,-0.234
50.49,113.25,-0.234
50.52,113.11,-0.234
50.55,112.97,-0.234
50.58,112.83,-0.234
50.61,112.69,-0.234
50.64,112.55,-0.234
50.66,112.40,-0.233
50.69,112.26,-0.233
50.72,112.12,-0.233
50.75,111.98,-0.233
50.78,111.84,-0.233
50.81,111.70,-0.233
50.84,111.55,-0.233
50.86,111.41,-0.233
50.89,111.27,-0.233
50.92,111.13,-0.233
50.95,110.99,-0.233
50.98,110.85,-0.233
51.01,110.71,-0.233
51.03,110.56,-0.233
51.06,110.42,-0.233
51.09,110.28,-0.233
51.12,110.14,-0.233
51.15,109.99,-0.233
51.18,109.85,-0.233
51.20,109.71,-0.233
51.23,109.57,-0.233
51.26,109.43,-0.233
51.29,109.29,-0.233
51.32,109.15,-0.233
51.34,109.00,-0.233
51.37,108.86,-0.232
51.40,108.72,-0.232
51.43,108.58,-0.232
51.46,108.44,-0.232
51.49,108.30,-0.232
51.51,108.15,-0.232
51.54,108.01,-0.232
51.57,107.87,-0.232
51.60,107.73,-0.232
51.63,107.59,-0.232
51.66,107.44,-0.232
51.69,107.30,-0.232
51.71,107.16,-0.232
51.74,107.02,-0.232
51.77,106.88,-0.232
51.80,106.74,-0.232
51.83,106.59,-0.232
51.86,106.45,-0.232
51.88,106.31,-0.231
51.91,106.17,-0.231
51.94,106.03,-0.231
51.97,105.89,-0.231
52.00,105.74,-0.231
52.03,105.60,-0.231
52.05,105.46,-0.231
52.08,105.32,-0.231
52.11,105.18,-0.231
52.14,105.04,-0.231
52.17,104.89,-0.231
52.19,104.75,-0.231
52.22,104.61,-0.231
52.25,104.47,-0.231
52.28,104.33,-0.231
52.31,104.19,-0.231
52.34,104.05,-0.231
52.36,103.90,-0.231
52.39,103.76,-0.231
52.42,103.62,-0.231
52.45,103.48,-0.231
52.48,103.34,-0.231
52.51,103.19,-0.230
52.54,103.05,-0.230
[...]
191.74,38.23,0.103,1.100
191.77,38.37,0.103,1.101
191.79,38.51,0.103,1.101
191.82,38.65,0.103,1.102
191.85,38.79,0.103,1.101
191.88,38.94,0.103,1.101
191.91,39.08,0.103,1.101
191.93,39.22,0.103,1.101
191.96,39.36,0.103,1.104
191.99,39.50,0.103,1.103
192.02,39.65,0.103,1.104
192.05,39.79,0.104,1.105
192.08,39.93,0.104,1.106
192.10,40.07,0.104,1.107
192.13,40.21,0.104,1.106
192.16,40.35,0.104,1.108
192.19,40.50,0.104,1.109
192.22,40.64,0.104,1.110
192.25,40.78,0.104,1.110
192.28,40.92,0.104,1.110
192.30,41.06,0.104,1.110
192.33,41.20,0.104,1.112
192.36,41.35,0.104,1.111
192.39,41.49,0.104,1.112
192.42,41.63,0.104,1.112
192.45,41.77,0.104,1.113
192.47,41.91,0.104,1.114
192.50,42.06,0.104,1.114
192.53,42.20,0.105,1.114
192.56,42.34,0.105,1.115
192.59,42.48,0.105,1.115
192.62,42.62,0.105,1.115
192.64,42.76,0.105,1.116
192.67,42.91,0.105,1.115
192.70,43.05,0.105,1.117
192.73,43.19,0.105,1.118
192.76,43.33,0.105,1.119
192.78,43.47,0.105,1.120
192.81,43.62,0.105,1.120
192.84,43.76,0.105,1.121
192.87,43.90,0.105,1.121
192.90,44.04,0.105,1.120
192.93,44.18,0.105,1.121
192.95,44.32,0.105,1.121
192.98,44.47,0.105,1.122
193.01,44.61,0.105,1.122
193.04,44.75,0.105,1.122
193.07,44.89,0.105,1.123
193.10,45.03,0.106,1.125
193.13,45.17,0.106,1.124
193.15,45.32,0.106,1.125
193.18,45.46,0.106,1.126
193.21,45.60,0.106,1.127
193.24,45.74,0.106,1.129
193.27,45.88,0.106,1.129
193.30,46.02,0.106,1.130
193.32,46.17,0.106,1.130
193.35,46.31,0.106,1.130
193.38,46.45,0.106,1.131
193.41,46.59,0.106,1.131
193.44,46.73,0.106,1.131
193.47,46.87,0.106,1.130
193.49,47.02,0.106,1.132
193.52,47.16,0.106,1.132
193.55,47.30,0.106,1.132
193.58,47.44,0.106,1.132
193.61,47.58,0.106,1.133
193.63,47.72,0.107,1.133
193.66,47.87,0.107,1.136
193.69,48.01,0.107,1.136
193.72,48.15,0.107,1.136
193.75,48.29,0.107,1.138
193.78,48.43,0.107,1.140
193.80,48.58,0.107,1.140
193.83,48.72,0.107,1.141
193.86,48.86,0.107,1.139
193.89,49.00,0.107,1.140
193.92,49.14,0.107,1.140
193.95,49.28,0.107,1.141
193.98,49.43,0.107,1.142
194.00,49.57,0.107,1.143
194.03,49.71,0.107,1.143
194.06,49.85,0.108,1.145
194.09,49.99,0.108,1.146
194.12,50.14,0.108,1.147
194.15,50.28,0.108,1.148
194.17,50.42,0.108,1.149
194.20,50.56,0.108,1.148
194.23,50.70,0.108,1.150
194.26,50.84,0.108,1.152
194.29,50.99,0.108,1.151
194.32,51.13,0.108,1.153
194.34,51.27,0.108,1.154
194.37,51.41,0.108,1.155
194.40,51.55,0.108,1.156
194.43,51.69,0.108,1.156
194.46,51.84,0.108,1.156
194.48,51.98,0.109,1.157
194.51,52.12,0.109,1.157
194.54,52.26,0.109,1.158
194.57,52.40,0.109,1.160
194.60,52.55,0.109,1.159
194.63,52.69,0.109,1.160
194.65,52.83,0.109,1.161
194.68,52.97,0.109,1.162
194.71,53.11,0.109,1.162
194.74,53.25,0.109,1.164
194.77,53.40,0.109,1.164
194.80,53.54,0.109,1.166
194.83,53.68,0.109,1.167
194.85,53.82,0.110,1.167
194.88,53.96,0.110,1.169
194.91,54.10,0.110,1.170
194.94,54.25,0.110,1.171
194.97,54.39,0.110,1.173
195.00,54.53,0.110,1.174
195.02,54.67,0.110,1.175
195.05,54.81,0.110,1.177
195.08,54.95,0.110,1.177
195.11,55.10,0.110,1.178
195.14,55.24,0.110,1.178
195.17,55.38,0.110,1.179
195.19,55.52,0.110,1.178
195.22,55.66,0.111,1.178
195.25,55.80,0.111,1.179
195.28,55.95,0.111,1.181
195.31,56.09,0.111,1.181
195.33,56.23,0.111,1.183
195.36,56.37,0.111,1.183
195.39,56.51,0.111,1.186
195.42,56.66,0.111,1.188
195.45,56.80,0.111,1.189
195.48,56.94,0.112,1.190
195.50,57.08,0.112,1.191
195.53,57.22,0.112,1.191
195.56,57.36,0.112,1.194
195.59,57.51,0.112,1.195
195.62,57.65,0.112,1.197
195.65,57.79,0.112,1.198
195.68,57.93,0.112,1.200
195.70,58.07,0.112,1.200
195.73,58.21,0.112,1.202
195.76,58.36,0.113,1.202
195.79,58.50,0.113,1.203
195.82,58.64,0.113,1.203
195.85,58.78,0.113,1.203
195.87,58.92,0.113,1.205
195.90,59.06,0.113,1.206
195.93,59.20,0.113,1.207
195.96,59.35,0.113,1.208
195.99,59.49,0.113,1.209
196.02,59.63,0.113,1.211
196.04,59.77,0.114,1.211
196.07,59.91,0.114,1.213
196.10,60.05,0.114,1.214
196.13,60.20,0.114,1.216
196.16,60.34,0.114,1.216
196.18,60.48,0.114,1.217
196.21,60.62,0.114,1.218
196.24,60.77,0.114,1.220
196.27,60.91,0.115,1.223
196.30,61.05,0.115,1.224
196.33,61.19,0.115,1.224
196.35,61.33,0.115,1.226
196.38,61.47,0.115,1.227
196.41,61.61,0.115,1.229
196.44,61.76,0.115,1.230
196.47,61.90,0.115,1.231
196.50,62.04,0.116,1.233
196.53,62.18,0.116,1.235
196.55,62.32,0.116,1.237
196.58,62.47,0.116,1.239
196.61,62.61,0.116,1.241
196.64,62.75,0.116,1.242
196.67,62.89,0.117,1.244
196.70,63.03,0.117,1.246
196.72,63.18,0.117,1.247
196.75,63.32,0.117,1.249
196.78,63.46,0.117,1.251
196.81,63.60,0.117,1.252
196.84,63.74,0.117,1.254
196.87,63.88,0.118,1.256
196.89,64.03,0.118,1.256
196.92,64.17,0.118,1.258
196.95,64.31,0.118,1.261
196.98,64.45,0.118,1.262
197.01,64.59,0.118,1.263
197.03,64.73,0.119,1.266
197.06,64.88,0.119,1.268
197.09,65.02,0.119,1.271
197.12,65.16,0.119,1.273
197.15,65.30,0.119,1.274
197.18,65.44,0.120,1.276
197.20,65.58,0.120,1.278
197.23,65.73,0.120,1.280
197.26,65.87,0.120,1.282
197.29,66.01,0.120,1.284
197.32,66.15,0.121,1.285
197.35,66.29,0.121,1.288
197.38,66.43,0.121,1.291
197.40,66.58,0.121,1.293
197.43,66.72,0.121,1.296
197.46,66.86,0.122,1.298
197.49,67.00,0.122,1.300
197.52,67.14,0.122,1.302
197.55,67.28,0.122,1.304
197.57,67.43,0.122,1.306
197.60,67.57,0.123,1.308
197.63,67.71,0.123,1.311
197.66,67.85,0.123,1.315
197.69,67.99,0.123,1.317
197.72,68.14,0.124,1.321
197.74,68.28,0.124,1.323
197.77,68.42,0.124,1.326
197.80,68.56,0.124,1.329
197.83,68.70,0.125,1.330
197.86,68.84,0.125,1.333
197.88,68.99,0.125,1.334
197.91,69.13,0.125,1.338
197.94,69.27,0.126,1.341
197.97,69.41,0.126,1.344
198.00,69.55,0.126,1.347
198.03,69.69,0.127,1.349
198.05,69.84,0.127,1.353
198.08,69.98,0.127,1.357
198.11,70.12,0.127,1.360
198.14,70.26,0.128,1.363
198.17,70.40,0.128,1.367
198.20,70.54,0.128,1.371
198.23,70.69,0.129,1.374
198.25,70.83,0.129,1.377
198.28,70.97,0.129,1.380
198.31,71.11,0.130,1.383
198.34,71.25,0.130,1.387
198.37,71.39,0.130,1.389
198.40,71.54,0.131,1.393
198.42,71.68,0.131,1.396
198.45,71.82,0.131,1.398
198.48,71.96,0.131,1.401
198.51,72.10,0.132,1.404
198.54,72.24,0.132,1.407
198.57,72.39,0.132,1.411
198.59,72.53,0.133,1.414
198.62,72.67,0.133,1.418
198.65,72.81,0.134,1.423
198.68,72.95,0.134,1.427
198.71,73.10,0.134,1.430
198.73,73.24,0.135,1.435
198.76,73.38,0.135,1.439
198.79,73.52,0.135,1.443
198.82,73.66,0.135,1.447
198.85,73.80,0.136,1.450
198.88,73.94,0.136,1.454
198.90,74.09,0.137,1.458
198.93,74.23,0.137,1.461
198.96,74.37,0.137,1.465
198.99,74.51,0.138,1.469
199.02,74.65,0.138,1.472
199.05,74.80,0.138,1.476
199.08,74.94,0.138,1.480
199.10,75.08,0.139,1.483
199.13,75.22,0.139,1.486
199.16,75.36,0.139,1.488
199.19,75.50,0.140,1.491
199.22,75.64,0.140,1.494
199.25,75.79,0.140,1.498
199.27,75.93,0.141,1.500
199.30,76.07,0.141,1.503
199.33,76.21,0.141,1.505
199.36,76.35,0.141,1.509
199.39,76.49,0.142,1.511
199.42,76.64,0.142,1.513
199.44,76.78,0.142,1.515
199.47,76.92,0.142,1.518
199.50,77.06,0.143,1.521
199.53,77.20,0.143,1.525
199.56,77.34,0.143,1.527
199.58,77.49,0.143,1.528
199.61,77.63,0.144,1.530
199.64,77.77,0.144,1.533
199.67,77.91,0.144,1.535
199.70,78.05,0.144,1.537
199.73,78.20,0.144,1.539
199.75,78.34,0.145,1.541
199.78,78.48,0.145,1.544
199.81,78.62,0.145,1.547
199.84,78.76,0.145,1.548
199.87,78.91,0.145,1.549
199.90,79.05,0.145,1.550
199.93,79.19,0.145,1.551
199.95,79.33,0.146,1.553
199.98,79.47,0.146,1.554
200.01,79.61,0.146,1.554
200.04,79.76,0.146,1.555
200.07,79.90,0.146,1.556
200.10,80.04,0.146,1.557
200.12,80.18,0.146,1.556
200.15,80.32,0.146,1.557
200.18,80.46,0.146,1.558
200.21,80.61,0.146,1.558
200.24,80.75,0.146,1.558
200.27,80.89,0.146,1.559
200.29,81.03,0.146,1.559
200.32,81.17,0.146,1.558
200.35,81.31,0.146,1.559
200.38,81.46,0.146,1.558
200.41,81.60,0.146,1.559
200.43,81.74,0.146,1.560
200.46,81.88,0.146,1.558
200.49,82.02,0.146,1.557
200.52,82.16,0.146,1.557
200.55,82.31,0.146,1.557
200.58,82.45,0.146,1.556
200.60,82.59,0.146,1.556
200.63,82.73,0.146,1.556
200.66,82.87,0.146,1.556
200.69,83.02,0.146,1.557
200.72,83.16,0.146,1.557
200.75,83.30,0.146,1.556
200.78,83.44,0.146,1.556
200.80,83.58,0.146,1.555
200.83,83.72,0.146,1.555
200.86,83.87,0.146,1.555
200.89,84.01,0.146,1.556
200.92,84.15,0.146,1.555
200.95,84.29,0.146,1.555
200.97,84.43,0.146,1.555
201.00,84.58,0.146,1.555
201.03,84.72,0.146,1.553
201.06,84.86,0.146,1.552
201.09,85.00,0.146,1.551
201.12,85.14,0.146,1.551
201.14,85.28,0.146,1.552
201.17,85.43,0.146,1.552
201.20,85.57,0.146,1.551
201.23,85.71,0.146,1.551
201.26,85.85,0.146,1.552
201.28,85.99,0.146,1.551
201.31,86.14,0.146,1.552
201.34,86.28,0.146,1.551
201.37,86.42,0.146,1.553
201.40,86.56,0.146,1.554
201.43,86.70,0.146,1.553
201.45,86.85,0.146,1.554
201.48,86.99,0.146,1.555
201.51,87.13,0.146,1.555
201.54,87.27,0.146,1.555
201.57,87.41,0.146,1.554
201.60,87.55,0.146,1.552
201.63,87.70,0.146,1.552
201.65,87.84,0.146,1.552
201.68,87.98,0.146,1.551
201.71,88.12,0.146,1.552
201.74,88.26,0.146,1.553
201.77,88.41,0.146,1.556
201.80,88.55,0.146,1.557
201.82,88.69,0.146,1.558
201.85,88.83,0.146,1.558
201.88,88.97,0.146,1.558
201.91,89.11,0.146,1.557
201.94,89.25,0.146,1.557
201.97,89.40,0.146,1.557
201.99,89.54,0.146,1.558
202.02,89.68,0.146,1.557
202.05,89.82,0.146,1.557
202.08,89.96,0.146,1.558
202.11,90.10,0.146,1.558
202.13,90.25,0.146,1.558
202.16,90.39,0.146,1.557
202.19,90.53,0.146,1.557
202.22,90.67,0.146,1.559
202.25,90.81,0.146,1.558
202.28,90.96,0.146,1.560
202.30,91.10,0.146,1.560
202.33,91.24,0.146,1.561
202.36,91.38,0.147,1.564
202.39,91.52,0.147,1.565
202.42,91.67,0.147,1.565
202.45,91.81,0.147,1.567
202.48,91.95,0.147,1.566
202.50,92.09,0.147,1.566
202.53,92.23,0.147,1.567
202.56,92.37,0.147,1.566
202.59,92.52,0.147,1.566
202.62,92.66,0.147,1.567
202.65,92.80,0.147,1.566
202.67,92.94,0.147,1.567
202.70,93.08,0.147,1.568
202.73,93.22,0.147,1.567
202.76,93.37,0.147,1.567
202.79,93.51,0.147,1.567
202.82,93.65,0.147,1.568
202.84,93.79,0.147,1.567
202.87,93.93,0.147,1.568
202.90,94.07,0.147,1.568
202.93,94.22,0.147,1.569
202.96,94.36,0.147,1.570
202.98,94.50,0.147,1.571
203.01,94.64,0.147,1.570
203.04,94.78,0.147,1.571
203.07,94.92,0.147,1.571
203.10,95.06,0.147,1.571
203.13,95.21,0.147,1.572
203.15,95.35,0.147,1.571
203.18,95.49,0.147,1.573
203.21,95.63,0.148,1.574
203.24,95.77,0.148,1.573
203.27,95.91,0.148,1.574
203.30,96.06,0.148,1.573
203.33,96.20,0.148,1.574
203.35,96.34,0.148,1.575
203.38,96.48,0.148,1.576
203.41,96.62,0.148,1.576
203.44,96.77,0.148,1.576
203.47,96.91,0.148,1.577
203.50,97.05,0.148,1.579
203.52,97.19,0.148,1.579
203.55,97.33,0.148,1.580
203.58,97.47,0.148,1.579
203.61,97.62,0.148,1.579
203.64,97.76,0.148,1.580
203.67,97.90,0.148,1.580
203.69,98.04,0.148,1.579
203.72,98.18,0.148,1.578
203.75,98.33,0.148,1.580
203.78,98.47,0.148,1.581
203.81,98.61,0.148,1.582
203.83,98.75,0.149,1.583
203.86,98.89,0.149,1.583
203.89,99.03,0.149,1.585
203.92,99.18,0.149,1.585
203.95,99.32,0.149,1.586
203.98,99.46,0.149,1.586
204.00,99.60,0.149,1.586
204.03,99.74,0.149,1.586
204.06,99.89,0.149,1.587
204.09,100.03,0.149,1.587
204.12,100.17,0.149,1.587
204.15,100.31,0.149,1.589
204.18,100.45,0.149,1.589
204.20,100.59,0.149,1.590
204.23,100.73,0.149,1.591
204.26,100.88,0.149,1.590
204.29,101.02,0.149,1.591
204.32,101.16,0.149,1.590
204.35,101.30,0.149,1.589
204.37,101.44,0.149,1.589
204.40,101.59,0.149,1.589
204.43,101.73,0.149,1.591
204.46,101.87,0.150,1.591
204.49,102.01,0.150,1.592
204.52,102.15,0.150,1.592
204.54,102.29,0.150,1.594
204.57,102.44,0.150,1.594
204.60,102.58,0.150,1.595
204.63,102.72,0.150,1.595
204.66,102.86,0.150,1.595
204.68,103.00,0.150,1.594
204.71,103.14,0.150,1.595
204.74,103.29,0.150,1.595
204.77,103.43,0.150,1.596
204.80,103.57,0.150,1.595
204.83,103.71,0.150,1.596
204.85,103.85,0.150,1.597
204.88,104.00,0.150,1.598
204.91,104.14,0.150,1.598
204.94,104.28,0.150,1.598
204.97,104.42,0.150,1.598
205.00,104.56,0.150,1.600
205.03,104.70,0.150,1.599
205.05,104.85,0.150,1.599
205.08,104.99,0.150,1.599
205.11,105.13,0.150,1.601
205.14,105.27,0.150,1.600
205.17,105.41,0.150,1.600
205.20,105.56,0.151,1.602
205.22,105.70,0.151,1.604
205.25,105.84,0.151,1.604
205.28,105.98,0.151,1.605
205.31,106.12,0.151,1.605
205.34,106.26,0.151,1.606
205.37,106.40,0.151,1.608
205.39,106.55,0.151,1.606
205.42,106.69,0.151,1.606
205.45,106.83,0.151,1.606
205.48,106.97,0.151,1.605
205.51,107.11,0.151,1.604
205.53,107.25,0.151,1.605
205.56,107.40,0.151,1.604
205.59,107.54,0.151,1.604
205.62,107.68,0.151,1.605
205.65,107.82,0.151,1.607
205.68,107.97,0.151,1.608
205.70,108.11,0.151,1.610
205.73,108.25,0.151,1.608
205.76,108.39,0.151,1.609
205.79,108.53,0.151,1.611
205.82,108.67,0.151,1.610
205.85,108.81,0.151,1.610
205.88,108.96,0.151,1.611
205.90,109.10,0.151,1.611
205.93,109.24,0.152,1.612
205.96,109.38,0.152,1.612
205.99,109.52,0.152,1.613
206.02,109.67,0.152,1.615
206.05,109.81,0.152,1.615
206.07,109.95,0.152,1.614
206.10,110.09,0.152,1.615
206.13,110.23,0.152,1.615
206.16,110.37,0.152,1.615
206.19,110.51,0.152,1.616
206.22,110.66,0.152,1.614
206.24,110.80,0.152,1.613
206.27,110.94,0.152,1.613
206.30,111.08,0.152,1.612
206.33,111.22,0.152,1.613
206.36,111.37,0.152,1.612
206.38,111.51,0.152,1.613
206.41,111.65,0.152,1.615
206.44,111.79,0.152,1.615
206.47,111.93,0.152,1.616
206.50,112.07,0.152,1.616
206.53,112.22,0.152,1.617
206.55,112.36,0.152,1.617
206.58,112.50,0.152,1.618
206.61,112.64,0.152,1.620
206.64,112.78,0.152,1.621
206.67,112.93,0.152,1.620
206.70,113.07,0.152,1.621
206.73,113.21,0.152,1.620
206.75,113.35,0.152,1.619
206.78,113.49,0.153,1.619
206.81,113.63,0.153,1.619
206.84,113.78,0.153,1.619
206.87,113.92,0.153,1.620
206.90,114.06,0.153,1.620
206.92,114.20,0.153,1.623
206.95,114.34,0.153,1.624
206.98,114.49,0.153,1.624
207.01,114.63,0.153,1.625
207.04,114.77,0.153,1.626
207.07,114.91,0.153,1.626
207.09,115.05,0.153,1.626
207.12,115.19,0.153,1.627
207.15,115.34,0.153,1.627
207.18,115.48,0.153,1.628
207.21,115.62,0.153,1.628
207.23,115.76,0.153,1.628
207.26,115.90,0.153,1.628
207.29,116.04,0.153,1.629
207.32,116.19,0.153,1.629
207.35,116.33,0.153,1.630
207.38,116.47,0.153,1.629
207.40,116.61,0.153,1.629
207.43,116.75,0.153,1.629
207.46,116.89,0.153,1.630
207.49,117.04,0.153,1.629
207.52,117.18,0.153,1.629
207.55,117.32,0.153,1.629
207.58,117.46,0.153,1.629
207.60,117.60,0.153,1.630
207.63,117.75,0.153,1.629
207.66,117.89,0.154,1.630
207.69,118.03,0.154,1.630
207.72,118.17,0.154,1.631
207.75,118.31,0.154,1.630
207.77,118.45,0.154,1.631
207.80,118.60,0.154,1.631
207.83,118.74,0.154,1.633
207.86,118.88,0.154,1.632
207.89,119.02,0.154,1.634
207.92,119.16,0.154,1.634
207.94,119.31,0.154,1.636
207.97,119.45,0.154,1.636
208.00,119.59,0.154,1.637
208.03,119.73,0.154,1.638
208.06,119.87,0.154,1.639
208.08,120.01,0.154,1.639
208.11,120.16,0.154,1.640
208.14,120.30,0.154,1.638
208.17,120.44,0.154,1.637
208.20,120.58,0.154,1.637
208.23,120.72,0.154,1.636
208.25,120.86,0.154,1.637
208.28,121.01,0.155,1.638
208.31,121.15,0.155,1.640
208.34,121.29,0.155,1.641
208.37,121.43,0.155,1.644
208.40,121.57,0.155,1.645
208.43,121.72,0.155,1.646
208.45,121.86,0.155,1.646
208.48,122.00,0.155,1.647
208.51,122.14,0.155,1.645
208.54,122.28,0.155,1.647
208.57,122.42,0.155,1.646
208.60,122.56,0.155,1.646
208.62,122.71,0.155,1.646
208.65,122.85,0.155,1.645
208.68,122.99,0.155,1.645
208.71,123.13,0.155,1.647
208.74,123.27,0.155,1.647
208.77,123.41,0.155,1.646
208.79,123.56,0.155,1.644
208.82,123.70,0.155,1.645
208.85,123.84,0.155,1.647
208.88,123.98,0.155,1.647
208.91,124.12,0.155,1.648
208.93,124.27,0.155,1.649
208.96,124.41,0.156,1.651
208.99,124.55,0.156,1.652
209.02,124.69,0.156,1.653
209.05,124.83,0.156,1.653
209.08,124.97,0.156,1.653
209.10,125.11,0.156,1.653
209.13,125.26,0.156,1.654
209.16,125.40,0.156,1.653
209.19,125.54,0.156,1.655
209.22,125.68,0.156,1.655
209.25,125.82,0.156,1.655
209.28,125.97,0.156,1.656
209.30,126.11,0.156,1.656
209.33,126.25,0.156,1.658
209.36,126.39,0.156,1.659
209.39,126.53,0.156,1.659
209.42,126.68,0.156,1.659
209.45,126.82,0.156,1.659
209.47,126.96,0.156,1.659
209.50,127.10,0.156,1.659
209.53,127.24,0.156,1.658
209.56,127.38,0.156,1.657
209.59,127.52,0.156,1.656
209.62,127.67,0.156,1.656
209.64,127.81,0.156,1.657
209.67,127.95,0.157,1.657
209.70,128.09,0.157,1.658
209.73,128.24,0.157,1.660
209.76,128.38,0.157,1.663
209.78,128.52,0.157,1.665
209.81,128.66,0.157,1.666
209.84,128.80,0.157,1.667
209.87,128.94,0.157,1.668
209.90,129.09,0.157,1.668
209.93,129.23,0.157,1.668
209.95,129.37,0.157,1.668
209.98,129.51,0.157,1.667
210.01,129.65,0.157,1.667
210.04,129.79,0.157,1.668
210.07,129.93,0.157,1.669
210.10,130.08,0.157,1.668
210.13,130.22,0.157,1.668
210.15,130.36,0.157,1.669
210.18,130.50,0.158,1.671
210.21,130.64,0.158,1.671
210.24,130.79,0.158,1.672
210.27,130.93,0.158,1.673
210.30,131.07,0.158,1.672
210.32,131.21,0.158,1.672
210.35,131.35,0.158,1.673
210.38,131.49,0.158,1.672
210.41,131.64,0.158,1.673
210.44,131.78,0.158,1.672
210.47,131.92,0.158,1.673
210.49,132.06,0.158,1.673
210.52,132.20,0.158,1.674
210.55,132.34,0.158,1.675
210.58,132.49,0.158,1.676
210.61,132.63,0.158,1.676
210.63,132.77,0.158,1.677
210.66,132.91,0.158,1.676
210.69,133.05,0.158,1.677
210.72,133.20,0.158,1.677
210.75,133.34,0.158,1.678
210.78,133.48,0.158,1.678
210.80,133.62,0.158,1.679
210.83,133.76,0.158,1.679
210.86,133.90,0.158,1.680
210.89,134.05,0.158,1.679
210.92,134.19,0.158,1.679
210.95,134.33,0.158,1.678
210.98,134.47,0.159,1.680
211.00,134.61,0.159,1.680
211.03,134.75,0.159,1.682
211.06,134.90,0.159,1.682
211.09,135.04,0.159,1.682
211.12,135.18,0.159,1.682
211.15,135.32,0.159,1.683
211.17,135.46,0.159,1.681
211.20,135.60,0.159,1.681
211.23,135.75,0.159,1.682
211.26,135.89,0.159,1.681
211.29,136.03,0.159,1.682
211.32,136.17,0.159,1.684
211.34,136.31,0.159,1.685
211.37,136.45,0.159,1.686
211.40,136.60,0.159,1.687
211.43,136.74,0.159,1.685
211.46,136.88,0.159,1.685
211.48,137.02,0.159,1.684
211.51,137.16,0.159,1.684
211.54,137.30,0.159,1.683
211.57,137.45,0.159,1.684
211.60,137.59,0.159,1.684
211.63,137.73,0.159,1.685
211.65,137.87,0.159,1.686
211.68,138.01,0.159,1.687
211.71,138.16,0.159,1.688
211.74,138.30,0.159,1.688
211.77,138.44,0.159,1.688
211.80,138.58,0.159,1.687
211.83,138.72,0.159,1.688
211.85,138.86,0.159,1.687
211.88,139.01,0.159,1.688
211.91,139.15,0.159,1.688
211.94,139.29,0.160,1.688
211.97,139.43,0.160,1.690
212.00,139.57,0.160,1.691
212.02,139.71,0.160,1.691
212.05,139.86,0.160,1.694
212.08,140.00,0.160,1.691
212.11,140.14,0.160,1.691
212.14,140.28,0.160,1.691
212.17,140.42,0.160,1.690
212.19,140.56,0.160,1.692
212.22,140.71,0.160,1.692
212.25,140.85,0.160,1.691
212.28,140.99,0.160,1.694
212.31,141.13,0.160,1.695
212.33,141.27,0.160,1.696
212.36,141.42,0.160,1.697
212.39,141.56,0.160,1.697
212.42,141.70,0.160,1.698
212.45,141.84,0.161,1.699
212.48,141.98,0.161,1.698
212.50,142.12,0.161,1.700
212.53,142.27,0.161,1.700
212.56,142.41,0.161,1.700
212.59,142.55,0.161,1.700
212.62,142.69,0.161,1.700
212.65,142.83,0.161,1.701
212.68,142.97,0.161,1.703
212.70,143.12,0.161,1.703
212.73,143.26,0.161,1.704
212.76,143.40,0.161,1.705
212.79,143.54,0.161,1.705
212.82,143.68,0.161,1.704
212.85,143.82,0.161,1.704
212.87,143.97,0.161,1.703
212.90,144.11,0.161,1.702
212.93,144.25,0.161,1.703
212.96,144.39,0.161,1.704
212.99,144.53,0.161,1.704
213.02,144.67,0.162,1.705
213.04,144.82,0.162,1.707
213.07,144.96,0.162,1.709
213.10,145.10,0.162,1.710
213.13,145.24,0.162,1.711
213.16,145.39,0.162,1.712
213.18,145.53,0.162,1.713
213.21,145.67,0.162,1.714
213.24,145.81,0.162,1.713
213.27,145.95,0.162,1.712
213.30,146.09,0.162,1.711
213.33,146.23,0.162,1.711
213.35,146.38,0.162,1.710
213.38,146.52,0.162,1.711
213.41,146.66,0.162,1.711
213.44,146.80,0.162,1.711
213.47,146.94,0.162,1.713
213.50,147.09,0.162,1.713
213.53,147.23,0.162,1.714
213.55,147.37,0.162,1.715
213.58,147.51,0.162,1.716
213.61,147.65,0.162,1.717
213.64,147.80,0.162,1.718
213.67,147.94,0.163,1.717
213.70,148.08,0.163,1.719
213.72,148.22,0.163,1.720
213.75,148.36,0.163,1.721
213.78,148.50,0.163,1.721
213.81,148.64,0.163,1.721
213.84,148.79,0.163,1.721
213.87,148.93,0.163,1.721
213.89,149.07,0.163,
213.92,149.21,0.163,
213.95,149.35,,
213.98,149.49,,
213.99,,,