File: DSC/Earl/2025_10_06_PVP10_5Cmin_n60C_170C_x3.csv
Filename,2025_10_06_PVP10_5Cmin_n60C_170C_x3
Instrument name,DSC2A-00468 (192.168.1.100)
Operator,JLY
rundate,10/6/2025
Sample name,2025_10_06_PVP10_5Cmin_n60C_170C_x3
proceduresegments,Data Off ; Equilibrate -60.00 °C; Data On ; Ramp 5.00 °C/min to 170.00 °C; Data Off ; Isothermal 1.0 min; Data On ; Ramp 5.00 °C/min to -60.00 °C; Data Off ; Isothermal 1.0 min; Data On ; Ramp 5.00 °C/min to 170.00 °C; Data Off ; Isothermal 1.0 min; Data On ; Ramp 5.00 °C/min to -60.00 °C; Data Off ; Isothermal 1.0 min; Data On ; Ramp 5.00 °C/min to 170.00 °C
[File Parameters]
Run date,10/6/2025 11:05:08 AM
Trios version,5.1.1.46572
Original File Name,
Current File Name,D:\DSC2500\JYarger\2025_10_06_PVP10_5Cmin_n60C_170C_x3.tri
[Procedure]
Procedure Name,ASD_n60C_170C_5Cmin_x3
Sample Name,2025_10_06_PVP10_5Cmin_n60C_170C_x3
Sample Mass,7.32 mg
Reference Sample Mass,0 mg
Pan Mass,32.47 mg
Pan Number,38
Reference Pan Mass,32.55 mg
Reference Pan Number,1
Pan Type,Aluminum
Comments,DSC_Samples_Y2_Tray_ASDs_Pharma_Oct2025 Google Sheet.
Project Name,Amorphous Pharma
Operator,JLY
Test,Custom
Unload Max Temperature,30
Unload Min Temperature,30
Load Max Temperature,30
Load Min Temperature,30
Stop on Gas Flow Error,Yes
[Signal List]
Signal #1,Time (min)
Signal #2,Temperature (°C)
Signal #3,Heat Flow (mW)
Signal #4,Delta T (µV)
Signal #5,Delta Tzero (µV)
Signal #6,Tzero Temperature (°C)
Signal #7,Cell Purge (mL/min)
Signal #8,Heater Temp (°C)
Signal #9,Power Delivered (W)
Signal #10,Reference Junction Temperature (°C)
Signal #11,Flange Temperature (°C)
Signal #12,Heat Flow Phase (rad)
Signal #13,Total Heat Capacity (J/°C)
Signal #14,Heat Capacity (J/°C)
[Configuration]
Company Name,ASU
Instrument Name,DSC2A-00468
Instrument Type,DSC2500
Serial Number,DSC2A-00468
IP,192.168.1.100
Location of Instrument,MRRC
DisplayType,Unknown
Sample Interval ,0.1 s/pt
Selected Heat Flow,T4P
Exotherm Direction,Down
Cell Serial,DRC2-00792
Lid Type,Standard
Cooler,RCS 90
Leave Cooler on at End of Sequence,On
Gas 2,Nitrogen
Gas Selected,Channel 1
Flow Rate,50 mL/min
Secondary Purge,On
Licensed Heat Flow,Heat Flow T4P
Modulation Licensed,Yes
[Versions]
Common IDD Version,1
Cortex Version,VER 2.10.2.31
Driver,5.0.0.6
GDM Version,1.0.3.3
TouchscreenVersion,1.0.0.16145
FEP Version,1.2.1.21
FEP Bootloader,2.0.0.5
AutoSampler Version,2.1.1.26
Auto Sampler Bootloader,2.0.0.5
FCM Version,1.1.0.3
FCM Bootloader,2.0.0.5
[Experiment Logs]
Experiment Log Entry # 1,Data On set to 0
Experiment Log Entry # 3,Equilibrate Segment -60 (C) Started
Experiment Log Entry # 5,Air Cool is off.
Experiment Log Entry # 7,Data On set to 1
Experiment Log Entry # 9,Ramp Segment 5 C/min to 170 Started
Experiment Log Entry # 11,Data On set to 0
Experiment Log Entry # 13,Isothermal Segment 1 min started
Experiment Log Entry # 15,Data On set to 1
Experiment Log Entry # 17,Ramp Segment 5 C/min to -60 Started
Experiment Log Entry # 19,Data On set to 0
Experiment Log Entry # 21,Isothermal Segment 1 min started
Experiment Log Entry # 23,Data On set to 1
Experiment Log Entry # 25,Ramp Segment 5 C/min to 170 Started
Experiment Log Entry # 27,Data On set to 0
Experiment Log Entry # 29,Isothermal Segment 1 min started
Experiment Log Entry # 31,Data On set to 1
Experiment Log Entry # 33,Ramp Segment 5 C/min to -60 Started
Experiment Log Entry # 35,Ending Experiment because user stopped
[Method Log]
Method Log Entry # 1,Data Off
Method Log Entry # 2,Equilibrate -60 °C
Method Log Entry # 3,Data On
Method Log Entry # 4,(Ramp 527095) Ramp 5 °C/minute to 170 °C
Method Log Entry # 5,Data Off
Method Log Entry # 6,Isothermal 1 minutes
Method Log Entry # 7,Data On
Method Log Entry # 8,(Ramp 527099) Ramp 5 °C/minute to -60 °C
Method Log Entry # 9,Data Off
Method Log Entry # 10,Isothermal 1 minutes
Method Log Entry # 11,Data On
Method Log Entry # 12,(Ramp 527103) Ramp 5 °C/minute to 170 °C
Method Log Entry # 13,Data Off
Method Log Entry # 14,Isothermal 1 minutes
Method Log Entry # 15,Data On
Method Log Entry # 16,(Ramp 527107) Ramp 5 °C/minute to -60 °C
Cell Serial,DRC2-00792
[T1 Calibration]
Slope,-0.008529666
Offset,9.636258
Initial Temperature,98.23
GUID,f8bfdadc-4977-4fdf-ba6d-0ba9134940c3
[TZero Calibration]
Date Applied,11/29/2022 4:06:13 PM
Description,From -89.059 °C to 396.009 °C at 20.000°C/min
Gas Type,Nitrogen
Pan Type,None
Source Files 1,C:\Users\yargerlab\Desktop\DSC Data\General\TZero_calibration_11_29_22_2nd(2).tri
Source Files 2,C:\Users\yargerlab\Desktop\DSC Data\General\TZero_calibration_11_29_22_2nd(3).tri
Delta T Offset,13.05235
Delta T Slope,-0.007271007
Delta T0 Offset,-13.69128
Delta T0 Slope,0.06063341
[Temperature Calibration]
Date Applied,11/29/2022 7:12:28 PM
Description,From 106.590 °C to 186.590 °C at 10.000°C/min
Gas Type,Nitrogen
Pan Type,Tzero Aluminum Hermetic
Source Files 1,C:\Users\yargerlab\Desktop\DSC Data\General\Indium(6).tri
Measured 1,157.391
Known 1,156.598
[Cell Constant Calibration]
Date Applied,11/29/2022 7:12:29 PM
Description,From 106.590 °C to 186.590 °C at 10.000°C/min
Gas Type,Nitrogen
Pan Type,Tzero Aluminum Hermetic
Source Files 1,C:\Users\yargerlab\Desktop\DSC Data\General\Indium(6).tri
T4P KCell,1.006051
Onset Slope,63.26126 mW/°C
[Direct Cp Calibration]
Date Applied,11/30/2022 11:04:51 AM
Description,From -79.983 °C to 298.409 °C at 10.000°C/min
Gas Type,Nitrogen
Pan Type,Tzero Aluminum Hermetic
Source Files 1,C:\Users\yargerlab\Desktop\DSC Data\General\Sapphire_Heat_Capacity_11_30_22.tri
[Rev Cp Calibration]
Date Applied,11/30/2022 1:58:51 PM
Description,From -79.996 °C to 292.812 °C at 3.000°C/min
Gas Type,Nitrogen
Pan Type,Tzero Aluminum Hermetic
Source Files 1,C:\Users\yargerlab\Desktop\DSC Data\General\Sapphire_MDSC_Calibration_11_30_22.tri
[step]
Ramp 5.00 °C/min to 170.00 °C
Time,Temperature,Heat Flow (Normalized)
min,°C,W/g
0.00,-59.80,-0.049
0.03,-59.81,-0.044
0.06,-59.80,-0.041
0.09,-59.74,-0.042
0.13,-59.64,-0.038
0.16,-59.51,-0.017
0.19,-59.38,0.003
0.22,-59.24,0.021
0.25,-59.10,0.034
0.29,-58.96,0.044
0.32,-58.82,0.051
0.35,-58.67,0.057
0.38,-58.52,0.061
0.41,-58.36,0.066
0.44,-58.21,0.068
0.48,-58.06,0.070
0.51,-57.90,0.071
0.54,-57.75,0.072
0.57,-57.59,0.073
0.60,-57.44,0.074
0.63,-57.28,0.074
0.67,-57.13,0.075
0.70,-56.97,0.075
0.73,-56.81,0.076
0.76,-56.66,0.076
0.79,-56.50,0.077
0.82,-56.34,0.077
0.85,-56.19,0.077
0.89,-56.03,0.078
0.92,-55.87,0.078
0.95,-55.71,0.078
0.98,-55.56,0.079
1.01,-55.40,0.079
1.05,-55.24,0.079
1.08,-55.09,0.079
1.11,-54.93,0.079
1.14,-54.77,0.079
1.17,-54.61,0.080
1.20,-54.45,0.080
1.23,-54.30,0.080
1.27,-54.14,0.080
1.30,-53.98,0.080
1.33,-53.82,0.080
1.36,-53.67,0.080
1.39,-53.51,0.080
1.43,-53.35,0.080
1.46,-53.19,0.081
1.49,-53.03,0.081
1.52,-52.88,0.081
1.55,-52.72,0.081
1.58,-52.56,0.081
1.62,-52.40,0.081
1.65,-52.24,0.081
1.68,-52.09,0.081
1.71,-51.93,0.081
1.74,-51.77,0.081
1.77,-51.61,0.081
1.81,-51.45,0.081
1.84,-51.29,0.081
1.87,-51.13,0.081
1.90,-50.98,0.081
1.93,-50.82,0.081
1.96,-50.66,0.081
1.99,-50.50,0.081
2.03,-50.34,0.081
2.06,-50.19,0.081
2.09,-50.03,0.081
2.12,-49.87,0.081
2.15,-49.71,0.081
2.19,-49.55,0.081
2.22,-49.39,0.081
2.25,-49.24,0.081
2.28,-49.08,0.081
2.31,-48.92,0.081
2.34,-48.76,0.081
2.38,-48.60,0.081
2.41,-48.45,0.081
2.44,-48.29,0.081
2.47,-48.13,0.081
2.50,-47.97,0.081
2.53,-47.81,0.081
2.56,-47.65,0.081
2.60,-47.50,0.081
2.63,-47.34,0.081
2.66,-47.18,0.081
2.69,-47.02,0.081
2.72,-46.86,0.081
2.76,-46.70,0.081
2.79,-46.55,0.081
2.82,-46.39,0.081
2.85,-46.23,0.081
2.88,-46.07,0.081
2.91,-45.91,0.082
2.94,-45.75,0.082
2.98,-45.60,0.082
3.01,-45.44,0.082
3.04,-45.28,0.082
3.07,-45.12,0.082
3.10,-44.97,0.082
3.14,-44.81,0.082
3.17,-44.65,0.082
3.20,-44.49,0.082
3.23,-44.33,0.082
3.26,-44.17,0.082
3.29,-44.02,0.082
3.33,-43.86,0.082
3.36,-43.70,0.082
3.39,-43.54,0.082
3.42,-43.38,0.082
3.45,-43.22,0.082
3.48,-43.06,0.082
3.51,-42.91,0.082
3.55,-42.75,0.082
3.58,-42.59,0.082
3.61,-42.43,0.082
3.64,-42.27,0.082
3.67,-42.12,0.082
3.71,-41.96,0.082
3.74,-41.80,0.082
3.77,-41.64,0.082
3.80,-41.48,0.082
3.83,-41.32,0.082
3.86,-41.16,0.082
3.89,-41.01,0.082
3.93,-40.85,0.082
3.96,-40.69,0.082
3.99,-40.53,0.082
4.02,-40.37,0.083
4.05,-40.21,0.083
4.09,-40.06,0.083
4.12,-39.90,0.083
4.15,-39.74,0.083
4.18,-39.58,0.083
4.21,-39.42,0.083
4.24,-39.26,0.083
4.28,-39.11,0.083
4.31,-38.95,0.083
4.34,-38.79,0.083
4.37,-38.63,0.083
4.40,-38.47,0.083
4.43,-38.31,0.083
4.46,-38.16,0.083
4.50,-38.00,0.083
4.53,-37.84,0.083
4.56,-37.68,0.083
4.59,-37.52,0.083
4.62,-37.36,0.083
4.65,-37.20,0.083
4.69,-37.05,0.083
4.72,-36.89,0.083
4.75,-36.73,0.083
4.78,-36.57,0.083
4.81,-36.41,0.083
4.85,-36.25,0.083
4.88,-36.09,0.083
4.91,-35.93,0.083
4.94,-35.78,0.083
4.97,-35.62,0.084
5.00,-35.46,0.084
5.04,-35.30,0.084
5.07,-35.14,0.084
5.10,-34.98,0.084
5.13,-34.83,0.084
5.16,-34.67,0.084
5.19,-34.51,0.084
5.23,-34.35,0.084
5.26,-34.19,0.084
5.29,-34.03,0.084
5.32,-33.87,0.084
5.35,-33.71,0.084
5.38,-33.56,0.084
5.41,-33.40,0.084
5.45,-33.24,0.084
5.48,-33.08,0.084
5.51,-32.92,0.084
5.54,-32.76,0.084
5.57,-32.60,0.084
5.60,-32.45,0.084
5.64,-32.29,0.084
5.67,-32.13,0.084
5.70,-31.97,0.084
5.73,-31.81,0.085
5.76,-31.65,0.085
5.80,-31.49,0.085
5.83,-31.34,0.085
5.86,-31.18,0.085
5.89,-31.02,0.085
5.92,-30.86,0.085
5.95,-30.70,0.085
5.99,-30.55,0.085
6.02,-30.39,0.085
6.05,-30.23,0.085
6.08,-30.07,0.085
6.11,-29.91,0.085
6.14,-29.75,0.085
6.18,-29.59,0.085
6.21,-29.43,0.085
6.24,-29.27,0.085
6.27,-29.12,0.085
6.30,-28.96,0.085
6.33,-28.80,0.085
6.36,-28.64,0.085
6.40,-28.48,0.085
6.43,-28.33,0.085
6.46,-28.17,0.085
6.49,-28.01,0.085
6.52,-27.85,0.085
6.55,-27.69,0.085
6.59,-27.53,0.086
6.62,-27.37,0.086
6.65,-27.21,0.086
6.68,-27.06,0.086
6.71,-26.90,0.086
6.75,-26.74,0.086
6.78,-26.58,0.086
6.81,-26.42,0.086
6.84,-26.26,0.086
6.87,-26.11,0.086
6.90,-25.95,0.086
6.94,-25.79,0.086
6.97,-25.63,0.086
7.00,-25.47,0.086
7.03,-25.31,0.086
7.06,-25.16,0.086
7.09,-25.00,0.086
7.13,-24.84,0.086
7.16,-24.68,0.086
7.19,-24.52,0.086
7.22,-24.36,0.086
7.25,-24.20,0.087
7.28,-24.05,0.087
7.31,-23.89,0.087
7.35,-23.73,0.087
7.38,-23.57,0.087
7.41,-23.41,0.087
7.44,-23.25,0.087
7.47,-23.09,0.087
7.50,-22.94,0.087
7.54,-22.78,0.087
7.57,-22.62,0.087
7.60,-22.46,0.087
7.63,-22.30,0.087
7.66,-22.14,0.087
7.70,-21.99,0.087
7.73,-21.83,0.087
7.76,-21.67,0.087
7.79,-21.51,0.087
7.82,-21.35,0.087
7.85,-21.19,0.087
7.89,-21.04,0.087
7.92,-20.88,0.087
7.95,-20.72,0.088
7.98,-20.56,0.088
8.01,-20.40,0.088
8.04,-20.24,0.088
8.08,-20.09,0.088
8.11,-19.92,0.088
8.14,-19.77,0.088
8.17,-19.61,0.088
8.20,-19.45,0.088
8.23,-19.29,0.088
8.26,-19.13,0.088
8.30,-18.98,0.088
8.33,-18.82,0.088
8.36,-18.66,0.088
8.39,-18.50,0.088
8.42,-18.34,0.088
8.45,-18.18,0.089
8.49,-18.02,0.089
8.52,-17.86,0.089
8.55,-17.70,0.089
8.58,-17.55,0.089
8.61,-17.39,0.089
8.65,-17.23,0.089
8.68,-17.07,0.089
8.71,-16.91,0.089
8.74,-16.76,0.089
8.77,-16.60,0.089
8.80,-16.44,0.089
8.83,-16.28,0.089
8.87,-16.12,0.089
8.90,-15.97,0.089
8.93,-15.81,0.089
8.96,-15.65,0.089
8.99,-15.49,0.089
9.03,-15.33,0.089
9.06,-15.17,0.089
9.09,-15.01,0.089
9.12,-14.86,0.089
9.15,-14.70,0.089
9.18,-14.54,0.090
9.22,-14.38,0.090
9.25,-14.22,0.090
9.28,-14.06,0.090
9.31,-13.91,0.090
9.34,-13.75,0.090
9.37,-13.59,0.090
9.40,-13.43,0.090
9.44,-13.27,0.090
9.47,-13.11,0.090
9.50,-12.95,0.090
9.53,-12.80,0.090
9.56,-12.64,0.090
9.60,-12.48,0.090
9.63,-12.32,0.090
9.66,-12.16,0.090
9.69,-12.00,0.090
9.72,-11.85,0.091
9.75,-11.69,0.091
9.78,-11.53,0.091
9.82,-11.37,0.091
9.85,-11.21,0.091
9.88,-11.05,0.091
9.91,-10.89,0.091
9.94,-10.74,0.091
9.98,-10.58,0.091
10.01,-10.42,0.091
10.04,-10.26,0.091
10.07,-10.10,0.091
10.10,-9.94,0.091
10.13,-9.78,0.091
10.17,-9.63,0.091
10.20,-9.47,0.092
10.23,-9.31,0.092
10.26,-9.15,0.092
10.29,-8.99,0.092
10.32,-8.83,0.092
10.35,-8.68,0.092
10.39,-8.52,0.092
10.42,-8.36,0.092
10.45,-8.20,0.092
10.48,-8.04,0.092
10.51,-7.88,0.092
10.55,-7.72,0.092
10.58,-7.57,0.092
10.61,-7.41,0.092
10.64,-7.25,0.092
10.67,-7.09,0.092
10.70,-6.93,0.092
10.73,-6.77,0.093
10.77,-6.61,0.093
10.80,-6.46,0.093
10.83,-6.30,0.093
10.86,-6.14,0.093
10.89,-5.98,0.093
10.93,-5.82,0.093
10.96,-5.66,0.093
10.99,-5.51,0.093
11.02,-5.35,0.093
11.05,-5.19,0.093
11.08,-5.03,0.093
11.12,-4.87,0.093
11.15,-4.71,0.094
11.18,-4.56,0.094
11.21,-4.40,0.094
11.24,-4.24,0.094
11.27,-4.08,0.094
11.30,-3.92,0.094
11.34,-3.76,0.094
11.37,-3.60,0.094
11.40,-3.45,0.094
11.43,-3.29,0.094
11.46,-3.13,0.094
11.50,-2.97,0.094
11.53,-2.81,0.094
11.56,-2.65,0.094
11.59,-2.50,0.094
11.62,-2.34,0.094
11.65,-2.18,0.094
11.68,-2.02,0.095
11.72,-1.86,0.095
11.75,-1.70,0.095
11.78,-1.54,0.095
11.81,-1.38,0.095
11.84,-1.23,0.095
11.88,-1.07,0.095
11.91,-0.91,0.095
11.94,-0.75,0.095
11.97,-0.59,0.095
12.00,-0.43,0.095
12.03,-0.28,0.095
12.07,-0.12,0.095
12.10,0.04,0.095
12.13,0.20,0.095
12.16,0.36,0.095
12.19,0.52,0.096
12.22,0.67,0.096
12.25,0.83,0.096
12.29,0.99,0.096
12.32,1.15,0.096
12.35,1.31,0.096
12.38,1.47,0.096
12.41,1.62,0.096
12.45,1.78,0.096
12.48,1.94,0.096
12.51,2.10,0.096
12.54,2.26,0.097
12.57,2.42,0.097
12.60,2.57,0.097
12.63,2.73,0.097
12.67,2.89,0.097
12.70,3.05,0.097
12.73,3.21,0.097
12.76,3.37,0.097
12.79,3.53,0.097
12.83,3.69,0.097
12.86,3.84,0.098
12.89,4.00,0.098
12.92,4.16,0.098
12.95,4.32,0.098
12.98,4.48,0.098
13.02,4.64,0.098
13.05,4.80,0.098
13.08,4.95,0.098
13.11,5.11,0.098
13.14,5.27,0.098
13.17,5.43,0.098
13.20,5.59,0.098
13.24,5.75,0.099
13.27,5.90,0.099
13.30,6.06,0.099
13.33,6.22,0.099
13.36,6.38,0.099
13.40,6.54,0.099
13.43,6.69,0.099
13.46,6.85,0.099
13.49,7.01,0.099
13.52,7.17,0.099
13.55,7.33,0.099
13.58,7.49,0.099
13.62,7.65,0.099
13.65,7.80,0.100
13.68,7.96,0.100
13.71,8.12,0.100
13.74,8.28,0.100
13.78,8.44,0.100
13.81,8.60,0.100
13.84,8.76,0.100
13.87,8.91,0.100
13.90,9.07,0.100
13.93,9.23,0.101
13.97,9.39,0.101
14.00,9.55,0.101
14.03,9.70,0.101
14.06,9.86,0.101
14.09,10.02,0.101
14.12,10.18,0.101
14.15,10.34,0.101
14.19,10.50,0.101
14.22,10.66,0.101
14.25,10.81,0.102
14.28,10.97,0.102
14.31,11.13,0.102
14.35,11.29,0.102
14.38,11.45,0.102
14.41,11.61,0.102
14.44,11.77,0.102
14.47,11.92,0.102
14.50,12.08,0.103
14.53,12.24,0.103
14.57,12.40,0.103
14.60,12.56,0.103
14.63,12.72,0.103
14.66,12.87,0.103
14.69,13.03,0.103
14.73,13.19,0.103
14.76,13.35,0.103
14.79,13.51,0.104
14.82,13.67,0.104
14.85,13.82,0.104
14.88,13.98,0.104
14.92,14.14,0.104
14.95,14.30,0.104
14.98,14.46,0.104
15.01,14.62,0.104
15.04,14.78,0.104
15.07,14.93,0.105
15.10,15.09,0.105
15.14,15.25,0.105
15.17,15.41,0.105
15.20,15.57,0.105
15.23,15.72,0.105
15.26,15.88,0.105
15.30,16.04,0.105
15.33,16.20,0.106
15.36,16.36,0.106
15.39,16.52,0.106
15.42,16.68,0.106
15.45,16.83,0.106
15.48,16.99,0.106
15.52,17.15,0.106
15.55,17.31,0.106
15.58,17.47,0.107
15.61,17.63,0.107
15.64,17.78,0.107
15.68,17.94,0.107
15.71,18.10,0.107
15.74,18.26,0.107
15.77,18.42,0.107
15.80,18.58,0.108
15.83,18.74,0.108
15.87,18.89,0.108
15.90,19.05,0.108
15.93,19.21,0.108
15.96,19.37,0.108
15.99,19.53,0.108
16.02,19.69,0.109
16.05,19.85,0.109
16.09,20.00,0.109
16.12,20.16,0.109
16.15,20.32,0.109
16.18,20.48,0.109
16.21,20.64,0.110
16.25,20.79,0.110
16.28,20.95,0.110
16.31,21.11,0.110
16.34,21.27,0.110
16.37,21.43,0.110
16.40,21.59,0.111
16.43,21.75,0.111
16.47,21.90,0.111
16.50,22.06,0.111
16.53,22.22,0.111
16.56,22.38,0.111
16.59,22.54,0.112
16.63,22.70,0.112
16.66,22.85,0.112
16.69,23.01,0.112
16.72,23.17,0.112
16.75,23.33,0.113
16.78,23.49,0.113
16.82,23.65,0.113
16.85,23.80,0.113
16.88,23.96,0.113
16.91,24.12,0.113
16.94,24.28,0.114
16.97,24.44,0.114
17.00,24.60,0.114
17.04,24.75,0.114
17.07,24.91,0.114
17.10,25.07,0.115
17.13,25.23,0.115
17.16,25.39,0.115
17.19,25.55,0.115
17.23,25.70,0.115
17.26,25.86,0.116
17.29,26.02,0.116
17.32,26.18,0.116
17.35,26.34,0.116
17.38,26.50,0.116
17.42,26.65,0.117
17.45,26.81,0.117
17.48,26.97,0.117
17.51,27.13,0.117
17.54,27.29,0.117
17.58,27.45,0.118
17.61,27.60,0.118
17.64,27.76,0.118
17.67,27.92,0.118
17.70,28.08,0.118
17.73,28.24,0.119
17.77,28.40,0.119
17.80,28.55,0.119
17.83,28.71,0.119
17.86,28.87,0.120
17.89,29.03,0.120
17.92,29.19,0.120
17.96,29.35,0.120
17.99,29.50,0.121
18.02,29.66,0.121
18.05,29.82,0.121
18.08,29.98,0.121
18.11,30.14,0.122
18.14,30.30,0.122
18.18,30.45,0.122
18.21,30.61,0.122
18.24,30.77,0.122
18.27,30.93,0.123
18.30,31.09,0.123
18.33,31.25,0.123
18.37,31.41,0.124
18.40,31.56,0.124
18.43,31.72,0.124
18.46,31.88,0.124
18.49,32.04,0.125
18.53,32.20,0.125
18.56,32.36,0.125
18.59,32.51,0.125
18.62,32.67,0.126
18.65,32.83,0.126
18.68,32.99,0.126
18.72,33.15,0.126
18.75,33.31,0.127
18.78,33.46,0.127
18.81,33.62,0.127
18.84,33.78,0.128
18.87,33.94,0.128
18.91,34.10,0.128
18.94,34.26,0.129
18.97,34.41,0.129
19.00,34.57,0.129
19.03,34.73,0.129
19.06,34.89,0.130
19.09,35.05,0.130
19.13,35.21,0.131
19.16,35.36,0.131
19.19,35.52,0.131
19.22,35.68,0.131
19.25,35.84,0.132
19.28,36.00,0.132
19.32,36.16,0.132
19.35,36.31,0.133
19.38,36.47,0.133
19.41,36.63,0.134
19.44,36.79,0.134
19.48,36.95,0.134
19.51,37.11,0.135
19.54,37.26,0.135
19.57,37.42,0.135
19.60,37.58,0.136
19.63,37.74,0.136
19.67,37.90,0.136
19.70,38.06,0.137
19.73,38.21,0.137
19.76,38.37,0.138
19.79,38.53,0.138
19.82,38.69,0.138
19.86,38.85,0.139
19.89,39.00,0.139
19.92,39.16,0.140
19.95,39.32,0.140
19.98,39.48,0.141
20.01,39.64,0.141
20.04,39.80,0.141
20.08,39.95,0.142
20.11,40.11,0.142
20.14,40.27,0.143
20.17,40.43,0.143
20.20,40.59,0.144
20.23,40.74,0.144
20.27,40.90,0.145
20.30,41.06,0.145
20.33,41.22,0.146
20.36,41.38,0.146
20.39,41.54,0.147
20.43,41.69,0.147
20.46,41.85,0.148
20.49,42.01,0.148
20.52,42.17,0.149
20.55,42.33,0.149
20.58,42.49,0.150
20.62,42.64,0.150
20.65,42.80,0.151
20.68,42.96,0.152
20.71,43.12,0.152
20.74,43.28,0.153
20.77,43.43,0.153
20.81,43.59,0.154
20.84,43.75,0.155
20.87,43.91,0.155
20.90,44.07,0.156
20.93,44.22,0.156
20.96,44.38,0.157
20.99,44.54,0.158
21.03,44.70,0.158
21.06,44.86,0.159
21.09,45.02,0.159
21.12,45.17,0.160
21.15,45.33,0.161
21.18,45.49,0.161
21.22,45.65,0.162
21.25,45.81,0.162
21.28,45.97,0.163
21.31,46.12,0.163
21.34,46.28,0.164
21.38,46.44,0.164
21.41,46.60,0.165
21.44,46.75,0.165
21.47,46.91,0.166
21.50,47.07,0.166
21.53,47.23,0.167
21.57,47.39,0.167
21.60,47.55,0.168
21.63,47.71,0.168
21.66,47.86,0.169
21.69,48.02,0.169
21.72,48.18,0.169
21.76,48.34,0.170
21.79,48.50,0.170
21.82,48.66,0.170
21.85,48.81,0.171
21.88,48.97,0.171
21.91,49.13,0.171
21.94,49.29,0.171
21.98,49.45,0.172
22.01,49.61,0.172
22.04,49.77,0.172
22.07,49.92,0.172
22.10,50.08,0.172
22.13,50.24,0.173
22.17,50.40,0.173
22.20,50.56,0.173
22.23,50.71,0.173
22.26,50.87,0.173
22.29,51.03,0.173
22.33,51.19,0.173
22.36,51.35,0.174
22.39,51.51,0.174
22.42,51.66,0.174
22.45,51.82,0.174
22.48,51.98,0.174
22.52,52.14,0.174
22.55,52.30,0.175
22.58,52.46,0.175
22.61,52.62,0.175
22.64,52.77,0.175
22.67,52.93,0.176
22.71,53.09,0.176
22.74,53.25,0.176
22.77,53.41,0.176
22.80,53.57,0.177
22.83,53.72,0.177
22.86,53.88,0.177
22.89,54.04,0.178
22.93,54.20,0.178
22.96,54.36,0.178
22.99,54.51,0.179
23.02,54.67,0.179
23.05,54.83,0.179
23.08,54.99,0.180
23.12,55.15,0.180
23.15,55.30,0.181
23.18,55.46,0.181
23.21,55.62,0.182
23.24,55.78,0.182
23.28,55.94,0.183
23.31,56.10,0.183
23.34,56.25,0.184
23.37,56.41,0.184
23.40,56.57,0.185
23.43,56.73,0.186
23.47,56.89,0.186
23.50,57.05,0.187
23.53,57.20,0.187
23.56,57.36,0.188
23.59,57.52,0.189
23.62,57.68,0.189
23.66,57.84,0.190
23.69,57.99,0.191
23.72,58.15,0.191
23.75,58.31,0.192
23.78,58.47,0.193
23.81,58.63,0.193
23.84,58.78,0.194
23.88,58.94,0.195
23.91,59.10,0.196
23.94,59.26,0.196
23.97,59.42,0.197
24.00,59.57,0.198
24.03,59.73,0.199
24.07,59.89,0.200
24.10,60.05,0.201
24.13,60.21,0.202
24.16,60.36,0.202
24.19,60.52,0.203
24.23,60.68,0.204
24.26,60.84,0.205
24.29,61.00,0.206
24.32,61.15,0.207
24.35,61.31,0.208
24.38,61.47,0.209
24.42,61.63,0.210
24.45,61.79,0.210
24.48,61.94,0.211
24.51,62.10,0.212
24.54,62.26,0.213
24.57,62.42,0.214
24.61,62.58,0.215
24.64,62.73,0.216
24.67,62.89,0.218
24.70,63.05,0.219
24.73,63.21,0.219
24.76,63.36,0.221
24.79,63.52,0.222
24.83,63.68,0.223
24.86,63.84,0.224
24.89,64.00,0.225
24.92,64.16,0.226
24.95,64.31,0.227
24.98,64.47,0.228
25.02,64.63,0.229
25.05,64.79,0.230
25.08,64.94,0.231
25.11,65.10,0.232
25.14,65.26,0.233
25.18,65.42,0.234
25.21,65.58,0.235
25.24,65.74,0.236
25.27,65.89,0.237
25.30,66.05,0.239
25.33,66.21,0.240
25.37,66.37,0.241
25.40,66.53,0.242
25.43,66.68,0.243
25.46,66.84,0.244
25.49,67.00,0.245
25.52,67.16,0.246
25.56,67.32,0.247
25.59,67.47,0.248
25.62,67.63,0.249
25.65,67.79,0.250
25.68,67.95,0.251
25.71,68.11,0.252
25.74,68.26,0.253
25.78,68.42,0.254
25.81,68.58,0.255
25.84,68.74,0.256
25.87,68.90,0.257
25.90,69.05,0.258
25.93,69.21,0.259
25.97,69.37,0.260
26.00,69.53,0.261
26.03,69.68,0.262
26.06,69.84,0.264
26.09,70.00,0.265
26.13,70.16,0.266
26.16,70.32,0.267
26.19,70.48,0.268
26.22,70.63,0.269
26.25,70.79,0.270
26.28,70.95,0.271
26.32,71.11,0.271
26.35,71.27,0.272
26.38,71.42,0.273
26.41,71.58,0.274
26.44,71.74,0.275
26.47,71.90,0.276
26.51,72.06,0.277
26.54,72.21,0.278
26.57,72.37,0.279
26.60,72.53,0.280
26.63,72.69,0.281
26.66,72.84,0.282
26.69,73.00,0.283
26.73,73.16,0.284
26.76,73.32,0.285
26.79,73.48,0.286
26.82,73.64,0.287
26.85,73.79,0.288
26.88,73.95,0.289
26.92,74.11,0.290
26.95,74.27,0.291
26.98,74.43,0.292
27.01,74.58,0.293
27.04,74.74,0.294
27.08,74.90,0.295
27.11,75.06,0.297
27.14,75.22,0.297
27.17,75.37,0.298
27.20,75.53,0.300
27.23,75.69,0.300
27.27,75.85,0.302
27.30,76.01,0.303
27.33,76.16,0.304
27.36,76.32,0.305
27.39,76.48,0.306
27.42,76.64,0.307
27.46,76.80,0.307
27.49,76.95,0.309
27.52,77.11,0.310
27.55,77.27,0.311
27.58,77.43,0.312
27.61,77.59,0.313
27.64,77.74,0.314
27.68,77.90,0.315
27.71,78.06,0.316
27.74,78.22,0.317
27.77,78.38,0.318
27.80,78.53,0.319
27.83,78.69,0.321
27.87,78.85,0.322
27.90,79.01,0.323
27.93,79.17,0.324
27.96,79.32,0.325
27.99,79.48,0.326
28.03,79.64,0.327
28.06,79.80,0.328
28.09,79.95,0.329
28.12,80.11,0.330
28.15,80.27,0.331
28.18,80.43,0.333
28.22,80.59,0.334
28.25,80.74,0.335
28.28,80.90,0.336
28.31,81.06,0.337
28.34,81.22,0.338
28.37,81.38,0.340
28.41,81.53,0.341
28.44,81.69,0.342
28.47,81.85,0.343
28.50,82.01,0.344
28.53,82.17,0.345
28.56,82.32,0.346
28.59,82.48,0.348
28.63,82.64,0.349
28.66,82.80,0.350
28.69,82.96,0.351
28.72,83.11,0.352
28.75,83.27,0.353
28.78,83.43,0.355
28.82,83.59,0.356
28.85,83.75,0.358
28.88,83.90,0.359
28.91,84.06,0.359
28.94,84.22,0.360
28.98,84.38,0.362
29.01,84.54,0.363
29.04,84.69,0.364
29.07,84.85,0.366
29.10,85.01,0.367
29.13,85.17,0.368
29.17,85.32,0.369
29.20,85.48,0.370
29.23,85.64,0.372
29.26,85.80,0.373
29.29,85.96,0.374
29.32,86.12,0.375
29.36,86.27,0.377
29.39,86.43,0.378
29.42,86.59,0.379
29.45,86.75,0.380
29.48,86.91,0.381
29.51,87.06,0.383
29.54,87.22,0.384
29.58,87.38,0.385
29.61,87.54,0.386
29.64,87.70,0.387
29.67,87.85,0.389
29.70,88.01,0.390
29.73,88.17,0.392
29.77,88.33,0.393
29.80,88.48,0.394
29.83,88.64,0.395
29.86,88.80,0.396
29.89,88.96,0.397
29.93,89.11,0.399
29.96,89.27,0.400
29.99,89.43,0.402
30.02,89.59,0.403
30.05,89.75,0.404
30.08,89.90,0.406
30.12,90.06,0.407
30.15,90.22,0.408
30.18,90.38,0.409
30.21,90.53,0.410
30.24,90.69,0.412
30.27,90.85,0.413
30.31,91.01,0.414
30.34,91.17,0.415
30.37,91.32,0.417
30.40,91.48,0.418
30.43,91.64,0.419
30.46,91.80,0.420
30.49,91.96,0.422
30.53,92.11,0.423
30.56,92.27,0.424
30.59,92.43,0.425
30.62,92.59,0.427
30.65,92.75,0.428
30.68,92.90,0.429
30.72,93.06,0.430
30.75,93.22,0.431
30.78,93.38,0.433
30.81,93.53,0.434
30.84,93.69,0.435
30.88,93.85,0.436
30.91,94.01,0.437
30.94,94.17,0.439
30.97,94.32,0.440
31.00,94.48,0.441
31.03,94.64,0.442
31.07,94.80,0.443
31.10,94.96,0.444
31.13,95.11,0.445
31.16,95.27,0.447
31.19,95.43,0.448
31.22,95.59,0.449
31.26,95.75,0.450
31.29,95.90,0.452
31.32,96.06,0.453
31.35,96.22,0.454
31.38,96.38,0.455
31.41,96.54,0.456
31.44,96.69,0.457
31.48,96.85,0.458
31.51,97.01,0.459
31.54,97.17,0.460
31.57,97.33,0.461
31.60,97.48,0.462
31.63,97.64,0.463
31.67,97.80,0.464
31.70,97.96,0.465
31.73,98.12,0.466
31.76,98.27,0.467
31.79,98.43,0.468
31.83,98.59,0.469
31.86,98.75,0.470
31.89,98.91,0.471
31.92,99.06,0.472
31.95,99.22,0.472
31.98,99.38,0.473
32.02,99.54,0.474
32.05,99.70,0.475
32.08,99.85,0.476
32.11,100.01,0.476
32.14,100.17,0.477
32.17,100.33,0.478
32.21,100.49,0.479
32.24,100.65,0.480
32.27,100.80,0.480
32.30,100.96,0.481
32.33,101.12,0.482
32.36,101.28,0.482
32.39,101.44,0.483
32.43,101.59,0.484
32.46,101.75,0.484
32.49,101.91,0.485
32.52,102.07,0.486
32.55,102.23,0.486
32.58,102.38,0.487
32.62,102.54,0.487
32.65,102.70,0.488
32.68,102.86,0.489
32.71,103.02,0.489
32.74,103.18,0.490
32.78,103.34,0.490
32.81,103.49,0.491
32.84,103.65,0.491
32.87,103.81,0.491
32.90,103.97,0.492
32.93,104.13,0.492
32.97,104.29,0.493
33.00,104.44,0.493
33.03,104.60,0.493
33.06,104.76,0.494
33.09,104.92,0.494
33.12,105.08,0.494
33.16,105.24,0.494
33.19,105.39,0.495
33.22,105.55,0.495
33.25,105.71,0.495
33.28,105.87,0.495
33.31,106.03,0.495
33.34,106.19,0.495
33.38,106.35,0.495
33.41,106.50,0.495
33.44,106.66,0.495
33.47,106.82,0.495
33.50,106.98,0.495
33.53,107.14,0.495
33.57,107.30,0.495
33.60,107.45,0.495
33.63,107.61,0.495
33.66,107.77,0.495
33.69,107.93,0.495
33.73,108.09,0.495
33.76,108.25,0.494
33.79,108.41,0.494
33.82,108.57,0.494
33.85,108.72,0.494
33.88,108.88,0.493
33.92,109.04,0.493
33.95,109.20,0.493
33.98,109.36,0.492
34.01,109.52,0.492
34.04,109.68,0.491
34.07,109.84,0.491
34.11,109.99,0.491
34.14,110.15,0.490
34.17,110.31,0.489
34.20,110.47,0.489
34.23,110.63,0.488
34.26,110.79,0.487
34.29,110.95,0.487
34.33,111.10,0.486
34.36,111.26,0.485
34.39,111.42,0.485
34.42,111.58,0.484
34.45,111.74,0.483
34.49,111.90,0.482
34.52,112.06,0.481
34.55,112.22,0.481
34.58,112.38,0.480
34.61,112.54,0.478
34.64,112.69,0.477
34.68,112.85,0.476
34.71,113.01,0.475
34.74,113.17,0.474
34.77,113.33,0.473
34.80,113.49,0.472
34.83,113.65,0.470
34.86,113.81,0.469
34.90,113.97,0.468
34.93,114.13,0.466
34.96,114.28,0.465
34.99,114.44,0.463
35.02,114.60,0.462
35.06,114.76,0.461
35.09,114.92,0.459
35.12,115.08,0.458
35.15,115.24,0.456
35.18,115.40,0.455
35.21,115.56,0.453
35.24,115.72,0.452
35.28,115.88,0.450
35.31,116.04,0.449
35.34,116.19,0.447
35.37,116.35,0.445
35.40,116.51,0.443
35.44,116.67,0.442
35.47,116.83,0.440
35.50,116.99,0.438
35.53,117.15,0.437
35.56,117.31,0.435
35.59,117.47,0.433
35.63,117.63,0.432
35.66,117.79,0.430
35.69,117.94,0.428
35.72,118.10,0.426
35.75,118.26,0.424
35.78,118.42,0.423
35.81,118.58,0.421
35.85,118.74,0.419
35.88,118.90,0.417
35.91,119.06,0.415
35.94,119.22,0.414
35.97,119.38,0.411
36.01,119.54,0.409
36.04,119.70,0.407
36.07,119.86,0.406
36.10,120.02,0.404
36.13,120.18,0.402
36.16,120.34,0.400
36.19,120.49,0.398
36.23,120.65,0.396
36.26,120.81,0.394
36.29,120.97,0.392
36.32,121.13,0.390
36.35,121.29,0.388
36.39,121.45,0.386
36.42,121.61,0.384
36.45,121.77,0.382
36.48,121.93,0.380
36.51,122.09,0.378
36.54,122.25,0.376
36.58,122.41,0.375
36.61,122.57,0.373
36.64,122.72,0.370
36.67,122.88,0.368
36.70,123.04,0.366
36.73,123.20,0.364
36.76,123.36,0.362
36.80,123.52,0.360
36.83,123.68,0.358
36.86,123.84,0.356
36.89,124.00,0.354
36.92,124.16,0.352
36.96,124.32,0.350
36.99,124.48,0.348
37.02,124.64,0.347
37.05,124.80,0.344
37.08,124.96,0.342
37.11,125.12,0.340
37.14,125.27,0.338
37.18,125.43,0.336
37.21,125.59,0.334
37.24,125.75,0.332
37.27,125.91,0.330
37.30,126.07,0.328
37.34,126.23,0.326
37.37,126.39,0.323
37.40,126.55,0.321
37.43,126.71,0.320
37.46,126.87,0.318
37.49,127.03,0.316
37.53,127.19,0.314
37.56,127.35,0.312
37.59,127.51,0.310
37.62,127.66,0.309
37.65,127.82,0.307
37.68,127.98,0.305
37.71,128.14,0.304
37.75,128.30,0.303
37.78,128.46,0.304
37.81,128.62,0.300
37.84,128.78,0.297
37.87,128.94,0.294
37.91,129.10,0.292
37.94,129.26,0.290
37.97,129.42,0.289
38.00,129.58,0.287
38.03,129.74,0.285
38.06,129.89,0.283
38.09,130.05,0.281
38.13,130.21,0.279
38.16,130.37,0.277
38.19,130.53,0.275
38.22,130.69,0.273
38.25,130.85,0.272
38.29,131.01,0.270
38.32,131.17,0.269
38.35,131.33,0.267
38.38,131.49,0.266
38.41,131.65,0.264
38.44,131.81,0.263
38.48,131.96,0.261
38.51,132.12,0.259
38.54,132.28,0.258
38.57,132.44,0.256
38.60,132.60,0.255
38.63,132.76,0.253
38.66,132.92,0.252
38.70,133.08,0.250
38.73,133.24,0.249
38.76,133.40,0.247
38.79,133.55,0.245
38.82,133.71,0.244
38.86,133.87,0.242
38.89,134.03,0.241
38.92,134.19,0.240
38.95,134.35,0.238
38.98,134.51,0.237
39.01,134.67,0.235
39.04,134.83,0.234
39.08,134.99,0.232
39.11,135.15,0.231
39.14,135.30,0.230
39.17,135.46,0.228
39.20,135.62,0.227
39.24,135.78,0.226
39.27,135.94,0.224
39.30,136.10,0.223
39.33,136.26,0.222
39.36,136.42,0.221
39.39,136.58,0.220
39.43,136.74,0.218
39.46,136.89,0.217
39.49,137.05,0.216
39.52,137.21,0.215
39.55,137.37,0.214
39.58,137.53,0.213
39.61,137.69,0.212
39.65,137.85,0.211
39.68,138.01,0.210
39.71,138.17,0.209
39.74,138.33,0.207
39.77,138.49,0.206
39.81,138.64,0.205
39.84,138.80,0.204
39.87,138.96,0.203
39.90,139.12,0.202
39.93,139.28,0.201
39.96,139.44,0.200
39.99,139.60,0.199
40.03,139.76,0.199
40.06,139.91,0.198
40.09,140.07,0.197
40.12,140.23,0.196
40.15,140.39,0.195
40.19,140.55,0.194
40.22,140.71,0.193
40.25,140.87,0.193
40.28,141.03,0.192
40.31,141.18,0.191
40.34,141.34,0.190
40.38,141.50,0.189
40.41,141.66,0.188
40.44,141.82,0.188
40.47,141.98,0.187
40.50,142.14,0.186
40.53,142.30,0.185
40.56,142.45,0.185
40.60,142.61,0.184
40.63,142.77,0.183
40.66,142.93,0.182
40.69,143.09,0.182
40.72,143.25,0.181
40.76,143.41,0.180
40.79,143.57,0.179
40.82,143.72,0.179
40.85,143.88,0.178
40.88,144.04,0.177
40.91,144.20,0.177
40.94,144.36,0.176
40.98,144.52,0.175
41.01,144.68,0.175
41.04,144.84,0.174
41.07,144.99,0.174
41.10,145.15,0.173
41.14,145.31,0.172
41.17,145.47,0.172
41.20,145.63,0.171
41.23,145.79,0.170
41.26,145.95,0.170
41.29,146.11,0.169
41.33,146.26,0.169
41.36,146.42,0.168
41.39,146.58,0.167
41.42,146.74,0.167
41.45,146.90,0.166
41.48,147.06,0.166
41.51,147.22,0.165
41.55,147.37,0.164
41.58,147.53,0.164
41.61,147.69,0.163
41.64,147.85,0.163
41.67,148.01,0.162
41.71,148.17,0.162
41.74,148.33,0.161
41.77,148.48,0.161
41.80,148.64,0.160
41.83,148.80,0.160
41.86,148.96,0.159
41.89,149.12,0.159
41.93,149.28,0.158
41.96,149.44,0.158
41.99,149.60,0.157
42.02,149.75,0.157
42.05,149.91,0.156
42.09,150.07,0.156
42.12,150.23,0.156
42.15,150.39,0.155
42.18,150.55,0.155
42.21,150.70,0.154
42.24,150.86,0.154
42.28,151.02,0.153
42.31,151.18,0.153
42.34,151.34,0.153
42.37,151.50,0.152
42.40,151.66,0.152
42.43,151.82,0.152
42.46,151.97,0.151
42.50,152.13,0.151
42.53,152.29,0.151
42.56,152.45,0.150
42.59,152.61,0.150
42.62,152.77,0.150
42.66,152.93,0.149
42.69,153.08,0.149
42.72,153.24,0.149
42.75,153.40,0.149
42.78,153.56,0.148
42.81,153.72,0.148
42.84,153.88,0.148
42.88,154.04,0.148
42.91,154.19,0.147
42.94,154.35,0.147
42.97,154.51,0.147
43.00,154.67,0.147
43.04,154.83,0.146
43.07,154.99,0.146
43.10,155.14,0.146
43.13,155.30,0.146
43.16,155.46,0.146
43.19,155.62,0.145
43.23,155.78,0.145
43.26,155.94,0.145
43.29,156.09,0.145
43.32,156.25,0.145
43.35,156.41,0.145
43.38,156.57,0.144
43.41,156.73,0.144
43.45,156.89,0.144
43.48,157.04,0.144
43.51,157.20,0.144
43.54,157.36,0.144
43.57,157.52,0.144
43.61,157.68,0.143
43.64,157.84,0.143
43.67,158.00,0.143
43.70,158.15,0.143
43.73,158.31,0.143
43.76,158.47,0.143
43.79,158.63,0.143
43.83,158.79,0.143
43.86,158.95,0.143
43.89,159.11,0.143
43.92,159.26,0.142
43.95,159.42,0.142
43.99,159.58,0.142
44.02,159.74,0.142
44.05,159.90,0.142
44.08,160.06,0.142
44.11,160.21,0.142
44.14,160.37,0.142
44.18,160.53,0.142
44.21,160.69,0.142
44.24,160.85,0.142
44.27,161.01,0.142
44.30,161.17,0.142
44.33,161.32,0.142
44.36,161.48,0.142
44.40,161.64,0.142
44.43,161.80,0.142
44.46,161.96,0.142
44.49,162.12,0.142
44.52,162.28,0.142
44.56,162.43,0.141
44.59,162.59,0.141
44.62,162.75,0.141
44.65,162.91,0.141
44.68,163.07,0.141
44.71,163.22,0.141
44.74,163.38,0.141
44.78,163.54,0.141
44.81,163.70,0.141
44.84,163.86,0.141
44.87,164.02,0.141
44.90,164.17,0.141
44.94,164.33,0.141
44.97,164.49,0.141
45.00,164.65,0.141
45.03,164.81,0.141
45.06,164.97,0.141
45.09,165.13,0.141
45.13,165.28,0.141
45.16,165.44,0.141
45.19,165.60,0.142
45.22,165.76,0.142
45.25,165.92,0.142
45.28,166.08,0.142
45.31,166.23,0.142
45.35,166.39,0.142
45.38,166.55,0.142
45.41,166.71,0.142
45.44,166.87,0.142
45.47,167.03,0.142
45.51,167.18,0.142
45.54,167.34,0.142
45.57,167.50,0.142
45.60,167.66,0.142
45.63,167.82,0.142
45.66,167.98,0.142
45.69,168.13,0.142
45.73,168.29,0.142
45.76,168.45,0.142
45.79,168.61,0.143
45.82,168.77,0.143
45.85,168.93,0.143
45.89,169.08,0.143
45.92,169.24,0.143
45.95,169.40,
45.98,,
45.99,,

[step]
Ramp 5.00 °C/min to -60.00 °C
Time,Temperature,Heat Flow (Normalized)
min,°C,W/g
46.99,170.15,-0.024
47.02,170.15,-0.024
47.05,170.14,-0.024
47.08,170.10,-0.027
47.11,170.02,-0.055
47.14,169.91,-0.091
47.18,169.78,-0.124
47.21,169.64,-0.146
47.24,169.50,-0.161
47.27,169.35,-0.169
47.30,169.20,-0.175
47.34,169.05,-0.179
47.37,168.89,-0.182
47.40,168.74,-0.184
47.43,168.58,-0.185
47.46,168.43,-0.185
47.49,168.27,-0.186
47.53,168.11,-0.186
47.56,167.96,-0.187
47.59,167.80,-0.187
47.62,167.64,-0.187
47.65,167.49,-0.188
47.68,167.33,-0.188
47.71,167.17,-0.188
47.75,167.01,-0.188
47.78,166.86,-0.188
47.81,166.70,-0.189
47.84,166.54,-0.189
47.87,166.38,-0.189
47.91,166.23,-0.189
47.94,166.07,-0.189
47.97,165.91,-0.189
48.00,165.75,-0.190
48.03,165.59,-0.190
48.06,165.43,-0.190
48.09,165.28,-0.190
48.13,165.12,-0.190
48.16,164.96,-0.190
48.19,164.80,-0.190
48.22,164.65,-0.190
48.25,164.49,-0.190
48.29,164.33,-0.190
48.32,164.17,-0.190
48.35,164.01,-0.190
48.38,163.86,-0.190
48.41,163.70,-0.190
48.44,163.54,-0.190
48.48,163.38,-0.190
48.51,163.22,-0.190
48.54,163.07,-0.190
48.57,162.91,-0.190
48.60,162.75,-0.190
48.63,162.59,-0.190
48.66,162.43,-0.190
48.70,162.28,-0.190
48.73,162.12,-0.190
48.76,161.96,-0.190
48.79,161.80,-0.190
48.82,161.64,-0.190
48.86,161.49,-0.190
48.89,161.33,-0.190
48.92,161.17,-0.189
48.95,161.01,-0.189
48.98,160.85,-0.189
49.01,160.69,-0.189
49.04,160.53,-0.190
49.08,160.38,-0.189
49.11,160.22,-0.190
49.14,160.06,-0.189
49.17,159.90,-0.189
49.20,159.74,-0.189
49.24,159.58,-0.189
49.27,159.43,-0.189
49.30,159.27,-0.189
49.33,159.11,-0.189
49.36,158.95,-0.189
49.39,158.79,-0.189
49.43,158.63,-0.189
49.46,158.48,-0.189
49.49,158.32,-0.189
49.52,158.16,-0.189
49.55,158.00,-0.189
49.58,157.84,-0.189
49.61,157.68,-0.189
49.65,157.53,-0.189
49.68,157.37,-0.189
49.71,157.21,-0.189
49.74,157.05,-0.189
49.77,156.89,-0.189
49.81,156.73,-0.189
49.84,156.58,-0.189
49.87,156.42,-0.189
49.90,156.26,-0.189
49.93,156.10,-0.189
49.96,155.94,-0.189
49.99,155.78,-0.189
50.03,155.63,-0.189
50.06,155.47,-0.189
50.09,155.31,-0.189
50.12,155.15,-0.189
50.15,154.99,-0.189
50.19,154.83,-0.189
50.22,154.68,-0.189
50.25,154.52,-0.189
50.28,154.36,-0.189
50.31,154.20,-0.189
50.34,154.04,-0.189
50.38,153.88,-0.189
50.41,153.73,-0.189
50.44,153.57,-0.189
50.47,153.41,-0.189
50.50,153.25,-0.189
50.53,153.09,-0.189
50.56,152.93,-0.189
50.60,152.78,-0.189
50.63,152.62,-0.189
50.66,152.46,-0.188
50.69,152.30,-0.188
50.72,152.14,-0.188
50.76,151.98,-0.188
50.79,151.83,-0.188
50.82,151.67,-0.188
50.85,151.51,-0.188
50.88,151.35,-0.188
50.91,151.19,-0.188
50.94,151.03,-0.188
50.98,150.88,-0.188
51.01,150.72,-0.188
51.04,150.56,-0.188
51.07,150.40,-0.188
51.10,150.24,-0.188
51.14,150.08,-0.188
51.17,149.93,-0.188
51.20,149.77,-0.188
51.23,149.61,-0.188
51.26,149.45,-0.188
51.29,149.29,-0.188
51.33,149.13,-0.188
51.36,148.98,-0.188
51.39,148.82,-0.188
51.42,148.66,-0.187
51.45,148.50,-0.187
51.48,148.34,-0.187
51.51,148.19,-0.187
51.55,148.03,-0.187
51.58,147.87,-0.187
51.61,147.71,-0.187
51.64,147.55,-0.187
51.67,147.39,-0.187
51.71,147.24,-0.187
51.74,147.08,-0.187
51.77,146.92,-0.187
51.80,146.76,-0.187
51.83,146.60,-0.187
51.86,146.44,-0.187
51.89,146.28,-0.187
51.93,146.13,-0.187
51.96,145.97,-0.186
51.99,145.81,-0.186
52.02,145.65,-0.186
52.05,145.49,-0.186
52.09,145.33,-0.186
52.12,145.18,-0.186
52.15,145.02,-0.186
52.18,144.86,-0.186
52.21,144.70,-0.186
52.24,144.54,-0.186
52.28,144.38,-0.186
52.31,144.23,-0.186
52.34,144.07,-0.185
52.37,143.91,-0.185
52.40,143.75,-0.185
52.43,143.59,-0.185
52.46,143.44,-0.185
52.50,143.28,-0.185
52.53,143.12,-0.185
52.56,142.96,-0.185
52.59,142.80,-0.185
52.62,142.64,-0.184
52.66,142.48,-0.184
52.69,142.33,-0.184
52.72,142.17,-0.184
52.75,142.01,-0.184
52.78,141.85,-0.184
52.81,141.69,-0.184
52.84,141.53,-0.183
52.88,141.38,-0.183
52.91,141.22,-0.183
52.94,141.06,-0.183
52.97,140.90,-0.183
53.00,140.74,-0.183
53.04,140.58,-0.183
53.07,140.43,-0.183
53.10,140.27,-0.182
53.13,140.11,-0.182
53.16,139.95,-0.182
53.19,139.79,-0.182
53.23,139.63,-0.182
53.26,139.47,-0.182
53.29,139.32,-0.181
53.32,139.16,-0.181
53.35,139.00,-0.181
53.38,138.84,-0.181
53.41,138.68,-0.181
53.45,138.52,-0.180
53.48,138.37,-0.180
53.51,138.21,-0.180
53.54,138.05,-0.180
53.57,137.89,-0.180
53.61,137.73,-0.180
53.64,137.57,-0.179
53.67,137.42,-0.179
53.70,137.26,-0.179
53.73,137.10,-0.179
53.76,136.94,-0.179
53.79,136.78,-0.178
53.83,136.62,-0.178
53.86,136.47,-0.178
53.89,136.31,-0.178
53.92,136.15,-0.178
53.95,135.99,-0.177
53.99,135.83,-0.177
54.02,135.67,-0.177
54.05,135.52,-0.177
54.08,135.36,-0.177
54.11,135.20,-0.176
54.14,135.04,-0.176
54.18,134.88,-0.176
54.21,134.72,-0.176
54.24,134.56,-0.176
54.27,134.41,-0.176
54.30,134.25,-0.175
54.33,134.09,-0.175
54.36,133.93,-0.175
54.40,133.77,-0.175
54.43,133.61,-0.174
54.46,133.46,-0.174
54.49,133.30,-0.174
54.52,133.14,-0.174
54.56,132.98,-0.174
54.59,132.82,-0.173
54.62,132.66,-0.173
54.65,132.51,-0.173
54.68,132.35,-0.173
54.71,132.19,-0.173
54.74,132.03,-0.173
54.78,131.87,-0.172
54.81,131.71,-0.172
54.84,131.56,-0.172
54.87,131.40,-0.172
54.90,131.24,-0.172
54.94,131.08,-0.171
54.97,130.92,-0.171
55.00,130.76,-0.171
55.03,130.60,-0.171
55.06,130.45,-0.171
55.09,130.29,-0.171
55.13,130.13,-0.171
55.16,129.97,-0.170
55.19,129.81,-0.170
55.22,129.65,-0.170
55.25,129.50,-0.170
55.28,129.34,-0.170
55.31,129.18,-0.169
55.35,129.02,-0.169
55.38,128.86,-0.169
55.41,128.70,-0.169
55.44,128.54,-0.169
55.47,128.39,-0.169
55.51,128.23,-0.168
55.54,128.07,-0.168
55.57,127.91,-0.168
55.60,127.75,-0.168
55.63,127.59,-0.168
55.66,127.44,-0.168
55.69,127.28,-0.168
55.73,127.12,-0.168
55.76,126.96,-0.167
55.79,126.80,-0.167
55.82,126.64,-0.167
55.85,126.49,-0.167
55.89,126.33,-0.167
55.92,126.17,-0.167
55.95,126.01,-0.167
55.98,125.85,-0.166
56.01,125.69,-0.166
56.04,125.54,-0.166
56.08,125.38,-0.166
56.11,125.22,-0.166
56.14,125.06,-0.166
56.17,124.90,-0.166
56.20,124.74,-0.165
56.23,124.59,-0.165
56.26,124.43,-0.165
56.30,124.27,-0.165
56.33,124.11,-0.165
56.36,123.95,-0.165
56.39,123.79,-0.165
56.42,123.64,-0.165
56.46,123.48,-0.164
56.49,123.32,-0.164
56.52,123.16,-0.164
56.55,123.00,-0.164
56.58,122.84,-0.164
56.61,122.69,-0.164
56.64,122.53,-0.164
56.68,122.37,-0.164
56.71,122.21,-0.163
56.74,122.05,-0.163
56.77,121.89,-0.163
56.80,121.73,-0.163
56.84,121.58,-0.163
56.87,121.42,-0.163
56.90,121.26,-0.163
56.93,121.10,-0.163
56.96,120.94,-0.163
56.99,120.78,-0.162
57.03,120.63,-0.162
57.06,120.47,-0.162
57.09,120.31,-0.162
57.12,120.15,-0.162
57.15,119.99,-0.162
57.18,119.83,-0.162
57.21,119.68,-0.162
57.25,119.52,-0.162
57.28,119.36,-0.162
57.31,119.20,-0.161
57.34,119.04,-0.161
57.37,118.88,-0.161
57.41,118.73,-0.161
57.44,118.57,-0.161
57.47,118.41,-0.161
57.50,118.25,-0.161
57.53,118.09,-0.161
57.56,117.93,-0.161
57.59,117.78,-0.160
57.63,117.62,-0.160
57.66,117.46,-0.160
57.69,117.30,-0.160
57.72,117.14,-0.160
57.75,116.98,-0.160
57.79,116.83,-0.160
57.82,116.67,-0.160
57.85,116.51,-0.160
57.88,116.35,-0.160
57.91,116.19,-0.160
57.94,116.03,-0.160
57.98,115.87,-0.159
58.01,115.72,-0.159
58.04,115.56,-0.159
58.07,115.40,-0.159
58.10,115.24,-0.159
58.13,115.08,-0.159
58.16,114.92,-0.159
58.20,114.77,-0.159
58.23,114.61,-0.159
58.26,114.45,-0.159
58.29,114.29,-0.159
58.32,114.13,-0.159
58.36,113.97,-0.158
58.39,113.82,-0.158
58.42,113.66,-0.158
58.45,113.50,-0.158
58.48,113.34,-0.158
58.51,113.18,-0.158
58.54,113.02,-0.158
58.58,112.87,-0.158
58.61,112.71,-0.158
58.64,112.55,-0.158
58.67,112.39,-0.158
58.70,112.23,-0.158
58.74,112.07,-0.158
58.77,111.92,-0.157
58.80,111.76,-0.157
58.83,111.60,-0.157
58.86,111.44,-0.157
58.89,111.28,-0.157
58.93,111.13,-0.157
58.96,110.97,-0.157
[...]
150.18,124.84,-0.166,1.757
150.20,124.76,-0.165,1.756
150.21,124.69,-0.165,1.755
150.23,124.61,-0.165,1.755
150.24,124.54,-0.165,1.754
150.26,124.46,-0.165,1.754
150.27,124.39,-0.165,1.752
150.29,124.31,-0.165,1.753
150.30,124.24,-0.165,1.751
150.32,124.16,-0.165,1.751
150.33,124.09,-0.165,1.751
150.35,124.01,-0.165,1.751
150.36,123.94,-0.165,1.750
150.38,123.86,-0.165,1.750
150.39,123.79,-0.165,1.748
150.41,123.71,-0.165,1.747
150.42,123.64,-0.165,1.746
150.44,123.56,-0.165,1.746
150.45,123.49,-0.164,1.746
150.47,123.41,-0.164,1.746
150.48,123.34,-0.164,1.746
150.50,123.26,-0.164,1.744
150.51,123.19,-0.164,1.744
150.53,123.11,-0.164,1.742
150.54,123.04,-0.164,1.741
150.56,122.96,-0.164,1.740
150.57,122.89,-0.164,1.740
150.59,122.81,-0.164,1.739
150.60,122.74,-0.164,1.739
150.62,122.66,-0.164,1.739
150.63,122.59,-0.164,1.737
150.65,122.51,-0.164,1.736
150.66,122.44,-0.164,1.736
150.68,122.36,-0.163,1.734
150.69,122.29,-0.163,1.734
150.71,122.21,-0.163,1.732
150.72,122.14,-0.163,1.733
150.74,122.06,-0.163,1.731
150.75,121.99,-0.163,1.731
150.77,121.91,-0.163,1.731
150.78,121.84,-0.163,1.731
150.80,121.76,-0.163,1.731
150.81,121.69,-0.163,1.730
150.83,121.61,-0.163,1.731
150.84,121.53,-0.163,1.730
150.86,121.46,-0.163,1.729
150.87,121.39,-0.163,1.728
150.89,121.31,-0.163,1.729
150.90,121.23,-0.163,1.729
150.92,121.16,-0.163,1.727
150.93,121.09,-0.163,1.726
150.95,121.01,-0.163,1.726
150.96,120.94,-0.162,1.725
150.98,120.86,-0.162,1.726
150.99,120.79,-0.162,1.725
151.01,120.71,-0.162,1.724
151.02,120.63,-0.162,1.722
151.04,120.56,-0.162,1.723
151.05,120.48,-0.162,1.723
151.07,120.41,-0.162,1.723
151.08,120.34,-0.162,1.721
151.10,120.26,-0.162,1.720
151.11,120.19,-0.162,1.719
151.13,120.11,-0.162,1.720
151.14,120.04,-0.162,1.720
151.16,119.96,-0.162,1.718
151.17,119.89,-0.162,1.719
151.19,119.81,-0.162,1.717
151.20,119.73,-0.162,1.716
151.22,119.66,-0.162,1.717
151.23,119.59,-0.162,1.716
151.25,119.51,-0.162,1.715
151.26,119.44,-0.161,1.715
151.28,119.36,-0.161,1.715
151.29,119.28,-0.161,1.714
151.31,119.21,-0.161,1.714
151.32,119.13,-0.161,1.715
151.34,119.06,-0.161,1.713
151.35,118.98,-0.161,1.714
151.37,118.91,-0.161,1.712
151.38,118.83,-0.161,1.712
151.40,118.76,-0.161,1.713
151.41,118.69,-0.161,1.712
151.43,118.61,-0.161,1.711
151.44,118.54,-0.161,1.711
151.46,118.46,-0.161,1.710
151.47,118.39,-0.161,1.709
151.49,118.31,-0.161,1.708
151.50,118.23,-0.161,1.708
151.52,118.16,-0.161,1.707
151.53,118.09,-0.161,1.707
151.55,118.01,-0.161,1.705
151.56,117.94,-0.161,1.706
151.58,117.86,-0.160,1.706
151.59,117.79,-0.160,1.704
151.61,117.71,-0.160,1.705
151.62,117.63,-0.160,1.702
151.64,117.56,-0.160,1.702
151.65,117.48,-0.160,1.702
151.67,117.41,-0.160,1.701
151.68,117.33,-0.160,1.702
151.70,117.26,-0.160,1.700
151.71,117.18,-0.160,1.700
151.73,117.11,-0.160,1.701
151.74,117.03,-0.160,1.701
151.76,116.96,-0.160,1.700
151.77,116.88,-0.160,1.698
151.79,116.81,-0.160,1.700
151.80,116.73,-0.160,1.699
151.82,116.66,-0.160,1.698
151.83,116.58,-0.160,1.697
151.85,116.51,-0.160,1.698
151.86,116.43,-0.160,1.697
151.88,116.36,-0.159,1.695
151.89,116.28,-0.159,1.696
151.91,116.21,-0.159,1.695
151.92,116.13,-0.159,1.694
151.94,116.06,-0.159,1.694
151.95,115.98,-0.159,1.693
151.97,115.91,-0.159,1.694
151.98,115.83,-0.159,1.692
152.00,115.76,-0.159,1.693
152.01,115.68,-0.159,1.692
152.03,115.61,-0.159,1.692
152.04,115.53,-0.159,1.691
152.06,115.46,-0.159,1.692
152.07,115.38,-0.159,1.691
152.09,115.31,-0.159,1.690
152.10,115.23,-0.159,1.689
152.12,115.16,-0.159,1.690
152.13,115.08,-0.159,1.689
152.15,115.01,-0.159,1.690
152.16,114.93,-0.159,1.689
152.18,114.86,-0.159,1.688
152.19,114.78,-0.159,1.689
152.21,114.71,-0.159,1.689
152.22,114.63,-0.159,1.688
152.24,114.56,-0.159,1.687
152.25,114.48,-0.159,1.686
152.27,114.41,-0.159,1.685
152.28,114.33,-0.159,1.685
152.30,114.26,-0.158,1.685
152.31,114.19,-0.158,1.684
152.33,114.11,-0.158,1.684
152.34,114.03,-0.158,1.684
152.36,113.96,-0.158,1.683
152.37,113.88,-0.158,1.683
152.39,113.81,-0.158,1.683
152.40,113.73,-0.158,1.682
152.42,113.66,-0.158,1.681
152.43,113.58,-0.158,1.681
152.45,113.51,-0.158,1.681
152.46,113.43,-0.158,1.681
152.48,113.36,-0.158,1.682
152.49,113.28,-0.158,1.681
152.51,113.21,-0.158,1.680
152.52,113.13,-0.158,1.679
152.54,113.06,-0.158,1.678
152.55,112.98,-0.158,1.678
152.57,112.91,-0.158,1.677
152.58,112.83,-0.158,1.677
152.60,112.76,-0.158,1.677
152.61,112.68,-0.158,1.676
152.63,112.61,-0.157,1.675
152.64,112.53,-0.157,1.674
152.66,112.46,-0.157,1.674
152.67,112.38,-0.157,1.674
152.69,112.31,-0.157,1.673
152.70,112.23,-0.157,1.673
152.72,112.16,-0.157,1.673
152.73,112.08,-0.157,1.673
152.75,112.01,-0.157,1.672
152.76,111.93,-0.157,1.671
152.78,111.86,-0.157,1.672
152.79,111.78,-0.157,1.670
152.81,111.71,-0.157,1.671
152.82,111.63,-0.157,1.672
152.84,111.56,-0.157,1.670
152.85,111.48,-0.157,1.671
152.87,111.41,-0.157,1.671
152.88,111.33,-0.157,1.672
152.90,111.26,-0.157,1.670
152.91,111.18,-0.157,1.670
152.93,111.11,-0.157,1.669
152.94,111.03,-0.157,1.669
152.96,110.96,-0.157,1.669
152.97,110.88,-0.157,1.668
152.99,110.81,-0.157,1.667
153.00,110.73,-0.157,1.666
153.02,110.66,-0.157,1.665
153.03,110.58,-0.157,1.666
153.05,110.51,-0.156,1.664
153.06,110.43,-0.156,1.665
153.08,110.36,-0.156,1.664
153.09,110.28,-0.156,1.664
153.11,110.21,-0.156,1.664
153.12,110.13,-0.156,1.663
153.14,110.06,-0.156,1.663
153.15,109.98,-0.156,1.663
153.17,109.91,-0.156,1.662
153.18,109.83,-0.156,1.661
153.20,109.76,-0.156,1.661
153.21,109.68,-0.156,1.661
153.23,109.61,-0.156,1.661
153.24,109.53,-0.156,1.660
153.26,109.46,-0.156,1.659
153.27,109.38,-0.156,1.658
153.29,109.31,-0.156,1.658
153.30,109.23,-0.156,1.656
153.32,109.16,-0.156,1.657
153.33,109.08,-0.156,1.657
153.35,109.01,-0.156,1.656
153.36,108.93,-0.156,1.657
153.38,108.86,-0.156,1.658
153.39,108.78,-0.156,1.657
153.41,108.71,-0.156,1.658
153.42,108.63,-0.156,1.657
153.44,108.56,-0.156,1.658
153.45,108.48,-0.156,1.658
153.47,108.41,-0.156,1.658
153.48,108.33,-0.156,1.659
153.50,108.26,-0.156,1.659
153.51,108.18,-0.155,1.657
153.53,108.11,-0.155,1.657
153.54,108.03,-0.155,1.656
153.56,107.96,-0.155,1.656
153.57,107.88,-0.155,1.654
153.59,107.81,-0.155,1.653
153.60,107.73,-0.155,1.652
153.62,107.66,-0.155,1.653
153.63,107.58,-0.155,1.650
153.65,107.51,-0.155,1.651
153.66,107.43,-0.155,1.649
153.68,107.36,-0.155,1.650
153.69,107.28,-0.155,1.649
153.71,107.21,-0.155,1.649
153.72,107.13,-0.155,1.648
153.74,107.06,-0.155,1.649
153.75,106.98,-0.155,1.649
153.77,106.91,-0.155,1.649
153.78,106.83,-0.155,1.649
153.80,106.76,-0.155,1.649
153.81,106.68,-0.155,1.649
153.83,106.61,-0.155,1.649
153.84,106.53,-0.155,1.648
153.86,106.46,-0.155,1.648
153.87,106.38,-0.155,1.655
153.89,106.31,-0.156,1.658
153.90,106.23,-0.156,1.656
153.92,106.16,-0.155,1.656
153.93,106.08,-0.155,1.654
153.95,106.01,-0.155,1.653
153.96,105.93,-0.155,1.653
153.98,105.86,-0.155,1.651
153.99,105.78,-0.155,1.651
154.01,105.71,-0.155,1.650
154.02,105.63,-0.155,1.649
154.04,105.56,-0.155,1.648
154.05,105.48,-0.155,1.647
154.07,105.41,-0.155,1.647
154.08,105.33,-0.155,1.647
154.10,105.26,-0.155,1.646
154.11,105.18,-0.155,1.647
154.13,105.11,-0.155,1.646
154.14,105.03,-0.154,1.646
154.16,104.96,-0.154,1.645
154.17,104.88,-0.154,1.645
154.19,104.81,-0.154,1.645
154.20,104.73,-0.154,1.644
154.22,104.66,-0.154,1.643
154.23,104.58,-0.154,1.642
154.25,104.51,-0.158,1.680
154.26,104.43,-0.160,1.700
154.28,104.36,-0.159,1.697
154.29,104.28,-0.159,1.691
154.31,104.21,-0.158,1.685
154.32,104.13,-0.158,1.681
154.34,104.06,-0.158,1.680
154.35,103.98,-0.157,1.675
154.37,103.91,-0.156,1.663
154.38,103.83,-0.156,1.661
154.40,103.76,-0.156,1.659
154.41,103.68,-0.156,1.658
154.43,103.61,-0.156,1.657
154.44,103.53,-0.155,1.655
154.46,103.46,-0.155,1.654
154.47,103.38,-0.155,1.652
154.49,103.31,-0.155,1.651
154.50,103.23,-0.155,1.649
154.52,103.16,-0.155,1.649
154.53,103.08,-0.155,1.647
154.55,103.01,-0.155,1.646
154.56,102.93,-0.154,1.645
154.58,102.86,-0.154,1.643
154.59,102.78,-0.154,1.643
154.61,102.71,-0.154,1.642
154.62,102.63,-0.154,1.642
154.64,102.56,-0.154,1.640
154.65,102.48,-0.154,1.639
154.67,102.41,-0.154,1.639
154.68,102.33,-0.154,1.638
154.70,102.26,-0.154,1.637
154.71,102.18,-0.154,1.637
154.73,102.11,-0.154,1.636
154.74,102.03,-0.153,1.636
154.76,101.96,-0.153,1.635
154.77,101.88,-0.153,1.634
154.79,101.81,-0.153,1.634
154.80,101.73,-0.153,1.633
154.82,101.66,-0.153,1.632
154.83,101.58,-0.153,1.631
154.85,101.51,-0.153,1.631
154.86,101.43,-0.153,1.632
154.88,101.36,-0.153,1.629
154.89,101.28,-0.153,1.629
154.91,101.21,-0.153,1.629
154.92,101.13,-0.153,1.628
154.94,101.06,-0.153,1.628
154.95,100.98,-0.153,1.629
154.97,100.91,-0.153,1.629
154.98,100.83,-0.153,1.628
155.00,100.76,-0.153,1.629
155.01,100.68,-0.153,1.628
155.03,100.61,-0.153,1.628
155.04,100.53,-0.153,1.628
155.06,100.46,-0.153,1.626
155.07,100.38,-0.153,1.627
155.09,100.31,-0.152,1.626
155.10,100.23,-0.152,1.625
155.12,100.16,-0.152,1.625
155.13,100.08,-0.152,1.624
155.15,100.01,-0.152,1.624
155.16,99.93,-0.152,1.623
155.18,99.86,-0.152,1.622
155.19,99.78,-0.152,1.623
155.21,99.71,-0.152,1.621
155.22,99.63,-0.152,1.622
155.24,99.56,-0.152,1.620
155.25,99.48,-0.152,1.620
155.27,99.41,-0.152,1.620
155.28,99.33,-0.152,1.619
155.30,99.26,-0.152,1.618
155.31,99.18,-0.152,1.619
155.33,99.11,-0.152,1.618
155.34,99.03,-0.152,1.617
155.36,98.96,-0.152,1.616
155.37,98.88,-0.152,1.616
155.39,98.81,-0.152,1.616
155.40,98.73,-0.152,1.617
155.42,98.66,-0.152,1.616
155.43,98.58,-0.152,1.617
155.45,98.51,-0.152,1.617
155.46,98.43,-0.152,1.617
155.48,98.36,-0.152,1.618
155.49,98.28,-0.152,1.617
155.51,98.21,-0.152,1.617
155.52,98.13,-0.152,1.618
155.54,98.06,-0.152,1.617
155.55,97.98,-0.152,1.617
155.57,97.91,-0.152,1.617
155.58,97.83,-0.152,1.616
155.60,97.76,-0.152,1.617
155.61,97.68,-0.152,1.615
155.63,97.61,-0.151,1.616
155.64,97.53,-0.151,1.615
155.66,97.46,-0.151,1.614
155.67,97.38,-0.151,1.614
155.69,97.31,-0.151,1.614
155.70,97.23,-0.151,1.612
155.72,97.16,-0.151,1.613
155.73,97.08,-0.151,1.613
155.75,97.01,-0.151,1.613
155.76,96.93,-0.151,1.612
155.78,96.86,-0.151,1.612
155.79,96.78,-0.151,1.610
155.81,96.71,-0.151,1.611
155.82,96.63,-0.151,1.611
155.84,96.56,-0.151,1.612
155.85,96.48,-0.151,1.613
155.87,96.41,-0.151,1.613
155.88,96.33,-0.151,1.613
155.90,96.26,-0.151,1.612
155.91,96.18,-0.151,1.612
155.93,96.11,-0.151,1.611
155.94,96.03,-0.151,1.610
155.96,95.96,-0.151,1.609
155.97,95.88,-0.151,1.608
155.99,95.81,-0.151,1.608
156.00,95.73,-0.151,1.607
156.02,95.66,-0.151,1.606
156.03,95.58,-0.151,1.606
156.05,95.51,-0.151,1.606
156.06,95.43,-0.151,1.605
156.08,95.36,-0.151,1.605
156.09,95.28,-0.151,1.604
156.11,95.21,-0.151,1.604
156.12,95.13,-0.151,1.604
156.14,95.06,-0.151,1.605
156.15,94.98,-0.151,1.606
156.17,94.91,-0.151,1.606
156.18,94.83,-0.150,1.606
156.20,94.76,-0.150,1.605
156.21,94.68,-0.150,1.606
156.23,94.61,-0.150,1.604
156.24,94.53,-0.150,1.605
156.26,94.46,-0.150,1.605
156.27,94.38,-0.150,1.603
156.29,94.31,-0.150,1.603
156.30,94.23,-0.150,1.602
156.32,94.16,-0.150,1.602
156.33,94.08,-0.150,1.601
156.35,94.01,-0.150,1.600
156.36,93.93,-0.150,1.601
156.38,93.86,-0.150,1.600
156.39,93.78,-0.150,1.600
156.41,93.71,-0.150,1.599
156.42,93.63,-0.150,1.599
156.44,93.56,-0.150,1.599
156.45,93.48,-0.150,1.597
156.47,93.41,-0.150,1.597
156.48,93.33,-0.150,1.596
156.50,93.26,-0.150,1.597
156.51,93.18,-0.150,1.596
156.53,93.11,-0.150,1.595
156.54,93.03,-0.150,1.596
156.56,92.96,-0.149,1.597
156.57,92.88,-0.149,1.598
156.59,92.81,-0.149,1.597
156.60,92.73,-0.149,1.597
156.62,92.66,-0.149,1.596
156.63,92.58,-0.149,1.597
156.65,92.51,-0.157,1.680
156.66,92.43,-0.162,1.735
156.68,92.36,-0.160,1.709
156.69,92.28,-0.159,1.698
156.71,92.21,-0.154,1.649
156.72,92.13,-0.153,1.638
156.74,92.06,-0.152,1.625
156.75,91.98,-0.152,1.621
156.77,91.91,-0.151,1.615
156.78,91.83,-0.151,1.612
156.80,91.76,-0.151,1.611
156.81,91.68,-0.151,1.610
156.83,91.61,-0.151,1.609
156.84,91.53,-0.151,1.607
156.86,91.46,-0.151,1.606
156.87,91.38,-0.151,1.607
156.89,91.31,-0.150,1.605
156.90,91.23,-0.150,1.603
156.92,91.16,-0.150,1.602
156.93,91.08,-0.150,1.601
156.95,91.01,-0.150,1.599
156.96,90.93,-0.150,1.599
156.98,90.86,-0.150,1.598
156.99,90.78,-0.150,1.598
157.01,90.71,-0.150,1.597
157.02,90.63,-0.150,1.596
157.04,90.56,-0.149,1.595
157.05,90.48,-0.149,1.595
157.07,90.41,-0.149,1.593
157.08,90.33,-0.149,1.592
157.10,90.26,-0.149,1.594
157.11,90.18,-0.149,1.593
157.13,90.11,-0.149,1.592
157.14,90.03,-0.149,1.591
157.16,89.96,-0.149,1.592
157.17,89.88,-0.149,1.591
157.19,89.81,-0.149,1.591
157.20,89.73,-0.149,1.590
157.22,89.66,-0.149,1.591
157.23,89.58,-0.149,1.589
157.25,89.51,-0.149,1.589
157.26,89.43,-0.149,1.588
157.28,89.36,-0.149,1.587
157.29,89.28,-0.149,1.586
157.31,89.21,-0.149,1.585
157.32,89.13,-0.148,1.583
157.34,89.06,-0.148,1.583
157.35,88.98,-0.148,1.581
157.37,88.91,-0.148,1.580
157.38,88.83,-0.148,1.579
157.40,88.76,-0.148,1.579
157.41,88.68,-0.148,1.579
157.43,88.60,-0.148,1.579
157.44,88.53,-0.148,1.580
157.46,88.45,-0.148,1.579
157.47,88.38,-0.148,1.581
157.49,88.31,-0.148,1.581
157.50,88.23,-0.148,1.581
157.52,88.16,-0.148,1.581
157.53,88.08,-0.148,1.581
157.55,88.00,-0.148,1.582
157.56,87.93,-0.148,1.582
157.58,87.86,-0.148,1.582
157.59,87.78,-0.148,1.580
157.61,87.71,-0.148,1.580
157.62,87.63,-0.148,1.578
157.64,87.56,-0.148,1.577
157.65,87.48,-0.148,1.577
157.67,87.41,-0.148,1.577
157.68,87.33,-0.148,1.576
157.70,87.26,-0.147,1.576
157.71,87.18,-0.147,1.575
157.73,87.11,-0.147,1.575
157.74,87.03,-0.147,1.573
157.76,86.96,-0.147,1.574
157.77,86.88,-0.147,1.574
157.79,86.81,-0.147,1.574
157.80,86.73,-0.147,1.574
157.82,86.66,-0.147,1.573
157.83,86.58,-0.147,1.573
157.85,86.51,-0.147,1.573
157.86,86.43,-0.147,1.573
157.88,86.36,-0.147,1.574
157.89,86.28,-0.147,1.573
157.91,86.21,-0.147,1.573
157.92,86.13,-0.147,1.573
157.94,86.06,-0.147,1.574
157.95,85.98,-0.148,1.576
157.97,85.91,-0.148,1.575
157.98,85.83,-0.148,1.576
158.00,85.76,-0.147,1.574
158.01,85.68,-0.147,1.574
158.03,85.61,-0.147,1.573
158.04,85.53,-0.147,1.572
158.06,85.46,-0.147,1.570
158.07,85.38,-0.147,1.571
158.09,85.31,-0.147,1.569
158.10,85.23,-0.147,1.568
158.12,85.16,-0.147,1.569
158.13,85.08,-0.147,1.568
158.15,85.01,-0.147,1.568
158.16,84.93,-0.147,1.568
158.18,84.86,-0.147,1.567
158.19,84.78,-0.147,1.567
158.21,84.71,-0.147,1.566
158.22,84.63,-0.147,1.566
158.24,84.56,-0.147,1.565
158.25,84.48,-0.147,1.564
158.27,84.41,-0.147,1.564
158.28,84.33,-0.147,1.564
158.30,84.26,-0.147,1.564
158.31,84.18,-0.147,1.564
158.33,84.11,-0.146,1.563
158.34,84.03,-0.147,1.563
158.36,83.96,-0.146,1.563
158.37,83.88,-0.146,1.564
158.39,83.81,-0.146,1.563
158.40,83.73,-0.146,1.564
158.42,83.66,-0.146,1.562
158.43,83.58,-0.146,1.564
158.45,83.50,-0.146,1.563
158.46,83.43,-0.146,1.563
158.48,83.36,-0.146,1.564
158.49,83.28,-0.146,1.562
158.51,83.21,-0.146,1.561
158.52,83.13,-0.146,1.562
158.54,83.06,-0.146,1.562
158.55,82.98,-0.146,1.560
158.57,82.91,-0.146,1.559
158.58,82.83,-0.146,1.559
158.60,82.76,-0.146,1.556
158.61,82.68,-0.146,1.557
158.63,82.61,-0.146,1.557
158.64,82.53,-0.146,1.556
158.66,82.46,-0.146,1.555
158.67,82.38,-0.146,1.554
158.69,82.31,-0.146,1.554
158.70,82.23,-0.146,1.554
158.72,82.15,-0.146,1.553
158.73,82.08,-0.146,1.554
158.75,82.01,-0.146,1.554
158.76,81.93,-0.146,1.553
158.78,81.86,-0.146,1.552
158.79,81.78,-0.146,1.554
158.81,81.70,-0.146,1.553
158.82,81.63,-0.146,1.553
158.84,81.55,-0.146,1.551
158.85,81.48,-0.146,1.552
158.87,81.40,-0.146,1.551
158.88,81.33,-0.146,1.551
158.90,81.26,-0.146,1.551
158.91,81.18,-0.146,1.552
158.93,81.10,-0.145,1.551
158.94,81.03,-0.145,1.552
158.96,80.95,-0.145,1.553
158.97,80.88,-0.145,1.553
158.99,80.80,-0.145,1.552
159.00,80.73,-0.145,1.553
159.02,80.65,-0.145,1.552
159.03,80.58,-0.145,1.554
159.05,80.50,-0.145,1.552
159.06,80.43,-0.145,1.553
159.08,80.36,-0.145,1.552
159.09,80.28,-0.145,1.553
159.11,80.21,-0.145,1.553
159.12,80.13,-0.145,1.552
159.14,80.05,-0.145,1.552
159.15,79.98,-0.145,1.551
159.17,79.91,-0.145,1.551
159.18,79.83,-0.145,1.551
159.20,79.76,-0.145,1.551
159.21,79.68,-0.145,1.550
159.23,79.61,-0.145,1.549
159.24,79.53,-0.145,1.549
159.26,79.45,-0.145,1.548
159.27,79.38,-0.145,1.547
159.29,79.31,-0.145,1.547
159.30,79.23,-0.145,1.546
159.32,79.16,-0.145,1.546
159.33,79.08,-0.145,1.545
159.35,79.01,-0.145,1.545
159.36,78.93,-0.145,1.545
159.38,78.86,-0.145,1.545
159.39,78.78,-0.145,1.544
159.41,78.71,-0.145,1.543
159.42,78.63,-0.145,1.544
159.44,78.56,-0.145,1.544
159.45,78.48,-0.145,1.544
159.47,78.41,-0.145,1.544
159.48,78.33,-0.144,1.542
159.50,78.26,-0.144,1.542
159.51,78.18,-0.144,1.541
159.53,78.11,-0.144,1.542
159.54,78.03,-0.144,1.542
159.56,77.96,-0.144,1.541
159.57,77.88,-0.144,1.541
159.59,77.81,-0.144,1.540
159.60,77.73,-0.144,1.541
159.62,77.66,-0.144,1.540
159.63,77.58,-0.144,1.539
159.65,77.51,-0.144,1.539
159.66,77.43,-0.144,1.538
159.68,77.35,-0.144,1.539
159.69,77.28,-0.144,1.538
159.71,77.21,-0.144,1.538
159.72,77.13,-0.144,1.538
159.74,77.05,-0.144,1.538
159.75,76.98,-0.144,1.537
159.77,76.90,-0.144,1.538
159.78,76.83,-0.144,1.538
159.80,76.75,-0.144,1.538
159.81,76.68,-0.144,1.537
159.83,76.61,-0.144,1.537
159.84,76.53,-0.144,1.537
159.86,76.45,-0.144,1.537
159.87,76.38,-0.144,1.536
159.89,76.31,-0.144,1.536
159.90,76.23,-0.144,1.537
159.92,76.16,-0.144,1.535
159.93,76.08,-0.144,1.535
159.95,76.01,-0.144,1.535
159.96,75.93,-0.144,1.535
159.98,75.85,-0.144,1.536
159.99,75.78,-0.144,1.535
160.01,75.71,-0.144,1.534
160.02,75.63,-0.144,1.534
160.04,75.56,-0.144,1.534
160.05,75.48,-0.144,1.533
160.07,75.41,-0.144,1.533
160.08,75.33,-0.143,1.534
160.10,75.26,-0.143,1.533
160.11,75.18,-0.143,1.533
160.13,75.11,-0.143,1.533
160.14,75.03,-0.143,1.531
160.16,74.96,-0.143,1.531
160.17,74.88,-0.143,1.530
160.19,74.81,-0.143,1.530
160.20,74.73,-0.143,1.527
160.22,74.66,-0.143,1.527
160.23,74.58,-0.143,1.527
160.25,74.51,-0.143,1.526
160.26,74.43,-0.143,1.525
160.28,74.36,-0.143,1.523
160.29,74.28,-0.143,1.522
160.31,74.21,-0.143,1.522
160.32,74.13,-0.143,1.522
160.34,74.06,-0.143,1.522
160.35,73.98,-0.143,1.523
160.37,73.91,-0.143,1.523
160.38,73.83,-0.143,1.524
160.40,73.76,-0.143,1.524
160.41,73.68,-0.143,1.526
160.43,73.61,-0.143,1.525
160.44,73.53,-0.143,1.525
160.46,73.46,-0.143,1.524
160.47,73.38,-0.143,1.524
160.49,73.30,-0.143,1.524
160.50,73.23,-0.143,1.523
160.52,73.16,-0.143,1.523
160.53,73.08,-0.143,1.522
160.55,73.01,-0.143,1.522
160.56,72.93,-0.143,1.520
160.58,72.86,-0.143,1.520
160.59,72.78,-0.143,1.520
160.61,72.70,-0.143,1.519
160.62,72.63,-0.142,1.518
160.64,72.55,-0.142,1.518
160.65,72.48,-0.142,1.518
160.67,72.40,-0.142,1.517
160.68,72.33,-0.142,1.515
160.70,72.26,-0.142,1.516
160.71,72.18,-0.142,1.515
160.73,72.10,-0.142,1.514
160.74,72.03,-0.142,1.514
160.76,71.95,-0.142,1.515
160.77,71.88,-0.142,1.514
160.79,71.80,-0.142,1.514
160.80,71.73,-0.142,1.514
160.82,71.65,-0.142,1.515
160.83,71.58,-0.142,1.516
160.85,71.50,-0.142,1.516
160.86,71.43,-0.142,1.517
160.88,71.35,-0.142,1.518
160.89,71.28,-0.142,1.516
160.91,71.20,-0.142,1.516
160.92,71.13,-0.142,1.516
160.94,71.05,-0.142,1.515
160.95,70.98,-0.142,1.515
160.97,70.90,-0.142,1.514
160.98,70.83,-0.142,1.515
161.00,70.75,-0.142,1.513
161.01,70.68,-0.142,1.513
161.03,70.60,-0.142,1.511
161.04,70.53,-0.142,1.511
161.06,70.45,-0.142,1.511
161.07,70.38,-0.142,1.510
161.09,70.30,-0.142,1.511
161.10,70.23,-0.142,1.510
161.12,70.15,-0.142,1.510
161.13,70.08,-0.142,1.509
161.15,70.00,-0.141,1.510
161.16,69.93,-0.141,1.509
161.18,69.85,-0.141,1.509
161.19,69.78,-0.141,1.508
161.21,69.70,-0.141,1.509
161.22,69.63,-0.141,1.509
161.24,69.55,-0.141,1.508
161.25,69.48,-0.141,1.508
161.27,69.40,-0.141,1.508
161.28,69.33,-0.141,1.507
161.30,69.25,-0.141,1.507
161.31,69.18,-0.141,1.507
161.33,69.10,-0.141,1.507
161.34,69.03,-0.141,1.506
161.36,68.95,-0.141,1.505
161.37,68.88,-0.141,1.504
161.39,68.80,-0.141,1.504
161.40,68.73,-0.141,1.502
161.42,68.65,-0.141,1.502
161.43,68.58,-0.141,
161.45,68.50,-0.141,
161.46,68.43,-0.141,
161.48,68.35,-0.141,
161.49,68.28,,
161.51,68.20,,
161.52,68.13,,
161.54,,,
161.54,,,