File: DSC/Earl/2025_10_07_1CBD_1PVP10_ASD_5Cmin_n60C_150C_x3.csv
Filename,2025_10_07_1CBD_1PVP10_ASD_5Cmin_n60C_150C_x3
Instrument name,DSC2A-00468 (192.168.1.100)
Operator,JLY
rundate,10/7/2025
Sample name,2025_10_07_1CBD_1PVP10_ASD_5Cmin_n60C_150C_x3
proceduresegments,Data Off ; Equilibrate -60.00 °C; Data On ; Ramp 5.00 °C/min to 150.00 °C; Data Off ; Isothermal 1.0 min; Data On ; Ramp 5.00 °C/min to -60.00 °C; Data Off ; Isothermal 1.0 min; Data On ; Ramp 5.00 °C/min to 150.00 °C; Data Off ; Isothermal 1.0 min; Data On ; Ramp 5.00 °C/min to -60.00 °C; Data Off ; Isothermal 1.0 min; Data On ; Ramp 5.00 °C/min to 150.00 °C
[File Parameters]
Run date,10/7/2025 12:53:38 PM
Trios version,5.1.1.46572
Original File Name,D:\DSC2500\JYarger\2025_10_07_1CBD_1PVP10_ASD_5Cmin_n60C_150C_x3.tri
Current File Name,D:\DSC2500\JYarger\2025_10_07_1CBD_1PVP10_ASD_5Cmin_n60C_150C_x3.tri
[Procedure]
Procedure Name,ASD_n60C_150C_5Cmin_x3
Sample Name,2025_10_07_1CBD_1PVP10_ASD_5Cmin_n60C_150C_x3
Sample Mass,5 mg
Reference Sample Mass,0 mg
Pan Mass,32.51 mg
Pan Number,21
Reference Pan Mass,32.55 mg
Reference Pan Number,1
Pan Type,Aluminum
Comments,DSC_Samples_Y2_Tray_ASDs_Pharma_Oct2025 Google Sheet.
Project Name,Amorphous Pharma
Operator,JLY
Test,Custom
Unload Max Temperature,30
Unload Min Temperature,30
Load Max Temperature,30
Load Min Temperature,30
Stop on Gas Flow Error,Yes
[Signal List]
Signal #1,Time (min)
Signal #2,Temperature (°C)
Signal #3,Heat Flow (mW)
Signal #4,Delta T (µV)
Signal #5,Delta Tzero (µV)
Signal #6,Tzero Temperature (°C)
Signal #7,Cell Purge (mL/min)
Signal #8,Heater Temp (°C)
Signal #9,Power Delivered (W)
Signal #10,Reference Junction Temperature (°C)
Signal #11,Flange Temperature (°C)
Signal #12,Heat Flow Phase (rad)
Signal #13,Total Heat Capacity (J/°C)
Signal #14,Heat Capacity (J/°C)
[Configuration]
Company Name,ASU
Instrument Name,DSC2A-00468
Instrument Type,DSC2500
Serial Number,DSC2A-00468
IP,192.168.1.100
Location of Instrument,MRRC
DisplayType,Unknown
Sample Interval ,0.1 s/pt
Selected Heat Flow,T4P
Exotherm Direction,Down
Cell Serial,DRC2-00792
Lid Type,Standard
Cooler,RCS 90
Leave Cooler on at End of Sequence,On
Gas 2,Nitrogen
Gas Selected,Channel 1
Flow Rate,50 mL/min
Secondary Purge,On
Licensed Heat Flow,Heat Flow T4P
Modulation Licensed,Yes
[Versions]
Common IDD Version,1
Cortex Version,VER 2.10.2.31
Driver,5.0.0.6
GDM Version,1.0.3.3
TouchscreenVersion,1.0.0.16145
FEP Version,1.2.1.21
FEP Bootloader,2.0.0.5
AutoSampler Version,2.1.1.26
Auto Sampler Bootloader,2.0.0.5
FCM Version,1.1.0.3
FCM Bootloader,2.0.0.5
[Experiment Logs]
Experiment Log Entry # 1,Data On set to 0
Experiment Log Entry # 3,Equilibrate Segment -60 (C) Started
Experiment Log Entry # 5,Air Cool is off.
Experiment Log Entry # 7,Data On set to 1
Experiment Log Entry # 9,Ramp Segment 5 C/min to 150 Started
Experiment Log Entry # 11,"An attempt to access flash memory was unsuccessful (ErrCode=3, FlashLoc=5, IsWrite=0)."
Experiment Log Entry # 13,Data On set to 0
Experiment Log Entry # 15,Isothermal Segment 1 min started
Experiment Log Entry # 17,Data On set to 1
Experiment Log Entry # 19,Ramp Segment 5 C/min to -60 Started
Experiment Log Entry # 21,Auto sampler has detected that FCM has gone offline
Experiment Log Entry # 23,Data On set to 0
Experiment Log Entry # 25,Isothermal Segment 1 min started
Experiment Log Entry # 27,Data On set to 1
Experiment Log Entry # 29,Ramp Segment 5 C/min to 150 Started
Experiment Log Entry # 31,Data On set to 0
Experiment Log Entry # 33,Isothermal Segment 1 min started
Experiment Log Entry # 35,Data On set to 1
Experiment Log Entry # 37,Ramp Segment 5 C/min to -60 Started
Experiment Log Entry # 39,Data On set to 0
Experiment Log Entry # 41,Isothermal Segment 1 min started
Experiment Log Entry # 43,Data On set to 1
Experiment Log Entry # 45,Ramp Segment 5 C/min to 150 Started
[Method Log]
Method Log Entry # 1,Data Off
Method Log Entry # 2,Equilibrate -60 °C
Method Log Entry # 3,Data On
Method Log Entry # 4,(Ramp 859513) Ramp 5 °C/minute to 150 °C
Method Log Entry # 5,Data Off
Method Log Entry # 6,Isothermal 1 minutes
Method Log Entry # 7,Data On
Method Log Entry # 8,(Ramp 859517) Ramp 5 °C/minute to -60 °C
Method Log Entry # 9,Data Off
Method Log Entry # 10,Isothermal 1 minutes
Method Log Entry # 11,Data On
Method Log Entry # 12,(Ramp 859521) Ramp 5 °C/minute to 150 °C
Method Log Entry # 13,Data Off
Method Log Entry # 14,Isothermal 1 minutes
Method Log Entry # 15,Data On
Method Log Entry # 16,(Ramp 859525) Ramp 5 °C/minute to -60 °C
Method Log Entry # 17,Data Off
Method Log Entry # 18,Isothermal 1 minutes
Method Log Entry # 19,Data On
Method Log Entry # 20,(Ramp 859529) Ramp 5 °C/minute to 150 °C
Cell Serial,DRC2-00792
[T1 Calibration]
Slope,-0.008529666
Offset,9.636258
Initial Temperature,98.23
GUID,f8bfdadc-4977-4fdf-ba6d-0ba9134940c3
[TZero Calibration]
Date Applied,11/29/2022 4:06:13 PM
Description,From -89.059 °C to 396.009 °C at 20.000°C/min
Gas Type,Nitrogen
Pan Type,None
Source Files 1,C:\Users\yargerlab\Desktop\DSC Data\General\TZero_calibration_11_29_22_2nd(2).tri
Source Files 2,C:\Users\yargerlab\Desktop\DSC Data\General\TZero_calibration_11_29_22_2nd(3).tri
Delta T Offset,13.05235
Delta T Slope,-0.007271007
Delta T0 Offset,-13.69128
Delta T0 Slope,0.06063341
[Temperature Calibration]
Date Applied,11/29/2022 7:12:28 PM
Description,From 106.590 °C to 186.590 °C at 10.000°C/min
Gas Type,Nitrogen
Pan Type,Tzero Aluminum Hermetic
Source Files 1,C:\Users\yargerlab\Desktop\DSC Data\General\Indium(6).tri
Measured 1,157.391
Known 1,156.598
[Cell Constant Calibration]
Date Applied,11/29/2022 7:12:29 PM
Description,From 106.590 °C to 186.590 °C at 10.000°C/min
Gas Type,Nitrogen
Pan Type,Tzero Aluminum Hermetic
Source Files 1,C:\Users\yargerlab\Desktop\DSC Data\General\Indium(6).tri
T4P KCell,1.006051
Onset Slope,63.26126 mW/°C
[Direct Cp Calibration]
Date Applied,11/30/2022 11:04:51 AM
Description,From -79.983 °C to 298.409 °C at 10.000°C/min
Gas Type,Nitrogen
Pan Type,Tzero Aluminum Hermetic
Source Files 1,C:\Users\yargerlab\Desktop\DSC Data\General\Sapphire_Heat_Capacity_11_30_22.tri
[Rev Cp Calibration]
Date Applied,11/30/2022 1:58:51 PM
Description,From -79.996 °C to 292.812 °C at 3.000°C/min
Gas Type,Nitrogen
Pan Type,Tzero Aluminum Hermetic
Source Files 1,C:\Users\yargerlab\Desktop\DSC Data\General\Sapphire_MDSC_Calibration_11_30_22.tri
[step]
Ramp 5.00 °C/min to 150.00 °C
Time,Temperature,Heat Flow (Normalized)
min,°C,W/g
0.00,-59.80,-0.051
0.03,-59.81,-0.047
0.06,-59.81,-0.041
0.08,-59.76,-0.038
0.11,-59.69,-0.031
0.14,-59.59,-0.013
0.17,-59.47,0.008
0.20,-59.35,0.027
0.23,-59.22,0.039
0.26,-59.10,0.051
0.28,-58.96,0.058
0.31,-58.83,0.063
0.34,-58.70,0.068
0.37,-58.56,0.071
0.40,-58.43,0.073
0.43,-58.29,0.075
0.45,-58.15,0.076
0.48,-58.01,0.077
0.51,-57.87,0.078
0.54,-57.73,0.079
0.57,-57.59,0.080
0.60,-57.45,0.080
0.62,-57.32,0.081
0.65,-57.17,0.081
0.68,-57.03,0.081
0.71,-56.90,0.082
0.74,-56.75,0.082
0.77,-56.61,0.083
0.79,-56.47,0.083
0.82,-56.33,0.083
0.85,-56.19,0.084
0.88,-56.05,0.084
0.91,-55.91,0.084
0.93,-55.77,0.085
0.96,-55.63,0.085
0.99,-55.49,0.085
1.02,-55.35,0.085
1.05,-55.21,0.085
1.08,-55.07,0.085
1.11,-54.93,0.086
1.13,-54.78,0.086
1.16,-54.64,0.086
1.19,-54.50,0.086
1.22,-54.36,0.086
1.25,-54.22,0.086
1.28,-54.08,0.086
1.30,-53.94,0.086
1.33,-53.79,0.086
1.36,-53.65,0.086
1.39,-53.51,0.086
1.42,-53.37,0.087
1.44,-53.23,0.087
1.47,-53.09,0.087
1.50,-52.95,0.087
1.53,-52.80,0.087
1.56,-52.66,0.087
1.59,-52.52,0.087
1.62,-52.38,0.087
1.64,-52.24,0.087
1.67,-52.10,0.087
1.70,-51.96,0.087
1.73,-51.82,0.087
1.76,-51.67,0.087
1.78,-51.53,0.087
1.81,-51.39,0.087
1.84,-51.25,0.087
1.87,-51.11,0.087
1.90,-50.97,0.087
1.93,-50.82,0.087
1.96,-50.68,0.087
1.98,-50.54,0.087
2.01,-50.40,0.087
2.04,-50.26,0.087
2.07,-50.12,0.087
2.10,-49.97,0.087
2.13,-49.83,0.087
2.15,-49.69,0.086
2.18,-49.55,0.087
2.21,-49.41,0.086
2.24,-49.27,0.087
2.27,-49.12,0.086
2.29,-48.98,0.086
2.32,-48.84,0.086
2.35,-48.70,0.086
2.38,-48.56,0.086
2.41,-48.42,0.086
2.44,-48.28,0.086
2.46,-48.13,0.086
2.49,-47.99,0.086
2.52,-47.85,0.086
2.55,-47.71,0.086
2.58,-47.57,0.086
2.61,-47.43,0.086
2.64,-47.28,0.086
2.66,-47.14,0.086
2.69,-47.00,0.086
2.72,-46.86,0.086
2.75,-46.72,0.086
2.78,-46.58,0.086
2.81,-46.44,0.086
2.83,-46.29,0.086
2.86,-46.15,0.086
2.89,-46.01,0.086
2.92,-45.87,0.086
2.95,-45.73,0.086
2.98,-45.59,0.086
3.00,-45.44,0.086
3.03,-45.30,0.086
3.06,-45.16,0.086
3.09,-45.02,0.086
3.12,-44.88,0.086
3.14,-44.74,0.086
3.17,-44.60,0.086
3.20,-44.45,0.086
3.23,-44.31,0.086
3.26,-44.17,0.086
3.29,-44.03,0.086
3.31,-43.89,0.086
3.34,-43.75,0.086
3.37,-43.60,0.086
3.40,-43.46,0.086
3.43,-43.32,0.086
3.46,-43.18,0.086
3.49,-43.04,0.086
3.51,-42.90,0.086
3.54,-42.75,0.086
3.57,-42.61,0.086
3.60,-42.47,0.086
3.63,-42.33,0.086
3.66,-42.19,0.086
3.68,-42.05,0.086
3.71,-41.90,0.086
3.74,-41.76,0.086
3.77,-41.62,0.086
3.80,-41.48,0.086
3.83,-41.34,0.086
3.85,-41.20,0.086
3.88,-41.05,0.086
3.91,-40.91,0.086
3.94,-40.77,0.086
3.97,-40.63,0.086
3.99,-40.49,0.086
4.02,-40.34,0.086
4.05,-40.20,0.086
4.08,-40.06,0.086
4.11,-39.92,0.087
4.14,-39.78,0.087
4.16,-39.63,0.087
4.19,-39.49,0.087
4.22,-39.35,0.087
4.25,-39.21,0.087
4.28,-39.07,0.087
4.31,-38.93,0.087
4.34,-38.78,0.087
4.36,-38.64,0.087
4.39,-38.50,0.087
4.42,-38.36,0.087
4.45,-38.22,0.087
4.48,-38.07,0.087
4.50,-37.93,0.087
4.53,-37.79,0.087
4.56,-37.65,0.087
4.59,-37.51,0.087
4.62,-37.36,0.087
4.65,-37.22,0.087
4.68,-37.08,0.087
4.70,-36.94,0.087
4.73,-36.80,0.087
4.76,-36.66,0.087
4.79,-36.52,0.087
4.82,-36.37,0.087
4.85,-36.23,0.087
4.87,-36.09,0.087
4.90,-35.95,0.087
4.93,-35.81,0.087
4.96,-35.66,0.087
4.99,-35.52,0.087
5.01,-35.38,0.087
5.04,-35.24,0.087
5.07,-35.10,0.087
5.10,-34.96,0.087
5.13,-34.81,0.087
5.16,-34.67,0.087
5.19,-34.53,0.087
5.21,-34.39,0.087
5.24,-34.25,0.087
5.27,-34.11,0.087
5.30,-33.96,0.087
5.33,-33.82,0.087
5.35,-33.68,0.087
5.38,-33.54,0.087
5.41,-33.40,0.087
5.44,-33.25,0.087
5.47,-33.11,0.087
5.50,-32.97,0.087
5.53,-32.83,0.087
5.55,-32.68,0.087
5.58,-32.54,0.087
5.61,-32.40,0.087
5.64,-32.26,0.087
5.67,-32.12,0.088
5.70,-31.98,0.088
5.72,-31.83,0.088
5.75,-31.69,0.088
5.78,-31.55,0.088
5.81,-31.41,0.088
5.84,-31.27,0.088
5.86,-31.12,0.088
5.89,-30.98,0.088
5.92,-30.84,0.088
5.95,-30.70,0.088
5.98,-30.56,0.088
6.01,-30.42,0.088
6.04,-30.27,0.088
6.06,-30.13,0.088
6.09,-29.99,0.088
6.12,-29.85,0.088
6.15,-29.71,0.088
6.18,-29.56,0.088
6.20,-29.42,0.088
6.23,-29.28,0.088
6.26,-29.14,0.088
6.29,-29.00,0.088
6.32,-28.86,0.088
6.35,-28.71,0.088
6.38,-28.57,0.088
6.40,-28.43,0.088
6.43,-28.29,0.088
6.46,-28.15,0.088
6.49,-28.01,0.088
6.52,-27.86,0.088
6.55,-27.72,0.088
6.57,-27.58,0.088
6.60,-27.44,0.088
6.63,-27.30,0.088
6.66,-27.15,0.088
6.69,-27.01,0.088
6.71,-26.87,0.088
6.74,-26.73,0.088
6.77,-26.59,0.088
6.80,-26.44,0.088
6.83,-26.30,0.088
6.86,-26.16,0.088
6.89,-26.02,0.088
6.91,-25.88,0.088
6.94,-25.73,0.088
6.97,-25.59,0.088
7.00,-25.45,0.088
7.03,-25.31,0.088
7.05,-25.17,0.088
7.08,-25.03,0.088
7.11,-24.88,0.088
7.14,-24.74,0.089
7.17,-24.60,0.089
7.20,-24.46,0.089
7.23,-24.32,0.089
7.25,-24.18,0.089
7.28,-24.03,0.089
7.31,-23.89,0.089
7.34,-23.75,0.089
7.37,-23.61,0.089
7.40,-23.47,0.089
7.42,-23.32,0.089
7.45,-23.18,0.089
7.48,-23.04,0.089
7.51,-22.90,0.089
7.54,-22.76,0.089
7.56,-22.62,0.089
7.59,-22.47,0.089
7.62,-22.33,0.089
7.65,-22.19,0.089
7.68,-22.05,0.089
7.71,-21.91,0.089
7.74,-21.76,0.089
7.76,-21.62,0.089
7.79,-21.48,0.089
7.82,-21.34,0.089
7.85,-21.20,0.089
7.88,-21.06,0.089
7.90,-20.91,0.089
7.93,-20.77,0.089
7.96,-20.63,0.089
7.99,-20.49,0.089
8.02,-20.35,0.089
8.05,-20.21,0.089
8.08,-20.07,0.089
8.10,-19.92,0.089
8.13,-19.78,0.089
8.16,-19.64,0.089
8.19,-19.50,0.089
8.22,-19.35,0.089
8.25,-19.22,0.089
8.27,-19.07,0.089
8.30,-18.93,0.089
8.33,-18.79,0.090
8.36,-18.65,0.090
8.39,-18.51,0.090
8.41,-18.36,0.090
8.44,-18.22,0.090
8.47,-18.08,0.090
8.50,-17.94,0.090
8.53,-17.79,0.090
8.56,-17.65,0.090
8.58,-17.51,0.090
8.61,-17.37,0.090
8.64,-17.23,0.090
8.67,-17.09,0.090
8.70,-16.95,0.090
8.73,-16.80,0.090
8.75,-16.66,0.090
8.78,-16.52,0.090
8.81,-16.38,0.090
8.84,-16.24,0.090
8.87,-16.09,0.090
8.90,-15.95,0.090
8.93,-15.81,0.090
8.95,-15.67,0.090
8.98,-15.53,0.090
9.01,-15.38,0.090
9.04,-15.24,0.090
9.07,-15.10,0.090
9.10,-14.96,0.090
9.12,-14.82,0.090
9.15,-14.68,0.090
9.18,-14.53,0.090
9.21,-14.39,0.090
9.24,-14.25,0.090
9.27,-14.11,0.090
9.29,-13.97,0.090
9.32,-13.82,0.090
9.35,-13.68,0.091
9.38,-13.54,0.091
9.41,-13.40,0.091
9.43,-13.26,0.091
9.46,-13.12,0.091
9.49,-12.97,0.091
9.52,-12.83,0.091
9.55,-12.69,0.091
9.58,-12.55,0.091
9.60,-12.41,0.091
9.63,-12.26,0.091
9.66,-12.12,0.091
9.69,-11.98,0.091
9.72,-11.84,0.091
9.75,-11.70,0.091
9.78,-11.56,0.091
9.80,-11.41,0.091
9.83,-11.27,0.091
9.86,-11.13,0.091
9.89,-10.99,0.091
9.92,-10.85,0.091
9.95,-10.70,0.091
9.97,-10.56,0.091
10.00,-10.42,0.091
10.03,-10.28,0.091
10.06,-10.14,0.091
10.09,-10.00,0.091
10.12,-9.85,0.091
10.14,-9.71,0.091
10.17,-9.57,0.091
10.20,-9.43,0.091
10.23,-9.29,0.091
10.26,-9.14,0.092
10.28,-9.00,0.092
10.31,-8.86,0.092
10.34,-8.72,0.092
10.37,-8.58,0.092
10.40,-8.43,0.092
10.43,-8.29,0.092
10.45,-8.15,0.092
10.48,-8.01,0.092
10.51,-7.87,0.092
10.54,-7.73,0.092
10.57,-7.58,0.092
10.60,-7.44,0.092
10.63,-7.30,0.092
10.65,-7.16,0.092
10.68,-7.02,0.092
10.71,-6.88,0.092
10.74,-6.73,0.092
10.77,-6.59,0.092
10.80,-6.45,0.092
10.82,-6.31,0.092
10.85,-6.17,0.092
10.88,-6.03,0.092
10.91,-5.88,0.092
10.94,-5.74,0.092
10.97,-5.60,0.092
10.99,-5.46,0.092
11.02,-5.32,0.093
11.05,-5.17,0.093
11.08,-5.03,0.093
11.11,-4.89,0.093
11.13,-4.75,0.093
11.16,-4.61,0.093
11.19,-4.46,0.093
11.22,-4.32,0.093
11.25,-4.18,0.093
11.28,-4.04,0.093
11.30,-3.90,0.093
11.33,-3.75,0.093
11.36,-3.61,0.093
11.39,-3.47,0.093
11.42,-3.33,0.093
11.45,-3.19,0.093
11.48,-3.05,0.093
11.50,-2.91,0.093
11.53,-2.76,0.093
11.56,-2.62,0.093
11.59,-2.48,0.093
11.62,-2.34,0.093
11.65,-2.20,0.093
11.67,-2.05,0.093
11.70,-1.91,0.093
11.73,-1.77,0.093
11.76,-1.63,0.094
11.79,-1.49,0.094
11.82,-1.35,0.094
11.84,-1.20,0.094
11.87,-1.06,0.094
11.90,-0.92,0.094
11.93,-0.78,0.094
11.96,-0.64,0.094
11.98,-0.49,0.094
12.01,-0.35,0.094
12.04,-0.21,0.094
12.07,-0.07,0.094
12.10,0.07,0.094
12.13,0.21,0.094
12.15,0.36,0.094
12.18,0.50,0.094
12.21,0.64,0.094
12.24,0.78,0.094
12.27,0.92,0.095
12.30,1.07,0.095
12.33,1.21,0.095
12.35,1.35,0.095
12.38,1.49,0.095
12.41,1.63,0.095
12.44,1.77,0.095
12.47,1.92,0.095
12.50,2.06,0.095
12.52,2.20,0.095
12.55,2.34,0.095
12.58,2.48,0.095
12.61,2.63,0.095
12.64,2.77,0.095
12.67,2.91,0.095
12.69,3.05,0.095
12.72,3.19,0.095
12.75,3.33,0.095
12.78,3.48,0.095
12.81,3.62,0.095
12.83,3.76,0.095
12.86,3.90,0.096
12.89,4.04,0.096
12.92,4.18,0.096
12.95,4.33,0.096
12.98,4.47,0.096
13.00,4.61,0.096
13.03,4.75,0.096
13.06,4.89,0.096
13.09,5.04,0.096
13.12,5.18,0.096
13.15,5.32,0.096
13.18,5.46,0.096
13.20,5.60,0.096
13.23,5.74,0.096
13.26,5.89,0.096
13.29,6.03,0.096
13.32,6.17,0.096
13.35,6.31,0.096
13.37,6.45,0.097
13.40,6.59,0.097
13.43,6.74,0.097
13.46,6.88,0.097
13.49,7.02,0.097
13.52,7.16,0.097
13.54,7.30,0.097
13.57,7.44,0.097
13.60,7.58,0.097
13.63,7.73,0.097
13.66,7.87,0.097
13.68,8.01,0.097
13.71,8.15,0.097
13.74,8.30,0.097
13.77,8.44,0.097
13.80,8.58,0.097
13.83,8.72,0.098
13.85,8.86,0.098
13.88,9.01,0.098
13.91,9.15,0.098
13.94,9.29,0.098
13.97,9.43,0.098
14.00,9.57,0.098
14.03,9.71,0.098
14.05,9.86,0.098
14.08,10.00,0.098
14.11,10.14,0.098
14.14,10.28,0.098
14.17,10.42,0.098
14.20,10.57,0.099
14.22,10.71,0.099
14.25,10.85,0.099
14.28,10.99,0.099
14.31,11.13,0.099
14.34,11.28,0.099
14.37,11.42,0.099
14.39,11.56,0.099
14.42,11.70,0.099
14.45,11.84,0.099
14.48,11.98,0.099
14.51,12.12,0.099
14.53,12.27,0.099
14.56,12.41,0.099
14.59,12.55,0.099
14.62,12.69,0.099
14.65,12.83,0.099
14.68,12.97,0.100
14.70,13.12,0.100
14.73,13.26,0.100
14.76,13.40,0.100
14.79,13.54,0.100
14.82,13.68,0.100
14.85,13.82,0.100
14.88,13.97,0.100
14.90,14.11,0.100
14.93,14.25,0.100
14.96,14.39,0.100
14.99,14.54,0.100
15.02,14.68,0.101
15.05,14.82,0.101
15.07,14.96,0.101
15.10,15.10,0.101
15.13,15.24,0.101
15.16,15.38,0.101
15.19,15.53,0.101
15.22,15.67,0.101
15.24,15.81,0.101
15.27,15.95,0.101
15.30,16.09,0.101
15.33,16.23,0.101
15.36,16.38,0.101
15.38,16.52,0.101
15.41,16.66,0.102
15.44,16.80,0.102
15.47,16.94,0.102
15.50,17.09,0.102
15.53,17.23,0.102
15.55,17.37,0.102
15.58,17.51,0.102
15.61,17.65,0.102
15.64,17.79,0.102
15.67,17.94,0.102
15.70,18.08,0.102
15.73,18.22,0.103
15.75,18.36,0.103
15.78,18.50,0.103
15.81,18.64,0.103
15.84,18.78,0.103
15.87,18.93,0.103
15.90,19.07,0.103
15.92,19.21,0.103
15.95,19.35,0.103
15.98,19.49,0.103
16.01,19.64,0.104
16.04,19.78,0.104
16.07,19.92,0.104
16.09,20.06,0.104
16.12,20.21,0.104
16.15,20.35,0.104
16.18,20.49,0.104
16.21,20.63,0.104
16.23,20.77,0.104
16.26,20.92,0.104
16.29,21.06,0.105
16.32,21.20,0.105
16.35,21.34,0.105
16.38,21.48,0.105
16.40,21.62,0.105
16.43,21.76,0.105
16.46,21.90,0.105
16.49,22.04,0.105
16.52,22.19,0.105
16.55,22.33,0.105
16.58,22.47,0.105
16.60,22.61,0.106
16.63,22.75,0.106
16.66,22.90,0.106
16.69,23.04,0.106
16.72,23.18,0.106
16.75,23.32,0.106
16.77,23.47,0.106
16.80,23.61,0.106
16.83,23.75,0.107
16.86,23.89,0.107
16.89,24.03,0.107
16.92,24.17,0.107
16.94,24.32,0.107
16.97,24.46,0.107
17.00,24.60,0.107
17.03,24.74,0.107
17.06,24.88,0.107
17.08,25.02,0.107
17.11,25.16,0.107
17.14,25.31,0.108
17.17,25.45,0.108
17.20,25.59,0.108
17.23,25.73,0.108
17.26,25.87,0.108
17.28,26.02,0.108
17.31,26.16,0.108
17.34,26.30,0.108
17.37,26.44,0.109
17.40,26.58,0.109
17.43,26.72,0.109
17.45,26.87,0.109
17.48,27.01,0.109
17.51,27.15,0.109
17.54,27.29,0.109
17.57,27.43,0.109
17.59,27.58,0.110
17.62,27.72,0.110
17.65,27.86,0.110
17.68,28.00,0.110
17.71,28.14,0.110
17.74,28.28,0.110
17.77,28.42,0.110
17.79,28.57,0.110
17.82,28.71,0.111
17.85,28.85,0.111
17.88,28.99,0.111
17.91,29.13,0.111
17.93,29.28,0.111
17.96,29.42,0.111
17.99,29.56,0.111
18.02,29.70,0.111
18.05,29.84,0.112
18.08,29.99,0.112
18.11,30.13,0.112
18.13,30.27,0.112
18.16,30.41,0.112
18.19,30.55,0.112
18.22,30.69,0.112
18.25,30.83,0.112
18.28,30.98,0.113
18.30,31.12,0.113
18.33,31.26,0.113
18.36,31.40,0.113
18.39,31.54,0.113
18.42,31.69,0.113
18.44,31.83,0.113
18.47,31.97,0.113
18.50,32.11,0.114
18.53,32.25,0.114
18.56,32.39,0.114
18.59,32.54,0.114
18.62,32.68,0.114
18.64,32.82,0.114
18.67,32.96,0.115
18.70,33.10,0.115
18.73,33.25,0.115
18.76,33.39,0.115
18.78,33.53,0.115
18.81,33.67,0.115
18.84,33.81,0.115
18.87,33.95,0.116
18.90,34.09,0.116
18.93,34.24,0.116
18.96,34.38,0.116
18.98,34.52,0.116
19.01,34.66,0.116
19.04,34.80,0.116
19.07,34.95,0.117
19.10,35.09,0.117
19.13,35.23,0.117
19.15,35.37,0.117
19.18,35.51,0.117
19.21,35.65,0.117
19.24,35.80,0.118
19.27,35.94,0.118
19.29,36.08,0.118
19.32,36.22,0.118
19.35,36.36,0.118
19.38,36.50,0.118
19.41,36.65,0.118
19.44,36.79,0.119
19.47,36.93,0.119
19.49,37.07,0.119
19.52,37.21,0.119
19.55,37.35,0.119
19.58,37.50,0.120
19.61,37.64,0.120
19.63,37.78,0.120
19.66,37.92,0.120
19.69,38.06,0.120
19.72,38.21,0.120
19.75,38.35,0.121
19.78,38.49,0.121
19.81,38.63,0.121
19.83,38.77,0.121
19.86,38.91,0.121
19.89,39.06,0.122
19.92,39.20,0.122
19.95,39.34,0.122
19.98,39.48,0.122
20.00,39.62,0.122
20.03,39.76,0.122
20.06,39.91,0.123
20.09,40.05,0.123
20.12,40.19,0.123
20.14,40.33,0.123
20.17,40.47,0.123
20.20,40.61,0.124
20.23,40.76,0.124
20.26,40.90,0.124
20.29,41.04,0.124
20.32,41.18,0.124
20.34,41.32,0.125
20.37,41.46,0.125
20.40,41.61,0.125
20.43,41.75,0.125
20.46,41.89,0.125
20.48,42.03,0.126
20.51,42.17,0.126
20.54,42.31,0.126
20.57,42.46,0.126
20.60,42.60,0.127
20.63,42.74,0.127
20.66,42.88,0.127
20.68,43.02,0.127
20.71,43.16,0.128
20.74,43.31,0.128
20.77,43.45,0.128
20.80,43.59,0.128
20.83,43.73,0.128
20.85,43.87,0.129
20.88,44.01,0.129
20.91,44.16,0.129
20.94,44.30,0.129
20.97,44.44,0.129
20.99,44.58,0.130
21.02,44.72,0.130
21.05,44.86,0.130
21.08,45.00,0.130
21.11,45.15,0.131
21.14,45.29,0.131
21.17,45.43,0.131
21.19,45.57,0.132
21.22,45.71,0.132
21.25,45.86,0.132
21.28,46.00,0.132
21.31,46.14,0.133
21.33,46.28,0.133
21.36,46.42,0.133
21.39,46.56,0.133
21.42,46.71,0.134
21.45,46.85,0.134
21.48,46.99,0.134
21.51,47.13,0.135
21.53,47.27,0.135
21.56,47.41,0.135
21.59,47.56,0.135
21.62,47.70,0.136
21.65,47.84,0.136
21.68,47.98,0.136
21.70,48.13,0.137
21.73,48.27,0.137
21.76,48.41,0.137
21.79,48.55,0.138
21.82,48.69,0.138
21.84,48.83,0.138
21.87,48.97,0.139
21.90,49.11,0.139
21.93,49.26,0.139
21.96,49.40,0.140
21.99,49.54,0.140
22.02,49.68,0.140
22.04,49.82,0.141
22.07,49.97,0.141
22.10,50.11,0.141
22.13,50.25,0.142
22.16,50.39,0.142
22.18,50.53,0.142
22.21,50.67,0.143
22.24,50.81,0.143
22.27,50.96,0.144
22.30,51.10,0.144
22.33,51.24,0.145
22.36,51.38,0.145
22.38,51.52,0.145
22.41,51.67,0.146
22.44,51.81,0.146
22.47,51.95,0.147
22.50,52.09,0.147
22.53,52.23,0.148
22.55,52.37,0.148
22.58,52.52,0.149
22.61,52.66,0.149
22.64,52.80,0.150
22.67,52.94,0.150
22.69,53.08,0.151
22.72,53.22,0.151
22.75,53.37,0.151
22.78,53.51,0.152
22.81,53.65,0.152
22.84,53.79,0.153
22.87,53.93,0.154
22.89,54.07,0.154
22.92,54.21,0.155
22.95,54.36,0.155
22.98,54.50,0.156
23.01,54.64,0.156
23.03,54.78,0.157
23.06,54.92,0.158
23.09,55.06,0.158
23.12,55.21,0.159
23.15,55.35,0.159
23.18,55.49,0.160
23.21,55.63,0.161
23.23,55.77,0.161
23.26,55.91,0.162
23.29,56.06,0.162
23.32,56.20,0.163
23.35,56.34,0.164
23.38,56.48,0.164
23.40,56.62,0.165
23.43,56.76,0.165
23.46,56.90,0.166
23.49,57.04,0.167
23.52,57.19,0.167
23.54,57.33,0.168
23.57,57.47,0.168
23.60,57.61,0.169
23.63,57.75,0.169
23.66,57.90,0.170
23.69,58.04,0.171
23.72,58.18,0.171
23.74,58.32,0.172
23.77,58.46,0.172
23.80,58.60,0.173
23.83,58.75,0.173
23.86,58.89,0.174
23.88,59.03,0.175
23.91,59.17,0.175
23.94,59.31,0.176
23.97,59.45,0.176
24.00,59.60,0.176
24.03,59.74,0.177
24.06,59.88,0.177
24.08,60.02,0.178
24.11,60.16,0.178
24.14,60.30,0.179
24.17,60.45,0.179
24.20,60.59,0.180
24.23,60.73,0.180
24.25,60.87,0.180
24.28,61.01,0.181
24.31,61.15,0.181
24.34,61.30,0.182
24.37,61.44,0.182
24.39,61.58,0.182
24.42,61.72,0.183
24.45,61.86,0.183
24.48,62.00,0.183
24.51,62.15,0.184
24.54,62.29,0.184
24.57,62.43,0.184
24.59,62.57,0.185
24.62,62.71,0.185
24.65,62.86,0.185
24.68,63.00,0.186
24.71,63.14,0.186
24.73,63.28,0.186
24.76,63.42,0.187
24.79,63.56,0.187
24.82,63.70,0.187
24.85,63.85,0.187
24.88,63.99,0.188
24.91,64.13,0.188
24.93,64.27,0.188
24.96,64.41,0.189
24.99,64.55,0.189
25.02,64.70,0.189
25.05,64.84,0.189
25.08,64.98,0.190
25.10,65.12,0.190
25.13,65.26,0.190
25.16,65.40,0.191
25.19,65.54,0.191
25.22,65.69,0.191
25.24,65.83,0.192
25.27,65.97,0.192
25.30,66.11,0.192
25.33,66.25,0.193
25.36,66.40,0.193
25.39,66.54,0.193
25.42,66.68,0.193
25.44,66.82,0.194
25.47,66.96,0.194
25.50,67.10,0.194
25.53,67.25,0.195
25.56,67.39,0.195
25.58,67.53,0.195
25.61,67.67,0.195
25.64,67.81,0.196
25.67,67.95,0.196
25.70,68.10,0.196
25.73,68.24,0.196
25.76,68.38,0.197
25.78,68.52,0.197
25.81,68.66,0.197
25.84,68.81,0.197
25.87,68.95,0.197
25.90,69.09,0.198
25.93,69.23,0.198
25.95,69.37,0.198
25.98,69.51,0.198
26.01,69.66,0.199
26.04,69.80,0.199
26.07,69.94,0.199
26.09,70.08,0.199
26.12,70.22,0.199
26.15,70.36,0.199
26.18,70.50,0.199
26.21,70.65,0.200
26.24,70.79,0.200
26.27,70.93,0.200
26.29,71.07,0.200
26.32,71.21,0.200
26.35,71.35,0.200
26.38,71.50,0.200
26.41,71.64,0.200
26.43,71.78,0.200
26.46,71.92,0.200
26.49,72.06,0.200
26.52,72.21,0.200
26.55,72.35,0.201
26.58,72.49,0.201
26.61,72.63,0.201
26.63,72.77,0.201
26.66,72.92,0.201
26.69,73.06,0.201
26.72,73.20,0.201
26.75,73.34,0.201
26.78,73.48,0.201
26.80,73.62,0.201
26.83,73.77,0.201
26.86,73.91,0.201
26.89,74.05,0.200
26.92,74.19,0.200
26.94,74.33,0.200
26.97,74.47,0.200
27.00,74.62,0.200
27.03,74.76,0.200
27.06,74.90,0.200
27.09,75.04,0.200
27.12,75.18,0.200
27.14,75.33,0.199
27.17,75.47,0.199
27.20,75.61,0.199
27.23,75.75,0.199
27.26,75.89,0.199
27.28,76.03,0.199
27.31,76.18,0.198
27.34,76.32,0.198
27.37,76.46,0.198
27.40,76.60,0.198
27.43,76.75,0.198
27.46,76.89,0.197
27.48,77.03,0.197
27.51,77.17,0.197
27.54,77.31,0.197
27.57,77.45,0.197
27.60,77.60,0.196
27.63,77.74,0.196
27.65,77.88,0.196
27.68,78.02,0.196
27.71,78.16,0.195
27.74,78.31,0.195
27.77,78.45,0.195
27.79,78.59,0.195
27.82,78.73,0.194
27.85,78.87,0.194
27.88,79.01,0.194
27.91,79.16,0.193
27.94,79.30,0.193
27.97,79.44,0.193
27.99,79.58,0.193
28.02,79.72,0.192
28.05,79.87,0.192
28.08,80.01,0.192
28.11,80.15,0.191
28.13,80.29,0.191
28.16,80.43,0.191
28.19,80.58,0.190
28.22,80.72,0.190
28.25,80.86,0.190
28.28,81.00,0.189
28.31,81.14,0.189
28.33,81.28,0.189
28.36,81.43,0.188
28.39,81.57,0.188
28.42,81.71,0.188
28.45,81.85,0.187
28.48,81.99,0.187
28.50,82.13,0.187
28.53,82.28,0.187
28.56,82.42,0.186
28.59,82.56,0.186
28.62,82.70,0.186
28.64,82.84,0.185
28.67,82.99,0.185
28.70,83.13,0.185
28.73,83.27,0.184
28.76,83.41,0.184
28.79,83.55,0.184
28.82,83.70,0.183
28.84,83.84,0.183
28.87,83.98,0.183
28.90,84.12,0.182
28.93,84.26,0.182
28.96,84.40,0.182
28.98,84.55,0.182
29.01,84.69,0.181
29.04,84.83,0.181
29.07,84.97,0.181
29.10,85.12,0.180
29.13,85.26,0.180
29.16,85.40,0.180
29.18,85.54,0.180
29.21,85.68,0.179
29.24,85.82,0.179
29.27,85.97,0.179
29.30,86.11,0.178
29.33,86.25,0.178
29.35,86.39,0.178
29.38,86.53,0.178
29.41,86.68,0.177
29.44,86.82,0.177
29.47,86.96,0.177
29.49,87.10,0.177
29.52,87.24,0.176
29.55,87.39,0.176
29.58,87.53,0.176
29.61,87.67,0.175
29.64,87.81,0.175
29.67,87.95,0.175
29.69,88.09,0.175
29.72,88.24,0.174
29.75,88.38,0.174
29.78,88.52,0.174
29.81,88.66,0.174
29.83,88.80,0.173
29.86,88.94,0.173
29.89,89.09,0.173
29.92,89.23,0.173
29.95,89.37,0.172
29.98,89.51,0.172
30.01,89.65,0.172
30.03,89.80,0.172
30.06,89.94,0.171
30.09,90.08,0.171
30.12,90.22,0.171
30.15,90.36,0.171
30.18,90.51,0.170
30.20,90.65,0.170
30.23,90.79,0.170
30.26,90.93,0.170
30.29,91.07,0.170
30.32,91.21,0.169
30.34,91.35,0.169
30.37,91.50,0.169
30.40,91.64,0.169
30.43,91.78,0.168
30.46,91.92,0.168
30.49,92.06,0.168
30.52,92.21,0.168
30.54,92.35,0.168
30.57,92.49,0.167
30.60,92.63,0.167
30.63,92.78,0.167
30.66,92.92,0.167
30.68,93.06,0.167
30.71,93.20,0.166
30.74,93.34,0.166
30.77,93.48,0.166
30.80,93.63,0.166
30.83,93.77,0.166
30.86,93.91,0.165
30.88,94.05,0.165
30.91,94.19,0.165
30.94,94.33,0.165
30.97,94.48,0.165
31.00,94.62,0.164
31.03,94.76,0.164
31.05,94.90,0.164
31.08,95.04,0.164
31.11,95.19,0.164
31.14,95.33,0.163
31.17,95.47,0.163
31.19,95.61,0.163
31.22,95.75,0.163
31.25,95.90,0.163
31.28,96.04,0.162
31.31,96.18,0.162
31.34,96.32,0.162
31.37,96.46,0.162
31.39,96.60,0.162
31.42,96.74,0.161
31.45,96.89,0.161
31.48,97.03,0.161
31.51,97.17,0.161
31.53,97.31,0.161
31.56,97.45,0.161
31.59,97.60,0.160
31.62,97.74,0.160
31.65,97.88,0.160
31.68,98.02,0.160
31.71,98.16,0.160
31.73,98.31,0.160
31.76,98.45,0.159
31.79,98.59,0.159
31.82,98.73,0.159
31.85,98.87,0.159
31.88,99.01,0.159
31.90,99.16,0.159
31.93,99.30,0.158
31.96,99.44,0.158
31.99,99.58,0.158
32.02,99.72,0.158
32.04,99.87,0.158
32.07,100.01,0.158
32.10,100.15,0.158
32.13,100.29,0.157
32.16,100.43,0.157
32.19,100.57,0.157
32.22,100.72,0.157
32.24,100.86,0.157
32.27,101.00,0.157
32.30,101.14,0.157
32.33,101.28,0.157
32.36,101.43,0.156
32.38,101.57,0.156
32.41,101.71,0.156
32.44,101.85,0.156
32.47,101.99,0.156
32.50,102.14,0.156
32.53,102.28,0.156
32.56,102.42,0.156
32.58,102.56,0.155
32.61,102.70,0.155
32.64,102.85,0.155
32.67,102.99,0.155
32.70,103.13,0.155
32.73,103.27,0.155
32.75,103.41,0.155
32.78,103.55,0.154
32.81,103.70,0.154
32.84,103.84,0.154
32.87,103.98,0.154
32.89,104.12,0.154
32.92,104.26,0.154
32.95,104.41,0.154
32.98,104.55,0.153
33.01,104.69,0.153
33.04,104.83,0.153
33.07,104.97,0.153
33.09,105.11,0.153
33.12,105.26,0.153
33.15,105.40,0.153
33.18,105.54,0.153
33.21,105.68,0.153
33.23,105.82,0.152
33.26,105.97,0.152
33.29,106.11,0.152
33.32,106.25,0.152
33.35,106.39,0.152
33.38,106.53,0.152
33.41,106.67,0.152
33.43,106.81,0.152
33.46,106.96,0.151
33.49,107.10,0.151
33.52,107.24,0.151
33.55,107.38,0.151
33.58,107.53,0.151
33.60,107.67,0.151
33.63,107.81,0.151
33.66,107.95,0.151
33.69,108.09,0.151
33.72,108.23,0.151
33.74,108.38,0.151
33.77,108.52,0.150
33.80,108.66,0.150
33.83,108.80,0.150
33.86,108.94,0.150
33.89,109.08,0.150
33.92,109.22,0.150
33.94,109.37,0.150
33.97,109.51,0.150
34.00,109.65,0.150
34.03,109.79,0.150
34.06,109.93,0.150
34.08,110.08,0.150
34.11,110.22,0.149
34.14,110.36,0.149
34.17,110.50,0.149
34.20,110.64,0.149
34.23,110.78,0.149
34.26,110.93,0.149
34.28,111.07,0.149
34.31,111.21,0.149
34.34,111.35,0.149
34.37,111.49,0.149
34.40,111.63,0.149
34.43,111.78,0.149
34.45,111.92,0.148
34.48,112.06,0.148
34.51,112.20,0.148
34.54,112.34,0.148
34.57,112.49,0.148
34.59,112.63,0.148
34.62,112.77,0.148
34.65,112.91,0.148
34.68,113.05,0.148
34.71,113.19,0.148
34.74,113.34,0.148
34.76,113.48,0.148
34.79,113.62,0.148
34.82,113.76,0.148
34.85,113.90,0.148
34.88,114.05,0.147
34.91,114.19,0.147
34.94,114.33,0.147
34.96,114.47,0.147
34.99,114.61,0.147
35.02,114.75,0.147
35.05,114.90,0.147
35.08,115.04,0.147
35.11,115.18,0.147
35.13,115.32,0.147
35.16,115.46,0.147
35.19,115.60,0.147
35.22,115.74,0.147
35.25,115.89,0.147
35.28,116.03,0.147
35.30,116.17,0.147
35.33,116.31,0.147
35.36,116.45,0.147
35.39,116.60,0.147
35.42,116.74,0.147
35.44,116.88,0.147
35.47,117.02,0.147
35.50,117.16,0.147
35.53,117.31,0.147
35.56,117.45,0.147
35.59,117.59,0.147
35.61,117.73,0.147
35.64,117.87,0.147
35.67,118.01,0.147
35.70,118.16,0.147
35.73,118.30,0.147
35.76,118.44,0.147
35.79,118.58,0.147
35.81,118.72,0.147
35.84,118.86,0.147
35.87,119.01,0.147
35.90,119.15,0.148
35.93,119.29,0.148
35.96,119.43,0.148
35.98,119.57,0.148
36.01,119.71,0.148
36.04,119.86,0.148
36.07,120.00,0.148
36.10,120.14,0.148
36.13,120.28,0.148
36.15,120.42,0.148
36.18,120.56,0.148
36.21,120.71,0.148
36.24,120.85,0.148
36.27,120.99,0.148
36.29,121.13,0.148
36.32,121.27,0.148
36.35,121.42,0.148
36.38,121.56,0.148
36.41,121.70,0.149
36.44,121.84,0.149
36.46,121.98,0.149
36.49,122.12,0.149
36.52,122.27,0.149
36.55,122.41,0.149
36.58,122.55,0.149
36.61,122.69,0.149
36.64,122.83,0.149
36.66,122.97,0.149
36.69,123.12,0.149
36.72,123.26,0.149
36.75,123.40,0.149
36.78,123.54,0.149
36.81,123.68,0.150
36.83,123.83,0.150
36.86,123.97,0.150
36.89,124.11,0.150
36.92,124.25,0.150
36.95,124.39,0.150
36.98,124.53,0.150
37.00,124.68,0.150
37.03,124.82,0.150
37.06,124.96,0.150
37.09,125.10,0.150
37.12,125.24,0.150
37.14,125.38,0.150
37.17,125.53,0.150
37.20,125.67,0.150
37.23,125.81,0.150
37.26,125.95,0.150
37.29,126.09,0.151
37.31,126.23,0.151
37.34,126.38,0.151
37.37,126.52,0.151
37.40,126.66,0.151
37.43,126.80,0.151
37.46,126.94,0.151
37.49,127.09,0.151
37.51,127.23,0.151
37.54,127.37,0.151
37.57,127.51,0.151
37.60,127.65,0.151
37.63,127.79,0.151
37.66,127.94,0.151
37.68,128.08,0.151
37.71,128.22,0.151
37.74,128.36,0.151
37.77,128.50,0.151
37.80,128.64,0.151
37.83,128.79,0.151
37.85,128.93,0.151
37.88,129.07,0.151
37.91,129.21,0.151
37.94,129.35,0.151
37.97,129.49,0.151
37.99,129.64,0.151
38.02,129.78,0.151
38.05,129.92,0.151
38.08,130.06,0.151
38.11,130.20,0.152
38.14,130.35,0.152
38.16,130.49,0.152
38.19,130.63,0.152
38.22,130.77,0.152
38.25,130.91,0.152
38.28,131.05,0.152
38.31,131.20,0.152
38.34,131.34,0.152
38.36,131.48,0.152
38.39,131.62,0.152
38.42,131.76,0.152
38.45,131.91,0.152
38.48,132.05,0.152
38.51,132.19,0.152
38.53,132.33,0.152
38.56,132.47,0.151
38.59,132.61,0.151
38.62,132.75,0.151
38.65,132.90,0.151
38.68,133.04,0.151
38.70,133.18,0.151
38.73,133.32,0.151
38.76,133.46,0.151
38.79,133.61,0.151
38.82,133.75,0.151
38.84,133.89,0.151
38.87,134.03,0.151
38.90,134.17,0.151
38.93,134.32,0.151
38.96,134.46,0.151
38.99,134.60,0.151
39.01,134.74,0.151
39.04,134.88,0.151
39.07,135.02,0.151
39.10,135.17,0.151
39.13,135.31,0.151
39.16,135.45,0.151
39.19,135.59,0.151
39.21,135.73,0.151
39.24,135.87,0.151
39.27,136.02,0.151
39.30,136.16,0.151
39.33,136.30,0.151
39.36,136.44,0.151
39.38,136.58,0.150
39.41,136.72,0.151
39.44,136.87,0.150
39.47,137.01,0.150
39.50,137.15,0.150
39.53,137.29,0.150
39.55,137.43,0.150
39.58,137.58,0.150
39.61,137.72,0.150
39.64,137.86,0.150
39.67,138.00,0.150
39.69,138.14,0.150
39.72,138.28,0.150
39.75,138.43,0.150
39.78,138.57,0.150
39.81,138.71,0.150
39.84,138.85,0.150
39.86,138.99,0.150
39.89,139.13,0.150
39.92,139.28,0.150
39.95,139.42,0.150
39.98,139.56,0.150
40.01,139.70,0.150
40.04,139.84,0.150
40.06,139.98,0.150
40.09,140.13,0.150
40.12,140.27,0.150
40.15,140.41,0.150
40.18,140.55,0.150
40.21,140.69,0.150
40.23,140.84,0.150
40.26,140.98,0.150
40.29,141.12,0.150
40.32,141.26,0.150
40.35,141.40,0.150
40.38,141.55,0.150
40.40,141.69,0.150
40.43,141.83,0.150
40.46,141.97,0.150
40.49,142.11,0.150
40.52,142.25,0.150
40.54,142.39,0.150
40.57,142.54,0.150
40.60,142.68,0.150
40.63,142.82,0.150
40.66,142.96,0.150
40.69,143.10,0.150
40.71,143.24,0.150
40.74,143.39,0.150
40.77,143.53,0.150
40.80,143.67,0.150
40.83,143.81,0.150
40.86,143.95,0.151
40.89,144.10,0.151
40.91,144.24,0.151
40.94,144.38,0.151
40.97,144.52,0.151
41.00,144.66,0.151
41.03,144.80,0.151
41.06,144.95,0.151
41.08,145.09,0.151
41.11,145.23,0.151
41.14,145.37,0.151
41.17,145.51,0.151
41.20,145.65,0.152
41.23,145.80,0.152
41.25,145.94,0.152
41.28,146.08,0.152
41.31,146.22,0.152
41.34,146.36,0.152
41.37,146.50,0.153
41.39,146.64,0.153
41.42,146.79,0.153
41.45,146.93,0.153
41.48,147.07,0.153
41.51,147.21,0.154
41.54,147.35,0.154
41.56,147.49,0.154
41.59,147.64,0.154
41.62,147.78,0.155
41.65,147.92,0.155
41.68,148.06,0.155
41.71,148.20,0.156
41.74,148.35,0.156
41.76,148.49,0.156
41.79,148.63,0.156
41.82,148.77,0.157
41.85,148.91,0.157
41.88,149.05,0.157
41.91,149.19,0.158
41.93,149.34,
41.96,149.48,
41.99,,

[step]
Ramp 5.00 °C/min to -60.00 °C
Time,Temperature,Heat Flow (Normalized)
min,°C,W/g
42.99,150.16,-0.041
43.01,150.16,-0.041
43.04,150.15,-0.041
43.07,150.12,-0.043
43.10,150.05,-0.072
43.13,149.96,-0.111
43.16,149.86,-0.149
43.19,149.74,-0.179
43.21,149.61,-0.200
43.24,149.48,-0.211
43.27,149.35,-0.220
43.30,149.22,-0.225
43.33,149.08,-0.229
43.36,148.94,-0.232
43.38,148.80,-0.234
43.41,148.66,-0.235
43.44,148.52,-0.235
43.47,148.38,-0.236
43.50,148.24,-0.237
43.53,148.11,-0.237
43.55,147.96,-0.237
43.58,147.82,-0.238
43.61,147.68,-0.238
43.64,147.54,-0.238
43.67,147.40,-0.239
43.69,147.26,-0.239
43.72,147.12,-0.239
43.75,146.98,-0.239
43.78,146.84,-0.239
43.81,146.70,-0.240
43.84,146.56,-0.240
43.86,146.41,-0.240
43.89,146.27,-0.240
43.92,146.13,-0.240
43.95,145.99,-0.240
43.98,145.85,-0.240
44.01,145.71,-0.240
44.04,145.57,-0.240
44.06,145.43,-0.240
44.09,145.28,-0.240
44.12,145.14,-0.240
44.15,145.00,-0.240
44.18,144.86,-0.240
44.21,144.72,-0.240
44.23,144.58,-0.240
44.26,144.44,-0.240
44.29,144.29,-0.240
44.32,144.15,-0.240
44.35,144.01,-0.240
44.38,143.87,-0.240
44.40,143.73,-0.240
44.43,143.59,-0.240
44.46,143.45,-0.240
44.49,143.30,-0.240
44.52,143.16,-0.240
44.54,143.02,-0.240
44.57,142.88,-0.240
44.60,142.74,-0.240
44.63,142.60,-0.239
44.66,142.45,-0.239
44.69,142.31,-0.239
44.71,142.17,-0.239
44.74,142.03,-0.239
44.77,141.89,-0.239
44.80,141.75,-0.239
44.83,141.61,-0.239
44.86,141.46,-0.239
44.89,141.32,-0.239
44.91,141.18,-0.239
44.94,141.04,-0.239
44.97,140.90,-0.239
45.00,140.76,-0.238
45.03,140.61,-0.238
45.06,140.47,-0.238
45.08,140.33,-0.238
45.11,140.19,-0.238
45.14,140.05,-0.238
45.17,139.91,-0.238
45.20,139.76,-0.238
45.23,139.62,-0.238
45.25,139.48,-0.238
45.28,139.34,-0.238
45.31,139.20,-0.238
45.34,139.06,-0.238
45.37,138.91,-0.238
45.39,138.77,-0.238
45.42,138.63,-0.237
45.45,138.49,-0.237
45.48,138.35,-0.237
45.51,138.21,-0.237
45.54,138.06,-0.237
45.56,137.92,-0.237
45.59,137.78,-0.237
45.62,137.64,-0.237
45.65,137.50,-0.237
45.68,137.36,-0.237
45.71,137.21,-0.237
45.74,137.07,-0.237
45.76,136.93,-0.237
45.79,136.79,-0.236
45.82,136.65,-0.236
45.85,136.51,-0.236
45.88,136.36,-0.236
45.91,136.22,-0.236
45.93,136.08,-0.236
45.96,135.94,-0.236
45.99,135.80,-0.236
46.02,135.66,-0.236
46.05,135.51,-0.236
46.08,135.37,-0.236
46.10,135.23,-0.236
46.13,135.09,-0.236
46.16,134.95,-0.236
46.19,134.81,-0.236
46.22,134.66,-0.236
46.24,134.52,-0.236
46.27,134.38,-0.236
46.30,134.24,-0.235
46.33,134.10,-0.235
46.36,133.96,-0.235
46.39,133.82,-0.235
46.41,133.67,-0.235
46.44,133.53,-0.235
46.47,133.39,-0.235
46.50,133.25,-0.235
46.53,133.11,-0.235
46.56,132.96,-0.235
46.59,132.82,-0.235
46.61,132.68,-0.235
46.64,132.54,-0.235
46.67,132.40,-0.235
46.70,132.26,-0.235
46.73,132.11,-0.235
46.76,131.97,-0.235
46.78,131.83,-0.235
46.81,131.69,-0.235
46.84,131.55,-0.235
46.87,131.40,-0.234
46.90,131.26,-0.234
46.93,131.12,-0.234
46.95,130.98,-0.234
46.98,130.84,-0.234
47.01,130.70,-0.234
47.04,130.56,-0.234
47.07,130.41,-0.234
47.09,130.27,-0.234
47.12,130.13,-0.234
47.15,129.99,-0.234
47.18,129.85,-0.234
47.21,129.71,-0.234
47.24,129.56,-0.234
47.26,129.42,-0.234
47.29,129.28,-0.234
47.32,129.14,-0.234
47.35,129.00,-0.234
47.38,128.86,-0.233
47.41,128.71,-0.233
47.44,128.57,-0.233
47.46,128.43,-0.233
47.49,128.29,-0.233
47.52,128.15,-0.233
47.55,128.01,-0.233
47.58,127.86,-0.233
47.61,127.72,-0.233
47.63,127.58,-0.233
47.66,127.44,-0.233
47.69,127.30,-0.233
47.72,127.16,-0.233
47.75,127.01,-0.233
47.78,126.87,-0.233
47.80,126.73,-0.233
47.83,126.59,-0.233
47.86,126.45,-0.233
47.89,126.31,-0.233
47.92,126.16,-0.233
47.94,126.02,-0.233
47.97,125.88,-0.232
48.00,125.74,-0.232
48.03,125.60,-0.232
48.06,125.46,-0.232
48.09,125.31,-0.232
48.11,125.17,-0.232
48.14,125.03,-0.232
48.17,124.89,-0.232
48.20,124.75,-0.232
48.23,124.61,-0.232
48.26,124.46,-0.232
48.29,124.32,-0.232
48.31,124.18,-0.232
48.34,124.04,-0.232
48.37,123.90,-0.232
48.40,123.76,-0.232
48.43,123.61,-0.232
48.46,123.47,-0.232
48.48,123.33,-0.232
48.51,123.19,-0.232
48.54,123.05,-0.232
48.57,122.91,-0.232
48.60,122.76,-0.232
48.63,122.62,-0.231
48.65,122.48,-0.231
48.68,122.34,-0.231
48.71,122.20,-0.231
48.74,122.06,-0.231
48.77,121.92,-0.231
48.79,121.77,-0.231
48.82,121.63,-0.231
48.85,121.49,-0.231
48.88,121.35,-0.231
48.91,121.20,-0.231
48.94,121.06,-0.231
48.96,120.92,-0.231
48.99,120.78,-0.231
49.02,120.64,-0.231
49.05,120.50,-0.231
49.08,120.35,-0.231
49.11,120.21,-0.231
49.14,120.07,-0.231
49.16,119.93,-0.231
49.19,119.79,-0.231
49.22,119.65,-0.231
49.25,119.50,-0.231
49.28,119.36,-0.231
49.31,119.22,-0.230
49.33,119.08,-0.230
49.36,118.94,-0.230
49.39,118.80,-0.230
49.42,118.66,-0.230
49.45,118.52,-0.230
49.48,118.37,-0.230
49.50,118.23,-0.230
49.53,118.09,-0.230
49.56,117.95,-0.230
49.59,117.81,-0.230
49.62,117.66,-0.230
49.64,117.52,-0.230
49.67,117.38,-0.230
49.70,117.24,-0.230
49.73,117.10,-0.230
49.76,116.96,-0.230
49.79,116.82,-0.230
49.81,116.67,-0.230
49.84,116.53,-0.229
49.87,116.39,-0.229
49.90,116.25,-0.229
49.93,116.11,-0.229
49.96,115.96,-0.229
49.99,115.82,-0.229
50.01,115.68,-0.229
50.04,115.54,-0.229
50.07,115.40,-0.229
50.10,115.25,-0.229
50.13,115.11,-0.229
50.16,114.97,-0.229
50.18,114.83,-0.229
50.21,114.69,-0.229
50.24,114.55,-0.229
50.27,114.41,-0.229
50.30,114.27,-0.229
50.33,114.12,-0.229
50.35,113.98,-0.229
50.38,113.84,-0.229
50.41,113.70,-0.229
50.44,113.56,-0.229
50.47,113.41,-0.229
50.49,113.27,-0.229
50.52,113.13,-0.229
50.55,112.99,-0.229
50.58,112.85,-0.228
50.61,112.71,-0.228
50.64,112.56,-0.228
50.66,112.42,-0.228
50.69,112.28,-0.228
50.72,112.14,-0.228
50.75,112.00,-0.228
50.78,111.85,-0.228
50.81,111.71,-0.228
50.84,111.57,-0.228
50.86,111.43,-0.228
50.89,111.29,-0.228
50.92,111.15,-0.228
50.95,111.00,-0.228
50.98,110.86,-0.228
51.01,110.72,-0.228
51.03,110.58,-0.228
51.06,110.44,-0.228
51.09,110.30,-0.228
51.12,110.16,-0.228
51.15,110.01,-0.227
51.18,109.87,-0.227
51.20,109.73,-0.227
51.23,109.59,-0.227
51.26,109.45,-0.227
51.29,109.30,-0.227
51.32,109.16,-0.227
51.34,109.02,-0.227
51.37,108.88,-0.227
51.40,108.74,-0.227
51.43,108.60,-0.227
51.46,108.46,-0.227
51.49,108.31,-0.227
51.51,108.17,-0.227
51.54,108.03,-0.227
51.57,107.89,-0.227
51.60,107.75,-0.227
51.63,107.61,-0.227
51.66,107.46,-0.227
51.69,107.32,-0.226
51.71,107.18,-0.226
51.74,107.04,-0.226
51.77,106.90,-0.226
51.80,106.76,-0.226
51.83,106.61,-0.226
51.86,106.47,-0.226
51.88,106.33,-0.226
51.91,106.19,-0.226
51.94,106.05,-0.226
51.97,105.91,-0.226
52.00,105.76,-0.226
52.03,105.62,-0.226
52.05,105.48,-0.226
52.08,105.34,-0.226
52.11,105.20,-0.226
52.14,105.06,-0.226
52.17,104.91,-0.226
52.19,104.77,-0.226
52.22,104.63,-0.226
[...]
191.73,38.23,0.083,0.889
191.76,38.38,0.083,0.889
191.79,38.52,0.083,0.889
191.82,38.66,0.083,0.890
191.85,38.80,0.083,0.889
191.88,38.94,0.083,0.890
191.90,39.08,0.083,0.891
191.93,39.23,0.083,0.891
191.96,39.37,0.083,0.892
191.99,39.51,0.083,0.892
192.02,39.65,0.083,0.892
192.05,39.79,0.084,0.892
192.08,39.93,0.084,0.893
192.10,40.08,0.084,0.893
192.13,40.22,0.084,0.894
192.16,40.36,0.084,0.894
192.19,40.50,0.084,0.894
192.22,40.64,0.084,0.895
192.25,40.79,0.084,0.895
192.27,40.93,0.084,0.895
192.30,41.07,0.084,0.896
192.33,41.21,0.084,0.896
192.36,41.35,0.084,0.896
192.39,41.49,0.084,0.896
192.42,41.64,0.084,0.897
192.44,41.78,0.084,0.897
192.47,41.92,0.084,0.898
192.50,42.06,0.084,0.898
192.53,42.20,0.084,0.898
192.56,42.35,0.084,0.899
192.58,42.49,0.084,0.900
192.61,42.63,0.084,0.900
192.64,42.77,0.084,0.900
192.67,42.91,0.085,0.901
192.70,43.05,0.085,0.902
192.73,43.20,0.085,0.902
192.75,43.34,0.085,0.902
192.78,43.48,0.085,0.902
192.81,43.62,0.085,0.903
192.84,43.76,0.085,0.903
192.87,43.90,0.085,0.904
192.90,44.05,0.085,0.904
192.93,44.19,0.085,0.904
192.95,44.33,0.085,0.905
192.98,44.47,0.085,0.904
193.01,44.61,0.085,0.905
193.04,44.75,0.085,0.906
193.07,44.90,0.085,0.907
193.10,45.04,0.085,0.907
193.12,45.18,0.085,0.908
193.15,45.32,0.085,0.908
193.18,45.46,0.085,0.909
193.21,45.61,0.085,0.910
193.24,45.75,0.085,0.910
193.27,45.89,0.086,0.911
193.29,46.03,0.086,0.911
193.32,46.17,0.086,0.912
193.35,46.31,0.086,0.913
193.38,46.46,0.086,0.914
193.41,46.60,0.086,0.915
193.43,46.74,0.086,0.916
193.46,46.88,0.086,0.916
193.49,47.02,0.086,0.917
193.52,47.16,0.086,0.918
193.55,47.31,0.086,0.918
193.58,47.45,0.086,0.918
193.60,47.59,0.086,0.917
193.63,47.73,0.086,0.917
193.66,47.87,0.086,0.919
193.69,48.01,0.086,0.919
193.72,48.16,0.086,0.919
193.75,48.30,0.086,0.920
193.78,48.44,0.086,0.922
193.80,48.58,0.087,0.922
193.83,48.72,0.087,0.922
193.86,48.87,0.087,0.921
193.89,49.01,0.087,0.923
193.92,49.15,0.087,0.924
193.95,49.29,0.087,0.925
193.97,49.43,0.087,0.924
194.00,49.57,0.087,0.925
194.03,49.72,0.087,0.927
194.06,49.86,0.087,0.929
194.09,50.00,0.087,0.929
194.12,50.14,0.087,0.930
194.14,50.28,0.087,0.929
194.17,50.42,0.087,0.930
194.20,50.57,0.087,0.931
194.23,50.71,0.087,0.931
194.26,50.85,0.087,0.933
194.28,50.99,0.088,0.933
194.31,51.13,0.088,0.933
194.34,51.27,0.088,0.935
194.37,51.42,0.088,0.936
194.40,51.56,0.088,0.936
194.43,51.70,0.088,0.936
194.45,51.84,0.088,0.937
194.48,51.98,0.088,0.937
194.51,52.13,0.088,0.938
194.54,52.27,0.088,0.940
194.57,52.41,0.088,0.940
194.60,52.55,0.088,0.941
194.63,52.69,0.088,0.940
194.65,52.83,0.088,0.941
194.68,52.98,0.088,0.943
194.71,53.12,0.088,0.943
194.74,53.26,0.089,0.943
194.77,53.40,0.089,0.945
194.80,53.54,0.089,0.946
194.82,53.68,0.089,0.946
194.85,53.83,0.089,0.947
194.88,53.97,0.089,0.947
194.91,54.11,0.089,0.947
194.94,54.25,0.089,0.949
194.97,54.39,0.089,0.949
194.99,54.54,0.089,0.951
195.02,54.68,0.089,0.952
195.05,54.82,0.089,0.953
195.08,54.96,0.089,0.954
195.11,55.10,0.089,0.955
195.13,55.25,0.090,0.956
195.16,55.39,0.090,0.957
195.19,55.53,0.090,0.958
195.22,55.67,0.090,0.958
195.25,55.81,0.090,0.959
195.28,55.95,0.090,0.960
195.30,56.09,0.090,0.961
195.33,56.24,0.090,0.961
195.36,56.38,0.090,0.961
195.39,56.52,0.090,0.961
195.42,56.66,0.090,0.962
195.45,56.81,0.090,0.962
195.48,56.95,0.090,0.964
195.50,57.09,0.090,0.965
195.53,57.23,0.091,0.966
195.56,57.37,0.091,0.968
195.59,57.51,0.091,0.969
195.62,57.66,0.091,0.969
195.65,57.80,0.091,0.970
195.67,57.94,0.091,0.971
195.70,58.08,0.091,0.972
195.73,58.22,0.091,0.972
195.76,58.36,0.091,0.973
195.79,58.50,0.091,0.974
195.82,58.65,0.091,0.975
195.84,58.79,0.091,0.976
195.87,58.93,0.092,0.976
195.90,59.07,0.092,0.977
195.93,59.21,0.092,0.978
195.96,59.36,0.092,0.979
195.98,59.50,0.092,0.979
196.01,59.64,0.092,0.980
196.04,59.78,0.092,0.982
196.07,59.92,0.092,0.982
196.10,60.06,0.092,0.983
196.13,60.21,0.092,0.983
196.15,60.35,0.092,0.984
196.18,60.49,0.092,0.985
196.21,60.63,0.092,0.985
196.24,60.77,0.092,0.985
196.27,60.92,0.093,0.987
196.30,61.06,0.093,0.989
196.33,61.20,0.093,0.991
196.35,61.34,0.093,0.993
196.38,61.48,0.093,0.995
196.41,61.63,0.093,0.996
196.44,61.77,0.093,0.998
196.47,61.91,0.094,0.999
196.50,62.05,0.094,1.000
196.52,62.19,0.094,1.002
196.55,62.33,0.094,1.002
196.58,62.47,0.094,1.004
196.61,62.62,0.094,1.005
196.64,62.76,0.094,1.005
196.67,62.90,0.094,1.007
196.69,63.04,0.094,1.008
196.72,63.18,0.094,1.008
196.75,63.33,0.095,1.010
196.78,63.47,0.095,1.010
196.81,63.61,0.095,1.012
196.83,63.75,0.095,1.013
196.86,63.89,0.095,1.015
196.89,64.03,0.095,1.016
196.92,64.17,0.095,1.017
196.95,64.32,0.095,1.018
196.98,64.46,0.096,1.020
197.00,64.60,0.096,1.020
197.03,64.74,0.096,1.022
197.06,64.88,0.096,1.024
197.09,65.03,0.096,1.025
197.12,65.17,0.096,1.027
197.15,65.31,0.097,1.030
197.18,65.45,0.097,1.032
197.20,65.59,0.097,1.034
197.23,65.73,0.097,1.037
197.26,65.88,0.097,1.038
197.29,66.02,0.097,1.041
197.32,66.16,0.097,1.042
197.35,66.30,0.098,1.042
197.37,66.44,0.098,1.043
197.40,66.58,0.098,1.045
197.43,66.73,0.098,1.046
197.46,66.87,0.098,1.048
197.49,67.01,0.098,1.049
197.52,67.15,0.099,1.051
197.54,67.29,0.099,1.053
197.57,67.43,0.099,1.054
197.60,67.58,0.099,1.057
197.63,67.72,0.099,1.057
197.66,67.86,0.099,1.060
197.68,68.00,0.100,1.062
197.71,68.14,0.100,1.065
197.74,68.28,0.100,1.067
197.77,68.43,0.100,1.069
197.80,68.57,0.100,1.071
197.83,68.71,0.101,1.074
197.85,68.85,0.101,1.075
197.88,68.99,0.101,1.079
197.91,69.14,0.101,1.081
197.94,69.28,0.102,1.083
197.97,69.42,0.102,1.086
198.00,69.56,0.102,1.089
198.03,69.70,0.102,1.091
198.05,69.84,0.103,1.094
198.08,69.99,0.103,1.096
198.11,70.13,0.103,1.100
198.14,70.27,0.103,1.102
198.17,70.41,0.104,1.105
198.20,70.55,0.104,1.108
198.22,70.69,0.104,1.111
198.25,70.84,0.104,1.115
198.28,70.98,0.105,1.116
198.31,71.12,0.105,1.119
198.34,71.26,0.105,1.122
198.37,71.40,0.105,1.126
198.39,71.55,0.106,1.128
198.42,71.69,0.106,1.131
198.45,71.83,0.106,1.134
198.48,71.97,0.107,1.138
198.51,72.11,0.107,1.142
198.53,72.25,0.107,1.145
198.56,72.40,0.108,1.148
198.59,72.54,0.108,1.152
198.62,72.68,0.108,1.155
198.65,72.82,0.108,1.158
198.68,72.96,0.109,1.161
198.70,73.10,0.109,1.164
198.73,73.24,0.109,1.168
198.76,73.39,0.110,1.171
198.79,73.53,0.110,1.173
198.82,73.67,0.110,1.178
198.85,73.81,0.111,1.182
198.88,73.95,0.111,1.187
198.90,74.10,0.112,1.192
198.93,74.24,0.112,1.196
198.96,74.38,0.112,1.200
198.99,74.52,0.113,1.203
199.02,74.66,0.113,1.208
199.05,74.80,0.113,1.211
199.07,74.94,0.114,1.216
199.10,75.09,0.114,1.219
199.13,75.23,0.115,1.223
199.16,75.37,0.115,1.226
199.19,75.51,0.115,1.231
199.22,75.65,0.116,1.235
199.24,75.80,0.116,1.239
199.27,75.94,0.116,1.242
199.30,76.08,0.117,1.247
199.33,76.22,0.117,1.251
199.36,76.36,0.117,1.255
199.38,76.50,0.118,1.259
199.41,76.64,0.118,1.264
199.44,76.78,0.119,1.266
199.47,76.93,0.119,1.270
199.50,77.07,0.119,1.274
199.53,77.21,0.120,1.279
199.55,77.35,0.120,1.282
199.58,77.49,0.121,1.287
199.61,77.63,0.121,1.290
199.64,77.78,0.121,1.296
199.67,77.92,0.122,1.299
199.70,78.06,0.122,1.303
199.73,78.20,0.122,1.306
199.75,78.34,0.123,1.311
199.78,78.48,0.123,1.314
199.81,78.63,0.124,1.319
199.84,78.77,0.124,1.322
199.87,78.91,0.124,1.327
199.90,79.05,0.125,1.331
199.92,79.19,0.125,1.334
199.95,79.33,0.125,1.338
199.98,79.48,0.126,1.341
200.01,79.62,0.126,1.344
200.04,79.76,0.126,1.347
200.07,79.90,0.126,1.350
200.09,80.04,0.127,1.352
200.12,80.18,0.127,1.354
200.15,80.33,0.127,1.356
200.18,80.47,0.127,1.358
200.21,80.61,0.128,1.360
200.23,80.75,0.128,1.363
200.26,80.89,0.128,1.364
200.29,81.04,0.128,1.367
200.32,81.18,0.128,1.370
200.35,81.32,0.129,1.371
200.38,81.46,0.129,1.374
200.40,81.60,0.129,1.376
200.43,81.74,0.129,1.378
200.46,81.89,0.129,1.379
200.49,82.03,0.129,1.380
200.52,82.17,0.129,1.382
200.55,82.31,0.130,1.383
200.58,82.45,0.130,1.383
200.60,82.59,0.130,1.384
200.63,82.73,0.130,1.385
200.66,82.88,0.130,1.386
200.69,83.02,0.130,1.386
200.72,83.16,0.130,1.387
200.75,83.30,0.130,1.387
200.77,83.44,0.130,1.388
200.80,83.59,0.130,1.389
200.83,83.73,0.130,1.389
200.86,83.87,0.130,1.389
200.89,84.01,0.130,1.389
200.92,84.15,0.130,1.387
200.94,84.29,0.130,1.387
200.97,84.44,0.130,1.387
201.00,84.58,0.130,1.386
201.03,84.72,0.130,1.385
201.06,84.86,0.130,1.386
201.08,85.00,0.130,1.386
201.11,85.15,0.130,1.385
201.14,85.29,0.130,1.385
201.17,85.43,0.130,1.385
201.20,85.57,0.130,1.385
201.23,85.71,0.130,1.386
201.25,85.86,0.130,1.385
201.28,86.00,0.130,1.384
201.31,86.14,0.130,1.383
201.34,86.28,0.130,1.383
201.37,86.42,0.129,1.382
201.40,86.56,0.129,1.380
201.43,86.71,0.129,1.380
201.45,86.85,0.129,1.378
201.48,86.99,0.129,1.378
201.51,87.13,0.129,1.378
201.54,87.27,0.129,1.377
201.57,87.41,0.129,1.376
201.60,87.56,0.129,1.376
201.62,87.70,0.129,1.375
201.65,87.84,0.129,1.375
201.68,87.98,0.129,1.374
201.71,88.12,0.129,1.374
201.74,88.27,0.129,1.372
201.77,88.41,0.129,1.373
201.79,88.55,0.129,1.372
201.82,88.69,0.129,1.373
201.85,88.83,0.129,1.373
201.88,88.97,0.129,1.373
201.91,89.12,0.129,1.373
201.93,89.26,0.129,1.374
201.96,89.40,0.129,1.374
201.99,89.54,0.129,1.375
202.02,89.68,0.129,1.374
202.05,89.82,0.129,1.373
202.08,89.96,0.129,1.372
202.10,90.11,0.129,1.370
202.13,90.25,0.129,1.370
202.16,90.39,0.128,1.370
202.19,90.53,0.128,1.369
202.22,90.68,0.129,1.370
202.25,90.82,0.129,1.372
202.28,90.96,0.129,1.374
202.30,91.10,0.129,1.375
202.33,91.24,0.129,1.375
202.36,91.38,0.129,1.375
202.39,91.52,0.129,1.374
202.42,91.67,0.129,1.373
202.45,91.81,0.129,1.372
202.47,91.95,0.129,1.372
202.50,92.09,0.129,1.372
202.53,92.23,0.129,1.372
202.56,92.38,0.129,1.373
202.59,92.52,0.129,1.374
202.62,92.66,0.129,1.373
202.64,92.80,0.129,1.373
202.67,92.94,0.129,1.372
202.70,93.08,0.129,1.371
202.73,93.23,0.129,1.371
202.76,93.37,0.129,1.371
202.78,93.51,0.129,1.372
202.81,93.65,0.129,1.373
202.84,93.79,0.129,1.374
202.87,93.94,0.129,1.375
202.90,94.08,0.129,1.375
202.93,94.22,0.129,1.376
202.95,94.36,0.129,1.376
202.98,94.50,0.129,1.376
203.01,94.64,0.129,1.376
203.04,94.78,0.129,1.378
203.07,94.93,0.129,1.378
203.10,95.07,0.129,1.378
203.13,95.21,0.129,1.377
203.15,95.35,0.129,1.376
203.18,95.49,0.129,1.375
203.21,95.64,0.129,1.376
203.24,95.78,0.129,1.376
203.27,95.92,0.129,1.375
203.30,96.06,0.129,1.375
203.32,96.20,0.129,1.375
203.35,96.34,0.129,1.375
203.38,96.49,0.129,1.375
203.41,96.63,0.129,1.375
203.44,96.77,0.129,1.377
203.47,96.91,0.129,1.377
203.49,97.05,0.129,1.378
203.52,97.20,0.129,1.379
203.55,97.34,0.129,1.380
203.58,97.48,0.129,1.380
203.61,97.62,0.130,1.380
203.63,97.76,0.130,1.380
203.66,97.90,0.130,1.381
203.69,98.05,0.130,1.381
203.72,98.19,0.130,1.381
203.75,98.33,0.130,1.381
203.78,98.47,0.130,1.382
203.80,98.61,0.130,1.382
203.83,98.75,0.130,1.381
203.86,98.90,0.130,1.382
203.89,99.04,0.130,1.382
203.92,99.18,0.130,1.382
203.95,99.32,0.130,1.382
203.98,99.46,0.130,1.381
204.00,99.61,0.130,1.381
204.03,99.75,0.130,1.382
204.06,99.89,0.130,1.382
204.09,100.03,0.130,1.383
204.12,100.17,0.130,1.384
204.15,100.31,0.130,1.383
204.17,100.46,0.130,1.385
204.20,100.60,0.130,1.386
204.23,100.74,0.130,1.387
204.26,100.88,0.130,1.387
204.29,101.02,0.130,1.386
204.32,101.16,0.130,1.385
204.34,101.31,0.130,1.385
204.37,101.45,0.130,1.384
204.40,101.59,0.130,1.384
204.43,101.73,0.130,1.384
204.46,101.87,0.130,1.385
204.48,102.02,0.130,1.387
204.51,102.16,0.130,1.388
204.54,102.30,0.130,1.388
204.57,102.44,0.130,1.389
204.60,102.58,0.130,1.390
204.63,102.72,0.130,1.391
204.65,102.87,0.130,1.390
204.68,103.01,0.130,1.389
204.71,103.15,0.130,1.388
204.74,103.29,0.130,1.388
204.77,103.43,0.130,1.387
204.80,103.57,0.130,1.388
204.83,103.72,0.131,1.388
204.85,103.86,0.131,1.389
204.88,104.00,0.131,1.390
204.91,104.14,0.131,1.391
204.94,104.28,0.131,1.392
204.97,104.43,0.131,1.391
205.00,104.57,0.131,1.392
205.02,104.71,0.131,1.392
205.05,104.85,0.131,1.392
205.08,104.99,0.131,1.392
205.11,105.14,0.131,1.392
205.14,105.28,0.131,1.393
205.17,105.42,0.131,1.394
205.19,105.56,0.131,1.396
205.22,105.70,0.131,1.397
205.25,105.84,0.131,1.396
205.28,105.98,0.131,1.395
205.31,106.13,0.131,1.394
205.33,106.27,0.131,1.392
205.36,106.41,0.131,1.391
205.39,106.55,0.131,1.391
205.42,106.69,0.131,1.391
205.45,106.84,0.131,1.392
205.48,106.98,0.131,1.393
205.50,107.12,0.131,1.395
205.53,107.26,0.131,1.397
205.56,107.40,0.131,1.397
205.59,107.55,0.131,1.398
205.62,107.69,0.131,1.396
205.65,107.83,0.131,1.397
205.68,107.97,0.131,1.397
205.70,108.11,0.131,1.397
205.73,108.25,0.131,1.397
205.76,108.40,0.132,1.398
205.79,108.54,0.132,1.397
205.82,108.68,0.132,1.398
205.85,108.82,0.132,1.399
205.87,108.96,0.132,1.400
205.90,109.11,0.132,1.400
205.93,109.25,0.132,1.400
205.96,109.39,0.132,1.399
205.99,109.53,0.132,1.400
206.02,109.67,0.132,1.400
206.04,109.82,0.132,1.401
206.07,109.96,0.132,1.401
206.10,110.10,0.132,1.402
206.13,110.24,0.132,1.403
206.16,110.38,0.132,1.405
206.18,110.53,0.132,1.406
206.21,110.67,0.132,1.408
206.24,110.81,0.132,1.408
206.27,110.95,0.132,1.410
206.30,111.09,0.132,1.410
206.33,111.23,0.132,1.410
206.35,111.37,0.132,1.412
206.38,111.52,0.132,1.413
206.41,111.66,0.132,1.411
206.44,111.80,0.132,1.411
206.47,111.94,0.132,1.409
206.50,112.08,0.132,1.410
206.53,112.22,0.132,1.408
206.55,112.36,0.132,1.405
206.58,112.51,0.132,1.405
206.61,112.65,0.132,1.403
206.64,112.79,0.132,1.404
206.67,112.93,0.132,1.404
206.70,113.07,0.132,1.407
206.72,113.21,0.132,1.408
206.75,113.36,0.133,1.409
206.78,113.50,0.133,1.409
206.81,113.64,0.133,1.410
206.84,113.78,0.133,1.410
206.87,113.92,0.133,1.411
206.89,114.07,0.133,1.410
206.92,114.21,0.133,1.413
206.95,114.35,0.133,1.414
206.98,114.49,0.133,1.417
207.01,114.63,0.133,1.417
207.03,114.77,0.133,1.415
207.06,114.91,0.133,1.412
207.09,115.06,0.133,1.412
207.12,115.20,0.133,1.411
207.15,115.34,0.133,1.411
207.18,115.48,0.133,1.411
207.20,115.62,0.133,1.413
207.23,115.77,0.133,1.414
207.26,115.91,0.133,1.416
207.29,116.05,0.133,1.416
207.32,116.19,0.133,1.417
207.35,116.33,0.133,1.417
207.38,116.47,0.133,1.417
207.40,116.62,0.133,1.418
207.43,116.76,0.133,1.419
207.46,116.90,0.133,1.421
207.49,117.04,0.134,1.420
207.52,117.18,0.134,1.418
207.55,117.32,0.134,1.417
207.57,117.47,0.134,1.418
207.60,117.61,0.134,1.418
207.63,117.75,0.134,1.418
207.66,117.89,0.134,1.418
207.69,118.03,0.134,1.420
207.72,118.18,0.134,1.422
207.74,118.32,0.134,1.423
207.77,118.46,0.134,1.423
207.80,118.60,0.134,1.422
207.83,118.74,0.134,1.422
207.86,118.88,0.134,1.422
207.88,119.03,0.134,1.421
207.91,119.17,0.134,1.420
207.94,119.31,0.134,1.421
207.97,119.45,0.134,1.422
208.00,119.59,0.134,1.423
208.03,119.74,0.134,1.422
208.05,119.88,0.134,1.421
208.08,120.02,0.134,1.422
208.11,120.16,0.134,1.423
208.14,120.30,0.134,1.424
208.17,120.44,0.134,1.425
208.20,120.59,0.134,1.426
208.23,120.73,0.135,1.428
208.25,120.87,0.135,1.430
208.28,121.01,0.135,1.432
208.31,121.15,0.135,1.432
208.34,121.29,0.135,1.432
208.37,121.44,0.135,1.431
208.40,121.58,0.135,1.431
208.42,121.72,0.135,1.430
208.45,121.86,0.135,1.432
208.48,122.00,0.135,1.431
208.51,122.15,0.135,1.433
208.54,122.29,0.135,1.435
208.57,122.43,0.135,1.436
208.59,122.57,0.135,1.436
208.62,122.71,0.135,1.435
208.65,122.85,0.135,1.435
208.68,122.99,0.135,1.433
208.71,123.14,0.135,1.434
208.73,123.28,0.135,1.433
208.76,123.42,0.135,1.434
208.79,123.56,0.135,1.435
208.82,123.70,0.135,1.436
208.85,123.85,0.135,1.436
208.88,123.99,0.135,1.439
208.90,124.13,0.135,1.438
208.93,124.27,0.136,1.438
208.96,124.41,0.136,1.438
208.99,124.55,0.136,1.438
209.02,124.70,0.136,1.437
209.05,124.84,0.136,1.438
209.08,124.98,0.136,1.438
209.10,125.12,0.136,1.439
209.13,125.26,0.136,1.441
209.16,125.40,0.136,1.440
209.19,125.55,0.136,1.441
209.22,125.69,0.136,1.441
209.25,125.83,0.136,1.442
209.27,125.97,0.136,1.442
209.30,126.11,0.136,1.444
209.33,126.25,0.136,1.444
209.36,126.40,0.136,1.446
209.39,126.54,0.136,1.445
209.42,126.68,0.136,1.446
209.44,126.82,0.136,1.446
209.47,126.96,0.136,1.447
209.50,127.11,0.136,1.446
209.53,127.25,0.137,1.447
209.56,127.39,0.137,1.449
209.58,127.53,0.137,1.450
209.61,127.67,0.137,1.452
209.64,127.81,0.137,1.452
209.67,127.96,0.137,1.454
209.70,128.10,0.137,1.455
209.73,128.24,0.137,1.456
209.75,128.38,0.137,1.456
209.78,128.52,0.137,1.455
209.81,128.66,0.137,1.455
209.84,128.80,0.137,1.454
209.87,128.95,0.137,1.453
209.90,129.09,0.137,1.450
209.93,129.23,0.137,1.450
209.95,129.37,0.137,1.450
209.98,129.52,0.137,1.452
210.01,129.66,0.137,1.453
210.04,129.80,0.137,1.456
210.07,129.94,0.137,1.458
210.10,130.08,0.138,1.460
210.12,130.22,0.138,1.461
210.15,130.37,0.138,1.461
210.18,130.51,0.138,1.461
210.21,130.65,0.138,1.461
210.24,130.79,0.138,1.461
210.27,130.93,0.138,1.461
210.29,131.07,0.138,1.461
210.32,131.22,0.138,1.462
210.35,131.36,0.138,1.464
210.38,131.50,0.138,1.465
210.41,131.64,0.138,1.466
210.43,131.78,0.138,1.467
210.46,131.93,0.139,1.468
210.49,132.07,0.139,1.468
210.52,132.21,0.139,1.471
210.55,132.35,0.139,1.472
210.58,132.49,0.139,1.474
210.60,132.63,0.139,1.475
210.63,132.78,0.139,1.476
210.66,132.92,0.139,1.478
210.69,133.06,0.139,1.479
210.72,133.20,0.140,1.481
210.75,133.34,0.140,1.481
210.78,133.48,0.140,1.482
210.80,133.62,0.140,1.482
210.83,133.77,0.140,1.484
210.86,133.91,0.140,1.484
210.89,134.05,0.140,1.484
210.92,134.19,0.140,1.485
210.95,134.33,0.140,1.486
210.97,134.47,0.140,1.487
211.00,134.62,0.141,1.489
211.03,134.76,0.141,1.490
211.06,134.90,0.141,1.490
211.09,135.04,0.141,1.492
211.12,135.18,0.141,1.493
211.14,135.33,0.141,1.494
211.17,135.47,0.141,1.495
211.20,135.61,0.141,1.495
211.23,135.75,0.141,1.496
211.26,135.89,0.141,1.497
211.28,136.03,0.141,1.496
211.31,136.18,0.141,1.497
211.34,136.32,0.141,1.497
211.37,136.46,0.141,1.497
211.40,136.60,0.141,1.498
211.43,136.74,0.141,1.498
211.45,136.88,0.141,1.497
211.48,137.03,0.141,1.497
211.51,137.17,0.141,1.499
211.54,137.31,0.141,1.498
211.57,137.45,0.141,1.498
211.60,137.59,0.142,1.499
211.63,137.73,0.142,1.499
211.65,137.88,0.142,1.499
211.68,138.02,0.142,1.499
211.71,138.16,0.142,1.498
211.74,138.30,0.142,1.499
211.77,138.44,0.142,1.501
211.80,138.58,0.142,1.501
211.82,138.73,0.142,1.502
211.85,138.87,0.142,1.502
211.88,139.01,0.142,1.504
211.91,139.15,0.142,1.504
211.94,139.29,0.142,1.504
211.97,139.44,0.142,1.503
211.99,139.58,0.142,1.503
212.02,139.72,0.142,1.503
212.05,139.86,0.142,1.505
212.08,140.00,0.142,1.503
212.11,140.15,0.142,1.502
212.13,140.29,0.142,1.503
212.16,140.43,0.142,1.504
212.19,140.57,0.142,1.505
212.22,140.71,0.142,1.507
212.25,140.85,0.142,1.506
212.28,141.00,0.142,1.509
212.30,141.14,0.143,1.510
212.33,141.28,0.143,1.510
212.36,141.42,0.142,1.509
212.39,141.56,0.143,1.508
212.42,141.70,0.143,1.509
212.45,141.85,0.142,1.509
212.48,141.99,0.143,1.510
212.50,142.13,0.143,1.509
212.53,142.27,0.143,1.511
212.56,142.41,0.143,1.512
212.59,142.55,0.143,1.513
212.62,142.70,0.143,1.514
212.65,142.84,0.143,1.514
212.67,142.98,0.143,1.512
212.70,143.12,0.143,1.512
212.73,143.26,0.143,1.511
212.76,143.40,0.143,1.511
212.79,143.55,0.143,1.512
212.82,143.69,0.144,1.525
212.84,143.83,0.144,1.526
212.87,143.97,0.145,1.528
212.90,144.11,0.145,1.530
212.93,144.25,0.145,1.530
212.96,144.40,0.145,1.532
212.98,144.54,0.145,1.531
213.01,144.68,0.145,1.531
213.04,144.82,0.145,1.530
213.07,144.96,0.145,1.530
213.10,145.10,0.145,1.528
213.13,145.25,0.145,1.529
213.15,145.39,0.145,1.527
213.18,145.53,0.145,1.526
213.21,145.67,0.145,1.527
213.24,145.81,0.145,1.529
213.27,145.96,0.145,1.528
213.30,146.10,0.145,1.529
213.33,146.24,0.145,1.530
213.35,146.38,0.145,1.530
213.38,146.52,0.145,1.531
213.41,146.66,0.145,1.532
213.44,146.80,0.145,1.530
213.47,146.95,0.145,1.531
213.50,147.09,0.145,1.530
213.52,147.23,0.145,1.530
213.55,147.37,0.145,1.531
213.58,147.51,0.145,1.531
213.61,147.65,0.145,1.531
213.64,147.80,0.145,1.531
213.67,147.94,0.145,1.531
213.69,148.08,0.145,1.532
213.72,148.22,0.145,1.533
213.75,148.36,0.145,1.532
213.78,148.51,0.145,1.532
213.81,148.65,0.145,1.533
213.83,148.79,0.146,1.536
213.86,148.93,0.146,1.537
213.89,149.07,0.146,
213.92,149.22,0.146,
213.95,149.36,,
213.98,149.50,,
213.98,,,