File: DSC/Earl/2025_10_05_Sapphire_Pc_5Cmin_n60C_250C_x3.csv
Filename,2025_10_05_Sapphire_Pc_5Cmin_n60C_250C_x3
Instrument name,DSC2A-00468 (192.168.1.100)
Operator,JLY
rundate,10/4/2025
Sample name,2025_10_05_Sapphire_Pc_5Cmin_n60C_250C_x3
proceduresegments,Data Off ; Equilibrate -60.00 °C; Data On ; Ramp 5.00 °C/min to 250.00 °C; Data Off ; Isothermal 1.0 min; Data On ; Ramp 5.00 °C/min to -60.00 °C; Data Off ; Isothermal 1.0 min; Data On ; Ramp 5.00 °C/min to 250.00 °C; Data Off ; Isothermal 1.0 min; Data On ; Ramp 5.00 °C/min to -60.00 °C; Data Off ; Isothermal 1.0 min; Data On ; Ramp 5.00 °C/min to 250.00 °C
[File Parameters]
Run date,10/4/2025 10:56:33 PM
Trios version,5.1.1.46572
Original File Name,
Current File Name,D:\DSC2500\JYarger\2025_10_05_Sapphire_Pc_5Cmin_n60C_250C_x3.tri
[Procedure]
Procedure Name,Sapphire_n60C_250C_5Cmin_3
Sample Name,2025_10_05_Sapphire_Pc_5Cmin_n60C_250C_x3
Sample Mass,3.29 mg
Reference Sample Mass,0 mg
Pan Mass,32.66 mg
Pan Number,6
Reference Pan Mass,32.55 mg
Reference Pan Number,1
Pan Type,Aluminum
Comments,DSC_Samples_Y2_Tray_ASDs_Pharma_Oct2025 Google Sheet.
Project Name,Amorphous Pharma
Operator,JLY
Test,Custom
Unload Max Temperature,30
Unload Min Temperature,30
Load Max Temperature,30
Load Min Temperature,30
Stop on Gas Flow Error,Yes
[Signal List]
Signal #1,Time (min)
Signal #2,Temperature (°C)
Signal #3,Heat Flow (mW)
Signal #4,Delta T (µV)
Signal #5,Delta Tzero (µV)
Signal #6,Tzero Temperature (°C)
Signal #7,Cell Purge (mL/min)
Signal #8,Heater Temp (°C)
Signal #9,Power Delivered (W)
Signal #10,Reference Junction Temperature (°C)
Signal #11,Flange Temperature (°C)
Signal #12,Heat Flow Phase (rad)
Signal #13,Total Heat Capacity (J/°C)
Signal #14,Heat Capacity (J/°C)
[Configuration]
Company Name,ASU
Instrument Name,DSC2A-00468
Instrument Type,DSC2500
Serial Number,DSC2A-00468
IP,192.168.1.100
Location of Instrument,MRRC
DisplayType,Unknown
Sample Interval ,0.1 s/pt
Selected Heat Flow,T4P
Exotherm Direction,Down
Cell Serial,DRC2-00792
Lid Type,Standard
Cooler,RCS 90
Leave Cooler on at End of Sequence,On
Gas 2,Nitrogen
Gas Selected,Channel 1
Flow Rate,50 mL/min
Secondary Purge,On
Licensed Heat Flow,Heat Flow T4P
Modulation Licensed,Yes
[Versions]
Common IDD Version,1
Cortex Version,VER 2.10.2.31
Driver,5.0.0.6
GDM Version,1.0.3.3
TouchscreenVersion,1.0.0.16145
FEP Version,1.2.1.21
FEP Bootloader,2.0.0.5
AutoSampler Version,2.1.1.26
Auto Sampler Bootloader,2.0.0.5
FCM Version,1.1.0.3
FCM Bootloader,2.0.0.5
[Experiment Logs]
Experiment Log Entry # 1,Data On set to 0
Experiment Log Entry # 3,Air Cool is off.
Experiment Log Entry # 5,Equilibrate Segment -60 (C) Started
Experiment Log Entry # 7,Data On set to 1
Experiment Log Entry # 9,Ramp Segment 5 C/min to 250 Started
Experiment Log Entry # 11,Data On set to 0
Experiment Log Entry # 13,Isothermal Segment 1 min started
Experiment Log Entry # 15,Data On set to 1
Experiment Log Entry # 17,Ramp Segment 5 C/min to -60 Started
Experiment Log Entry # 19,Data On set to 0
Experiment Log Entry # 21,Isothermal Segment 1 min started
Experiment Log Entry # 23,Data On set to 1
Experiment Log Entry # 25,Ramp Segment 5 C/min to 250 Started
Experiment Log Entry # 27,Auto sampler has detected that FCM has gone offline
Experiment Log Entry # 29,Data On set to 0
Experiment Log Entry # 31,Isothermal Segment 1 min started
Experiment Log Entry # 33,Data On set to 1
Experiment Log Entry # 35,Ramp Segment 5 C/min to -60 Started
Experiment Log Entry # 37,Data On set to 0
Experiment Log Entry # 39,Isothermal Segment 1 min started
Experiment Log Entry # 41,Data On set to 1
Experiment Log Entry # 43,Ramp Segment 5 C/min to 250 Started
[Method Log]
Method Log Entry # 1,Data Off
Method Log Entry # 2,Equilibrate -60 °C
Method Log Entry # 3,Data On
Method Log Entry # 4,(Ramp 60040) Ramp 5 °C/minute to 250 °C
Method Log Entry # 5,Data Off
Method Log Entry # 6,Isothermal 1 minutes
Method Log Entry # 7,Data On
Method Log Entry # 8,(Ramp 60044) Ramp 5 °C/minute to -60 °C
Method Log Entry # 9,Data Off
Method Log Entry # 10,Isothermal 1 minutes
Method Log Entry # 11,Data On
Method Log Entry # 12,(Ramp 60048) Ramp 5 °C/minute to 250 °C
Method Log Entry # 13,Data Off
Method Log Entry # 14,Isothermal 1 minutes
Method Log Entry # 15,Data On
Method Log Entry # 16,(Ramp 60052) Ramp 5 °C/minute to -60 °C
Method Log Entry # 17,Data Off
Method Log Entry # 18,Isothermal 1 minutes
Method Log Entry # 19,Data On
Method Log Entry # 20,(Ramp 60056) Ramp 5 °C/minute to 250 °C
Cell Serial,DRC2-00792
[T1 Calibration]
Slope,-0.008529666
Offset,9.636258
Initial Temperature,98.23
GUID,f8bfdadc-4977-4fdf-ba6d-0ba9134940c3
[TZero Calibration]
Date Applied,11/29/2022 4:06:13 PM
Description,From -89.059 °C to 396.009 °C at 20.000°C/min
Gas Type,Nitrogen
Pan Type,None
Source Files 1,C:\Users\yargerlab\Desktop\DSC Data\General\TZero_calibration_11_29_22_2nd(2).tri
Source Files 2,C:\Users\yargerlab\Desktop\DSC Data\General\TZero_calibration_11_29_22_2nd(3).tri
Delta T Offset,13.05235
Delta T Slope,-0.007271007
Delta T0 Offset,-13.69128
Delta T0 Slope,0.06063341
[Temperature Calibration]
Date Applied,11/29/2022 7:12:28 PM
Description,From 106.590 °C to 186.590 °C at 10.000°C/min
Gas Type,Nitrogen
Pan Type,Tzero Aluminum Hermetic
Source Files 1,C:\Users\yargerlab\Desktop\DSC Data\General\Indium(6).tri
Measured 1,157.391
Known 1,156.598
[Cell Constant Calibration]
Date Applied,11/29/2022 7:12:29 PM
Description,From 106.590 °C to 186.590 °C at 10.000°C/min
Gas Type,Nitrogen
Pan Type,Tzero Aluminum Hermetic
Source Files 1,C:\Users\yargerlab\Desktop\DSC Data\General\Indium(6).tri
T4P KCell,1.006051
Onset Slope,63.26126 mW/°C
[Direct Cp Calibration]
Date Applied,11/30/2022 11:04:51 AM
Description,From -79.983 °C to 298.409 °C at 10.000°C/min
Gas Type,Nitrogen
Pan Type,Tzero Aluminum Hermetic
Source Files 1,C:\Users\yargerlab\Desktop\DSC Data\General\Sapphire_Heat_Capacity_11_30_22.tri
[Rev Cp Calibration]
Date Applied,11/30/2022 1:58:51 PM
Description,From -79.996 °C to 292.812 °C at 3.000°C/min
Gas Type,Nitrogen
Pan Type,Tzero Aluminum Hermetic
Source Files 1,C:\Users\yargerlab\Desktop\DSC Data\General\Sapphire_MDSC_Calibration_11_30_22.tri
[step]
Ramp 5.00 °C/min to 250.00 °C
Time,Temperature,Heat Flow (Normalized)
min,°C,W/g
0.00,-59.83,-0.046
0.04,-59.84,-0.041
0.08,-59.80,-0.007
0.13,-59.68,0.031
0.17,-59.51,0.052
0.21,-59.33,0.062
0.25,-59.14,0.067
0.29,-58.94,0.069
0.33,-58.74,0.072
0.38,-58.54,0.074
0.42,-58.34,0.075
0.46,-58.13,0.075
0.50,-57.93,0.076
0.54,-57.72,0.077
0.58,-57.52,0.078
0.63,-57.31,0.079
0.67,-57.11,0.079
0.71,-56.90,0.080
0.75,-56.69,0.080
0.79,-56.49,0.081
0.83,-56.28,0.081
0.88,-56.07,0.081
0.92,-55.87,0.082
0.96,-55.66,0.082
1.00,-55.45,0.082
1.04,-55.24,0.082
1.08,-55.03,0.082
1.13,-54.83,0.083
1.17,-54.62,0.083
1.21,-54.41,0.083
1.25,-54.20,0.083
1.29,-54.00,0.083
1.33,-53.79,0.083
1.38,-53.58,0.083
1.42,-53.37,0.083
1.46,-53.17,0.083
1.50,-52.96,0.083
1.54,-52.75,0.083
1.58,-52.54,0.083
1.63,-52.33,0.083
1.67,-52.13,0.082
1.71,-51.92,0.082
1.75,-51.71,0.082
1.79,-51.50,0.082
1.83,-51.30,0.082
1.88,-51.09,0.082
1.92,-50.88,0.082
1.96,-50.67,0.082
2.00,-50.46,0.082
2.04,-50.25,0.082
2.08,-50.05,0.082
2.13,-49.84,0.082
2.17,-49.63,0.082
2.21,-49.42,0.082
2.25,-49.21,0.082
2.29,-49.00,0.082
2.33,-48.80,0.082
2.38,-48.59,0.081
2.42,-48.38,0.081
2.46,-48.17,0.081
2.50,-47.96,0.081
2.54,-47.75,0.081
2.58,-47.55,0.081
2.63,-47.34,0.081
2.67,-47.13,0.081
2.71,-46.92,0.081
2.75,-46.71,0.081
2.79,-46.50,0.081
2.83,-46.30,0.081
2.88,-46.09,0.081
2.92,-45.88,0.081
2.96,-45.67,0.081
3.00,-45.46,0.081
3.04,-45.26,0.081
3.08,-45.05,0.081
3.13,-44.84,0.081
3.17,-44.63,0.081
3.21,-44.42,0.081
3.25,-44.21,0.081
3.29,-44.01,0.081
3.33,-43.80,0.081
3.38,-43.59,0.081
3.42,-43.38,0.081
3.46,-43.17,0.081
3.50,-42.96,0.081
3.54,-42.76,0.081
3.58,-42.55,0.081
3.63,-42.34,0.081
3.67,-42.13,0.081
3.71,-41.92,0.081
3.75,-41.71,0.081
3.79,-41.50,0.081
3.83,-41.30,0.081
3.88,-41.09,0.081
3.92,-40.88,0.081
3.96,-40.67,0.081
4.00,-40.46,0.080
4.04,-40.26,0.080
4.08,-40.05,0.080
4.13,-39.84,0.080
4.17,-39.63,0.080
4.21,-39.42,0.080
4.25,-39.21,0.080
4.29,-39.00,0.080
4.33,-38.79,0.080
4.38,-38.59,0.080
4.42,-38.38,0.080
4.46,-38.17,0.080
4.50,-37.96,0.080
4.54,-37.75,0.080
4.58,-37.54,0.080
4.63,-37.33,0.080
4.67,-37.13,0.080
4.71,-36.92,0.080
4.75,-36.71,0.080
4.79,-36.50,0.080
4.83,-36.29,0.080
4.88,-36.08,0.080
4.92,-35.87,0.080
4.96,-35.66,0.080
5.00,-35.46,0.080
5.04,-35.25,0.080
5.08,-35.04,0.080
5.13,-34.83,0.080
5.17,-34.62,0.080
5.21,-34.41,0.080
5.25,-34.20,0.080
5.29,-33.99,0.080
5.33,-33.79,0.080
5.38,-33.58,0.080
5.42,-33.37,0.080
5.46,-33.16,0.080
5.50,-32.95,0.080
5.54,-32.74,0.080
5.58,-32.54,0.080
5.63,-32.33,0.080
5.67,-32.12,0.080
5.71,-31.91,0.080
5.75,-31.70,0.080
5.79,-31.49,0.080
5.83,-31.28,0.080
5.88,-31.07,0.080
5.92,-30.87,0.080
5.96,-30.66,0.080
6.00,-30.45,0.080
6.04,-30.24,0.080
6.08,-30.03,0.080
6.13,-29.82,0.080
6.17,-29.62,0.080
6.21,-29.41,0.080
6.25,-29.20,0.080
6.29,-28.99,0.080
6.33,-28.78,0.080
6.38,-28.57,0.080
6.42,-28.36,0.080
6.46,-28.16,0.080
6.50,-27.95,0.080
6.54,-27.74,0.080
6.58,-27.53,0.080
6.63,-27.32,0.080
6.67,-27.11,0.080
6.71,-26.90,0.080
6.75,-26.70,0.080
6.79,-26.49,0.080
6.83,-26.28,0.080
6.88,-26.07,0.080
6.92,-25.86,0.080
6.96,-25.65,0.080
7.00,-25.44,0.080
7.04,-25.23,0.080
7.08,-25.03,0.080
7.13,-24.82,0.080
7.17,-24.61,0.080
7.21,-24.40,0.080
7.25,-24.19,0.080
7.29,-23.98,0.080
7.33,-23.78,0.080
7.38,-23.57,0.080
7.42,-23.36,0.080
7.46,-23.15,0.080
7.50,-22.94,0.080
7.54,-22.73,0.080
7.58,-22.52,0.080
7.63,-22.32,0.080
7.67,-22.11,0.080
7.71,-21.90,0.080
7.75,-21.69,0.080
7.79,-21.48,0.080
7.83,-21.27,0.080
7.88,-21.06,0.080
7.92,-20.85,0.080
7.96,-20.65,0.080
8.00,-20.44,0.080
8.04,-20.23,0.080
8.08,-20.02,0.081
8.13,-19.81,0.081
8.17,-19.60,0.080
8.21,-19.40,0.080
8.25,-19.19,0.080
8.29,-18.98,0.080
8.33,-18.77,0.080
8.38,-18.56,0.080
8.42,-18.35,0.080
8.46,-18.15,0.080
8.50,-17.94,0.080
8.54,-17.73,0.080
8.58,-17.52,0.080
8.63,-17.31,0.080
8.67,-17.10,0.080
8.71,-16.89,0.080
8.75,-16.68,0.080
8.79,-16.48,0.080
8.83,-16.27,0.081
8.88,-16.06,0.081
8.92,-15.85,0.081
8.96,-15.64,0.081
9.00,-15.43,0.081
9.04,-15.22,0.081
9.08,-15.01,0.080
9.13,-14.81,0.080
9.17,-14.60,0.080
9.21,-14.39,0.080
9.25,-14.18,0.081
9.29,-13.97,0.081
9.33,-13.76,0.081
9.38,-13.56,0.081
9.42,-13.35,0.081
9.46,-13.14,0.080
9.50,-12.93,0.080
9.54,-12.72,0.080
9.58,-12.52,0.080
9.63,-12.31,0.080
9.67,-12.10,0.080
9.71,-11.89,0.080
9.75,-11.68,0.081
9.79,-11.47,0.081
9.83,-11.26,0.081
9.88,-11.05,0.081
9.92,-10.85,0.081
9.96,-10.64,0.081
10.00,-10.43,0.081
10.04,-10.22,0.081
10.08,-10.01,0.081
10.13,-9.80,0.081
10.17,-9.59,0.081
10.21,-9.38,0.081
10.25,-9.18,0.081
10.29,-8.97,0.081
10.33,-8.76,0.081
10.38,-8.55,0.081
10.42,-8.34,0.081
10.46,-8.13,0.081
10.50,-7.93,0.081
10.54,-7.72,0.081
10.58,-7.51,0.081
10.63,-7.30,0.081
10.67,-7.09,0.081
10.71,-6.88,0.081
10.75,-6.67,0.081
10.79,-6.47,0.081
10.83,-6.26,0.081
10.88,-6.05,0.081
10.92,-5.84,0.081
10.96,-5.63,0.081
11.00,-5.42,0.081
11.04,-5.21,0.081
11.08,-5.01,0.081
11.13,-4.80,0.081
11.17,-4.59,0.081
11.21,-4.38,0.081
11.25,-4.17,0.081
11.29,-3.96,0.081
11.33,-3.75,0.081
11.38,-3.55,0.081
11.42,-3.34,0.081
11.46,-3.13,0.081
11.50,-2.92,0.081
11.54,-2.71,0.081
11.58,-2.51,0.081
11.63,-2.30,0.081
11.67,-2.09,0.081
11.71,-1.88,0.081
11.75,-1.67,0.081
11.79,-1.46,0.081
11.83,-1.25,0.081
11.88,-1.04,0.081
11.92,-0.83,0.081
11.96,-0.62,0.081
12.00,-0.42,0.081
12.04,-0.21,0.081
12.08,0.00,0.081
12.13,0.21,0.081
12.17,0.41,0.081
12.21,0.62,0.081
12.25,0.83,0.081
12.29,1.04,0.081
12.33,1.25,0.081
12.38,1.46,0.081
12.42,1.66,0.081
12.46,1.87,0.081
12.50,2.08,0.081
12.54,2.29,0.081
12.58,2.50,0.081
12.63,2.71,0.081
12.67,2.92,0.082
12.71,3.13,0.082
12.75,3.34,0.082
12.79,3.55,0.082
12.83,3.75,0.082
12.88,3.96,0.082
12.92,4.17,0.082
12.96,4.38,0.082
13.00,4.59,0.082
13.04,4.80,0.082
13.08,5.00,0.081
13.13,5.21,0.081
13.17,5.42,0.081
13.21,5.63,0.081
13.25,5.84,0.081
13.29,6.05,0.082
13.33,6.25,0.082
13.38,6.46,0.082
13.42,6.67,0.082
13.46,6.88,0.082
13.50,7.09,0.082
13.54,7.30,0.082
13.58,7.51,0.082
13.63,7.72,0.082
13.67,7.92,0.082
13.71,8.13,0.082
13.75,8.34,0.082
13.79,8.55,0.082
13.83,8.76,0.082
13.88,8.97,0.082
13.92,9.17,0.082
13.96,9.38,0.082
14.00,9.59,0.082
14.04,9.80,0.082
14.08,10.01,0.082
14.13,10.22,0.082
14.17,10.43,0.082
14.21,10.63,0.082
14.25,10.84,0.082
14.29,11.05,0.082
14.33,11.26,0.082
14.38,11.47,0.082
14.42,11.68,0.082
14.46,11.88,0.082
14.50,12.09,0.082
14.54,12.30,0.082
14.58,12.51,0.082
14.63,12.72,0.082
14.67,12.93,0.082
14.71,13.14,0.082
14.75,13.35,0.082
14.79,13.56,0.082
14.83,13.76,0.082
14.88,13.97,0.082
14.92,14.18,0.082
14.96,14.39,0.082
15.00,14.60,0.082
15.04,14.80,0.082
15.08,15.01,0.082
15.13,15.22,0.082
15.17,15.43,0.082
15.21,15.64,0.082
15.25,15.85,0.082
15.29,16.06,0.082
15.33,16.27,0.082
15.38,16.47,0.082
15.42,16.68,0.082
15.46,16.89,0.082
15.50,17.10,0.082
15.54,17.31,0.082
15.58,17.52,0.082
15.63,17.73,0.082
15.67,17.93,0.082
15.71,18.14,0.082
15.75,18.35,0.082
15.79,18.56,0.082
15.83,18.77,0.082
15.88,18.98,0.082
15.92,19.18,0.082
15.96,19.39,0.082
16.00,19.60,0.082
16.04,19.81,0.082
16.08,20.02,0.083
16.13,20.23,0.083
16.17,20.43,0.083
16.21,20.64,0.083
16.25,20.85,0.083
16.29,21.06,0.083
16.33,21.27,0.083
16.38,21.48,0.083
16.42,21.69,0.083
16.46,21.89,0.083
16.50,22.10,0.083
16.54,22.31,0.083
16.58,22.52,0.083
16.63,22.73,0.083
16.67,22.94,0.083
16.71,23.15,0.083
16.75,23.35,0.083
16.79,23.56,0.083
16.83,23.77,0.083
16.88,23.98,0.083
16.92,24.19,0.083
16.96,24.40,0.083
17.00,24.61,0.083
17.04,24.81,0.083
17.08,25.02,0.083
17.13,25.23,0.083
17.17,25.44,0.083
17.21,25.65,0.083
17.25,25.86,0.083
17.29,26.06,0.083
17.33,26.27,0.083
17.38,26.48,0.083
17.42,26.69,0.083
17.46,26.90,0.083
17.50,27.11,0.083
17.54,27.32,0.083
17.58,27.52,0.084
17.63,27.73,0.084
17.67,27.94,0.084
17.71,28.15,0.084
17.75,28.36,0.084
17.79,28.57,0.084
17.83,28.78,0.084
17.88,28.98,0.084
17.92,29.19,0.084
17.96,29.40,0.084
18.00,29.61,0.084
18.04,29.82,0.084
18.08,30.03,0.084
18.13,30.23,0.084
18.17,30.44,0.084
18.21,30.65,0.084
18.25,30.86,0.084
18.29,31.07,0.084
18.33,31.28,0.084
18.38,31.49,0.084
18.42,31.70,0.084
18.46,31.90,0.084
18.50,32.11,0.084
18.54,32.32,0.084
18.58,32.53,0.084
18.63,32.74,0.084
18.67,32.95,0.084
18.71,33.16,0.084
18.75,33.36,0.084
18.79,33.57,0.084
18.83,33.78,0.084
18.88,33.99,0.084
18.92,34.20,0.084
18.96,34.41,0.084
19.00,34.61,0.084
19.04,34.82,0.084
19.08,35.03,0.084
19.13,35.24,0.084
19.17,35.45,0.084
19.21,35.66,0.084
19.25,35.86,0.084
19.29,36.07,0.084
19.33,36.28,0.084
19.38,36.49,0.084
19.42,36.70,0.084
19.46,36.91,0.084
19.50,37.12,0.084
19.54,37.32,0.084
19.58,37.53,0.084
19.63,37.74,0.084
19.67,37.95,0.084
19.71,38.16,0.084
19.75,38.37,0.085
19.79,38.58,0.085
19.83,38.78,0.085
19.88,38.99,0.085
19.92,39.20,0.085
19.96,39.41,0.085
20.00,39.62,0.085
20.04,39.83,0.085
20.08,40.03,0.085
20.13,40.24,0.085
20.17,40.45,0.085
20.21,40.66,0.085
20.25,40.87,0.085
20.29,41.08,0.085
20.33,41.29,0.085
20.38,41.49,0.085
20.42,41.70,0.085
20.46,41.91,0.085
20.50,42.12,0.085
20.54,42.33,0.085
20.58,42.54,0.085
20.63,42.75,0.085
20.67,42.95,0.085
20.71,43.16,0.085
20.75,43.37,0.085
20.79,43.58,0.085
20.83,43.79,0.085
20.88,44.00,0.085
20.92,44.21,0.085
20.96,44.41,0.085
21.00,44.62,0.085
21.04,44.83,0.085
21.08,45.04,0.085
21.13,45.25,0.085
21.17,45.46,0.085
21.21,45.66,0.085
21.25,45.87,0.085
21.29,46.08,0.085
21.33,46.29,0.085
21.38,46.50,0.085
21.42,46.71,0.085
21.46,46.92,0.085
21.50,47.12,0.085
21.54,47.33,0.085
21.58,47.54,0.085
21.63,47.75,0.085
21.67,47.96,0.086
21.71,48.17,0.086
21.75,48.37,0.086
21.79,48.58,0.086
21.83,48.79,0.086
21.88,49.00,0.086
21.92,49.21,0.086
21.96,49.42,0.086
22.00,49.63,0.086
22.04,49.83,0.086
22.08,50.04,0.086
22.13,50.25,0.086
22.17,50.46,0.086
22.21,50.67,0.086
22.25,50.88,0.086
22.29,51.09,0.086
22.33,51.29,0.086
22.38,51.50,0.086
22.42,51.71,0.086
22.46,51.92,0.086
22.50,52.13,0.086
22.54,52.34,0.086
22.58,52.54,0.086
22.63,52.75,0.086
22.67,52.96,0.086
22.71,53.17,0.086
22.75,53.38,0.086
22.79,53.59,0.086
22.83,53.79,0.086
22.88,54.00,0.086
22.92,54.21,0.086
22.96,54.42,0.086
23.00,54.63,0.086
23.04,54.84,0.086
23.08,55.05,0.086
23.13,55.25,0.086
23.17,55.46,0.086
23.21,55.67,0.086
23.25,55.88,0.086
23.29,56.09,0.086
23.33,56.30,0.086
23.38,56.50,0.086
23.42,56.71,0.086
23.46,56.92,0.086
23.50,57.13,0.086
23.54,57.34,0.086
23.58,57.55,0.087
23.63,57.76,0.087
23.67,57.96,0.087
23.71,58.17,0.087
23.75,58.38,0.087
23.79,58.59,0.087
23.83,58.80,0.087
23.88,59.01,0.087
23.92,59.22,0.087
23.96,59.42,0.087
24.00,59.63,0.087
24.04,59.84,0.087
24.08,60.05,0.087
24.13,60.26,0.087
24.17,60.47,0.087
24.21,60.68,0.087
24.25,60.88,0.087
24.29,61.09,0.087
24.33,61.30,0.087
24.38,61.51,0.087
24.42,61.72,0.087
24.46,61.92,0.087
24.50,62.13,0.087
24.54,62.34,0.087
24.58,62.55,0.087
24.63,62.76,0.087
24.67,62.97,0.087
24.71,63.18,0.087
24.75,63.39,0.087
24.79,63.59,0.088
24.83,63.80,0.088
24.88,64.01,0.088
24.92,64.22,0.088
24.96,64.43,0.088
25.00,64.64,0.088
25.04,64.85,0.088
25.08,65.05,0.088
25.13,65.26,0.088
25.17,65.47,0.088
25.21,65.68,0.088
25.25,65.89,0.088
25.29,66.10,0.088
25.33,66.31,0.088
25.38,66.51,0.088
25.42,66.72,0.088
25.46,66.93,0.088
25.50,67.14,0.088
25.54,67.35,0.088
25.58,67.56,0.088
25.63,67.76,0.088
25.67,67.97,0.088
25.71,68.18,0.088
25.75,68.39,0.088
25.79,68.60,0.088
25.83,68.81,0.088
25.88,69.02,0.088
25.92,69.22,0.088
25.96,69.43,0.088
26.00,69.64,0.088
26.04,69.85,0.088
26.08,70.06,0.088
26.13,70.27,0.088
26.17,70.48,0.088
26.21,70.68,0.088
26.25,70.89,0.088
26.29,71.10,0.088
26.33,71.31,0.088
26.38,71.52,0.088
26.42,71.72,0.088
26.46,71.93,0.089
26.50,72.14,0.089
26.54,72.35,0.089
26.58,72.56,0.089
26.63,72.77,0.089
26.67,72.98,0.089
26.71,73.18,0.089
26.75,73.39,0.088
26.79,73.60,0.089
26.83,73.81,0.089
26.88,74.02,0.089
26.92,74.23,0.089
26.96,74.44,0.089
27.00,74.64,0.089
27.04,74.85,0.089
27.08,75.06,0.089
27.13,75.27,0.089
27.17,75.48,0.089
27.21,75.69,0.089
27.25,75.90,0.089
27.29,76.10,0.089
27.33,76.31,0.089
27.38,76.52,0.089
27.42,76.73,0.089
27.46,76.94,0.089
27.50,77.15,0.089
27.54,77.36,0.089
27.58,77.56,0.089
27.63,77.77,0.089
27.67,77.98,0.089
27.71,78.19,0.089
27.75,78.40,0.089
27.79,78.60,0.089
27.83,78.81,0.089
27.88,79.02,0.089
27.92,79.23,0.089
27.96,79.44,0.089
28.00,79.65,0.089
28.04,79.86,0.089
28.08,80.06,0.089
28.13,80.27,0.089
28.17,80.48,0.089
28.21,80.69,0.089
28.25,80.90,0.089
28.29,81.11,0.089
28.33,81.32,0.089
28.38,81.53,0.089
28.42,81.73,0.089
28.46,81.94,0.089
28.50,82.15,0.089
28.54,82.36,0.089
28.58,82.57,0.089
28.63,82.78,0.090
28.67,82.98,0.090
28.71,83.19,0.089
28.75,83.40,0.089
28.79,83.61,0.089
28.83,83.82,0.089
28.88,84.03,0.089
28.92,84.24,0.089
28.96,84.44,0.089
29.00,84.65,0.089
29.04,84.86,0.089
29.08,85.07,0.089
29.13,85.28,0.089
29.17,85.48,0.089
29.21,85.69,0.089
29.25,85.90,0.090
29.29,86.11,0.089
29.33,86.32,0.090
29.38,86.53,0.090
29.42,86.74,0.090
29.46,86.94,0.090
29.50,87.15,0.090
29.54,87.36,0.090
29.58,87.57,0.090
29.63,87.78,0.090
29.67,87.99,0.090
29.71,88.20,0.090
29.75,88.40,0.090
29.79,88.61,0.090
29.83,88.82,0.090
29.88,89.03,0.090
29.92,89.24,0.090
29.96,89.45,0.090
30.00,89.66,0.090
30.04,89.86,0.090
30.08,90.07,0.090
30.13,90.28,0.090
30.17,90.49,0.090
30.21,90.70,0.090
30.25,90.91,0.090
30.29,91.11,0.090
30.33,91.32,0.090
30.38,91.53,0.090
30.42,91.74,0.090
30.46,91.95,0.090
30.50,92.16,0.090
30.54,92.36,0.090
30.58,92.57,0.090
30.63,92.78,0.091
30.67,92.99,0.091
30.71,93.20,0.091
30.75,93.41,0.091
30.79,93.62,0.091
30.83,93.82,0.091
30.88,94.03,0.091
30.92,94.24,0.091
30.96,94.45,0.091
31.00,94.66,0.091
31.04,94.87,0.091
31.08,95.07,0.091
31.13,95.28,0.091
31.17,95.49,0.091
31.21,95.70,0.091
31.25,95.91,0.091
31.29,96.12,0.091
31.33,96.33,0.091
31.38,96.53,0.091
31.42,96.74,0.091
31.46,96.95,0.091
31.50,97.16,0.091
31.54,97.37,0.091
31.58,97.58,0.091
31.63,97.79,0.091
31.67,97.99,0.091
31.71,98.20,0.091
31.75,98.41,0.091
31.79,98.62,0.091
31.83,98.83,0.091
31.88,99.04,0.091
31.92,99.24,0.091
31.96,99.45,0.091
32.00,99.66,0.091
32.04,99.87,0.092
32.08,100.08,0.092
32.13,100.29,0.092
32.17,100.50,0.091
32.21,100.70,0.091
32.25,100.91,0.091
32.29,101.12,0.091
32.33,101.33,0.092
32.38,101.54,0.092
32.42,101.75,0.092
32.46,101.95,0.092
32.50,102.16,0.092
32.54,102.37,0.092
32.58,102.58,0.092
32.63,102.79,0.092
32.67,103.00,0.092
32.71,103.21,0.092
32.75,103.42,0.092
32.79,103.62,0.092
32.83,103.83,0.092
32.88,104.04,0.092
32.92,104.25,0.092
32.96,104.46,0.092
33.00,104.66,0.092
33.04,104.87,0.092
33.08,105.08,0.092
33.13,105.29,0.092
33.17,105.50,0.092
33.21,105.71,0.092
33.25,105.92,0.092
33.29,106.12,0.092
33.33,106.33,0.092
33.38,106.54,0.092
33.42,106.75,0.092
33.46,106.96,0.092
33.50,107.17,0.092
33.54,107.37,0.092
33.58,107.58,0.092
33.63,107.79,0.092
33.67,108.00,0.092
33.71,108.21,0.092
33.75,108.42,0.093
33.79,108.63,0.093
33.83,108.83,0.093
33.88,109.04,0.093
33.92,109.25,0.093
33.96,109.46,0.093
34.00,109.67,0.093
34.04,109.88,0.093
34.08,110.09,0.093
34.13,110.29,0.093
34.17,110.50,0.093
34.21,110.71,0.093
34.25,110.92,0.093
34.29,111.13,0.093
34.33,111.34,0.093
34.38,111.54,0.093
34.42,111.75,0.093
34.46,111.96,0.093
34.50,112.17,0.093
34.54,112.38,0.093
34.58,112.59,0.093
34.63,112.79,0.093
34.67,113.00,0.093
34.71,113.21,0.093
34.75,113.42,0.093
34.79,113.63,0.093
34.83,113.84,0.093
34.88,114.05,0.093
34.92,114.25,0.093
34.96,114.46,0.093
35.00,114.67,0.093
35.04,114.88,0.093
35.08,115.09,0.093
35.13,115.30,0.093
35.17,115.50,0.093
35.21,115.71,0.093
35.25,115.92,0.093
35.29,116.13,0.093
35.33,116.34,0.093
35.38,116.55,0.093
35.42,116.76,0.093
35.46,116.96,0.093
35.50,117.17,0.094
35.54,117.38,0.094
35.58,117.59,0.094
35.63,117.80,0.094
35.67,118.00,0.094
35.71,118.21,0.094
35.75,118.42,0.094
35.79,118.63,0.094
35.83,118.84,0.094
35.88,119.05,0.094
35.92,119.26,0.094
35.96,119.46,0.094
36.00,119.67,0.094
36.04,119.88,0.094
36.08,120.09,0.094
36.13,120.30,0.094
36.17,120.51,0.094
36.21,120.72,0.094
36.25,120.93,0.094
36.29,121.13,0.094
36.33,121.34,0.094
36.38,121.55,0.094
36.42,121.76,0.094
36.46,121.97,0.094
36.50,122.18,0.094
36.54,122.39,0.094
36.58,122.59,0.094
36.63,122.80,0.094
36.67,123.01,0.094
36.71,123.22,0.094
36.75,123.43,0.094
36.79,123.64,0.094
36.83,123.84,0.094
36.88,124.05,0.094
36.92,124.26,0.094
36.96,124.47,0.094
37.00,124.68,0.094
37.04,124.89,0.094
37.08,125.09,0.094
37.13,125.30,0.094
37.17,125.51,0.094
37.21,125.72,0.094
37.25,125.93,0.094
37.29,126.14,0.094
37.33,126.35,0.094
37.38,126.55,0.094
37.42,126.76,0.094
37.46,126.97,0.094
37.50,127.18,0.094
37.54,127.39,0.094
37.58,127.60,0.094
37.63,127.81,0.094
37.67,128.01,0.094
37.71,128.22,0.094
37.75,128.43,0.094
37.79,128.64,0.094
37.83,128.85,0.094
37.88,129.05,0.094
37.92,129.26,0.094
37.96,129.47,0.094
38.00,129.68,0.094
38.04,129.89,0.094
38.08,130.10,0.094
38.13,130.31,0.094
38.17,130.51,0.094
38.21,130.72,0.094
38.25,130.93,0.094
38.29,131.14,0.094
38.33,131.35,0.094
38.38,131.55,0.095
38.42,131.76,0.095
38.46,131.97,0.095
38.50,132.18,0.095
38.54,132.39,0.095
38.58,132.60,0.095
38.63,132.81,0.095
38.67,133.01,0.095
38.71,133.22,0.095
38.75,133.43,0.095
38.79,133.64,0.095
38.83,133.85,0.095
38.88,134.06,0.095
38.92,134.27,0.095
38.96,134.47,0.095
39.00,134.68,0.095
39.04,134.89,0.095
39.08,135.10,0.095
39.13,135.31,0.095
39.17,135.52,0.095
39.21,135.72,0.095
39.25,135.93,0.095
39.29,136.14,0.095
39.33,136.35,0.095
39.38,136.56,0.095
39.42,136.77,0.095
39.46,136.97,0.095
39.50,137.18,0.095
39.54,137.39,0.095
39.58,137.60,0.095
39.63,137.81,0.095
39.67,138.02,0.095
39.71,138.22,0.095
39.75,138.43,0.095
39.79,138.64,0.095
39.83,138.85,0.095
39.88,139.06,0.095
39.92,139.27,0.095
39.96,139.48,0.095
40.00,139.68,0.095
40.04,139.89,0.096
40.08,140.10,0.096
40.13,140.31,0.096
40.17,140.52,0.096
40.21,140.73,0.096
40.25,140.94,0.096
40.29,141.14,0.096
40.33,141.35,0.096
40.38,141.56,0.096
40.42,141.77,0.096
40.46,141.98,0.096
40.50,142.19,0.096
40.54,142.40,0.096
40.58,142.60,0.096
40.63,142.81,0.096
40.67,143.02,0.096
40.71,143.23,0.096
40.75,143.44,0.096
40.79,143.65,0.096
40.83,143.86,0.096
40.88,144.06,0.096
40.92,144.27,0.096
40.96,144.48,0.096
41.00,144.69,0.096
41.04,144.90,0.097
41.08,145.10,0.097
41.13,145.31,0.097
41.17,145.52,0.097
41.21,145.73,0.097
41.25,145.94,0.097
41.29,146.15,0.097
41.33,146.36,0.097
41.38,146.56,0.097
41.42,146.77,0.097
41.46,146.98,0.097
41.50,147.19,0.097
41.54,147.40,0.097
41.58,147.61,0.097
41.63,147.81,0.097
41.67,148.02,0.097
41.71,148.23,0.097
41.75,148.44,0.097
41.79,148.65,0.097
41.83,148.86,0.097
41.88,149.07,0.097
41.92,149.27,0.097
41.96,149.48,0.097
42.00,149.69,0.097
42.04,149.90,0.097
42.08,150.11,0.097
42.13,150.31,0.098
42.17,150.52,0.098
42.21,150.73,0.098
42.25,150.94,0.098
42.29,151.15,0.098
42.33,151.36,0.098
42.38,151.57,0.098
42.42,151.78,0.098
42.46,151.98,0.098
42.50,152.19,0.098
42.54,152.40,0.098
42.58,152.61,0.098
42.63,152.82,0.098
42.67,153.02,0.098
42.71,153.23,0.098
42.75,153.44,0.098
42.79,153.65,0.098
42.83,153.86,0.098
42.88,154.07,0.098
42.92,154.28,0.098
42.96,154.48,0.098
43.00,154.69,0.098
43.04,154.90,0.098
43.08,155.11,0.098
43.13,155.32,0.099
43.17,155.53,0.099
43.21,155.73,0.099
43.25,155.94,0.099
43.29,156.15,0.099
43.33,156.36,0.099
43.38,156.57,0.099
43.42,156.78,0.099
43.46,156.99,0.099
43.50,157.20,0.099
43.54,157.40,0.099
43.58,157.61,0.099
43.63,157.82,0.099
43.67,158.03,0.099
43.71,158.23,0.099
43.75,158.44,0.099
43.79,158.65,0.099
43.83,158.86,0.099
43.88,159.07,0.099
43.92,159.28,0.099
43.96,159.49,0.099
44.00,159.69,0.099
44.04,159.90,0.099
44.08,160.11,0.099
44.13,160.32,0.099
44.17,160.53,0.099
44.21,160.74,0.100
44.25,160.95,0.100
44.29,161.15,0.100
44.33,161.36,0.100
44.38,161.57,0.100
44.42,161.78,0.100
44.46,161.99,0.100
44.50,162.19,0.100
44.54,162.40,0.100
44.58,162.61,0.100
44.63,162.82,0.100
44.67,163.03,0.100
44.71,163.24,0.100
44.75,163.45,0.100
44.79,163.65,0.100
44.83,163.86,0.100
44.88,164.07,0.100
44.92,164.28,0.100
44.96,164.49,0.100
45.00,164.70,0.100
45.04,164.91,0.100
45.08,165.11,0.100
45.13,165.32,0.100
45.17,165.53,0.100
45.21,165.74,0.100
45.25,165.95,0.100
45.29,166.16,0.100
45.33,166.36,0.100
45.38,166.57,0.100
45.42,166.78,0.100
45.46,166.99,0.101
45.50,167.20,0.101
45.54,167.41,0.101
45.58,167.62,0.101
45.63,167.83,0.101
45.67,168.03,0.101
45.71,168.24,0.101
45.75,168.45,0.101
45.79,168.66,0.101
45.83,168.87,0.101
45.88,169.08,0.101
45.92,169.28,0.101
45.96,169.49,0.101
46.00,169.70,0.101
46.04,169.91,0.101
46.08,170.12,0.101
46.13,170.32,0.101
46.17,170.53,0.102
46.21,170.74,0.102
46.25,170.95,0.102
46.29,171.16,0.102
46.33,171.37,0.102
46.38,171.58,0.102
46.42,171.78,0.102
46.46,171.99,0.102
46.50,172.20,0.102
46.54,172.41,0.102
46.58,172.62,0.102
46.63,172.82,0.102
46.67,173.03,0.102
46.71,173.24,0.102
46.75,173.45,0.102
46.79,173.66,0.102
46.83,173.87,0.102
46.88,174.08,0.102
46.92,174.28,0.102
46.96,174.49,0.102
47.00,174.70,0.102
47.04,174.91,0.102
47.08,175.12,0.102
47.13,175.33,0.102
47.17,175.53,0.102
47.21,175.74,0.102
47.25,175.95,0.102
47.29,176.16,0.102
47.33,176.37,0.102
47.38,176.58,0.102
47.42,176.78,0.102
47.46,176.99,0.102
47.50,177.20,0.102
47.54,177.41,0.102
47.58,177.62,0.103
47.63,177.83,0.103
47.67,178.04,0.103
47.71,178.24,0.103
47.75,178.45,0.103
47.79,178.66,0.103
47.83,178.87,0.103
47.88,179.08,0.103
47.92,179.29,0.103
47.96,179.50,0.103
48.00,179.70,0.103
48.04,179.91,0.103
48.08,180.12,0.103
48.13,180.33,0.103
48.17,180.54,0.103
48.21,180.75,0.103
48.25,180.95,0.103
48.29,181.16,0.104
48.33,181.37,0.104
48.38,181.58,0.104
48.42,181.79,0.104
48.46,182.00,0.104
48.50,182.21,0.104
48.54,182.41,0.104
48.58,182.62,0.104
48.63,182.83,0.104
48.67,183.04,0.104
48.71,183.25,0.104
48.75,183.46,0.104
48.79,183.66,0.104
48.83,183.87,0.104
48.88,184.08,0.104
48.92,184.29,0.104
48.96,184.50,0.104
49.00,184.71,0.104
49.04,184.91,0.104
49.08,185.12,0.104
49.13,185.33,0.104
49.17,185.54,0.104
49.21,185.75,0.105
49.25,185.95,0.105
49.29,186.16,0.105
49.33,186.37,0.105
49.38,186.58,0.105
49.42,186.79,0.105
49.46,187.00,0.105
49.50,187.21,0.105
49.54,187.41,0.105
49.58,187.62,0.105
49.63,187.83,0.105
49.67,188.04,0.105
49.71,188.25,0.105
49.75,188.46,0.105
49.79,188.67,0.105
49.83,188.87,0.105
49.88,189.08,0.106
49.92,189.29,0.106
49.96,189.50,0.105
50.00,189.71,0.105
50.04,189.91,0.105
50.08,190.12,0.105
50.13,190.33,0.105
50.17,190.54,0.105
50.21,190.75,0.105
50.25,190.96,0.105
50.29,191.16,0.106
50.33,191.37,0.106
50.38,191.58,0.106
50.42,191.79,0.106
50.46,192.00,0.106
50.50,192.21,0.106
50.54,192.42,0.106
50.58,192.63,0.106
50.63,192.83,0.106
50.67,193.04,0.106
50.71,193.25,0.106
50.75,193.46,0.106
50.79,193.67,0.106
50.83,193.88,0.106
50.88,194.08,0.107
50.92,194.29,0.107
50.96,194.50,0.107
51.00,194.71,0.107
51.04,194.92,0.107
51.08,195.12,0.107
51.13,195.33,0.107
51.17,195.54,0.107
51.21,195.75,0.107
51.25,195.96,0.107
51.29,196.17,0.107
51.33,196.38,0.107
51.38,196.59,0.107
51.42,196.79,0.107
51.46,197.00,0.107
51.50,197.21,0.107
51.54,197.42,0.107
51.58,197.63,0.107
51.63,197.83,0.107
51.67,198.04,0.107
51.71,198.25,0.107
51.75,198.46,0.107
51.79,198.67,0.107
51.83,198.88,0.107
51.88,199.09,0.107
51.92,199.29,0.108
51.96,199.50,0.108
52.00,199.71,0.108
52.04,199.92,0.108
52.08,200.13,0.108
52.13,200.34,0.108
52.17,200.55,0.108
52.21,200.75,0.108
52.25,200.96,0.108
52.29,201.17,0.108
52.33,201.38,0.108
52.38,201.59,0.108
52.42,201.80,0.108
52.46,202.00,0.108
52.50,202.21,0.108
52.54,202.42,0.108
52.58,202.63,0.108
52.63,202.84,0.108
52.67,203.05,0.109
52.71,203.25,0.109
52.75,203.46,0.109
52.79,203.67,0.109
52.83,203.88,0.109
52.88,204.09,0.109
52.92,204.30,0.109
52.96,204.50,0.109
53.00,204.71,0.109
53.04,204.92,0.109
53.08,205.13,0.109
53.13,205.34,0.109
53.17,205.55,0.109
53.21,205.76,0.109
53.25,205.96,0.109
53.29,206.17,0.109
53.33,206.38,0.109
53.38,206.59,0.109
53.42,206.80,0.109
53.46,207.01,0.110
53.50,207.22,0.110
53.54,207.43,0.110
53.58,207.63,0.110
53.63,207.84,0.110
53.67,208.05,0.110
53.71,208.26,0.110
53.75,208.46,0.110
53.79,208.67,0.110
53.83,208.88,0.110
53.88,209.09,0.110
53.92,209.30,0.110
53.96,209.51,0.110
54.00,209.72,0.110
54.04,209.92,0.110
54.08,210.13,0.110
54.13,210.34,0.110
54.17,210.55,0.111
54.21,210.76,0.111
54.25,210.96,0.111
54.29,211.17,0.111
54.33,211.38,0.111
54.38,211.59,0.111
54.42,211.80,0.111
54.46,212.01,0.111
54.50,212.21,0.111
54.54,212.42,0.111
54.58,212.63,0.111
54.63,212.84,0.111
54.67,213.05,0.111
54.71,213.26,0.111
54.75,213.47,0.112
54.79,213.67,0.112
54.83,213.88,0.112
54.88,214.09,0.112
54.92,214.30,0.112
54.96,214.51,0.112
55.00,214.72,0.112
55.04,214.93,0.112
55.08,215.13,0.112
55.13,215.34,0.112
55.17,215.55,0.112
55.21,215.76,0.112
55.25,215.97,0.112
55.29,216.17,0.112
55.33,216.38,0.112
55.38,216.59,0.113
55.42,216.80,0.113
55.46,217.01,0.113
55.50,217.22,0.113
55.54,217.43,0.113
55.58,217.63,0.113
55.63,217.84,0.113
55.67,218.05,0.113
55.71,218.26,0.113
55.75,218.47,0.113
55.79,218.68,0.113
55.83,218.88,0.113
55.88,219.09,0.113
55.92,219.30,0.113
55.96,219.51,0.113
56.00,219.72,0.113
56.04,219.93,0.113
56.08,220.13,0.114
56.13,220.34,0.114
56.17,220.55,0.114
56.21,220.76,0.114
56.25,220.97,0.114
56.29,221.18,0.114
56.33,221.39,0.114
56.38,221.59,0.114
56.42,221.80,0.114
56.46,222.01,0.114
56.50,222.22,0.115
56.54,222.43,0.115
56.58,222.64,0.115
56.63,222.84,0.115
56.67,223.05,0.115
56.71,223.26,0.115
56.75,223.47,0.115
56.79,223.68,0.115
56.83,223.89,0.115
56.88,224.10,0.115
56.92,224.30,0.115
56.96,224.51,0.115
57.00,224.72,0.115
57.04,224.93,0.115
57.08,225.14,0.115
57.13,225.34,0.116
57.17,225.55,0.116
57.21,225.76,0.116
57.25,225.97,0.116
57.29,226.18,0.116
57.33,226.39,0.116
57.38,226.60,0.116
57.42,226.80,0.116
57.46,227.01,0.116
57.50,227.22,0.116
57.54,227.43,0.116
57.58,227.64,0.116
57.63,227.85,0.116
57.67,228.06,0.116
57.71,228.26,0.116
57.75,228.47,0.116
57.79,228.68,0.117
57.83,228.89,0.117
57.88,229.10,0.117
57.92,229.30,0.117
57.96,229.51,0.117
58.00,229.72,0.117
58.04,229.93,0.117
58.08,230.14,0.117
58.13,230.35,0.117
58.17,230.56,0.117
58.21,230.76,0.118
58.25,230.97,0.118
58.29,231.18,0.118
58.33,231.39,0.118
58.38,231.60,0.118
58.42,231.81,0.118
58.46,232.01,0.118
58.50,232.22,0.118
58.54,232.43,0.118
58.58,232.64,0.118
58.63,232.85,0.118
58.67,233.06,0.118
58.71,233.26,0.118
58.75,233.47,0.119
58.79,233.68,0.119
58.83,233.89,0.119
58.88,234.10,0.119
58.92,234.31,0.119
58.96,234.51,0.119
59.00,234.72,0.119
59.04,234.93,0.119
59.08,235.14,0.119
59.13,235.35,0.119
59.17,235.56,0.119
59.21,235.77,0.119
59.25,235.97,0.119
59.29,236.18,0.119
59.33,236.39,0.119
59.38,236.60,0.119
59.42,236.81,0.120
59.46,237.01,0.120
59.50,237.22,0.120
59.54,237.43,0.120
59.58,237.64,0.120
59.63,237.85,0.120
59.67,238.06,0.120
59.71,238.27,0.120
59.75,238.47,0.120
59.79,238.68,0.120
59.83,238.89,0.120
59.88,239.10,0.120
59.92,239.31,0.120
59.96,239.51,0.120
60.00,239.72,0.120
60.04,239.93,0.120
60.08,240.14,0.120
60.13,240.35,0.120
60.17,240.56,0.121
60.21,240.77,0.121
60.25,240.98,0.121
60.29,241.19,0.121
60.33,241.40,0.121
60.38,241.61,0.121
60.42,241.82,0.121
60.46,242.02,0.121
60.50,242.23,0.121
60.54,242.44,0.121
60.58,242.65,0.121
60.63,242.86,0.120
60.67,243.06,0.120
60.71,243.27,0.120
60.75,243.48,0.120
60.79,243.69,0.120
60.83,243.89,0.120
60.88,244.10,0.120
60.92,244.31,0.120
60.96,244.52,0.120
61.00,244.73,0.120
61.04,244.93,0.120
61.08,245.14,0.120
61.13,245.35,0.120
61.17,245.56,0.120
61.21,245.77,0.120
61.25,245.98,0.120
61.29,246.19,0.120
61.33,246.39,0.120
61.38,246.60,0.120
61.42,246.81,0.120
61.46,247.02,0.121
61.50,247.23,0.121
61.54,247.43,0.121
61.58,247.64,0.121
61.63,247.85,0.121
61.67,248.06,0.121
61.71,248.27,0.121
61.75,248.48,0.121
61.79,248.68,0.121
61.83,248.89,0.121
61.88,249.10,0.121
61.92,249.31,0.122
61.96,249.52,
61.99,,

[step]
Ramp 5.00 °C/min to -60.00 °C
Time,Temperature,Heat Flow (Normalized)
min,°C,W/g
62.99,250.15,-0.036
63.03,250.15,-0.036
63.07,250.12,-0.063
63.11,250.03,-0.116
63.15,249.87,-0.157
63.19,249.69,-0.177
63.24,249.49,-0.182
63.28,249.29,-0.184
63.32,249.08,-0.185
63.36,248.87,-0.186
63.40,248.67,-0.186
63.44,248.46,-0.187
63.49,248.25,-0.187
63.53,248.05,-0.188
63.57,247.84,-0.188
63.61,247.63,-0.188
63.65,247.43,-0.188
63.69,247.22,-0.188
63.74,247.01,-0.188
63.78,246.81,-0.188
63.82,246.60,-0.188
63.86,246.39,-0.188
63.90,246.18,-0.189
63.94,245.98,-0.189
63.99,245.77,-0.189
64.03,245.56,-0.189
64.07,245.35,-0.189
64.11,245.14,-0.189
64.15,244.94,-0.189
64.19,244.73,-0.188
64.24,244.52,-0.188
64.28,244.32,-0.188
64.32,244.11,-0.188
64.36,243.90,-0.188
64.40,243.69,-0.188
64.44,243.48,-0.188
64.49,243.28,-0.188
64.53,243.07,-0.188
64.57,242.86,-0.188
64.61,242.65,-0.188
64.65,242.44,-0.188
64.69,242.23,-0.188
64.74,242.03,-0.188
64.78,241.82,-0.188
64.82,241.61,-0.188
64.86,241.40,-0.188
64.90,241.19,-0.188
64.94,240.99,-0.188
64.99,240.78,-0.188
65.03,240.57,-0.188
65.07,240.36,-0.188
65.11,240.15,-0.188
65.15,239.94,-0.188
65.19,239.74,-0.188
65.24,239.53,-0.188
65.28,239.32,-0.187
65.32,239.11,-0.187
65.36,238.90,-0.187
65.40,238.69,-0.187
65.44,238.49,-0.187
65.49,238.28,-0.187
65.53,238.07,-0.187
65.57,237.86,-0.187
65.61,237.65,-0.187
65.65,237.44,-0.187
65.69,237.24,-0.187
65.74,237.03,-0.187
65.78,236.82,-0.187
65.82,236.61,-0.187
65.86,236.40,-0.187
65.90,236.19,-0.187
65.94,235.98,-0.187
65.99,235.78,-0.186
66.03,235.57,-0.186
66.07,235.36,-0.186
66.11,235.15,-0.186
66.15,234.95,-0.186
66.19,234.74,-0.186
66.24,234.53,-0.186
66.28,234.32,-0.186
66.32,234.11,-0.186
66.36,233.90,-0.186
66.40,233.69,-0.186
66.44,233.49,-0.186
66.49,233.28,-0.186
66.53,233.07,-0.186
66.57,232.86,-0.186
66.61,232.66,-0.186
66.65,232.45,-0.186
66.69,232.24,-0.186
66.74,232.03,-0.186
66.78,231.82,-0.186
66.82,231.61,-0.186
66.86,231.41,-0.186
66.90,231.20,-0.186
66.94,230.99,-0.186
66.99,230.78,-0.186
67.03,230.57,-0.186
67.07,230.37,-0.186
67.11,230.16,-0.187
67.15,229.95,-0.187
67.19,229.74,-0.187
67.24,229.53,-0.187
67.28,229.32,-0.186
67.32,229.12,-0.186
67.36,228.91,-0.186
67.40,228.70,-0.187
67.44,228.49,-0.187
67.49,228.28,-0.187
67.53,228.07,-0.187
67.57,227.86,-0.187
67.61,227.65,-0.187
67.65,227.45,-0.187
67.69,227.24,-0.186
67.74,227.03,-0.186
67.78,226.82,-0.186
67.82,226.61,-0.186
67.86,226.41,-0.186
67.90,226.20,-0.186
67.94,225.99,-0.186
67.99,225.78,-0.186
68.03,225.57,-0.186
68.07,225.37,-0.186
68.11,225.16,-0.186
68.15,224.95,-0.186
68.19,224.74,-0.186
68.24,224.53,-0.186
68.28,224.32,-0.187
68.32,224.12,-0.186
68.36,223.91,-0.186
68.40,223.70,-0.186
68.45,223.49,-0.186
68.49,223.28,-0.187
68.53,223.07,-0.187
68.57,222.86,-0.187
68.61,222.66,-0.187
68.65,222.45,-0.187
68.70,222.24,-0.187
68.74,222.03,-0.187
68.78,221.82,-0.186
68.82,221.61,-0.186
68.86,221.41,-0.186
68.90,221.20,-0.186
68.95,220.99,-0.186
68.99,220.78,-0.187
69.03,220.57,-0.187
69.07,220.36,-0.186
69.11,220.16,-0.186
69.15,219.95,-0.186
69.20,219.74,-0.186
69.24,219.53,-0.186
69.28,219.32,-0.186
69.32,219.12,-0.187
69.36,218.91,-0.187
69.40,218.70,-0.186
69.45,218.49,-0.186
69.49,218.28,-0.186
69.53,218.08,-0.186
69.57,217.87,-0.187
69.61,217.66,-0.187
69.65,217.45,-0.187
69.70,217.24,-0.187
69.74,217.03,-0.187
69.78,216.82,-0.187
69.82,216.61,-0.187
69.86,216.40,-0.187
69.90,216.20,-0.187
69.95,215.99,-0.187
69.99,215.78,-0.186
70.03,215.57,-0.186
70.07,215.36,-0.186
70.11,215.16,-0.186
70.15,214.95,-0.186
70.20,214.74,-0.186
70.24,214.53,-0.186
70.28,214.33,-0.186
70.32,214.12,-0.186
70.36,213.91,-0.186
70.40,213.70,-0.186
70.45,213.49,-0.186
70.49,213.28,-0.186
70.53,213.08,-0.186
70.57,212.87,-0.186
70.61,212.66,-0.186
70.65,212.45,-0.186
70.70,212.24,-0.186
70.74,212.03,-0.186
70.78,211.82,-0.186
70.82,211.62,-0.186
70.86,211.41,-0.186
70.90,211.20,-0.186
70.95,210.99,-0.186
70.99,210.78,-0.186
71.03,210.58,-0.186
71.07,210.37,-0.186
71.11,210.16,-0.186
71.15,209.95,-0.186
71.20,209.74,-0.186
71.24,209.54,-0.186
71.28,209.33,-0.186
71.32,209.12,-0.186
71.36,208.91,-0.186
71.40,208.70,-0.186
71.45,208.49,-0.186
71.49,208.29,-0.186
71.53,208.08,-0.186
71.57,207.87,-0.186
71.61,207.66,-0.186
71.65,207.45,-0.186
71.70,207.24,-0.186
71.74,207.03,-0.186
71.78,206.82,-0.187
71.82,206.62,-0.187
71.86,206.41,-0.187
71.90,206.20,-0.187
71.95,205.99,-0.186
71.99,205.78,-0.186
72.03,205.58,-0.186
72.07,205.37,-0.187
72.11,205.16,-0.187
72.15,204.95,-0.186
72.20,204.74,-0.187
72.24,204.53,-0.187
72.28,204.33,-0.187
72.32,204.12,-0.187
72.36,203.91,-0.187
72.40,203.70,-0.187
72.45,203.49,-0.187
72.49,203.29,-0.187
72.53,203.08,-0.187
72.57,202.87,-0.187
72.61,202.66,-0.187
72.65,202.45,-0.187
72.70,202.24,-0.187
72.74,202.03,-0.187
72.78,201.83,-0.187
72.82,201.62,-0.187
72.86,201.41,-0.187
72.90,201.20,-0.187
72.95,201.00,-0.187
72.99,200.79,-0.187
73.03,200.58,-0.187
73.07,200.37,-0.187
73.11,200.16,-0.187
73.15,199.95,-0.187
73.20,199.75,-0.187
73.24,199.54,-0.187
73.28,199.33,-0.187
73.32,199.12,-0.187
73.36,198.91,-0.187
73.40,198.70,-0.187
73.45,198.50,-0.187
73.49,198.29,-0.187
73.53,198.08,-0.187
73.57,197.87,-0.187
73.61,197.66,-0.187
73.65,197.46,-0.187
73.70,197.25,-0.187
73.74,197.04,-0.187
73.78,196.83,-0.187
73.82,196.62,-0.187
73.86,196.41,-0.187
73.90,196.20,-0.187
73.95,195.99,-0.187
73.99,195.79,-0.187
74.03,195.58,-0.187
74.07,195.37,-0.187
74.11,195.16,-0.187
74.15,194.95,-0.187
74.20,194.74,-0.187
74.24,194.53,-0.187
74.28,194.33,-0.187
74.32,194.12,-0.187
74.36,193.91,-0.187
74.40,193.70,-0.187
74.45,193.49,-0.187
74.49,193.29,-0.187
74.53,193.08,-0.187
74.57,192.87,-0.187
74.61,192.66,-0.187
74.65,192.45,-0.187
74.70,192.24,-0.187
74.74,192.04,-0.187
74.78,191.83,-0.187
74.82,191.62,-0.187
74.86,191.41,-0.187
74.90,191.20,-0.187
74.95,191.00,-0.187
74.99,190.79,-0.187
75.03,190.58,-0.187
75.07,190.37,-0.187
75.11,190.16,-0.187
75.15,189.95,-0.187
75.20,189.75,-0.187
75.24,189.54,-0.187
75.28,189.33,-0.187
75.32,189.12,-0.187
75.36,188.91,-0.187
75.40,188.71,-0.187
75.45,188.50,-0.187
75.49,188.29,-0.187
75.53,188.08,-0.187
75.57,187.87,-0.187
75.61,187.66,-0.187
75.65,187.45,-0.187
75.70,187.25,-0.187
75.74,187.04,-0.187
75.78,186.83,-0.187
75.82,186.62,-0.187
75.86,186.41,-0.187
75.90,186.20,-0.187
75.95,186.00,-0.187
[...]
281.86,88.90,0.093,0.992
281.90,89.11,0.093,0.993
281.94,89.32,0.093,0.993
281.99,89.53,0.093,0.992
282.03,89.74,0.093,0.993
282.07,89.94,0.093,0.994
282.11,90.15,0.093,0.995
282.15,90.36,0.093,0.996
282.19,90.57,0.094,0.998
282.24,90.78,0.094,0.999
282.28,90.99,0.094,0.999
282.32,91.20,0.094,0.999
282.36,91.40,0.094,1.000
282.40,91.61,0.094,1.000
282.44,91.82,0.094,1.000
282.49,92.03,0.094,1.000
282.53,92.24,0.094,1.001
282.57,92.45,0.094,1.001
282.61,92.66,0.094,1.001
282.65,92.86,0.094,1.001
282.69,93.07,0.094,1.000
282.74,93.28,0.094,1.000
282.78,93.49,0.094,1.000
282.82,93.70,0.094,1.000
282.86,93.91,0.094,1.001
282.90,94.11,0.094,1.002
282.94,94.32,0.094,1.002
282.99,94.53,0.094,1.003
283.03,94.74,0.094,1.004
283.07,94.95,0.094,1.003
283.11,95.16,0.094,1.002
283.15,95.37,0.094,1.002
283.19,95.57,0.094,1.001
283.24,95.78,0.094,1.002
283.28,95.99,0.094,1.001
283.32,96.20,0.094,1.002
283.36,96.41,0.094,1.002
283.40,96.62,0.094,1.003
283.44,96.83,0.094,1.004
283.49,97.03,0.094,1.003
283.53,97.24,0.094,1.004
283.57,97.45,0.094,1.004
283.61,97.66,0.094,1.004
283.65,97.87,0.094,1.004
283.69,98.08,0.094,1.005
283.74,98.28,0.094,1.005
283.78,98.49,0.094,1.005
283.82,98.70,0.094,1.004
283.86,98.91,0.094,1.005
283.90,99.12,0.094,1.005
283.94,99.33,0.094,1.005
283.99,99.54,0.094,1.006
284.03,99.74,0.094,1.007
284.07,99.95,0.094,1.006
284.11,100.16,0.094,1.008
284.15,100.37,0.094,1.007
284.19,100.58,0.095,1.008
284.24,100.78,0.095,1.007
284.28,100.99,0.095,1.008
284.32,101.20,0.095,1.007
284.36,101.41,0.095,1.008
284.40,101.62,0.095,1.008
284.44,101.83,0.095,1.009
284.49,102.03,0.095,1.010
284.53,102.24,0.095,1.010
284.57,102.45,0.095,1.010
284.61,102.66,0.095,1.009
284.65,102.87,0.095,1.009
284.69,103.08,0.095,1.009
284.74,103.29,0.095,1.010
284.78,103.50,0.095,1.010
284.82,103.70,0.095,1.011
284.86,103.91,0.095,1.012
284.90,104.12,0.095,1.012
284.94,104.33,0.095,1.013
284.99,104.54,0.095,1.013
285.03,104.75,0.095,1.014
285.07,104.95,0.095,1.012
285.11,105.16,0.095,1.012
285.15,105.37,0.095,1.011
285.19,105.58,0.095,1.012
285.24,105.79,0.095,1.011
285.28,106.00,0.095,1.013
285.32,106.21,0.095,1.013
285.36,106.41,0.095,1.013
285.40,106.62,0.095,1.014
285.44,106.83,0.095,1.013
285.49,107.04,0.095,1.012
285.53,107.25,0.095,1.012
285.57,107.46,0.095,1.013
285.61,107.67,0.095,1.013
285.65,107.88,0.095,1.014
285.69,108.08,0.095,1.017
285.74,108.29,0.095,1.017
285.78,108.50,0.095,1.017
285.82,108.71,0.095,1.016
285.86,108.91,0.095,1.016
285.90,109.12,0.096,1.016
285.94,109.33,0.096,1.017
285.99,109.54,0.096,1.017
286.03,109.75,0.096,1.018
286.07,109.96,0.096,1.019
286.11,110.17,0.096,1.019
286.15,110.38,0.096,1.019
286.19,110.58,0.096,1.020
286.24,110.79,0.096,1.020
286.28,111.00,0.096,1.021
286.32,111.21,0.096,1.019
286.36,111.42,0.096,1.021
286.40,111.63,0.096,1.021
286.44,111.83,0.096,1.021
286.49,112.04,0.096,1.021
286.53,112.25,0.096,1.022
286.57,112.46,0.096,1.023
286.61,112.67,0.096,1.024
286.65,112.88,0.096,1.025
286.69,113.09,0.096,1.026
286.74,113.29,0.096,1.027
286.78,113.50,0.096,1.026
286.82,113.71,0.096,1.025
286.86,113.92,0.096,1.024
286.90,114.13,0.096,1.024
286.94,114.34,0.097,1.024
286.99,114.55,0.097,1.025
287.03,114.75,0.097,1.027
287.07,114.96,0.097,1.027
287.11,115.17,0.097,1.027
287.15,115.38,0.097,1.029
287.19,115.59,0.097,1.029
287.24,115.80,0.097,1.029
287.28,116.01,0.097,1.029
287.32,116.21,0.097,1.030
287.36,116.42,0.097,1.028
287.40,116.63,0.097,1.029
287.44,116.84,0.097,1.029
287.49,117.05,0.097,1.030
287.53,117.26,0.097,1.030
287.57,117.47,0.097,1.030
287.61,117.67,0.097,1.031
287.65,117.88,0.097,1.030
287.69,118.09,0.097,1.029
287.74,118.30,0.097,1.029
287.78,118.51,0.097,1.030
287.82,118.71,0.097,1.030
287.86,118.92,0.097,1.030
287.90,119.13,0.097,1.030
287.94,119.34,0.097,1.030
287.99,119.55,0.097,1.030
288.03,119.76,0.097,1.029
288.07,119.96,0.097,1.030
288.11,120.17,0.097,1.031
288.15,120.38,0.097,1.032
288.19,120.59,0.097,1.032
288.24,120.80,0.097,1.033
288.28,121.01,0.097,1.034
288.32,121.21,0.097,1.034
288.36,121.42,0.097,1.033
288.40,121.63,0.097,1.034
288.44,121.84,0.097,1.033
288.49,122.05,0.097,1.032
288.53,122.26,0.097,1.033
288.57,122.47,0.097,1.034
288.61,122.67,0.097,1.034
288.65,122.88,0.097,1.035
288.69,123.09,0.098,1.035
288.74,123.30,0.098,1.037
288.78,123.51,0.098,1.036
288.82,123.72,0.098,1.037
288.86,123.93,0.098,1.038
288.90,124.13,0.098,1.038
288.94,124.34,0.098,1.039
288.99,124.55,0.098,1.040
289.03,124.76,0.098,1.040
289.07,124.97,0.098,1.040
289.11,125.18,0.098,1.039
289.15,125.39,0.098,1.039
289.19,125.59,0.098,1.041
289.24,125.80,0.098,1.041
289.28,126.01,0.098,1.042
289.32,126.22,0.098,1.042
289.36,126.43,0.098,1.042
289.40,126.63,0.098,1.041
289.44,126.84,0.098,1.041
289.49,127.05,0.098,1.041
289.53,127.26,0.098,1.041
289.57,127.47,0.098,1.042
289.61,127.68,0.098,1.042
289.65,127.89,0.098,1.044
289.69,128.09,0.099,1.044
289.74,128.30,0.098,1.044
289.78,128.51,0.098,1.044
289.82,128.72,0.099,1.045
289.86,128.93,0.099,1.044
289.90,129.14,0.099,1.045
289.94,129.34,0.099,1.045
289.99,129.55,0.099,1.047
290.03,129.76,0.099,1.048
290.07,129.97,0.099,1.049
290.11,130.18,0.099,1.049
290.15,130.39,0.099,1.048
290.19,130.59,0.099,1.045
290.24,130.80,0.099,1.045
290.28,131.01,0.099,1.046
290.32,131.22,0.099,1.047
290.36,131.43,0.099,1.047
290.40,131.64,0.099,1.048
290.44,131.85,0.099,1.046
290.49,132.05,0.099,1.046
290.53,132.26,0.099,1.046
290.57,132.47,0.099,1.047
290.61,132.68,0.099,1.048
290.65,132.89,0.099,1.050
290.69,133.10,0.099,1.051
290.74,133.30,0.099,1.051
290.78,133.51,0.099,1.050
290.82,133.72,0.099,1.051
290.86,133.93,0.099,1.051
290.90,134.14,0.099,1.051
290.94,134.35,0.099,1.051
290.99,134.56,0.099,1.052
291.03,134.76,0.099,1.054
291.07,134.97,0.099,1.053
291.11,135.18,0.099,1.053
291.15,135.39,0.099,1.054
291.19,135.60,0.100,1.054
291.24,135.81,0.100,1.055
291.28,136.01,0.100,1.056
291.32,136.22,0.100,1.056
291.36,136.43,0.100,1.056
291.40,136.64,0.100,1.055
291.44,136.85,0.100,1.055
291.49,137.06,0.100,1.055
291.53,137.27,0.100,1.056
291.57,137.47,0.100,1.057
291.61,137.68,0.100,1.059
291.65,137.89,0.100,1.059
291.69,138.10,0.100,1.058
291.74,138.31,0.100,1.057
291.78,138.52,0.100,1.057
291.82,138.73,0.100,1.058
291.86,138.93,0.100,1.059
291.90,139.14,0.100,1.060
291.94,139.35,0.100,1.062
291.99,139.56,0.100,1.062
292.03,139.77,0.100,1.063
292.07,139.98,0.100,1.064
292.11,140.18,0.100,1.063
292.15,140.39,0.100,1.062
292.19,140.60,0.100,1.061
292.24,140.81,0.100,1.062
292.28,141.02,0.100,1.061
292.32,141.23,0.100,1.062
292.36,141.44,0.100,1.063
292.40,141.64,0.100,1.063
292.44,141.85,0.100,1.062
292.49,142.06,0.101,1.063
292.53,142.27,0.101,1.062
292.57,142.48,0.101,1.064
292.61,142.69,0.101,1.066
292.65,142.89,0.101,1.067
292.69,143.10,0.101,1.068
292.74,143.31,0.101,1.070
292.78,143.52,0.101,1.070
292.82,143.73,0.101,1.068
292.86,143.94,0.101,1.069
292.90,144.14,0.101,1.069
292.94,144.35,0.101,1.067
292.99,144.56,0.101,1.067
293.03,144.77,0.101,1.066
293.07,144.98,0.101,1.067
293.11,145.19,0.101,1.067
293.15,145.40,0.101,1.068
293.19,145.60,0.101,1.068
293.24,145.81,0.101,1.070
293.28,146.02,0.101,1.070
293.32,146.23,0.101,1.071
293.36,146.44,0.101,1.072
293.40,146.65,0.101,1.072
293.44,146.85,0.101,1.072
293.49,147.06,0.101,1.072
293.53,147.27,0.101,1.072
293.57,147.48,0.101,1.071
293.61,147.69,0.101,1.070
293.65,147.90,0.101,1.070
293.69,148.10,0.101,1.071
293.74,148.31,0.101,1.072
293.78,148.52,0.102,1.071
293.82,148.73,0.102,1.071
293.86,148.94,0.102,1.071
293.90,149.15,0.102,1.072
293.94,149.36,0.102,1.074
293.99,149.57,0.102,1.076
294.03,149.77,0.102,1.076
294.07,149.98,0.102,1.076
294.11,150.19,0.102,1.076
294.15,150.40,0.102,1.075
294.19,150.61,0.102,1.073
294.24,150.82,0.102,1.074
294.28,151.02,0.102,1.076
294.32,151.23,0.102,1.077
294.36,151.44,0.102,1.078
294.40,151.65,0.102,1.078
294.44,151.86,0.102,1.077
294.49,152.06,0.102,1.077
294.53,152.27,0.102,1.076
294.57,152.48,0.102,1.075
294.61,152.69,0.102,1.077
294.65,152.90,0.102,1.077
294.69,153.11,0.102,1.077
294.74,153.32,0.102,1.080
294.78,153.53,0.103,1.082
294.82,153.73,0.103,1.083
294.86,153.94,0.102,1.082
294.90,154.15,0.102,1.083
294.94,154.36,0.103,1.082
294.99,154.57,0.103,1.082
295.03,154.77,0.103,1.082
295.07,154.98,0.103,1.084
295.11,155.19,0.103,1.084
295.15,155.40,0.103,1.085
295.19,155.61,0.103,1.085
295.24,155.82,0.103,1.084
295.28,156.02,0.103,1.084
295.32,156.23,0.103,1.083
295.36,156.44,0.103,1.083
295.40,156.65,0.103,1.084
295.44,156.86,0.103,1.085
295.49,157.07,0.103,1.086
295.53,157.28,0.103,1.088
295.57,157.48,0.103,1.088
295.61,157.69,0.103,1.088
295.65,157.90,0.103,1.087
295.69,158.11,0.103,1.087
295.74,158.32,0.103,1.086
295.78,158.52,0.103,1.085
295.82,158.73,0.103,1.085
295.86,158.94,0.103,1.084
295.90,159.15,0.103,1.085
295.94,159.36,0.103,1.086
295.99,159.57,0.103,1.086
296.03,159.78,0.103,1.086
296.07,159.99,0.103,1.087
296.11,160.19,0.103,1.086
296.15,160.40,0.103,1.087
296.19,160.61,0.103,1.087
296.24,160.82,0.103,1.088
296.28,161.03,0.103,1.088
296.32,161.24,0.103,1.089
296.36,161.45,0.103,1.089
296.40,161.65,0.103,1.089
296.44,161.86,0.103,1.089
296.49,162.07,0.103,1.089
296.53,162.28,0.103,1.089
296.57,162.49,0.103,1.090
296.61,162.70,0.103,1.090
296.65,162.90,0.103,1.090
296.69,163.11,0.103,1.090
296.74,163.32,0.104,1.089
296.78,163.53,0.104,1.089
296.82,163.74,0.104,1.090
296.86,163.95,0.104,1.092
296.90,164.16,0.104,1.092
296.94,164.36,0.104,1.093
296.99,164.57,0.104,1.093
297.03,164.78,0.104,1.094
297.07,164.99,0.104,1.093
297.11,165.20,0.104,1.094
297.15,165.41,0.104,1.094
297.19,165.61,0.104,1.094
297.24,165.82,0.104,1.095
297.28,166.03,0.104,1.096
297.32,166.24,0.104,1.097
297.36,166.45,0.104,1.097
297.40,166.66,0.104,1.099
297.44,166.86,0.104,1.099
297.49,167.07,0.104,1.099
297.53,167.28,0.104,1.099
297.57,167.49,0.104,1.099
297.61,167.70,0.104,1.099
297.65,167.91,0.104,1.098
297.69,168.11,0.104,1.099
297.74,168.32,0.105,1.099
297.78,168.53,0.105,1.099
297.82,168.74,0.105,1.100
297.86,168.95,0.105,1.101
297.90,169.16,0.105,1.102
297.94,169.37,0.105,1.102
297.99,169.57,0.105,1.102
298.03,169.78,0.105,1.102
298.07,169.99,0.105,1.101
298.11,170.20,0.105,1.100
298.15,170.41,0.105,1.100
298.19,170.61,0.105,1.100
298.24,170.82,0.105,1.101
298.28,171.03,0.105,1.102
298.32,171.24,0.105,1.104
298.36,171.45,0.105,1.104
298.40,171.66,0.105,1.105
298.44,171.86,0.105,1.105
298.49,172.07,0.105,1.106
298.53,172.28,0.105,1.105
298.57,172.49,0.105,1.106
298.61,172.70,0.105,1.105
298.65,172.91,0.105,1.106
298.69,173.11,0.105,1.106
298.74,173.32,0.105,1.106
298.78,173.53,0.106,1.107
298.82,173.74,0.106,1.108
298.86,173.95,0.106,1.109
298.90,174.16,0.106,1.110
298.94,174.37,0.106,1.111
298.99,174.57,0.106,1.112
299.03,174.78,0.106,1.111
299.07,174.99,0.106,1.112
299.11,175.20,0.106,1.112
299.15,175.41,0.106,1.112
299.19,175.62,0.106,1.112
299.24,175.82,0.106,1.111
299.28,176.03,0.106,1.114
299.32,176.24,0.106,1.113
299.36,176.45,0.106,1.113
299.40,176.66,0.106,1.112
299.44,176.87,0.106,1.111
299.49,177.08,0.106,1.110
299.53,177.28,0.106,1.110
299.57,177.49,0.106,1.110
299.61,177.70,0.106,1.110
299.65,177.91,0.106,1.112
299.69,178.12,0.106,1.114
299.74,178.33,0.106,1.117
299.78,178.54,0.106,1.118
299.82,178.74,0.106,1.117
299.86,178.95,0.106,1.116
299.90,179.16,0.106,1.116
299.94,179.37,0.106,1.115
299.99,179.58,0.106,1.116
300.03,179.79,0.107,1.117
300.07,179.99,0.106,1.117
300.11,180.20,0.106,1.117
300.15,180.41,0.107,1.116
300.19,180.62,0.107,1.116
300.24,180.83,0.107,1.116
300.28,181.04,0.107,1.115
300.32,181.24,0.107,1.116
300.36,181.45,0.107,1.118
300.40,181.66,0.107,1.120
300.44,181.87,0.107,1.122
300.49,182.08,0.107,1.123
300.53,182.28,0.107,1.122
300.57,182.49,0.107,1.120
300.61,182.70,0.107,1.119
300.65,182.91,0.107,1.120
300.69,183.12,0.107,1.121
300.74,183.33,0.107,1.124
300.78,183.54,0.107,1.126
300.82,183.74,0.107,1.125
300.86,183.95,0.107,1.124
300.90,184.16,0.107,1.125
300.94,184.37,0.108,1.126
300.99,184.58,0.108,1.126
301.03,184.79,0.108,1.127
301.07,185.00,0.108,1.127
301.11,185.20,0.108,1.126
301.15,185.41,0.108,1.125
301.19,185.62,0.108,1.125
301.24,185.83,0.108,1.126
301.28,186.04,0.108,1.127
301.32,186.25,0.108,1.128
301.36,186.46,0.108,1.128
301.40,186.66,0.108,1.130
301.44,186.87,0.108,1.132
301.49,187.08,0.108,1.131
301.53,187.29,0.108,1.131
301.57,187.49,0.108,1.130
301.61,187.70,0.108,1.128
301.65,187.91,0.108,1.128
301.69,188.12,0.108,1.130
301.74,188.33,0.108,1.131
301.78,188.54,0.108,1.133
301.82,188.75,0.108,1.135
301.86,188.96,0.108,1.135
301.90,189.16,0.108,1.135
301.94,189.37,0.108,1.135
301.99,189.58,0.108,1.133
302.03,189.79,0.108,1.131
302.07,190.00,0.108,1.133
302.11,190.21,0.109,1.134
302.15,190.41,0.109,1.133
302.19,190.62,0.109,1.135
302.24,190.83,0.109,1.136
302.28,191.04,0.109,1.136
302.32,191.25,0.109,1.135
302.36,191.46,0.109,1.136
302.40,191.67,0.109,1.137
302.44,191.87,0.109,1.138
302.49,192.08,0.109,1.139
302.53,192.29,0.109,1.141
302.57,192.50,0.109,1.142
302.61,192.71,0.109,1.142
302.65,192.91,0.109,1.141
302.69,193.12,0.109,1.140
302.74,193.33,0.109,1.140
302.78,193.54,0.109,1.139
302.82,193.75,0.109,1.140
302.86,193.96,0.109,1.141
302.90,194.17,0.109,1.143
302.94,194.37,0.110,1.144
302.99,194.58,0.110,1.143
303.03,194.79,0.110,1.142
303.07,195.00,0.110,1.142
303.11,195.21,0.110,1.143
303.15,195.42,0.110,1.145
303.19,195.63,0.110,1.147
303.24,195.83,0.110,1.149
303.28,196.04,0.110,1.150
303.32,196.25,0.110,1.149
303.36,196.46,0.110,1.148
303.40,196.67,0.110,1.148
303.44,196.87,0.110,1.146
303.49,197.08,0.110,1.146
303.53,197.29,0.110,1.147
303.57,197.50,0.110,1.147
303.61,197.71,0.110,1.149
303.65,197.92,0.110,1.149
303.69,198.13,0.110,1.149
303.74,198.33,0.110,1.148
303.78,198.54,0.110,1.148
303.82,198.75,0.110,1.148
303.86,198.96,0.110,1.149
303.90,199.17,0.110,1.149
303.94,199.38,0.110,1.150
303.99,199.58,0.110,1.151
304.03,199.79,0.111,1.152
304.07,200.00,0.111,1.153
304.11,200.21,0.111,1.152
304.15,200.42,0.111,1.151
304.19,200.63,0.111,1.152
304.24,200.84,0.111,1.153
304.28,201.04,0.111,1.154
304.32,201.25,0.111,1.156
304.36,201.46,0.111,1.156
304.40,201.67,0.111,1.158
304.44,201.88,0.111,1.157
304.49,202.08,0.111,1.157
304.53,202.29,0.111,1.155
304.57,202.50,0.111,1.155
304.61,202.71,0.111,1.155
304.65,202.92,0.111,1.156
304.69,203.13,0.111,1.156
304.74,203.34,0.111,1.159
304.78,203.55,0.112,1.160
304.82,203.75,0.112,1.161
304.86,203.96,0.112,1.161
304.90,204.17,0.112,1.161
304.94,204.38,0.112,1.160
304.99,204.59,0.112,1.161
305.03,204.80,0.112,1.162
305.07,205.00,0.112,1.163
305.11,205.21,0.112,1.164
305.15,205.42,0.112,1.164
305.19,205.63,0.112,1.163
305.24,205.84,0.112,1.163
305.28,206.04,0.112,1.162
305.32,206.25,0.112,1.162
305.36,206.46,0.112,1.164
305.40,206.67,0.112,1.165
305.44,206.88,0.112,1.166
305.49,207.09,0.112,1.169
305.53,207.30,0.112,1.171
305.57,207.50,0.112,1.171
305.61,207.71,0.112,1.169
305.65,207.92,0.112,1.169
305.69,208.13,0.112,1.167
305.74,208.34,0.113,1.167
305.78,208.55,0.113,1.168
305.82,208.75,0.113,1.169
305.86,208.96,0.113,1.170
305.90,209.17,0.113,1.171
305.94,209.38,0.113,1.172
305.99,209.59,0.113,1.172
306.03,209.80,0.113,1.171
306.07,210.00,0.113,1.172
306.11,210.21,0.113,1.172
306.15,210.42,0.113,1.174
306.19,210.63,0.113,1.175
306.24,210.84,0.113,1.176
306.28,211.05,0.113,1.177
306.32,211.26,0.114,1.178
306.36,211.46,0.114,1.178
306.40,211.67,0.114,1.179
306.44,211.88,0.114,1.179
306.49,212.09,0.114,1.179
306.53,212.30,0.114,1.179
306.57,212.51,0.114,1.179
306.61,212.71,0.114,1.179
306.65,212.92,0.114,1.180
306.69,213.13,0.114,1.180
306.74,213.34,0.114,1.181
306.78,213.55,0.114,1.182
306.82,213.76,0.114,1.183
306.86,213.97,0.114,1.182
306.90,214.17,0.114,1.183
306.94,214.38,0.114,1.184
306.99,214.59,0.114,1.185
307.03,214.80,0.114,1.186
307.07,215.01,0.114,1.187
307.11,215.21,0.114,1.186
307.15,215.42,0.114,1.185
307.19,215.63,0.114,1.186
307.24,215.84,0.115,1.185
307.28,216.05,0.115,1.186
307.32,216.26,0.115,1.187
307.36,216.47,0.115,1.187
307.40,216.67,0.115,1.187
307.44,216.88,0.115,1.187
307.49,217.09,0.115,1.187
307.53,217.30,0.115,1.186
307.57,217.51,0.115,1.187
307.61,217.72,0.115,1.187
307.65,217.93,0.115,1.189
307.69,218.13,0.115,1.190
307.74,218.34,0.115,1.191
307.78,218.55,0.115,1.192
307.82,218.76,0.115,1.191
307.86,218.97,0.115,1.192
307.90,219.17,0.116,1.194
307.94,219.38,0.116,1.195
307.99,219.59,0.116,1.196
308.03,219.80,0.116,1.197
308.07,220.01,0.116,1.198
308.11,220.22,0.116,1.198
308.15,220.43,0.116,1.198
308.19,220.63,0.116,1.198
308.24,220.84,0.116,1.199
308.28,221.05,0.116,1.200
308.32,221.26,0.116,1.200
308.36,221.47,0.116,1.201
308.40,221.68,0.116,1.202
308.44,221.89,0.116,1.201
308.49,222.09,0.116,1.203
308.53,222.30,0.117,1.203
308.57,222.51,0.117,1.205
308.61,222.72,0.117,1.205
308.65,222.93,0.117,1.204
308.69,223.13,0.117,1.203
308.74,223.34,0.117,1.204
308.78,223.55,0.117,1.204
308.82,223.76,0.117,1.205
308.86,223.97,0.117,1.206
308.90,224.18,0.117,1.207
308.94,224.38,0.117,1.206
308.99,224.59,0.117,1.204
309.03,224.80,0.117,1.204
309.07,225.01,0.117,1.205
309.11,225.22,0.117,1.203
309.15,225.43,0.117,1.204
309.19,225.64,0.117,1.205
309.24,225.84,0.117,1.207
309.28,226.05,0.117,1.208
309.32,226.26,0.117,1.210
309.36,226.47,0.117,1.209
309.40,226.68,0.117,1.209
309.44,226.88,0.117,1.208
309.49,227.09,0.117,1.208
309.53,227.30,0.117,1.207
309.57,227.51,0.117,1.209
309.61,227.72,0.117,1.209
309.65,227.93,0.117,1.209
309.69,228.14,0.117,1.209
309.74,228.34,0.117,1.210
309.78,228.55,0.117,1.210
309.82,228.76,0.117,1.210
309.86,228.97,0.117,1.209
309.90,229.18,0.118,1.209
309.94,229.39,0.118,1.210
309.99,229.60,0.118,1.212
310.03,229.80,0.118,1.213
310.07,230.01,0.118,1.213
310.11,230.22,0.118,1.214
310.15,230.43,0.118,1.214
310.19,230.64,0.118,1.213
310.24,230.85,0.118,1.214
310.28,231.05,0.118,1.214
310.32,231.26,0.118,1.215
310.36,231.47,0.118,1.216
310.40,231.68,0.118,1.216
310.44,231.89,0.118,1.216
310.49,232.10,0.118,1.216
310.53,232.30,0.118,1.216
310.57,232.51,0.119,1.218
310.61,232.72,0.119,1.218
310.65,232.93,0.119,1.219
310.69,233.14,0.119,1.219
310.74,233.35,0.119,1.220
310.78,233.55,0.119,1.221
310.82,233.76,0.119,1.220
310.86,233.97,0.119,1.219
310.90,234.18,0.119,1.218
310.94,234.39,0.119,1.218
310.99,234.60,0.119,1.218
311.03,234.81,0.119,1.219
311.07,235.01,0.119,1.221
311.11,235.22,0.119,1.222
311.15,235.43,0.119,1.224
311.19,235.64,0.119,1.224
311.24,235.85,0.119,1.223
311.28,236.05,0.119,1.223
311.32,236.26,0.119,1.223
311.36,236.47,0.119,1.222
311.40,236.68,0.119,1.222
311.44,236.89,0.119,1.224
311.49,237.10,0.120,1.225
311.53,237.31,0.120,1.226
311.57,237.52,0.120,1.228
311.61,237.72,0.120,1.228
311.65,237.93,0.120,1.229
311.69,238.14,0.120,1.230
311.74,238.35,0.120,1.231
311.78,238.56,0.120,1.232
311.82,238.77,0.120,1.232
311.86,238.97,0.120,1.232
311.90,239.18,0.120,1.231
311.94,239.39,0.120,1.230
311.99,239.60,0.120,1.229
312.03,239.81,0.120,1.230
312.07,240.01,0.120,1.230
312.11,240.22,0.120,1.229
312.15,240.43,0.120,1.230
312.19,240.64,0.120,1.231
312.24,240.85,0.120,1.231
312.28,241.06,0.121,1.232
312.32,241.26,0.121,1.231
312.36,241.47,0.121,1.229
312.40,241.68,0.121,1.228
312.44,241.89,0.121,1.229
312.49,242.10,0.121,1.231
312.53,242.31,0.121,1.234
312.57,242.52,0.121,1.236
312.61,242.73,0.121,1.238
312.65,242.94,0.120,1.236
312.69,243.15,0.120,1.233
312.74,243.35,0.120,1.231
312.78,243.56,0.120,1.228
312.82,243.77,0.120,1.228
312.86,243.98,0.120,1.227
312.90,244.18,0.120,1.226
312.94,244.39,0.119,1.222
312.99,244.60,0.119,1.222
313.03,244.81,0.119,1.222
313.07,245.02,0.119,1.218
313.11,245.23,0.119,1.219
313.15,245.44,0.120,1.221
313.19,245.64,0.120,1.222
313.24,245.85,0.120,1.223
313.28,246.06,0.120,1.225
313.32,246.27,0.120,1.224
313.36,246.47,0.120,1.224
313.40,246.68,0.120,1.225
313.44,246.89,0.120,1.225
313.49,247.10,0.120,1.228
313.53,247.31,0.120,1.230
313.57,247.52,0.120,1.229
313.61,247.72,0.120,1.229
313.65,247.93,0.120,1.229
313.69,248.14,0.120,1.229
313.74,248.35,0.121,1.228
313.78,248.56,0.121,1.228
313.82,248.77,0.121,1.228
313.86,248.98,0.121,1.229
313.90,249.18,0.121,
313.94,249.39,,
313.98,,,