File: DSC/Earl/2025_10_06_PVP40_5Cmin_n60C_210C_x3.csv
Filename,2025_10_06_PVP40_5Cmin_n60C_210C_x3
Instrument name,DSC2A-00468 (192.168.1.100)
Operator,JLY
rundate,10/6/2025
Sample name,2025_10_06_PVP40_5Cmin_n60C_210C_x3
proceduresegments,Data Off ; Equilibrate -60.00 °C; Data On ; Ramp 5.00 °C/min to 210.00 °C; Data Off ; Isothermal 1.0 min; Data On ; Ramp 5.00 °C/min to -60.00 °C; Data Off ; Isothermal 1.0 min; Data On ; Ramp 5.00 °C/min to 210.00 °C; Data Off ; Isothermal 1.0 min; Data On ; Ramp 5.00 °C/min to -60.00 °C; Data Off ; Isothermal 1.0 min; Data On ; Ramp 5.00 °C/min to 210.00 °C
[File Parameters]
Run date,10/6/2025 6:28:54 PM
Trios version,5.1.1.46572
Original File Name,
Current File Name,D:\DSC2500\JYarger\2025_10_06_PVP40_5Cmin_n60C_210C_x3.tri
[Procedure]
Procedure Name,ASD_n60C_210C_5Cmin_x3
Sample Name,2025_10_06_PVP40_5Cmin_n60C_210C_x3
Sample Mass,5.16 mg
Reference Sample Mass,0 mg
Pan Mass,32.46 mg
Pan Number,40
Reference Pan Mass,32.55 mg
Reference Pan Number,1
Pan Type,Aluminum
Comments,DSC_Samples_Y2_Tray_ASDs_Pharma_Oct2025 Google Sheet.
Project Name,Amorphous Pharma
Operator,JLY
Test,Custom
Unload Max Temperature,30
Unload Min Temperature,30
Load Max Temperature,30
Load Min Temperature,30
Stop on Gas Flow Error,Yes
[Signal List]
Signal #1,Time (min)
Signal #2,Temperature (°C)
Signal #3,Heat Flow (mW)
Signal #4,Delta T (µV)
Signal #5,Delta Tzero (µV)
Signal #6,Tzero Temperature (°C)
Signal #7,Cell Purge (mL/min)
Signal #8,Heater Temp (°C)
Signal #9,Power Delivered (W)
Signal #10,Reference Junction Temperature (°C)
Signal #11,Flange Temperature (°C)
Signal #12,Heat Flow Phase (rad)
Signal #13,Total Heat Capacity (J/°C)
Signal #14,Heat Capacity (J/°C)
[Configuration]
Company Name,ASU
Instrument Name,DSC2A-00468
Instrument Type,DSC2500
Serial Number,DSC2A-00468
IP,192.168.1.100
Location of Instrument,MRRC
DisplayType,Unknown
Sample Interval ,0.1 s/pt
Selected Heat Flow,T4P
Exotherm Direction,Down
Cell Serial,DRC2-00792
Lid Type,Standard
Cooler,RCS 90
Leave Cooler on at End of Sequence,On
Gas 2,Nitrogen
Gas Selected,Channel 1
Flow Rate,50 mL/min
Secondary Purge,On
Licensed Heat Flow,Heat Flow T4P
Modulation Licensed,Yes
[Versions]
Common IDD Version,1
Cortex Version,VER 2.10.2.31
Driver,5.0.0.6
GDM Version,1.0.3.3
TouchscreenVersion,1.0.0.16145
FEP Version,1.2.1.21
FEP Bootloader,2.0.0.5
AutoSampler Version,2.1.1.26
Auto Sampler Bootloader,2.0.0.5
FCM Version,1.1.0.3
FCM Bootloader,2.0.0.5
[Experiment Logs]
Experiment Log Entry # 1,Data On set to 0
Experiment Log Entry # 3,Equilibrate Segment -60 (C) Started
Experiment Log Entry # 5,Air Cool is off.
Experiment Log Entry # 7,Data On set to 1
Experiment Log Entry # 9,Ramp Segment 5 C/min to 210 Started
Experiment Log Entry # 11,Data On set to 0
Experiment Log Entry # 13,Isothermal Segment 1 min started
Experiment Log Entry # 15,Data On set to 1
Experiment Log Entry # 17,Ramp Segment 5 C/min to -60 Started
Experiment Log Entry # 19,Data On set to 0
Experiment Log Entry # 21,Isothermal Segment 1 min started
Experiment Log Entry # 23,Data On set to 1
Experiment Log Entry # 25,Ramp Segment 5 C/min to 210 Started
Experiment Log Entry # 27,Data On set to 0
Experiment Log Entry # 29,Isothermal Segment 1 min started
Experiment Log Entry # 31,Data On set to 1
Experiment Log Entry # 33,Ramp Segment 5 C/min to -60 Started
Experiment Log Entry # 35,Auto sampler has detected that FEP has gone offline
Experiment Log Entry # 37,Data On set to 0
Experiment Log Entry # 39,Isothermal Segment 1 min started
Experiment Log Entry # 41,Data On set to 1
Experiment Log Entry # 43,Ramp Segment 5 C/min to 210 Started
Experiment Log Entry # 45,Auto sampler has detected that FEP has gone offline
[Method Log]
Method Log Entry # 1,Data Off
Method Log Entry # 2,Equilibrate -60 °C
Method Log Entry # 3,Data On
Method Log Entry # 4,(Ramp 621920) Ramp 5 °C/minute to 210 °C
Method Log Entry # 5,Data Off
Method Log Entry # 6,Isothermal 1 minutes
Method Log Entry # 7,Data On
Method Log Entry # 8,(Ramp 621924) Ramp 5 °C/minute to -60 °C
Method Log Entry # 9,Data Off
Method Log Entry # 10,Isothermal 1 minutes
Method Log Entry # 11,Data On
Method Log Entry # 12,(Ramp 621928) Ramp 5 °C/minute to 210 °C
Method Log Entry # 13,Data Off
Method Log Entry # 14,Isothermal 1 minutes
Method Log Entry # 15,Data On
Method Log Entry # 16,(Ramp 621932) Ramp 5 °C/minute to -60 °C
Method Log Entry # 17,Data Off
Method Log Entry # 18,Isothermal 1 minutes
Method Log Entry # 19,Data On
Method Log Entry # 20,(Ramp 621936) Ramp 5 °C/minute to 210 °C
Cell Serial,DRC2-00792
[T1 Calibration]
Slope,-0.008529666
Offset,9.636258
Initial Temperature,98.23
GUID,f8bfdadc-4977-4fdf-ba6d-0ba9134940c3
[TZero Calibration]
Date Applied,11/29/2022 4:06:13 PM
Description,From -89.059 °C to 396.009 °C at 20.000°C/min
Gas Type,Nitrogen
Pan Type,None
Source Files 1,C:\Users\yargerlab\Desktop\DSC Data\General\TZero_calibration_11_29_22_2nd(2).tri
Source Files 2,C:\Users\yargerlab\Desktop\DSC Data\General\TZero_calibration_11_29_22_2nd(3).tri
Delta T Offset,13.05235
Delta T Slope,-0.007271007
Delta T0 Offset,-13.69128
Delta T0 Slope,0.06063341
[Temperature Calibration]
Date Applied,11/29/2022 7:12:28 PM
Description,From 106.590 °C to 186.590 °C at 10.000°C/min
Gas Type,Nitrogen
Pan Type,Tzero Aluminum Hermetic
Source Files 1,C:\Users\yargerlab\Desktop\DSC Data\General\Indium(6).tri
Measured 1,157.391
Known 1,156.598
[Cell Constant Calibration]
Date Applied,11/29/2022 7:12:29 PM
Description,From 106.590 °C to 186.590 °C at 10.000°C/min
Gas Type,Nitrogen
Pan Type,Tzero Aluminum Hermetic
Source Files 1,C:\Users\yargerlab\Desktop\DSC Data\General\Indium(6).tri
T4P KCell,1.006051
Onset Slope,63.26126 mW/°C
[Direct Cp Calibration]
Date Applied,11/30/2022 11:04:51 AM
Description,From -79.983 °C to 298.409 °C at 10.000°C/min
Gas Type,Nitrogen
Pan Type,Tzero Aluminum Hermetic
Source Files 1,C:\Users\yargerlab\Desktop\DSC Data\General\Sapphire_Heat_Capacity_11_30_22.tri
[Rev Cp Calibration]
Date Applied,11/30/2022 1:58:51 PM
Description,From -79.996 °C to 292.812 °C at 3.000°C/min
Gas Type,Nitrogen
Pan Type,Tzero Aluminum Hermetic
Source Files 1,C:\Users\yargerlab\Desktop\DSC Data\General\Sapphire_MDSC_Calibration_11_30_22.tri
[step]
Ramp 5.00 °C/min to 210.00 °C
Time,Temperature,Heat Flow (Normalized)
min,°C,W/g
0.00,-59.81,-0.050
0.04,-59.82,-0.044
0.07,-59.79,-0.041
0.11,-59.70,-0.037
0.15,-59.56,-0.016
0.18,-59.41,0.012
0.22,-59.25,0.034
0.26,-59.09,0.049
0.29,-58.92,0.059
0.33,-58.75,0.066
0.37,-58.57,0.072
0.40,-58.39,0.075
0.44,-58.22,0.077
0.48,-58.04,0.079
0.51,-57.86,0.080
0.55,-57.68,0.081
0.59,-57.50,0.082
0.62,-57.32,0.082
0.66,-57.14,0.083
0.70,-56.96,0.083
0.73,-56.77,0.084
0.77,-56.59,0.085
0.81,-56.41,0.085
0.84,-56.23,0.085
0.88,-56.05,0.086
0.92,-55.86,0.086
0.95,-55.68,0.086
0.99,-55.50,0.087
1.03,-55.32,0.087
1.06,-55.13,0.087
1.10,-54.95,0.087
1.14,-54.77,0.087
1.17,-54.59,0.088
1.21,-54.40,0.088
1.25,-54.22,0.088
1.28,-54.04,0.088
1.32,-53.86,0.088
1.36,-53.67,0.088
1.39,-53.49,0.088
1.43,-53.31,0.088
1.47,-53.12,0.088
1.50,-52.94,0.088
1.54,-52.76,0.088
1.58,-52.57,0.088
1.61,-52.39,0.088
1.65,-52.21,0.088
1.69,-52.02,0.088
1.72,-51.84,0.088
1.76,-51.66,0.088
1.80,-51.48,0.088
1.83,-51.29,0.088
1.87,-51.11,0.088
1.91,-50.93,0.088
1.94,-50.74,0.088
1.98,-50.56,0.088
2.02,-50.38,0.088
2.05,-50.19,0.088
2.09,-50.01,0.088
2.13,-49.83,0.088
2.16,-49.64,0.088
2.20,-49.46,0.088
2.24,-49.28,0.088
2.27,-49.09,0.088
2.31,-48.91,0.088
2.35,-48.73,0.088
2.38,-48.54,0.088
2.42,-48.36,0.088
2.46,-48.18,0.088
2.49,-48.00,0.088
2.53,-47.81,0.088
2.57,-47.63,0.088
2.60,-47.44,0.088
2.64,-47.26,0.088
2.68,-47.08,0.088
2.71,-46.90,0.088
2.75,-46.71,0.088
2.79,-46.53,0.088
2.82,-46.35,0.088
2.86,-46.16,0.088
2.90,-45.98,0.088
2.93,-45.80,0.088
2.97,-45.61,0.088
3.01,-45.43,0.088
3.04,-45.25,0.088
3.08,-45.06,0.088
3.12,-44.88,0.088
3.15,-44.70,0.088
3.19,-44.52,0.088
3.23,-44.33,0.088
3.26,-44.15,0.088
3.30,-43.97,0.088
3.34,-43.78,0.088
3.37,-43.60,0.088
3.41,-43.42,0.088
3.45,-43.23,0.088
3.48,-43.05,0.088
3.52,-42.86,0.088
3.56,-42.68,0.088
3.59,-42.50,0.088
3.63,-42.32,0.088
3.67,-42.13,0.088
3.70,-41.95,0.088
3.74,-41.77,0.088
3.78,-41.58,0.088
3.81,-41.40,0.088
3.85,-41.22,0.088
3.89,-41.03,0.088
3.92,-40.85,0.088
3.96,-40.67,0.088
4.00,-40.48,0.088
4.03,-40.30,0.089
4.07,-40.11,0.089
4.11,-39.93,0.089
4.14,-39.75,0.089
4.18,-39.56,0.089
4.22,-39.38,0.089
4.25,-39.20,0.089
4.29,-39.01,0.089
4.33,-38.83,0.088
4.36,-38.65,0.089
4.40,-38.47,0.089
4.44,-38.28,0.089
4.47,-38.10,0.089
4.51,-37.91,0.089
4.55,-37.73,0.089
4.58,-37.55,0.089
4.62,-37.36,0.089
4.66,-37.18,0.089
4.69,-36.99,0.089
4.73,-36.81,0.089
4.77,-36.63,0.089
4.80,-36.44,0.089
4.84,-36.26,0.089
4.88,-36.08,0.089
4.91,-35.89,0.089
4.95,-35.71,0.089
4.99,-35.53,0.089
5.02,-35.34,0.089
5.06,-35.16,0.089
5.10,-34.97,0.090
5.13,-34.79,0.090
5.17,-34.61,0.090
5.21,-34.43,0.090
5.24,-34.24,0.090
5.28,-34.06,0.090
5.32,-33.87,0.090
5.35,-33.69,0.090
5.39,-33.51,0.090
5.43,-33.32,0.090
5.46,-33.14,0.090
5.50,-32.96,0.090
5.54,-32.77,0.090
5.57,-32.59,0.090
5.61,-32.40,0.090
5.65,-32.22,0.090
5.68,-32.04,0.090
5.72,-31.85,0.090
5.76,-31.67,0.090
5.79,-31.49,0.090
5.83,-31.30,0.090
5.87,-31.12,0.090
5.90,-30.94,0.090
5.94,-30.75,0.090
5.98,-30.57,0.090
6.01,-30.39,0.090
6.05,-30.20,0.090
6.09,-30.02,0.090
6.12,-29.83,0.090
6.16,-29.65,0.090
6.20,-29.47,0.091
6.23,-29.28,0.091
6.27,-29.10,0.091
6.31,-28.92,0.091
6.34,-28.73,0.091
6.38,-28.55,0.091
6.42,-28.37,0.091
6.45,-28.18,0.091
6.49,-28.00,0.091
6.53,-27.81,0.091
6.56,-27.63,0.091
6.60,-27.45,0.091
6.64,-27.26,0.091
6.67,-27.08,0.091
6.71,-26.90,0.091
6.75,-26.71,0.091
6.78,-26.53,0.091
6.82,-26.35,0.091
6.86,-26.16,0.091
6.89,-25.98,0.091
6.93,-25.80,0.091
6.97,-25.61,0.091
7.00,-25.43,0.091
7.04,-25.25,0.091
7.08,-25.06,0.091
7.11,-24.88,0.092
7.15,-24.70,0.092
7.19,-24.51,0.092
7.22,-24.33,0.092
7.26,-24.15,0.092
7.30,-23.96,0.092
7.33,-23.78,0.092
7.37,-23.59,0.092
7.41,-23.41,0.092
7.44,-23.23,0.092
7.48,-23.04,0.092
7.52,-22.86,0.092
7.55,-22.68,0.092
7.59,-22.49,0.092
7.63,-22.31,0.092
7.66,-22.13,0.092
7.70,-21.94,0.092
7.74,-21.76,0.092
7.77,-21.58,0.092
7.81,-21.39,0.092
7.85,-21.21,0.093
7.88,-21.03,0.093
7.92,-20.84,0.093
7.96,-20.66,0.093
7.99,-20.48,0.093
8.03,-20.29,0.093
8.07,-20.11,0.093
8.10,-19.93,0.093
8.14,-19.74,0.093
8.18,-19.56,0.093
8.21,-19.37,0.093
8.25,-19.19,0.093
8.29,-19.01,0.093
8.32,-18.82,0.093
8.36,-18.64,0.093
8.40,-18.46,0.093
8.43,-18.27,0.093
8.47,-18.09,0.093
8.51,-17.91,0.093
8.54,-17.72,0.094
8.58,-17.54,0.094
8.62,-17.36,0.094
8.65,-17.17,0.094
8.69,-16.99,0.094
8.73,-16.81,0.094
8.76,-16.62,0.094
8.80,-16.44,0.094
8.84,-16.26,0.094
8.87,-16.07,0.094
8.91,-15.89,0.094
8.95,-15.71,0.094
8.98,-15.52,0.094
9.02,-15.34,0.094
9.06,-15.15,0.094
9.09,-14.97,0.094
9.13,-14.79,0.094
9.17,-14.60,0.094
9.20,-14.42,0.095
9.24,-14.24,0.095
9.28,-14.05,0.095
9.31,-13.87,0.095
9.35,-13.69,0.095
9.39,-13.50,0.095
9.42,-13.32,0.095
9.46,-13.14,0.095
9.50,-12.95,0.095
9.53,-12.77,0.095
9.57,-12.59,0.095
9.61,-12.40,0.095
9.64,-12.22,0.095
9.68,-12.04,0.095
9.72,-11.85,0.095
9.75,-11.67,0.095
9.79,-11.49,0.095
9.83,-11.30,0.096
9.86,-11.12,0.096
9.90,-10.94,0.096
9.94,-10.75,0.096
9.97,-10.57,0.096
10.01,-10.38,0.096
10.05,-10.20,0.096
10.08,-10.02,0.096
10.12,-9.83,0.096
10.16,-9.65,0.096
10.19,-9.47,0.096
10.23,-9.29,0.096
10.27,-9.10,0.096
10.30,-8.92,0.096
10.34,-8.73,0.096
10.38,-8.55,0.097
10.41,-8.37,0.097
10.45,-8.18,0.097
10.49,-8.00,0.097
10.52,-7.82,0.097
10.56,-7.64,0.097
10.60,-7.45,0.097
10.63,-7.27,0.097
10.67,-7.08,0.097
10.71,-6.90,0.097
10.74,-6.72,0.097
10.78,-6.53,0.097
10.82,-6.35,0.098
10.85,-6.16,0.098
10.89,-5.98,0.098
10.93,-5.79,0.098
10.96,-5.61,0.098
11.00,-5.43,0.098
11.04,-5.25,0.098
11.07,-5.06,0.098
11.11,-4.88,0.098
11.15,-4.70,0.098
11.18,-4.51,0.098
11.22,-4.33,0.099
11.26,-4.15,0.099
11.29,-3.96,0.099
11.33,-3.78,0.099
11.37,-3.60,0.099
11.40,-3.41,0.099
11.44,-3.23,0.099
11.48,-3.04,0.099
11.51,-2.86,0.099
11.55,-2.68,0.099
11.59,-2.50,0.099
11.62,-2.31,0.099
11.66,-2.13,0.099
11.70,-1.94,0.100
11.73,-1.76,0.100
11.77,-1.58,0.100
11.81,-1.39,0.100
11.84,-1.21,0.100
11.88,-1.03,0.100
11.92,-0.84,0.100
11.95,-0.66,0.100
11.99,-0.48,0.100
12.03,-0.29,0.100
12.06,-0.11,0.100
12.10,0.07,0.101
12.14,0.26,0.101
12.17,0.44,0.101
12.21,0.62,0.101
12.25,0.81,0.101
12.28,0.99,0.101
12.32,1.18,0.101
12.36,1.36,0.101
12.39,1.54,0.101
12.43,1.73,0.101
12.47,1.91,0.101
12.50,2.09,0.101
12.54,2.28,0.102
12.58,2.46,0.102
12.61,2.64,0.102
12.65,2.83,0.102
12.69,3.01,0.102
12.72,3.19,0.102
12.76,3.38,0.102
12.80,3.56,0.102
12.83,3.75,0.102
12.87,3.93,0.102
12.91,4.11,0.102
12.94,4.29,0.103
12.98,4.48,0.103
13.02,4.66,0.103
13.05,4.85,0.103
13.09,5.03,0.103
13.13,5.21,0.103
13.16,5.40,0.103
13.20,5.58,0.103
13.24,5.76,0.103
13.27,5.95,0.103
13.31,6.13,0.104
13.35,6.31,0.104
13.38,6.50,0.104
13.42,6.68,0.104
13.46,6.86,0.104
13.49,7.05,0.104
13.53,7.23,0.104
13.57,7.41,0.104
13.60,7.60,0.105
13.64,7.78,0.105
13.68,7.97,0.105
13.71,8.15,0.105
13.75,8.33,0.105
13.79,8.51,0.105
13.82,8.70,0.105
13.86,8.88,0.105
13.90,9.06,0.105
13.93,9.25,0.105
13.97,9.43,0.106
14.01,9.62,0.106
14.04,9.80,0.106
14.08,9.98,0.106
14.12,10.16,0.106
14.15,10.35,0.106
14.19,10.53,0.107
14.23,10.72,0.107
14.26,10.90,0.107
14.30,11.08,0.107
14.34,11.27,0.107
14.37,11.45,0.107
14.41,11.63,0.107
14.45,11.82,0.107
14.48,12.00,0.107
14.52,12.18,0.108
14.56,12.37,0.108
14.59,12.55,0.108
14.63,12.73,0.108
14.67,12.92,0.108
14.70,13.10,0.108
14.74,13.28,0.109
14.78,13.47,0.109
14.81,13.65,0.109
14.85,13.83,0.109
14.89,14.02,0.109
14.92,14.20,0.109
14.96,14.39,0.109
15.00,14.57,0.109
15.03,14.75,0.110
15.07,14.94,0.110
15.11,15.12,0.110
15.14,15.30,0.110
15.18,15.48,0.110
15.22,15.67,0.110
15.25,15.85,0.110
15.29,16.04,0.111
15.33,16.22,0.111
15.36,16.40,0.111
15.40,16.59,0.111
15.44,16.77,0.111
15.47,16.95,0.112
15.51,17.14,0.112
15.55,17.32,0.112
15.58,17.51,0.112
15.62,17.69,0.112
15.66,17.87,0.112
15.69,18.06,0.113
15.73,18.24,0.113
15.77,18.42,0.113
15.80,18.61,0.113
15.84,18.79,0.113
15.88,18.97,0.113
15.91,19.16,0.114
15.95,19.34,0.114
15.99,19.52,0.114
16.02,19.70,0.114
16.06,19.89,0.114
16.10,20.07,0.115
16.13,20.25,0.115
16.17,20.44,0.115
16.21,20.62,0.115
16.24,20.81,0.115
16.28,20.99,0.116
16.32,21.17,0.116
16.35,21.36,0.116
16.39,21.54,0.116
16.43,21.72,0.116
16.46,21.90,0.117
16.50,22.09,0.117
16.54,22.27,0.117
16.57,22.46,0.117
16.61,22.64,0.117
16.65,22.82,0.118
16.68,23.01,0.118
16.72,23.19,0.118
16.76,23.37,0.118
16.79,23.56,0.119
16.83,23.74,0.119
16.87,23.92,0.119
16.90,24.11,0.119
16.94,24.29,0.119
16.98,24.47,0.120
17.01,24.66,0.120
17.05,24.84,0.120
17.09,25.02,0.120
17.12,25.21,0.121
17.16,25.39,0.121
17.20,25.57,0.121
17.23,25.76,0.121
17.27,25.94,0.122
17.31,26.12,0.122
17.34,26.31,0.122
17.38,26.49,0.122
17.42,26.67,0.123
17.45,26.86,0.123
17.49,27.04,0.123
17.53,27.22,0.123
17.56,27.41,0.124
17.60,27.59,0.124
17.64,27.77,0.124
17.67,27.96,0.125
17.71,28.14,0.125
17.75,28.32,0.125
17.78,28.51,0.125
17.82,28.69,0.126
17.86,28.88,0.126
17.89,29.06,0.126
17.93,29.24,0.126
17.97,29.43,0.127
18.00,29.61,0.127
18.04,29.79,0.127
18.08,29.97,0.128
18.11,30.16,0.128
18.15,30.34,0.128
18.19,30.52,0.128
18.22,30.71,0.129
18.26,30.89,0.129
18.30,31.07,0.129
18.33,31.26,0.130
18.37,31.44,0.130
18.41,31.62,0.130
18.44,31.81,0.131
18.48,31.99,0.131
18.52,32.18,0.131
18.55,32.36,0.132
18.59,32.54,0.132
18.63,32.73,0.133
18.66,32.91,0.133
18.70,33.09,0.133
18.74,33.28,0.134
18.77,33.46,0.134
18.81,33.64,0.134
18.85,33.83,0.135
18.88,34.01,0.135
18.92,34.19,0.135
18.96,34.38,0.136
18.99,34.56,0.136
19.03,34.74,0.136
19.07,34.92,0.137
19.10,35.11,0.137
19.14,35.29,0.138
19.18,35.48,0.138
19.21,35.66,0.138
19.25,35.84,0.139
19.29,36.03,0.139
19.32,36.21,0.140
19.36,36.39,0.140
19.40,36.58,0.140
19.43,36.76,0.141
19.47,36.94,0.141
19.51,37.13,0.142
19.54,37.31,0.142
19.58,37.49,0.143
19.62,37.68,0.143
19.65,37.86,0.143
19.69,38.04,0.144
19.73,38.23,0.144
19.76,38.41,0.145
19.80,38.59,0.145
19.84,38.78,0.146
19.87,38.96,0.146
19.91,39.14,0.146
19.95,39.33,0.147
19.98,39.51,0.147
20.02,39.69,0.148
20.06,39.88,0.149
20.09,40.06,0.149
20.13,40.24,0.150
20.17,40.43,0.150
20.20,40.61,0.151
20.24,40.79,0.151
20.28,40.98,0.152
20.31,41.16,0.152
20.35,41.34,0.153
20.39,41.53,0.153
20.42,41.71,0.154
20.46,41.89,0.154
20.50,42.07,0.155
20.53,42.26,0.156
20.57,42.44,0.156
20.61,42.62,0.157
20.64,42.81,0.157
20.68,42.99,0.158
20.72,43.18,0.159
20.75,43.36,0.159
20.79,43.54,0.160
20.83,43.72,0.161
20.86,43.91,0.161
20.90,44.09,0.162
20.94,44.27,0.162
20.97,44.46,0.163
21.01,44.64,0.164
21.05,44.82,0.164
21.08,45.01,0.165
21.12,45.19,0.166
21.16,45.37,0.166
21.19,45.56,0.167
21.23,45.74,0.168
21.27,45.92,0.169
21.30,46.11,0.169
21.34,46.29,0.170
21.38,46.47,0.171
21.41,46.66,0.171
21.45,46.84,0.172
21.49,47.02,0.173
21.52,47.20,0.174
21.56,47.39,0.174
21.60,47.57,0.175
21.63,47.75,0.176
21.67,47.94,0.177
21.71,48.12,0.177
21.74,48.30,0.178
21.78,48.49,0.179
21.82,48.67,0.179
21.85,48.85,0.180
21.89,49.04,0.181
21.93,49.22,0.181
21.96,49.40,0.182
22.00,49.59,0.183
22.04,49.77,0.183
22.07,49.95,0.184
22.11,50.14,0.185
22.15,50.32,0.185
22.18,50.50,0.186
22.22,50.69,0.186
22.26,50.87,0.187
22.29,51.05,0.188
22.33,51.24,0.188
22.37,51.42,0.189
22.40,51.60,0.189
22.44,51.79,0.190
22.48,51.97,0.190
22.51,52.15,0.191
22.55,52.34,0.191
22.59,52.52,0.192
22.62,52.70,0.192
22.66,52.89,0.193
22.70,53.07,0.193
22.73,53.25,0.194
22.77,53.44,0.194
22.81,53.62,0.195
22.84,53.80,0.195
22.88,53.99,0.196
22.92,54.17,0.196
22.95,54.35,0.196
22.99,54.54,0.197
23.03,54.72,0.197
23.06,54.90,0.198
23.10,55.09,0.198
23.14,55.27,0.199
23.17,55.45,0.199
23.21,55.64,0.200
23.25,55.82,0.200
23.28,56.00,0.201
23.32,56.19,0.202
23.36,56.37,0.202
23.39,56.56,0.203
23.43,56.74,0.203
23.47,56.92,0.204
23.50,57.10,0.205
23.54,57.29,0.205
23.58,57.47,0.206
23.61,57.65,0.206
23.65,57.84,0.207
23.69,58.02,0.208
23.72,58.20,0.208
23.76,58.39,0.209
23.80,58.57,0.210
23.83,58.75,0.211
23.87,58.94,0.211
23.91,59.12,0.212
23.94,59.30,0.213
23.98,59.49,0.214
24.02,59.67,0.215
24.05,59.85,0.215
24.09,60.04,0.216
24.13,60.22,0.217
24.16,60.40,0.218
24.20,60.59,0.219
24.24,60.77,0.220
24.27,60.95,0.221
24.31,61.13,0.222
24.35,61.32,0.222
24.38,61.50,0.223
24.42,61.68,0.224
24.46,61.87,0.225
24.49,62.05,0.226
24.53,62.23,0.227
24.57,62.42,0.228
24.60,62.60,0.229
24.64,62.78,0.230
24.68,62.97,0.231
24.71,63.15,0.232
24.75,63.33,0.233
24.79,63.51,0.234
24.82,63.70,0.235
24.86,63.88,0.236
24.90,64.06,0.237
24.93,64.25,0.238
24.97,64.43,0.239
25.01,64.61,0.240
25.04,64.80,0.241
25.08,64.98,0.242
25.12,65.16,0.244
25.15,65.35,0.245
25.19,65.53,0.246
25.23,65.71,0.247
25.26,65.90,0.248
25.30,66.08,0.250
25.34,66.26,0.251
25.37,66.45,0.252
25.41,66.63,0.253
25.45,66.81,0.254
25.48,67.00,0.255
25.52,67.18,0.257
25.56,67.36,0.258
25.59,67.54,0.259
25.63,67.73,0.260
25.67,67.91,0.262
25.70,68.09,0.263
25.74,68.28,0.264
25.78,68.46,0.265
25.81,68.64,0.267
25.85,68.83,0.268
25.89,69.01,0.269
25.92,69.19,0.271
25.96,69.37,0.272
26.00,69.56,0.273
26.03,69.74,0.275
26.07,69.92,0.276
26.11,70.10,0.277
26.14,70.29,0.278
26.18,70.47,0.280
26.22,70.65,0.281
26.25,70.84,0.283
26.29,71.02,0.284
26.33,71.20,0.286
26.36,71.39,0.287
26.40,71.57,0.289
26.44,71.75,0.290
26.47,71.94,0.292
26.51,72.12,0.293
26.55,72.30,0.295
26.58,72.48,0.296
26.62,72.67,0.298
26.66,72.85,0.299
26.69,73.03,0.301
26.73,73.22,0.302
26.77,73.40,0.304
26.80,73.58,0.305
26.84,73.76,0.307
26.88,73.95,0.309
26.91,74.13,0.310
26.95,74.31,0.312
26.99,74.50,0.313
27.02,74.68,0.315
27.06,74.86,0.316
27.10,75.05,0.318
27.13,75.23,0.320
27.17,75.41,0.321
27.21,75.59,0.323
27.24,75.78,0.325
27.28,75.96,0.326
27.32,76.14,0.328
27.35,76.33,0.330
27.39,76.51,0.332
27.43,76.69,0.333
27.46,76.88,0.334
27.50,77.06,0.336
27.54,77.24,0.338
27.57,77.42,0.339
27.61,77.61,0.341
27.65,77.79,0.343
27.68,77.97,0.345
27.72,78.15,0.347
27.76,78.34,0.348
27.79,78.52,0.350
27.83,78.70,0.352
27.87,78.89,0.354
27.90,79.07,0.355
27.94,79.25,0.357
27.98,79.44,0.359
28.01,79.62,0.361
28.05,79.80,0.362
28.09,79.98,0.364
28.12,80.17,0.366
28.16,80.35,0.367
28.20,80.53,0.369
28.23,80.71,0.371
28.27,80.90,0.373
28.31,81.08,0.375
28.34,81.26,0.377
28.38,81.45,0.378
28.42,81.63,0.380
28.45,81.81,0.382
28.49,82.00,0.384
28.53,82.18,0.385
28.56,82.36,0.387
28.60,82.54,0.389
28.64,82.73,0.391
28.67,82.91,0.393
28.71,83.09,0.394
28.75,83.28,0.396
28.78,83.46,0.398
28.82,83.64,0.400
28.86,83.82,0.401
28.89,84.01,0.403
28.93,84.19,0.405
28.97,84.37,0.407
29.00,84.56,0.408
29.04,84.74,0.410
29.08,84.92,0.412
29.11,85.10,0.414
29.15,85.29,0.415
29.19,85.47,0.417
29.22,85.65,0.419
29.26,85.84,0.421
29.30,86.02,0.423
29.33,86.20,0.425
29.37,86.38,0.426
29.41,86.57,0.428
29.44,86.75,0.430
29.48,86.93,0.431
29.52,87.12,0.433
29.55,87.30,0.435
29.59,87.48,0.437
29.63,87.66,0.438
29.66,87.85,0.440
29.70,88.03,0.442
29.74,88.21,0.444
29.77,88.40,0.445
29.81,88.58,0.447
29.85,88.76,0.449
29.88,88.94,0.451
29.92,89.13,0.453
29.96,89.31,0.454
29.99,89.49,0.456
30.03,89.68,0.458
30.07,89.86,0.459
30.10,90.04,0.461
30.14,90.23,0.463
30.18,90.41,0.464
30.21,90.59,0.466
30.25,90.77,0.468
30.29,90.96,0.469
30.32,91.14,0.471
30.36,91.32,0.472
30.40,91.51,0.474
30.43,91.69,0.475
30.47,91.87,0.477
30.51,92.06,0.478
30.54,92.24,0.480
30.58,92.42,0.481
30.62,92.61,0.483
30.65,92.79,0.484
30.69,92.97,0.486
30.73,93.15,0.487
30.76,93.34,0.489
30.80,93.52,0.490
30.84,93.70,0.491
30.87,93.89,0.493
30.91,94.07,0.494
30.95,94.25,0.495
30.98,94.44,0.497
31.02,94.62,0.498
31.06,94.80,0.499
31.09,94.98,0.501
31.13,95.17,0.502
31.17,95.35,0.503
31.20,95.53,0.505
31.24,95.72,0.506
31.28,95.90,0.507
31.31,96.08,0.508
31.35,96.27,0.510
31.39,96.45,0.511
31.42,96.63,0.512
31.46,96.82,0.513
31.50,97.00,0.514
31.53,97.18,0.515
31.57,97.36,0.516
31.61,97.55,0.517
31.64,97.73,0.518
31.68,97.91,0.519
31.72,98.10,0.520
31.75,98.28,0.521
31.79,98.46,0.522
31.83,98.65,0.523
31.86,98.83,0.524
31.90,99.01,0.524
31.94,99.20,0.525
31.97,99.38,0.526
32.01,99.56,0.527
32.05,99.75,0.528
32.08,99.93,0.528
32.12,100.11,0.529
32.16,100.30,0.530
32.19,100.48,0.530
32.23,100.66,0.531
32.27,100.85,0.531
32.30,101.03,0.532
32.34,101.21,0.532
32.38,101.40,0.533
32.41,101.58,0.533
32.45,101.76,0.534
32.49,101.95,0.534
32.52,102.13,0.534
32.56,102.32,0.534
32.60,102.50,0.535
32.63,102.68,0.535
32.67,102.87,0.535
32.71,103.05,0.535
32.74,103.23,0.535
32.78,103.42,0.535
32.82,103.60,0.535
32.85,103.79,0.535
32.89,103.97,0.535
32.93,104.15,0.535
32.96,104.34,0.535
33.00,104.52,0.534
33.04,104.70,0.534
33.07,104.89,0.534
33.11,105.07,0.534
33.15,105.25,0.533
33.18,105.44,0.533
33.22,105.62,0.532
33.26,105.81,0.532
33.29,105.99,0.531
33.33,106.17,0.531
33.37,106.36,0.530
33.40,106.54,0.529
33.44,106.72,0.529
33.48,106.91,0.528
33.51,107.09,0.527
33.55,107.28,0.526
33.59,107.46,0.526
33.62,107.64,0.525
33.66,107.83,0.524
33.70,108.01,0.523
33.73,108.19,0.522
33.77,108.38,0.521
33.81,108.56,0.519
33.84,108.75,0.518
33.88,108.93,0.517
33.92,109.11,0.516
33.95,109.30,0.515
33.99,109.48,0.513
34.03,109.67,0.512
34.06,109.85,0.510
34.10,110.03,0.509
34.14,110.22,0.507
34.17,110.40,0.506
34.21,110.58,0.504
34.25,110.77,0.502
34.28,110.95,0.501
34.32,111.14,0.499
34.36,111.32,0.498
34.39,111.50,0.496
34.43,111.69,0.494
34.47,111.87,0.492
34.50,112.06,0.491
34.54,112.24,0.488
34.58,112.43,0.486
34.61,112.61,0.485
34.65,112.79,0.483
34.69,112.98,0.480
34.72,113.16,0.478
34.76,113.34,0.476
34.80,113.53,0.474
34.83,113.71,0.472
34.87,113.90,0.470
34.91,114.08,0.468
34.94,114.27,0.466
34.98,114.45,0.464
35.02,114.64,0.462
35.05,114.82,0.459
35.09,115.00,0.457
35.13,115.19,0.455
35.16,115.37,0.452
35.20,115.56,0.450
35.24,115.74,0.448
35.27,115.92,0.446
35.31,116.11,0.444
35.35,116.29,0.442
35.38,116.47,0.440
35.42,116.66,0.437
35.46,116.84,0.435
35.49,117.03,0.433
35.53,117.21,0.431
35.57,117.40,0.429
35.60,117.58,0.426
35.64,117.76,0.424
35.68,117.95,0.422
35.71,118.13,0.419
35.75,118.32,0.417
35.79,118.50,0.414
35.82,118.69,0.412
35.86,118.87,0.410
35.90,119.06,0.407
35.93,119.24,0.405
35.97,119.42,0.403
36.01,119.61,0.401
36.04,119.79,0.398
36.08,119.97,0.396
36.12,120.16,0.393
36.15,120.34,0.391
36.19,120.53,0.388
36.23,120.71,0.386
36.26,120.90,0.384
36.30,121.08,0.382
36.34,121.26,0.379
36.37,121.45,0.377
36.41,121.63,0.375
36.45,121.82,0.372
36.48,122.00,0.370
36.52,122.19,0.367
36.56,122.37,0.365
36.59,122.55,0.363
36.63,122.74,0.361
36.67,122.92,0.359
36.70,123.11,0.357
36.74,123.29,0.354
36.78,123.47,0.352
36.81,123.66,0.349
36.85,123.84,0.347
36.89,124.03,0.345
36.92,124.21,0.343
36.96,124.40,0.341
37.00,124.58,0.339
37.03,124.76,0.337
37.07,124.95,0.334
37.11,125.13,0.332
37.14,125.32,0.329
37.18,125.50,0.327
37.22,125.69,0.325
37.25,125.87,0.323
37.29,126.05,0.321
37.33,126.24,0.319
37.36,126.42,0.317
37.40,126.60,0.314
37.44,126.79,0.312
37.47,126.97,0.310
37.51,127.16,0.308
37.55,127.34,0.306
37.58,127.53,0.304
37.62,127.71,0.302
37.66,127.90,0.300
37.69,128.08,0.298
37.73,128.26,0.296
37.77,128.45,0.294
37.80,128.63,0.291
37.84,128.82,0.289
37.88,129.00,0.287
37.91,129.18,0.285
37.95,129.37,0.283
37.99,129.55,0.280
38.02,129.73,0.278
38.06,129.92,0.277
38.10,130.10,0.275
38.13,130.29,0.273
38.17,130.47,0.271
38.21,130.66,0.269
38.24,130.84,0.268
38.28,131.02,0.266
38.32,131.21,0.264
38.35,131.39,0.262
38.39,131.58,0.260
38.43,131.76,0.258
38.46,131.94,0.256
38.50,132.13,0.254
38.54,132.31,0.252
38.57,132.50,0.251
38.61,132.68,0.249
38.65,132.87,0.247
38.68,133.05,0.245
38.72,133.23,0.243
38.76,133.42,0.242
38.79,133.60,0.240
38.83,133.78,0.238
38.87,133.97,0.236
38.90,134.15,0.235
38.94,134.34,0.233
38.98,134.52,0.232
39.01,134.70,0.230
39.05,134.89,0.228
39.09,135.07,0.226
39.12,135.26,0.224
39.16,135.44,0.223
39.20,135.62,0.221
39.23,135.81,0.220
39.27,135.99,0.218
39.31,136.18,0.217
39.34,136.36,0.215
39.38,136.54,0.213
39.42,136.73,0.212
39.45,136.91,0.210
39.49,137.10,0.208
39.53,137.28,0.207
39.56,137.46,0.206
39.60,137.65,0.204
39.64,137.83,0.203
39.67,138.02,0.201
39.71,138.20,0.200
39.75,138.38,0.198
39.78,138.57,0.197
39.82,138.75,0.195
39.86,138.94,0.194
39.89,139.12,0.192
39.93,139.30,0.191
39.97,139.49,0.190
40.00,139.67,0.188
40.04,139.85,0.187
40.08,140.04,0.185
40.11,140.22,0.184
40.15,140.41,0.183
40.19,140.59,0.182
40.22,140.77,0.180
40.26,140.96,0.179
40.30,141.14,0.178
40.33,141.32,0.176
40.37,141.51,0.175
40.41,141.69,0.174
40.44,141.88,0.173
40.48,142.06,0.172
40.52,142.24,0.170
40.55,142.43,0.169
40.59,142.61,0.168
40.63,142.80,0.167
40.66,142.98,0.166
40.70,143.16,0.165
40.74,143.35,0.164
40.77,143.53,0.162
40.81,143.71,0.161
40.85,143.90,0.160
40.88,144.08,0.159
40.92,144.27,0.158
40.96,144.45,0.157
40.99,144.63,0.156
41.03,144.82,0.155
41.07,145.00,0.154
41.10,145.18,0.154
41.14,145.37,0.153
41.18,145.55,0.152
41.21,145.73,0.151
41.25,145.92,0.150
41.29,146.10,0.149
41.32,146.29,0.148
41.36,146.47,0.147
41.40,146.65,0.146
41.43,146.84,0.146
41.47,147.02,0.145
41.51,147.20,0.144
41.54,147.39,0.143
41.58,147.57,0.142
41.62,147.75,0.142
41.65,147.94,0.141
41.69,148.12,0.140
41.73,148.30,0.140
41.76,148.49,0.139
41.80,148.67,0.138
41.84,148.86,0.138
41.87,149.04,0.137
41.91,149.22,0.137
41.95,149.41,0.136
41.98,149.59,0.135
42.02,149.77,0.135
42.06,149.96,0.135
42.09,150.14,0.134
42.13,150.32,0.134
42.17,150.50,0.133
42.20,150.69,0.132
42.24,150.87,0.132
42.28,151.06,0.132
42.31,151.24,0.131
42.35,151.42,0.131
42.39,151.61,0.131
42.42,151.79,0.130
42.46,151.98,0.130
42.50,152.16,0.130
42.53,152.34,0.130
42.57,152.53,0.129
42.61,152.71,0.129
42.64,152.89,0.129
42.68,153.08,0.129
42.72,153.26,0.129
42.75,153.44,0.128
42.79,153.63,0.128
42.83,153.81,0.128
42.86,153.99,0.128
42.90,154.18,0.128
42.94,154.36,0.128
42.97,154.54,0.128
43.01,154.73,0.128
43.05,154.91,0.128
43.08,155.09,0.128
43.12,155.28,0.128
43.16,155.46,0.128
43.19,155.65,0.128
43.23,155.83,0.128
43.27,156.01,0.128
43.30,156.20,0.129
43.34,156.38,0.129
43.38,156.56,0.129
43.41,156.74,0.129
43.45,156.93,0.129
43.49,157.11,0.130
43.52,157.30,0.130
43.56,157.48,0.130
43.60,157.66,0.130
43.63,157.84,0.131
43.67,158.03,0.131
43.71,158.21,0.131
43.74,158.39,0.131
43.78,158.58,0.132
43.82,158.76,0.132
43.85,158.95,0.132
43.89,159.13,0.133
43.93,159.31,0.133
43.96,159.49,0.133
44.00,159.68,0.134
44.04,159.86,0.134
44.07,160.04,0.134
44.11,160.23,0.134
44.15,160.41,0.134
44.18,160.59,0.135
44.22,160.78,0.135
44.26,160.96,0.135
44.29,161.14,0.135
44.33,161.33,0.135
44.37,161.51,0.135
44.40,161.69,0.135
44.44,161.88,0.135
44.48,162.06,0.135
44.51,162.25,0.135
44.55,162.43,0.135
44.59,162.61,0.135
44.62,162.80,0.135
44.66,162.98,0.135
44.70,163.16,0.135
44.73,163.35,0.135
44.77,163.53,0.135
44.81,163.71,0.134
44.84,163.90,0.134
44.88,164.08,0.134
44.92,164.26,0.134
44.95,164.45,0.134
44.99,164.63,0.133
45.03,164.81,0.133
45.06,165.00,0.133
45.10,165.18,0.133
45.14,165.36,0.133
45.17,165.55,0.132
45.21,165.73,0.132
45.25,165.91,0.132
45.28,166.10,0.132
45.32,166.28,0.132
45.36,166.47,0.132
45.39,166.65,0.132
45.43,166.83,0.131
45.47,167.02,0.131
45.50,167.20,0.131
45.54,167.38,0.131
45.58,167.57,0.131
45.61,167.75,0.131
45.65,167.93,0.131
45.69,168.12,0.131
45.72,168.30,0.131
45.76,168.48,0.131
45.80,168.67,0.131
45.83,168.85,0.131
45.87,169.03,0.131
45.91,169.22,0.131
45.94,169.40,0.131
45.98,169.58,0.131
46.02,169.77,0.131
46.05,169.95,0.131
46.09,170.13,0.131
46.13,170.32,0.131
46.16,170.50,0.131
46.20,170.68,0.131
46.24,170.87,0.131
46.27,171.05,0.131
46.31,171.23,0.131
46.35,171.42,0.131
46.38,171.60,0.131
46.42,171.78,0.131
46.46,171.97,0.131
46.49,172.15,0.131
46.53,172.34,0.131
46.57,172.52,0.131
46.60,172.70,0.131
46.64,172.89,0.131
46.68,173.07,0.131
46.71,173.25,0.131
46.75,173.44,0.131
46.79,173.62,0.131
46.82,173.80,0.131
46.86,173.98,0.132
46.90,174.17,0.132
46.93,174.35,0.132
46.97,174.53,0.132
47.01,174.72,0.132
47.04,174.90,0.132
47.08,175.09,0.132
47.12,175.27,0.132
47.15,175.45,0.132
47.19,175.64,0.132
47.23,175.82,0.132
47.26,176.00,0.132
47.30,176.19,0.133
47.34,176.37,0.133
47.37,176.55,0.133
47.41,176.74,0.133
47.45,176.92,0.133
47.48,177.10,0.133
47.52,177.29,0.133
47.56,177.47,0.133
47.59,177.65,0.133
47.63,177.84,0.133
47.67,178.02,0.133
47.70,178.20,0.133
47.74,178.39,0.133
47.78,178.57,0.133
47.81,178.75,0.134
47.85,178.94,0.134
47.89,179.12,0.134
47.92,179.30,0.134
47.96,179.49,0.134
48.00,179.67,0.134
48.03,179.85,0.134
48.07,180.04,0.134
48.11,180.22,0.134
48.14,180.40,0.134
48.18,180.59,0.134
48.22,180.77,0.135
48.25,180.95,0.135
48.29,181.14,0.135
48.33,181.32,0.135
48.36,181.51,0.135
48.40,181.69,0.135
48.44,181.87,0.135
48.47,182.05,0.136
48.51,182.24,0.136
48.55,182.42,0.136
48.58,182.60,0.136
48.62,182.79,0.136
48.66,182.97,0.136
48.69,183.15,0.136
48.73,183.34,0.136
48.77,183.52,0.137
48.80,183.70,0.137
48.84,183.89,0.137
48.88,184.07,0.137
48.91,184.26,0.137
48.95,184.44,0.137
48.99,184.62,0.137
49.02,184.81,0.137
49.06,184.99,0.138
49.10,185.17,0.138
49.13,185.36,0.138
49.17,185.54,0.138
49.21,185.72,0.138
49.24,185.91,0.138
49.28,186.09,0.138
49.32,186.27,0.138
49.35,186.46,0.139
49.39,186.64,0.139
49.43,186.82,0.139
49.46,187.01,0.139
49.50,187.19,0.139
49.54,187.37,0.139
49.57,187.56,0.139
49.61,187.74,0.139
49.65,187.92,0.139
49.68,188.10,0.140
49.72,188.29,0.140
49.76,188.47,0.140
49.79,188.65,0.140
49.83,188.84,0.140
49.87,189.02,0.140
49.90,189.21,0.140
49.94,189.39,0.140
49.98,189.57,0.141
50.01,189.76,0.141
50.05,189.94,0.141
50.09,190.12,0.141
50.12,190.31,0.141
50.16,190.49,0.141
50.20,190.67,0.142
50.23,190.86,0.142
50.27,191.04,0.142
50.31,191.22,0.142
50.34,191.41,0.142
50.38,191.59,0.142
50.42,191.78,0.142
50.45,191.96,0.142
50.49,192.14,0.142
50.53,192.32,0.142
50.56,192.51,0.142
50.60,192.69,0.142
50.64,192.87,0.142
50.67,193.06,0.143
50.71,193.24,0.143
50.75,193.42,0.143
50.78,193.61,0.143
50.82,193.79,0.143
50.86,193.97,0.143
50.89,194.16,0.143
50.93,194.34,0.143
50.97,194.52,0.143
51.00,194.71,0.143
51.04,194.89,0.144
51.08,195.07,0.144
51.11,195.26,0.144
51.15,195.44,0.144
51.19,195.62,0.144
51.22,195.81,0.144
51.26,195.99,0.144
51.30,196.17,0.144
51.33,196.36,0.144
51.37,196.54,0.144
51.41,196.72,0.144
51.44,196.91,0.144
51.48,197.09,0.145
51.52,197.28,0.145
51.55,197.46,0.145
51.59,197.64,0.145
51.63,197.82,0.145
51.66,198.01,0.145
51.70,198.19,0.145
51.74,198.37,0.145
51.77,198.56,0.145
51.81,198.74,0.145
51.85,198.93,0.145
51.88,199.11,0.145
51.92,199.29,0.145
51.96,199.48,0.146
51.99,199.66,0.146
52.03,199.84,0.146
52.07,200.03,0.146
52.10,200.21,0.146
52.14,200.39,0.146
52.18,200.58,0.146
52.21,200.76,0.146
52.25,200.94,0.146
52.29,201.13,0.146
52.32,201.31,0.146
52.36,201.49,0.146
52.40,201.68,0.146
52.43,201.86,0.146
52.47,202.04,0.146
52.51,202.23,0.146
52.54,202.41,0.146
52.58,202.59,0.146
52.62,202.78,0.146
52.65,202.96,0.146
52.69,203.14,0.146
52.73,203.33,0.146
52.76,203.51,0.146
52.80,203.69,0.146
52.84,203.88,0.146
52.87,204.06,0.147
52.91,204.25,0.147
52.95,204.43,0.147
52.98,204.61,0.147
53.02,204.80,0.147
53.06,204.98,0.147
53.09,205.16,0.147
53.13,205.35,0.147
53.17,205.53,0.147
53.20,205.71,0.147
53.24,205.89,0.147
53.28,206.08,0.147
53.31,206.26,0.147
53.35,206.44,0.147
53.39,206.63,0.147
53.42,206.81,0.147
53.46,206.99,0.147
53.50,207.18,0.147
53.53,207.36,0.147
53.57,207.54,0.147
53.61,207.73,0.147
53.64,207.91,0.147
53.68,208.09,0.147
53.72,208.28,0.147
53.75,208.46,0.147
53.79,208.65,0.147
53.83,208.83,0.147
53.86,209.01,0.148
53.90,209.20,0.148
53.94,209.38,
53.97,209.56,
53.99,,

[step]
Ramp 5.00 °C/min to -60.00 °C
Time,Temperature,Heat Flow (Normalized)
min,°C,W/g
54.99,210.16,-0.036
55.02,210.16,-0.036
55.06,210.14,-0.036
55.10,210.07,-0.056
55.13,209.96,-0.099
55.17,209.82,-0.143
55.21,209.66,-0.175
55.24,209.49,-0.191
55.28,209.31,-0.201
55.32,209.14,-0.206
55.35,208.96,-0.208
55.39,208.78,-0.210
55.43,208.59,-0.211
55.46,208.41,-0.211
55.50,208.23,-0.212
55.54,208.05,-0.212
55.57,207.87,-0.212
55.61,207.69,-0.213
55.65,207.50,-0.213
55.68,207.32,-0.213
55.72,207.14,-0.214
55.76,206.96,-0.214
55.79,206.78,-0.214
55.83,206.59,-0.214
55.87,206.41,-0.214
55.90,206.23,-0.215
55.94,206.04,-0.215
55.98,205.86,-0.215
56.01,205.68,-0.215
56.05,205.50,-0.215
56.09,205.32,-0.215
56.12,205.13,-0.215
56.16,204.95,-0.215
56.20,204.77,-0.215
56.23,204.58,-0.215
56.27,204.40,-0.215
56.31,204.22,-0.215
56.34,204.03,-0.216
56.38,203.85,-0.216
56.42,203.67,-0.216
56.45,203.48,-0.216
56.49,203.30,-0.216
56.53,203.12,-0.215
56.56,202.94,-0.215
56.60,202.75,-0.215
56.64,202.57,-0.215
56.67,202.39,-0.215
56.71,202.20,-0.216
56.75,202.02,-0.216
56.78,201.84,-0.216
56.82,201.65,-0.216
56.86,201.47,-0.216
56.89,201.29,-0.216
56.93,201.10,-0.216
56.97,200.92,-0.216
57.00,200.74,-0.215
57.04,200.56,-0.215
57.08,200.37,-0.215
57.11,200.19,-0.215
57.15,200.00,-0.215
57.19,199.82,-0.215
57.22,199.64,-0.215
57.26,199.45,-0.215
57.30,199.27,-0.215
57.33,199.09,-0.215
57.37,198.90,-0.215
57.41,198.72,-0.215
57.44,198.54,-0.215
57.48,198.35,-0.215
57.52,198.17,-0.215
57.55,197.99,-0.215
57.59,197.81,-0.215
57.63,197.62,-0.215
57.66,197.44,-0.215
57.70,197.25,-0.215
57.74,197.07,-0.215
57.77,196.89,-0.215
57.81,196.70,-0.215
57.85,196.52,-0.215
57.88,196.34,-0.215
57.92,196.16,-0.215
57.96,195.97,-0.215
57.99,195.79,-0.215
58.03,195.60,-0.215
58.07,195.42,-0.215
58.10,195.24,-0.215
58.14,195.06,-0.215
58.18,194.87,-0.215
58.21,194.69,-0.215
58.25,194.51,-0.215
58.29,194.32,-0.215
58.32,194.14,-0.215
58.36,193.96,-0.215
58.40,193.77,-0.215
58.43,193.59,-0.215
58.47,193.41,-0.215
58.51,193.22,-0.215
58.54,193.04,-0.215
58.58,192.86,-0.215
58.62,192.67,-0.215
58.65,192.49,-0.215
58.69,192.31,-0.215
58.73,192.12,-0.215
58.76,191.94,-0.215
58.80,191.75,-0.215
58.84,191.57,-0.215
58.87,191.39,-0.215
58.91,191.20,-0.215
58.95,191.02,-0.215
58.98,190.84,-0.214
59.02,190.65,-0.214
59.06,190.47,-0.214
59.09,190.29,-0.214
59.13,190.11,-0.214
59.17,189.92,-0.214
59.20,189.74,-0.214
59.24,189.56,-0.214
59.28,189.37,-0.214
59.31,189.19,-0.214
59.35,189.00,-0.214
59.39,188.82,-0.214
59.42,188.64,-0.214
59.46,188.46,-0.214
59.50,188.27,-0.214
59.53,188.09,-0.214
59.57,187.91,-0.214
59.61,187.72,-0.214
59.64,187.54,-0.214
59.68,187.36,-0.214
59.72,187.17,-0.214
59.75,186.99,-0.214
59.79,186.81,-0.214
59.83,186.62,-0.214
59.86,186.44,-0.214
59.90,186.26,-0.214
59.94,186.07,-0.214
59.97,185.89,-0.213
60.01,185.71,-0.213
60.05,185.52,-0.214
60.08,185.34,-0.214
60.12,185.16,-0.214
60.16,184.97,-0.214
60.19,184.79,-0.214
60.23,184.61,-0.214
60.27,184.42,-0.213
60.30,184.24,-0.213
60.34,184.06,-0.213
60.38,183.87,-0.213
60.41,183.69,-0.213
60.45,183.51,-0.213
60.49,183.32,-0.213
60.52,183.14,-0.213
60.56,182.96,-0.213
60.60,182.77,-0.213
60.63,182.59,-0.213
60.67,182.41,-0.213
60.71,182.22,-0.213
60.74,182.04,-0.213
60.78,181.86,-0.213
60.82,181.67,-0.213
60.85,181.49,-0.213
60.89,181.31,-0.213
60.93,181.12,-0.213
60.96,180.94,-0.213
61.00,180.76,-0.213
61.04,180.57,-0.213
61.07,180.39,-0.213
61.11,180.21,-0.213
61.15,180.02,-0.213
61.18,179.84,-0.213
61.22,179.66,-0.213
61.26,179.47,-0.213
61.29,179.29,-0.212
61.33,179.11,-0.212
61.37,178.92,-0.212
61.40,178.74,-0.212
61.44,178.56,-0.212
61.48,178.38,-0.212
61.51,178.19,-0.212
61.55,178.01,-0.212
61.59,177.82,-0.212
61.62,177.64,-0.212
61.66,177.46,-0.212
61.70,177.28,-0.212
61.73,177.09,-0.212
61.77,176.91,-0.212
61.81,176.72,-0.212
61.84,176.54,-0.212
61.88,176.36,-0.212
61.92,176.17,-0.212
61.95,175.99,-0.212
61.99,175.81,-0.212
62.03,175.62,-0.212
62.06,175.44,-0.212
62.10,175.26,-0.212
62.14,175.08,-0.211
62.17,174.89,-0.211
62.21,174.71,-0.211
62.25,174.52,-0.211
62.28,174.34,-0.211
62.32,174.16,-0.211
62.36,173.97,-0.211
62.39,173.79,-0.211
62.43,173.61,-0.211
62.47,173.42,-0.211
62.50,173.24,-0.211
62.54,173.06,-0.211
62.58,172.88,-0.211
62.61,172.69,-0.211
62.65,172.51,-0.211
62.69,172.32,-0.211
62.72,172.14,-0.211
62.76,171.96,-0.210
62.80,171.77,-0.210
62.83,171.59,-0.210
62.87,171.41,-0.210
62.91,171.22,-0.210
62.94,171.04,-0.210
62.98,170.86,-0.210
63.02,170.67,-0.210
63.05,170.49,-0.210
63.09,170.31,-0.210
63.13,170.12,-0.210
63.16,169.94,-0.210
63.20,169.76,-0.209
63.24,169.57,-0.209
63.27,169.39,-0.209
63.31,169.21,-0.209
63.35,169.03,-0.209
63.38,168.84,-0.209
63.42,168.66,-0.209
63.46,168.48,-0.208
63.49,168.29,-0.208
63.53,168.11,-0.208
63.57,167.92,-0.208
63.60,167.74,-0.208
63.64,167.56,-0.208
63.68,167.38,-0.207
63.71,167.19,-0.207
63.75,167.01,-0.207
63.79,166.82,-0.207
63.82,166.64,-0.207
63.86,166.46,-0.207
63.90,166.27,-0.206
63.93,166.09,-0.206
63.97,165.91,-0.206
64.01,165.72,-0.206
64.04,165.54,-0.206
64.08,165.36,-0.205
64.12,165.17,-0.205
64.15,164.99,-0.205
64.19,164.81,-0.205
64.23,164.62,-0.204
64.26,164.44,-0.204
64.30,164.26,-0.204
64.34,164.07,-0.204
64.37,163.89,-0.204
64.41,163.71,-0.203
64.45,163.52,-0.203
64.48,163.34,-0.203
64.52,163.16,-0.203
64.56,162.97,-0.203
64.59,162.79,-0.202
64.63,162.61,-0.202
64.67,162.42,-0.202
64.70,162.24,-0.201
64.74,162.06,-0.201
64.78,161.87,-0.201
64.81,161.69,-0.201
64.85,161.51,-0.200
64.89,161.32,-0.200
64.92,161.14,-0.200
64.96,160.96,-0.200
65.00,160.77,-0.200
65.03,160.59,-0.199
65.07,160.41,-0.199
65.11,160.22,-0.199
65.14,160.04,-0.198
65.18,159.85,-0.198
65.22,159.67,-0.198
65.25,159.49,-0.198
65.29,159.31,-0.198
65.33,159.12,-0.197
65.36,158.94,-0.197
65.40,158.76,-0.197
65.44,158.57,-0.197
65.47,158.39,-0.196
65.51,158.21,-0.196
65.55,158.02,-0.196
65.58,157.84,-0.196
65.62,157.65,-0.196
65.66,157.47,-0.196
65.69,157.29,-0.195
65.73,157.10,-0.195
65.77,156.92,-0.195
65.80,156.74,-0.195
65.84,156.56,-0.194
65.88,156.37,-0.194
65.91,156.19,-0.194
65.95,156.01,-0.194
65.99,155.82,-0.193
66.02,155.64,-0.193
66.06,155.45,-0.193
66.10,155.27,-0.193
66.13,155.09,-0.193
66.17,154.90,-0.193
66.21,154.72,-0.192
66.24,154.54,-0.192
66.28,154.35,-0.192
66.32,154.17,-0.192
66.35,153.99,-0.192
66.39,153.81,-0.191
66.43,153.62,-0.191
66.46,153.44,-0.191
66.50,153.25,-0.191
66.54,153.07,-0.191
66.57,152.89,-0.190
66.61,152.70,-0.190
66.65,152.52,-0.190
66.68,152.34,-0.190
66.72,152.15,-0.190
66.76,151.97,-0.190
66.79,151.79,-0.189
66.83,151.60,-0.189
66.87,151.42,-0.189
66.90,151.24,-0.189
66.94,151.05,-0.189
66.98,150.87,-0.189
67.01,150.69,-0.188
[...]
245.54,67.30,0.085,0.902
245.58,67.48,0.085,0.902
245.62,67.66,0.085,0.902
245.65,67.85,0.085,0.903
245.69,68.03,0.085,0.904
245.73,68.21,0.085,0.904
245.76,68.40,0.085,0.904
245.80,68.58,0.085,0.904
245.84,68.76,0.085,0.905
245.87,68.95,0.085,0.905
245.91,69.13,0.085,0.906
245.95,69.31,0.085,0.905
245.98,69.50,0.085,0.906
246.02,69.68,0.085,0.907
246.06,69.87,0.085,0.907
246.09,70.05,0.085,0.908
246.13,70.23,0.085,0.907
246.17,70.42,0.085,0.909
246.20,70.60,0.085,0.910
246.24,70.78,0.085,0.910
246.28,70.97,0.085,0.911
246.31,71.15,0.085,0.911
246.35,71.33,0.085,0.912
246.39,71.52,0.085,0.912
246.42,71.70,0.085,0.911
246.46,71.88,0.086,0.912
246.50,72.07,0.086,0.912
246.53,72.25,0.086,0.912
246.57,72.43,0.086,0.913
246.61,72.62,0.086,0.914
246.64,72.80,0.086,0.914
246.68,72.98,0.086,0.915
246.72,73.17,0.086,0.916
246.75,73.35,0.086,0.916
246.79,73.54,0.086,0.917
246.83,73.72,0.086,0.917
246.86,73.90,0.086,0.918
246.90,74.09,0.086,0.918
246.94,74.27,0.086,0.918
246.97,74.45,0.086,0.919
247.01,74.64,0.086,0.920
247.05,74.82,0.086,0.920
247.08,75.00,0.086,0.922
247.12,75.19,0.086,0.922
247.16,75.37,0.087,0.923
247.19,75.55,0.087,0.922
247.23,75.74,0.087,0.923
247.27,75.92,0.087,0.923
247.30,76.10,0.087,0.924
247.34,76.29,0.087,0.925
247.38,76.47,0.087,0.926
247.41,76.65,0.087,0.926
247.45,76.84,0.087,0.927
247.49,77.02,0.087,0.927
247.52,77.20,0.087,0.927
247.56,77.39,0.087,0.927
247.60,77.57,0.087,0.927
247.63,77.75,0.087,0.928
247.67,77.94,0.087,0.927
247.71,78.12,0.087,0.928
247.74,78.30,0.087,0.928
247.78,78.49,0.087,0.928
247.82,78.67,0.087,0.927
247.85,78.86,0.087,0.928
247.89,79.04,0.087,0.928
247.93,79.22,0.087,0.929
247.96,79.41,0.087,0.931
248.00,79.59,0.087,0.932
248.04,79.77,0.087,0.933
248.07,79.96,0.087,0.934
248.11,80.14,0.087,0.933
248.15,80.32,0.087,0.933
248.18,80.51,0.087,0.932
248.22,80.69,0.087,0.934
248.26,80.87,0.088,0.934
248.29,81.06,0.088,0.934
248.33,81.24,0.088,0.935
248.37,81.42,0.088,0.935
248.40,81.61,0.088,0.937
248.44,81.79,0.088,0.938
248.48,81.97,0.088,0.939
248.51,82.16,0.088,0.939
248.55,82.34,0.088,0.940
248.59,82.52,0.088,0.940
248.62,82.71,0.088,0.939
248.66,82.89,0.088,0.940
248.70,83.07,0.088,0.941
248.73,83.26,0.088,0.941
248.77,83.44,0.088,0.941
248.81,83.62,0.088,0.941
248.84,83.81,0.088,0.942
248.88,83.99,0.088,0.942
248.92,84.18,0.088,0.942
248.95,84.36,0.088,0.944
248.99,84.54,0.089,0.945
249.03,84.73,0.089,0.945
249.06,84.91,0.089,0.946
249.10,85.09,0.089,0.945
249.14,85.28,0.089,0.946
249.17,85.46,0.089,0.946
249.21,85.64,0.089,0.947
249.25,85.83,0.089,0.948
249.28,86.01,0.089,0.948
249.32,86.19,0.089,0.948
249.36,86.37,0.089,0.948
249.39,86.56,0.089,0.949
249.43,86.74,0.089,0.949
249.47,86.93,0.089,0.948
249.50,87.11,0.089,0.948
249.54,87.29,0.089,0.949
249.58,87.48,0.089,0.949
249.61,87.66,0.089,0.950
249.65,87.84,0.089,0.951
249.69,88.03,0.089,0.952
249.72,88.21,0.089,0.953
249.76,88.39,0.089,0.954
249.80,88.58,0.089,0.954
249.83,88.76,0.089,0.954
249.87,88.94,0.089,0.953
249.91,89.13,0.089,0.953
249.94,89.31,0.089,0.954
249.98,89.49,0.089,0.954
250.02,89.68,0.090,0.955
250.05,89.86,0.090,0.957
250.09,90.04,0.090,0.957
250.13,90.23,0.090,0.959
250.16,90.41,0.090,0.959
250.20,90.59,0.090,0.959
250.24,90.78,0.090,0.959
250.27,90.96,0.090,0.959
250.31,91.14,0.090,0.959
250.35,91.33,0.090,0.959
250.38,91.51,0.090,0.959
250.42,91.69,0.090,0.961
250.46,91.88,0.090,0.962
250.49,92.06,0.090,0.963
250.53,92.25,0.090,0.964
250.57,92.43,0.090,0.962
250.60,92.61,0.090,0.962
250.64,92.80,0.090,0.963
250.68,92.98,0.090,0.963
250.71,93.16,0.090,0.964
250.75,93.35,0.091,0.965
250.79,93.53,0.091,0.968
250.82,93.71,0.091,0.968
250.86,93.90,0.091,0.968
250.90,94.08,0.091,0.967
250.93,94.26,0.091,0.966
250.97,94.45,0.091,0.966
251.01,94.63,0.091,0.966
251.04,94.81,0.091,0.967
251.08,95.00,0.091,0.968
251.12,95.18,0.091,0.969
251.15,95.36,0.091,0.969
251.19,95.55,0.091,0.969
251.23,95.73,0.091,0.969
251.26,95.91,0.091,0.970
251.30,96.10,0.091,0.972
251.34,96.28,0.091,0.973
251.37,96.47,0.091,0.975
251.41,96.65,0.092,0.976
251.45,96.83,0.092,0.978
251.48,97.02,0.092,0.978
251.52,97.20,0.092,0.979
251.56,97.38,0.092,0.978
251.59,97.57,0.092,0.978
251.63,97.75,0.092,0.979
251.67,97.93,0.092,0.977
251.70,98.12,0.092,0.978
251.74,98.30,0.092,0.978
251.78,98.48,0.092,0.979
251.81,98.67,0.092,0.980
251.85,98.85,0.092,0.980
251.89,99.03,0.092,0.981
251.92,99.22,0.092,0.981
251.96,99.40,0.092,0.981
252.00,99.58,0.092,0.982
252.03,99.77,0.092,0.983
252.07,99.95,0.092,0.983
252.11,100.13,0.092,0.984
252.14,100.32,0.092,0.984
252.18,100.50,0.092,0.983
252.22,100.68,0.093,0.984
252.25,100.87,0.093,0.984
252.29,101.05,0.093,0.985
252.33,101.23,0.093,0.986
252.36,101.42,0.093,0.987
252.40,101.60,0.093,0.988
252.44,101.78,0.093,0.989
252.47,101.97,0.093,0.989
252.51,102.15,0.093,0.990
252.55,102.33,0.093,0.989
252.58,102.52,0.093,0.989
252.62,102.70,0.093,0.988
252.66,102.89,0.093,0.988
252.69,103.07,0.093,0.990
252.73,103.25,0.093,0.991
252.77,103.44,0.093,0.992
252.80,103.62,0.093,0.993
252.84,103.80,0.093,0.994
252.88,103.99,0.093,0.995
252.91,104.17,0.093,0.994
252.95,104.35,0.093,0.993
252.99,104.54,0.093,0.994
253.02,104.72,0.093,0.995
253.06,104.90,0.093,0.995
253.10,105.09,0.094,0.996
253.13,105.27,0.094,0.996
253.17,105.45,0.094,0.996
253.21,105.64,0.094,0.996
253.24,105.82,0.094,0.998
253.28,106.00,0.094,0.998
253.32,106.19,0.094,0.998
253.35,106.37,0.094,0.998
253.39,106.55,0.094,0.998
253.43,106.74,0.094,0.998
253.46,106.92,0.094,0.999
253.50,107.11,0.094,1.000
253.54,107.29,0.094,1.002
253.57,107.47,0.094,1.003
253.61,107.66,0.094,1.003
253.65,107.84,0.094,1.004
253.68,108.02,0.094,1.005
253.72,108.21,0.094,1.005
253.76,108.39,0.094,1.005
253.79,108.57,0.094,1.005
253.83,108.76,0.094,1.004
253.87,108.94,0.094,1.005
253.90,109.12,0.094,1.005
253.94,109.31,0.095,1.006
253.98,109.49,0.095,1.006
254.01,109.67,0.095,1.007
254.05,109.86,0.095,1.008
254.09,110.04,0.095,1.009
254.12,110.22,0.095,1.009
254.16,110.41,0.095,1.009
254.20,110.59,0.095,1.009
254.23,110.77,0.095,1.009
254.27,110.96,0.095,1.011
254.31,111.14,0.095,1.011
254.34,111.32,0.095,1.011
254.38,111.51,0.095,1.012
254.42,111.69,0.095,1.012
254.45,111.87,0.095,1.013
254.49,112.06,0.095,1.013
254.53,112.24,0.095,1.015
254.56,112.42,0.095,1.015
254.60,112.61,0.095,1.016
254.64,112.79,0.095,1.015
254.67,112.97,0.096,1.015
254.71,113.16,0.096,1.015
254.75,113.34,0.096,1.016
254.78,113.52,0.096,1.015
254.82,113.71,0.096,1.015
254.86,113.89,0.096,1.016
254.89,114.08,0.096,1.017
254.93,114.26,0.096,1.018
254.97,114.44,0.096,1.021
255.00,114.63,0.096,1.022
255.04,114.81,0.096,1.023
255.08,114.99,0.096,1.023
255.11,115.17,0.096,1.023
255.15,115.36,0.096,1.022
255.19,115.54,0.096,1.022
255.22,115.73,0.096,1.023
255.26,115.91,0.096,1.023
255.30,116.09,0.096,1.024
255.33,116.28,0.096,1.025
255.37,116.46,0.096,1.024
255.41,116.64,0.096,1.024
255.44,116.83,0.096,1.023
255.48,117.01,0.096,1.025
255.52,117.19,0.096,1.026
255.55,117.38,0.097,1.026
255.59,117.56,0.097,1.027
255.63,117.74,0.097,1.028
255.66,117.93,0.097,1.028
255.70,118.11,0.097,1.028
255.74,118.29,0.097,1.028
255.77,118.48,0.097,1.028
255.81,118.66,0.097,1.028
255.85,118.84,0.097,1.028
255.88,119.03,0.097,1.029
255.92,119.21,0.097,1.030
255.96,119.39,0.097,1.031
255.99,119.58,0.097,1.032
256.03,119.76,0.097,1.032
256.07,119.94,0.097,1.032
256.10,120.13,0.097,1.031
256.14,120.31,0.097,1.031
256.18,120.49,0.097,1.030
256.21,120.68,0.097,1.031
256.25,120.86,0.097,1.032
256.29,121.05,0.097,1.033
256.32,121.23,0.097,1.035
256.36,121.41,0.097,1.035
256.40,121.60,0.097,1.035
256.43,121.78,0.097,1.035
256.47,121.96,0.098,1.036
256.51,122.15,0.097,1.036
256.54,122.33,0.098,1.036
256.58,122.51,0.098,1.036
256.62,122.69,0.098,1.036
256.65,122.88,0.098,1.036
256.69,123.06,0.098,1.036
256.73,123.25,0.098,1.036
256.76,123.43,0.098,1.036
256.80,123.61,0.098,1.037
256.84,123.80,0.098,1.039
256.87,123.98,0.098,1.038
256.91,124.16,0.098,1.039
256.95,124.35,0.098,1.040
256.98,124.53,0.098,1.040
257.02,124.71,0.098,1.041
257.06,124.90,0.098,1.041
257.09,125.08,0.098,1.042
257.13,125.26,0.098,1.042
257.17,125.45,0.098,1.042
257.20,125.63,0.098,1.043
257.24,125.82,0.098,1.044
257.28,126.00,0.098,1.044
257.31,126.18,0.098,1.045
257.35,126.36,0.098,1.044
257.39,126.55,0.098,1.044
257.42,126.73,0.098,1.043
257.46,126.91,0.098,1.042
257.50,127.10,0.098,1.043
257.53,127.28,0.098,1.043
257.57,127.47,0.099,1.044
257.61,127.65,0.099,1.045
257.64,127.83,0.099,1.046
257.68,128.02,0.099,1.047
257.72,128.20,0.099,1.048
257.75,128.38,0.099,1.049
257.79,128.57,0.099,1.050
257.83,128.75,0.099,1.049
257.86,128.93,0.099,1.048
257.90,129.12,0.099,1.048
257.94,129.30,0.099,1.047
257.97,129.48,0.099,1.048
258.01,129.67,0.099,1.049
258.05,129.85,0.099,1.049
258.08,130.03,0.099,1.050
258.12,130.22,0.099,1.049
258.16,130.40,0.099,1.049
258.19,130.58,0.099,1.050
258.23,130.77,0.099,1.050
258.27,130.95,0.099,1.050
258.30,131.13,0.099,1.051
258.34,131.32,0.099,1.051
258.38,131.50,0.099,1.053
258.41,131.68,0.099,1.053
258.45,131.87,0.099,1.055
258.49,132.05,0.100,1.055
258.52,132.23,0.100,1.055
258.56,132.42,0.100,1.056
258.60,132.60,0.100,1.056
258.63,132.78,0.100,1.057
258.67,132.97,0.100,1.057
258.71,133.15,0.100,1.058
258.74,133.33,0.100,1.057
258.78,133.52,0.100,1.058
258.82,133.70,0.100,1.059
258.85,133.89,0.100,1.060
258.89,134.07,0.100,1.061
258.93,134.25,0.100,1.059
258.96,134.44,0.100,1.059
259.00,134.62,0.100,1.060
259.04,134.80,0.100,1.061
259.07,134.99,0.100,1.062
259.11,135.17,0.100,1.063
259.15,135.35,0.100,1.064
259.18,135.54,0.100,1.063
259.22,135.72,0.100,1.064
259.26,135.90,0.100,1.064
259.29,136.09,0.101,1.065
259.33,136.27,0.101,1.067
259.37,136.45,0.101,1.067
259.40,136.64,0.101,1.067
259.44,136.82,0.101,1.067
259.48,137.00,0.101,1.068
259.51,137.19,0.101,1.067
259.55,137.37,0.101,1.067
259.59,137.55,0.101,1.068
259.62,137.74,0.101,1.068
259.66,137.92,0.101,1.069
259.70,138.10,0.101,1.070
259.73,138.29,0.101,1.070
259.77,138.47,0.101,1.070
259.81,138.65,0.101,1.071
259.84,138.84,0.101,1.071
259.88,139.02,0.101,1.073
259.92,139.20,0.101,1.073
259.95,139.39,0.101,1.073
259.99,139.57,0.101,1.072
260.03,139.75,0.101,1.072
260.06,139.94,0.101,1.073
260.10,140.12,0.101,1.073
260.14,140.31,0.101,1.073
260.17,140.49,0.102,1.075
260.21,140.67,0.102,1.075
260.25,140.86,0.102,1.075
260.28,141.04,0.102,1.076
260.32,141.22,0.102,1.076
260.36,141.41,0.102,1.079
260.39,141.59,0.102,1.079
260.43,141.77,0.102,1.080
260.47,141.96,0.102,1.079
260.50,142.14,0.102,1.080
260.54,142.33,0.102,1.081
260.58,142.51,0.102,1.083
260.61,142.69,0.102,1.084
260.65,142.87,0.102,1.085
260.69,143.05,0.102,1.085
260.72,143.24,0.102,1.083
260.76,143.42,0.102,1.083
260.80,143.60,0.102,1.081
260.83,143.79,0.102,1.081
260.87,143.97,0.102,1.082
260.91,144.16,0.103,1.083
260.94,144.34,0.103,1.084
260.98,144.52,0.103,1.086
261.02,144.71,0.103,1.087
261.05,144.89,0.103,1.089
261.09,145.07,0.103,1.090
261.13,145.26,0.103,1.091
261.16,145.44,0.103,1.092
261.20,145.62,0.103,1.092
261.24,145.81,0.103,1.092
261.27,145.99,0.103,1.091
261.31,146.17,0.103,1.092
261.35,146.36,0.103,1.092
261.38,146.54,0.103,1.093
261.42,146.72,0.103,1.093
261.46,146.91,0.104,1.094
261.49,147.09,0.104,1.095
261.53,147.27,0.104,1.096
261.57,147.46,0.104,1.096
261.60,147.64,0.104,1.096
261.64,147.82,0.104,1.097
261.68,148.01,0.104,1.097
261.71,148.19,0.104,1.096
261.75,148.37,0.104,1.097
261.79,148.56,0.104,1.098
261.82,148.74,0.104,1.098
261.86,148.93,0.104,1.099
261.90,149.11,0.104,1.099
261.93,149.29,0.104,1.101
261.97,149.48,0.104,1.103
262.01,149.66,0.105,1.106
262.04,149.84,0.105,1.107
262.08,150.03,0.105,1.109
262.12,150.21,0.105,1.109
262.15,150.39,0.105,1.108
262.19,150.58,0.105,1.107
262.23,150.76,0.105,1.106
262.26,150.94,0.105,1.106
262.30,151.13,0.105,1.106
262.34,151.31,0.105,1.107
262.37,151.49,0.105,1.109
262.41,151.68,0.105,1.111
262.45,151.86,0.105,1.113
262.48,152.04,0.105,1.115
262.52,152.23,0.105,1.115
262.56,152.41,0.106,1.116
262.59,152.59,0.106,1.116
262.63,152.78,0.106,1.115
262.67,152.96,0.106,1.116
262.70,153.14,0.106,1.115
262.74,153.33,0.106,1.116
262.78,153.51,0.106,1.117
262.81,153.69,0.106,1.117
262.85,153.88,0.106,1.119
262.89,154.06,0.106,1.121
262.92,154.24,0.106,1.121
262.96,154.43,0.106,1.122
263.00,154.61,0.106,1.122
263.03,154.80,0.106,1.122
263.07,154.98,0.107,1.123
263.11,155.16,0.107,1.124
263.14,155.35,0.107,1.126
263.18,155.53,0.107,1.128
263.22,155.71,0.107,1.129
263.25,155.90,0.107,1.130
263.29,156.08,0.107,1.132
263.33,156.26,0.107,1.133
263.36,156.44,0.107,1.134
263.40,156.63,0.107,1.135
263.44,156.81,0.107,1.134
263.47,156.99,0.107,1.134
263.51,157.18,0.108,1.136
263.55,157.36,0.108,1.136
263.58,157.54,0.108,1.138
263.62,157.73,0.108,1.138
263.66,157.91,0.108,1.140
263.69,158.09,0.108,1.141
263.73,158.28,0.108,1.143
263.77,158.46,0.109,1.143
263.80,158.65,0.109,1.146
263.84,158.83,0.109,1.147
263.88,159.01,0.109,1.149
263.91,159.19,0.109,1.151
263.95,159.38,0.109,1.152
263.99,159.56,0.109,1.153
264.02,159.75,0.110,1.154
264.06,159.93,0.110,1.155
264.10,160.11,0.110,1.157
264.13,160.30,0.110,1.159
264.17,160.48,0.110,1.162
264.21,160.66,0.110,1.163
264.24,160.85,0.110,1.164
264.28,161.03,0.111,1.165
264.32,161.21,0.111,1.167
264.35,161.40,0.111,1.168
264.39,161.58,0.111,1.171
264.43,161.76,0.111,1.174
264.46,161.95,0.112,1.176
264.50,162.13,0.112,1.178
264.54,162.31,0.112,1.181
264.57,162.50,0.112,1.183
264.61,162.68,0.112,1.185
264.65,162.86,0.113,1.187
264.68,163.04,0.113,1.188
264.72,163.23,0.113,1.190
264.76,163.41,0.113,1.192
264.79,163.60,0.114,1.196
264.83,163.78,0.114,1.200
264.87,163.96,0.114,1.204
264.90,164.15,0.115,1.208
264.94,164.33,0.115,1.211
264.98,164.51,0.115,1.214
265.01,164.69,0.115,1.216
265.05,164.88,0.116,1.219
265.09,165.06,0.116,1.222
265.12,165.24,0.116,1.223
265.16,165.43,0.117,1.226
265.20,165.61,0.117,1.228
265.23,165.80,0.117,1.232
265.27,165.98,0.118,1.235
265.31,166.16,0.118,1.240
265.34,166.35,0.118,1.245
265.38,166.53,0.119,1.250
265.42,166.71,0.119,1.256
265.45,166.90,0.120,1.262
265.49,167.08,0.120,1.266
265.53,167.26,0.121,1.271
265.56,167.45,0.121,1.274
265.60,167.63,0.121,1.278
265.64,167.81,0.122,1.280
265.67,168.00,0.122,1.283
265.71,168.18,0.122,1.287
265.75,168.36,0.123,1.293
265.78,168.55,0.123,1.298
265.82,168.73,0.124,1.304
265.86,168.91,0.124,1.311
265.89,169.10,0.125,1.316
265.93,169.28,0.125,1.321
265.97,169.46,0.126,1.326
266.00,169.64,0.126,1.330
266.04,169.83,0.127,1.334
266.08,170.01,0.127,1.338
266.11,170.19,0.128,1.341
266.15,170.38,0.128,1.347
266.19,170.56,0.128,1.350
266.22,170.74,0.129,1.353
266.26,170.93,0.129,1.357
266.30,171.11,0.130,1.362
266.33,171.29,0.130,1.367
266.37,171.48,0.131,1.371
266.41,171.66,0.131,1.376
266.44,171.84,0.131,1.382
266.48,172.03,0.132,1.385
266.52,172.21,0.132,1.390
266.55,172.39,0.133,1.393
266.59,172.58,0.133,1.396
266.63,172.76,0.133,1.398
266.66,172.94,0.133,1.399
266.70,173.13,0.133,1.400
266.74,173.31,0.134,1.403
266.77,173.49,0.134,1.404
266.81,173.68,0.134,1.408
266.85,173.86,0.134,1.410
266.88,174.04,0.134,1.411
266.92,174.23,0.134,1.411
266.96,174.41,0.134,1.410
266.99,174.59,0.134,1.410
267.03,174.78,0.134,1.408
267.07,174.96,0.134,1.408
267.10,175.15,0.134,1.408
267.14,175.33,0.134,1.407
267.18,175.51,0.134,1.407
267.21,175.70,0.134,1.409
267.25,175.88,0.134,1.410
267.29,176.06,0.134,1.409
267.32,176.25,0.134,1.408
267.36,176.43,0.134,1.406
267.40,176.61,0.134,1.403
267.43,176.80,0.134,1.401
267.47,176.98,0.134,1.400
267.51,177.16,0.134,1.399
267.54,177.35,0.133,1.400
267.58,177.53,0.133,1.399
267.62,177.71,0.133,1.399
267.65,177.90,0.133,1.396
267.69,178.08,0.133,1.394
267.73,178.26,0.133,1.391
267.76,178.45,0.133,1.388
267.80,178.63,0.133,1.387
267.84,178.81,0.133,1.385
267.87,179.00,0.133,1.386
267.91,179.18,0.133,1.386
267.95,179.37,0.133,1.388
267.98,179.55,0.132,1.390
268.02,179.73,0.132,1.391
268.06,179.92,0.132,1.390
268.09,180.10,0.132,1.390
268.13,180.28,0.132,1.386
268.17,180.47,0.132,1.384
268.20,180.65,0.132,1.382
268.24,180.83,0.132,1.380
268.28,181.02,0.132,1.382
268.31,181.20,0.132,1.382
268.35,181.38,0.132,1.383
268.39,181.57,0.132,1.384
268.42,181.75,0.132,1.386
268.46,181.93,0.132,1.385
268.50,182.11,0.132,1.384
268.53,182.30,0.132,1.383
268.57,182.48,0.132,1.380
268.61,182.67,0.132,1.379
268.64,182.85,0.132,1.380
268.68,183.03,0.132,1.381
268.72,183.22,0.132,1.381
268.75,183.40,0.132,1.382
268.79,183.58,0.132,1.383
268.83,183.77,0.132,1.383
268.86,183.95,0.132,1.383
268.90,184.13,0.132,1.384
268.94,184.32,0.132,1.385
268.97,184.50,0.132,1.386
269.01,184.68,0.132,1.386
269.05,184.87,0.132,1.385
269.08,185.05,0.132,1.385
269.12,185.23,0.132,1.384
269.16,185.42,0.132,1.382
269.19,185.60,0.132,1.381
269.23,185.78,0.132,1.382
269.27,185.97,0.132,1.383
269.30,186.15,0.132,1.384
269.34,186.33,0.133,1.385
269.38,186.52,0.133,1.388
269.41,186.70,0.133,1.389
269.45,186.88,0.133,1.390
269.49,187.07,0.133,1.390
269.52,187.25,0.133,1.387
269.56,187.43,0.133,1.386
269.60,187.62,0.133,1.386
269.63,187.80,0.133,1.386
269.67,187.98,0.133,1.387
269.71,188.17,0.133,1.388
269.74,188.35,0.133,1.388
269.78,188.53,0.133,1.389
269.82,188.72,0.133,1.389
269.85,188.90,0.133,1.389
269.89,189.08,0.133,1.386
269.93,189.27,0.133,1.389
269.96,189.45,0.133,1.390
270.00,189.64,0.133,1.388
270.04,189.82,0.133,1.389
270.07,190.00,0.133,1.391
270.11,190.19,0.133,1.391
270.15,190.37,0.133,1.391
270.18,190.55,0.133,1.391
270.22,190.74,0.133,1.393
270.26,190.92,0.133,1.393
270.29,191.10,0.133,1.393
270.33,191.29,0.133,1.395
270.37,191.47,0.134,1.396
270.40,191.65,0.134,1.398
270.44,191.84,0.134,1.399
270.48,192.02,0.134,1.397
270.51,192.20,0.133,1.395
270.55,192.38,0.133,1.393
270.59,192.57,0.133,1.392
270.62,192.75,0.134,1.391
270.66,192.94,0.134,1.391
270.70,193.12,0.134,1.393
270.73,193.30,0.134,1.396
270.77,193.49,0.134,1.397
270.81,193.67,0.134,1.398
270.84,193.85,0.134,1.399
270.88,194.04,0.134,1.399
270.92,194.22,0.134,1.398
270.95,194.40,0.134,1.396
270.99,194.59,0.134,1.395
271.03,194.77,0.134,1.396
271.06,194.96,0.134,1.395
271.10,195.14,0.134,1.396
271.14,195.32,0.134,1.397
271.17,195.50,0.134,1.401
271.21,195.69,0.134,1.402
271.25,195.87,0.134,1.405
271.28,196.06,0.134,1.405
271.32,196.24,0.134,1.404
271.36,196.42,0.134,1.404
271.39,196.61,0.134,1.401
271.43,196.79,0.135,1.401
271.47,196.97,0.135,1.403
271.50,197.16,0.135,1.403
271.54,197.34,0.135,1.405
271.58,197.52,0.135,1.406
271.61,197.71,0.135,1.407
271.65,197.89,0.135,1.406
271.69,198.07,0.135,1.406
271.72,198.25,0.135,1.405
271.76,198.44,0.135,1.403
271.80,198.62,0.135,1.403
271.83,198.81,0.135,1.403
271.87,198.99,0.135,1.404
271.91,199.17,0.135,1.405
271.94,199.36,0.135,1.406
271.98,199.54,0.135,1.408
272.02,199.72,0.135,1.410
272.05,199.91,0.135,1.409
272.09,200.09,0.135,1.409
272.13,200.27,0.135,1.407
272.16,200.45,0.135,1.407
272.20,200.64,0.135,1.406
272.24,200.82,0.135,1.407
272.27,201.01,0.135,1.409
272.31,201.19,0.136,1.412
272.35,201.37,0.136,1.412
272.38,201.56,0.136,1.412
272.42,201.74,0.136,1.413
272.46,201.92,0.136,1.413
272.49,202.11,0.136,1.413
272.53,202.29,0.136,1.414
272.57,202.47,0.136,1.415
272.60,202.66,0.136,1.415
272.64,202.84,0.136,1.413
272.68,203.02,0.136,1.413
272.71,203.20,0.136,1.411
272.75,203.39,0.136,1.410
272.79,203.57,0.136,1.409
272.82,203.76,0.136,1.410
272.86,203.94,0.136,1.412
272.90,204.13,0.136,1.415
272.93,204.31,0.136,1.418
272.97,204.49,0.137,1.422
273.01,204.68,0.137,1.425
273.04,204.86,0.137,1.427
273.08,205.04,0.137,1.426
273.12,205.22,0.136,1.422
273.15,205.40,0.136,1.419
273.19,205.59,0.136,1.416
273.23,205.77,0.136,1.414
273.26,205.96,0.136,1.413
273.30,206.14,0.137,1.414
273.34,206.33,0.137,1.415
273.37,206.51,0.137,1.419
273.41,206.69,0.137,1.421
273.45,206.88,0.137,1.425
273.48,207.06,0.137,1.425
273.52,207.24,0.137,1.425
273.56,207.43,0.137,1.423
273.59,207.61,0.137,1.423
273.63,207.79,0.137,1.421
273.67,207.98,0.137,1.422
273.70,208.16,0.137,1.423
273.74,208.34,0.137,1.426
273.78,208.53,0.137,1.427
273.81,208.71,0.137,1.428
273.85,208.89,0.137,1.429
273.89,209.08,0.137,
273.92,209.26,0.137,
273.96,209.44,,
273.98,,,