File: DSC/Earl/2025_10_06_Aspirin_5Cmin_n60C_150C.csv
Filename,2025_10_06_Aspirin_5Cmin_n60C_150C
Instrument name,DSC2A-00468 (192.168.1.100)
Operator,JLY
rundate,10/6/2025
Sample name,2025_10_06_Aspirin_5Cmin_n60C_150C
proceduresegments,Data Off ; Equilibrate -60.00 °C; Data On ; Ramp 5.00 °C/min to 150.00 °C; Data Off ; Isothermal 0.1 min; Data On ; Ramp 50.00 °C/min to -60.00 °C; Data Off ; Isothermal 1.0 min; Data On ; Ramp 5.00 °C/min to 100.00 °C; Data Off ; Isothermal 1.0 min; Data On ; Ramp 5.00 °C/min to -60.00 °C; Data Off ; Isothermal 1.0 min; Data On ; Ramp 5.00 °C/min to 100.00 °C
[File Parameters]
Run date,10/6/2025 11:13:11 PM
Trios version,5.1.1.46572
Original File Name,
Current File Name,D:\DSC2500\JYarger\2025_10_06_Aspirin_5Cmin_n60C_150C.tri
[Procedure]
Procedure Name,Aspirin_n60C_150C_5Cmin_3
Sample Name,2025_10_06_Aspirin_5Cmin_n60C_150C
Sample Mass,0.77 mg
Reference Sample Mass,0 mg
Pan Mass,32.55 mg
Pan Number,47
Reference Pan Mass,32.55 mg
Reference Pan Number,1
Pan Type,Aluminum
Comments,DSC_Samples_Y2_Tray_ASDs_Pharma_Oct2025 Google Sheet.
Project Name,Amorphous Pharma
Operator,JLY
Test,Custom
Unload Max Temperature,30
Unload Min Temperature,30
Load Max Temperature,30
Load Min Temperature,30
Stop on Gas Flow Error,Yes
[Signal List]
Signal #1,Time (min)
Signal #2,Temperature (°C)
Signal #3,Heat Flow (mW)
Signal #4,Delta T (µV)
Signal #5,Delta Tzero (µV)
Signal #6,Tzero Temperature (°C)
Signal #7,Cell Purge (mL/min)
Signal #8,Heater Temp (°C)
Signal #9,Power Delivered (W)
Signal #10,Reference Junction Temperature (°C)
Signal #11,Flange Temperature (°C)
Signal #12,Heat Flow Phase (rad)
Signal #13,Total Heat Capacity (J/°C)
Signal #14,Heat Capacity (J/°C)
[Configuration]
Company Name,ASU
Instrument Name,DSC2A-00468
Instrument Type,DSC2500
Serial Number,DSC2A-00468
IP,192.168.1.100
Location of Instrument,MRRC
DisplayType,Unknown
Sample Interval ,0.1 s/pt
Selected Heat Flow,T4P
Exotherm Direction,Down
Cell Serial,DRC2-00792
Lid Type,Standard
Cooler,RCS 90
Leave Cooler on at End of Sequence,On
Gas 2,Nitrogen
Gas Selected,Channel 1
Flow Rate,50 mL/min
Secondary Purge,On
Licensed Heat Flow,Heat Flow T4P
Modulation Licensed,Yes
[Versions]
Common IDD Version,1
Cortex Version,VER 2.10.2.31
Driver,5.0.0.6
GDM Version,1.0.3.3
TouchscreenVersion,1.0.0.16145
FEP Version,1.2.1.21
FEP Bootloader,2.0.0.5
AutoSampler Version,2.1.1.26
Auto Sampler Bootloader,2.0.0.5
FCM Version,1.1.0.3
FCM Bootloader,2.0.0.5
[Experiment Logs]
Experiment Log Entry # 1,Air Cool is off.
Experiment Log Entry # 3,Data On set to 0
Experiment Log Entry # 5,Equilibrate Segment -60 (C) Started
Experiment Log Entry # 7,Data On set to 1
Experiment Log Entry # 9,Ramp Segment 5 C/min to 150 Started
Experiment Log Entry # 11,Data On set to 0
Experiment Log Entry # 13,Isothermal Segment 0.1 min started
Experiment Log Entry # 15,Data On set to 1
Experiment Log Entry # 17,Ramp Segment 50 C/min to -60 Started
Experiment Log Entry # 19,Data On set to 0
Experiment Log Entry # 21,Isothermal Segment 1 min started
Experiment Log Entry # 23,Data On set to 1
Experiment Log Entry # 25,Ramp Segment 5 C/min to 100 Started
Experiment Log Entry # 27,Data On set to 0
Experiment Log Entry # 29,Isothermal Segment 1 min started
Experiment Log Entry # 31,Data On set to 1
Experiment Log Entry # 33,Ramp Segment 5 C/min to -60 Started
Experiment Log Entry # 35,Data On set to 0
Experiment Log Entry # 37,Isothermal Segment 1 min started
Experiment Log Entry # 39,Data On set to 1
Experiment Log Entry # 41,Ramp Segment 5 C/min to 100 Started
[Method Log]
Method Log Entry # 1,Data Off
Method Log Entry # 2,Equilibrate -60 °C
Method Log Entry # 3,Data On
Method Log Entry # 4,(Ramp 683541) Ramp 5 °C/minute to 150 °C
Method Log Entry # 5,Data Off
Method Log Entry # 6,Isothermal 0.1 minutes
Method Log Entry # 7,Data On
Method Log Entry # 8,(Ramp 683545) Ramp 50 °C/minute to -60 °C
Method Log Entry # 9,Data Off
Method Log Entry # 10,Isothermal 1 minutes
Method Log Entry # 11,Data On
Method Log Entry # 12,(Ramp 683549) Ramp 5 °C/minute to 100 °C
Method Log Entry # 13,Data Off
Method Log Entry # 14,Isothermal 1 minutes
Method Log Entry # 15,Data On
Method Log Entry # 16,(Ramp 683553) Ramp 5 °C/minute to -60 °C
Method Log Entry # 17,Data Off
Method Log Entry # 18,Isothermal 1 minutes
Method Log Entry # 19,Data On
Method Log Entry # 20,(Ramp 683557) Ramp 5 °C/minute to 100 °C
Cell Serial,DRC2-00792
[T1 Calibration]
Slope,-0.008529666
Offset,9.636258
Initial Temperature,98.23
GUID,f8bfdadc-4977-4fdf-ba6d-0ba9134940c3
[TZero Calibration]
Date Applied,11/29/2022 4:06:13 PM
Description,From -89.059 °C to 396.009 °C at 20.000°C/min
Gas Type,Nitrogen
Pan Type,None
Source Files 1,C:\Users\yargerlab\Desktop\DSC Data\General\TZero_calibration_11_29_22_2nd(2).tri
Source Files 2,C:\Users\yargerlab\Desktop\DSC Data\General\TZero_calibration_11_29_22_2nd(3).tri
Delta T Offset,13.05235
Delta T Slope,-0.007271007
Delta T0 Offset,-13.69128
Delta T0 Slope,0.06063341
[Temperature Calibration]
Date Applied,11/29/2022 7:12:28 PM
Description,From 106.590 °C to 186.590 °C at 10.000°C/min
Gas Type,Nitrogen
Pan Type,Tzero Aluminum Hermetic
Source Files 1,C:\Users\yargerlab\Desktop\DSC Data\General\Indium(6).tri
Measured 1,157.391
Known 1,156.598
[Cell Constant Calibration]
Date Applied,11/29/2022 7:12:29 PM
Description,From 106.590 °C to 186.590 °C at 10.000°C/min
Gas Type,Nitrogen
Pan Type,Tzero Aluminum Hermetic
Source Files 1,C:\Users\yargerlab\Desktop\DSC Data\General\Indium(6).tri
T4P KCell,1.006051
Onset Slope,63.26126 mW/°C
[Direct Cp Calibration]
Date Applied,11/30/2022 11:04:51 AM
Description,From -79.983 °C to 298.409 °C at 10.000°C/min
Gas Type,Nitrogen
Pan Type,Tzero Aluminum Hermetic
Source Files 1,C:\Users\yargerlab\Desktop\DSC Data\General\Sapphire_Heat_Capacity_11_30_22.tri
[Rev Cp Calibration]
Date Applied,11/30/2022 1:58:51 PM
Description,From -79.996 °C to 292.812 °C at 3.000°C/min
Gas Type,Nitrogen
Pan Type,Tzero Aluminum Hermetic
Source Files 1,C:\Users\yargerlab\Desktop\DSC Data\General\Sapphire_MDSC_Calibration_11_30_22.tri
[step]
Ramp 5.00 °C/min to 150.00 °C
Time,Temperature,Heat Flow (Normalized)
min,°C,W/g
0.00,-59.81,-0.177
0.03,-59.82,-0.168
0.06,-59.81,-0.152
0.08,-59.77,-0.148
0.11,-59.69,-0.147
0.14,-59.58,-0.144
0.17,-59.46,-0.103
0.20,-59.34,-0.028
0.23,-59.21,0.010
0.26,-59.08,0.034
0.28,-58.94,0.049
0.31,-58.81,0.059
0.34,-58.67,0.068
0.37,-58.53,0.072
0.40,-58.40,0.075
0.43,-58.26,0.079
0.45,-58.12,0.081
0.48,-57.98,0.084
0.51,-57.84,0.087
0.54,-57.70,0.089
0.57,-57.56,0.092
0.60,-57.42,0.094
0.62,-57.28,0.096
0.65,-57.14,0.097
0.68,-57.00,0.099
0.71,-56.86,0.100
0.74,-56.72,0.101
0.77,-56.58,0.102
0.79,-56.44,0.102
0.82,-56.30,0.103
0.85,-56.16,0.104
0.88,-56.02,0.104
0.91,-55.88,0.105
0.93,-55.74,0.105
0.96,-55.60,0.105
0.99,-55.46,0.105
1.02,-55.31,0.105
1.05,-55.17,0.105
1.08,-55.03,0.104
1.11,-54.89,0.104
1.13,-54.75,0.104
1.16,-54.61,0.104
1.19,-54.47,0.103
1.22,-54.33,0.103
1.25,-54.18,0.103
1.28,-54.04,0.102
1.30,-53.90,0.102
1.33,-53.76,0.101
1.36,-53.62,0.101
1.39,-53.48,0.101
1.42,-53.34,0.100
1.44,-53.20,0.100
1.47,-53.05,0.099
1.50,-52.91,0.099
1.53,-52.77,0.098
1.56,-52.63,0.098
1.59,-52.49,0.097
1.62,-52.35,0.097
1.64,-52.20,0.096
1.67,-52.06,0.096
1.70,-51.92,0.095
1.73,-51.78,0.095
1.76,-51.64,0.094
1.78,-51.50,0.094
1.81,-51.36,0.093
1.84,-51.21,0.093
1.87,-51.07,0.092
1.90,-50.93,0.091
1.93,-50.79,0.091
1.96,-50.65,0.091
1.98,-50.51,0.090
2.01,-50.36,0.089
2.04,-50.22,0.089
2.07,-50.08,0.089
2.10,-49.94,0.089
2.13,-49.80,0.088
2.15,-49.66,0.088
2.18,-49.52,0.087
2.21,-49.37,0.087
2.24,-49.23,0.086
2.27,-49.09,0.086
2.29,-48.95,0.085
2.32,-48.81,0.085
2.35,-48.67,0.085
2.38,-48.52,0.084
2.41,-48.38,0.084
2.44,-48.24,0.083
2.46,-48.10,0.083
2.49,-47.96,0.082
2.52,-47.81,0.082
2.55,-47.67,0.082
2.58,-47.53,0.081
2.61,-47.39,0.081
2.64,-47.25,0.080
2.66,-47.11,0.080
2.69,-46.97,0.080
2.72,-46.82,0.079
2.75,-46.68,0.079
2.78,-46.54,0.078
2.81,-46.40,0.078
2.83,-46.26,0.078
2.86,-46.12,0.077
2.89,-45.98,0.077
2.92,-45.83,0.077
2.95,-45.69,0.077
2.98,-45.55,0.076
3.00,-45.41,0.076
3.03,-45.27,0.076
3.06,-45.13,0.075
3.09,-44.99,0.075
3.12,-44.84,0.074
3.14,-44.70,0.074
3.17,-44.56,0.074
3.20,-44.42,0.074
3.23,-44.28,0.073
3.26,-44.14,0.073
3.29,-43.99,0.073
3.31,-43.85,0.072
3.34,-43.71,0.072
3.37,-43.57,0.071
3.40,-43.43,0.071
3.43,-43.28,0.071
3.46,-43.14,0.071
3.49,-43.00,0.070
3.51,-42.86,0.070
3.54,-42.72,0.070
3.57,-42.58,0.070
3.60,-42.43,0.070
3.63,-42.29,0.069
3.66,-42.15,0.069
3.68,-42.01,0.069
3.71,-41.87,0.069
3.74,-41.73,0.068
3.77,-41.59,0.068
3.80,-41.44,0.068
3.83,-41.30,0.067
3.85,-41.16,0.067
3.88,-41.02,0.067
3.91,-40.88,0.066
3.94,-40.74,0.066
3.97,-40.59,0.066
3.99,-40.45,0.066
4.02,-40.31,0.066
4.05,-40.17,0.065
4.08,-40.03,0.065
4.11,-39.88,0.065
4.14,-39.74,0.065
4.16,-39.60,0.065
4.19,-39.46,0.064
4.22,-39.32,0.064
4.25,-39.18,0.063
4.28,-39.03,0.063
4.31,-38.89,0.063
4.34,-38.75,0.062
4.36,-38.61,0.062
4.39,-38.46,0.062
4.42,-38.32,0.062
4.45,-38.18,0.061
4.48,-38.04,0.061
4.50,-37.90,0.061
4.53,-37.76,0.061
4.56,-37.61,0.061
4.59,-37.47,0.061
4.62,-37.33,0.060
4.65,-37.19,0.060
4.68,-37.05,0.060
4.70,-36.91,0.060
4.73,-36.76,0.059
4.76,-36.62,0.059
4.79,-36.48,0.059
4.82,-36.34,0.059
4.85,-36.20,0.058
4.87,-36.05,0.058
4.90,-35.91,0.057
4.93,-35.77,0.057
4.96,-35.63,0.057
4.99,-35.49,0.057
5.01,-35.34,0.057
5.04,-35.20,0.056
5.07,-35.06,0.056
5.10,-34.92,0.056
5.13,-34.78,0.056
5.16,-34.64,0.056
5.19,-34.49,0.055
5.21,-34.35,0.055
5.24,-34.21,0.055
5.27,-34.07,0.055
5.30,-33.93,0.054
5.33,-33.78,0.054
5.35,-33.64,0.054
5.38,-33.50,0.053
5.41,-33.36,0.053
5.44,-33.22,0.053
5.47,-33.08,0.052
5.50,-32.93,0.052
5.53,-32.79,0.052
5.55,-32.65,0.052
5.58,-32.51,0.052
5.61,-32.37,0.052
5.64,-32.22,0.052
5.67,-32.08,0.051
5.70,-31.94,0.051
5.72,-31.80,0.051
5.75,-31.66,0.051
5.78,-31.51,0.050
5.81,-31.37,0.050
5.84,-31.23,0.050
5.86,-31.09,0.049
5.89,-30.95,0.049
5.92,-30.80,0.049
5.95,-30.66,0.049
5.98,-30.52,0.049
6.01,-30.38,0.048
6.04,-30.24,0.048
6.06,-30.10,0.048
6.09,-29.95,0.048
6.12,-29.81,0.048
6.15,-29.67,0.048
6.18,-29.53,0.047
6.20,-29.39,0.047
6.23,-29.24,0.047
6.26,-29.10,0.047
6.29,-28.96,0.047
6.32,-28.82,0.047
6.35,-28.68,0.047
6.38,-28.53,0.047
6.40,-28.39,0.046
6.43,-28.25,0.046
6.46,-28.11,0.046
6.49,-27.97,0.046
6.52,-27.82,0.046
6.55,-27.68,0.045
6.57,-27.54,0.045
6.60,-27.40,0.045
6.63,-27.26,0.045
6.66,-27.12,0.044
6.69,-26.98,0.044
6.71,-26.83,0.044
6.74,-26.69,0.044
6.77,-26.55,0.044
6.80,-26.41,0.043
6.83,-26.27,0.043
6.86,-26.12,0.043
6.89,-25.98,0.043
6.91,-25.84,0.042
6.94,-25.70,0.042
6.97,-25.56,0.042
7.00,-25.42,0.042
7.03,-25.27,0.042
7.05,-25.13,0.041
7.08,-24.99,0.041
7.11,-24.85,0.041
7.14,-24.71,0.041
7.17,-24.57,0.041
7.20,-24.42,0.041
7.23,-24.28,0.040
7.25,-24.14,0.040
7.28,-24.00,0.040
7.31,-23.86,0.040
7.34,-23.71,0.040
7.37,-23.57,0.039
7.40,-23.43,0.039
7.42,-23.29,0.039
7.45,-23.15,0.039
7.48,-23.00,0.039
7.51,-22.86,0.039
7.54,-22.72,0.038
7.56,-22.58,0.038
7.59,-22.44,0.038
7.62,-22.30,0.038
7.65,-22.15,0.038
7.68,-22.01,0.038
7.71,-21.87,0.038
7.74,-21.73,0.038
7.76,-21.59,0.038
7.79,-21.45,0.038
7.82,-21.30,0.037
7.85,-21.16,0.038
7.88,-21.02,0.037
7.90,-20.88,0.037
7.93,-20.73,0.037
7.96,-20.59,0.037
7.99,-20.45,0.037
8.02,-20.31,0.037
8.05,-20.17,0.037
8.08,-20.03,0.037
8.10,-19.89,0.037
8.13,-19.74,0.037
8.16,-19.60,0.037
8.19,-19.46,0.036
8.22,-19.32,0.036
8.25,-19.18,0.036
8.27,-19.03,0.036
8.30,-18.89,0.035
8.33,-18.75,0.036
8.36,-18.61,0.036
8.39,-18.47,0.035
8.41,-18.32,0.035
8.44,-18.18,0.035
8.47,-18.04,0.035
8.50,-17.90,0.035
8.53,-17.76,0.035
8.56,-17.62,0.035
8.58,-17.47,0.035
8.61,-17.33,0.035
8.64,-17.19,0.034
8.67,-17.05,0.034
8.70,-16.91,0.034
8.73,-16.76,0.034
8.75,-16.62,0.033
8.78,-16.48,0.033
8.81,-16.34,0.033
8.84,-16.20,0.033
8.87,-16.05,0.033
8.90,-15.91,0.032
8.93,-15.77,0.032
8.95,-15.63,0.032
8.98,-15.49,0.032
9.01,-15.35,0.032
9.04,-15.20,0.032
9.07,-15.06,0.032
9.10,-14.92,0.032
9.12,-14.78,0.031
9.15,-14.64,0.031
9.18,-14.50,0.031
9.21,-14.35,0.031
9.24,-14.21,0.031
9.27,-14.07,0.031
9.29,-13.93,0.030
9.32,-13.79,0.030
9.35,-13.65,0.030
9.38,-13.50,0.030
9.41,-13.36,0.030
9.43,-13.22,0.029
9.46,-13.08,0.029
9.49,-12.93,0.029
9.52,-12.79,0.029
9.55,-12.65,0.029
9.58,-12.51,0.029
9.60,-12.37,0.029
9.63,-12.23,0.029
9.66,-12.09,0.029
9.69,-11.94,0.029
9.72,-11.80,0.029
9.75,-11.66,0.029
9.78,-11.52,0.029
9.80,-11.38,0.029
9.83,-11.23,0.028
9.86,-11.09,0.028
9.89,-10.95,0.028
9.92,-10.81,0.028
9.95,-10.67,0.028
9.97,-10.53,0.028
10.00,-10.38,0.028
10.03,-10.24,0.028
10.06,-10.10,0.028
10.09,-9.96,0.027
10.12,-9.82,0.027
10.14,-9.67,0.027
10.17,-9.53,0.027
10.20,-9.39,0.027
10.23,-9.25,0.027
10.26,-9.11,0.027
10.28,-8.97,0.027
10.31,-8.82,0.027
10.34,-8.68,0.027
10.37,-8.54,0.026
10.40,-8.40,0.026
10.43,-8.26,0.026
10.45,-8.12,0.026
10.48,-7.97,0.026
10.51,-7.83,0.026
10.54,-7.69,0.026
10.57,-7.55,0.026
10.60,-7.41,0.026
10.63,-7.27,0.026
10.65,-7.13,0.026
10.68,-6.98,0.025
10.71,-6.84,0.025
10.74,-6.70,0.025
10.77,-6.56,0.025
10.80,-6.42,0.025
10.82,-6.27,0.025
10.85,-6.13,0.025
10.88,-5.99,0.025
10.91,-5.85,0.024
10.94,-5.70,0.025
10.97,-5.56,0.024
10.99,-5.42,0.024
11.02,-5.28,0.024
11.05,-5.14,0.024
11.08,-5.00,0.024
11.11,-4.85,0.024
11.13,-4.71,0.024
11.16,-4.57,0.024
11.19,-4.43,0.024
11.22,-4.29,0.024
11.25,-4.15,0.023
11.28,-4.00,0.023
11.30,-3.86,0.023
11.33,-3.72,0.023
11.36,-3.58,0.023
11.39,-3.44,0.023
11.42,-3.29,0.023
11.45,-3.15,0.023
11.48,-3.01,0.023
11.50,-2.87,0.023
11.53,-2.73,0.022
11.56,-2.59,0.022
11.59,-2.44,0.022
11.62,-2.30,0.022
11.65,-2.16,0.022
11.67,-2.02,0.022
11.70,-1.88,0.022
11.73,-1.73,0.021
11.76,-1.59,0.021
11.79,-1.45,0.021
11.82,-1.31,0.020
11.84,-1.17,0.021
11.87,-1.02,0.021
11.90,-0.88,0.021
11.93,-0.74,0.021
11.96,-0.60,0.020
11.98,-0.46,0.020
12.01,-0.32,0.020
12.04,-0.17,0.020
12.07,-0.03,0.020
12.10,0.11,0.020
12.13,0.25,0.020
12.15,0.39,0.020
12.18,0.54,0.019
12.21,0.68,0.019
12.24,0.82,0.019
12.27,0.96,0.019
12.30,1.10,0.019
12.33,1.24,0.019
12.35,1.39,0.019
12.38,1.53,0.018
12.41,1.67,0.018
12.44,1.81,0.018
12.47,1.95,0.018
12.50,2.09,0.018
12.52,2.24,0.018
12.55,2.38,0.018
12.58,2.52,0.018
12.61,2.66,0.018
12.64,2.80,0.017
12.67,2.95,0.017
12.69,3.09,0.017
12.72,3.23,0.017
12.75,3.37,0.016
12.78,3.51,0.016
12.81,3.65,0.016
12.83,3.80,0.016
12.86,3.94,0.016
12.89,4.08,0.016
12.92,4.22,0.016
12.95,4.36,0.016
12.98,4.51,0.016
13.00,4.65,0.015
13.03,4.79,0.015
13.06,4.93,0.015
13.09,5.07,0.015
13.12,5.21,0.015
13.15,5.36,0.015
13.18,5.50,0.015
13.20,5.64,0.014
13.23,5.78,0.014
13.26,5.92,0.014
13.29,6.07,0.014
13.32,6.21,0.014
13.35,6.35,0.014
13.37,6.49,0.014
13.40,6.63,0.014
13.43,6.77,0.014
13.46,6.91,0.014
13.49,7.06,0.014
13.52,7.20,0.014
13.54,7.34,0.014
13.57,7.48,0.014
13.60,7.63,0.013
13.63,7.77,0.013
13.66,7.91,0.013
13.68,8.05,0.013
13.71,8.19,0.013
13.74,8.34,0.013
13.77,8.48,0.013
13.80,8.62,0.013
13.83,8.76,0.012
13.85,8.90,0.012
13.88,9.05,0.012
13.91,9.19,0.012
13.94,9.33,0.012
13.97,9.47,0.012
14.00,9.61,0.012
14.03,9.75,0.012
14.05,9.90,0.012
14.08,10.04,0.012
14.11,10.18,0.011
14.14,10.32,0.011
14.17,10.46,0.011
14.20,10.60,0.011
14.22,10.75,0.011
14.25,10.89,0.011
14.28,11.03,0.011
14.31,11.17,0.011
14.34,11.31,0.010
14.37,11.45,0.010
14.39,11.59,0.010
14.42,11.74,0.010
14.45,11.88,0.010
14.48,12.02,0.010
14.51,12.16,0.010
14.53,12.31,0.010
14.56,12.45,0.010
14.59,12.59,0.010
14.62,12.73,0.010
14.65,12.87,0.009
14.68,13.01,0.009
14.70,13.15,0.009
14.73,13.30,0.009
14.76,13.44,0.009
14.79,13.58,0.009
14.82,13.72,0.008
14.85,13.87,0.008
14.88,14.01,0.008
14.90,14.15,0.008
14.93,14.29,0.008
14.96,14.43,0.008
14.99,14.57,0.008
15.02,14.72,0.008
15.05,14.86,0.008
15.07,15.00,0.008
15.10,15.14,0.008
15.13,15.28,0.008
15.16,15.42,0.008
15.19,15.57,0.008
15.22,15.71,0.008
15.24,15.85,0.008
15.27,15.99,0.008
15.30,16.13,0.008
15.33,16.28,0.008
15.36,16.42,0.008
15.38,16.56,0.007
15.41,16.70,0.007
15.44,16.85,0.007
15.47,16.99,0.007
15.50,17.13,0.007
15.53,17.27,0.007
15.55,17.41,0.007
15.58,17.55,0.007
15.61,17.69,0.007
15.64,17.84,0.006
15.67,17.98,0.006
15.70,18.12,0.006
15.73,18.26,0.007
15.75,18.40,0.006
15.78,18.54,0.006
15.81,18.69,0.006
15.84,18.83,0.006
15.87,18.97,0.006
15.90,19.11,0.006
15.92,19.25,0.006
15.95,19.40,0.006
15.98,19.54,0.006
16.01,19.68,0.005
16.04,19.82,0.005
16.07,19.96,0.005
16.09,20.10,0.005
16.12,20.25,0.005
16.15,20.39,0.005
16.18,20.53,0.005
16.21,20.67,0.005
16.23,20.81,0.005
16.26,20.95,0.005
16.29,21.10,0.005
16.32,21.24,0.004
16.35,21.38,0.004
16.38,21.52,0.004
16.40,21.67,0.004
16.43,21.81,0.004
16.46,21.95,0.004
16.49,22.09,0.004
16.52,22.23,0.004
16.55,22.37,0.004
16.58,22.51,0.003
16.60,22.65,0.003
16.63,22.80,0.003
16.66,22.94,0.003
16.69,23.08,0.003
16.72,23.22,0.003
16.75,23.37,0.003
16.77,23.51,0.003
16.80,23.65,0.003
16.83,23.79,0.003
16.86,23.93,0.003
16.89,24.07,0.003
16.92,24.22,0.003
16.94,24.36,0.003
16.97,24.50,0.003
17.00,24.64,0.003
17.03,24.78,0.002
17.06,24.92,0.002
17.08,25.07,0.002
17.11,25.21,0.002
17.14,25.35,0.002
17.17,25.49,0.002
17.20,25.63,0.002
17.23,25.77,0.002
17.26,25.92,0.002
17.28,26.06,0.002
17.31,26.20,0.002
17.34,26.34,0.002
17.37,26.48,0.002
17.40,26.63,0.002
17.43,26.77,0.002
17.45,26.91,0.001
17.48,27.05,0.001
17.51,27.19,0.001
17.54,27.33,0.001
17.57,27.48,0.001
17.59,27.62,0.001
17.62,27.76,0.001
17.65,27.90,0.001
17.68,28.04,0.001
17.71,28.18,0.001
17.74,28.33,0.001
17.77,28.47,0.001
17.79,28.61,0.001
17.82,28.75,0.001
17.85,28.89,0.001
17.88,29.04,0.001
17.91,29.18,0.001
17.93,29.32,0.001
17.96,29.46,0.001
17.99,29.60,0.001
18.02,29.75,0.001
18.05,29.89,0.001
18.08,30.03,0.001
18.11,30.17,0.001
18.13,30.31,0.001
18.16,30.45,0.001
18.19,30.59,0.001
18.22,30.74,0.001
18.25,30.88,0.001
18.28,31.02,0.001
18.30,31.16,0.001
18.33,31.31,0.001
18.36,31.45,0.001
18.39,31.59,0.001
18.42,31.73,0.001
18.44,31.87,0.001
18.47,32.01,0.001
18.50,32.16,0.001
18.53,32.30,0.001
18.56,32.44,0.001
18.59,32.58,0.001
18.62,32.72,0.000
18.64,32.86,0.001
18.67,33.01,0.001
18.70,33.15,0.001
18.73,33.29,0.001
18.76,33.43,0.001
18.78,33.57,0.000
18.81,33.71,0.001
18.84,33.86,0.000
18.87,34.00,0.000
18.90,34.14,0.000
18.93,34.28,0.000
18.96,34.42,0.000
18.98,34.57,0.000
19.01,34.71,0.000
19.04,34.85,0.000
19.07,34.99,0.000
19.10,35.13,0.000
19.13,35.27,0.000
19.15,35.42,-0.001
19.18,35.56,-0.001
19.21,35.70,-0.001
19.24,35.84,-0.001
19.27,35.98,-0.001
19.29,36.12,-0.001
19.32,36.27,-0.001
19.35,36.41,-0.001
19.38,36.55,-0.001
19.41,36.69,-0.001
19.44,36.83,-0.001
19.47,36.97,-0.001
19.49,37.12,-0.001
19.52,37.26,-0.001
19.55,37.40,-0.002
19.58,37.54,-0.002
19.61,37.68,-0.002
19.63,37.82,-0.002
19.66,37.97,-0.002
19.69,38.11,-0.002
19.72,38.25,-0.002
19.75,38.39,-0.002
19.78,38.53,-0.002
19.81,38.67,-0.002
19.83,38.82,-0.002
19.86,38.96,-0.002
19.89,39.10,-0.003
19.92,39.24,-0.002
19.95,39.39,-0.003
19.98,39.53,-0.003
20.00,39.67,-0.003
20.03,39.81,-0.003
20.06,39.95,-0.003
20.09,40.09,-0.003
20.12,40.24,-0.003
20.14,40.38,-0.003
20.17,40.52,-0.003
20.20,40.66,-0.003
20.23,40.80,-0.003
20.26,40.95,-0.003
20.29,41.09,-0.003
20.32,41.23,-0.003
20.34,41.37,-0.003
20.37,41.51,-0.003
20.40,41.65,-0.003
20.43,41.80,-0.003
20.46,41.94,-0.004
20.48,42.08,-0.004
20.51,42.22,-0.004
20.54,42.36,-0.004
20.57,42.51,-0.004
20.60,42.65,-0.004
20.63,42.79,-0.004
20.66,42.93,-0.004
20.68,43.07,-0.004
20.71,43.21,-0.004
20.74,43.36,-0.004
20.77,43.50,-0.004
20.80,43.64,-0.004
20.83,43.78,-0.004
20.85,43.92,-0.004
20.88,44.06,-0.004
20.91,44.21,-0.004
20.94,44.35,-0.005
20.97,44.49,-0.005
20.99,44.63,-0.005
21.02,44.77,-0.005
21.05,44.91,-0.005
21.08,45.06,-0.005
21.11,45.20,-0.005
21.14,45.34,-0.005
21.17,45.48,-0.005
21.19,45.62,-0.005
21.22,45.77,-0.005
21.25,45.91,-0.005
21.28,46.05,-0.005
21.31,46.19,-0.005
21.33,46.33,-0.005
21.36,46.47,-0.005
21.39,46.62,-0.005
21.42,46.76,-0.005
21.45,46.90,-0.005
21.48,47.04,-0.005
21.51,47.18,-0.005
21.53,47.33,-0.005
21.56,47.47,-0.005
21.59,47.61,-0.005
21.62,47.75,-0.005
21.65,47.89,-0.005
21.68,48.03,-0.005
21.70,48.18,-0.005
21.73,48.32,-0.005
21.76,48.46,-0.005
21.79,48.60,-0.005
21.82,48.74,-0.005
21.84,48.88,-0.005
21.87,49.02,-0.005
21.90,49.17,-0.005
21.93,49.31,-0.005
21.96,49.45,-0.005
21.99,49.59,-0.005
22.02,49.73,-0.005
22.04,49.88,-0.006
22.07,50.02,-0.006
22.10,50.16,-0.006
22.13,50.30,-0.006
22.16,50.44,-0.006
22.18,50.59,-0.006
22.21,50.73,-0.006
22.24,50.87,-0.005
22.27,51.01,-0.006
22.30,51.15,-0.005
22.33,51.29,-0.005
22.36,51.44,-0.005
22.38,51.58,-0.006
22.41,51.72,-0.006
22.44,51.86,-0.006
22.47,52.00,-0.006
22.50,52.14,-0.006
22.53,52.29,-0.006
22.55,52.43,-0.006
22.58,52.57,-0.006
22.61,52.71,-0.006
22.64,52.85,-0.006
22.67,53.00,-0.006
22.69,53.14,-0.006
22.72,53.28,-0.006
22.75,53.42,-0.006
22.78,53.56,-0.006
22.81,53.70,-0.006
22.84,53.84,-0.006
22.87,53.99,-0.006
22.89,54.13,-0.006
22.92,54.27,-0.007
22.95,54.41,-0.007
22.98,54.55,-0.007
23.01,54.70,-0.007
23.03,54.84,-0.007
23.06,54.98,-0.007
23.09,55.12,-0.007
23.12,55.26,-0.007
23.15,55.40,-0.007
23.18,55.55,-0.007
23.21,55.69,-0.007
23.23,55.83,-0.007
23.26,55.97,-0.007
23.29,56.11,-0.007
23.32,56.26,-0.007
23.35,56.40,-0.007
23.38,56.54,-0.007
23.40,56.68,-0.007
23.43,56.82,-0.007
23.46,56.97,-0.007
23.49,57.11,-0.007
23.52,57.25,-0.007
23.54,57.39,-0.007
23.57,57.53,-0.007
23.60,57.67,-0.007
23.63,57.82,-0.007
23.66,57.96,-0.007
23.69,58.10,-0.008
23.72,58.24,-0.008
23.74,58.38,-0.007
23.77,58.52,-0.008
23.80,58.67,-0.008
23.83,58.81,-0.008
23.86,58.95,-0.008
23.88,59.09,-0.008
23.91,59.23,-0.008
23.94,59.37,-0.008
23.97,59.52,-0.008
24.00,59.66,-0.008
24.03,59.80,-0.008
24.06,59.94,-0.008
24.08,60.08,-0.007
24.11,60.23,-0.007
24.14,60.37,-0.007
24.17,60.51,-0.007
24.20,60.65,-0.008
24.23,60.79,-0.008
24.25,60.94,-0.008
24.28,61.08,-0.008
24.31,61.22,-0.008
24.34,61.36,-0.007
24.37,61.50,-0.008
24.39,61.64,-0.008
24.42,61.78,-0.008
24.45,61.93,-0.008
24.48,62.07,-0.008
24.51,62.21,-0.008
24.54,62.35,-0.008
24.57,62.49,-0.007
24.59,62.64,-0.007
24.62,62.78,-0.007
24.65,62.92,-0.007
24.68,63.06,-0.007
24.71,63.20,-0.008
24.73,63.34,-0.008
24.76,63.49,-0.008
24.79,63.63,-0.008
24.82,63.77,-0.008
24.85,63.91,-0.008
24.88,64.05,-0.008
24.91,64.19,-0.008
24.93,64.34,-0.008
24.96,64.48,-0.008
24.99,64.62,-0.008
25.02,64.76,-0.008
25.05,64.90,-0.008
25.08,65.05,-0.009
25.10,65.19,-0.009
25.13,65.33,-0.009
25.16,65.47,-0.009
25.19,65.61,-0.009
25.22,65.76,-0.009
25.24,65.90,-0.009
25.27,66.04,-0.009
25.30,66.18,-0.009
25.33,66.32,-0.009
25.36,66.46,-0.010
25.39,66.61,-0.010
25.42,66.75,-0.010
25.44,66.89,-0.009
25.47,67.03,-0.010
25.50,67.17,-0.010
25.53,67.32,-0.010
25.56,67.46,-0.010
25.58,67.60,-0.010
25.61,67.74,-0.010
25.64,67.88,-0.010
25.67,68.02,-0.010
25.70,68.16,-0.010
25.73,68.31,-0.010
25.76,68.45,-0.010
25.78,68.59,-0.010
25.81,68.73,-0.010
25.84,68.87,-0.010
25.87,69.02,-0.010
25.90,69.16,-0.010
25.93,69.30,-0.010
25.95,69.44,-0.010
25.98,69.58,-0.010
26.01,69.72,-0.010
26.04,69.87,-0.010
26.07,70.01,-0.010
26.09,70.15,-0.010
26.12,70.29,-0.010
26.15,70.43,-0.010
26.18,70.58,-0.010
26.21,70.72,-0.009
26.24,70.86,-0.009
26.27,71.00,-0.009
26.29,71.14,-0.010
26.32,71.29,-0.010
26.35,71.43,-0.010
26.38,71.57,-0.010
26.41,71.71,-0.010
26.43,71.85,-0.010
26.46,71.99,-0.010
26.49,72.14,-0.010
26.52,72.28,-0.010
26.55,72.42,-0.010
26.58,72.56,-0.010
26.61,72.70,-0.010
26.63,72.85,-0.010
26.66,72.99,-0.011
26.69,73.13,-0.010
26.72,73.27,-0.010
26.75,73.41,-0.010
26.78,73.55,-0.011
26.80,73.70,-0.011
26.83,73.84,-0.011
26.86,73.98,-0.011
26.89,74.12,-0.011
26.92,74.26,-0.011
26.94,74.41,-0.011
26.97,74.55,-0.011
27.00,74.69,-0.011
27.03,74.83,-0.011
27.06,74.97,-0.011
27.09,75.11,-0.011
27.12,75.25,-0.011
27.14,75.40,-0.011
27.17,75.54,-0.011
27.20,75.68,-0.011
27.23,75.82,-0.011
27.26,75.97,-0.011
27.28,76.11,-0.011
27.31,76.25,-0.011
27.34,76.39,-0.011
27.37,76.53,-0.011
27.40,76.67,-0.011
27.43,76.81,-0.011
27.46,76.96,-0.011
27.48,77.10,-0.011
27.51,77.24,-0.011
27.54,77.38,-0.011
27.57,77.52,-0.012
27.60,77.66,-0.012
27.63,77.81,-0.012
27.65,77.95,-0.012
27.68,78.09,-0.012
27.71,78.23,-0.012
27.74,78.37,-0.012
27.77,78.51,-0.012
27.79,78.66,-0.012
27.82,78.80,-0.012
27.85,78.94,-0.012
27.88,79.08,-0.012
27.91,79.22,-0.012
27.94,79.37,-0.012
27.97,79.51,-0.012
27.99,79.65,-0.012
28.02,79.79,-0.012
28.05,79.93,-0.012
28.08,80.07,-0.012
28.11,80.21,-0.012
28.13,80.36,-0.012
28.16,80.50,-0.012
28.19,80.64,-0.012
28.22,80.78,-0.012
28.25,80.92,-0.012
28.28,81.07,-0.012
28.31,81.21,-0.012
28.33,81.35,-0.012
28.36,81.49,-0.012
28.39,81.63,-0.012
28.42,81.77,-0.012
28.45,81.92,-0.012
28.48,82.06,-0.012
28.50,82.20,-0.012
28.53,82.34,-0.012
28.56,82.48,-0.012
28.59,82.63,-0.012
28.62,82.77,-0.012
28.64,82.91,-0.012
28.67,83.05,-0.012
28.70,83.19,-0.013
28.73,83.33,-0.013
28.76,83.48,-0.013
28.79,83.62,-0.013
28.82,83.76,-0.013
28.84,83.90,-0.013
28.87,84.04,-0.012
28.90,84.19,-0.012
28.93,84.33,-0.012
28.96,84.47,-0.012
28.98,84.61,-0.012
29.01,84.75,-0.013
29.04,84.89,-0.013
29.07,85.03,-0.013
29.10,85.18,-0.013
29.13,85.32,-0.013
29.16,85.46,-0.013
29.18,85.60,-0.013
29.21,85.74,-0.013
29.24,85.89,-0.013
29.27,86.03,-0.013
29.30,86.17,-0.013
29.33,86.31,-0.013
29.35,86.45,-0.013
29.38,86.60,-0.013
29.41,86.74,-0.013
29.44,86.88,-0.013
29.47,87.02,-0.013
29.49,87.16,-0.013
29.52,87.30,-0.013
29.55,87.45,-0.013
29.58,87.59,-0.013
29.61,87.73,-0.013
29.64,87.87,-0.013
29.67,88.01,-0.013
29.69,88.15,-0.013
29.72,88.30,-0.013
29.75,88.44,-0.013
29.78,88.58,-0.013
29.81,88.72,-0.013
29.83,88.86,-0.013
29.86,89.00,-0.013
29.89,89.15,-0.013
29.92,89.29,-0.013
29.95,89.43,-0.013
29.98,89.57,-0.013
30.01,89.71,-0.013
30.03,89.85,-0.013
30.06,90.00,-0.013
30.09,90.14,-0.013
30.12,90.28,-0.013
30.15,90.42,-0.013
30.18,90.56,-0.013
30.20,90.71,-0.013
30.23,90.85,-0.013
30.26,90.99,-0.013
30.29,91.13,-0.014
30.32,91.27,-0.014
30.34,91.41,-0.014
30.37,91.56,-0.014
30.40,91.70,-0.014
30.43,91.84,-0.014
30.46,91.98,-0.014
30.49,92.12,-0.014
30.52,92.26,-0.014
30.54,92.41,-0.014
30.57,92.55,-0.014
30.60,92.69,-0.014
30.63,92.83,-0.014
30.66,92.97,-0.014
30.68,93.11,-0.014
30.71,93.26,-0.014
30.74,93.40,-0.014
30.77,93.54,-0.014
30.80,93.68,-0.014
30.83,93.82,-0.014
30.86,93.97,-0.014
30.88,94.11,-0.014
30.91,94.25,-0.014
30.94,94.39,-0.014
30.97,94.53,-0.014
31.00,94.67,-0.014
31.03,94.82,-0.014
31.05,94.96,-0.014
31.08,95.10,-0.015
31.11,95.24,-0.015
31.14,95.38,-0.015
31.17,95.53,-0.014
31.19,95.67,-0.015
31.22,95.81,-0.014
31.25,95.95,-0.015
31.28,96.09,-0.015
31.31,96.23,-0.015
31.34,96.38,-0.014
31.37,96.52,-0.014
31.39,96.66,-0.014
31.42,96.80,-0.014
31.45,96.94,-0.014
31.48,97.08,-0.014
31.51,97.23,-0.014
31.53,97.37,-0.014
31.56,97.51,-0.014
31.59,97.65,-0.014
31.62,97.79,-0.015
31.65,97.94,-0.015
31.68,98.08,-0.014
31.71,98.22,-0.014
31.73,98.36,-0.014
31.76,98.50,-0.014
31.79,98.64,-0.014
31.82,98.79,-0.014
31.85,98.93,-0.014
31.88,99.07,-0.014
31.90,99.21,-0.014
31.93,99.35,-0.014
31.96,99.50,-0.014
31.99,99.64,-0.014
32.02,99.78,-0.014
32.04,99.92,-0.014
32.07,100.06,-0.014
32.10,100.20,-0.014
32.13,100.34,-0.014
32.16,100.49,-0.014
32.19,100.63,-0.014
32.22,100.77,-0.014
32.24,100.91,-0.014
32.27,101.05,-0.014
32.30,101.20,-0.014
32.33,101.34,-0.014
32.36,101.48,-0.014
32.38,101.62,-0.014
32.41,101.76,-0.014
32.44,101.90,-0.014
32.47,102.05,-0.014
32.50,102.19,-0.014
32.53,102.33,-0.014
32.56,102.47,-0.014
32.58,102.61,-0.014
32.61,102.75,-0.014
32.64,102.90,-0.014
32.67,103.04,-0.014
32.70,103.18,-0.014
32.73,103.32,-0.014
32.75,103.46,-0.015
32.78,103.61,-0.015
32.81,103.75,-0.015
32.84,103.89,-0.014
32.87,104.03,-0.015
32.89,104.17,-0.014
32.92,104.31,-0.014
32.95,104.46,-0.014
32.98,104.60,-0.014
33.01,104.74,-0.014
33.04,104.88,-0.014
33.07,105.02,-0.014
33.09,105.16,-0.014
33.12,105.31,-0.014
33.15,105.45,-0.014
33.18,105.59,-0.014
33.21,105.73,-0.014
33.23,105.87,-0.014
33.26,106.01,-0.014
33.29,106.16,-0.014
33.32,106.30,-0.014
33.35,106.44,-0.015
33.38,106.58,-0.015
33.41,106.72,-0.015
33.43,106.86,-0.015
33.46,107.00,-0.015
33.49,107.15,-0.015
33.52,107.29,-0.015
33.55,107.43,-0.015
33.58,107.57,-0.015
33.60,107.72,-0.015
33.63,107.86,-0.015
33.66,108.00,-0.015
33.69,108.14,-0.015
33.72,108.28,-0.015
33.74,108.42,-0.015
33.77,108.57,-0.015
33.80,108.71,-0.015
33.83,108.85,-0.015
33.86,108.99,-0.015
33.89,109.13,-0.015
33.92,109.28,-0.015
33.94,109.42,-0.015
33.97,109.56,-0.015
34.00,109.70,-0.015
34.03,109.84,-0.015
34.06,109.98,-0.015
34.08,110.12,-0.015
34.11,110.27,-0.015
34.14,110.41,-0.015
34.17,110.55,-0.015
34.20,110.69,-0.015
34.23,110.83,-0.015
34.26,110.98,-0.015
34.28,111.12,-0.015
34.31,111.26,-0.014
34.34,111.40,-0.014
34.37,111.54,-0.014
34.40,111.69,-0.014
34.43,111.83,-0.015
34.45,111.97,-0.015
34.48,112.11,-0.015
34.51,112.25,-0.015
34.54,112.39,-0.015
34.57,112.54,-0.014
34.59,112.68,-0.015
34.62,112.82,-0.014
34.65,112.96,-0.014
34.68,113.10,-0.014
34.71,113.24,-0.014
34.74,113.39,-0.014
34.76,113.53,-0.014
34.79,113.67,-0.014
34.82,113.81,-0.014
34.85,113.95,-0.014
34.88,114.10,-0.013
34.91,114.24,-0.013
34.94,114.38,-0.012
34.96,114.52,-0.012
34.99,114.66,-0.011
35.02,114.81,-0.011
35.05,114.95,-0.010
35.08,115.09,-0.010
35.11,115.23,-0.009
35.13,115.37,-0.009
35.16,115.51,-0.009
35.19,115.65,-0.009
35.22,115.80,-0.010
35.25,115.94,-0.010
35.28,116.08,-0.011
35.30,116.22,-0.011
35.33,116.36,-0.012
35.36,116.50,-0.012
35.39,116.65,-0.012
35.42,116.79,-0.013
35.44,116.93,-0.013
35.47,117.07,-0.013
35.50,117.21,-0.013
35.53,117.35,-0.013
35.56,117.49,-0.013
35.59,117.64,-0.013
35.61,117.78,-0.013
35.64,117.92,-0.014
35.67,118.06,-0.014
35.70,118.20,-0.014
35.73,118.35,-0.014
35.76,118.49,-0.014
35.79,118.63,-0.014
35.81,118.77,-0.014
35.84,118.92,-0.013
35.87,119.06,-0.013
35.90,119.20,-0.013
35.93,119.34,-0.013
35.96,119.48,-0.013
35.98,119.62,-0.013
36.01,119.76,-0.013
36.04,119.91,-0.013
36.07,120.05,-0.013
36.10,120.19,-0.013
36.13,120.33,-0.013
36.15,120.47,-0.013
36.18,120.62,-0.013
36.21,120.76,-0.013
36.24,120.90,-0.013
36.27,121.04,-0.013
36.29,121.18,-0.013
36.32,121.32,-0.013
36.35,121.47,-0.013
36.38,121.61,-0.013
36.41,121.75,-0.013
36.44,121.89,-0.013
36.46,122.03,-0.012
36.49,122.17,-0.012
36.52,122.32,-0.012
36.55,122.46,-0.012
36.58,122.60,-0.011
36.61,122.74,-0.011
36.64,122.88,-0.011
36.66,123.02,-0.011
36.69,123.16,-0.011
36.72,123.31,-0.011
36.75,123.45,-0.011
36.78,123.59,-0.011
36.81,123.73,-0.011
36.83,123.87,-0.011
36.86,124.02,-0.011
36.89,124.16,-0.010
36.92,124.30,-0.010
36.95,124.44,-0.010
36.98,124.58,-0.010
37.00,124.73,-0.010
37.03,124.87,-0.010
37.06,125.01,-0.010
37.09,125.15,-0.010
37.12,125.29,-0.010
37.14,125.43,-0.009
37.17,125.58,-0.009
37.20,125.72,-0.009
37.23,125.86,-0.009
37.26,126.00,-0.009
37.29,126.14,-0.009
37.31,126.28,-0.009
37.34,126.43,-0.009
37.37,126.57,-0.008
37.40,126.71,-0.008
37.43,126.85,-0.007
37.46,126.99,-0.007
37.49,127.13,-0.007
37.51,127.28,-0.007
37.54,127.42,-0.007
37.57,127.56,-0.006
37.60,127.70,-0.006
37.63,127.84,-0.005
37.66,127.99,-0.005
37.68,128.13,-0.005
37.71,128.27,-0.005
37.74,128.41,-0.005
37.77,128.55,-0.004
37.80,128.69,-0.004
37.83,128.83,-0.004
37.85,128.98,-0.004
37.88,129.12,-0.003
37.91,129.26,-0.003
37.94,129.40,-0.003
37.97,129.55,-0.002
37.99,129.69,-0.002
38.02,129.83,-0.001
38.05,129.97,-0.001
38.08,130.11,0.000
38.11,130.25,0.000
38.14,130.39,0.001
38.16,130.54,0.002
38.19,130.68,0.002
38.22,130.82,0.003
38.25,130.96,0.004
38.28,131.10,0.005
38.31,131.25,0.006
38.34,131.39,0.006
38.36,131.53,0.007
38.39,131.67,0.009
38.42,131.81,0.010
38.45,131.95,0.011
38.48,132.09,0.012
38.51,132.24,0.013
38.53,132.38,0.015
38.56,132.52,0.016
38.59,132.66,0.017
38.62,132.80,0.019
38.65,132.94,0.021
38.68,133.09,0.022
38.70,133.23,0.024
38.73,133.37,0.027
38.76,133.51,0.029
38.79,133.65,0.031
38.82,133.79,0.034
38.84,133.94,0.037
38.87,134.08,0.041
38.90,134.22,0.044
38.93,134.36,0.048
38.96,134.50,0.053
38.99,134.64,0.057
39.01,134.78,0.064
39.04,134.93,0.071
39.07,135.07,0.078
39.10,135.21,0.086
39.13,135.35,0.099
39.16,135.49,0.109
39.19,135.63,0.130
39.21,135.77,0.147
39.24,135.91,0.168
39.27,136.05,0.199
39.30,136.19,0.228
39.33,136.33,0.257
39.36,136.47,0.287
39.38,136.62,0.321
39.41,136.76,0.362
39.44,136.90,0.407
39.47,137.04,0.453
39.50,137.18,0.502
39.53,137.32,0.567
39.55,137.45,0.631
39.58,137.59,0.701
39.61,137.73,0.781
39.64,137.87,0.875
39.67,138.01,0.972
39.69,138.14,1.085
39.72,138.28,1.211
39.75,138.42,1.352
39.78,138.55,1.515
39.81,138.69,1.689
39.84,138.82,1.874
39.86,138.95,2.081
39.89,139.09,2.307
39.92,139.22,2.565
39.95,139.35,2.846
39.98,139.48,3.137
40.01,139.60,3.484
40.04,139.73,3.780
40.06,139.86,4.085
40.09,139.99,4.418
40.12,140.11,4.708
40.15,140.24,5.116
40.18,140.37,5.302
40.21,140.50,5.441
40.23,140.64,5.481
40.26,140.78,5.267
40.29,140.93,5.018
40.32,141.08,4.714
40.35,141.24,4.454
40.38,141.39,4.038
40.40,141.55,3.504
40.43,141.73,2.796
40.46,141.90,2.166
40.49,142.07,1.564
40.52,142.23,1.191
40.54,142.39,0.960
40.57,142.54,0.814
40.60,142.69,0.720
40.63,142.84,0.658
40.66,142.98,0.615
40.69,143.12,0.589
40.71,143.27,0.572
40.74,143.41,0.557
40.77,143.55,0.548
40.80,143.69,0.543
40.83,143.84,0.537
40.86,143.98,0.534
40.89,144.12,0.530
40.91,144.26,0.526
40.94,144.40,0.523
40.97,144.55,0.519
41.00,144.69,0.516
41.03,144.83,0.512
41.06,144.97,0.510
41.08,145.11,0.507
41.11,145.25,0.506
41.14,145.40,0.505
41.17,145.54,0.505
41.20,145.68,0.506
41.23,145.82,0.508
41.25,145.96,0.511
41.28,146.10,0.514
41.31,146.24,0.516
41.34,146.39,0.519
41.37,146.53,0.522
41.39,146.67,0.524
41.42,146.81,0.526
41.45,146.95,0.527
41.48,147.10,0.527
41.51,147.24,0.526
41.54,147.38,0.523
41.56,147.52,0.519
41.59,147.66,0.509
41.62,147.81,0.499
41.65,147.95,0.485
41.68,148.09,0.471
41.71,148.23,0.452
41.74,148.38,0.437
41.76,148.52,0.424
41.79,148.66,0.410
41.82,148.80,0.391
41.85,148.95,0.368
41.88,149.09,0.336
41.91,149.23,0.305
41.93,149.38,
41.96,149.52,
41.98,,

[step]
Ramp 50.00 °C/min to -60.00 °C
Time,Temperature,Heat Flow (Normalized)
min,°C,W/g
42.09,150.07,0.199
42.09,150.08,0.199
42.09,150.09,0.198
42.09,150.10,0.198
42.10,150.10,0.198
42.10,150.11,0.197
42.11,150.11,0.196
42.11,150.12,0.194
42.11,150.12,0.190
42.11,150.12,0.185
42.12,150.13,0.176
42.12,150.12,0.169
42.13,150.12,0.162
42.13,150.12,0.157
42.13,150.11,0.155
42.14,150.10,0.154
42.14,150.09,0.154
42.14,150.07,0.153
42.14,150.05,0.154
42.15,150.03,0.155
42.15,150.01,0.163
42.16,149.98,0.184
42.16,149.95,0.214
42.16,149.91,0.246
42.16,149.87,0.273
42.17,149.82,0.289
42.17,149.77,0.296
42.18,149.71,0.299
42.18,149.66,0.301
42.18,149.59,0.300
42.19,149.52,0.297
42.19,149.45,0.293
42.19,149.38,0.287
42.19,149.30,0.285
42.20,149.21,0.279
42.20,149.13,0.241
42.21,149.04,0.172
42.21,148.94,0.104
42.21,148.84,0.057
42.21,148.74,0.010
42.22,148.63,-0.043
42.22,148.53,-0.097
42.23,148.41,-0.148
42.23,148.30,-0.203
42.23,148.18,-0.269
42.24,148.06,-0.331
42.24,147.93,-0.398
42.24,147.80,-0.466
42.24,147.67,-0.533
42.25,147.54,-0.604
42.25,147.41,-0.674
42.26,147.27,-0.740
42.26,147.13,-0.804
42.26,146.99,-0.871
42.26,146.85,-0.936
42.27,146.70,-1.006
42.27,146.55,-1.076
42.28,146.40,-1.143
42.28,146.25,-1.214
42.28,146.10,-1.286
42.29,145.95,-1.354
42.29,145.79,-1.424
42.29,145.64,-1.495
42.29,145.48,-1.566
42.30,145.32,-1.636
42.30,145.17,-1.705
42.31,145.01,-1.774
42.31,144.85,-1.844
42.31,144.69,-1.917
42.31,144.53,-1.979
42.32,144.37,-2.037
42.32,144.21,-2.094
42.33,144.05,-2.143
42.33,143.89,-2.200
42.33,143.73,-2.253
42.34,143.57,-2.298
42.34,143.41,-2.334
42.34,143.25,-2.372
42.34,143.09,-2.406
42.35,142.93,-2.439
42.35,142.77,-2.472
42.36,142.61,-2.498
42.36,142.44,-2.520
42.36,142.28,-2.539
42.36,142.12,-2.562
42.37,141.96,-2.583
42.37,141.80,-2.596
42.38,141.64,-2.612
42.38,141.48,-2.630
42.38,141.32,-2.643
42.39,141.15,-2.657
42.39,140.99,-2.665
42.39,140.83,-2.679
42.39,140.67,-2.689
42.40,140.50,-2.700
42.40,140.34,-2.712
42.41,140.18,-2.724
42.41,140.02,-2.731
42.41,139.85,-2.742
42.41,139.69,-2.754
42.42,139.53,-2.760
42.42,139.36,-2.769
42.43,139.20,-2.783
42.43,139.03,-2.787
42.43,138.87,-2.798
42.44,138.71,-2.809
42.44,138.54,-2.813
42.44,138.38,-2.820
42.44,138.22,-2.830
42.45,138.05,-2.839
42.45,137.89,-2.849
42.46,137.72,-2.862
42.46,137.56,-2.865
42.46,137.40,-2.867
42.46,137.23,-2.870
42.47,137.07,-2.873
42.47,136.90,-2.879
42.48,136.74,-2.888
42.48,136.58,-2.892
42.48,136.41,-2.895
42.49,136.25,-2.899
42.49,136.08,-2.904
42.49,135.92,-2.910
42.49,135.75,-2.915
42.50,135.59,-2.915
42.50,135.43,-2.915
42.51,135.26,-2.917
42.51,135.10,-2.919
42.51,134.93,-2.922
42.51,134.77,-2.926
42.52,134.60,-2.928
42.52,134.44,-2.930
42.53,134.27,-2.933
42.53,134.11,-2.936
42.53,133.95,-2.938
42.54,133.78,-2.942
42.54,133.62,-2.943
42.54,133.45,-2.944
42.54,133.29,-2.945
42.55,133.12,-2.946
42.55,132.96,-2.947
42.56,132.79,-2.948
42.56,132.63,-2.950
42.56,132.46,-2.952
42.56,132.30,-2.954
42.57,132.13,-2.956
42.57,131.97,-2.958
42.58,131.80,-2.959
42.58,131.64,-2.960
42.58,131.47,-2.961
42.59,131.31,-2.962
42.59,131.14,-2.962
42.59,130.98,-2.963
42.59,130.81,-2.964
42.60,130.65,-2.965
42.60,130.48,-2.967
42.61,130.32,-2.968
42.61,130.15,-2.968
42.61,129.99,-2.969
42.61,129.82,-2.971
42.62,129.66,-2.972
42.62,129.49,-2.972
42.63,129.33,-2.973
42.63,129.16,-2.974
42.63,129.00,-2.974
42.64,128.83,-2.975
42.64,128.67,-2.975
42.64,128.50,-2.976
42.64,128.34,-2.976
42.65,128.17,-2.976
42.65,128.01,-2.977
42.66,127.84,-2.977
42.66,127.68,-2.977
42.66,127.51,-2.977
42.66,127.34,-2.978
42.67,127.18,-2.978
42.67,127.01,-2.978
42.68,126.85,-2.978
42.68,126.68,-2.979
42.68,126.52,-2.979
42.69,126.35,-2.979
42.69,126.19,-2.980
42.69,126.02,-2.980
42.69,125.86,-2.980
42.70,125.69,-2.981
42.70,125.53,-2.981
42.71,125.36,-2.981
42.71,125.20,-2.981
42.71,125.03,-2.982
42.71,124.87,-2.982
42.72,124.70,-2.982
42.72,124.53,-2.982
42.73,124.37,-2.983
42.73,124.20,-2.983
42.73,124.04,-2.983
42.74,123.87,-2.983
42.74,123.71,-2.983
42.74,123.54,-2.983
42.74,123.38,-2.984
42.75,123.21,-2.984
42.75,123.05,-2.984
42.76,122.88,-2.984
42.76,122.71,-2.984
42.76,122.55,-2.985
42.76,122.38,-2.985
42.77,122.22,-2.985
42.77,122.05,-2.985
42.78,121.89,-2.986
42.78,121.72,-2.986
42.78,121.55,-2.986
42.79,121.39,-2.986
42.79,121.22,-2.986
42.79,121.06,-2.987
42.79,120.89,-2.987
42.80,120.73,-2.987
42.80,120.56,-2.987
42.81,120.40,-2.987
42.81,120.23,-2.987
42.81,120.07,-2.987
42.81,119.90,-2.988
42.82,119.73,-2.988
42.82,119.57,-2.988
42.83,119.40,-2.988
42.83,119.24,-2.988
42.83,119.07,-2.988
42.84,118.91,-2.988
42.84,118.74,-2.988
42.84,118.58,-2.988
42.84,118.41,-2.989
42.85,118.24,-2.989
42.85,118.08,-2.989
42.86,117.91,-2.989
42.86,117.75,-2.989
42.86,117.58,-2.989
42.86,117.42,-2.989
42.87,117.25,-2.989
42.87,117.08,-2.989
42.88,116.92,-2.989
42.88,116.75,-2.989
42.88,116.59,-2.989
42.89,116.42,-2.989
42.89,116.26,-2.989
42.89,116.09,-2.989
42.89,115.92,-2.989
42.90,115.76,-2.989
42.90,115.59,-2.989
42.91,115.43,-2.989
42.91,115.26,-2.989
42.91,115.09,-2.989
42.91,114.93,-2.989
42.92,114.76,-2.989
42.92,114.60,-2.989
42.93,114.43,-2.989
42.93,114.27,-2.989
42.93,114.10,-2.989
42.94,113.93,-2.989
42.94,113.77,-2.989
42.94,113.60,-2.989
42.94,113.44,-2.988
42.95,113.27,-2.988
42.95,113.11,-2.988
42.96,112.94,-2.988
42.96,112.77,-2.988
42.96,112.61,-2.988
42.96,112.44,-2.988
42.97,112.28,-2.987
42.97,112.11,-2.987
42.98,111.95,-2.987
42.98,111.78,-2.987
42.98,111.61,-2.987
42.99,111.45,-2.987
42.99,111.28,-2.987
42.99,111.12,-2.987
42.99,110.95,-2.987
43.00,110.78,-2.986
43.00,110.62,-2.986
43.01,110.45,-2.986
43.01,110.29,-2.986
43.01,110.12,-2.986
43.01,109.96,-2.986
43.02,109.79,-2.985
43.02,109.62,-2.985
43.03,109.46,-2.985
43.03,109.29,-2.985
43.03,109.13,-2.985
43.04,108.96,-2.985
43.04,108.80,-2.984
43.04,108.63,-2.984
43.04,108.47,-2.983
43.05,108.30,-2.983
43.05,108.13,-2.983
43.06,107.97,-2.983
43.06,107.80,-2.983
43.06,107.64,-2.982
43.06,107.47,-2.982
43.07,107.31,-2.982
43.07,107.14,-2.981
43.08,106.97,-2.981
43.08,106.81,-2.981
43.08,106.64,-2.980
43.09,106.48,-2.980
43.09,106.31,-2.980
43.09,106.15,-2.979
43.09,105.98,-2.978
43.10,105.82,-2.977
43.10,105.65,-2.977
43.11,105.49,-2.977
43.11,105.32,-2.976
43.11,105.15,-2.976
43.11,104.99,-2.976
[...]
123.96,12.72,0.024,0.254
123.99,12.83,0.023,0.250
124.01,12.94,0.023,0.250
124.03,13.05,0.023,0.251
124.05,13.15,0.023,0.249
124.07,13.26,0.023,0.247
124.09,13.37,0.023,0.247
124.11,13.48,0.023,0.247
124.14,13.59,0.023,0.247
124.16,13.70,0.023,0.246
124.18,13.80,0.023,0.245
124.20,13.91,0.023,0.242
124.22,14.02,0.023,0.243
124.25,14.13,0.023,0.243
124.27,14.24,0.022,0.240
124.29,14.35,0.023,0.241
124.31,14.45,0.023,0.242
124.33,14.56,0.022,0.240
124.35,14.67,0.022,0.239
124.38,14.78,0.023,0.241
124.40,14.89,0.023,0.242
124.42,15.00,0.022,0.240
124.44,15.11,0.022,0.237
124.46,15.21,0.022,0.235
124.48,15.32,0.022,0.236
124.50,15.43,0.022,0.236
124.53,15.54,0.022,0.235
124.55,15.65,0.022,0.234
124.57,15.76,0.022,0.232
124.59,15.87,0.022,0.231
124.61,15.97,0.022,0.232
124.64,16.08,0.022,0.230
124.66,16.19,0.022,0.232
124.68,16.30,0.022,0.232
124.70,16.41,0.022,0.232
124.72,16.52,0.022,0.231
124.74,16.62,0.022,0.230
124.76,16.73,0.021,0.229
124.79,16.84,0.021,0.228
124.81,16.95,0.021,0.226
124.83,17.06,0.021,0.222
124.85,17.17,0.021,0.222
124.87,17.28,0.021,0.223
124.90,17.38,0.021,0.223
124.92,17.49,0.021,0.221
124.94,17.60,0.020,0.219
124.96,17.71,0.021,0.223
124.98,17.82,0.021,0.221
125.00,17.92,0.020,0.218
125.03,18.03,0.020,0.218
125.05,18.14,0.020,0.217
125.07,18.25,0.020,0.218
125.09,18.36,0.020,0.214
125.11,18.47,0.020,0.216
125.13,18.57,0.020,0.215
125.15,18.68,0.020,0.216
125.18,18.79,0.020,0.214
125.20,18.90,0.020,0.212
125.22,19.01,0.020,0.212
125.24,19.12,0.020,0.210
125.26,19.23,0.019,0.208
125.29,19.33,0.019,0.207
125.31,19.44,0.019,0.204
125.33,19.55,0.019,0.203
125.35,19.66,0.019,0.200
125.37,19.77,0.019,0.201
125.39,19.88,0.019,0.200
125.41,19.98,0.018,0.197
125.44,20.09,0.018,0.198
125.46,20.20,0.018,0.197
125.48,20.31,0.018,0.194
125.50,20.42,0.018,0.193
125.52,20.53,0.018,0.190
125.55,20.63,0.018,0.190
125.57,20.74,0.018,0.188
125.59,20.85,0.017,0.186
125.61,20.96,0.017,0.186
125.63,21.07,0.017,0.186
125.65,21.18,0.017,0.185
125.68,21.29,0.017,0.186
125.70,21.39,0.017,0.184
125.72,21.50,0.017,0.185
125.74,21.61,0.017,0.187
125.76,21.72,0.017,0.184
125.78,21.83,0.017,0.183
125.80,21.93,0.017,0.181
125.83,22.04,0.017,0.183
125.85,22.15,0.017,0.183
125.87,22.26,0.017,0.182
125.89,22.37,0.017,0.178
125.91,22.48,0.017,0.178
125.94,22.59,0.017,0.178
125.96,22.69,0.017,0.177
125.98,22.80,0.017,0.177
126.00,22.91,0.016,0.174
126.02,23.02,0.016,0.172
126.04,23.13,0.016,0.173
126.06,23.24,0.016,0.174
126.09,23.35,0.016,0.173
126.11,23.45,0.016,0.173
126.13,23.56,0.016,0.173
126.15,23.67,0.016,0.174
126.17,23.78,0.016,0.175
126.20,23.89,0.016,0.176
126.22,24.00,0.016,0.172
126.24,24.11,0.016,0.172
126.26,24.21,0.016,0.173
126.28,24.32,0.016,0.172
126.30,24.43,0.016,0.170
126.33,24.54,0.016,0.171
126.35,24.65,0.016,0.170
126.37,24.76,0.016,0.171
126.39,24.86,0.016,0.166
126.41,24.97,0.016,0.169
126.43,25.08,0.016,0.169
126.45,25.19,0.016,0.168
126.48,25.30,0.016,0.171
126.50,25.41,0.016,0.169
126.52,25.51,0.016,0.169
126.54,25.62,0.016,0.169
126.56,25.73,0.016,0.169
126.59,25.84,0.016,0.167
126.61,25.95,0.016,0.166
126.63,26.06,0.016,0.167
126.65,26.16,0.015,0.166
126.67,26.27,0.015,0.165
126.69,26.38,0.015,0.165
126.71,26.49,0.015,0.163
126.74,26.60,0.015,0.162
126.76,26.71,0.015,0.161
126.78,26.82,0.015,0.160
126.80,26.92,0.015,0.159
126.82,27.03,0.015,0.158
126.85,27.14,0.015,0.158
126.87,27.25,0.015,0.157
126.89,27.36,0.015,0.155
126.91,27.47,0.015,0.157
126.93,27.57,0.015,0.157
126.95,27.68,0.015,0.156
126.98,27.79,0.015,0.155
127.00,27.90,0.014,0.155
127.02,28.01,0.014,0.155
127.04,28.12,0.014,0.151
127.06,28.23,0.014,0.151
127.08,28.33,0.014,0.150
127.10,28.44,0.014,0.150
127.13,28.55,0.014,0.151
127.15,28.66,0.014,0.150
127.17,28.77,0.014,0.148
127.19,28.88,0.014,0.147
127.21,28.98,0.014,0.147
127.24,29.09,0.014,0.148
127.26,29.20,0.014,0.148
127.28,29.31,0.014,0.147
127.30,29.42,0.014,0.148
127.32,29.53,0.014,0.146
127.34,29.63,0.014,0.146
127.36,29.74,0.014,0.146
127.39,29.85,0.014,0.145
127.41,29.96,0.013,0.142
127.43,30.07,0.014,0.145
127.45,30.18,0.013,0.142
127.47,30.28,0.013,0.144
127.50,30.39,0.013,0.144
127.52,30.50,0.013,0.140
127.54,30.61,0.013,0.139
127.56,30.72,0.013,0.141
127.58,30.83,0.013,0.138
127.60,30.94,0.013,0.136
127.63,31.04,0.013,0.136
127.65,31.15,0.013,0.136
127.67,31.26,0.012,0.133
127.69,31.37,0.013,0.137
127.71,31.48,0.013,0.135
127.73,31.59,0.013,0.137
127.75,31.69,0.013,0.136
127.78,31.80,0.013,0.136
127.80,31.91,0.013,0.137
127.82,32.02,0.013,0.136
127.84,32.13,0.012,0.133
127.86,32.24,0.012,0.132
127.89,32.34,0.012,0.133
127.91,32.45,0.012,0.132
127.93,32.56,0.012,0.131
127.95,32.67,0.012,0.131
127.97,32.78,0.012,0.131
127.99,32.89,0.012,0.130
128.01,33.00,0.012,0.131
128.04,33.10,0.012,0.128
128.06,33.21,0.012,0.131
128.08,33.32,0.012,0.132
128.10,33.43,0.012,0.129
128.12,33.54,0.012,0.130
128.15,33.65,0.012,0.129
128.17,33.75,0.012,0.129
128.19,33.86,0.012,0.128
128.21,33.97,0.012,0.128
128.23,34.08,0.012,0.128
128.25,34.19,0.012,0.128
128.28,34.30,0.012,0.126
128.30,34.40,0.012,0.125
128.32,34.51,0.012,0.126
128.34,34.62,0.012,0.129
128.36,34.73,0.012,0.128
128.38,34.84,0.012,0.127
128.40,34.95,0.012,0.130
128.43,35.06,0.012,0.128
128.45,35.16,0.012,0.128
128.47,35.27,0.012,0.128
128.49,35.38,0.012,0.127
128.51,35.49,0.012,0.129
128.54,35.60,0.012,0.130
128.56,35.71,0.012,0.130
128.58,35.81,0.012,0.131
128.60,35.92,0.012,0.130
128.62,36.03,0.012,0.129
128.64,36.14,0.012,0.129
128.66,36.25,0.012,0.130
128.69,36.36,0.012,0.127
128.71,36.46,0.012,0.128
128.73,36.57,0.012,0.129
128.75,36.68,0.012,0.126
128.77,36.79,0.012,0.124
128.80,36.90,0.012,0.126
128.82,37.01,0.011,0.122
128.84,37.11,0.011,0.122
128.86,37.22,0.011,0.123
128.88,37.33,0.011,0.122
128.90,37.44,0.011,0.121
128.93,37.55,0.011,0.123
128.95,37.66,0.012,0.123
128.97,37.77,0.011,0.121
128.99,37.87,0.011,0.121
129.01,37.98,0.011,0.119
129.03,38.09,0.011,0.119
129.05,38.20,0.011,0.119
129.08,38.31,0.011,0.117
129.10,38.42,0.011,0.117
129.12,38.53,0.011,0.119
129.14,38.64,0.011,0.120
129.16,38.74,0.011,0.120
129.19,38.85,0.011,0.121
129.21,38.96,0.011,0.120
129.23,39.07,0.011,0.121
129.25,39.18,0.011,0.121
129.27,39.28,0.011,0.121
129.29,39.39,0.012,0.123
129.31,39.50,0.011,0.122
129.34,39.61,0.011,0.121
129.36,39.72,0.011,0.119
129.38,39.83,0.011,0.117
129.40,39.93,0.011,0.117
129.42,40.04,0.011,0.116
129.45,40.15,0.011,0.116
129.47,40.26,0.011,0.115
129.49,40.37,0.011,0.115
129.51,40.48,0.011,0.114
129.53,40.59,0.011,0.113
129.55,40.69,0.011,0.115
129.58,40.80,0.011,0.117
129.60,40.91,0.011,0.115
129.62,41.02,0.011,0.117
129.64,41.13,0.011,0.115
129.66,41.23,0.011,0.117
129.68,41.34,0.011,0.118
129.70,41.45,0.011,0.117
129.73,41.56,0.011,0.115
129.75,41.67,0.011,0.117
129.77,41.78,0.011,0.116
129.79,41.89,0.011,0.114
129.81,41.99,0.011,0.113
129.84,42.10,0.010,0.112
129.86,42.21,0.010,0.110
129.88,42.32,0.010,0.111
129.90,42.43,0.010,0.109
129.92,42.53,0.010,0.108
129.94,42.64,0.010,0.107
129.96,42.75,0.010,0.104
129.99,42.86,0.010,0.105
130.01,42.97,0.010,0.107
130.03,43.08,0.010,0.106
130.05,43.19,0.010,0.107
130.07,43.29,0.010,0.106
130.10,43.40,0.010,0.105
130.12,43.51,0.010,0.106
130.14,43.62,0.010,0.105
130.16,43.73,0.010,0.108
130.18,43.83,0.010,0.105
130.20,43.94,0.010,0.104
130.23,44.05,0.010,0.104
130.25,44.16,0.009,0.100
130.27,44.27,0.009,0.100
130.29,44.38,0.009,0.100
130.31,44.49,0.009,0.100
130.33,44.59,0.010,0.102
130.35,44.70,0.009,0.101
130.38,44.81,0.010,0.102
130.40,44.92,0.010,0.105
130.42,45.03,0.010,0.104
130.44,45.14,0.010,0.103
130.46,45.25,0.010,0.104
130.49,45.35,0.010,0.105
130.51,45.46,0.010,0.105
130.53,45.57,0.010,0.104
130.55,45.68,0.010,0.105
130.57,45.79,0.010,0.105
130.59,45.90,0.010,0.106
130.61,46.01,0.010,0.105
130.64,46.11,0.010,0.105
130.66,46.22,0.010,0.105
130.68,46.33,0.010,0.105
130.70,46.44,0.010,0.104
130.72,46.55,0.010,0.103
130.75,46.66,0.010,0.103
130.77,46.76,0.010,0.103
130.79,46.87,0.010,0.101
130.81,46.98,0.010,0.104
130.83,47.09,0.010,0.105
130.85,47.20,0.010,0.106
130.88,47.31,0.010,0.105
130.90,47.41,0.010,0.106
130.92,47.52,0.010,0.108
130.94,47.63,0.010,0.108
130.96,47.74,0.010,0.107
130.98,47.85,0.010,0.108
131.00,47.96,0.010,0.108
131.03,48.07,0.010,0.106
131.05,48.17,0.010,0.107
131.07,48.28,0.010,0.107
131.09,48.39,0.010,0.106
131.11,48.50,0.010,0.106
131.14,48.61,0.010,0.105
131.16,48.72,0.010,0.103
131.18,48.82,0.010,0.104
131.20,48.93,0.010,0.106
131.22,49.04,0.010,0.106
131.24,49.15,0.010,0.105
131.26,49.26,0.010,0.106
131.29,49.37,0.010,0.104
131.31,49.48,0.010,0.103
131.33,49.58,0.010,0.105
131.35,49.69,0.010,0.104
131.37,49.80,0.010,0.103
131.40,49.91,0.010,0.103
131.42,50.02,0.010,0.102
131.44,50.13,0.009,0.100
131.46,50.23,0.010,0.102
131.48,50.34,0.010,0.102
131.50,50.45,0.010,0.101
131.53,50.56,0.010,0.101
131.55,50.67,0.010,0.103
131.57,50.78,0.010,0.102
131.59,50.88,0.010,0.102
131.61,50.99,0.010,0.102
131.63,51.10,0.010,0.102
131.65,51.21,0.010,0.103
131.68,51.32,0.010,0.101
131.70,51.43,0.010,0.102
131.72,51.53,0.010,0.103
131.74,51.64,0.010,0.103
131.76,51.75,0.010,0.103
131.79,51.86,0.010,0.101
131.81,51.97,0.010,0.103
131.83,52.08,0.010,0.102
131.85,52.19,0.009,0.101
131.87,52.29,0.009,0.100
131.89,52.40,0.010,0.103
131.91,52.51,0.010,0.102
131.94,52.62,0.010,0.102
131.96,52.73,0.010,0.102
131.98,52.84,0.010,0.104
132.00,52.94,0.010,0.105
132.02,53.05,0.010,0.104
132.05,53.16,0.010,0.105
132.07,53.27,0.010,0.104
132.09,53.38,0.010,0.106
132.11,53.49,0.010,0.105
132.13,53.59,0.010,0.108
132.15,53.70,0.010,0.107
132.18,53.81,0.010,0.107
132.20,53.92,0.010,0.110
132.22,54.03,0.010,0.111
132.24,54.14,0.010,0.111
132.26,54.25,0.011,0.113
132.28,54.35,0.011,0.113
132.30,54.46,0.011,0.114
132.33,54.57,0.011,0.113
132.35,54.68,0.011,0.113
132.37,54.79,0.010,0.112
132.39,54.90,0.010,0.111
132.41,55.01,0.010,0.109
132.44,55.11,0.010,0.109
132.46,55.22,0.010,0.111
132.48,55.33,0.010,0.111
132.50,55.44,0.010,0.110
132.52,55.55,0.010,0.110
132.54,55.65,0.010,0.110
132.56,55.76,0.010,0.109
132.59,55.87,0.010,0.110
132.61,55.98,0.010,0.108
132.63,56.09,0.010,0.109
132.65,56.20,0.010,0.108
132.67,56.31,0.010,0.108
132.70,56.41,0.010,0.109
132.72,56.52,0.010,0.110
132.74,56.63,0.010,0.110
132.76,56.74,0.011,0.113
132.78,56.85,0.010,0.112
132.80,56.96,0.010,0.110
132.83,57.06,0.010,0.109
132.85,57.17,0.010,0.109
132.87,57.28,0.010,0.107
132.89,57.39,0.010,0.107
132.91,57.50,0.010,0.106
132.93,57.61,0.010,0.105
132.95,57.71,0.010,0.104
132.98,57.82,0.010,0.103
133.00,57.93,0.010,0.102
133.02,58.04,0.010,0.102
133.04,58.15,0.010,0.102
133.06,58.26,0.010,0.103
133.09,58.37,0.009,0.100
133.11,58.47,0.009,0.101
133.13,58.58,0.009,0.101
133.15,58.69,0.009,0.099
133.17,58.80,0.009,0.099
133.19,58.91,0.009,0.099
133.21,59.02,0.009,0.096
133.24,59.12,0.009,0.097
133.26,59.23,0.009,0.096
133.28,59.34,0.009,0.097
133.30,59.45,0.009,0.097
133.32,59.56,0.009,0.096
133.35,59.67,0.009,0.097
133.37,59.78,0.009,0.098
133.39,59.89,0.009,0.097
133.41,59.99,0.009,0.099
133.43,60.10,0.009,0.100
133.45,60.21,0.009,0.101
133.48,60.32,0.010,0.101
133.50,60.43,0.010,0.103
133.52,60.54,0.009,0.100
133.54,60.64,0.010,0.102
133.56,60.75,0.009,0.099
133.58,60.86,0.009,0.101
133.60,60.97,0.010,0.101
133.63,61.08,0.009,0.100
133.65,61.19,0.009,0.099
133.67,61.29,0.009,0.099
133.69,61.40,0.009,0.100
133.71,61.51,0.009,0.100
133.74,61.62,0.009,0.101
133.76,61.73,0.010,0.102
133.78,61.84,0.010,0.102
133.80,61.94,0.010,0.102
133.82,62.05,0.009,0.101
133.84,62.16,0.009,0.100
133.86,62.27,0.009,0.100
133.89,62.38,0.009,0.100
133.91,62.49,0.009,0.101
133.93,62.60,0.009,0.100
133.95,62.70,0.009,0.099
133.97,62.81,0.009,0.098
134.00,62.92,0.009,0.097
134.02,63.03,0.009,0.097
134.04,63.14,0.009,0.095
134.06,63.25,0.009,0.094
134.08,63.35,0.009,0.098
134.10,63.46,0.009,0.098
134.13,63.57,0.009,0.095
134.15,63.68,0.009,0.096
134.17,63.79,0.009,0.096
134.19,63.90,0.009,0.093
134.21,64.00,0.009,0.095
134.23,64.11,0.009,0.094
134.25,64.22,0.009,0.093
134.28,64.33,0.009,0.094
134.30,64.44,0.009,0.094
134.32,64.55,0.009,0.093
134.34,64.65,0.008,0.091
134.36,64.76,0.008,0.089
134.39,64.87,0.008,0.088
134.41,64.98,0.008,0.088
134.43,65.09,0.008,0.088
134.45,65.20,0.008,0.089
134.47,65.30,0.008,0.088
134.49,65.41,0.008,0.086
134.51,65.52,0.008,0.087
134.54,65.63,0.008,0.085
134.56,65.74,0.008,0.085
134.58,65.85,0.008,0.085
134.60,65.95,0.008,0.084
134.62,66.06,0.008,0.084
134.65,66.17,0.008,0.085
134.67,66.28,0.008,0.087
134.69,66.39,0.008,0.088
134.71,66.50,0.008,0.086
134.73,66.60,0.008,0.086
134.75,66.71,0.008,0.085
134.78,66.82,0.008,0.084
134.80,66.93,0.008,0.085
134.82,67.04,0.008,0.086
134.84,67.15,0.008,0.087
134.86,67.26,0.008,0.086
134.88,67.36,0.008,0.087
134.90,67.47,0.008,0.086
134.93,67.58,0.008,0.085
134.95,67.69,0.008,0.086
134.97,67.80,0.008,0.086
134.99,67.91,0.008,0.087
135.01,68.01,0.008,0.086
135.04,68.12,0.008,0.087
135.06,68.23,0.008,0.087
135.08,68.34,0.008,0.088
135.10,68.45,0.008,0.088
135.12,68.56,0.008,0.088
135.14,68.66,0.008,0.087
135.16,68.77,0.008,0.089
135.19,68.88,0.008,0.090
135.21,68.99,0.009,0.091
135.23,69.10,0.008,0.091
135.25,69.21,0.009,0.091
135.27,69.31,0.009,0.093
135.30,69.42,0.009,0.093
135.32,69.53,0.009,0.092
135.34,69.64,0.008,0.089
135.36,69.75,0.008,0.090
135.38,69.86,0.009,0.091
135.40,69.97,0.008,0.091
135.43,70.07,0.009,0.092
135.45,70.18,0.009,0.094
135.47,70.29,0.009,0.093
135.49,70.40,0.009,0.093
135.51,70.51,0.009,0.095
135.53,70.61,0.009,0.094
135.55,70.72,0.009,0.094
135.58,70.83,0.009,0.094
135.60,70.94,0.009,0.093
135.62,71.05,0.009,0.092
135.64,71.16,0.009,0.092
135.66,71.27,0.009,0.092
135.69,71.37,0.009,0.093
135.71,71.48,0.009,0.094
135.73,71.59,0.009,0.095
135.75,71.70,0.009,0.094
135.77,71.81,0.009,0.094
135.79,71.92,0.009,0.097
135.81,72.02,0.009,0.097
135.84,72.13,0.009,0.098
135.86,72.24,0.009,0.099
135.88,72.35,0.009,0.100
135.90,72.46,0.009,0.099
135.92,72.57,0.009,0.099
135.95,72.67,0.009,0.100
135.97,72.78,0.009,0.100
135.99,72.89,0.009,0.101
136.01,73.00,0.009,0.100
136.03,73.11,0.010,0.102
136.05,73.22,0.010,0.103
136.08,73.32,0.010,0.104
136.10,73.43,0.010,0.103
136.12,73.54,0.010,0.104
136.14,73.65,0.010,0.104
136.16,73.76,0.010,0.102
136.18,73.87,0.010,0.104
136.20,73.98,0.010,0.105
136.23,74.08,0.010,0.107
136.25,74.19,0.010,0.109
136.27,74.30,0.010,0.109
136.29,74.41,0.010,0.110
136.31,74.52,0.010,0.111
136.34,74.63,0.010,0.111
136.36,74.74,0.011,0.114
136.38,74.84,0.011,0.113
136.40,74.95,0.011,0.114
136.42,75.06,0.011,0.113
136.44,75.17,0.011,0.114
136.46,75.28,0.011,0.115
136.49,75.39,0.011,0.116
136.51,75.49,0.011,0.119
136.53,75.60,0.011,0.118
136.55,75.71,0.011,0.119
136.57,75.82,0.011,0.119
136.60,75.93,0.011,0.121
136.62,76.04,0.011,0.121
136.64,76.14,0.011,0.121
136.66,76.25,0.011,0.122
136.68,76.36,0.011,0.122
136.70,76.47,0.011,0.122
136.73,76.58,0.012,0.124
136.75,76.69,0.012,0.123
136.77,76.79,0.012,0.124
136.79,76.90,0.012,0.124
136.81,77.01,0.012,0.125
136.83,77.12,0.012,0.123
136.85,77.23,0.012,0.123
136.88,77.34,0.011,0.122
136.90,77.44,0.011,0.120
136.92,77.55,0.011,0.121
136.94,77.66,0.011,0.120
136.96,77.77,0.011,0.120
136.98,77.88,0.011,0.121
137.01,77.99,0.011,0.120
137.03,78.10,0.011,0.120
137.05,78.20,0.011,0.119
137.07,78.31,0.011,0.119
137.09,78.42,0.011,0.120
137.12,78.53,0.011,0.122
137.14,78.64,0.011,0.121
137.16,78.75,0.011,0.121
137.18,78.85,0.011,0.121
137.20,78.96,0.011,0.122
137.22,79.07,0.011,0.121
137.25,79.18,0.011,0.121
137.27,79.29,0.012,0.124
137.29,79.40,0.012,0.123
137.31,79.50,0.011,0.123
137.33,79.61,0.011,0.122
137.35,79.72,0.011,0.121
137.38,79.83,0.011,0.121
137.40,79.94,0.011,0.119
137.42,80.05,0.011,0.120
137.44,80.15,0.011,0.122
137.46,80.26,0.011,0.121
137.48,80.37,0.011,0.120
137.50,80.48,0.011,0.121
137.53,80.59,0.011,0.122
137.55,80.70,0.012,0.123
137.57,80.81,0.012,0.127
137.59,80.91,0.012,0.128
137.61,81.02,0.012,0.130
137.63,81.13,0.012,0.130
137.66,81.24,0.012,0.129
137.68,81.35,0.012,0.130
137.70,81.45,0.012,0.129
137.72,81.56,0.012,0.131
137.74,81.67,0.012,0.128
137.77,81.78,0.012,0.127
137.79,81.89,0.012,0.126
137.81,82.00,0.012,0.127
137.83,82.11,0.012,0.128
137.85,82.21,0.012,0.131
137.87,82.32,0.012,0.131
137.90,82.43,0.012,0.130
137.92,82.54,0.013,0.135
137.94,82.65,0.013,0.135
137.96,82.76,0.013,0.137
137.98,82.87,0.013,0.139
138.00,82.97,0.013,0.140
138.03,83.08,0.013,0.141
138.05,83.19,0.013,0.140
138.07,83.30,0.013,0.143
138.09,83.41,0.014,0.144
138.11,83.52,0.013,0.142
138.13,83.62,0.013,0.144
138.15,83.73,0.013,0.144
138.18,83.84,0.013,0.141
138.20,83.95,0.013,0.143
138.22,84.06,0.014,0.144
138.24,84.16,0.013,0.142
138.26,84.27,0.013,0.143
138.28,84.38,0.013,0.142
138.31,84.49,0.013,0.141
138.33,84.60,0.013,0.142
138.35,84.71,0.013,0.144
138.37,84.82,0.013,0.143
138.39,84.92,0.014,0.145
138.42,85.03,0.014,0.145
138.44,85.14,0.014,0.146
138.46,85.25,0.014,0.147
138.48,85.36,0.014,0.148
138.50,85.47,0.014,0.148
138.52,85.57,0.014,0.149
138.55,85.68,0.014,0.150
138.57,85.79,0.014,0.154
138.59,85.90,0.014,0.154
138.61,86.01,0.015,0.156
138.63,86.12,0.015,0.157
138.65,86.22,0.015,0.159
138.68,86.33,0.015,0.157
138.70,86.44,0.015,0.159
138.72,86.55,0.015,0.159
138.74,86.66,0.015,0.160
138.76,86.77,0.015,0.162
138.78,86.88,0.015,0.161
138.80,86.98,0.015,0.161
138.83,87.09,0.015,0.160
138.85,87.20,0.015,0.157
138.87,87.31,0.015,0.157
138.89,87.42,0.015,0.157
138.91,87.53,0.014,0.154
138.93,87.63,0.014,0.154
138.96,87.74,0.015,0.158
138.98,87.85,0.014,0.154
139.00,87.96,0.015,0.155
139.02,88.07,0.015,0.156
139.04,88.18,0.015,0.157
139.07,88.28,0.015,0.156
139.09,88.39,0.015,0.156
139.11,88.50,0.015,0.157
139.13,88.61,0.015,0.156
139.15,88.72,0.015,0.155
139.17,88.83,0.015,0.159
139.20,88.93,0.015,0.159
139.22,89.04,0.015,0.158
139.24,89.15,0.015,0.159
139.26,89.26,0.015,0.158
139.28,89.37,0.015,0.160
139.30,89.48,0.015,0.160
139.33,89.59,0.015,0.162
139.35,89.69,0.015,0.162
139.37,89.80,0.015,0.161
139.39,89.91,0.015,0.163
139.41,90.02,0.015,0.164
139.43,90.13,0.015,0.164
139.45,90.24,0.015,0.165
139.48,90.34,0.016,0.166
139.50,90.45,0.016,0.167
139.52,90.56,0.016,0.166
139.54,90.67,0.016,0.166
139.56,90.78,0.016,0.167
139.58,90.89,0.016,0.168
139.61,90.99,0.016,0.167
139.63,91.10,0.016,0.167
139.65,91.21,0.016,0.169
139.67,91.32,0.016,0.167
139.69,91.43,0.016,0.169
139.72,91.54,0.016,0.170
139.74,91.64,0.016,0.172
139.76,91.75,0.016,0.175
139.78,91.86,0.016,0.173
139.80,91.97,0.016,0.173
139.82,92.08,0.016,0.171
139.85,92.19,0.016,0.173
139.87,92.29,0.016,0.173
139.89,92.40,0.016,0.172
139.91,92.51,0.016,0.171
139.93,92.62,0.016,0.173
139.95,92.73,0.016,0.174
139.98,92.84,0.016,0.175
140.00,92.94,0.016,0.174
140.02,93.05,0.016,0.175
140.04,93.16,0.017,0.176
140.06,93.27,0.017,0.178
140.08,93.38,0.017,0.181
140.10,93.49,0.017,0.183
140.13,93.60,0.017,0.183
140.15,93.70,0.017,0.184
140.17,93.81,0.018,0.187
140.19,93.92,0.018,0.189
140.21,94.03,0.018,0.191
140.23,94.14,0.018,0.193
140.26,94.25,0.018,0.195
140.28,94.36,0.018,0.197
140.30,94.47,0.018,0.195
140.32,94.57,0.019,0.198
140.34,94.68,0.019,0.201
140.37,94.79,0.019,0.202
140.39,94.90,0.019,0.203
140.41,95.01,0.019,0.206
140.43,95.12,0.019,0.207
140.45,95.22,0.020,0.211
140.47,95.33,0.020,0.212
140.50,95.44,0.020,0.210
140.52,95.55,0.020,0.213
140.54,95.66,0.020,0.213
140.56,95.76,0.020,0.212
140.58,95.87,0.020,0.212
140.60,95.98,0.020,0.214
140.63,96.09,0.020,0.217
140.65,96.20,0.020,0.217
140.67,96.31,0.020,0.218
140.69,96.41,0.021,0.220
140.71,96.52,0.021,0.220
140.73,96.63,0.021,0.222
140.75,96.74,0.021,0.225
140.78,96.85,0.021,0.226
140.80,96.96,0.022,0.230
140.82,97.07,0.022,0.230
140.84,97.17,0.022,0.232
140.86,97.28,0.022,0.233
140.88,97.39,0.022,0.232
140.91,97.50,0.022,0.234
140.93,97.61,0.022,0.234
140.95,97.72,0.022,0.236
140.97,97.82,0.022,0.238
140.99,97.93,0.023,0.240
141.02,98.04,0.023,0.242
141.04,98.15,0.023,0.245
141.06,98.26,0.023,0.246
141.08,98.37,0.023,0.250
141.10,98.47,0.024,0.252
141.12,98.58,0.024,0.253
141.15,98.69,0.024,0.255
141.17,98.80,0.024,0.256
141.19,98.91,0.024,0.258
141.21,99.02,0.024,
141.23,99.13,0.025,
141.25,99.23,0.025,
141.28,99.34,,
141.30,99.45,,
141.32,,,