File: DSC/Earl/2025_10_05_1CBG_1PVP40_ASD_5Cmin_n60C_150C_x3.csv
Filename,2025_10_05_1CBG_1PVP40_ASD_5Cmin_n60C_150C_x3
Instrument name,DSC2A-00468 (192.168.1.100)
Operator,JLY
rundate,10/5/2025
Sample name,2025_10_05_1CBG_1PVP40_ASD_5Cmin_n60C_150C_x3
proceduresegments,Data Off ; Equilibrate -60.00 °C; Data On ; Ramp 5.00 °C/min to 150.00 °C; Data Off ; Isothermal 1.0 min; Data On ; Ramp 5.00 °C/min to -60.00 °C; Data Off ; Isothermal 1.0 min; Data On ; Ramp 5.00 °C/min to 150.00 °C; Data Off ; Isothermal 1.0 min; Data On ; Ramp 5.00 °C/min to -60.00 °C; Data Off ; Isothermal 1.0 min; Data On ; Ramp 5.00 °C/min to 150.00 °C
[File Parameters]
Run date,10/5/2025 11:54:32 PM
Trios version,5.1.1.46572
Original File Name,
Current File Name,D:\DSC2500\JYarger\2025_10_05_1CBG_1PVP40_ASD_5Cmin_n60C_150C_x3.tri
[Procedure]
Procedure Name,ASD_n60C_150C_5Cmin_x3
Sample Name,2025_10_05_1CBG_1PVP40_ASD_5Cmin_n60C_150C_x3
Sample Mass,5.85 mg
Reference Sample Mass,0 mg
Pan Mass,32.46 mg
Pan Number,50
Reference Pan Mass,32.55 mg
Reference Pan Number,1
Pan Type,Aluminum
Comments,DSC_Samples_Y2_Tray_ASDs_Pharma_Oct2025 Google Sheet.
Project Name,Amorphous Pharma
Operator,JLY
Test,Custom
Unload Max Temperature,30
Unload Min Temperature,30
Load Max Temperature,30
Load Min Temperature,30
Stop on Gas Flow Error,Yes
[Signal List]
Signal #1,Time (min)
Signal #2,Temperature (°C)
Signal #3,Heat Flow (mW)
Signal #4,Delta T (µV)
Signal #5,Delta Tzero (µV)
Signal #6,Tzero Temperature (°C)
Signal #7,Cell Purge (mL/min)
Signal #8,Heater Temp (°C)
Signal #9,Power Delivered (W)
Signal #10,Reference Junction Temperature (°C)
Signal #11,Flange Temperature (°C)
Signal #12,Heat Flow Phase (rad)
Signal #13,Total Heat Capacity (J/°C)
Signal #14,Heat Capacity (J/°C)
[Configuration]
Company Name,ASU
Instrument Name,DSC2A-00468
Instrument Type,DSC2500
Serial Number,DSC2A-00468
IP,192.168.1.100
Location of Instrument,MRRC
DisplayType,Unknown
Sample Interval ,0.1 s/pt
Selected Heat Flow,T4P
Exotherm Direction,Down
Cell Serial,DRC2-00792
Lid Type,Standard
Cooler,RCS 90
Leave Cooler on at End of Sequence,On
Gas 2,Nitrogen
Gas Selected,Channel 1
Flow Rate,50 mL/min
Secondary Purge,On
Licensed Heat Flow,Heat Flow T4P
Modulation Licensed,Yes
[Versions]
Common IDD Version,1
Cortex Version,VER 2.10.2.31
Driver,5.0.0.6
GDM Version,1.0.3.3
TouchscreenVersion,1.0.0.16145
FEP Version,1.2.1.21
FEP Bootloader,2.0.0.5
AutoSampler Version,2.1.1.26
Auto Sampler Bootloader,2.0.0.5
FCM Version,1.1.0.3
FCM Bootloader,2.0.0.5
[Experiment Logs]
Experiment Log Entry # 1,Data On set to 0
Experiment Log Entry # 3,Equilibrate Segment -60 (C) Started
Experiment Log Entry # 5,Air Cool is off.
Experiment Log Entry # 7,Data On set to 1
Experiment Log Entry # 9,Ramp Segment 5 C/min to 150 Started
Experiment Log Entry # 11,Data On set to 0
Experiment Log Entry # 13,Isothermal Segment 1 min started
Experiment Log Entry # 15,Data On set to 1
Experiment Log Entry # 17,Ramp Segment 5 C/min to -60 Started
Experiment Log Entry # 19,Data On set to 0
Experiment Log Entry # 21,Isothermal Segment 1 min started
Experiment Log Entry # 23,Data On set to 1
Experiment Log Entry # 25,Ramp Segment 5 C/min to 150 Started
Experiment Log Entry # 27,Data On set to 0
Experiment Log Entry # 29,Isothermal Segment 1 min started
Experiment Log Entry # 31,Data On set to 1
Experiment Log Entry # 33,Ramp Segment 5 C/min to -60 Started
Experiment Log Entry # 35,Data On set to 0
Experiment Log Entry # 37,Isothermal Segment 1 min started
Experiment Log Entry # 39,Data On set to 1
Experiment Log Entry # 41,Ramp Segment 5 C/min to 150 Started
[Method Log]
Method Log Entry # 1,Data Off
Method Log Entry # 2,Equilibrate -60 °C
Method Log Entry # 3,Data On
Method Log Entry # 4,(Ramp 383548) Ramp 5 °C/minute to 150 °C
Method Log Entry # 5,Data Off
Method Log Entry # 6,Isothermal 1 minutes
Method Log Entry # 7,Data On
Method Log Entry # 8,(Ramp 383552) Ramp 5 °C/minute to -60 °C
Method Log Entry # 9,Data Off
Method Log Entry # 10,Isothermal 1 minutes
Method Log Entry # 11,Data On
Method Log Entry # 12,(Ramp 383556) Ramp 5 °C/minute to 150 °C
Method Log Entry # 13,Data Off
Method Log Entry # 14,Isothermal 1 minutes
Method Log Entry # 15,Data On
Method Log Entry # 16,(Ramp 383560) Ramp 5 °C/minute to -60 °C
Method Log Entry # 17,Data Off
Method Log Entry # 18,Isothermal 1 minutes
Method Log Entry # 19,Data On
Method Log Entry # 20,(Ramp 383564) Ramp 5 °C/minute to 150 °C
Cell Serial,DRC2-00792
[T1 Calibration]
Slope,-0.008529666
Offset,9.636258
Initial Temperature,98.23
GUID,f8bfdadc-4977-4fdf-ba6d-0ba9134940c3
[TZero Calibration]
Date Applied,11/29/2022 4:06:13 PM
Description,From -89.059 °C to 396.009 °C at 20.000°C/min
Gas Type,Nitrogen
Pan Type,None
Source Files 1,C:\Users\yargerlab\Desktop\DSC Data\General\TZero_calibration_11_29_22_2nd(2).tri
Source Files 2,C:\Users\yargerlab\Desktop\DSC Data\General\TZero_calibration_11_29_22_2nd(3).tri
Delta T Offset,13.05235
Delta T Slope,-0.007271007
Delta T0 Offset,-13.69128
Delta T0 Slope,0.06063341
[Temperature Calibration]
Date Applied,11/29/2022 7:12:28 PM
Description,From 106.590 °C to 186.590 °C at 10.000°C/min
Gas Type,Nitrogen
Pan Type,Tzero Aluminum Hermetic
Source Files 1,C:\Users\yargerlab\Desktop\DSC Data\General\Indium(6).tri
Measured 1,157.391
Known 1,156.598
[Cell Constant Calibration]
Date Applied,11/29/2022 7:12:29 PM
Description,From 106.590 °C to 186.590 °C at 10.000°C/min
Gas Type,Nitrogen
Pan Type,Tzero Aluminum Hermetic
Source Files 1,C:\Users\yargerlab\Desktop\DSC Data\General\Indium(6).tri
T4P KCell,1.006051
Onset Slope,63.26126 mW/°C
[Direct Cp Calibration]
Date Applied,11/30/2022 11:04:51 AM
Description,From -79.983 °C to 298.409 °C at 10.000°C/min
Gas Type,Nitrogen
Pan Type,Tzero Aluminum Hermetic
Source Files 1,C:\Users\yargerlab\Desktop\DSC Data\General\Sapphire_Heat_Capacity_11_30_22.tri
[Rev Cp Calibration]
Date Applied,11/30/2022 1:58:51 PM
Description,From -79.996 °C to 292.812 °C at 3.000°C/min
Gas Type,Nitrogen
Pan Type,Tzero Aluminum Hermetic
Source Files 1,C:\Users\yargerlab\Desktop\DSC Data\General\Sapphire_MDSC_Calibration_11_30_22.tri
[step]
Ramp 5.00 °C/min to 150.00 °C
Time,Temperature,Heat Flow (Normalized)
min,°C,W/g
0.00,-59.81,-0.052
0.03,-59.81,-0.048
0.06,-59.81,-0.042
0.08,-59.77,-0.041
0.11,-59.69,-0.037
0.14,-59.59,-0.020
0.17,-59.47,0.001
0.20,-59.35,0.020
0.23,-59.22,0.036
0.26,-59.10,0.047
0.28,-58.97,0.055
0.31,-58.84,0.062
0.34,-58.70,0.066
0.37,-58.57,0.070
0.40,-58.43,0.073
0.43,-58.29,0.076
0.45,-58.16,0.077
0.48,-58.02,0.078
0.51,-57.88,0.079
0.54,-57.74,0.080
0.57,-57.60,0.080
0.60,-57.46,0.081
0.62,-57.32,0.081
0.65,-57.18,0.082
0.68,-57.04,0.082
0.71,-56.90,0.083
0.74,-56.76,0.083
0.77,-56.62,0.084
0.79,-56.48,0.084
0.82,-56.34,0.084
0.85,-56.20,0.085
0.88,-56.06,0.085
0.91,-55.92,0.085
0.93,-55.78,0.086
0.96,-55.64,0.086
0.99,-55.50,0.086
1.02,-55.36,0.086
1.05,-55.22,0.087
1.08,-55.08,0.087
1.11,-54.94,0.087
1.13,-54.79,0.087
1.16,-54.65,0.087
1.19,-54.51,0.087
1.22,-54.37,0.087
1.25,-54.23,0.088
1.28,-54.09,0.088
1.30,-53.95,0.088
1.33,-53.80,0.088
1.36,-53.66,0.088
1.39,-53.52,0.088
1.42,-53.38,0.088
1.44,-53.24,0.088
1.47,-53.10,0.088
1.50,-52.96,0.088
1.53,-52.81,0.088
1.56,-52.67,0.088
1.59,-52.53,0.088
1.62,-52.39,0.088
1.64,-52.25,0.088
1.67,-52.11,0.088
1.70,-51.97,0.088
1.73,-51.82,0.088
1.76,-51.68,0.088
1.78,-51.54,0.088
1.81,-51.40,0.088
1.84,-51.26,0.088
1.87,-51.12,0.088
1.90,-50.98,0.088
1.93,-50.83,0.088
1.96,-50.69,0.088
1.98,-50.55,0.088
2.01,-50.41,0.088
2.04,-50.27,0.088
2.07,-50.13,0.088
2.10,-49.98,0.088
2.13,-49.84,0.088
2.15,-49.70,0.088
2.18,-49.56,0.088
2.21,-49.42,0.088
2.24,-49.28,0.088
2.27,-49.14,0.088
2.29,-48.99,0.088
2.32,-48.85,0.088
2.35,-48.71,0.088
2.38,-48.57,0.088
2.41,-48.43,0.088
2.44,-48.29,0.088
2.46,-48.14,0.088
2.49,-48.00,0.088
2.52,-47.86,0.088
2.55,-47.72,0.088
2.58,-47.58,0.088
2.61,-47.44,0.088
2.64,-47.30,0.088
2.66,-47.15,0.088
2.69,-47.01,0.088
2.72,-46.87,0.088
2.75,-46.73,0.088
2.78,-46.59,0.088
2.81,-46.44,0.088
2.83,-46.30,0.089
2.86,-46.16,0.089
2.89,-46.02,0.089
2.92,-45.88,0.089
2.95,-45.74,0.089
2.98,-45.60,0.089
3.00,-45.45,0.089
3.03,-45.31,0.089
3.06,-45.17,0.089
3.09,-45.03,0.089
3.12,-44.89,0.089
3.14,-44.75,0.089
3.17,-44.60,0.089
3.20,-44.46,0.089
3.23,-44.32,0.089
3.26,-44.18,0.089
3.29,-44.04,0.089
3.31,-43.90,0.089
3.34,-43.76,0.089
3.37,-43.61,0.089
3.40,-43.48,0.089
3.43,-43.34,0.089
3.46,-43.20,0.089
3.49,-43.05,0.088
3.51,-42.91,0.088
3.54,-42.77,0.088
3.57,-42.63,0.088
3.60,-42.49,0.088
3.63,-42.34,0.088
3.66,-42.20,0.088
3.68,-42.06,0.088
3.71,-41.92,0.089
3.74,-41.78,0.089
3.77,-41.63,0.089
3.80,-41.49,0.089
3.83,-41.35,0.089
3.85,-41.21,0.089
3.88,-41.07,0.089
3.91,-40.92,0.089
3.94,-40.78,0.089
3.97,-40.64,0.089
3.99,-40.50,0.089
4.02,-40.36,0.089
4.05,-40.22,0.089
4.08,-40.07,0.089
4.11,-39.93,0.089
4.14,-39.79,0.089
4.16,-39.65,0.089
4.19,-39.51,0.089
4.22,-39.36,0.089
4.25,-39.22,0.089
4.28,-39.08,0.089
4.31,-38.94,0.089
4.34,-38.80,0.089
4.36,-38.65,0.089
4.39,-38.51,0.089
4.42,-38.37,0.089
4.45,-38.23,0.089
4.48,-38.09,0.089
4.50,-37.94,0.089
4.53,-37.80,0.089
4.56,-37.66,0.089
4.59,-37.52,0.089
4.62,-37.38,0.089
4.65,-37.23,0.089
4.68,-37.09,0.090
4.70,-36.95,0.090
4.73,-36.81,0.090
4.76,-36.67,0.090
4.79,-36.52,0.090
4.82,-36.38,0.090
4.85,-36.24,0.090
4.87,-36.10,0.090
4.90,-35.96,0.090
4.93,-35.81,0.090
4.96,-35.67,0.090
4.99,-35.53,0.090
5.01,-35.39,0.090
5.04,-35.25,0.090
5.07,-35.11,0.090
5.10,-34.96,0.090
5.13,-34.82,0.090
5.16,-34.68,0.090
5.19,-34.54,0.090
5.21,-34.40,0.090
5.24,-34.25,0.090
5.27,-34.11,0.090
5.30,-33.97,0.090
5.33,-33.83,0.090
5.35,-33.69,0.090
5.38,-33.55,0.090
5.41,-33.40,0.090
5.44,-33.26,0.090
5.47,-33.12,0.090
5.50,-32.98,0.090
5.53,-32.84,0.090
5.55,-32.70,0.090
5.58,-32.55,0.090
5.61,-32.41,0.090
5.64,-32.27,0.090
5.67,-32.13,0.090
5.70,-31.99,0.090
5.72,-31.84,0.090
5.75,-31.70,0.090
5.78,-31.56,0.090
5.81,-31.42,0.091
5.84,-31.28,0.091
5.86,-31.13,0.091
5.89,-30.99,0.091
5.92,-30.85,0.091
5.95,-30.71,0.091
5.98,-30.57,0.091
6.01,-30.42,0.091
6.04,-30.28,0.091
6.06,-30.14,0.091
6.09,-30.00,0.091
6.12,-29.86,0.091
6.15,-29.72,0.091
6.18,-29.58,0.091
6.20,-29.43,0.091
6.23,-29.29,0.091
6.26,-29.15,0.091
6.29,-29.01,0.091
6.32,-28.87,0.091
6.35,-28.72,0.091
6.38,-28.58,0.091
6.40,-28.44,0.091
6.43,-28.30,0.091
6.46,-28.16,0.091
6.49,-28.01,0.091
6.52,-27.87,0.091
6.55,-27.73,0.091
6.57,-27.59,0.091
6.60,-27.45,0.091
6.63,-27.31,0.091
6.66,-27.16,0.091
6.69,-27.02,0.091
6.71,-26.88,0.091
6.74,-26.74,0.091
6.77,-26.60,0.091
6.80,-26.45,0.091
6.83,-26.31,0.091
6.86,-26.17,0.091
6.89,-26.03,0.091
6.91,-25.89,0.091
6.94,-25.75,0.092
6.97,-25.60,0.092
7.00,-25.46,0.092
7.03,-25.32,0.092
7.05,-25.18,0.092
7.08,-25.04,0.092
7.11,-24.89,0.092
7.14,-24.75,0.092
7.17,-24.61,0.092
7.20,-24.47,0.092
7.23,-24.33,0.092
7.25,-24.19,0.092
7.28,-24.04,0.092
7.31,-23.90,0.092
7.34,-23.76,0.092
7.37,-23.62,0.092
7.40,-23.48,0.092
7.42,-23.33,0.092
7.45,-23.19,0.092
7.48,-23.05,0.092
7.51,-22.91,0.092
7.54,-22.77,0.092
7.56,-22.62,0.092
7.59,-22.48,0.092
7.62,-22.34,0.092
7.65,-22.20,0.092
7.68,-22.06,0.092
7.71,-21.92,0.092
7.74,-21.77,0.092
7.76,-21.63,0.092
7.79,-21.49,0.092
7.82,-21.35,0.093
7.85,-21.21,0.093
7.88,-21.07,0.093
7.90,-20.92,0.093
7.93,-20.78,0.093
7.96,-20.64,0.093
7.99,-20.50,0.093
8.02,-20.36,0.093
8.05,-20.21,0.093
8.08,-20.07,0.093
8.10,-19.93,0.093
8.13,-19.79,0.093
8.16,-19.65,0.093
8.19,-19.51,0.093
8.22,-19.36,0.093
8.25,-19.22,0.093
8.27,-19.08,0.093
8.30,-18.94,0.093
8.33,-18.80,0.093
8.36,-18.66,0.093
8.39,-18.51,0.093
8.41,-18.37,0.093
8.44,-18.23,0.093
8.47,-18.09,0.093
8.50,-17.95,0.093
8.53,-17.80,0.093
8.56,-17.66,0.094
8.58,-17.52,0.094
8.61,-17.38,0.094
8.64,-17.24,0.094
8.67,-17.09,0.094
8.70,-16.95,0.094
8.73,-16.81,0.094
8.75,-16.67,0.094
8.78,-16.53,0.094
8.81,-16.39,0.094
8.84,-16.24,0.094
8.87,-16.10,0.094
8.90,-15.96,0.094
8.93,-15.82,0.094
8.95,-15.68,0.094
8.98,-15.53,0.094
9.01,-15.39,0.094
9.04,-15.25,0.094
9.07,-15.11,0.094
9.10,-14.97,0.094
9.12,-14.83,0.094
9.15,-14.68,0.094
9.18,-14.54,0.094
9.21,-14.40,0.094
9.24,-14.26,0.095
9.27,-14.12,0.095
9.29,-13.98,0.095
9.32,-13.83,0.095
9.35,-13.69,0.095
9.38,-13.55,0.095
9.41,-13.41,0.095
9.43,-13.27,0.095
9.46,-13.12,0.095
9.49,-12.99,0.095
9.52,-12.84,0.095
9.55,-12.70,0.095
9.58,-12.56,0.095
9.60,-12.42,0.095
9.63,-12.27,0.095
9.66,-12.13,0.095
9.69,-11.99,0.095
9.72,-11.85,0.095
9.75,-11.71,0.095
9.78,-11.56,0.095
9.80,-11.42,0.095
9.83,-11.28,0.095
9.86,-11.14,0.096
9.89,-11.00,0.096
9.92,-10.85,0.096
9.95,-10.71,0.096
9.97,-10.57,0.096
10.00,-10.43,0.096
10.03,-10.28,0.096
10.06,-10.14,0.096
10.09,-10.00,0.096
10.12,-9.86,0.096
10.14,-9.72,0.096
10.17,-9.58,0.096
10.20,-9.44,0.096
10.23,-9.29,0.096
10.26,-9.15,0.096
10.28,-9.01,0.096
10.31,-8.87,0.096
10.34,-8.73,0.096
10.37,-8.59,0.096
10.40,-8.44,0.096
10.43,-8.30,0.097
10.45,-8.16,0.097
10.48,-8.02,0.097
10.51,-7.88,0.097
10.54,-7.74,0.097
10.57,-7.60,0.097
10.60,-7.45,0.097
10.63,-7.31,0.097
10.65,-7.17,0.097
10.68,-7.03,0.097
10.71,-6.89,0.097
10.74,-6.74,0.097
10.77,-6.60,0.097
10.80,-6.46,0.097
10.82,-6.32,0.097
10.85,-6.18,0.097
10.88,-6.04,0.097
10.91,-5.90,0.097
10.94,-5.75,0.097
10.97,-5.61,0.098
10.99,-5.47,0.098
11.02,-5.33,0.098
11.05,-5.19,0.098
11.08,-5.05,0.098
11.11,-4.90,0.098
11.13,-4.76,0.098
11.16,-4.62,0.098
11.19,-4.48,0.098
11.22,-4.34,0.098
11.25,-4.19,0.098
11.28,-4.05,0.098
11.30,-3.91,0.098
11.33,-3.77,0.098
11.36,-3.63,0.098
11.39,-3.49,0.099
11.42,-3.34,0.099
11.45,-3.20,0.099
11.48,-3.06,0.099
11.50,-2.92,0.099
11.53,-2.78,0.099
11.56,-2.63,0.099
11.59,-2.49,0.099
11.62,-2.35,0.099
11.65,-2.21,0.099
11.67,-2.07,0.099
11.70,-1.92,0.099
11.73,-1.78,0.099
11.76,-1.64,0.099
11.79,-1.50,0.099
11.82,-1.36,0.099
11.84,-1.22,0.099
11.87,-1.07,0.099
11.90,-0.93,0.100
11.93,-0.79,0.100
11.96,-0.65,0.100
11.98,-0.51,0.100
12.01,-0.36,0.100
12.04,-0.22,0.100
12.07,-0.08,0.100
12.10,0.06,0.100
12.13,0.20,0.100
12.15,0.35,0.100
12.18,0.48,0.100
12.21,0.63,0.100
12.24,0.77,0.100
12.27,0.91,0.100
12.30,1.05,0.100
12.33,1.20,0.100
12.35,1.34,0.101
12.38,1.48,0.101
12.41,1.62,0.101
12.44,1.76,0.101
12.47,1.90,0.101
12.50,2.05,0.101
12.52,2.19,0.101
12.55,2.33,0.101
12.58,2.47,0.101
12.61,2.61,0.101
12.64,2.75,0.101
12.67,2.90,0.101
12.69,3.04,0.101
12.72,3.18,0.101
12.75,3.32,0.102
12.78,3.46,0.102
12.81,3.60,0.102
12.83,3.75,0.102
12.86,3.89,0.102
12.89,4.03,0.102
12.92,4.17,0.102
12.95,4.31,0.102
12.98,4.46,0.102
13.00,4.60,0.102
13.03,4.74,0.102
13.06,4.88,0.102
13.09,5.02,0.103
13.12,5.16,0.103
13.15,5.31,0.103
13.18,5.45,0.103
13.20,5.59,0.103
13.23,5.73,0.103
13.26,5.87,0.103
13.29,6.02,0.103
13.32,6.16,0.103
13.35,6.30,0.103
13.37,6.44,0.103
13.40,6.58,0.103
13.43,6.72,0.103
13.46,6.87,0.104
13.49,7.01,0.104
13.52,7.15,0.104
13.54,7.29,0.104
13.57,7.43,0.104
13.60,7.58,0.104
13.63,7.72,0.104
13.66,7.86,0.104
13.68,8.00,0.104
13.71,8.14,0.104
13.74,8.28,0.104
13.77,8.43,0.105
13.80,8.57,0.105
13.83,8.71,0.105
13.85,8.85,0.105
13.88,8.99,0.105
13.91,9.13,0.105
13.94,9.28,0.105
13.97,9.42,0.105
14.00,9.56,0.105
14.03,9.70,0.105
14.05,9.84,0.106
14.08,9.99,0.106
14.11,10.13,0.106
14.14,10.27,0.106
14.17,10.41,0.106
14.20,10.55,0.106
14.22,10.69,0.106
14.25,10.84,0.106
14.28,10.98,0.106
14.31,11.12,0.107
14.34,11.26,0.107
14.37,11.40,0.107
14.39,11.55,0.107
14.42,11.69,0.107
14.45,11.83,0.107
14.48,11.97,0.107
14.51,12.11,0.107
14.53,12.25,0.107
14.56,12.39,0.107
14.59,12.54,0.107
14.62,12.68,0.107
14.65,12.82,0.107
14.68,12.96,0.108
14.70,13.10,0.108
14.73,13.25,0.108
14.76,13.39,0.108
14.79,13.53,0.108
14.82,13.67,0.108
14.85,13.81,0.108
14.88,13.95,0.108
14.90,14.10,0.108
14.93,14.24,0.109
14.96,14.38,0.109
14.99,14.52,0.109
15.02,14.66,0.109
15.05,14.80,0.109
15.07,14.95,0.109
15.10,15.09,0.109
15.13,15.23,0.109
15.16,15.37,0.109
15.19,15.51,0.110
15.22,15.65,0.110
15.24,15.80,0.110
15.27,15.94,0.110
15.30,16.08,0.110
15.33,16.22,0.110
15.36,16.36,0.110
15.38,16.51,0.110
15.41,16.65,0.111
15.44,16.79,0.111
15.47,16.93,0.111
15.50,17.07,0.111
15.53,17.21,0.111
15.55,17.36,0.111
15.58,17.50,0.111
15.61,17.64,0.111
15.64,17.78,0.111
15.67,17.92,0.112
15.70,18.06,0.112
15.73,18.21,0.112
15.75,18.35,0.112
15.78,18.49,0.112
15.81,18.63,0.112
15.84,18.77,0.112
15.87,18.92,0.112
15.90,19.06,0.113
15.92,19.20,0.113
15.95,19.34,0.113
15.98,19.48,0.113
16.01,19.62,0.113
16.04,19.77,0.113
16.07,19.91,0.113
16.09,20.05,0.113
16.12,20.19,0.114
16.15,20.33,0.114
16.18,20.48,0.114
16.21,20.62,0.114
16.23,20.76,0.114
16.26,20.90,0.114
16.29,21.04,0.114
16.32,21.18,0.114
16.35,21.32,0.114
16.38,21.47,0.115
16.40,21.61,0.115
16.43,21.75,0.115
16.46,21.89,0.115
16.49,22.03,0.115
16.52,22.18,0.115
16.55,22.32,0.115
16.58,22.46,0.116
16.60,22.60,0.116
16.63,22.74,0.116
16.66,22.89,0.116
16.69,23.03,0.116
16.72,23.17,0.116
16.75,23.31,0.117
16.77,23.45,0.117
16.80,23.59,0.117
16.83,23.73,0.117
16.86,23.88,0.117
16.89,24.02,0.117
16.92,24.16,0.117
16.94,24.30,0.118
16.97,24.44,0.118
17.00,24.59,0.118
17.03,24.73,0.118
17.06,24.87,0.118
17.08,25.01,0.118
17.11,25.15,0.118
17.14,25.29,0.119
17.17,25.44,0.119
17.20,25.58,0.119
17.23,25.72,0.119
17.26,25.86,0.119
17.28,26.00,0.119
17.31,26.14,0.120
17.34,26.29,0.120
17.37,26.43,0.120
17.40,26.57,0.120
17.43,26.71,0.120
17.45,26.85,0.121
17.48,26.99,0.121
17.51,27.14,0.121
17.54,27.28,0.121
17.57,27.42,0.121
17.59,27.56,0.121
17.62,27.70,0.122
17.65,27.84,0.122
17.68,27.99,0.122
17.71,28.13,0.122
17.74,28.27,0.122
17.77,28.41,0.122
17.79,28.55,0.123
17.82,28.69,0.123
17.85,28.84,0.123
17.88,28.98,0.123
17.91,29.12,0.123
17.93,29.26,0.124
17.96,29.40,0.124
17.99,29.55,0.124
18.02,29.69,0.124
18.05,29.83,0.124
18.08,29.97,0.125
18.11,30.11,0.125
18.13,30.25,0.125
18.16,30.39,0.125
18.19,30.54,0.125
18.22,30.68,0.126
18.25,30.82,0.126
18.28,30.96,0.126
18.30,31.10,0.126
18.33,31.24,0.126
18.36,31.39,0.127
18.39,31.53,0.127
18.42,31.67,0.127
18.44,31.81,0.127
18.47,31.96,0.128
18.50,32.10,0.128
18.53,32.24,0.128
18.56,32.38,0.128
18.59,32.52,0.128
18.62,32.66,0.129
18.64,32.80,0.129
18.67,32.94,0.129
18.70,33.09,0.129
18.73,33.23,0.130
18.76,33.37,0.130
18.78,33.51,0.130
18.81,33.65,0.130
18.84,33.79,0.130
18.87,33.94,0.131
18.90,34.08,0.131
18.93,34.22,0.131
18.96,34.36,0.131
18.98,34.50,0.132
19.01,34.65,0.132
19.04,34.79,0.132
19.07,34.93,0.132
19.10,35.07,0.133
19.13,35.21,0.133
19.15,35.35,0.133
19.18,35.50,0.133
19.21,35.64,0.134
19.24,35.78,0.134
19.27,35.92,0.134
19.29,36.06,0.134
19.32,36.20,0.135
19.35,36.35,0.135
19.38,36.49,0.135
19.41,36.63,0.135
19.44,36.77,0.136
19.47,36.91,0.136
19.49,37.06,0.136
19.52,37.20,0.136
19.55,37.34,0.137
19.58,37.48,0.137
19.61,37.62,0.137
19.63,37.76,0.137
19.66,37.90,0.138
19.69,38.05,0.138
19.72,38.19,0.138
19.75,38.33,0.139
19.78,38.47,0.139
19.81,38.61,0.139
19.83,38.75,0.139
19.86,38.90,0.140
19.89,39.04,0.140
19.92,39.18,0.140
19.95,39.32,0.140
19.98,39.46,0.140
20.00,39.61,0.141
20.03,39.75,0.141
20.06,39.89,0.141
20.09,40.03,0.141
20.12,40.17,0.142
20.14,40.31,0.142
20.17,40.46,0.142
20.20,40.60,0.142
20.23,40.74,0.142
20.26,40.88,0.143
20.29,41.02,0.143
20.32,41.17,0.143
20.34,41.31,0.143
20.37,41.45,0.143
20.40,41.59,0.144
20.43,41.73,0.144
20.46,41.87,0.144
20.48,42.01,0.144
20.51,42.16,0.144
20.54,42.30,0.144
20.57,42.44,0.145
20.60,42.58,0.145
20.63,42.72,0.145
20.66,42.87,0.145
20.68,43.01,0.145
20.71,43.15,0.145
20.74,43.29,0.145
20.77,43.43,0.146
20.80,43.58,0.146
20.83,43.72,0.146
20.85,43.86,0.146
20.88,44.00,0.146
20.91,44.14,0.146
20.94,44.28,0.146
20.97,44.42,0.147
20.99,44.57,0.147
21.02,44.71,0.147
21.05,44.85,0.147
21.08,44.99,0.147
21.11,45.14,0.147
21.14,45.28,0.147
21.17,45.42,0.147
21.19,45.56,0.148
21.22,45.70,0.148
21.25,45.84,0.148
21.28,45.98,0.148
21.31,46.13,0.148
21.33,46.27,0.148
21.36,46.41,0.148
21.39,46.55,0.148
21.42,46.69,0.149
21.45,46.84,0.149
21.48,46.98,0.149
21.51,47.12,0.149
21.53,47.26,0.149
21.56,47.40,0.149
21.59,47.54,0.150
21.62,47.69,0.150
21.65,47.83,0.150
21.68,47.97,0.150
21.70,48.11,0.150
21.73,48.25,0.151
21.76,48.39,0.151
21.79,48.54,0.151
21.82,48.68,0.151
21.84,48.82,0.151
21.87,48.96,0.151
21.90,49.10,0.152
21.93,49.24,0.152
21.96,49.38,0.152
21.99,49.53,0.152
22.02,49.67,0.152
22.04,49.81,0.153
22.07,49.95,0.153
22.10,50.09,0.153
22.13,50.24,0.153
22.16,50.38,0.153
22.18,50.52,0.154
22.21,50.66,0.154
22.24,50.80,0.154
22.27,50.94,0.154
22.30,51.09,0.155
22.33,51.23,0.155
22.36,51.37,0.155
22.38,51.51,0.155
22.41,51.65,0.156
22.44,51.79,0.156
22.47,51.93,0.156
22.50,52.08,0.157
22.53,52.22,0.157
22.55,52.36,0.157
22.58,52.50,0.158
22.61,52.64,0.158
22.64,52.78,0.158
22.67,52.93,0.158
22.69,53.07,0.159
22.72,53.21,0.159
22.75,53.35,0.159
22.78,53.49,0.160
22.81,53.63,0.160
22.84,53.78,0.160
22.87,53.92,0.161
22.89,54.06,0.161
22.92,54.20,0.161
22.95,54.34,0.162
22.98,54.48,0.162
23.01,54.62,0.162
23.03,54.77,0.163
23.06,54.91,0.163
23.09,55.05,0.163
23.12,55.19,0.164
23.15,55.34,0.164
23.18,55.48,0.164
23.21,55.62,0.165
23.23,55.76,0.165
23.26,55.90,0.165
23.29,56.04,0.166
23.32,56.18,0.166
23.35,56.33,0.167
23.38,56.47,0.167
23.40,56.61,0.167
23.43,56.75,0.168
23.46,56.89,0.168
23.49,57.03,0.168
23.52,57.17,0.169
23.54,57.32,0.169
23.57,57.46,0.170
23.60,57.60,0.170
23.63,57.74,0.170
23.66,57.88,0.171
23.69,58.03,0.171
23.72,58.17,0.171
23.74,58.31,0.172
23.77,58.45,0.172
23.80,58.59,0.173
23.83,58.73,0.173
23.86,58.88,0.173
23.88,59.02,0.174
23.91,59.16,0.174
23.94,59.30,0.174
23.97,59.44,0.175
24.00,59.58,0.175
24.03,59.73,0.175
24.06,59.87,0.176
24.08,60.01,0.176
24.11,60.15,0.176
24.14,60.29,0.177
24.17,60.43,0.177
24.20,60.57,0.177
24.23,60.72,0.178
24.25,60.86,0.178
24.28,61.00,0.178
24.31,61.14,0.179
24.34,61.28,0.179
24.37,61.43,0.179
24.39,61.57,0.179
24.42,61.71,0.180
24.45,61.85,0.180
24.48,61.99,0.180
24.51,62.13,0.180
24.54,62.27,0.180
24.57,62.42,0.180
24.59,62.56,0.181
24.62,62.70,0.181
24.65,62.84,0.181
24.68,62.98,0.181
24.71,63.13,0.181
24.73,63.27,0.181
24.76,63.41,0.181
24.79,63.55,0.181
24.82,63.69,0.181
24.85,63.83,0.181
24.88,63.98,0.181
24.91,64.12,0.181
24.93,64.26,0.182
24.96,64.40,0.182
24.99,64.54,0.182
25.02,64.69,0.182
25.05,64.83,0.182
25.08,64.97,0.181
25.10,65.11,0.181
25.13,65.25,0.181
25.16,65.39,0.181
25.19,65.54,0.181
25.22,65.68,0.181
25.24,65.82,0.181
25.27,65.96,0.181
25.30,66.10,0.181
25.33,66.24,0.181
25.36,66.39,0.181
25.39,66.53,0.180
25.42,66.67,0.180
25.44,66.81,0.180
25.47,66.95,0.180
25.50,67.10,0.180
25.53,67.24,0.180
25.56,67.38,0.180
25.58,67.52,0.180
25.61,67.66,0.180
25.64,67.80,0.180
25.67,67.95,0.180
25.70,68.09,0.180
25.73,68.23,0.180
25.76,68.37,0.180
25.78,68.51,0.179
25.81,68.66,0.179
25.84,68.80,0.179
25.87,68.94,0.179
25.90,69.08,0.179
25.93,69.22,0.179
25.95,69.37,0.179
25.98,69.51,0.179
26.01,69.65,0.179
26.04,69.79,0.179
26.07,69.93,0.179
26.09,70.07,0.179
26.12,70.22,0.179
26.15,70.36,0.179
26.18,70.50,0.179
26.21,70.64,0.179
26.24,70.78,0.179
26.27,70.93,0.179
26.29,71.07,0.179
26.32,71.21,0.179
26.35,71.35,0.179
26.38,71.49,0.179
26.41,71.63,0.179
26.43,71.78,0.179
26.46,71.92,0.179
26.49,72.06,0.179
26.52,72.20,0.179
26.55,72.34,0.179
26.58,72.48,0.179
26.61,72.62,0.179
26.63,72.77,0.179
26.66,72.91,0.179
26.69,73.05,0.179
26.72,73.19,0.179
26.75,73.33,0.179
26.78,73.48,0.179
26.80,73.62,0.179
26.83,73.76,0.179
26.86,73.90,0.179
26.89,74.04,0.179
26.92,74.19,0.179
26.94,74.33,0.179
26.97,74.47,0.179
27.00,74.61,0.179
27.03,74.75,0.179
27.06,74.90,0.179
27.09,75.04,0.179
27.12,75.18,0.179
27.14,75.32,0.179
27.17,75.46,0.179
27.20,75.60,0.179
27.23,75.75,0.179
27.26,75.89,0.179
27.28,76.03,0.179
27.31,76.17,0.178
27.34,76.31,0.178
27.37,76.46,0.178
27.40,76.60,0.178
27.43,76.74,0.178
27.46,76.88,0.178
27.48,77.02,0.178
27.51,77.16,0.178
27.54,77.31,0.178
27.57,77.45,0.178
27.60,77.59,0.178
27.63,77.73,0.178
27.65,77.87,0.178
27.68,78.01,0.178
27.71,78.16,0.178
27.74,78.30,0.178
27.77,78.44,0.178
27.79,78.58,0.178
27.82,78.72,0.178
27.85,78.87,0.178
27.88,79.01,0.178
27.91,79.15,0.178
27.94,79.29,0.178
27.97,79.43,0.178
27.99,79.57,0.178
28.02,79.72,0.178
28.05,79.86,0.178
28.08,80.00,0.177
28.11,80.14,0.177
28.13,80.28,0.177
28.16,80.42,0.177
28.19,80.57,0.177
28.22,80.71,0.177
28.25,80.85,0.177
28.28,80.99,0.177
28.31,81.13,0.177
28.33,81.28,0.177
28.36,81.42,0.177
28.39,81.56,0.177
28.42,81.70,0.177
28.45,81.84,0.177
28.48,81.99,0.177
28.50,82.13,0.177
28.53,82.27,0.176
28.56,82.41,0.176
28.59,82.55,0.176
28.62,82.69,0.176
28.64,82.84,0.176
28.67,82.98,0.176
28.70,83.12,0.176
28.73,83.26,0.176
28.76,83.40,0.176
28.79,83.54,0.176
28.82,83.69,0.176
28.84,83.83,0.176
28.87,83.97,0.176
28.90,84.11,0.176
28.93,84.25,0.175
28.96,84.40,0.175
28.98,84.54,0.175
29.01,84.68,0.175
29.04,84.82,0.175
29.07,84.96,0.175
29.10,85.10,0.175
29.13,85.25,0.175
29.16,85.39,0.175
29.18,85.53,0.175
29.21,85.67,0.175
29.24,85.81,0.175
29.27,85.95,0.175
29.30,86.10,0.175
29.33,86.24,0.174
29.35,86.38,0.174
29.38,86.52,0.174
29.41,86.66,0.174
29.44,86.81,0.174
29.47,86.95,0.174
29.49,87.09,0.174
29.52,87.23,0.174
29.55,87.37,0.174
29.58,87.51,0.174
29.61,87.66,0.174
29.64,87.80,0.174
29.67,87.94,0.174
29.69,88.08,0.173
29.72,88.22,0.173
29.75,88.37,0.173
29.78,88.51,0.173
29.81,88.65,0.173
29.83,88.79,0.173
29.86,88.93,0.173
29.89,89.08,0.173
29.92,89.22,0.173
29.95,89.36,0.173
29.98,89.50,0.173
30.01,89.64,0.173
30.03,89.78,0.173
30.06,89.93,0.173
30.09,90.07,0.173
30.12,90.21,0.173
30.15,90.35,0.172
30.18,90.49,0.172
30.20,90.64,0.172
30.23,90.78,0.172
30.26,90.92,0.172
30.29,91.06,0.172
30.32,91.20,0.172
30.34,91.35,0.172
30.37,91.49,0.172
30.40,91.63,0.172
30.43,91.77,0.172
30.46,91.91,0.172
30.49,92.05,0.172
30.52,92.20,0.172
30.54,92.34,0.172
30.57,92.48,0.172
30.60,92.62,0.172
30.63,92.76,0.172
30.66,92.91,0.172
30.68,93.05,0.171
30.71,93.19,0.171
30.74,93.33,0.171
30.77,93.47,0.171
30.80,93.61,0.171
30.83,93.76,0.171
30.86,93.90,0.171
30.88,94.04,0.171
30.91,94.18,0.171
30.94,94.32,0.171
30.97,94.46,0.171
31.00,94.61,0.171
31.03,94.75,0.171
31.05,94.89,0.171
31.08,95.03,0.171
31.11,95.17,0.171
31.14,95.31,0.171
31.17,95.46,0.171
31.19,95.60,0.171
31.22,95.74,0.171
31.25,95.88,0.170
31.28,96.02,0.170
31.31,96.16,0.170
31.34,96.31,0.170
31.37,96.45,0.170
31.39,96.59,0.170
31.42,96.73,0.170
31.45,96.87,0.170
31.48,97.02,0.170
31.51,97.16,0.170
31.53,97.30,0.170
31.56,97.44,0.170
31.59,97.58,0.170
31.62,97.73,0.170
31.65,97.87,0.170
31.68,98.01,0.170
31.71,98.15,0.170
31.73,98.29,0.170
31.76,98.43,0.170
31.79,98.57,0.170
31.82,98.72,0.170
31.85,98.86,0.170
31.88,99.00,0.170
31.90,99.14,0.169
31.93,99.28,0.169
31.96,99.43,0.169
31.99,99.57,0.169
32.02,99.71,0.169
32.04,99.85,0.169
32.07,99.99,0.169
32.10,100.13,0.169
32.13,100.28,0.169
32.16,100.42,0.169
32.19,100.56,0.169
32.22,100.70,0.169
32.24,100.84,0.169
32.27,100.99,0.169
32.30,101.13,0.169
32.33,101.27,0.169
32.36,101.41,0.169
32.38,101.55,0.169
32.41,101.69,0.169
32.44,101.84,0.169
32.47,101.98,0.169
32.50,102.12,0.169
32.53,102.26,0.169
32.56,102.40,0.169
32.58,102.55,0.169
32.61,102.69,0.169
32.64,102.83,0.169
32.67,102.97,0.169
32.70,103.11,0.169
32.73,103.25,0.169
32.75,103.40,0.169
32.78,103.54,0.169
32.81,103.68,0.169
32.84,103.82,0.168
32.87,103.96,0.168
32.89,104.10,0.168
32.92,104.24,0.168
32.95,104.39,0.168
32.98,104.53,0.168
33.01,104.67,0.168
33.04,104.81,0.168
33.07,104.95,0.168
33.09,105.10,0.168
33.12,105.24,0.168
33.15,105.38,0.168
33.18,105.52,0.168
33.21,105.66,0.168
33.23,105.81,0.168
33.26,105.95,0.168
33.29,106.09,0.168
33.32,106.23,0.168
33.35,106.37,0.168
33.38,106.51,0.168
33.41,106.66,0.168
33.43,106.80,0.168
33.46,106.94,0.168
33.49,107.08,0.168
33.52,107.22,0.168
33.55,107.36,0.168
33.58,107.51,0.168
33.60,107.65,0.168
33.63,107.79,0.168
33.66,107.93,0.168
33.69,108.07,0.168
33.72,108.22,0.168
33.74,108.36,0.168
33.77,108.50,0.168
33.80,108.64,0.168
33.83,108.78,0.168
33.86,108.92,0.168
33.89,109.06,0.168
33.92,109.21,0.168
33.94,109.35,0.168
33.97,109.49,0.168
34.00,109.63,0.168
34.03,109.77,0.168
34.06,109.92,0.169
34.08,110.06,0.168
34.11,110.20,0.169
34.14,110.34,0.169
34.17,110.48,0.169
34.20,110.63,0.169
34.23,110.77,0.169
34.26,110.91,0.169
34.28,111.05,0.169
34.31,111.19,0.169
34.34,111.33,0.169
34.37,111.48,0.169
34.40,111.62,0.169
34.43,111.76,0.169
34.45,111.90,0.169
34.48,112.04,0.169
34.51,112.18,0.169
34.54,112.33,0.169
34.57,112.47,0.169
34.59,112.61,0.169
34.62,112.75,0.169
34.65,112.89,0.169
34.68,113.03,0.169
34.71,113.18,0.169
34.74,113.32,0.169
34.76,113.46,0.169
34.79,113.60,0.169
34.82,113.74,0.169
34.85,113.88,0.169
34.88,114.03,0.169
34.91,114.17,0.169
34.94,114.31,0.169
34.96,114.45,0.169
34.99,114.59,0.169
35.02,114.74,0.169
35.05,114.88,0.169
35.08,115.02,0.169
35.11,115.16,0.170
35.13,115.30,0.170
35.16,115.45,0.170
35.19,115.59,0.170
35.22,115.73,0.169
35.25,115.87,0.169
35.28,116.01,0.169
35.30,116.15,0.170
35.33,116.29,0.169
35.36,116.44,0.170
35.39,116.58,0.170
35.42,116.72,0.170
35.44,116.86,0.170
35.47,117.00,0.170
35.50,117.15,0.170
35.53,117.29,0.170
35.56,117.43,0.170
35.59,117.57,0.170
35.61,117.71,0.170
35.64,117.85,0.170
35.67,118.00,0.170
35.70,118.14,0.170
35.73,118.28,0.170
35.76,118.42,0.170
35.79,118.56,0.170
35.81,118.70,0.170
35.84,118.85,0.170
35.87,118.99,0.170
35.90,119.13,0.170
35.93,119.27,0.170
35.96,119.41,0.170
35.98,119.56,0.170
36.01,119.70,0.170
36.04,119.84,0.170
36.07,119.98,0.170
36.10,120.12,0.170
36.13,120.26,0.170
36.15,120.41,0.170
36.18,120.55,0.170
36.21,120.69,0.170
36.24,120.83,0.170
36.27,120.97,0.170
36.29,121.12,0.170
36.32,121.26,0.170
36.35,121.40,0.170
36.38,121.54,0.170
36.41,121.68,0.170
36.44,121.82,0.170
36.46,121.97,0.170
36.49,122.11,0.170
36.52,122.25,0.170
36.55,122.39,0.170
36.58,122.53,0.170
36.61,122.67,0.170
36.64,122.81,0.170
36.66,122.96,0.170
36.69,123.10,0.170
36.72,123.24,0.170
36.75,123.38,0.170
36.78,123.52,0.170
36.81,123.66,0.170
36.83,123.81,0.170
36.86,123.95,0.170
36.89,124.09,0.170
36.92,124.23,0.171
36.95,124.37,0.171
36.98,124.52,0.171
37.00,124.66,0.171
37.03,124.80,0.171
37.06,124.94,0.171
37.09,125.08,0.171
37.12,125.22,0.171
37.14,125.37,0.171
37.17,125.51,0.171
37.20,125.65,0.171
37.23,125.79,0.171
37.26,125.93,0.171
37.29,126.08,0.171
37.31,126.22,0.171
37.34,126.36,0.171
37.37,126.50,0.171
37.40,126.64,0.171
37.43,126.78,0.171
37.46,126.93,0.171
37.49,127.07,0.171
37.51,127.21,0.171
37.54,127.35,0.171
37.57,127.49,0.171
37.60,127.63,0.171
37.63,127.78,0.171
37.66,127.92,0.171
37.68,128.06,0.171
37.71,128.20,0.171
37.74,128.34,0.171
37.77,128.49,0.171
37.80,128.63,0.171
37.83,128.77,0.171
37.85,128.91,0.171
37.88,129.05,0.171
37.91,129.19,0.171
37.94,129.34,0.171
37.97,129.48,0.171
37.99,129.62,0.171
38.02,129.76,0.171
38.05,129.90,0.171
38.08,130.04,0.171
38.11,130.19,0.171
38.14,130.33,0.171
38.16,130.47,0.171
38.19,130.61,0.171
38.22,130.75,0.171
38.25,130.89,0.171
38.28,131.04,0.171
38.31,131.18,0.171
38.34,131.32,0.171
38.36,131.46,0.171
38.39,131.60,0.171
38.42,131.75,0.171
38.45,131.89,0.171
38.48,132.03,0.171
38.51,132.17,0.171
38.53,132.31,0.171
38.56,132.45,0.171
38.59,132.60,0.171
38.62,132.74,0.171
38.65,132.88,0.171
38.68,133.02,0.171
38.70,133.16,0.171
38.73,133.31,0.171
38.76,133.45,0.171
38.79,133.59,0.171
38.82,133.73,0.171
38.84,133.87,0.171
38.87,134.01,0.171
38.90,134.15,0.171
38.93,134.30,0.171
38.96,134.44,0.171
38.99,134.58,0.171
39.01,134.72,0.172
39.04,134.86,0.172
39.07,135.00,0.172
39.10,135.15,0.172
39.13,135.29,0.171
39.16,135.43,0.172
39.19,135.57,0.172
39.21,135.71,0.172
39.24,135.86,0.172
39.27,136.00,0.172
39.30,136.14,0.172
39.33,136.28,0.172
39.36,136.42,0.172
39.38,136.56,0.172
39.41,136.71,0.172
39.44,136.85,0.172
39.47,136.99,0.172
39.50,137.13,0.172
39.53,137.27,0.172
39.55,137.42,0.172
39.58,137.56,0.172
39.61,137.70,0.172
39.64,137.84,0.172
39.67,137.98,0.172
39.69,138.12,0.172
39.72,138.27,0.172
39.75,138.41,0.172
39.78,138.55,0.172
39.81,138.69,0.172
39.84,138.83,0.172
39.86,138.97,0.172
39.89,139.12,0.172
39.92,139.26,0.173
39.95,139.40,0.173
39.98,139.54,0.173
40.01,139.68,0.173
40.04,139.82,0.173
40.06,139.97,0.173
40.09,140.11,0.173
40.12,140.25,0.173
40.15,140.39,0.173
40.18,140.53,0.173
40.21,140.68,0.173
40.23,140.82,0.173
40.26,140.96,0.173
40.29,141.10,0.173
40.32,141.24,0.173
40.35,141.38,0.174
40.38,141.53,0.174
40.40,141.67,0.174
40.43,141.81,0.174
40.46,141.95,0.174
40.49,142.09,0.174
40.52,142.23,0.174
40.54,142.38,0.174
40.57,142.52,0.174
40.60,142.66,0.174
40.63,142.80,0.174
40.66,142.94,0.174
40.69,143.08,0.174
40.71,143.23,0.174
40.74,143.37,0.174
40.77,143.51,0.174
40.80,143.65,0.174
40.83,143.79,0.174
40.86,143.94,0.174
40.89,144.08,0.175
40.91,144.22,0.175
40.94,144.36,0.175
40.97,144.50,0.175
41.00,144.64,0.175
41.03,144.79,0.175
41.06,144.93,0.175
41.08,145.07,0.175
41.11,145.21,0.175
41.14,145.35,0.175
41.17,145.49,0.175
41.20,145.64,0.175
41.23,145.78,0.175
41.25,145.92,0.175
41.28,146.06,0.175
41.31,146.20,0.175
41.34,146.34,0.175
41.37,146.49,0.175
41.39,146.63,0.175
41.42,146.77,0.175
41.45,146.91,0.176
41.48,147.05,0.176
41.51,147.19,0.176
41.54,147.34,0.176
41.56,147.48,0.176
41.59,147.62,0.176
41.62,147.76,0.176
41.65,147.90,0.176
41.68,148.05,0.176
41.71,148.19,0.176
41.74,148.33,0.176
41.76,148.47,0.176
41.79,148.61,0.176
41.82,148.75,0.176
41.85,148.90,0.176
41.88,149.04,0.176
41.91,149.18,0.176
41.93,149.32,
41.96,149.46,
41.99,,

[step]
Ramp 5.00 °C/min to -60.00 °C
Time,Temperature,Heat Flow (Normalized)
min,°C,W/g
42.99,150.15,-0.035
43.01,150.15,-0.035
43.04,150.14,-0.035
43.07,150.11,-0.037
43.10,150.05,-0.065
43.13,149.96,-0.103
43.16,149.85,-0.142
43.19,149.74,-0.173
43.21,149.61,-0.193
43.24,149.49,-0.206
43.27,149.35,-0.216
43.30,149.22,-0.223
43.33,149.08,-0.227
43.36,148.95,-0.231
43.38,148.81,-0.233
43.41,148.67,-0.234
43.44,148.53,-0.235
43.47,148.39,-0.236
43.50,148.25,-0.237
43.53,148.11,-0.237
43.55,147.97,-0.238
43.58,147.83,-0.238
43.61,147.69,-0.238
43.64,147.55,-0.239
43.67,147.41,-0.239
43.69,147.27,-0.239
43.72,147.13,-0.239
43.75,146.98,-0.240
43.78,146.84,-0.240
43.81,146.70,-0.240
43.84,146.56,-0.240
43.86,146.42,-0.240
43.89,146.28,-0.240
43.92,146.14,-0.240
43.95,146.00,-0.240
43.98,145.86,-0.240
44.01,145.71,-0.241
44.04,145.57,-0.241
44.06,145.43,-0.241
44.09,145.29,-0.241
44.12,145.15,-0.241
44.15,145.01,-0.241
44.18,144.87,-0.241
44.21,144.72,-0.241
44.23,144.58,-0.241
44.26,144.44,-0.241
44.29,144.30,-0.241
44.32,144.16,-0.241
44.35,144.02,-0.241
44.38,143.88,-0.241
44.40,143.73,-0.241
44.43,143.59,-0.240
44.46,143.45,-0.240
44.49,143.31,-0.240
44.52,143.17,-0.240
44.54,143.03,-0.240
44.57,142.89,-0.240
44.60,142.75,-0.240
44.63,142.60,-0.240
44.66,142.46,-0.240
44.69,142.32,-0.240
44.71,142.18,-0.240
44.74,142.04,-0.240
44.77,141.89,-0.240
44.80,141.75,-0.240
44.83,141.61,-0.240
44.86,141.47,-0.239
44.89,141.33,-0.239
44.91,141.19,-0.239
44.94,141.04,-0.239
44.97,140.90,-0.239
45.00,140.76,-0.239
45.03,140.62,-0.239
45.06,140.48,-0.239
45.08,140.34,-0.239
45.11,140.19,-0.239
45.14,140.05,-0.239
45.17,139.91,-0.239
45.20,139.77,-0.239
45.23,139.63,-0.239
45.25,139.49,-0.239
45.28,139.35,-0.239
45.31,139.20,-0.239
45.34,139.06,-0.238
45.37,138.92,-0.238
45.39,138.78,-0.238
45.42,138.64,-0.238
45.45,138.49,-0.238
45.48,138.35,-0.238
45.51,138.21,-0.238
45.54,138.07,-0.238
45.56,137.93,-0.238
45.59,137.79,-0.238
45.62,137.65,-0.238
45.65,137.50,-0.238
45.68,137.36,-0.238
45.71,137.22,-0.238
45.74,137.08,-0.237
45.76,136.94,-0.237
45.79,136.80,-0.237
45.82,136.66,-0.237
45.85,136.51,-0.237
45.88,136.37,-0.237
45.91,136.23,-0.237
45.93,136.09,-0.237
45.96,135.94,-0.237
45.99,135.80,-0.237
46.02,135.66,-0.237
46.05,135.52,-0.237
46.08,135.38,-0.237
46.10,135.24,-0.237
46.13,135.09,-0.237
46.16,134.95,-0.237
46.19,134.81,-0.237
46.22,134.67,-0.236
46.24,134.53,-0.236
46.27,134.39,-0.236
46.30,134.24,-0.236
46.33,134.10,-0.236
46.36,133.96,-0.236
46.39,133.82,-0.236
46.41,133.68,-0.236
46.44,133.54,-0.236
46.47,133.40,-0.236
46.50,133.26,-0.236
46.53,133.11,-0.236
46.56,132.97,-0.236
46.59,132.83,-0.236
46.61,132.69,-0.236
46.64,132.55,-0.236
46.67,132.40,-0.236
46.70,132.26,-0.235
46.73,132.12,-0.235
46.76,131.98,-0.235
46.78,131.84,-0.235
46.81,131.70,-0.235
46.84,131.55,-0.235
46.87,131.41,-0.235
46.90,131.27,-0.235
46.93,131.13,-0.235
46.95,130.99,-0.235
46.98,130.85,-0.235
47.01,130.70,-0.235
47.04,130.56,-0.235
47.07,130.42,-0.235
47.09,130.28,-0.235
47.12,130.14,-0.235
47.15,129.99,-0.235
47.18,129.85,-0.234
47.21,129.71,-0.234
47.24,129.57,-0.234
47.26,129.43,-0.234
47.29,129.29,-0.234
47.32,129.15,-0.234
47.35,129.00,-0.234
47.38,128.86,-0.234
47.41,128.72,-0.234
47.44,128.58,-0.234
47.46,128.44,-0.234
47.49,128.30,-0.234
47.52,128.15,-0.234
47.55,128.01,-0.234
47.58,127.87,-0.234
47.61,127.73,-0.234
47.63,127.59,-0.234
47.66,127.44,-0.234
47.69,127.30,-0.234
47.72,127.16,-0.234
47.75,127.02,-0.233
47.78,126.88,-0.233
47.80,126.74,-0.233
47.83,126.59,-0.233
47.86,126.45,-0.233
47.89,126.31,-0.233
47.92,126.17,-0.233
47.94,126.03,-0.233
47.97,125.89,-0.233
48.00,125.75,-0.233
48.03,125.60,-0.233
48.06,125.46,-0.233
48.09,125.32,-0.233
48.11,125.18,-0.233
48.14,125.04,-0.233
48.17,124.90,-0.233
48.20,124.75,-0.233
48.23,124.61,-0.233
48.26,124.47,-0.233
48.29,124.33,-0.233
48.31,124.19,-0.233
48.34,124.05,-0.233
48.37,123.90,-0.233
48.40,123.76,-0.232
48.43,123.62,-0.232
48.46,123.48,-0.232
48.48,123.34,-0.232
48.51,123.20,-0.232
48.54,123.05,-0.232
48.57,122.91,-0.232
48.60,122.77,-0.232
48.63,122.63,-0.232
48.65,122.49,-0.232
48.68,122.35,-0.232
48.71,122.20,-0.232
48.74,122.06,-0.232
48.77,121.92,-0.232
48.79,121.78,-0.232
48.82,121.64,-0.232
48.85,121.50,-0.232
48.88,121.35,-0.231
48.91,121.21,-0.231
48.94,121.07,-0.231
48.96,120.93,-0.231
48.99,120.79,-0.231
49.02,120.64,-0.231
49.05,120.50,-0.231
49.08,120.36,-0.231
49.11,120.22,-0.231
49.14,120.08,-0.231
49.16,119.94,-0.231
49.19,119.80,-0.231
49.22,119.65,-0.231
49.25,119.51,-0.231
49.28,119.37,-0.231
49.31,119.23,-0.231
49.33,119.09,-0.231
49.36,118.94,-0.231
49.39,118.80,-0.231
49.42,118.66,-0.230
49.45,118.52,-0.230
49.48,118.38,-0.230
49.50,118.24,-0.230
49.53,118.10,-0.230
49.56,117.95,-0.230
49.59,117.81,-0.230
49.62,117.67,-0.230
49.64,117.53,-0.230
49.67,117.39,-0.230
49.70,117.25,-0.230
49.73,117.10,-0.230
49.76,116.96,-0.230
49.79,116.82,-0.230
49.81,116.68,-0.230
49.84,116.54,-0.230
49.87,116.40,-0.230
49.90,116.25,-0.229
49.93,116.11,-0.229
49.96,115.97,-0.229
49.99,115.83,-0.229
50.01,115.69,-0.229
50.04,115.54,-0.229
50.07,115.40,-0.229
50.10,115.26,-0.229
50.13,115.12,-0.229
50.16,114.98,-0.229
50.18,114.84,-0.229
50.21,114.69,-0.229
50.24,114.55,-0.229
50.27,114.41,-0.229
50.30,114.27,-0.229
50.33,114.13,-0.229
50.35,113.99,-0.229
50.38,113.85,-0.229
50.41,113.70,-0.229
50.44,113.56,-0.228
50.47,113.42,-0.229
50.49,113.28,-0.228
50.52,113.14,-0.228
50.55,112.99,-0.228
50.58,112.85,-0.228
50.61,112.71,-0.228
50.64,112.57,-0.228
50.66,112.43,-0.228
50.69,112.29,-0.228
50.72,112.15,-0.228
50.75,112.00,-0.228
50.78,111.86,-0.228
50.81,111.72,-0.228
50.84,111.58,-0.228
50.86,111.44,-0.228
50.89,111.29,-0.228
50.92,111.15,-0.228
50.95,111.01,-0.228
50.98,110.87,-0.228
51.01,110.73,-0.228
51.03,110.59,-0.228
51.06,110.44,-0.228
51.09,110.30,-0.227
51.12,110.16,-0.227
51.15,110.02,-0.227
51.18,109.88,-0.227
51.20,109.74,-0.227
51.23,109.59,-0.227
51.26,109.45,-0.227
51.29,109.31,-0.227
51.32,109.17,-0.227
51.34,109.03,-0.227
51.37,108.89,-0.227
51.40,108.74,-0.227
51.43,108.60,-0.227
51.46,108.46,-0.227
51.49,108.32,-0.227
51.51,108.18,-0.227
51.54,108.04,-0.227
51.57,107.89,-0.227
51.60,107.75,-0.227
51.63,107.61,-0.226
51.66,107.47,-0.226
51.69,107.33,-0.226
51.71,107.19,-0.226
51.74,107.04,-0.226
51.77,106.90,-0.226
51.80,106.76,-0.226
51.83,106.62,-0.226
51.86,106.48,-0.226
51.88,106.34,-0.226
51.91,106.20,-0.226
51.94,106.05,-0.226
51.97,105.91,-0.226
52.00,105.77,-0.226
52.03,105.63,-0.226
52.05,105.49,-0.225
52.08,105.35,-0.225
52.11,105.20,-0.225
52.14,105.06,-0.225
52.17,104.92,-0.225
52.19,104.78,-0.225
52.22,104.64,-0.225
52.25,104.49,-0.225
52.28,104.35,-0.225
52.31,104.21,-0.225
52.34,104.07,-0.225
52.36,103.93,-0.225
52.39,103.79,-0.225
52.42,103.64,-0.225
52.45,103.50,-0.225
52.48,103.36,-0.225
52.51,103.22,-0.225
52.54,103.08,-0.225
52.56,102.94,-0.225
52.59,102.79,-0.225
[...]
191.73,38.21,0.110,1.173
191.76,38.35,0.110,1.173
191.79,38.49,0.110,1.174
191.82,38.64,0.110,1.175
191.85,38.78,0.110,1.177
191.88,38.92,0.110,1.177
191.90,39.06,0.110,1.180
191.93,39.20,0.110,1.180
191.96,39.34,0.111,1.181
191.99,39.49,0.111,1.182
192.02,39.63,0.111,1.183
192.05,39.77,0.111,1.184
192.08,39.91,0.111,1.185
192.10,40.05,0.111,1.185
192.13,40.20,0.111,1.186
192.16,40.34,0.111,1.188
192.19,40.48,0.111,1.189
192.22,40.62,0.111,1.190
192.25,40.76,0.111,1.191
192.27,40.90,0.112,1.190
192.30,41.04,0.112,1.192
192.33,41.19,0.112,1.193
192.36,41.33,0.112,1.193
192.39,41.47,0.112,1.193
192.42,41.61,0.112,1.193
192.44,41.75,0.112,1.196
192.47,41.90,0.112,1.197
192.50,42.04,0.112,1.197
192.53,42.18,0.112,1.197
192.56,42.32,0.112,1.199
192.58,42.46,0.112,1.200
192.61,42.61,0.113,1.201
192.64,42.75,0.113,1.201
192.67,42.89,0.113,1.203
192.70,43.03,0.113,1.204
192.73,43.17,0.113,1.206
192.75,43.31,0.113,1.207
192.78,43.46,0.113,1.208
192.81,43.60,0.113,1.209
192.84,43.74,0.113,1.211
192.87,43.88,0.114,1.210
192.90,44.02,0.114,1.213
192.93,44.16,0.114,1.213
192.95,44.31,0.114,1.213
192.98,44.45,0.114,1.214
193.01,44.59,0.114,1.214
193.04,44.73,0.114,1.216
193.07,44.87,0.114,1.218
193.10,45.01,0.114,1.217
193.12,45.16,0.114,1.219
193.15,45.30,0.115,1.220
193.18,45.44,0.115,1.221
193.21,45.58,0.115,1.222
193.24,45.72,0.115,1.223
193.27,45.87,0.115,1.224
193.29,46.01,0.115,1.225
193.32,46.15,0.115,1.226
193.35,46.29,0.115,1.228
193.38,46.43,0.115,1.229
193.41,46.57,0.115,1.231
193.43,46.72,0.116,1.232
193.46,46.86,0.116,1.233
193.49,47.00,0.116,1.233
193.52,47.14,0.116,1.234
193.55,47.28,0.116,1.237
193.58,47.42,0.116,1.236
193.60,47.57,0.116,1.236
193.63,47.71,0.116,1.236
193.66,47.85,0.116,1.240
193.69,47.99,0.117,1.241
193.72,48.13,0.117,1.242
193.75,48.27,0.117,1.243
193.78,48.42,0.117,1.246
193.80,48.56,0.117,1.248
193.83,48.70,0.117,1.247
193.86,48.84,0.117,1.247
193.89,48.98,0.117,1.248
193.92,49.12,0.117,1.251
193.95,49.27,0.117,1.251
193.97,49.41,0.118,1.251
194.00,49.55,0.118,1.251
194.03,49.69,0.118,1.255
194.06,49.83,0.118,1.257
194.09,49.98,0.118,1.259
194.12,50.12,0.118,1.259
194.14,50.26,0.118,1.260
194.17,50.40,0.118,1.261
194.20,50.54,0.118,1.262
194.23,50.68,0.119,1.263
194.26,50.83,0.119,1.264
194.28,50.97,0.119,1.266
194.31,51.11,0.119,1.268
194.34,51.25,0.119,1.269
194.37,51.39,0.119,1.270
194.40,51.53,0.119,1.271
194.43,51.68,0.119,1.273
194.45,51.82,0.120,1.275
194.48,51.96,0.120,1.275
194.51,52.10,0.120,1.276
194.54,52.24,0.120,1.278
194.57,52.39,0.120,1.280
194.60,52.53,0.120,1.281
194.63,52.67,0.120,1.283
194.65,52.81,0.121,1.284
194.68,52.95,0.121,1.286
194.71,53.09,0.121,1.288
194.74,53.24,0.121,1.291
194.77,53.38,0.121,1.291
194.80,53.52,0.121,1.294
194.82,53.66,0.121,1.294
194.85,53.80,0.122,1.297
194.88,53.94,0.122,1.299
194.91,54.09,0.122,1.300
194.94,54.23,0.122,1.301
194.97,54.37,0.122,1.304
194.99,54.51,0.122,1.306
195.02,54.65,0.122,1.308
195.05,54.79,0.123,1.309
195.08,54.94,0.123,1.309
195.11,55.08,0.123,1.310
195.13,55.22,0.123,1.311
195.16,55.36,0.123,1.312
195.19,55.50,0.123,1.314
195.22,55.64,0.123,1.314
195.25,55.79,0.124,1.316
195.28,55.93,0.124,1.319
195.30,56.07,0.124,1.322
195.33,56.21,0.124,1.324
195.36,56.35,0.124,1.325
195.39,56.49,0.124,1.328
195.42,56.64,0.125,1.331
195.45,56.78,0.125,1.333
195.48,56.92,0.125,1.334
195.50,57.06,0.125,1.336
195.53,57.20,0.125,1.338
195.56,57.34,0.126,1.340
195.59,57.49,0.126,1.342
195.62,57.63,0.126,1.344
195.65,57.77,0.126,1.346
195.67,57.91,0.126,1.348
195.70,58.05,0.126,1.350
195.73,58.19,0.127,1.352
195.76,58.34,0.127,1.355
195.79,58.48,0.127,1.356
195.82,58.62,0.127,1.358
195.84,58.76,0.127,1.361
195.87,58.90,0.128,1.362
195.90,59.04,0.128,1.365
195.93,59.19,0.128,1.367
195.96,59.33,0.128,1.368
195.98,59.47,0.128,1.372
196.01,59.61,0.129,1.373
196.04,59.75,0.129,1.375
196.07,59.90,0.129,1.378
196.10,60.04,0.129,1.379
196.13,60.18,0.129,1.382
196.15,60.32,0.130,1.385
196.18,60.46,0.130,1.386
196.21,60.60,0.130,1.388
196.24,60.74,0.130,1.389
196.27,60.89,0.130,1.392
196.30,61.03,0.131,1.395
196.33,61.17,0.131,1.396
196.35,61.31,0.131,1.401
196.38,61.45,0.131,1.403
196.41,61.60,0.132,1.406
196.44,61.74,0.132,1.409
196.47,61.88,0.132,1.412
196.50,62.02,0.132,1.414
196.52,62.16,0.133,1.417
196.55,62.30,0.133,1.418
196.58,62.45,0.133,1.421
196.61,62.59,0.133,1.424
196.64,62.73,0.134,1.426
196.67,62.87,0.134,1.428
196.69,63.01,0.134,1.432
196.72,63.15,0.134,1.435
196.75,63.30,0.135,1.438
196.78,63.44,0.135,1.439
196.81,63.58,0.135,1.442
196.83,63.72,0.135,1.446
196.86,63.86,0.136,1.452
196.89,64.00,0.136,1.453
196.92,64.15,0.136,1.457
196.95,64.29,0.136,1.458
196.98,64.43,0.137,1.462
197.00,64.57,0.137,1.464
197.03,64.71,0.137,1.467
197.06,64.85,0.137,1.467
197.09,64.99,0.138,1.469
197.12,65.14,0.138,1.471
197.15,65.28,0.138,1.473
197.18,65.42,0.138,1.476
197.20,65.56,0.139,1.478
197.23,65.70,0.139,1.481
197.26,65.84,0.139,1.483
197.29,65.99,0.139,1.486
197.32,66.13,0.140,1.488
197.35,66.27,0.140,1.490
197.37,66.41,0.140,1.492
197.40,66.55,0.140,1.495
197.43,66.70,0.141,1.498
197.46,66.84,0.141,1.501
197.49,66.98,0.141,1.503
197.52,67.12,0.141,1.506
197.54,67.26,0.141,1.509
197.57,67.40,0.142,1.511
197.60,67.55,0.142,1.513
197.63,67.69,0.142,1.514
197.66,67.83,0.142,1.514
197.68,67.97,0.142,1.516
197.71,68.11,0.142,1.517
197.74,68.25,0.142,1.518
197.77,68.40,0.142,1.518
197.80,68.54,0.143,1.519
197.83,68.68,0.143,1.520
197.85,68.82,0.143,1.521
197.88,68.96,0.143,1.521
197.91,69.11,0.143,1.523
197.94,69.25,0.143,1.525
197.97,69.39,0.143,1.526
198.00,69.53,0.143,1.527
198.03,69.67,0.143,1.527
198.05,69.81,0.143,1.528
198.08,69.96,0.143,1.527
198.11,70.10,0.143,1.528
198.14,70.24,0.143,1.528
198.17,70.38,0.143,1.527
198.20,70.52,0.143,1.528
198.22,70.66,0.143,1.528
198.25,70.81,0.143,1.528
198.28,70.95,0.143,1.528
198.31,71.09,0.143,1.527
198.34,71.23,0.143,1.527
198.37,71.37,0.143,1.528
198.39,71.52,0.143,1.528
198.42,71.66,0.143,1.528
198.45,71.80,0.143,1.527
198.48,71.94,0.143,1.526
198.51,72.08,0.143,1.527
198.53,72.22,0.143,1.527
198.56,72.37,0.143,1.526
198.59,72.51,0.143,1.526
198.62,72.65,0.143,1.527
198.65,72.79,0.143,1.526
198.68,72.93,0.143,1.526
198.70,73.08,0.143,1.525
198.73,73.22,0.143,1.524
198.76,73.36,0.143,1.524
198.79,73.50,0.143,1.523
198.82,73.64,0.143,1.522
198.85,73.78,0.143,1.524
198.88,73.93,0.143,1.524
198.90,74.07,0.143,1.523
198.93,74.21,0.143,1.523
198.96,74.35,0.143,1.523
198.99,74.49,0.143,1.524
199.02,74.63,0.143,1.524
199.05,74.78,0.143,1.523
199.07,74.92,0.143,1.524
199.10,75.06,0.143,1.526
199.13,75.20,0.143,1.526
199.16,75.34,0.143,1.526
199.19,75.49,0.143,1.525
199.22,75.63,0.143,1.526
199.24,75.77,0.143,1.527
199.27,75.91,0.143,1.526
199.30,76.05,0.143,1.527
199.33,76.19,0.143,1.526
199.36,76.34,0.143,1.527
199.38,76.48,0.143,1.525
199.41,76.62,0.143,1.525
199.44,76.76,0.143,1.525
199.47,76.90,0.143,1.524
199.50,77.04,0.143,1.524
199.53,77.19,0.143,1.525
199.55,77.33,0.143,1.525
199.58,77.47,0.143,1.527
199.61,77.61,0.143,1.527
199.64,77.75,0.143,1.527
199.67,77.90,0.143,1.528
199.70,78.04,0.143,1.529
199.73,78.18,0.143,1.529
199.75,78.32,0.144,1.530
199.78,78.46,0.144,1.531
199.81,78.61,0.144,1.533
199.84,78.75,0.144,1.533
199.87,78.89,0.144,1.533
199.90,79.03,0.144,1.533
199.92,79.17,0.144,1.533
199.95,79.31,0.144,1.532
199.98,79.46,0.144,1.531
200.01,79.60,0.144,1.530
200.04,79.74,0.144,1.530
200.07,79.88,0.144,1.531
200.09,80.02,0.144,1.533
200.12,80.17,0.144,1.532
200.15,80.31,0.144,1.533
200.18,80.45,0.144,1.535
200.21,80.59,0.144,1.536
200.23,80.73,0.144,1.537
200.26,80.87,0.144,1.538
200.29,81.02,0.144,1.540
200.32,81.16,0.144,1.540
200.35,81.30,0.144,1.541
200.38,81.44,0.144,1.543
200.40,81.58,0.144,1.543
200.43,81.72,0.144,1.543
200.46,81.86,0.144,1.542
200.49,82.01,0.144,1.542
200.52,82.15,0.144,1.541
200.55,82.29,0.144,1.541
200.58,82.43,0.144,1.540
200.60,82.57,0.144,1.541
200.63,82.72,0.145,1.540
200.66,82.86,0.145,1.540
200.69,83.00,0.145,1.541
200.72,83.14,0.145,1.543
200.75,83.28,0.145,1.542
200.77,83.42,0.145,1.543
200.80,83.57,0.145,1.544
200.83,83.71,0.145,1.546
200.86,83.85,0.145,1.548
200.89,83.99,0.145,1.548
200.92,84.13,0.145,1.548
200.94,84.27,0.145,1.549
200.97,84.42,0.145,1.549
201.00,84.56,0.145,1.550
201.03,84.70,0.145,1.549
201.06,84.84,0.145,1.548
201.08,84.98,0.145,1.549
201.11,85.12,0.145,1.548
201.14,85.27,0.145,1.548
201.17,85.41,0.145,1.549
201.20,85.55,0.145,1.548
201.23,85.69,0.145,1.548
201.25,85.83,0.145,1.549
201.28,85.97,0.145,1.549
201.31,86.12,0.145,1.550
201.34,86.26,0.145,1.551
201.37,86.40,0.145,1.553
201.40,86.54,0.146,1.553
201.43,86.69,0.146,1.554
201.45,86.83,0.146,1.555
201.48,86.97,0.146,1.556
201.51,87.11,0.146,1.555
201.54,87.25,0.146,1.553
201.57,87.39,0.146,1.553
201.60,87.54,0.146,1.552
201.62,87.68,0.146,1.552
201.65,87.82,0.146,1.554
201.68,87.96,0.146,1.555
201.71,88.10,0.146,1.558
201.74,88.25,0.146,1.560
201.77,88.39,0.146,1.562
201.79,88.53,0.146,1.563
201.82,88.67,0.146,1.565
201.85,88.81,0.146,1.563
201.88,88.95,0.146,1.563
201.91,89.10,0.146,1.561
201.93,89.24,0.146,1.562
201.96,89.38,0.146,1.561
201.99,89.52,0.146,1.561
202.02,89.66,0.146,1.561
202.05,89.80,0.146,1.562
202.08,89.95,0.147,1.562
202.10,90.09,0.147,1.563
202.13,90.23,0.147,1.563
202.16,90.37,0.147,1.565
202.19,90.51,0.147,1.567
202.22,90.65,0.147,1.567
202.25,90.80,0.147,1.566
202.28,90.94,0.147,1.567
202.30,91.08,0.147,1.567
202.33,91.22,0.147,1.568
202.36,91.37,0.147,1.567
202.39,91.51,0.147,1.568
202.42,91.65,0.147,1.569
202.45,91.79,0.147,1.570
202.47,91.93,0.147,1.570
202.50,92.07,0.147,1.571
202.53,92.21,0.147,1.571
202.56,92.36,0.147,1.571
202.59,92.50,0.147,1.571
202.62,92.64,0.147,1.571
202.64,92.78,0.148,1.573
202.67,92.92,0.148,1.573
202.70,93.07,0.148,1.574
202.73,93.21,0.148,1.574
202.76,93.35,0.148,1.575
202.78,93.49,0.148,1.576
202.81,93.63,0.148,1.577
202.84,93.77,0.148,1.577
202.87,93.92,0.148,1.578
202.90,94.06,0.148,1.578
202.93,94.20,0.148,1.578
202.95,94.34,0.148,1.579
202.98,94.48,0.148,1.579
203.01,94.63,0.148,1.579
203.04,94.77,0.148,1.580
203.07,94.91,0.148,1.580
203.10,95.05,0.148,1.581
203.13,95.19,0.148,1.581
203.15,95.33,0.148,1.581
203.18,95.47,0.148,1.581
203.21,95.62,0.148,1.581
203.24,95.76,0.148,1.580
203.27,95.90,0.148,1.580
203.30,96.04,0.148,1.581
203.32,96.18,0.148,1.582
203.35,96.33,0.149,1.584
203.38,96.47,0.149,1.585
203.41,96.61,0.149,1.585
203.44,96.75,0.149,1.586
203.47,96.89,0.149,1.587
203.49,97.03,0.149,1.585
203.52,97.17,0.149,1.586
203.55,97.32,0.149,1.586
203.58,97.46,0.149,1.585
203.61,97.60,0.149,1.587
203.63,97.74,0.149,1.588
203.66,97.88,0.149,1.587
203.69,98.03,0.149,1.589
203.72,98.17,0.149,1.589
203.75,98.31,0.149,1.589
203.78,98.45,0.149,1.590
203.80,98.59,0.149,1.590
203.83,98.73,0.149,1.589
203.86,98.88,0.149,1.590
203.89,99.02,0.149,1.590
203.92,99.16,0.149,1.592
203.95,99.30,0.149,1.592
203.98,99.44,0.150,1.592
204.00,99.58,0.150,1.593
204.03,99.73,0.150,1.595
204.06,99.87,0.150,1.595
204.09,100.01,0.150,1.596
204.12,100.15,0.150,1.596
204.15,100.29,0.150,1.596
204.17,100.43,0.150,1.595
204.20,100.58,0.150,1.596
204.23,100.72,0.150,1.596
204.26,100.86,0.150,1.596
204.29,101.00,0.150,1.597
204.32,101.14,0.150,1.596
204.34,101.28,0.150,1.597
204.37,101.43,0.150,1.598
204.40,101.57,0.150,1.597
204.43,101.71,0.150,1.597
204.46,101.85,0.150,1.598
204.48,101.99,0.150,1.598
204.51,102.14,0.150,1.599
204.54,102.28,0.150,1.600
204.57,102.42,0.150,1.600
204.60,102.56,0.150,1.601
204.63,102.70,0.150,1.602
204.65,102.84,0.150,1.601
204.68,102.99,0.151,1.601
204.71,103.13,0.151,1.603
204.74,103.27,0.151,1.603
204.77,103.41,0.151,1.604
204.80,103.55,0.151,1.604
204.83,103.70,0.151,1.604
204.85,103.84,0.151,1.606
204.88,103.98,0.151,1.606
204.91,104.12,0.151,1.606
204.94,104.26,0.151,1.606
204.97,104.40,0.151,1.607
205.00,104.55,0.151,1.607
205.02,104.69,0.151,1.608
205.05,104.83,0.151,1.609
205.08,104.97,0.151,1.610
205.11,105.11,0.151,1.609
205.14,105.25,0.151,1.608
205.17,105.40,0.151,1.608
205.19,105.54,0.151,1.609
205.22,105.68,0.151,1.608
205.25,105.82,0.151,1.608
205.28,105.96,0.151,1.608
205.31,106.10,0.151,1.608
205.33,106.25,0.151,1.611
205.36,106.39,0.151,1.611
205.39,106.53,0.151,1.611
205.42,106.67,0.151,1.612
205.45,106.81,0.151,1.612
205.48,106.95,0.152,1.613
205.50,107.10,0.152,1.613
205.53,107.24,0.152,1.612
205.56,107.38,0.152,1.613
205.59,107.52,0.152,1.614
205.62,107.66,0.152,1.615
205.65,107.81,0.152,1.615
205.68,107.95,0.152,1.617
205.70,108.09,0.152,1.616
205.73,108.23,0.152,1.617
205.76,108.37,0.152,1.616
205.79,108.51,0.152,1.617
205.82,108.66,0.152,1.616
205.85,108.80,0.152,1.617
205.87,108.94,0.152,1.619
205.90,109.08,0.152,1.620
205.93,109.22,0.152,1.619
205.96,109.37,0.152,1.621
205.99,109.51,0.152,1.621
206.02,109.65,0.152,1.621
206.04,109.79,0.152,1.622
206.07,109.93,0.152,1.620
206.10,110.07,0.152,1.621
206.13,110.21,0.152,1.622
206.16,110.36,0.152,1.621
206.18,110.50,0.153,1.622
206.21,110.64,0.153,1.621
206.24,110.78,0.153,1.621
206.27,110.92,0.153,1.622
206.30,111.07,0.153,1.622
206.33,111.21,0.153,1.623
206.35,111.35,0.153,1.623
206.38,111.49,0.153,1.622
206.41,111.63,0.153,1.623
206.44,111.77,0.153,1.624
206.47,111.92,0.153,1.624
206.50,112.06,0.153,1.626
206.53,112.20,0.153,1.625
206.55,112.34,0.153,1.627
206.58,112.48,0.153,1.627
206.61,112.62,0.153,1.628
206.64,112.77,0.153,1.626
206.67,112.91,0.153,1.627
206.70,113.05,0.153,1.627
206.72,113.19,0.153,1.627
206.75,113.33,0.153,1.628
206.78,113.48,0.153,1.628
206.81,113.62,0.153,1.630
206.84,113.76,0.153,1.631
206.87,113.90,0.154,1.631
206.89,114.04,0.154,1.632
206.92,114.18,0.154,1.631
206.95,114.33,0.154,1.631
206.98,114.47,0.154,1.632
207.01,114.61,0.154,1.632
207.03,114.75,0.154,1.634
207.06,114.89,0.154,1.634
207.09,115.04,0.154,1.635
207.12,115.18,0.154,1.637
207.15,115.32,0.154,1.636
207.18,115.46,0.154,1.636
207.20,115.60,0.154,1.636
207.23,115.74,0.154,1.636
207.26,115.88,0.154,1.637
207.29,116.03,0.154,1.637
207.32,116.17,0.154,1.637
207.35,116.31,0.154,1.638
207.38,116.45,0.154,1.638
207.40,116.59,0.154,1.638
207.43,116.73,0.154,1.638
207.46,116.88,0.154,1.639
207.49,117.02,0.154,1.640
207.52,117.16,0.154,1.639
207.55,117.30,0.154,1.638
207.57,117.44,0.154,1.640
207.60,117.59,0.154,1.641
207.63,117.73,0.154,1.641
207.66,117.87,0.154,1.640
207.69,118.01,0.154,1.640
207.72,118.15,0.155,1.640
207.74,118.29,0.155,1.641
207.77,118.44,0.155,1.641
207.80,118.58,0.155,1.641
207.83,118.72,0.155,1.642
207.86,118.86,0.155,1.643
207.88,119.00,0.155,1.644
207.91,119.15,0.155,1.645
207.94,119.29,0.155,1.647
207.97,119.43,0.155,1.648
208.00,119.57,0.155,1.649
208.03,119.71,0.155,1.647
208.05,119.85,0.155,1.646
208.08,119.99,0.155,1.647
208.11,120.14,0.155,1.646
208.14,120.28,0.155,1.645
208.17,120.42,0.155,1.645
208.20,120.56,0.155,1.645
208.23,120.70,0.155,1.647
208.25,120.85,0.155,1.648
208.28,120.99,0.155,1.649
208.31,121.13,0.155,1.651
208.34,121.27,0.155,1.653
208.37,121.41,0.155,1.652
208.40,121.56,0.156,1.652
208.42,121.70,0.156,1.652
208.45,121.84,0.156,1.652
208.48,121.98,0.156,1.651
208.51,122.12,0.156,1.651
208.54,122.26,0.156,1.652
208.57,122.41,0.156,1.651
208.59,122.55,0.156,1.652
208.62,122.69,0.156,1.653
208.65,122.83,0.156,1.654
208.68,122.97,0.156,1.655
208.71,123.12,0.156,1.656
208.73,123.26,0.156,1.656
208.76,123.40,0.156,1.658
208.79,123.54,0.156,1.658
208.82,123.68,0.156,1.658
208.85,123.82,0.156,1.657
208.88,123.96,0.156,1.657
208.90,124.11,0.156,1.656
208.93,124.25,0.156,1.656
208.96,124.39,0.156,1.655
208.99,124.53,0.156,1.656
209.02,124.67,0.156,1.655
209.05,124.81,0.156,1.655
209.08,124.96,0.156,1.656
209.10,125.10,0.156,1.656
209.13,125.24,0.156,1.656
209.16,125.38,0.156,1.657
209.19,125.52,0.156,1.657
209.22,125.67,0.156,1.659
209.25,125.81,0.156,1.660
209.27,125.95,0.157,1.660
209.30,126.09,0.157,1.663
209.33,126.23,0.157,1.664
209.36,126.37,0.157,1.666
209.39,126.52,0.157,1.665
209.42,126.66,0.157,1.665
209.44,126.80,0.157,1.664
209.47,126.94,0.157,1.664
209.50,127.08,0.157,1.664
209.53,127.22,0.157,1.662
209.56,127.37,0.157,1.662
209.58,127.51,0.157,1.661
209.61,127.65,0.157,1.662
209.64,127.79,0.157,1.662
209.67,127.93,0.157,1.663
209.70,128.08,0.157,1.665
209.73,128.22,0.157,1.667
209.75,128.36,0.157,1.669
209.78,128.50,0.157,1.671
209.81,128.64,0.157,1.672
209.84,128.78,0.157,1.672
209.87,128.93,0.157,1.671
209.90,129.07,0.157,1.671
209.93,129.21,0.157,1.670
209.95,129.35,0.157,1.670
209.98,129.49,0.157,1.670
210.01,129.63,0.157,1.669
210.04,129.78,0.158,1.670
210.07,129.92,0.158,1.672
210.10,130.06,0.158,1.671
210.12,130.20,0.158,1.672
210.15,130.34,0.158,1.672
210.18,130.48,0.158,1.674
210.21,130.63,0.158,1.673
210.24,130.77,0.158,1.675
210.27,130.91,0.158,1.674
210.29,131.05,0.158,1.675
210.32,131.19,0.158,1.675
210.35,131.34,0.158,1.675
210.38,131.48,0.158,1.672
210.41,131.62,0.158,1.673
210.43,131.76,0.158,1.673
210.46,131.90,0.158,1.672
210.49,132.04,0.158,1.674
210.52,132.19,0.158,1.674
210.55,132.33,0.158,1.673
210.58,132.47,0.158,1.675
210.60,132.61,0.158,1.675
210.63,132.75,0.158,1.676
210.66,132.89,0.158,1.678
210.69,133.04,0.158,1.678
210.72,133.18,0.158,1.679
210.75,133.32,0.158,1.679
210.78,133.46,0.158,1.680
210.80,133.60,0.158,1.680
210.83,133.74,0.159,1.681
210.86,133.89,0.159,1.680
210.89,134.03,0.159,1.682
210.92,134.17,0.159,1.682
210.95,134.31,0.159,1.683
210.97,134.45,0.159,1.682
211.00,134.59,0.159,1.682
211.03,134.74,0.159,1.681
211.06,134.88,0.159,1.681
211.09,135.02,0.159,1.679
211.12,135.16,0.159,1.680
211.14,135.30,0.159,1.680
211.17,135.45,0.159,1.680
211.20,135.59,0.159,1.681
211.23,135.73,0.159,1.682
211.26,135.87,0.159,1.683
211.28,136.01,0.159,1.684
211.31,136.15,0.159,1.686
211.34,136.30,0.159,1.686
211.37,136.44,0.159,1.686
211.40,136.58,0.159,1.685
211.43,136.72,0.159,1.684
211.45,136.86,0.159,1.683
211.48,137.00,0.159,1.683
211.51,137.15,0.159,1.681
211.54,137.29,0.159,1.682
211.57,137.43,0.159,1.684
211.60,137.57,0.159,1.685
211.63,137.71,0.159,1.686
211.65,137.85,0.159,1.686
211.68,138.00,0.159,1.686
211.71,138.14,0.159,1.687
211.74,138.28,0.159,1.686
211.77,138.42,0.159,1.686
211.80,138.56,0.159,1.685
211.82,138.70,0.159,1.686
211.85,138.85,0.159,1.685
211.88,138.99,0.159,1.687
211.91,139.13,0.159,1.688
211.94,139.27,0.159,1.689
211.97,139.41,0.159,1.687
211.99,139.56,0.160,1.688
212.02,139.70,0.160,1.689
212.05,139.84,0.160,1.692
212.08,139.98,0.160,1.690
212.11,140.12,0.160,1.690
212.13,140.26,0.160,1.689
212.16,140.41,0.160,1.690
212.19,140.55,0.160,1.690
212.22,140.69,0.160,1.690
212.25,140.83,0.160,1.688
212.28,140.97,0.160,1.690
212.30,141.12,0.160,1.691
212.33,141.26,0.160,1.692
212.36,141.40,0.160,1.692
212.39,141.54,0.160,1.693
212.42,141.68,0.160,1.695
212.45,141.82,0.160,1.695
212.48,141.97,0.160,1.693
212.50,142.11,0.160,1.695
212.53,142.25,0.160,1.693
212.56,142.39,0.160,1.694
212.59,142.53,0.160,1.695
212.62,142.68,0.160,1.696
212.65,142.82,0.160,1.697
212.67,142.96,0.160,1.697
212.70,143.10,0.160,1.699
212.73,143.24,0.160,1.699
212.76,143.38,0.160,1.697
212.79,143.52,0.160,1.696
212.82,143.67,0.160,1.695
212.84,143.81,0.160,1.694
212.87,143.95,0.160,1.694
212.90,144.09,0.160,1.694
212.93,144.23,0.160,1.694
212.96,144.37,0.161,1.696
212.98,144.52,0.161,1.696
213.01,144.66,0.161,1.698
213.04,144.80,0.161,1.700
213.07,144.94,0.161,1.701
213.10,145.08,0.161,1.704
213.13,145.23,0.161,1.704
213.15,145.37,0.161,1.705
213.18,145.51,0.161,1.703
213.21,145.65,0.161,1.703
213.24,145.79,0.161,1.702
213.27,145.93,0.161,1.702
213.30,146.08,0.161,1.700
213.33,146.22,0.161,1.700
213.35,146.36,0.161,1.701
213.38,146.50,0.161,1.703
213.41,146.64,0.161,1.704
213.44,146.78,0.161,1.704
213.47,146.93,0.161,1.704
213.50,147.07,0.161,1.705
213.52,147.21,0.161,1.706
213.55,147.35,0.161,1.705
213.58,147.49,0.161,1.704
213.61,147.64,0.161,1.703
213.64,147.78,0.161,1.704
213.67,147.92,0.161,1.704
213.69,148.06,0.161,1.704
213.72,148.20,0.161,1.704
213.75,148.34,0.161,1.704
213.78,148.48,0.161,1.706
213.81,148.63,0.162,1.707
213.83,148.77,0.162,1.706
213.86,148.91,0.162,1.705
213.89,149.05,0.162,
213.92,149.20,0.162,
213.95,149.34,,
213.98,149.48,,
213.98,,,