File: DSC/Earl/2025_10_04_Benzoic_Acid_5Cmin_n60C_150C_x3.csv
Filename,2025_10_04_Benzoic_Acid_5Cmin_n60C_150C_x3
Instrument name,DSC2A-00468 (192.168.1.100)
Operator,JLY
rundate,10/5/2025
Sample name,2025_10_04_Benzoic_Acid_5Cmin_n60C_150C_x3
proceduresegments,Data Off ; Equilibrate -60.00 °C; Data On ; Ramp 5.00 °C/min to 150.00 °C; Data Off ; Isothermal 1.0 min; Data On ; Ramp 5.00 °C/min to -60.00 °C; Data Off ; Isothermal 1.0 min; Data On ; Ramp 5.00 °C/min to 150.00 °C; Data Off ; Isothermal 1.0 min; Data On ; Ramp 5.00 °C/min to -60.00 °C; Data Off ; Isothermal 1.0 min; Data On ; Ramp 5.00 °C/min to 150.00 °C
[File Parameters]
Run date,10/5/2025 9:46:17 AM
Trios version,5.1.1.46572
Original File Name,
Current File Name,D:\DSC2500\JYarger\2025_10_04_Benzoic_Acid_5Cmin_n60C_150C_x3.tri
[Procedure]
Procedure Name,BA_n60C_150C_5Cmin_3
Sample Name,2025_10_04_Benzoic_Acid_5Cmin_n60C_150C_x3
Sample Mass,13.64 mg
Reference Sample Mass,0 mg
Pan Mass,32.7 mg
Pan Number,4
Reference Pan Mass,32.55 mg
Reference Pan Number,1
Pan Type,Aluminum
Comments,DSC_Samples_Y2_Tray_ASDs_Pharma_Oct2025 Google Sheet.
Project Name,Amorphous Pharma
Operator,JLY
Test,Custom
Unload Max Temperature,30
Unload Min Temperature,30
Load Max Temperature,30
Load Min Temperature,30
Stop on Gas Flow Error,Yes
[Signal List]
Signal #1,Time (min)
Signal #2,Temperature (°C)
Signal #3,Heat Flow (mW)
Signal #4,Delta T (µV)
Signal #5,Delta Tzero (µV)
Signal #6,Tzero Temperature (°C)
Signal #7,Cell Purge (mL/min)
Signal #8,Heater Temp (°C)
Signal #9,Power Delivered (W)
Signal #10,Reference Junction Temperature (°C)
Signal #11,Flange Temperature (°C)
Signal #12,Heat Flow Phase (rad)
Signal #13,Total Heat Capacity (J/°C)
Signal #14,Heat Capacity (J/°C)
[Configuration]
Company Name,ASU
Instrument Name,DSC2A-00468
Instrument Type,DSC2500
Serial Number,DSC2A-00468
IP,192.168.1.100
Location of Instrument,MRRC
DisplayType,Unknown
Sample Interval ,0.1 s/pt
Selected Heat Flow,T4P
Exotherm Direction,Down
Cell Serial,DRC2-00792
Lid Type,Standard
Cooler,RCS 90
Leave Cooler on at End of Sequence,On
Gas 2,Nitrogen
Gas Selected,Channel 1
Flow Rate,50 mL/min
Secondary Purge,On
Licensed Heat Flow,Heat Flow T4P
Modulation Licensed,Yes
[Versions]
Common IDD Version,1
Cortex Version,VER 2.10.2.31
Driver,5.0.0.6
GDM Version,1.0.3.3
TouchscreenVersion,1.0.0.16145
FEP Version,1.2.1.21
FEP Bootloader,2.0.0.5
AutoSampler Version,2.1.1.26
Auto Sampler Bootloader,2.0.0.5
FCM Version,1.1.0.3
FCM Bootloader,2.0.0.5
[Experiment Logs]
Experiment Log Entry # 1,Data On set to 0
Experiment Log Entry # 3,Equilibrate Segment -60 (C) Started
Experiment Log Entry # 5,Air Cool is off.
Experiment Log Entry # 7,Data On set to 1
Experiment Log Entry # 9,Ramp Segment 5 C/min to 150 Started
Experiment Log Entry # 11,Data On set to 0
Experiment Log Entry # 13,Isothermal Segment 1 min started
Experiment Log Entry # 15,Data On set to 1
Experiment Log Entry # 17,Ramp Segment 5 C/min to -60 Started
Experiment Log Entry # 19,Data On set to 0
Experiment Log Entry # 21,Isothermal Segment 1 min started
Experiment Log Entry # 23,Data On set to 1
Experiment Log Entry # 25,Ramp Segment 5 C/min to 150 Started
Experiment Log Entry # 27,Data On set to 0
Experiment Log Entry # 29,Isothermal Segment 1 min started
Experiment Log Entry # 31,Data On set to 1
Experiment Log Entry # 33,Ramp Segment 5 C/min to -60 Started
Experiment Log Entry # 35,Ramp Segment 5 C/min to 30 Started
Experiment Log Entry # 37,User modified running procedure
Experiment Log Entry # 39,Ending Experiment because user stopped
[Method Log]
Method Log Entry # 1,Data Off
Method Log Entry # 2,Equilibrate -60 °C
Method Log Entry # 3,Data On
Method Log Entry # 4,(Ramp 198916) Ramp 5 °C/minute to 150 °C
Method Log Entry # 5,Data Off
Method Log Entry # 6,Isothermal 1 minutes
Method Log Entry # 7,Data On
Method Log Entry # 8,(Ramp 198920) Ramp 5 °C/minute to -60 °C
Method Log Entry # 9,Data Off
Method Log Entry # 10,Isothermal 1 minutes
Method Log Entry # 11,Data On
Method Log Entry # 12,(Ramp 198924) Ramp 5 °C/minute to 150 °C
Method Log Entry # 13,Data Off
Method Log Entry # 14,Isothermal 1 minutes
Method Log Entry # 15,Data On
Method Log Entry # 16,(Ramp 198928) Ramp 5 °C/minute to 30 °C
Cell Serial,DRC2-00792
[T1 Calibration]
Slope,-0.008529666
Offset,9.636258
Initial Temperature,98.23
GUID,f8bfdadc-4977-4fdf-ba6d-0ba9134940c3
[TZero Calibration]
Date Applied,11/29/2022 4:06:13 PM
Description,From -89.059 °C to 396.009 °C at 20.000°C/min
Gas Type,Nitrogen
Pan Type,None
Source Files 1,C:\Users\yargerlab\Desktop\DSC Data\General\TZero_calibration_11_29_22_2nd(2).tri
Source Files 2,C:\Users\yargerlab\Desktop\DSC Data\General\TZero_calibration_11_29_22_2nd(3).tri
Delta T Offset,13.05235
Delta T Slope,-0.007271007
Delta T0 Offset,-13.69128
Delta T0 Slope,0.06063341
[Temperature Calibration]
Date Applied,11/29/2022 7:12:28 PM
Description,From 106.590 °C to 186.590 °C at 10.000°C/min
Gas Type,Nitrogen
Pan Type,Tzero Aluminum Hermetic
Source Files 1,C:\Users\yargerlab\Desktop\DSC Data\General\Indium(6).tri
Measured 1,157.391
Known 1,156.598
[Cell Constant Calibration]
Date Applied,11/29/2022 7:12:29 PM
Description,From 106.590 °C to 186.590 °C at 10.000°C/min
Gas Type,Nitrogen
Pan Type,Tzero Aluminum Hermetic
Source Files 1,C:\Users\yargerlab\Desktop\DSC Data\General\Indium(6).tri
T4P KCell,1.006051
Onset Slope,63.26126 mW/°C
[Direct Cp Calibration]
Date Applied,11/30/2022 11:04:51 AM
Description,From -79.983 °C to 298.409 °C at 10.000°C/min
Gas Type,Nitrogen
Pan Type,Tzero Aluminum Hermetic
Source Files 1,C:\Users\yargerlab\Desktop\DSC Data\General\Sapphire_Heat_Capacity_11_30_22.tri
[Rev Cp Calibration]
Date Applied,11/30/2022 1:58:51 PM
Description,From -79.996 °C to 292.812 °C at 3.000°C/min
Gas Type,Nitrogen
Pan Type,Tzero Aluminum Hermetic
Source Files 1,C:\Users\yargerlab\Desktop\DSC Data\General\Sapphire_MDSC_Calibration_11_30_22.tri
[step]
Ramp 5.00 °C/min to 150.00 °C
Time,Temperature,Heat Flow (Normalized)
min,°C,W/g
0.00,-59.79,-0.030
0.03,-59.81,-0.027
0.06,-59.80,-0.020
0.08,-59.77,-0.007
0.11,-59.70,0.009
0.14,-59.61,0.026
0.17,-59.50,0.039
0.20,-59.39,0.050
0.23,-59.27,0.057
0.26,-59.15,0.062
0.28,-59.02,0.066
0.31,-58.89,0.070
0.34,-58.75,0.072
0.37,-58.62,0.074
0.40,-58.48,0.075
0.43,-58.35,0.076
0.45,-58.21,0.077
0.48,-58.07,0.078
0.51,-57.93,0.078
0.54,-57.79,0.078
0.57,-57.65,0.079
0.60,-57.52,0.079
0.62,-57.38,0.079
0.65,-57.24,0.079
0.68,-57.10,0.080
0.71,-56.96,0.080
0.74,-56.82,0.080
0.77,-56.68,0.080
0.79,-56.54,0.080
0.82,-56.39,0.081
0.85,-56.25,0.081
0.88,-56.11,0.081
0.91,-55.97,0.081
0.93,-55.83,0.081
0.96,-55.69,0.081
0.99,-55.55,0.081
1.02,-55.41,0.081
1.05,-55.27,0.082
1.08,-55.13,0.082
1.11,-54.99,0.082
1.13,-54.85,0.082
1.16,-54.70,0.082
1.19,-54.56,0.082
1.22,-54.42,0.082
1.25,-54.28,0.082
1.28,-54.14,0.082
1.30,-54.00,0.082
1.33,-53.86,0.082
1.36,-53.72,0.082
1.39,-53.58,0.082
1.42,-53.43,0.083
1.44,-53.29,0.083
1.47,-53.15,0.083
1.50,-53.01,0.083
1.53,-52.87,0.083
1.56,-52.73,0.083
1.59,-52.59,0.083
1.62,-52.44,0.083
1.64,-52.30,0.083
1.67,-52.16,0.083
1.70,-52.02,0.083
1.73,-51.88,0.083
1.76,-51.74,0.083
1.78,-51.59,0.083
1.81,-51.45,0.083
1.84,-51.31,0.083
1.87,-51.17,0.083
1.90,-51.03,0.083
1.93,-50.89,0.083
1.96,-50.75,0.083
1.98,-50.60,0.083
2.01,-50.46,0.083
2.04,-50.32,0.083
2.07,-50.18,0.083
2.10,-50.04,0.083
2.13,-49.90,0.083
2.15,-49.76,0.083
2.18,-49.61,0.083
2.21,-49.47,0.084
2.24,-49.33,0.084
2.27,-49.19,0.084
2.29,-49.05,0.084
2.32,-48.90,0.084
2.35,-48.76,0.084
2.38,-48.62,0.084
2.41,-48.48,0.084
2.44,-48.34,0.084
2.46,-48.20,0.084
2.49,-48.05,0.084
2.52,-47.91,0.084
2.55,-47.77,0.084
2.58,-47.63,0.084
2.61,-47.49,0.084
2.64,-47.35,0.084
2.66,-47.21,0.084
2.69,-47.06,0.084
2.72,-46.92,0.084
2.75,-46.78,0.084
2.78,-46.64,0.084
2.81,-46.50,0.084
2.83,-46.36,0.084
2.86,-46.22,0.084
2.89,-46.07,0.084
2.92,-45.93,0.084
2.95,-45.79,0.084
2.98,-45.65,0.084
3.00,-45.51,0.084
3.03,-45.37,0.084
3.06,-45.22,0.084
3.09,-45.08,0.084
3.12,-44.94,0.084
3.14,-44.80,0.084
3.17,-44.66,0.084
3.20,-44.52,0.084
3.23,-44.38,0.084
3.26,-44.23,0.084
3.29,-44.09,0.084
3.31,-43.95,0.084
3.34,-43.81,0.084
3.37,-43.67,0.085
3.40,-43.53,0.085
3.43,-43.38,0.085
3.46,-43.24,0.085
3.49,-43.10,0.085
3.51,-42.96,0.085
3.54,-42.82,0.085
3.57,-42.68,0.085
3.60,-42.53,0.085
3.63,-42.39,0.085
3.66,-42.25,0.085
3.68,-42.11,0.085
3.71,-41.97,0.085
3.74,-41.82,0.085
3.77,-41.68,0.085
3.80,-41.54,0.085
3.83,-41.40,0.085
3.85,-41.26,0.085
3.88,-41.12,0.085
3.91,-40.98,0.085
3.94,-40.83,0.085
3.97,-40.69,0.085
3.99,-40.55,0.085
4.02,-40.41,0.085
4.05,-40.27,0.085
4.08,-40.13,0.085
4.11,-39.98,0.085
4.14,-39.84,0.085
4.16,-39.70,0.085
4.19,-39.56,0.086
4.22,-39.42,0.086
4.25,-39.27,0.086
4.28,-39.13,0.086
4.31,-38.99,0.086
4.34,-38.85,0.086
4.36,-38.71,0.086
4.39,-38.57,0.086
4.42,-38.42,0.086
4.45,-38.28,0.086
4.48,-38.14,0.086
4.50,-38.00,0.086
4.53,-37.86,0.086
4.56,-37.72,0.086
4.59,-37.57,0.086
4.62,-37.43,0.086
4.65,-37.29,0.086
4.68,-37.15,0.086
4.70,-37.01,0.086
4.73,-36.86,0.086
4.76,-36.72,0.086
4.79,-36.58,0.086
4.82,-36.44,0.086
4.85,-36.30,0.086
4.87,-36.15,0.086
4.90,-36.01,0.086
4.93,-35.87,0.086
4.96,-35.73,0.086
4.99,-35.59,0.086
5.01,-35.45,0.087
5.04,-35.30,0.087
5.07,-35.16,0.087
5.10,-35.02,0.087
5.13,-34.88,0.087
5.16,-34.74,0.087
5.19,-34.59,0.087
5.21,-34.45,0.087
5.24,-34.31,0.087
5.27,-34.17,0.087
5.30,-34.03,0.087
5.33,-33.89,0.087
5.35,-33.74,0.087
5.38,-33.60,0.087
5.41,-33.46,0.087
5.44,-33.32,0.087
5.47,-33.18,0.087
5.50,-33.03,0.087
5.53,-32.89,0.087
5.55,-32.75,0.087
5.58,-32.61,0.087
5.61,-32.47,0.087
5.64,-32.33,0.087
5.67,-32.18,0.087
5.70,-32.04,0.087
5.72,-31.90,0.087
5.75,-31.76,0.087
5.78,-31.62,0.087
5.81,-31.48,0.087
5.84,-31.33,0.088
5.86,-31.19,0.088
5.89,-31.05,0.088
5.92,-30.91,0.088
5.95,-30.77,0.088
5.98,-30.62,0.088
6.01,-30.48,0.088
6.04,-30.34,0.088
6.06,-30.20,0.088
6.09,-30.06,0.088
6.12,-29.91,0.088
6.15,-29.77,0.088
6.18,-29.63,0.088
6.20,-29.49,0.088
6.23,-29.35,0.088
6.26,-29.21,0.088
6.29,-29.06,0.088
6.32,-28.92,0.088
6.35,-28.78,0.088
6.38,-28.64,0.088
6.40,-28.49,0.088
6.43,-28.35,0.088
6.46,-28.21,0.088
6.49,-28.07,0.088
6.52,-27.93,0.088
6.55,-27.79,0.088
6.57,-27.65,0.088
6.60,-27.50,0.089
6.63,-27.36,0.089
6.66,-27.22,0.089
6.69,-27.08,0.089
6.71,-26.94,0.089
6.74,-26.80,0.089
6.77,-26.65,0.089
6.80,-26.51,0.089
6.83,-26.37,0.089
6.86,-26.23,0.089
6.89,-26.09,0.089
6.91,-25.94,0.089
6.94,-25.80,0.089
6.97,-25.66,0.089
7.00,-25.52,0.089
7.03,-25.38,0.089
7.05,-25.23,0.089
7.08,-25.09,0.089
7.11,-24.95,0.089
7.14,-24.81,0.089
7.17,-24.67,0.089
7.20,-24.53,0.089
7.23,-24.38,0.089
7.25,-24.24,0.089
7.28,-24.10,0.089
7.31,-23.96,0.090
7.34,-23.82,0.090
7.37,-23.67,0.090
7.40,-23.53,0.090
7.42,-23.39,0.090
7.45,-23.25,0.090
7.48,-23.11,0.090
7.51,-22.97,0.090
7.54,-22.82,0.090
7.56,-22.68,0.090
7.59,-22.54,0.090
7.62,-22.40,0.090
7.65,-22.26,0.090
7.68,-22.12,0.090
7.71,-21.97,0.090
7.74,-21.83,0.090
7.76,-21.69,0.090
7.79,-21.55,0.090
7.82,-21.40,0.090
7.85,-21.27,0.090
7.88,-21.12,0.090
7.90,-20.98,0.090
7.93,-20.84,0.090
7.96,-20.70,0.090
7.99,-20.55,0.090
8.02,-20.41,0.090
8.05,-20.27,0.091
8.08,-20.13,0.091
8.10,-19.99,0.091
8.13,-19.85,0.091
8.16,-19.70,0.091
8.19,-19.56,0.091
8.22,-19.42,0.091
8.25,-19.28,0.091
8.27,-19.14,0.091
8.30,-18.99,0.091
8.33,-18.85,0.091
8.36,-18.71,0.091
8.39,-18.57,0.091
8.41,-18.43,0.091
8.44,-18.29,0.091
8.47,-18.14,0.091
8.50,-18.00,0.091
8.53,-17.86,0.091
8.56,-17.72,0.091
8.58,-17.58,0.091
8.61,-17.43,0.091
8.64,-17.29,0.091
8.67,-17.15,0.091
8.70,-17.01,0.091
8.73,-16.87,0.091
8.75,-16.73,0.091
8.78,-16.58,0.091
8.81,-16.44,0.091
8.84,-16.30,0.091
8.87,-16.16,0.091
8.90,-16.02,0.092
8.93,-15.88,0.092
8.95,-15.73,0.092
8.98,-15.59,0.092
9.01,-15.45,0.092
9.04,-15.31,0.092
9.07,-15.17,0.092
9.10,-15.03,0.092
9.12,-14.88,0.092
9.15,-14.74,0.092
9.18,-14.60,0.092
9.21,-14.46,0.092
9.24,-14.32,0.092
9.27,-14.18,0.092
9.29,-14.03,0.092
9.32,-13.89,0.092
9.35,-13.75,0.092
9.38,-13.61,0.092
9.41,-13.46,0.092
9.43,-13.32,0.092
9.46,-13.18,0.092
9.49,-13.04,0.092
9.52,-12.90,0.092
9.55,-12.76,0.093
9.58,-12.61,0.093
9.60,-12.47,0.093
9.63,-12.33,0.093
9.66,-12.19,0.093
9.69,-12.05,0.093
9.72,-11.91,0.093
9.75,-11.76,0.093
9.78,-11.62,0.093
9.80,-11.48,0.093
9.83,-11.34,0.093
9.86,-11.20,0.093
9.89,-11.06,0.093
9.92,-10.91,0.093
9.95,-10.77,0.093
9.97,-10.63,0.093
10.00,-10.49,0.093
10.03,-10.35,0.093
10.06,-10.21,0.093
10.09,-10.06,0.093
10.12,-9.92,0.093
10.14,-9.78,0.093
10.17,-9.64,0.093
10.20,-9.50,0.093
10.23,-9.36,0.093
10.26,-9.21,0.094
10.28,-9.07,0.094
10.31,-8.93,0.094
10.34,-8.78,0.094
10.37,-8.65,0.094
10.40,-8.50,0.094
10.43,-8.36,0.094
10.45,-8.22,0.094
10.48,-8.08,0.094
10.51,-7.94,0.094
10.54,-7.79,0.094
10.57,-7.65,0.094
10.60,-7.51,0.094
10.63,-7.37,0.094
10.65,-7.23,0.094
10.68,-7.09,0.094
10.71,-6.94,0.094
10.74,-6.80,0.094
10.77,-6.66,0.094
10.80,-6.52,0.094
10.82,-6.38,0.094
10.85,-6.24,0.094
10.88,-6.09,0.094
10.91,-5.95,0.094
10.94,-5.81,0.094
10.97,-5.67,0.095
10.99,-5.53,0.095
11.02,-5.39,0.095
11.05,-5.24,0.095
11.08,-5.10,0.095
11.11,-4.96,0.095
11.13,-4.82,0.095
11.16,-4.68,0.095
11.19,-4.54,0.095
11.22,-4.39,0.095
11.25,-4.25,0.095
11.28,-4.11,0.095
11.30,-3.97,0.095
11.33,-3.83,0.095
11.36,-3.68,0.095
11.39,-3.54,0.095
11.42,-3.40,0.095
11.45,-3.26,0.095
11.48,-3.12,0.095
11.50,-2.98,0.095
11.53,-2.84,0.095
11.56,-2.69,0.095
11.59,-2.55,0.095
11.62,-2.41,0.095
11.65,-2.27,0.096
11.67,-2.12,0.096
11.70,-1.98,0.096
11.73,-1.84,0.096
11.76,-1.70,0.096
11.79,-1.56,0.096
11.82,-1.42,0.096
11.84,-1.27,0.096
11.87,-1.13,0.096
11.90,-0.99,0.096
11.93,-0.85,0.096
11.96,-0.71,0.096
11.98,-0.56,0.096
12.01,-0.42,0.096
12.04,-0.28,0.096
12.07,-0.14,0.096
12.10,0.00,0.096
12.13,0.15,0.096
12.15,0.29,0.096
12.18,0.43,0.096
12.21,0.57,0.096
12.24,0.71,0.096
12.27,0.85,0.096
12.30,1.00,0.096
12.33,1.14,0.096
12.35,1.28,0.097
12.38,1.42,0.097
12.41,1.56,0.097
12.44,1.71,0.097
12.47,1.85,0.097
12.50,1.99,0.097
12.52,2.13,0.097
12.55,2.27,0.097
12.58,2.41,0.097
12.61,2.56,0.097
12.64,2.70,0.097
12.67,2.84,0.097
12.69,2.98,0.097
12.72,3.12,0.097
12.75,3.27,0.097
12.78,3.41,0.097
12.81,3.55,0.097
12.83,3.69,0.097
12.86,3.83,0.097
12.89,3.97,0.097
12.92,4.12,0.097
12.95,4.26,0.097
12.98,4.40,0.097
13.00,4.54,0.098
13.03,4.68,0.098
13.06,4.82,0.098
13.09,4.97,0.098
13.12,5.11,0.098
13.15,5.25,0.098
13.18,5.39,0.098
13.20,5.53,0.098
13.23,5.67,0.098
13.26,5.82,0.098
13.29,5.96,0.098
13.32,6.10,0.098
13.35,6.24,0.098
13.37,6.38,0.098
13.40,6.52,0.098
13.43,6.67,0.098
13.46,6.81,0.098
13.49,6.95,0.098
13.52,7.09,0.098
13.54,7.23,0.098
13.57,7.37,0.098
13.60,7.52,0.098
13.63,7.66,0.098
13.66,7.80,0.098
13.68,7.94,0.099
13.71,8.08,0.099
13.74,8.23,0.099
13.77,8.37,0.099
13.80,8.51,0.099
13.83,8.65,0.099
13.85,8.79,0.099
13.88,8.94,0.099
13.91,9.08,0.099
13.94,9.22,0.099
13.97,9.36,0.099
14.00,9.50,0.099
14.03,9.64,0.099
14.05,9.79,0.099
14.08,9.93,0.099
14.11,10.07,0.099
14.14,10.21,0.099
14.17,10.35,0.099
14.20,10.50,0.099
14.22,10.64,0.100
14.25,10.78,0.100
14.28,10.92,0.100
14.31,11.06,0.100
14.34,11.20,0.100
14.37,11.35,0.100
14.39,11.49,0.100
14.42,11.63,0.100
14.45,11.77,0.100
14.48,11.91,0.100
14.51,12.05,0.100
14.53,12.20,0.100
14.56,12.34,0.100
14.59,12.48,0.100
14.62,12.62,0.100
14.65,12.76,0.100
14.68,12.91,0.100
14.70,13.05,0.100
14.73,13.19,0.100
14.76,13.33,0.100
14.79,13.47,0.100
14.82,13.61,0.100
14.85,13.76,0.101
14.88,13.90,0.101
14.90,14.04,0.101
14.93,14.18,0.101
14.96,14.32,0.101
14.99,14.47,0.101
15.02,14.61,0.101
15.05,14.75,0.101
15.07,14.89,0.101
15.10,15.03,0.101
15.13,15.17,0.101
15.16,15.32,0.101
15.19,15.46,0.101
15.22,15.60,0.101
15.24,15.74,0.101
15.27,15.88,0.101
15.30,16.02,0.101
15.33,16.17,0.101
15.36,16.31,0.101
15.38,16.45,0.101
15.41,16.59,0.102
15.44,16.74,0.102
15.47,16.88,0.102
15.50,17.02,0.102
15.53,17.16,0.102
15.55,17.30,0.102
15.58,17.44,0.102
15.61,17.58,0.102
15.64,17.73,0.102
15.67,17.87,0.102
15.70,18.01,0.102
15.73,18.15,0.102
15.75,18.29,0.102
15.78,18.43,0.102
15.81,18.57,0.102
15.84,18.72,0.102
15.87,18.86,0.102
15.90,19.00,0.102
15.92,19.14,0.102
15.95,19.29,0.102
15.98,19.43,0.102
16.01,19.57,0.102
16.04,19.71,0.103
16.07,19.85,0.103
16.09,19.99,0.103
16.12,20.14,0.103
16.15,20.28,0.103
16.18,20.42,0.103
16.21,20.56,0.103
16.23,20.70,0.103
16.26,20.84,0.103
16.29,20.99,0.103
16.32,21.13,0.103
16.35,21.27,0.103
16.38,21.41,0.103
16.40,21.55,0.103
16.43,21.70,0.103
16.46,21.84,0.103
16.49,21.98,0.103
16.52,22.12,0.103
16.55,22.26,0.103
16.58,22.40,0.103
16.60,22.55,0.103
16.63,22.69,0.103
16.66,22.83,0.104
16.69,22.97,0.104
16.72,23.11,0.104
16.75,23.25,0.104
16.77,23.40,0.104
16.80,23.54,0.104
16.83,23.68,0.104
16.86,23.82,0.104
16.89,23.96,0.104
16.92,24.10,0.104
16.94,24.25,0.104
16.97,24.39,0.104
17.00,24.53,0.104
17.03,24.67,0.104
17.06,24.81,0.104
17.08,24.95,0.104
17.11,25.10,0.104
17.14,25.24,0.104
17.17,25.38,0.104
17.20,25.52,0.104
17.23,25.66,0.104
17.26,25.81,0.105
17.28,25.95,0.105
17.31,26.09,0.105
17.34,26.23,0.105
17.37,26.37,0.105
17.40,26.51,0.105
17.43,26.66,0.105
17.45,26.80,0.105
17.48,26.94,0.105
17.51,27.08,0.105
17.54,27.22,0.105
17.57,27.37,0.105
17.59,27.51,0.105
17.62,27.65,0.105
17.65,27.79,0.105
17.68,27.93,0.105
17.71,28.07,0.105
17.74,28.22,0.105
17.77,28.36,0.105
17.79,28.50,0.106
17.82,28.64,0.106
17.85,28.78,0.106
17.88,28.92,0.106
17.91,29.07,0.106
17.93,29.21,0.106
17.96,29.35,0.106
17.99,29.49,0.106
18.02,29.64,0.106
18.05,29.78,0.106
18.08,29.92,0.106
18.11,30.06,0.106
18.13,30.20,0.106
18.16,30.34,0.106
18.19,30.49,0.106
18.22,30.63,0.106
18.25,30.77,0.106
18.28,30.91,0.106
18.30,31.05,0.107
18.33,31.19,0.107
18.36,31.34,0.107
18.39,31.48,0.107
18.42,31.62,0.107
18.44,31.76,0.107
18.47,31.90,0.107
18.50,32.04,0.107
18.53,32.18,0.107
18.56,32.33,0.107
18.59,32.47,0.107
18.62,32.61,0.107
18.64,32.75,0.107
18.67,32.90,0.107
18.70,33.04,0.107
18.73,33.18,0.107
18.76,33.32,0.107
18.78,33.46,0.107
18.81,33.60,0.107
18.84,33.75,0.107
18.87,33.89,0.107
18.90,34.03,0.108
18.93,34.17,0.108
18.96,34.31,0.108
18.98,34.45,0.108
19.01,34.60,0.108
19.04,34.74,0.108
19.07,34.88,0.108
19.10,35.02,0.108
19.13,35.16,0.108
19.15,35.30,0.108
19.18,35.45,0.108
19.21,35.59,0.108
19.24,35.73,0.108
19.27,35.87,0.108
19.29,36.01,0.108
19.32,36.16,0.108
19.35,36.30,0.108
19.38,36.44,0.108
19.41,36.58,0.108
19.44,36.72,0.108
19.47,36.86,0.108
19.49,37.01,0.108
19.52,37.15,0.108
19.55,37.29,0.109
19.58,37.43,0.109
19.61,37.57,0.109
19.63,37.72,0.109
19.66,37.86,0.109
19.69,38.00,0.109
19.72,38.14,0.109
19.75,38.28,0.109
19.78,38.42,0.109
19.81,38.57,0.109
19.83,38.71,0.109
19.86,38.85,0.109
19.89,38.99,0.109
19.92,39.13,0.109
19.95,39.27,0.109
19.98,39.42,0.109
20.00,39.56,0.109
20.03,39.70,0.109
20.06,39.84,0.109
20.09,39.98,0.109
20.12,40.12,0.109
20.14,40.27,0.110
20.17,40.41,0.110
20.20,40.55,0.110
20.23,40.69,0.110
20.26,40.84,0.110
20.29,40.98,0.110
20.32,41.12,0.110
20.34,41.26,0.110
20.37,41.40,0.110
20.40,41.54,0.110
20.43,41.68,0.110
20.46,41.83,0.110
20.48,41.97,0.110
20.51,42.11,0.110
20.54,42.25,0.110
20.57,42.39,0.110
20.60,42.53,0.110
20.63,42.68,0.110
20.66,42.82,0.110
20.68,42.96,0.110
20.71,43.10,0.111
20.74,43.24,0.111
20.77,43.38,0.111
20.80,43.53,0.111
20.83,43.67,0.111
20.85,43.81,0.111
20.88,43.95,0.111
20.91,44.09,0.111
20.94,44.23,0.111
20.97,44.38,0.111
20.99,44.52,0.111
21.02,44.66,0.111
21.05,44.80,0.111
21.08,44.94,0.111
21.11,45.09,0.111
21.14,45.23,0.111
21.17,45.37,0.111
21.19,45.51,0.111
21.22,45.65,0.111
21.25,45.80,0.112
21.28,45.94,0.112
21.31,46.08,0.112
21.33,46.22,0.112
21.36,46.36,0.112
21.39,46.50,0.112
21.42,46.65,0.112
21.45,46.79,0.112
21.48,46.93,0.112
21.51,47.07,0.112
21.53,47.21,0.112
21.56,47.35,0.112
21.59,47.49,0.112
21.62,47.64,0.112
21.65,47.78,0.112
21.68,47.92,0.112
21.70,48.06,0.112
21.73,48.20,0.112
21.76,48.35,0.112
21.79,48.49,0.112
21.82,48.63,0.113
21.84,48.77,0.113
21.87,48.91,0.113
21.90,49.05,0.113
21.93,49.20,0.113
21.96,49.34,0.113
21.99,49.48,0.113
22.02,49.62,0.113
22.04,49.76,0.113
22.07,49.91,0.113
22.10,50.05,0.113
22.13,50.19,0.113
22.16,50.33,0.113
22.18,50.47,0.113
22.21,50.61,0.113
22.24,50.75,0.113
22.27,50.90,0.113
22.30,51.04,0.113
22.33,51.18,0.113
22.36,51.32,0.113
22.38,51.47,0.114
22.41,51.61,0.114
22.44,51.75,0.114
22.47,51.89,0.114
22.50,52.03,0.114
22.53,52.17,0.114
22.55,52.32,0.114
22.58,52.46,0.114
22.61,52.60,0.114
22.64,52.74,0.114
22.67,52.88,0.114
22.69,53.02,0.114
22.72,53.17,0.114
22.75,53.31,0.114
22.78,53.45,0.114
22.81,53.59,0.114
22.84,53.73,0.114
22.87,53.87,0.114
22.89,54.02,0.114
22.92,54.16,0.114
22.95,54.30,0.115
22.98,54.44,0.115
23.01,54.58,0.115
23.03,54.72,0.115
23.06,54.87,0.115
23.09,55.01,0.115
23.12,55.15,0.115
23.15,55.29,0.115
23.18,55.43,0.115
23.21,55.58,0.115
23.23,55.72,0.115
23.26,55.86,0.115
23.29,56.00,0.115
23.32,56.14,0.115
23.35,56.29,0.115
23.38,56.43,0.115
23.40,56.57,0.115
23.43,56.71,0.115
23.46,56.85,0.115
23.49,56.99,0.115
23.52,57.14,0.115
23.54,57.28,0.115
23.57,57.42,0.116
23.60,57.56,0.116
23.63,57.70,0.116
23.66,57.84,0.116
23.69,57.99,0.116
23.72,58.13,0.116
23.74,58.27,0.116
23.77,58.41,0.116
23.80,58.55,0.116
23.83,58.69,0.116
23.86,58.84,0.116
23.88,58.98,0.116
23.91,59.12,0.116
23.94,59.26,0.116
23.97,59.40,0.116
24.00,59.54,0.116
24.03,59.69,0.116
24.06,59.83,0.116
24.08,59.97,0.116
24.11,60.11,0.116
24.14,60.25,0.116
24.17,60.39,0.116
24.20,60.54,0.117
24.23,60.68,0.117
24.25,60.82,0.117
24.28,60.96,0.117
24.31,61.10,0.117
24.34,61.24,0.117
24.37,61.39,0.117
24.39,61.53,0.117
24.42,61.67,0.117
24.45,61.81,0.117
24.48,61.95,0.117
24.51,62.10,0.117
24.54,62.24,0.117
24.57,62.38,0.117
24.59,62.52,0.117
24.62,62.66,0.117
24.65,62.80,0.117
24.68,62.95,0.117
24.71,63.09,0.117
24.73,63.23,0.117
24.76,63.37,0.118
24.79,63.51,0.118
24.82,63.65,0.118
24.85,63.80,0.118
24.88,63.94,0.118
24.91,64.08,0.118
24.93,64.22,0.118
24.96,64.36,0.118
24.99,64.51,0.118
25.02,64.65,0.118
25.05,64.79,0.118
25.08,64.93,0.118
25.10,65.07,0.118
25.13,65.21,0.118
25.16,65.36,0.118
25.19,65.50,0.118
25.22,65.64,0.118
25.24,65.78,0.118
25.27,65.92,0.118
25.30,66.07,0.119
25.33,66.21,0.119
25.36,66.35,0.119
25.39,66.49,0.119
25.42,66.63,0.119
25.44,66.77,0.119
25.47,66.91,0.119
25.50,67.06,0.119
25.53,67.20,0.119
25.56,67.34,0.119
25.58,67.48,0.119
25.61,67.62,0.119
25.64,67.77,0.119
25.67,67.91,0.119
25.70,68.05,0.119
25.73,68.19,0.119
25.76,68.33,0.119
25.78,68.47,0.119
25.81,68.62,0.119
25.84,68.76,0.119
25.87,68.90,0.119
25.90,69.04,0.119
25.93,69.18,0.119
25.95,69.32,0.119
25.98,69.47,0.120
26.01,69.61,0.120
26.04,69.75,0.120
26.07,69.89,0.120
26.09,70.03,0.120
26.12,70.18,0.120
26.15,70.32,0.120
26.18,70.46,0.120
26.21,70.60,0.120
26.24,70.74,0.120
26.27,70.88,0.120
26.29,71.03,0.120
26.32,71.17,0.120
26.35,71.31,0.120
26.38,71.45,0.120
26.41,71.59,0.120
26.43,71.74,0.120
26.46,71.88,0.120
26.49,72.02,0.120
26.52,72.16,0.120
26.55,72.30,0.121
26.58,72.44,0.121
26.61,72.58,0.121
26.63,72.73,0.121
26.66,72.87,0.121
26.69,73.01,0.121
26.72,73.15,0.121
26.75,73.29,0.121
26.78,73.44,0.121
26.80,73.58,0.121
26.83,73.72,0.121
26.86,73.86,0.121
26.89,74.01,0.121
26.92,74.15,0.121
26.94,74.29,0.122
26.97,74.43,0.122
27.00,74.57,0.122
27.03,74.72,0.122
27.06,74.86,0.122
27.09,75.00,0.122
27.12,75.14,0.122
27.14,75.28,0.122
27.17,75.42,0.122
27.20,75.56,0.122
27.23,75.71,0.122
27.26,75.85,0.122
27.28,75.99,0.122
27.31,76.13,0.122
27.34,76.27,0.122
27.37,76.42,0.122
27.40,76.56,0.122
27.43,76.70,0.122
27.46,76.84,0.122
27.48,76.98,0.122
27.51,77.12,0.122
27.54,77.26,0.122
27.57,77.41,0.122
27.60,77.55,0.122
27.63,77.69,0.122
27.65,77.83,0.122
27.68,77.97,0.122
27.71,78.11,0.122
27.74,78.26,0.122
27.77,78.40,0.122
27.79,78.54,0.122
27.82,78.68,0.122
27.85,78.82,0.123
27.88,78.97,0.123
27.91,79.11,0.123
27.94,79.25,0.123
27.97,79.39,0.123
27.99,79.53,0.123
28.02,79.67,0.123
28.05,79.82,0.123
28.08,79.96,0.123
28.11,80.10,0.123
28.13,80.24,0.123
28.16,80.38,0.123
28.19,80.52,0.123
28.22,80.66,0.123
28.25,80.81,0.123
28.28,80.95,0.123
28.31,81.09,0.123
28.33,81.23,0.123
28.36,81.37,0.123
28.39,81.52,0.124
28.42,81.66,0.124
28.45,81.80,0.124
28.48,81.94,0.124
28.50,82.08,0.124
28.53,82.22,0.124
28.56,82.37,0.124
28.59,82.51,0.124
28.62,82.65,0.124
28.64,82.79,0.124
28.67,82.93,0.124
28.70,83.07,0.124
28.73,83.22,0.124
28.76,83.36,0.124
28.79,83.50,0.124
28.82,83.64,0.124
28.84,83.78,0.124
28.87,83.93,0.124
28.90,84.07,0.124
28.93,84.21,0.124
28.96,84.35,0.124
28.98,84.49,0.125
29.01,84.64,0.125
29.04,84.78,0.125
29.07,84.92,0.125
29.10,85.06,0.125
29.13,85.20,0.125
29.16,85.34,0.125
29.18,85.49,0.125
29.21,85.63,0.125
29.24,85.77,0.125
29.27,85.91,0.125
29.30,86.05,0.125
29.33,86.19,0.125
29.35,86.33,0.125
29.38,86.48,0.125
29.41,86.62,0.125
29.44,86.76,0.125
29.47,86.90,0.125
29.49,87.04,0.125
29.52,87.19,0.125
29.55,87.33,0.125
29.58,87.47,0.125
29.61,87.61,0.126
29.64,87.75,0.126
29.67,87.89,0.126
29.69,88.04,0.126
29.72,88.18,0.126
29.75,88.32,0.126
29.78,88.46,0.126
29.81,88.60,0.126
29.83,88.74,0.126
29.86,88.89,0.126
29.89,89.03,0.126
29.92,89.17,0.126
29.95,89.31,0.126
29.98,89.45,0.126
30.01,89.59,0.126
30.03,89.74,0.126
30.06,89.88,0.126
30.09,90.02,0.126
30.12,90.16,0.127
30.15,90.30,0.127
30.18,90.45,0.127
30.20,90.59,0.127
30.23,90.73,0.127
30.26,90.87,0.127
30.29,91.01,0.127
30.32,91.15,0.127
30.34,91.30,0.127
30.37,91.44,0.127
30.40,91.58,0.127
30.43,91.72,0.127
30.46,91.86,0.127
30.49,92.01,0.127
30.52,92.15,0.127
30.54,92.29,0.127
30.57,92.43,0.127
30.60,92.57,0.128
30.63,92.71,0.128
30.66,92.86,0.128
30.68,93.00,0.128
30.71,93.14,0.128
30.74,93.28,0.128
30.77,93.42,0.128
30.80,93.56,0.128
30.83,93.71,0.128
30.86,93.85,0.128
30.88,93.99,0.128
30.91,94.13,0.128
30.94,94.27,0.128
30.97,94.41,0.128
31.00,94.56,0.128
31.03,94.70,0.128
31.05,94.84,0.128
31.08,94.98,0.128
31.11,95.12,0.129
31.14,95.27,0.129
31.17,95.41,0.129
31.19,95.55,0.129
31.22,95.69,0.129
31.25,95.83,0.129
31.28,95.97,0.129
31.31,96.12,0.129
31.34,96.26,0.129
31.37,96.40,0.129
31.39,96.54,0.129
31.42,96.68,0.129
31.45,96.82,0.129
31.48,96.97,0.129
31.51,97.11,0.129
31.53,97.25,0.130
31.56,97.39,0.130
31.59,97.53,0.130
31.62,97.68,0.130
31.65,97.82,0.130
31.68,97.96,0.130
31.71,98.10,0.130
31.73,98.24,0.130
31.76,98.38,0.130
31.79,98.52,0.130
31.82,98.67,0.130
31.85,98.81,0.130
31.88,98.95,0.130
31.90,99.09,0.130
31.93,99.23,0.130
31.96,99.38,0.130
31.99,99.52,0.131
32.02,99.66,0.131
32.04,99.80,0.131
32.07,99.94,0.131
32.10,100.08,0.131
32.13,100.23,0.131
32.16,100.37,0.131
32.19,100.51,0.131
32.22,100.65,0.131
32.24,100.79,0.131
32.27,100.93,0.131
32.30,101.07,0.131
32.33,101.22,0.131
32.36,101.36,0.131
32.38,101.50,0.131
32.41,101.64,0.131
32.44,101.78,0.131
32.47,101.93,0.132
32.50,102.07,0.132
32.53,102.21,0.132
32.56,102.35,0.132
32.58,102.49,0.132
32.61,102.63,0.132
32.64,102.78,0.132
32.67,102.92,0.132
32.70,103.06,0.132
32.73,103.20,0.132
32.75,103.34,0.132
32.78,103.48,0.132
32.81,103.63,0.132
32.84,103.77,0.132
32.87,103.91,0.133
32.89,104.05,0.133
32.92,104.19,0.133
32.95,104.34,0.133
32.98,104.48,0.133
33.01,104.62,0.133
33.04,104.76,0.133
33.07,104.90,0.133
33.09,105.04,0.133
33.12,105.19,0.133
33.15,105.33,0.133
33.18,105.47,0.133
33.21,105.61,0.133
33.23,105.75,0.134
33.26,105.89,0.134
33.29,106.04,0.134
33.32,106.18,0.134
33.35,106.32,0.134
33.38,106.46,0.134
33.41,106.60,0.134
33.43,106.74,0.134
33.46,106.88,0.134
33.49,107.03,0.134
33.52,107.17,0.134
33.55,107.31,0.134
33.58,107.45,0.134
33.60,107.59,0.135
33.63,107.74,0.135
33.66,107.88,0.135
33.69,108.02,0.135
33.72,108.16,0.135
33.74,108.30,0.135
33.77,108.44,0.135
33.80,108.59,0.135
33.83,108.73,0.135
33.86,108.87,0.135
33.89,109.01,0.135
33.92,109.15,0.135
33.94,109.29,0.136
33.97,109.44,0.136
34.00,109.58,0.136
34.03,109.72,0.136
34.06,109.86,0.136
34.08,110.00,0.136
34.11,110.14,0.136
34.14,110.29,0.136
34.17,110.43,0.136
34.20,110.57,0.136
34.23,110.71,0.136
34.26,110.85,0.137
34.28,111.00,0.137
34.31,111.14,0.137
34.34,111.28,0.137
34.37,111.42,0.137
34.40,111.56,0.137
34.43,111.70,0.137
34.45,111.84,0.137
34.48,111.99,0.137
34.51,112.13,0.137
34.54,112.27,0.137
34.57,112.41,0.137
34.59,112.55,0.138
34.62,112.69,0.138
34.65,112.84,0.138
34.68,112.98,0.138
34.71,113.12,0.138
34.74,113.26,0.138
34.76,113.40,0.138
34.79,113.55,0.138
34.82,113.69,0.138
34.85,113.83,0.138
34.88,113.97,0.139
34.91,114.11,0.139
34.94,114.25,0.139
34.96,114.39,0.139
34.99,114.54,0.139
35.02,114.68,0.139
35.05,114.82,0.139
35.08,114.96,0.139
35.11,115.10,0.139
35.13,115.25,0.140
35.16,115.39,0.140
35.19,115.53,0.140
35.22,115.67,0.140
35.25,115.81,0.140
35.28,115.95,0.140
35.30,116.10,0.140
35.33,116.24,0.140
35.36,116.38,0.140
35.39,116.52,0.141
35.42,116.66,0.141
35.44,116.80,0.141
35.47,116.95,0.141
35.50,117.09,0.141
35.53,117.23,0.141
35.56,117.37,0.141
35.59,117.51,0.141
35.61,117.65,0.141
35.64,117.80,0.142
35.67,117.94,0.142
35.70,118.08,0.142
35.73,118.22,0.142
35.76,118.36,0.142
35.79,118.50,0.142
35.81,118.65,0.142
35.84,118.79,0.143
35.87,118.93,0.143
35.90,119.07,0.143
35.93,119.21,0.143
35.96,119.35,0.143
35.98,119.49,0.143
36.01,119.64,0.144
36.04,119.78,0.144
36.07,119.92,0.144
36.10,120.06,0.144
36.13,120.20,0.144
36.15,120.35,0.145
36.18,120.49,0.145
36.21,120.63,0.145
36.24,120.77,0.146
36.27,120.91,0.146
36.29,121.05,0.147
36.32,121.19,0.150
36.35,121.33,0.153
36.38,121.47,0.157
36.41,121.61,0.163
36.44,121.75,0.174
36.46,121.88,0.196
36.49,121.99,0.241
36.52,122.09,0.323
36.55,122.16,0.430
36.58,122.22,0.562
36.61,122.25,0.694
36.64,122.29,0.825
36.66,122.32,0.952
36.69,122.36,1.080
36.72,122.40,1.209
36.75,122.43,1.336
36.78,122.47,1.461
36.81,122.50,1.584
36.83,122.55,1.706
36.86,122.58,1.832
36.89,122.62,1.958
36.92,122.66,2.088
36.95,122.70,2.213
36.98,122.73,2.335
37.00,122.78,2.459
37.03,122.82,2.578
37.06,122.86,2.694
37.09,122.90,2.824
37.12,122.94,2.935
37.14,122.99,3.050
37.17,123.04,3.150
37.20,123.09,3.265
37.23,123.15,3.329
37.26,123.25,3.348
37.29,123.33,3.499
37.31,123.37,3.616
37.34,123.40,3.782
37.37,123.46,3.797
37.40,123.52,3.948
37.43,123.64,3.867
37.46,123.78,3.897
37.49,123.95,3.755
37.51,124.20,3.546
37.54,124.55,3.160
37.57,124.93,2.894
37.60,125.35,2.484
37.63,125.82,2.016
37.66,126.34,1.554
37.68,126.80,1.277
37.71,127.17,1.079
37.74,127.49,0.933
37.77,127.76,0.824
37.80,128.00,0.744
37.83,128.21,0.684
37.85,128.40,0.640
37.88,128.58,0.607
37.91,128.75,0.584
37.94,128.91,0.567
37.97,129.07,0.555
37.99,129.22,0.546
38.02,129.37,0.541
38.05,129.52,0.537
38.08,129.66,0.535
38.11,129.81,0.534
38.14,129.95,0.534
38.16,130.09,0.534
38.19,130.23,0.535
38.22,130.37,0.536
38.25,130.51,0.537
38.28,130.65,0.538
38.31,130.79,0.540
38.34,130.94,0.542
38.36,131.08,0.544
38.39,131.22,0.547
38.42,131.36,0.549
38.45,131.50,0.551
38.48,131.64,0.553
38.51,131.78,0.555
38.53,131.92,0.558
38.56,132.06,0.560
38.59,132.20,0.563
38.62,132.34,0.565
38.65,132.48,0.568
38.68,132.62,0.570
38.70,132.75,0.573
38.73,132.90,0.575
38.76,133.04,0.577
38.79,133.17,0.580
38.82,133.31,0.582
38.84,133.45,0.585
38.87,133.59,0.587
38.90,133.73,0.589
38.93,133.87,0.592
38.96,134.01,0.594
38.99,134.15,0.597
39.01,134.29,0.599
39.04,134.43,0.602
39.07,134.57,0.604
39.10,134.71,0.606
39.13,134.85,0.608
39.16,134.99,0.611
39.19,135.13,0.614
39.21,135.27,0.616
39.24,135.41,0.618
39.27,135.55,0.621
39.30,135.69,0.623
39.33,135.83,0.626
39.36,135.97,0.628
39.38,136.11,0.630
39.41,136.25,0.632
39.44,136.39,0.634
39.47,136.53,0.636
39.50,136.67,0.638
39.53,136.81,0.640
39.55,136.95,0.643
39.58,137.09,0.645
39.61,137.23,0.648
39.64,137.37,0.651
39.67,137.51,0.654
39.69,137.65,0.656
39.72,137.79,0.659
39.75,137.93,0.662
39.78,138.07,0.664
39.81,138.21,0.666
39.84,138.35,0.669
39.86,138.49,0.671
39.89,138.63,0.672
39.92,138.77,0.672
39.95,138.91,0.673
39.98,139.05,0.673
40.01,139.20,0.674
40.04,139.34,0.676
40.06,139.48,0.679
40.09,139.61,0.682
40.12,139.76,0.683
40.15,139.90,0.685
40.18,140.04,0.688
40.21,140.17,0.692
40.23,140.31,0.693
40.26,140.46,0.695
40.29,140.60,0.696
40.32,140.74,0.696
40.35,140.88,0.696
40.38,141.02,0.696
40.40,141.16,0.696
40.43,141.30,0.696
40.46,141.45,0.696
40.49,141.59,0.695
40.52,141.73,0.695
40.54,141.88,0.694
40.57,142.02,0.693
40.60,142.16,0.692
40.63,142.30,0.690
40.66,142.45,0.689
40.69,142.59,0.692
40.71,142.73,0.694
40.74,142.87,0.696
40.77,143.01,0.698
40.80,143.15,0.702
40.83,143.29,0.704
40.86,143.43,0.705
40.89,143.57,0.708
40.91,143.70,0.712
40.94,143.84,0.718
40.97,143.98,0.725
41.00,144.12,0.731
41.03,144.25,0.735
41.06,144.39,0.740
41.08,144.53,0.744
41.11,144.67,0.748
41.14,144.81,0.751
41.17,144.95,0.754
41.20,145.09,0.755
41.23,145.23,0.755
41.25,145.37,0.753
41.28,145.52,0.748
41.31,145.66,0.745
41.34,145.81,0.742
41.37,145.95,0.738
41.39,146.09,0.734
41.42,146.24,0.733
41.45,146.38,0.733
41.48,146.52,0.733
41.51,146.66,0.735
41.54,146.80,0.737
41.56,146.94,0.739
41.59,147.08,0.741
41.62,147.23,0.743
41.65,147.37,0.743
41.68,147.51,0.743
41.71,147.65,0.746
41.74,147.79,0.749
41.76,147.93,0.750
41.79,148.07,0.750
41.82,148.21,0.749
41.85,148.36,0.749
41.88,148.50,0.749
41.91,148.64,0.749
41.93,148.78,
41.96,148.92,
41.99,,

[step]
Ramp 5.00 °C/min to -60.00 °C
Time,Temperature,Heat Flow (Normalized)
min,°C,W/g
42.99,149.67,0.586
43.01,149.67,0.568
43.04,149.66,0.589
43.07,149.63,0.568
43.10,149.58,0.528
43.13,149.51,0.495
43.16,149.40,0.498
43.19,149.29,0.465
43.21,149.17,0.438
43.24,149.05,0.464
43.27,148.92,0.443
43.30,148.79,0.418
43.33,148.66,0.443
43.36,148.52,0.431
43.38,148.38,0.408
43.41,148.25,0.415
43.44,148.11,0.424
43.47,147.97,0.402
43.50,147.84,0.385
43.53,147.70,0.417
43.55,147.56,0.401
43.58,147.42,0.381
43.61,147.29,0.378
43.64,147.15,0.402
43.67,147.01,0.384
43.69,146.87,0.367
43.72,146.74,0.380
43.75,146.59,0.387
43.78,146.45,0.369
43.81,146.32,0.353
43.84,146.18,0.382
43.86,146.04,0.375
43.89,145.90,0.354
43.92,145.76,0.340
43.95,145.62,0.370
43.98,145.48,0.357
44.01,145.34,0.340
44.04,145.21,0.333
44.06,145.07,0.357
44.09,144.92,0.342
44.12,144.79,0.328
44.15,144.65,0.324
44.18,144.51,0.345
44.21,144.37,0.330
44.23,144.23,0.318
44.26,144.10,0.311
44.29,143.95,0.335
44.32,143.81,0.322
44.35,143.67,0.308
44.38,143.54,0.296
44.40,143.40,0.324
44.43,143.25,0.319
44.46,143.11,0.301
44.49,142.98,0.289
44.52,142.84,0.310
44.54,142.70,0.308
44.57,142.56,0.294
44.60,142.42,0.282
44.63,142.28,0.277
44.66,142.14,0.300
44.69,142.00,0.291
44.71,141.86,0.278
44.74,141.72,0.267
44.77,141.59,0.287
44.80,141.44,0.285
44.83,141.30,0.274
44.86,141.16,0.263
44.89,141.03,0.253
44.91,140.89,0.276
44.94,140.74,0.272
44.97,140.60,0.260
45.00,140.46,0.250
45.03,140.33,0.240
45.06,140.19,0.265
45.08,140.04,0.260
45.11,139.90,0.249
45.14,139.77,0.239
45.17,139.63,0.230
45.20,139.49,0.252
45.23,139.34,0.249
45.25,139.20,0.241
45.28,139.07,0.231
45.31,138.93,0.221
45.34,138.79,0.220
45.37,138.65,0.239
45.39,138.51,0.235
45.42,138.37,0.222
45.45,138.23,0.214
45.48,138.09,0.207
45.51,137.95,0.224
45.54,137.81,0.225
45.56,137.67,0.219
45.59,137.53,0.208
45.62,137.39,0.200
45.65,137.25,0.193
45.68,137.11,0.213
45.71,136.97,0.212
45.74,136.82,0.207
45.76,136.68,0.197
45.79,136.55,0.190
45.82,136.41,0.183
45.85,136.27,0.199
45.88,136.13,0.200
45.91,135.98,0.195
45.93,135.84,0.185
45.96,135.71,0.178
45.99,135.57,0.173
46.02,135.43,0.175
46.05,135.29,0.188
46.08,135.14,0.186
46.10,135.00,0.177
46.13,134.86,0.170
46.16,134.73,0.163
46.19,134.59,0.157
46.22,134.45,0.177
46.24,134.30,0.174
46.27,134.16,0.169
46.30,134.02,0.162
46.33,133.88,0.156
46.36,133.75,0.150
46.39,133.61,0.146
46.41,133.47,0.164
46.44,133.32,0.161
46.47,133.18,0.156
46.50,133.04,0.149
46.53,132.90,0.144
46.56,132.76,0.139
46.59,132.63,0.134
46.61,132.48,0.152
46.64,132.34,0.149
46.67,132.20,0.144
46.70,132.06,0.138
46.73,131.92,0.133
46.76,131.78,0.128
46.78,131.64,0.123
46.81,131.50,0.139
46.84,131.36,0.138
46.87,131.22,0.136
46.90,131.08,0.128
46.93,130.94,0.124
46.95,130.80,0.118
46.98,130.66,0.114
47.01,130.52,0.110
47.04,130.38,0.127
47.07,130.24,0.124
47.09,130.09,0.122
47.12,129.95,0.115
47.15,129.81,0.111
47.18,129.67,0.107
47.21,129.54,0.103
47.24,129.40,0.099
47.26,129.25,0.115
47.29,129.11,0.113
47.32,128.97,0.111
47.35,128.83,0.105
47.38,128.69,0.101
47.41,128.55,0.097
47.44,128.41,0.092
47.46,128.27,0.089
47.49,128.13,0.094
47.52,127.99,0.101
47.55,127.85,0.100
47.58,127.70,0.096
47.61,127.56,0.091
47.63,127.43,0.088
47.66,127.29,0.083
47.69,127.15,0.080
47.72,127.01,0.077
47.75,126.87,0.089
47.78,126.72,0.089
47.80,126.58,0.088
47.83,126.44,0.084
47.86,126.30,0.080
47.89,126.16,0.077
47.92,126.02,0.073
47.94,125.88,0.070
47.97,125.74,0.067
48.00,125.60,0.065
48.03,125.46,0.077
48.06,125.32,0.076
48.09,125.17,0.074
48.11,125.03,0.069
48.14,124.89,0.066
48.17,124.75,0.063
48.20,124.61,0.060
48.23,124.47,0.058
48.26,124.33,0.055
48.29,124.20,0.059
48.31,124.05,0.065
48.34,123.91,0.064
48.37,123.77,0.062
48.40,123.63,0.058
48.43,123.49,0.055
48.46,123.35,0.053
48.48,123.21,0.050
48.51,123.07,0.047
48.54,122.93,0.045
48.57,122.79,0.043
48.60,122.65,0.053
48.63,122.50,0.052
48.65,122.36,0.052
48.68,122.22,0.049
48.71,122.08,0.045
48.74,121.94,0.043
48.77,121.80,0.040
48.79,121.66,0.038
48.82,121.52,0.036
48.85,121.38,0.034
48.88,121.24,0.031
48.91,121.10,0.042
48.94,120.95,0.041
48.96,120.81,0.040
48.99,120.67,0.038
49.02,120.53,0.035
49.05,120.39,0.032
49.08,120.25,0.030
49.11,120.11,0.028
49.14,119.97,0.026
49.16,119.83,0.024
49.19,119.69,0.022
49.22,119.55,0.021
49.25,119.41,0.029
49.28,119.26,0.029
49.31,119.12,0.028
49.33,118.98,0.027
49.36,118.84,0.024
49.39,118.70,0.022
49.42,118.56,0.019
49.45,118.42,0.017
49.48,118.28,0.016
49.50,118.14,0.014
49.53,118.00,0.012
49.56,117.86,0.011
49.59,117.71,0.018
49.62,117.57,0.018
49.64,117.43,0.018
49.67,117.29,0.017
49.70,117.15,0.015
49.73,117.01,0.013
49.76,116.87,0.011
49.79,116.73,0.009
49.81,116.58,0.007
49.84,116.45,0.006
49.87,116.30,0.004
49.90,116.16,0.003
49.93,116.02,0.001
49.96,115.88,0.005
49.99,115.74,0.007
50.01,115.60,0.007
50.04,115.46,0.006
50.07,115.31,0.005
50.10,115.17,0.003
50.13,115.03,0.001
50.16,114.89,0.000
50.18,114.75,-0.002
50.21,114.61,-0.003
50.24,114.47,-0.005
50.27,114.33,-0.006
50.30,114.19,-0.007
50.33,114.05,-0.009
50.35,113.91,-0.003
50.38,113.76,-0.003
50.41,113.62,-0.003
50.44,113.48,-0.004
50.47,113.34,-0.005
50.49,113.20,-0.006
50.52,113.06,-0.008
50.55,112.92,-0.009
50.58,112.78,-0.010
50.61,112.64,-0.012
50.64,112.50,-0.013
50.66,112.35,-0.015
50.69,112.22,-0.016
50.72,112.07,-0.017
50.75,111.93,-0.018
50.78,111.79,-0.015
50.81,111.65,-0.014
50.84,111.51,-0.014
50.86,111.37,-0.014
50.89,111.22,-0.015
50.92,111.08,-0.016
50.95,110.94,-0.017
50.98,110.80,-0.018
51.01,110.66,-0.019
51.03,110.52,-0.021
51.06,110.38,-0.022
51.09,110.24,-0.022
51.12,110.10,-0.024
51.15,109.95,-0.025
51.18,109.81,-0.026
51.20,109.67,-0.026
51.23,109.53,-0.023
51.26,109.39,-0.023
51.29,109.25,-0.023
51.32,109.11,-0.023
51.34,108.96,-0.024
51.37,108.82,-0.024
51.40,108.68,-0.026
51.43,108.54,-0.027
51.46,108.40,-0.028
51.49,108.26,-0.029
51.51,108.12,-0.029
51.54,107.98,-0.031
51.57,107.84,-0.031
51.60,107.70,-0.032
51.63,107.55,-0.033
51.66,107.41,-0.033
51.69,107.27,-0.034
51.71,107.13,-0.033
51.74,106.99,-0.032
51.77,106.85,-0.032
51.80,106.71,-0.033
51.83,106.56,-0.033
51.86,106.42,-0.034
51.88,106.28,-0.034
51.91,106.14,-0.035
51.94,106.00,-0.036
51.97,105.86,-0.036
52.00,105.72,-0.037
52.03,105.57,-0.038
52.05,105.43,-0.038
52.08,105.29,-0.039
52.11,105.15,-0.040
52.14,105.01,-0.041
52.17,104.87,-0.041
52.19,104.73,-0.042
52.22,104.59,-0.041
52.25,104.45,-0.041
52.28,104.30,-0.041
52.31,104.16,-0.041
52.34,104.02,-0.041
52.36,103.88,-0.041
52.39,103.74,-0.042
52.42,103.60,-0.042
52.45,103.46,-0.043
52.48,103.31,-0.043
52.51,103.17,-0.044
52.54,103.03,-0.044
52.56,102.89,-0.045
52.59,102.75,-0.046
52.62,102.61,-0.046
52.65,102.47,-0.047
52.68,102.33,-0.047
52.71,102.18,-0.048
52.73,102.04,-0.048
52.76,101.90,-0.049
52.79,101.76,-0.048
52.82,101.62,-0.048
52.85,101.48,-0.048
52.88,101.33,-0.049
52.90,101.19,-0.049
52.93,101.05,-0.049
52.96,100.91,-0.050
52.99,100.77,-0.050
53.02,100.63,-0.050
53.04,100.49,-0.051
53.07,100.35,-0.051
53.10,100.21,-0.052
53.13,100.06,-0.052
53.16,99.92,-0.053
53.19,99.78,-0.053
53.21,99.64,-0.054
53.24,99.50,-0.054
[...]
134.23,124.54,-0.018,0.187
134.24,124.49,-0.018,0.187
134.25,124.44,-0.018,0.188
134.26,124.39,-0.018,0.188
134.27,124.34,-0.018,0.188
134.28,124.29,-0.018,0.188
134.29,124.24,-0.018,0.188
134.30,124.19,-0.018,0.189
134.31,124.14,-0.018,0.189
134.32,124.09,-0.018,0.189
134.33,124.04,-0.018,0.189
134.34,123.99,-0.018,0.190
134.35,123.94,-0.018,0.190
134.36,123.89,-0.018,0.190
134.37,123.84,-0.018,0.190
134.38,123.79,-0.018,0.190
134.39,123.74,-0.018,0.191
134.40,123.69,-0.018,0.191
134.41,123.64,-0.018,0.191
134.42,123.59,-0.018,0.191
134.43,123.54,-0.018,0.192
134.44,123.49,-0.018,0.192
134.45,123.44,-0.018,0.192
134.46,123.39,-0.018,0.192
134.47,123.34,-0.018,0.192
134.48,123.29,-0.018,0.192
134.49,123.24,-0.018,0.193
134.50,123.19,-0.018,0.193
134.51,123.14,-0.018,0.193
134.52,123.09,-0.018,0.193
134.53,123.04,-0.018,0.193
134.54,122.99,-0.018,0.194
134.55,122.94,-0.018,0.194
134.56,122.89,-0.018,0.194
134.57,122.84,-0.018,0.194
134.58,122.79,-0.018,0.195
134.59,122.74,-0.018,0.195
134.60,122.69,-0.018,0.195
134.61,122.64,-0.018,0.195
134.62,122.59,-0.018,0.195
134.63,122.54,-0.018,0.196
134.64,122.49,-0.018,0.196
134.65,122.44,-0.018,0.196
134.66,122.39,-0.018,0.196
134.67,122.34,-0.018,0.197
134.68,122.29,-0.019,0.197
134.69,122.24,-0.019,0.197
134.70,122.19,-0.019,0.197
134.71,122.14,-0.019,0.198
134.72,122.09,-0.019,0.198
134.73,122.04,-0.019,0.198
134.74,121.99,-0.019,0.198
134.75,121.94,-0.019,0.198
134.76,121.89,-0.019,0.199
134.77,121.84,-0.019,0.199
134.78,121.79,-0.019,0.199
134.79,121.74,-0.019,0.199
134.80,121.69,-0.019,0.199
134.81,121.64,-0.019,0.200
134.82,121.59,-0.019,0.200
134.83,121.54,-0.019,0.200
134.84,121.49,-0.019,0.200
134.85,121.44,-0.019,0.200
134.86,121.39,-0.019,0.201
134.87,121.34,-0.019,0.201
134.88,121.29,-0.019,0.201
134.89,121.24,-0.019,0.201
134.90,121.19,-0.019,0.202
134.91,121.14,-0.019,0.202
134.92,121.09,-0.019,0.202
134.93,121.04,-0.019,0.202
134.94,120.99,-0.019,0.202
134.95,120.94,-0.019,0.202
134.96,120.89,-0.019,0.203
134.97,120.84,-0.019,0.203
134.98,120.79,-0.019,0.203
134.99,120.74,-0.019,0.203
135.00,120.69,-0.019,0.203
135.01,120.64,-0.019,0.203
135.02,120.59,-0.019,0.204
135.03,120.54,-0.019,0.204
135.04,120.49,-0.019,0.204
135.05,120.44,-0.019,0.204
135.06,120.39,-0.019,0.205
135.07,120.34,-0.019,0.205
135.08,120.29,-0.019,0.205
135.09,120.24,-0.019,0.205
135.10,120.19,-0.019,0.205
135.11,120.14,-0.019,0.206
135.12,120.09,-0.019,0.206
135.13,120.04,-0.019,0.206
135.14,119.99,-0.019,0.206
135.15,119.94,-0.019,0.206
135.16,119.89,-0.019,0.206
135.17,119.84,-0.019,0.207
135.18,119.79,-0.019,0.207
135.19,119.74,-0.019,0.207
135.20,119.69,-0.019,0.207
135.21,119.64,-0.019,0.207
135.22,119.59,-0.019,0.207
135.23,119.54,-0.020,0.208
135.24,119.49,-0.020,0.208
135.25,119.44,-0.020,0.208
135.26,119.39,-0.020,0.208
135.27,119.34,-0.020,0.208
135.28,119.29,-0.020,0.209
135.29,119.24,-0.020,0.209
135.30,119.19,-0.020,0.209
135.31,119.14,-0.020,0.209
135.32,119.09,-0.020,0.209
135.33,119.04,-0.020,0.209
135.34,118.99,-0.020,0.209
135.35,118.94,-0.020,0.210
135.36,118.89,-0.020,0.210
135.37,118.84,-0.020,0.210
135.38,118.79,-0.020,0.210
135.39,118.74,-0.020,0.210
135.40,118.69,-0.020,0.211
135.41,118.64,-0.020,0.210
135.42,118.59,-0.020,0.211
135.43,118.54,-0.020,0.211
135.44,118.49,-0.020,0.211
135.45,118.44,-0.020,0.211
135.46,118.39,-0.020,0.211
135.47,118.34,-0.020,0.212
135.48,118.29,-0.020,0.212
135.49,118.24,-0.020,0.212
135.50,118.19,-0.020,0.212
135.51,118.14,-0.020,0.212
135.52,118.09,-0.020,0.212
135.53,118.04,-0.020,0.212
135.54,117.99,-0.020,0.213
135.55,117.94,-0.020,0.213
135.56,117.89,-0.020,0.213
135.57,117.84,-0.020,0.213
135.58,117.79,-0.020,0.214
135.59,117.74,-0.020,0.214
135.60,117.69,-0.020,0.214
135.61,117.64,-0.020,0.214
135.62,117.59,-0.020,0.214
135.63,117.54,-0.020,0.214
135.64,117.49,-0.020,0.215
135.65,117.44,-0.020,0.215
135.66,117.39,-0.020,0.215
135.67,117.34,-0.020,0.215
135.68,117.29,-0.020,0.215
135.69,117.24,-0.020,0.215
135.70,117.19,-0.020,0.216
135.71,117.14,-0.020,0.216
135.72,117.09,-0.020,0.216
135.73,117.04,-0.020,0.216
135.74,116.99,-0.020,0.216
135.75,116.94,-0.020,0.216
135.76,116.89,-0.020,0.216
135.77,116.84,-0.020,0.216
135.78,116.79,-0.020,0.217
135.79,116.74,-0.020,0.217
135.80,116.69,-0.020,0.217
135.81,116.64,-0.020,0.217
135.82,116.59,-0.020,0.217
135.83,116.54,-0.020,0.217
135.84,116.49,-0.020,0.218
135.85,116.44,-0.020,0.217
135.86,116.39,-0.020,0.218
135.87,116.34,-0.021,0.218
135.88,116.29,-0.021,0.218
135.89,116.24,-0.021,0.218
135.90,116.19,-0.021,0.218
135.91,116.14,-0.021,0.219
135.92,116.09,-0.021,0.219
135.93,116.04,-0.021,0.219
135.94,115.99,-0.021,0.219
135.95,115.94,-0.021,0.219
135.96,115.89,-0.021,0.220
135.97,115.84,-0.021,0.220
135.98,115.79,-0.021,0.220
135.99,115.74,-0.021,0.220
136.00,115.69,-0.021,0.220
136.01,115.64,-0.021,0.220
136.02,115.59,-0.021,0.220
136.03,115.54,-0.021,0.221
136.04,115.49,-0.021,0.221
136.05,115.44,-0.021,0.221
136.06,115.39,-0.021,0.221
136.07,115.34,-0.021,0.221
136.08,115.29,-0.021,0.221
136.09,115.24,-0.021,0.221
136.10,115.19,-0.021,0.221
136.11,115.14,-0.021,0.222
136.12,115.09,-0.021,0.222
136.13,115.04,-0.021,0.222
136.14,114.99,-0.021,0.222
136.15,114.94,-0.021,0.222
136.16,114.89,-0.021,0.222
136.17,114.84,-0.021,0.222
136.18,114.79,-0.021,0.222
136.19,114.74,-0.021,0.223
136.20,114.69,-0.021,0.223
136.21,114.64,-0.021,0.223
136.22,114.59,-0.021,0.223
136.23,114.54,-0.021,0.223
136.24,114.49,-0.021,0.223
136.25,114.44,-0.021,0.224
136.26,114.39,-0.021,0.224
136.27,114.34,-0.021,0.224
136.28,114.29,-0.021,0.224
136.29,114.24,-0.021,0.224
136.30,114.19,-0.021,0.224
136.31,114.14,-0.021,0.225
136.32,114.09,-0.021,0.224
136.33,114.04,-0.021,0.225
136.34,113.99,-0.021,0.225
136.35,113.94,-0.021,0.225
136.36,113.89,-0.021,0.225
136.37,113.84,-0.021,0.225
136.38,113.79,-0.021,0.225
136.39,113.74,-0.021,0.225
136.40,113.69,-0.021,0.226
136.41,113.64,-0.021,0.226
136.42,113.59,-0.021,0.226
136.43,113.54,-0.021,0.226
136.44,113.49,-0.021,0.226
136.45,113.44,-0.021,0.226
136.46,113.39,-0.021,0.226
136.47,113.34,-0.021,0.227
136.48,113.29,-0.021,0.227
136.49,113.24,-0.021,0.227
136.50,113.19,-0.021,0.227
136.51,113.14,-0.021,0.227
136.52,113.09,-0.021,0.227
136.53,113.04,-0.021,0.227
136.54,112.99,-0.021,0.227
136.55,112.94,-0.021,0.227
136.56,112.89,-0.021,0.228
136.57,112.84,-0.021,0.228
136.58,112.80,-0.021,0.228
136.59,112.74,-0.021,0.228
136.60,112.69,-0.021,0.228
136.61,112.64,-0.021,0.228
136.62,112.60,-0.021,0.228
136.63,112.54,-0.021,0.229
136.64,112.49,-0.022,0.229
136.65,112.44,-0.022,0.229
136.66,112.39,-0.022,0.229
136.67,112.34,-0.022,0.229
136.68,112.29,-0.022,0.229
136.69,112.24,-0.022,0.229
136.70,112.19,-0.022,0.230
136.71,112.14,-0.022,0.230
136.72,112.09,-0.022,0.230
136.73,112.04,-0.022,0.230
136.74,112.00,-0.022,0.230
136.75,111.94,-0.022,0.230
136.76,111.89,-0.022,0.230
136.77,111.84,-0.022,0.230
136.78,111.79,-0.022,0.230
136.79,111.74,-0.022,0.230
136.80,111.69,-0.022,0.231
136.81,111.64,-0.022,0.231
136.82,111.59,-0.022,0.231
136.83,111.54,-0.022,0.231
136.84,111.49,-0.022,0.231
136.85,111.44,-0.022,0.231
136.86,111.39,-0.022,0.232
136.87,111.34,-0.022,0.232
136.88,111.29,-0.022,0.232
136.89,111.24,-0.022,0.232
136.90,111.19,-0.022,0.232
136.91,111.14,-0.022,0.232
136.92,111.09,-0.022,0.232
136.93,111.04,-0.022,0.233
136.94,110.99,-0.022,0.233
136.95,110.94,-0.022,0.232
136.96,110.89,-0.022,0.233
136.97,110.84,-0.022,0.233
136.98,110.79,-0.022,0.233
136.99,110.74,-0.022,0.233
137.00,110.69,-0.022,0.233
137.01,110.64,-0.022,0.233
137.02,110.59,-0.022,0.234
137.03,110.54,-0.022,0.234
137.04,110.49,-0.022,0.234
137.05,110.44,-0.022,0.234
137.06,110.39,-0.022,0.234
137.07,110.34,-0.022,0.234
137.08,110.29,-0.022,0.234
137.09,110.24,-0.022,0.234
137.10,110.19,-0.022,0.234
137.11,110.14,-0.022,0.235
137.12,110.09,-0.022,0.235
137.13,110.04,-0.022,0.235
137.14,109.99,-0.022,0.235
137.15,109.94,-0.022,0.235
137.16,109.89,-0.022,0.235
137.17,109.84,-0.022,0.235
137.18,109.79,-0.022,0.235
137.19,109.74,-0.022,0.235
137.20,109.69,-0.022,0.236
137.21,109.64,-0.022,0.236
137.22,109.59,-0.022,0.236
137.23,109.54,-0.022,0.236
137.24,109.49,-0.022,0.236
137.25,109.44,-0.022,0.236
137.26,109.39,-0.022,0.236
137.27,109.34,-0.022,0.236
137.28,109.29,-0.022,0.236
137.29,109.24,-0.022,0.237
137.30,109.19,-0.022,0.237
137.31,109.14,-0.022,0.237
137.32,109.09,-0.022,0.237
137.33,109.04,-0.022,0.237
137.34,108.99,-0.022,0.237
137.35,108.94,-0.022,0.237
137.36,108.89,-0.022,0.237
137.37,108.84,-0.022,0.238
137.38,108.79,-0.022,0.238
137.39,108.74,-0.022,0.238
137.40,108.69,-0.022,0.238
137.41,108.64,-0.022,0.238
137.42,108.59,-0.022,0.238
137.43,108.54,-0.022,0.238
137.44,108.49,-0.022,0.238
137.45,108.44,-0.022,0.239
137.46,108.39,-0.022,0.238
137.47,108.34,-0.022,0.238
137.48,108.29,-0.022,0.239
137.49,108.24,-0.022,0.239
137.50,108.19,-0.022,0.239
137.51,108.14,-0.022,0.239
137.52,108.09,-0.022,0.239
137.53,108.04,-0.022,0.239
137.54,107.99,-0.022,0.239
137.55,107.94,-0.022,0.240
137.56,107.89,-0.023,0.240
137.57,107.84,-0.023,0.240
137.58,107.79,-0.023,0.240
137.59,107.74,-0.023,0.240
137.60,107.69,-0.023,0.240
137.61,107.64,-0.023,0.240
137.62,107.59,-0.023,0.240
137.63,107.54,-0.023,0.240
137.64,107.49,-0.023,0.240
137.65,107.44,-0.023,0.240
137.66,107.39,-0.023,0.240
137.67,107.34,-0.023,0.241
137.68,107.29,-0.023,0.241
137.69,107.24,-0.023,0.241
137.70,107.19,-0.023,0.241
137.71,107.14,-0.023,0.241
137.72,107.09,-0.023,0.241
137.73,107.04,-0.023,0.241
137.74,106.99,-0.023,0.241
137.75,106.94,-0.023,0.241
137.76,106.89,-0.023,0.241
137.77,106.84,-0.023,0.241
137.78,106.79,-0.023,0.242
137.79,106.74,-0.023,0.241
137.80,106.69,-0.023,0.241
137.81,106.64,-0.023,0.242
137.82,106.59,-0.023,0.242
137.83,106.54,-0.023,0.242
137.84,106.49,-0.023,0.242
137.85,106.44,-0.023,0.242
137.86,106.39,-0.023,0.242
137.87,106.34,-0.023,0.243
137.88,106.29,-0.023,0.243
137.89,106.24,-0.023,0.243
137.90,106.19,-0.023,0.243
137.91,106.14,-0.023,0.243
137.92,106.09,-0.023,0.243
137.93,106.04,-0.023,0.243
137.94,105.99,-0.023,0.243
137.95,105.94,-0.023,0.243
137.96,105.89,-0.023,0.243
137.97,105.84,-0.023,0.243
137.98,105.79,-0.023,0.244
137.99,105.74,-0.023,0.244
138.00,105.69,-0.023,0.244
138.01,105.65,-0.023,0.244
138.02,105.60,-0.023,0.244
138.03,105.54,-0.023,0.244
138.04,105.49,-0.023,0.244
138.05,105.45,-0.023,0.244
138.06,105.39,-0.023,0.244
138.07,105.34,-0.023,0.244
138.08,105.29,-0.023,0.244
138.09,105.24,-0.023,0.244
138.10,105.19,-0.023,0.244
138.11,105.14,-0.023,0.245
138.12,105.09,-0.023,0.245
138.13,105.04,-0.023,0.245
138.14,105.00,-0.023,0.245
138.15,104.94,-0.023,0.245
138.16,104.90,-0.023,0.245
138.17,104.84,-0.023,0.245
138.18,104.79,-0.023,0.245
138.19,104.74,-0.023,0.245
138.20,104.69,-0.023,0.246
138.21,104.64,-0.023,0.246
138.22,104.59,-0.023,0.246
138.23,104.54,-0.023,0.246
138.24,104.49,-0.023,0.246
138.25,104.44,-0.023,0.246
138.26,104.39,-0.023,0.246
138.27,104.34,-0.023,0.246
138.28,104.29,-0.023,0.246
138.29,104.24,-0.023,0.246
138.30,104.19,-0.023,0.246
138.31,104.14,-0.023,0.246
138.32,104.09,-0.023,0.246
138.33,104.04,-0.023,0.247
138.34,103.99,-0.023,0.247
138.35,103.94,-0.023,0.247
138.36,103.89,-0.023,0.247
138.37,103.84,-0.023,0.247
138.38,103.79,-0.023,0.247
138.39,103.74,-0.023,0.247
138.40,103.69,-0.023,0.247
138.41,103.64,-0.023,0.247
138.42,103.59,-0.023,0.247
138.43,103.54,-0.023,0.247
138.44,103.49,-0.023,0.247
138.45,103.44,-0.023,0.247
138.46,103.39,-0.023,0.247
138.47,103.34,-0.023,0.247
138.48,103.29,-0.023,0.248
138.49,103.24,-0.023,0.248
138.50,103.19,-0.023,0.248
138.51,103.14,-0.023,0.248
138.52,103.09,-0.023,0.248
138.53,103.04,-0.023,0.248
138.54,102.99,-0.023,0.248
138.55,102.94,-0.023,0.249
138.56,102.89,-0.023,0.248
138.57,102.84,-0.023,0.248
138.58,102.79,-0.023,0.248
138.59,102.74,-0.023,0.248
138.60,102.69,-0.023,0.248
138.61,102.64,-0.023,0.248
138.62,102.59,-0.023,0.249
138.63,102.54,-0.023,0.249
138.64,102.50,-0.023,0.249
138.65,102.44,-0.023,0.249
138.66,102.39,-0.023,0.249
138.67,102.34,-0.023,0.249
138.68,102.29,-0.023,0.249
138.69,102.24,-0.023,0.249
138.70,102.19,-0.023,0.249
138.71,102.14,-0.023,0.249
138.72,102.09,-0.023,0.249
138.73,102.04,-0.023,0.249
138.74,101.99,-0.023,0.249
138.75,101.94,-0.023,0.249
138.76,101.89,-0.023,0.249
138.77,101.84,-0.023,0.250
138.78,101.79,-0.023,0.250
138.79,101.74,-0.023,0.250
138.80,101.69,-0.023,0.250
138.81,101.64,-0.023,0.250
138.82,101.59,-0.023,0.250
138.83,101.54,-0.023,0.250
138.84,101.49,-0.023,0.250
138.85,101.44,-0.023,0.250
138.86,101.39,-0.023,0.250
138.87,101.34,-0.023,0.250
138.88,101.29,-0.023,0.250
138.89,101.24,-0.023,0.250
138.90,101.19,-0.023,0.250
138.91,101.14,-0.023,0.250
138.92,101.09,-0.023,0.250
138.93,101.04,-0.024,0.251
138.94,100.99,-0.024,0.251
138.95,100.94,-0.024,0.251
138.96,100.89,-0.024,0.251
138.97,100.84,-0.024,0.251
138.98,100.79,-0.024,0.251
138.99,100.74,-0.024,0.251
139.00,100.69,-0.024,0.251
139.01,100.64,-0.024,0.251
139.02,100.59,-0.024,0.251
139.03,100.54,-0.024,0.252
139.04,100.49,-0.024,0.252
139.05,100.44,-0.024,0.252
139.06,100.39,-0.024,0.252
139.07,100.34,-0.024,0.252
139.08,100.29,-0.024,0.252
139.09,100.24,-0.024,0.252
139.10,100.19,-0.024,0.252
139.11,100.14,-0.024,0.252
139.12,100.09,-0.024,0.252
139.13,100.04,-0.024,0.253
139.14,99.99,-0.024,0.253
139.15,99.94,-0.024,0.253
139.16,99.89,-0.024,0.252
139.17,99.84,-0.024,0.252
139.18,99.80,-0.024,0.253
139.19,99.75,-0.024,0.253
139.20,99.70,-0.024,0.253
139.21,99.65,-0.024,0.253
139.22,99.60,-0.024,0.253
139.23,99.55,-0.024,0.253
139.24,99.50,-0.024,0.253
139.25,99.45,-0.024,0.253
139.26,99.40,-0.024,0.253
139.27,99.35,-0.024,0.253
139.28,99.30,-0.024,0.253
139.29,99.25,-0.024,0.253
139.30,99.20,-0.024,0.253
139.31,99.15,-0.024,0.253
139.32,99.10,-0.024,0.253
139.33,99.05,-0.024,0.253
139.34,99.00,-0.024,0.253
139.35,98.95,-0.024,0.254
139.36,98.89,-0.024,0.254
139.37,98.84,-0.024,0.254
139.38,98.79,-0.024,0.254
139.39,98.74,-0.024,0.254
139.40,98.69,-0.024,0.254
139.41,98.64,-0.024,0.254
139.42,98.59,-0.024,0.254
139.43,98.54,-0.024,0.254
139.44,98.49,-0.024,0.255
139.45,98.44,-0.024,0.255
139.46,98.39,-0.024,0.255
139.47,98.34,-0.024,0.255
139.48,98.29,-0.024,0.255
139.49,98.24,-0.024,0.255
139.50,98.19,-0.024,0.255
139.51,98.14,-0.024,0.255
139.52,98.09,-0.024,0.255
139.53,98.04,-0.024,0.255
139.54,98.00,-0.024,0.256
139.55,97.94,-0.024,0.255
139.56,97.89,-0.024,0.255
139.57,97.84,-0.024,0.256
139.58,97.79,-0.024,0.256
139.59,97.74,-0.024,0.256
139.60,97.69,-0.024,0.256
139.61,97.64,-0.024,0.256
139.62,97.59,-0.024,0.256
139.63,97.54,-0.024,0.256
139.64,97.50,-0.024,0.256
139.65,97.45,-0.024,0.256
139.66,97.39,-0.024,0.256
139.67,97.34,-0.024,0.256
139.68,97.30,-0.024,0.256
139.69,97.25,-0.024,0.256
139.70,97.20,-0.024,0.256
139.71,97.15,-0.024,0.256
139.72,97.10,-0.024,0.256
139.73,97.05,-0.024,0.256
139.74,96.99,-0.024,0.256
139.75,96.95,-0.024,0.256
139.76,96.90,-0.024,0.256
139.77,96.85,-0.024,0.256
139.78,96.80,-0.024,0.257
139.79,96.75,-0.024,0.256
139.80,96.70,-0.024,0.256
139.81,96.64,-0.024,0.256
139.82,96.59,-0.024,0.256
139.83,96.55,-0.024,0.257
139.84,96.50,-0.024,0.257
139.85,96.45,-0.024,0.257
139.86,96.40,-0.024,0.266
139.87,96.35,-0.024,0.283
139.88,96.30,-0.024,0.282
139.89,96.25,-0.024,0.278
139.90,96.20,-0.024,0.275
139.91,96.15,-0.024,0.272
139.92,96.10,-0.024,0.270
139.93,96.05,-0.024,0.268
139.94,96.00,-0.024,0.266
139.95,95.95,-0.049,0.541
139.96,95.92,-0.425,4.648
139.97,95.95,-0.400,4.367
139.98,95.88,-0.059,0.646
139.99,95.82,-0.044,0.477
140.00,95.76,-0.033,0.358
140.01,95.70,-0.030,0.322
140.02,95.64,-0.029,0.313
140.03,95.59,-0.028,0.303
140.04,95.53,-0.028,0.301
140.05,95.48,-0.028,0.302
140.06,95.42,-0.027,0.288
140.07,95.37,-0.028,0.274
140.08,95.31,-0.028,0.271
140.09,95.26,-0.027,0.272
140.10,95.21,-0.027,0.276
140.11,95.16,-0.027,0.272
140.12,95.11,-0.027,0.279
140.13,95.05,-0.027,0.277
140.14,95.00,-0.027,0.277
140.15,94.95,-0.027,0.276
140.16,94.90,-0.027,0.281
140.17,94.85,-0.027,0.282
140.18,94.80,-0.027,0.282
140.19,94.75,-0.027,0.282
140.20,94.70,-0.027,0.282
140.21,94.65,-0.027,0.283
140.22,94.60,-0.027,0.283
140.23,94.55,-0.027,0.283
140.24,94.50,-0.027,0.283
140.25,94.45,-0.027,0.283
140.26,94.40,-0.027,0.283
140.27,94.35,-0.027,0.283
140.28,94.30,-0.027,0.283
140.29,94.25,-0.027,0.283
140.30,94.20,-0.027,0.283
140.31,94.15,-0.027,0.283
140.32,94.10,-0.027,0.282
140.33,94.05,-0.027,0.282
140.34,94.00,-0.026,0.282
140.35,93.95,-0.026,0.282
140.36,93.90,-0.026,0.282
140.37,93.85,-0.026,0.281
140.38,93.80,-0.026,0.281
140.39,93.75,-0.026,0.281
140.40,93.70,-0.026,0.281
140.41,93.65,-0.026,0.280
140.42,93.60,-0.026,0.280
140.43,93.55,-0.026,0.280
140.44,93.50,-0.026,0.280
140.45,93.45,-0.026,0.280
140.46,93.40,-0.026,0.280
140.47,93.35,-0.026,0.280
140.48,93.30,-0.026,0.280
140.49,93.25,-0.026,0.280
140.50,93.20,-0.026,0.280
140.51,93.15,-0.026,0.279
140.52,93.10,-0.026,0.279
140.53,93.05,-0.026,0.279
140.54,93.00,-0.026,0.279
140.55,92.95,-0.026,0.278
140.56,92.90,-0.026,0.278
140.57,92.85,-0.026,0.278
140.58,92.80,-0.026,0.278
140.59,92.75,-0.026,0.278
140.60,92.70,-0.026,0.278
140.61,92.65,-0.026,0.278
140.62,92.60,-0.026,0.278
140.63,92.55,-0.026,0.278
140.64,92.50,-0.026,0.278
140.65,92.45,-0.026,0.277
140.66,92.40,-0.026,0.277
140.67,92.35,-0.026,0.277
140.68,92.30,-0.026,0.277
140.69,92.25,-0.026,0.277
140.70,92.20,-0.026,0.277
140.71,92.15,-0.026,0.277
140.72,92.10,-0.026,0.276
140.73,92.05,-0.026,0.276
140.74,92.00,-0.026,0.276
140.75,91.95,-0.026,0.276
140.76,91.90,-0.026,0.276
140.77,91.85,-0.026,0.276
140.78,91.80,-0.026,0.276
140.79,91.75,-0.026,0.275
140.80,91.70,-0.026,0.276
140.81,91.65,-0.026,0.276
140.82,91.60,-0.026,0.275
140.83,91.55,-0.026,0.275
140.84,91.50,-0.026,0.275
140.85,91.45,-0.026,0.275
140.86,91.40,-0.026,0.275
140.87,91.35,-0.026,0.275
140.88,91.30,-0.026,0.275
140.89,91.25,-0.026,0.275
140.90,91.20,-0.026,0.275
140.91,91.15,-0.026,0.275
140.92,91.10,-0.026,0.275
140.93,91.05,-0.026,0.275
140.94,91.00,-0.026,0.275
140.95,90.95,-0.026,0.275
140.96,90.90,-0.026,0.275
140.97,90.85,-0.026,0.274
140.98,90.80,-0.026,0.275
140.99,90.75,-0.026,0.274
141.00,90.70,-0.026,0.274
141.01,90.65,-0.026,0.274
141.02,90.60,-0.026,0.274
141.03,90.55,-0.026,0.274
141.04,90.50,-0.026,0.274
141.05,90.45,-0.026,0.274
141.06,90.40,-0.026,0.274
141.07,90.34,-0.026,0.274
141.08,90.30,-0.026,0.274
141.09,90.25,-0.026,0.274
141.10,90.19,-0.026,0.274
141.11,90.15,-0.026,0.274
141.12,90.10,-0.026,0.274
141.13,90.05,-0.026,0.274
141.14,89.99,-0.026,0.274
141.15,89.94,-0.026,0.274
141.16,89.89,-0.026,0.274
141.17,89.84,-0.026,0.274
141.18,89.80,-0.026,0.273
141.19,89.74,-0.026,0.273
141.20,89.69,-0.026,0.273
141.21,89.65,-0.026,0.273
141.22,89.60,-0.026,0.273
141.23,89.55,-0.026,0.273
141.24,89.50,-0.026,0.273
141.25,89.45,-0.026,0.273
141.26,89.40,-0.026,0.273
141.27,89.35,-0.026,0.273
141.28,89.30,-0.026,0.273
141.29,89.25,-0.026,0.273
141.30,89.20,-0.026,0.273
141.31,89.15,-0.026,0.273
141.32,89.10,-0.026,0.273
141.33,89.05,-0.026,0.273
141.34,89.00,-0.026,0.273
141.35,88.95,-0.026,0.273
141.36,88.90,-0.025,0.273
141.37,88.85,-0.025,0.273
141.38,88.80,-0.025,0.272
141.39,88.75,-0.025,0.272
141.40,88.70,-0.025,0.272
141.41,88.65,-0.025,0.272
141.42,88.60,-0.025,0.272
141.43,88.55,-0.025,0.272
141.44,88.50,-0.025,0.272
141.45,88.45,-0.025,0.271
141.46,88.40,-0.025,0.272
141.47,88.35,-0.025,0.271
141.48,88.30,-0.025,0.271
141.49,88.25,-0.025,0.271
141.50,88.20,-0.025,0.271
141.51,88.15,-0.025,0.271
141.52,88.10,-0.025,0.271
141.53,88.05,-0.025,0.271
141.54,88.00,-0.025,0.271
141.55,87.95,-0.025,0.270
141.56,87.90,-0.025,0.270
141.57,87.85,-0.025,0.270
141.58,87.80,-0.025,0.269
141.59,87.75,-0.025,0.269
141.60,87.70,-0.025,0.269
141.61,87.65,-0.025,0.269
141.62,87.60,-0.025,0.268
141.63,87.55,-0.025,0.268
141.64,87.50,-0.025,
141.65,87.45,-0.025,
141.66,87.40,-0.025,
141.67,87.35,-0.025,
141.68,87.30,-0.025,
141.69,87.25,-0.025,
141.70,87.20,,
141.71,87.15,,
141.72,87.09,,
141.73,87.04,,
141.74,86.99,,
141.75,,,
141.75,,,