File: DSC/Earl/2025_10_06_PVP29_5Cmin_n60C_200C_x3.csv
Filename,2025_10_06_PVP29_5Cmin_n60C_200C_x3
Instrument name,DSC2A-00468 (192.168.1.100)
Operator,JLY
rundate,10/6/2025
Sample name,2025_10_06_PVP29_5Cmin_n60C_200C_x3
proceduresegments,Data Off ; Equilibrate -60.00 °C; Data On ; Ramp 5.00 °C/min to 200.00 °C; Data Off ; Isothermal 1.0 min; Data On ; Ramp 5.00 °C/min to -60.00 °C; Data Off ; Isothermal 1.0 min; Data On ; Ramp 5.00 °C/min to 200.00 °C; Data Off ; Isothermal 1.0 min; Data On ; Ramp 5.00 °C/min to -60.00 °C; Data Off ; Isothermal 1.0 min; Data On ; Ramp 5.00 °C/min to 200.00 °C
[File Parameters]
Run date,10/6/2025 1:54:37 PM
Trios version,5.1.1.46572
Original File Name,
Current File Name,D:\DSC2500\JYarger\2025_10_06_PVP29_5Cmin_n60C_200C_x3.tri
[Procedure]
Procedure Name,ASD_n60C_200C_5Cmin_x3
Sample Name,2025_10_06_PVP29_5Cmin_n60C_200C_x3
Sample Mass,4.36 mg
Reference Sample Mass,0 mg
Pan Mass,32.79 mg
Pan Number,39
Reference Pan Mass,32.55 mg
Reference Pan Number,1
Pan Type,Aluminum
Comments,DSC_Samples_Y2_Tray_ASDs_Pharma_Oct2025 Google Sheet.
Project Name,Amorphous Pharma
Operator,JLY
Test,Custom
Unload Max Temperature,30
Unload Min Temperature,30
Load Max Temperature,30
Load Min Temperature,30
Stop on Gas Flow Error,Yes
[Signal List]
Signal #1,Time (min)
Signal #2,Temperature (°C)
Signal #3,Heat Flow (mW)
Signal #4,Delta T (µV)
Signal #5,Delta Tzero (µV)
Signal #6,Tzero Temperature (°C)
Signal #7,Cell Purge (mL/min)
Signal #8,Heater Temp (°C)
Signal #9,Power Delivered (W)
Signal #10,Reference Junction Temperature (°C)
Signal #11,Flange Temperature (°C)
Signal #12,Heat Flow Phase (rad)
Signal #13,Total Heat Capacity (J/°C)
Signal #14,Heat Capacity (J/°C)
[Configuration]
Company Name,ASU
Instrument Name,DSC2A-00468
Instrument Type,DSC2500
Serial Number,DSC2A-00468
IP,192.168.1.100
Location of Instrument,MRRC
DisplayType,Unknown
Sample Interval ,0.1 s/pt
Selected Heat Flow,T4P
Exotherm Direction,Down
Cell Serial,DRC2-00792
Lid Type,Standard
Cooler,RCS 90
Leave Cooler on at End of Sequence,On
Gas 2,Nitrogen
Gas Selected,Channel 1
Flow Rate,50 mL/min
Secondary Purge,On
Licensed Heat Flow,Heat Flow T4P
Modulation Licensed,Yes
[Versions]
Common IDD Version,1
Cortex Version,VER 2.10.2.31
Driver,5.0.0.6
GDM Version,1.0.3.3
TouchscreenVersion,1.0.0.16145
FEP Version,1.2.1.21
FEP Bootloader,2.0.0.5
AutoSampler Version,2.1.1.26
Auto Sampler Bootloader,2.0.0.5
FCM Version,1.1.0.3
FCM Bootloader,2.0.0.5
[Experiment Logs]
Experiment Log Entry # 1,Data On set to 0
Experiment Log Entry # 3,Equilibrate Segment -60 (C) Started
Experiment Log Entry # 5,Air Cool is off.
Experiment Log Entry # 7,Data On set to 1
Experiment Log Entry # 9,Ramp Segment 5 C/min to 200 Started
Experiment Log Entry # 11,Data On set to 0
Experiment Log Entry # 13,Isothermal Segment 1 min started
Experiment Log Entry # 15,Data On set to 1
Experiment Log Entry # 17,Ramp Segment 5 C/min to -60 Started
Experiment Log Entry # 19,Data On set to 0
Experiment Log Entry # 21,Isothermal Segment 1 min started
Experiment Log Entry # 23,Data On set to 1
Experiment Log Entry # 25,Ramp Segment 5 C/min to 200 Started
Experiment Log Entry # 27,Data On set to 0
Experiment Log Entry # 29,Isothermal Segment 1 min started
Experiment Log Entry # 31,Data On set to 1
Experiment Log Entry # 33,Ramp Segment 5 C/min to -60 Started
Experiment Log Entry # 35,Auto sampler has detected that Cortex has gone offline
Experiment Log Entry # 37,Data On set to 0
Experiment Log Entry # 39,Isothermal Segment 1 min started
Experiment Log Entry # 41,Data On set to 1
Experiment Log Entry # 43,Ramp Segment 5 C/min to 200 Started
[Method Log]
Method Log Entry # 1,Data Off
Method Log Entry # 2,Equilibrate -60 °C
Method Log Entry # 3,Data On
Method Log Entry # 4,(Ramp 563267) Ramp 5 °C/minute to 200 °C
Method Log Entry # 5,Data Off
Method Log Entry # 6,Isothermal 1 minutes
Method Log Entry # 7,Data On
Method Log Entry # 8,(Ramp 563271) Ramp 5 °C/minute to -60 °C
Method Log Entry # 9,Data Off
Method Log Entry # 10,Isothermal 1 minutes
Method Log Entry # 11,Data On
Method Log Entry # 12,(Ramp 563275) Ramp 5 °C/minute to 200 °C
Method Log Entry # 13,Data Off
Method Log Entry # 14,Isothermal 1 minutes
Method Log Entry # 15,Data On
Method Log Entry # 16,(Ramp 563279) Ramp 5 °C/minute to -60 °C
Method Log Entry # 17,Data Off
Method Log Entry # 18,Isothermal 1 minutes
Method Log Entry # 19,Data On
Method Log Entry # 20,(Ramp 563283) Ramp 5 °C/minute to 200 °C
Cell Serial,DRC2-00792
[T1 Calibration]
Slope,-0.008529666
Offset,9.636258
Initial Temperature,98.23
GUID,f8bfdadc-4977-4fdf-ba6d-0ba9134940c3
[TZero Calibration]
Date Applied,11/29/2022 4:06:13 PM
Description,From -89.059 °C to 396.009 °C at 20.000°C/min
Gas Type,Nitrogen
Pan Type,None
Source Files 1,C:\Users\yargerlab\Desktop\DSC Data\General\TZero_calibration_11_29_22_2nd(2).tri
Source Files 2,C:\Users\yargerlab\Desktop\DSC Data\General\TZero_calibration_11_29_22_2nd(3).tri
Delta T Offset,13.05235
Delta T Slope,-0.007271007
Delta T0 Offset,-13.69128
Delta T0 Slope,0.06063341
[Temperature Calibration]
Date Applied,11/29/2022 7:12:28 PM
Description,From 106.590 °C to 186.590 °C at 10.000°C/min
Gas Type,Nitrogen
Pan Type,Tzero Aluminum Hermetic
Source Files 1,C:\Users\yargerlab\Desktop\DSC Data\General\Indium(6).tri
Measured 1,157.391
Known 1,156.598
[Cell Constant Calibration]
Date Applied,11/29/2022 7:12:29 PM
Description,From 106.590 °C to 186.590 °C at 10.000°C/min
Gas Type,Nitrogen
Pan Type,Tzero Aluminum Hermetic
Source Files 1,C:\Users\yargerlab\Desktop\DSC Data\General\Indium(6).tri
T4P KCell,1.006051
Onset Slope,63.26126 mW/°C
[Direct Cp Calibration]
Date Applied,11/30/2022 11:04:51 AM
Description,From -79.983 °C to 298.409 °C at 10.000°C/min
Gas Type,Nitrogen
Pan Type,Tzero Aluminum Hermetic
Source Files 1,C:\Users\yargerlab\Desktop\DSC Data\General\Sapphire_Heat_Capacity_11_30_22.tri
[Rev Cp Calibration]
Date Applied,11/30/2022 1:58:51 PM
Description,From -79.996 °C to 292.812 °C at 3.000°C/min
Gas Type,Nitrogen
Pan Type,Tzero Aluminum Hermetic
Source Files 1,C:\Users\yargerlab\Desktop\DSC Data\General\Sapphire_MDSC_Calibration_11_30_22.tri
[step]
Ramp 5.00 °C/min to 200.00 °C
Time,Temperature,Heat Flow (Normalized)
min,°C,W/g
0.00,-59.81,-0.051
0.03,-59.82,-0.045
0.07,-59.79,-0.041
0.11,-59.72,-0.042
0.14,-59.59,-0.028
0.18,-59.45,-0.001
0.21,-59.29,0.024
0.24,-59.14,0.041
0.28,-58.98,0.052
0.31,-58.81,0.059
0.35,-58.65,0.065
0.39,-58.48,0.068
0.42,-58.31,0.071
0.45,-58.14,0.073
0.49,-57.97,0.074
0.53,-57.80,0.075
0.56,-57.62,0.076
0.60,-57.45,0.077
0.63,-57.28,0.077
0.67,-57.10,0.078
0.70,-56.93,0.079
0.73,-56.76,0.079
0.77,-56.59,0.080
0.80,-56.41,0.080
0.84,-56.24,0.080
0.88,-56.06,0.081
0.91,-55.89,0.081
0.95,-55.72,0.081
0.98,-55.54,0.081
1.02,-55.37,0.082
1.05,-55.19,0.082
1.08,-55.02,0.082
1.12,-54.85,0.082
1.16,-54.67,0.082
1.19,-54.50,0.082
1.23,-54.32,0.083
1.26,-54.15,0.083
1.29,-53.97,0.083
1.33,-53.80,0.083
1.37,-53.62,0.083
1.40,-53.45,0.083
1.43,-53.28,0.083
1.47,-53.10,0.083
1.51,-52.92,0.083
1.54,-52.75,0.083
1.58,-52.58,0.083
1.61,-52.40,0.083
1.64,-52.23,0.083
1.68,-52.05,0.083
1.72,-51.88,0.083
1.75,-51.70,0.083
1.78,-51.53,0.083
1.82,-51.35,0.083
1.86,-51.18,0.083
1.89,-51.00,0.082
1.93,-50.83,0.082
1.96,-50.65,0.082
1.99,-50.48,0.082
2.03,-50.30,0.082
2.07,-50.13,0.082
2.10,-49.95,0.082
2.14,-49.78,0.082
2.17,-49.60,0.082
2.21,-49.43,0.082
2.24,-49.25,0.082
2.28,-49.08,0.082
2.31,-48.90,0.082
2.34,-48.73,0.082
2.38,-48.55,0.082
2.41,-48.38,0.082
2.45,-48.20,0.082
2.49,-48.03,0.082
2.52,-47.85,0.082
2.56,-47.68,0.082
2.59,-47.51,0.082
2.63,-47.33,0.082
2.66,-47.16,0.082
2.69,-46.98,0.082
2.73,-46.81,0.082
2.76,-46.63,0.082
2.80,-46.45,0.082
2.84,-46.28,0.082
2.87,-46.11,0.082
2.91,-45.93,0.082
2.94,-45.76,0.082
2.98,-45.58,0.082
3.01,-45.41,0.082
3.04,-45.23,0.082
3.08,-45.06,0.082
3.11,-44.88,0.082
3.15,-44.71,0.082
3.19,-44.53,0.082
3.22,-44.36,0.082
3.26,-44.18,0.082
3.29,-44.01,0.082
3.33,-43.83,0.082
3.36,-43.66,0.082
3.39,-43.48,0.082
3.43,-43.31,0.082
3.46,-43.13,0.082
3.50,-42.96,0.082
3.54,-42.78,0.082
3.57,-42.61,0.082
3.61,-42.43,0.082
3.64,-42.26,0.082
3.68,-42.08,0.082
3.71,-41.91,0.082
3.74,-41.73,0.082
3.78,-41.56,0.082
3.81,-41.38,0.082
3.85,-41.21,0.082
3.89,-41.03,0.082
3.92,-40.86,0.082
3.96,-40.68,0.082
3.99,-40.51,0.082
4.03,-40.33,0.082
4.06,-40.16,0.082
4.09,-39.98,0.082
4.13,-39.81,0.082
4.16,-39.63,0.082
4.20,-39.46,0.082
4.24,-39.28,0.082
4.27,-39.11,0.082
4.30,-38.93,0.082
4.34,-38.76,0.082
4.38,-38.58,0.082
4.41,-38.40,0.082
4.45,-38.23,0.082
4.48,-38.05,0.082
4.51,-37.88,0.082
4.55,-37.70,0.082
4.59,-37.53,0.082
4.62,-37.35,0.082
4.65,-37.18,0.082
4.69,-37.00,0.082
4.73,-36.83,0.082
4.76,-36.65,0.082
4.80,-36.48,0.082
4.83,-36.30,0.082
4.86,-36.13,0.082
4.90,-35.95,0.082
4.94,-35.78,0.082
4.97,-35.60,0.082
5.00,-35.43,0.082
5.04,-35.25,0.082
5.08,-35.08,0.082
5.11,-34.90,0.082
5.15,-34.72,0.082
5.18,-34.55,0.083
5.21,-34.37,0.083
5.25,-34.20,0.083
5.29,-34.02,0.083
5.32,-33.85,0.083
5.35,-33.67,0.083
5.39,-33.50,0.083
5.43,-33.32,0.083
5.46,-33.15,0.083
5.50,-32.97,0.083
5.53,-32.80,0.083
5.56,-32.63,0.083
5.60,-32.45,0.083
5.64,-32.28,0.083
5.67,-32.10,0.083
5.70,-31.93,0.083
5.74,-31.75,0.083
5.78,-31.58,0.083
5.81,-31.40,0.083
5.85,-31.22,0.083
5.88,-31.05,0.083
5.91,-30.87,0.083
5.95,-30.70,0.083
5.99,-30.52,0.083
6.02,-30.35,0.083
6.05,-30.17,0.083
6.09,-30.00,0.083
6.13,-29.82,0.083
6.16,-29.64,0.083
6.20,-29.47,0.083
6.23,-29.29,0.084
6.26,-29.12,0.084
6.30,-28.94,0.084
6.34,-28.77,0.084
6.37,-28.59,0.084
6.40,-28.41,0.084
6.44,-28.24,0.084
6.48,-28.06,0.084
6.51,-27.89,0.084
6.55,-27.72,0.084
6.58,-27.54,0.084
6.61,-27.37,0.084
6.65,-27.19,0.084
6.69,-27.02,0.084
6.72,-26.84,0.084
6.75,-26.67,0.084
6.79,-26.49,0.084
6.83,-26.32,0.084
6.86,-26.14,0.084
6.90,-25.97,0.084
6.93,-25.79,0.084
6.96,-25.61,0.084
7.00,-25.44,0.084
7.04,-25.26,0.084
7.07,-25.09,0.084
7.10,-24.91,0.084
7.14,-24.74,0.084
7.18,-24.56,0.084
7.21,-24.39,0.084
7.25,-24.21,0.084
7.28,-24.04,0.085
7.31,-23.86,0.085
7.35,-23.69,0.085
7.39,-23.51,0.085
7.42,-23.34,0.085
7.45,-23.16,0.085
7.49,-22.99,0.085
7.53,-22.81,0.085
7.56,-22.64,0.085
7.60,-22.46,0.085
7.63,-22.29,0.085
7.66,-22.11,0.085
7.70,-21.94,0.085
7.74,-21.76,0.085
7.77,-21.59,0.085
7.80,-21.41,0.085
7.84,-21.23,0.085
7.88,-21.06,0.085
7.91,-20.88,0.085
7.95,-20.71,0.085
7.98,-20.53,0.085
8.01,-20.36,0.086
8.05,-20.18,0.086
8.09,-20.01,0.086
8.12,-19.83,0.086
8.15,-19.66,0.086
8.19,-19.48,0.086
8.23,-19.31,0.086
8.26,-19.13,0.086
8.30,-18.96,0.086
8.33,-18.78,0.086
8.36,-18.61,0.086
8.40,-18.43,0.086
8.44,-18.26,0.086
8.47,-18.08,0.086
8.50,-17.91,0.086
8.54,-17.73,0.086
8.58,-17.56,0.086
8.61,-17.38,0.086
8.65,-17.21,0.086
8.68,-17.03,0.086
8.72,-16.86,0.086
8.75,-16.68,0.086
8.78,-16.51,0.086
8.82,-16.33,0.086
8.85,-16.15,0.086
8.89,-15.98,0.087
8.93,-15.81,0.087
8.96,-15.63,0.087
9.00,-15.45,0.087
9.03,-15.28,0.087
9.07,-15.10,0.087
9.10,-14.93,0.087
9.13,-14.75,0.087
9.17,-14.58,0.087
9.20,-14.40,0.087
9.24,-14.23,0.087
9.28,-14.05,0.087
9.31,-13.88,0.087
9.35,-13.70,0.087
9.38,-13.53,0.087
9.42,-13.35,0.087
9.45,-13.18,0.088
9.48,-13.00,0.088
9.52,-12.83,0.088
9.55,-12.65,0.088
9.59,-12.48,0.088
9.63,-12.30,0.088
9.66,-12.13,0.088
9.70,-11.95,0.088
9.73,-11.78,0.088
9.77,-11.60,0.088
9.80,-11.43,0.088
9.83,-11.25,0.088
9.87,-11.08,0.088
9.90,-10.90,0.088
9.94,-10.73,0.088
9.98,-10.55,0.088
10.01,-10.38,0.089
10.05,-10.20,0.089
10.08,-10.03,0.089
10.12,-9.85,0.089
10.15,-9.68,0.089
10.18,-9.50,0.089
10.22,-9.33,0.089
10.25,-9.15,0.089
10.29,-8.98,0.089
10.33,-8.80,0.089
10.36,-8.63,0.089
10.40,-8.45,0.089
10.43,-8.28,0.089
10.47,-8.10,0.090
10.50,-7.93,0.090
10.53,-7.75,0.090
10.57,-7.58,0.090
10.60,-7.40,0.090
10.64,-7.22,0.090
10.68,-7.05,0.090
10.71,-6.87,0.090
10.75,-6.70,0.090
10.78,-6.52,0.091
10.82,-6.35,0.091
10.85,-6.17,0.091
10.88,-6.00,0.091
10.92,-5.82,0.091
10.95,-5.65,0.091
10.99,-5.47,0.091
11.03,-5.29,0.091
11.06,-5.12,0.091
11.10,-4.94,0.091
11.13,-4.77,0.091
11.17,-4.59,0.091
11.20,-4.42,0.092
11.23,-4.24,0.092
11.27,-4.07,0.092
11.30,-3.89,0.092
11.34,-3.72,0.092
11.38,-3.54,0.092
11.41,-3.37,0.092
11.45,-3.19,0.092
11.48,-3.02,0.092
11.52,-2.84,0.092
11.55,-2.67,0.092
11.58,-2.49,0.092
11.62,-2.32,0.092
11.65,-2.14,0.092
11.69,-1.97,0.092
11.73,-1.79,0.092
11.76,-1.62,0.093
11.80,-1.44,0.093
11.83,-1.27,0.093
11.87,-1.09,0.093
11.90,-0.92,0.093
11.93,-0.74,0.093
11.97,-0.57,0.093
12.00,-0.39,0.093
12.04,-0.22,0.093
12.08,-0.04,0.093
12.11,0.13,0.093
12.15,0.31,0.094
12.18,0.48,0.094
12.22,0.66,0.094
12.25,0.83,0.094
12.28,1.01,0.094
12.32,1.18,0.094
12.35,1.36,0.094
12.39,1.53,0.094
12.43,1.71,0.094
12.46,1.89,0.094
12.50,2.06,0.095
12.53,2.24,0.095
12.57,2.41,0.095
12.60,2.59,0.095
12.63,2.76,0.095
12.67,2.94,0.095
12.70,3.11,0.095
12.74,3.29,0.095
12.78,3.46,0.095
12.81,3.64,0.095
12.85,3.81,0.096
12.88,3.99,0.096
12.92,4.16,0.096
12.95,4.34,0.096
12.98,4.51,0.096
13.02,4.69,0.096
13.05,4.86,0.096
13.09,5.04,0.096
13.13,5.21,0.096
13.16,5.39,0.097
13.20,5.56,0.097
13.23,5.74,0.097
13.27,5.91,0.097
13.30,6.09,0.097
13.33,6.26,0.097
13.37,6.44,0.097
13.40,6.61,0.098
13.44,6.79,0.098
13.48,6.96,0.098
13.51,7.14,0.098
13.55,7.31,0.098
13.58,7.49,0.098
13.62,7.66,0.098
13.65,7.84,0.098
13.68,8.01,0.099
13.72,8.19,0.099
13.75,8.36,0.099
13.79,8.54,0.099
13.83,8.71,0.099
13.86,8.89,0.099
13.90,9.07,0.099
13.93,9.24,0.100
13.97,9.42,0.100
14.00,9.59,0.100
14.03,9.77,0.100
14.07,9.94,0.100
14.10,10.12,0.100
14.14,10.29,0.101
14.18,10.47,0.101
14.21,10.64,0.101
14.25,10.82,0.101
14.28,10.99,0.101
14.32,11.17,0.101
14.35,11.34,0.102
14.38,11.52,0.102
14.42,11.69,0.102
14.45,11.87,0.102
14.49,12.04,0.102
14.53,12.22,0.102
14.56,12.39,0.103
14.60,12.57,0.103
14.63,12.74,0.103
14.67,12.92,0.103
14.70,13.09,0.103
14.73,13.27,0.104
14.77,13.44,0.104
14.80,13.62,0.104
14.84,13.79,0.104
14.88,13.97,0.104
14.91,14.14,0.104
14.95,14.32,0.105
14.98,14.49,0.105
15.02,14.67,0.105
15.05,14.84,0.105
15.08,15.02,0.105
15.12,15.19,0.106
15.15,15.37,0.106
15.19,15.54,0.106
15.23,15.72,0.106
15.26,15.89,0.106
15.30,16.07,0.107
15.33,16.25,0.107
15.37,16.42,0.107
15.40,16.60,0.107
15.43,16.77,0.107
15.47,16.94,0.108
15.50,17.12,0.108
15.54,17.30,0.108
15.58,17.47,0.108
15.61,17.65,0.108
15.65,17.82,0.109
15.68,18.00,0.109
15.72,18.17,0.109
15.75,18.35,0.109
15.78,18.52,0.110
15.82,18.70,0.110
15.85,18.87,0.110
15.89,19.05,0.110
15.93,19.22,0.111
15.96,19.40,0.111
16.00,19.57,0.111
16.03,19.75,0.111
16.07,19.92,0.111
16.10,20.10,0.112
16.13,20.27,0.112
16.17,20.45,0.112
16.20,20.62,0.113
16.24,20.80,0.113
16.28,20.97,0.113
16.31,21.15,0.113
16.35,21.32,0.114
16.38,21.50,0.114
16.42,21.67,0.114
16.45,21.85,0.114
16.48,22.02,0.115
16.52,22.20,0.115
16.55,22.37,0.115
16.59,22.55,0.115
16.63,22.72,0.116
16.66,22.90,0.116
16.70,23.07,0.116
16.73,23.25,0.117
16.77,23.42,0.117
16.80,23.60,0.117
16.83,23.77,0.118
16.87,23.95,0.118
16.90,24.12,0.118
16.94,24.30,0.118
16.98,24.47,0.119
17.01,24.65,0.119
17.05,24.82,0.119
17.08,25.00,0.120
17.12,25.17,0.120
17.15,25.35,0.120
17.18,25.52,0.121
17.22,25.70,0.121
17.26,25.87,0.121
17.29,26.05,0.122
17.33,26.22,0.122
17.36,26.40,0.122
17.39,26.57,0.123
17.43,26.75,0.123
17.47,26.92,0.123
17.50,27.10,0.124
17.53,27.27,0.124
17.57,27.45,0.124
17.61,27.62,0.125
17.64,27.80,0.125
17.68,27.97,0.125
17.71,28.15,0.126
17.74,28.32,0.126
17.78,28.50,0.127
17.82,28.67,0.127
17.85,28.85,0.127
17.88,29.02,0.128
17.92,29.20,0.128
17.96,29.38,0.128
17.99,29.55,0.129
18.03,29.72,0.129
18.06,29.90,0.130
18.09,30.07,0.130
18.13,30.25,0.130
18.17,30.42,0.131
18.20,30.60,0.131
18.23,30.77,0.132
18.27,30.95,0.132
18.31,31.12,0.132
18.34,31.30,0.133
18.38,31.47,0.133
18.41,31.65,0.134
18.44,31.83,0.134
18.48,32.00,0.135
18.52,32.17,0.135
18.55,32.35,0.135
18.58,32.53,0.136
18.62,32.70,0.136
18.66,32.87,0.137
18.69,33.05,0.137
18.73,33.23,0.138
18.76,33.40,0.138
18.79,33.57,0.139
18.83,33.75,0.139
18.87,33.93,0.140
18.90,34.10,0.140
18.93,34.28,0.141
18.97,34.45,0.141
19.01,34.63,0.142
19.04,34.80,0.142
19.08,34.98,0.143
19.11,35.15,0.143
19.14,35.33,0.144
19.18,35.50,0.144
19.22,35.68,0.145
19.25,35.85,0.145
19.28,36.03,0.146
19.32,36.20,0.146
19.36,36.38,0.147
19.39,36.55,0.147
19.43,36.72,0.148
19.46,36.90,0.148
19.49,37.07,0.149
19.53,37.25,0.150
19.57,37.43,0.150
19.60,37.60,0.151
19.63,37.77,0.151
19.67,37.95,0.152
19.71,38.13,0.152
19.74,38.30,0.153
19.78,38.48,0.154
19.81,38.65,0.154
19.84,38.83,0.155
19.88,39.00,0.155
19.92,39.18,0.156
19.95,39.35,0.157
19.98,39.53,0.157
20.02,39.70,0.158
20.06,39.87,0.159
20.09,40.05,0.159
20.13,40.22,0.160
20.16,40.40,0.161
20.19,40.58,0.161
20.23,40.75,0.162
20.27,40.92,0.162
20.30,41.10,0.163
20.33,41.27,0.164
20.37,41.45,0.164
20.41,41.62,0.165
20.44,41.80,0.166
20.48,41.97,0.166
20.51,42.15,0.167
20.54,42.32,0.168
20.58,42.50,0.169
20.62,42.67,0.169
20.65,42.85,0.170
20.68,43.02,0.171
20.72,43.20,0.172
20.76,43.37,0.172
20.79,43.55,0.173
20.83,43.72,0.174
20.86,43.90,0.175
20.89,44.07,0.175
20.93,44.25,0.176
20.97,44.42,0.177
21.00,44.60,0.178
21.03,44.77,0.179
21.07,44.95,0.179
21.11,45.12,0.180
21.14,45.29,0.181
21.18,45.47,0.182
21.21,45.65,0.183
21.24,45.82,0.183
21.28,46.00,0.184
21.32,46.17,0.185
21.35,46.35,0.186
21.38,46.52,0.187
21.42,46.69,0.188
21.46,46.87,0.189
21.49,47.04,0.190
21.53,47.22,0.191
21.56,47.39,0.191
21.59,47.57,0.192
21.63,47.74,0.193
21.67,47.92,0.194
21.70,48.09,0.195
21.73,48.27,0.196
21.77,48.44,0.197
21.81,48.62,0.198
21.84,48.79,0.199
21.88,48.97,0.200
21.91,49.14,0.201
21.94,49.32,0.202
21.98,49.49,0.203
22.02,49.67,0.204
22.05,49.84,0.205
22.08,50.02,0.206
22.12,50.19,0.207
22.16,50.37,0.208
22.19,50.54,0.209
22.23,50.72,0.210
22.26,50.89,0.211
22.29,51.07,0.213
22.33,51.24,0.214
22.37,51.42,0.215
22.40,51.59,0.216
22.43,51.77,0.217
22.47,51.94,0.218
22.51,52.11,0.219
22.54,52.29,0.220
22.58,52.47,0.222
22.61,52.64,0.223
22.64,52.81,0.224
22.68,52.99,0.225
22.72,53.16,0.226
22.75,53.34,0.228
22.78,53.51,0.229
22.82,53.69,0.230
22.86,53.86,0.231
22.89,54.04,0.233
22.93,54.21,0.234
22.96,54.39,0.235
22.99,54.56,0.236
23.03,54.74,0.238
23.07,54.91,0.239
23.10,55.09,0.240
23.13,55.26,0.241
23.17,55.43,0.243
23.21,55.61,0.244
23.24,55.78,0.246
23.28,55.96,0.247
23.31,56.13,0.248
23.34,56.31,0.250
23.38,56.48,0.251
23.42,56.66,0.253
23.45,56.83,0.254
23.48,57.01,0.256
23.52,57.18,0.257
23.56,57.36,0.259
23.59,57.53,0.260
23.63,57.71,0.262
23.66,57.88,0.263
23.69,58.06,0.265
23.73,58.23,0.266
23.77,58.41,0.268
23.80,58.58,0.269
23.83,58.75,0.271
23.87,58.93,0.273
23.91,59.10,0.275
23.94,59.28,0.276
23.98,59.45,0.278
24.01,59.63,0.280
24.04,59.80,0.281
24.08,59.98,0.283
24.12,60.15,0.285
24.15,60.33,0.287
24.18,60.50,0.289
24.22,60.68,0.290
24.26,60.85,0.292
24.29,61.03,0.294
24.33,61.20,0.295
24.36,61.37,0.297
24.39,61.55,0.299
24.43,61.72,0.300
24.47,61.90,0.302
24.50,62.07,0.303
24.53,62.25,0.305
24.57,62.42,0.306
24.61,62.60,0.308
24.64,62.77,0.309
24.68,62.95,0.311
24.71,63.12,0.312
24.74,63.29,0.313
24.78,63.47,0.315
24.82,63.64,0.316
24.85,63.82,0.317
24.88,63.99,0.319
24.92,64.17,0.320
24.96,64.34,0.321
24.99,64.52,0.323
25.03,64.69,0.324
25.06,64.87,0.325
25.09,65.04,0.327
25.13,65.22,0.328
25.17,65.39,0.329
25.20,65.57,0.331
25.23,65.74,0.332
25.27,65.92,0.333
25.31,66.09,0.335
25.34,66.27,0.336
25.38,66.44,0.337
25.41,66.62,0.339
25.44,66.79,0.340
25.48,66.97,0.342
25.52,67.14,0.343
25.55,67.32,0.345
25.58,67.49,0.347
25.62,67.66,0.348
25.66,67.84,0.350
25.69,68.01,0.351
25.73,68.19,0.353
25.76,68.36,0.354
25.79,68.54,0.356
25.83,68.71,0.358
25.87,68.89,0.360
25.90,69.06,0.362
25.93,69.24,0.363
25.97,69.41,0.365
26.01,69.59,0.367
26.04,69.76,0.368
26.08,69.93,0.370
26.11,70.11,0.372
26.14,70.28,0.374
26.18,70.46,0.375
26.22,70.63,0.377
26.25,70.81,0.379
26.28,70.98,0.380
26.32,71.16,0.382
26.36,71.33,0.384
26.39,71.51,0.386
26.43,71.68,0.388
26.46,71.86,0.390
26.49,72.03,0.392
26.53,72.21,0.394
26.57,72.38,0.395
26.60,72.55,0.397
26.63,72.73,0.399
26.67,72.90,0.401
26.71,73.08,0.403
26.74,73.25,0.405
26.78,73.43,0.407
26.81,73.60,0.408
26.84,73.78,0.410
26.88,73.95,0.412
26.92,74.13,0.413
26.95,74.30,0.415
26.98,74.48,0.417
27.02,74.65,0.419
27.06,74.83,0.421
27.09,75.00,0.423
27.13,75.18,0.424
27.16,75.35,0.426
27.19,75.52,0.428
27.23,75.70,0.430
27.27,75.87,0.431
27.30,76.05,0.433
27.33,76.22,0.435
27.37,76.40,0.437
27.41,76.57,0.439
27.44,76.75,0.441
27.48,76.92,0.442
27.51,77.10,0.444
27.54,77.27,0.446
27.58,77.45,0.448
27.62,77.62,0.450
27.65,77.79,0.451
27.68,77.97,0.453
27.72,78.14,0.455
27.76,78.32,0.457
27.79,78.49,0.458
27.83,78.67,0.460
27.86,78.84,0.462
27.89,79.02,0.464
27.93,79.19,0.465
27.97,79.37,0.467
28.00,79.54,0.469
28.03,79.72,0.471
28.07,79.89,0.472
28.11,80.06,0.474
28.14,80.24,0.475
28.18,80.41,0.477
28.21,80.59,0.479
28.24,80.76,0.481
28.28,80.94,0.483
28.32,81.11,0.484
28.35,81.29,0.486
28.38,81.46,0.488
28.42,81.64,0.489
28.46,81.81,0.491
28.49,81.99,0.493
28.53,82.16,0.494
28.56,82.34,0.496
28.59,82.51,0.497
28.63,82.68,0.499
28.67,82.86,0.501
28.70,83.04,0.503
28.73,83.21,0.504
28.77,83.38,0.506
28.81,83.56,0.507
28.84,83.73,0.509
28.88,83.91,0.510
28.91,84.08,0.512
28.94,84.26,0.513
28.98,84.43,0.514
29.02,84.61,0.516
29.05,84.78,0.517
29.08,84.96,0.519
29.12,85.13,0.520
29.16,85.31,0.522
29.19,85.48,0.523
29.23,85.66,0.524
29.26,85.83,0.526
29.29,86.01,0.527
29.33,86.18,0.529
29.37,86.36,0.530
29.40,86.53,0.531
29.43,86.71,0.532
29.47,86.88,0.534
29.51,87.06,0.535
29.54,87.23,0.536
29.58,87.41,0.537
29.61,87.58,0.538
29.64,87.76,0.540
29.68,87.93,0.541
29.72,88.11,0.542
29.75,88.28,0.543
29.78,88.45,0.544
29.82,88.63,0.545
29.86,88.80,0.546
29.89,88.98,0.547
29.93,89.15,0.548
29.96,89.33,0.549
29.99,89.50,0.550
30.03,89.68,0.550
30.07,89.85,0.551
30.10,90.03,0.552
30.13,90.20,0.553
30.17,90.38,0.554
30.21,90.55,0.554
30.24,90.73,0.555
30.28,90.90,0.556
30.31,91.08,0.556
30.34,91.25,0.557
30.38,91.43,0.557
30.42,91.60,0.558
30.45,91.78,0.558
30.48,91.95,0.559
30.52,92.13,0.559
30.56,92.30,0.560
30.59,92.48,0.560
30.63,92.65,0.560
30.66,92.83,0.560
30.69,93.00,0.560
30.73,93.18,0.561
30.77,93.35,0.561
30.80,93.53,0.561
30.83,93.71,0.561
30.87,93.88,0.561
30.91,94.06,0.561
30.94,94.23,0.560
30.98,94.41,0.560
31.01,94.58,0.560
31.04,94.76,0.560
31.08,94.93,0.559
31.12,95.11,0.559
31.15,95.28,0.558
31.18,95.46,0.558
31.22,95.63,0.557
31.26,95.81,0.557
31.29,95.98,0.556
31.33,96.16,0.556
31.36,96.33,0.555
31.39,96.51,0.554
31.43,96.69,0.553
31.47,96.86,0.553
31.50,97.04,0.552
31.53,97.21,0.551
31.57,97.39,0.550
31.61,97.56,0.549
31.64,97.74,0.547
31.68,97.91,0.546
31.71,98.09,0.545
31.74,98.26,0.544
31.78,98.44,0.543
31.82,98.62,0.541
31.85,98.79,0.540
31.88,98.97,0.538
31.92,99.14,0.537
31.96,99.32,0.535
31.99,99.49,0.533
32.03,99.67,0.532
32.06,99.84,0.530
32.09,100.02,0.528
32.13,100.20,0.527
32.17,100.37,0.525
32.20,100.55,0.523
32.23,100.72,0.521
32.27,100.90,0.520
32.31,101.08,0.518
32.34,101.25,0.516
32.38,101.43,0.513
32.41,101.60,0.511
32.44,101.78,0.509
32.48,101.95,0.507
32.52,102.13,0.505
32.55,102.31,0.503
32.58,102.48,0.500
32.62,102.66,0.498
32.66,102.83,0.495
32.69,103.01,0.493
32.73,103.18,0.490
32.76,103.36,0.488
32.79,103.54,0.486
32.83,103.71,0.483
32.87,103.89,0.481
32.90,104.06,0.479
32.93,104.24,0.476
32.97,104.41,0.473
33.01,104.59,0.470
33.04,104.76,0.468
33.08,104.94,0.465
33.11,105.12,0.463
33.14,105.29,0.461
33.18,105.47,0.459
33.22,105.65,0.456
33.25,105.82,0.454
33.28,106.00,0.451
33.32,106.17,0.449
33.36,106.35,0.446
33.39,106.52,0.443
33.43,106.70,0.441
33.46,106.87,0.438
33.49,107.05,0.436
33.53,107.23,0.433
33.57,107.40,0.430
33.60,107.58,0.428
33.63,107.76,0.424
33.67,107.93,0.422
33.71,108.11,0.419
33.74,108.28,0.416
33.78,108.46,0.414
33.81,108.63,0.411
33.84,108.81,0.409
33.88,108.99,0.407
33.92,109.16,0.405
33.95,109.34,0.402
33.98,109.51,0.398
34.02,109.69,0.396
34.06,109.87,0.394
34.09,110.04,0.391
34.13,110.22,0.388
34.16,110.39,0.386
34.19,110.57,0.383
34.23,110.74,0.381
34.26,110.92,0.378
34.30,111.10,0.376
34.34,111.27,0.373
34.37,111.45,0.370
34.41,111.62,0.368
34.44,111.80,0.365
34.48,111.98,0.363
34.51,112.15,0.360
34.54,112.33,0.358
34.58,112.50,0.355
34.61,112.68,0.353
34.65,112.85,0.350
34.69,113.03,0.347
34.72,113.21,0.345
34.76,113.38,0.343
34.79,113.56,0.341
34.83,113.73,0.338
34.86,113.91,0.335
34.89,114.09,0.333
34.93,114.26,0.330
34.96,114.44,0.328
35.00,114.61,0.325
35.04,114.79,0.323
35.07,114.96,0.321
35.11,115.14,0.319
35.14,115.31,0.316
35.18,115.49,0.313
35.21,115.67,0.311
35.24,115.84,0.309
35.28,116.02,0.307
35.31,116.19,0.305
35.35,116.37,0.302
35.39,116.54,0.299
35.42,116.72,0.297
35.46,116.90,0.295
35.49,117.07,0.292
35.53,117.25,0.291
35.56,117.42,0.288
35.59,117.60,0.285
35.63,117.78,0.283
35.66,117.95,0.281
35.70,118.13,0.279
35.74,118.30,0.277
35.77,118.48,0.274
35.81,118.65,0.272
35.84,118.83,0.270
35.88,119.01,0.268
35.91,119.18,0.266
35.94,119.36,0.263
35.98,119.53,0.261
36.01,119.71,0.259
36.05,119.88,0.257
36.09,120.06,0.255
36.12,120.23,0.253
36.16,120.41,0.251
36.19,120.59,0.249
36.23,120.76,0.247
36.26,120.94,0.245
36.29,121.11,0.243
36.33,121.29,0.240
36.36,121.47,0.238
36.40,121.64,0.236
36.44,121.82,0.235
36.47,121.99,0.233
36.51,122.17,0.231
36.54,122.34,0.229
36.58,122.52,0.227
36.61,122.69,0.225
36.64,122.87,0.223
36.68,123.05,0.222
36.71,123.22,0.220
36.75,123.40,0.218
36.79,123.57,0.216
36.82,123.75,0.214
36.86,123.92,0.213
36.89,124.10,0.211
36.93,124.27,0.209
36.96,124.45,0.207
36.99,124.63,0.205
37.03,124.80,0.204
37.06,124.98,0.202
37.10,125.15,0.200
37.14,125.33,0.198
37.17,125.50,0.197
37.21,125.68,0.195
37.24,125.85,0.193
37.28,126.03,0.192
37.31,126.21,0.190
37.34,126.38,0.188
37.38,126.56,0.187
37.41,126.73,0.185
37.45,126.91,0.184
37.49,127.08,0.182
37.52,127.26,0.180
37.56,127.43,0.179
37.59,127.61,0.178
37.63,127.79,0.176
37.66,127.96,0.174
37.69,128.14,0.173
37.73,128.31,0.171
37.76,128.49,0.170
37.80,128.66,0.168
37.84,128.84,0.167
37.87,129.01,0.165
37.91,129.19,0.164
37.94,129.36,0.162
37.98,129.54,0.161
38.01,129.71,0.160
38.04,129.89,0.158
38.08,130.07,0.157
38.11,130.24,0.156
38.15,130.42,0.155
38.19,130.59,0.153
38.22,130.77,0.152
38.26,130.94,0.151
38.29,131.12,0.150
38.33,131.29,0.149
38.36,131.47,0.147
38.39,131.65,0.146
38.43,131.82,0.145
38.46,132.00,0.144
38.50,132.17,0.143
38.54,132.35,0.142
38.57,132.52,0.141
38.61,132.70,0.139
38.64,132.87,0.138
38.68,133.05,0.137
38.71,133.22,0.136
38.74,133.40,0.135
38.78,133.57,0.134
38.81,133.75,0.133
38.85,133.92,0.132
38.89,134.10,0.131
38.92,134.27,0.130
38.96,134.45,0.129
38.99,134.63,0.128
39.03,134.80,0.128
39.06,134.98,0.127
39.09,135.15,0.126
39.13,135.33,0.125
39.16,135.50,0.124
39.20,135.68,0.123
39.24,135.85,0.123
39.27,136.03,0.122
39.31,136.20,0.121
39.34,136.38,0.120
39.38,136.55,0.120
39.41,136.73,0.119
39.44,136.90,0.118
39.48,137.08,0.117
39.51,137.26,0.117
39.55,137.43,0.116
39.59,137.61,0.115
39.62,137.78,0.115
39.66,137.96,0.114
39.69,138.13,0.114
39.73,138.31,0.113
39.76,138.48,0.113
39.79,138.66,0.112
39.83,138.83,0.112
39.86,139.01,0.111
39.90,139.18,0.111
39.94,139.36,0.110
39.97,139.53,0.110
40.01,139.71,0.109
40.04,139.88,0.109
40.08,140.06,0.108
40.11,140.23,0.108
40.14,140.41,0.108
40.18,140.58,0.107
40.21,140.76,0.107
40.25,140.93,0.107
40.29,141.11,0.106
40.32,141.29,0.106
40.36,141.46,0.106
40.39,141.64,0.106
40.43,141.81,0.105
40.46,141.99,0.105
40.49,142.16,0.105
40.53,142.34,0.105
40.56,142.51,0.104
40.60,142.69,0.104
40.64,142.86,0.104
40.67,143.04,0.104
40.71,143.21,0.104
40.74,143.39,0.104
40.78,143.56,0.103
40.81,143.74,0.103
40.84,143.91,0.103
40.88,144.09,0.103
40.91,144.26,0.103
40.95,144.44,0.103
40.99,144.61,0.103
41.02,144.79,0.103
41.06,144.96,0.103
41.09,145.14,0.103
41.13,145.31,0.103
41.16,145.49,0.103
41.19,145.66,0.103
41.23,145.84,0.103
41.26,146.01,0.103
41.30,146.19,0.103
41.34,146.36,0.103
41.37,146.54,0.103
41.41,146.71,0.103
41.44,146.89,0.103
41.48,147.06,0.103
41.51,147.24,0.103
41.54,147.41,0.103
41.58,147.59,0.104
41.61,147.76,0.104
41.65,147.94,0.104
41.69,148.11,0.104
41.72,148.29,0.104
41.76,148.46,0.104
41.79,148.64,0.105
41.83,148.81,0.105
41.86,148.99,0.105
41.89,149.16,0.105
41.93,149.34,0.105
41.96,149.51,0.106
42.00,149.69,0.106
42.04,149.86,0.106
42.07,150.04,0.107
42.11,150.21,0.107
42.14,150.39,0.107
42.18,150.56,0.107
42.21,150.74,0.108
42.24,150.91,0.108
42.28,151.09,0.108
42.31,151.26,0.109
42.35,151.44,0.109
42.39,151.61,0.110
42.42,151.79,0.110
42.46,151.96,0.110
42.49,152.14,0.111
42.53,152.31,0.111
42.56,152.49,0.111
42.59,152.66,0.112
42.63,152.84,0.112
42.66,153.01,0.112
42.70,153.19,0.113
42.74,153.36,0.113
42.77,153.54,0.113
42.81,153.71,0.114
42.84,153.89,0.114
42.88,154.06,0.115
42.91,154.24,0.115
42.94,154.41,0.115
42.98,154.59,0.115
43.01,154.76,0.116
43.05,154.94,0.116
43.09,155.11,0.116
43.12,155.29,0.117
43.16,155.46,0.117
43.19,155.64,0.117
43.23,155.81,0.117
43.26,155.99,0.118
43.29,156.16,0.118
43.33,156.34,0.118
43.36,156.51,0.118
43.40,156.69,0.118
43.44,156.86,0.118
43.47,157.04,0.118
43.51,157.21,0.118
43.54,157.39,0.118
43.58,157.56,0.119
43.61,157.74,0.119
43.64,157.91,0.119
43.68,158.09,0.119
43.71,158.26,0.119
43.75,158.44,0.119
43.79,158.61,0.119
43.82,158.79,0.119
43.86,158.96,0.119
43.89,159.14,0.119
43.93,159.32,0.119
43.96,159.49,0.119
43.99,159.67,0.118
44.03,159.84,0.118
44.06,160.02,0.118
44.10,160.19,0.118
44.14,160.37,0.118
44.17,160.54,0.118
44.21,160.72,0.118
44.24,160.89,0.118
44.28,161.07,0.118
44.31,161.24,0.118
44.34,161.42,0.118
44.38,161.59,0.118
44.41,161.77,0.118
44.45,161.94,0.118
44.49,162.12,0.118
44.52,162.29,0.118
44.56,162.47,0.118
44.59,162.64,0.118
44.63,162.81,0.118
44.66,162.99,0.118
44.69,163.17,0.118
44.73,163.34,0.118
44.76,163.52,0.118
44.80,163.69,0.118
44.84,163.87,0.119
44.87,164.04,0.119
44.91,164.22,0.119
44.94,164.39,0.119
44.98,164.57,0.119
45.01,164.74,0.119
45.04,164.92,0.119
45.08,165.09,0.119
45.11,165.27,0.119
45.15,165.44,0.119
45.19,165.62,0.119
45.22,165.79,0.119
45.26,165.97,0.119
45.29,166.14,0.119
45.33,166.32,0.119
45.36,166.49,0.119
45.39,166.67,0.119
45.43,166.84,0.119
45.46,167.02,0.120
45.50,167.19,0.120
45.54,167.37,0.120
45.57,167.54,0.120
45.61,167.72,0.120
45.64,167.89,0.120
45.68,168.07,0.120
45.71,168.24,0.120
45.74,168.42,0.120
45.78,168.59,0.120
45.81,168.77,0.120
45.85,168.94,0.121
45.89,169.12,0.121
45.92,169.30,0.121
45.96,169.47,0.121
45.99,169.65,0.121
46.03,169.82,0.121
46.06,169.99,0.121
46.09,170.17,0.121
46.13,170.34,0.121
46.16,170.52,0.121
46.20,170.69,0.121
46.24,170.87,0.121
46.27,171.05,0.121
46.31,171.22,0.122
46.34,171.40,0.122
46.38,171.57,0.122
46.41,171.75,0.122
46.44,171.92,0.122
46.48,172.10,0.122
46.51,172.27,0.122
46.55,172.45,0.122
46.59,172.62,0.122
46.62,172.80,0.122
46.66,172.97,0.122
46.69,173.15,0.123
46.73,173.32,0.123
46.76,173.50,0.123
46.79,173.67,0.123
46.83,173.85,0.123
46.86,174.02,0.123
46.90,174.20,0.123
46.94,174.37,0.123
46.97,174.54,0.123
47.01,174.72,0.123
47.04,174.90,0.123
47.08,175.07,0.123
47.11,175.24,0.124
47.14,175.42,0.124
47.18,175.60,0.124
47.21,175.77,0.124
47.25,175.95,0.124
47.29,176.12,0.124
47.32,176.30,0.124
47.36,176.47,0.124
47.39,176.65,0.124
47.43,176.82,0.125
47.46,177.00,0.125
47.49,177.17,0.125
47.53,177.35,0.125
47.56,177.52,0.125
47.60,177.70,0.125
47.64,177.87,0.125
47.67,178.05,0.125
47.71,178.22,0.125
47.74,178.40,0.125
47.78,178.57,0.125
47.81,178.75,0.125
47.84,178.92,0.125
47.88,179.10,0.126
47.91,179.27,0.126
47.95,179.45,0.126
47.99,179.62,0.126
48.02,179.80,0.126
48.06,179.97,0.126
48.09,180.15,0.126
48.13,180.32,0.126
48.16,180.50,0.126
48.19,180.67,0.126
48.23,180.85,0.126
48.26,181.02,0.127
48.30,181.20,0.127
48.34,181.37,0.127
48.37,181.55,0.127
48.41,181.72,0.127
48.44,181.90,0.127
48.48,182.07,0.127
48.51,182.25,0.127
48.54,182.42,0.127
48.58,182.60,0.128
48.61,182.77,0.128
48.65,182.95,0.128
48.69,183.12,0.128
48.72,183.30,0.128
48.76,183.47,0.128
48.79,183.65,0.128
48.83,183.82,0.128
48.86,184.00,0.128
48.89,184.17,0.129
48.93,184.35,0.129
48.96,184.52,0.129
49.00,184.70,0.129
49.04,184.87,0.129
49.07,185.05,0.129
49.11,185.22,0.129
49.14,185.40,0.129
49.18,185.57,0.129
49.21,185.75,0.130
49.24,185.92,0.130
49.28,186.10,0.130
49.31,186.27,0.130
49.35,186.45,0.130
49.39,186.62,0.130
49.42,186.80,0.130
49.46,186.98,0.131
49.49,187.15,0.131
49.53,187.33,0.131
49.56,187.50,0.131
49.59,187.68,0.131
49.63,187.85,0.131
49.66,188.02,0.131
49.70,188.20,0.131
49.74,188.37,0.131
49.77,188.55,0.131
49.81,188.72,0.132
49.84,188.90,0.132
49.88,189.07,0.132
49.91,189.25,0.132
49.94,189.43,0.132
49.98,189.60,0.132
50.01,189.77,0.132
50.05,189.95,0.132
50.09,190.13,0.132
50.12,190.30,0.133
50.16,190.48,0.133
50.19,190.65,0.133
50.23,190.82,0.133
50.26,191.00,0.133
50.29,191.18,0.133
50.33,191.35,0.133
50.36,191.53,0.133
50.40,191.70,0.133
50.44,191.88,0.134
50.47,192.05,0.134
50.51,192.23,0.134
50.54,192.40,0.134
50.58,192.57,0.134
50.61,192.75,0.134
50.64,192.93,0.134
50.68,193.10,0.134
50.71,193.28,0.135
50.75,193.45,0.135
50.79,193.63,0.135
50.82,193.80,0.135
50.86,193.98,0.135
50.89,194.15,0.135
50.93,194.33,0.135
50.96,194.50,0.135
50.99,194.68,0.135
51.03,194.85,0.135
51.06,195.03,0.136
51.10,195.20,0.136
51.14,195.38,0.136
51.17,195.55,0.136
51.21,195.73,0.136
51.24,195.90,0.136
51.28,196.08,0.136
51.31,196.25,0.136
51.34,196.43,0.136
51.38,196.60,0.137
51.41,196.78,0.137
51.45,196.95,0.137
51.49,197.13,0.137
51.52,197.30,0.137
51.56,197.48,0.137
51.59,197.65,0.137
51.63,197.83,0.137
51.66,198.00,0.137
51.69,198.18,0.137
51.73,198.35,0.138
51.76,198.53,0.138
51.80,198.70,0.138
51.84,198.88,0.138
51.87,199.05,0.138
51.91,199.23,0.138
51.94,199.40,
51.98,199.58,
51.99,,

[step]
Ramp 5.00 °C/min to -60.00 °C
Time,Temperature,Heat Flow (Normalized)
min,°C,W/g
52.99,200.16,-0.032
53.02,200.16,-0.032
53.06,200.14,-0.032
53.09,200.08,-0.037
53.13,199.98,-0.077
53.16,199.85,-0.120
53.20,199.70,-0.152
53.23,199.53,-0.173
53.27,199.37,-0.183
53.30,199.20,-0.188
53.34,199.03,-0.191
53.37,198.86,-0.193
53.41,198.68,-0.194
53.44,198.51,-0.195
53.48,198.34,-0.195
53.51,198.16,-0.196
53.55,197.99,-0.196
53.58,197.82,-0.196
53.62,197.64,-0.197
53.65,197.47,-0.197
53.69,197.30,-0.197
53.72,197.12,-0.198
53.76,196.95,-0.198
53.79,196.77,-0.198
53.83,196.60,-0.198
53.86,196.42,-0.199
53.90,196.25,-0.199
53.93,196.08,-0.199
53.97,195.90,-0.199
54.00,195.73,-0.199
54.04,195.55,-0.199
54.07,195.38,-0.199
54.11,195.20,-0.200
54.14,195.03,-0.200
54.18,194.86,-0.200
54.21,194.68,-0.200
54.25,194.51,-0.200
54.28,194.33,-0.200
54.32,194.16,-0.200
54.35,193.98,-0.200
54.39,193.81,-0.201
54.42,193.63,-0.201
54.46,193.46,-0.201
54.49,193.28,-0.201
54.53,193.11,-0.201
54.56,192.93,-0.201
54.60,192.76,-0.201
54.63,192.58,-0.201
54.67,192.41,-0.201
54.70,192.24,-0.201
54.74,192.06,-0.201
54.77,191.89,-0.201
54.81,191.71,-0.201
54.84,191.53,-0.201
54.88,191.36,-0.201
54.91,191.19,-0.201
54.95,191.01,-0.201
54.98,190.84,-0.201
55.02,190.66,-0.201
55.05,190.49,-0.201
55.09,190.31,-0.201
55.12,190.14,-0.201
55.16,189.96,-0.201
55.19,189.78,-0.201
55.23,189.61,-0.201
55.26,189.43,-0.201
55.30,189.26,-0.201
55.33,189.09,-0.202
55.37,188.91,-0.201
55.40,188.74,-0.201
55.44,188.56,-0.201
55.47,188.39,-0.201
55.51,188.21,-0.201
55.54,188.04,-0.201
55.58,187.86,-0.201
55.61,187.69,-0.201
55.65,187.51,-0.201
55.68,187.34,-0.201
55.72,187.16,-0.201
55.75,186.99,-0.201
55.79,186.81,-0.201
55.82,186.64,-0.201
55.86,186.46,-0.201
55.89,186.29,-0.201
55.93,186.11,-0.201
55.96,185.94,-0.201
56.00,185.76,-0.201
56.03,185.59,-0.201
56.07,185.41,-0.201
56.10,185.24,-0.201
56.14,185.06,-0.201
56.17,184.89,-0.201
56.21,184.71,-0.201
56.24,184.54,-0.201
56.28,184.36,-0.201
56.31,184.19,-0.201
56.35,184.01,-0.201
56.38,183.84,-0.201
56.42,183.66,-0.201
56.45,183.49,-0.201
56.49,183.31,-0.201
56.52,183.14,-0.201
56.56,182.96,-0.201
56.59,182.79,-0.201
56.63,182.61,-0.201
56.66,182.44,-0.201
56.70,182.26,-0.201
56.73,182.09,-0.201
56.77,181.91,-0.201
56.80,181.74,-0.201
56.84,181.56,-0.201
56.87,181.39,-0.201
56.91,181.21,-0.201
56.94,181.04,-0.201
56.98,180.86,-0.201
57.01,180.69,-0.201
57.05,180.51,-0.201
57.08,180.34,-0.201
57.12,180.16,-0.201
57.15,179.99,-0.201
57.19,179.81,-0.201
57.22,179.64,-0.201
57.26,179.46,-0.201
57.29,179.29,-0.201
57.33,179.11,-0.201
57.36,178.94,-0.201
57.40,178.76,-0.201
57.43,178.59,-0.201
57.47,178.41,-0.201
57.50,178.24,-0.201
57.54,178.06,-0.201
57.57,177.89,-0.201
57.61,177.71,-0.201
57.64,177.54,-0.201
57.68,177.36,-0.201
57.71,177.19,-0.201
57.75,177.01,-0.201
57.78,176.84,-0.201
57.82,176.66,-0.201
57.85,176.49,-0.201
57.89,176.31,-0.201
57.92,176.14,-0.201
57.96,175.96,-0.201
57.99,175.79,-0.201
58.03,175.61,-0.201
58.06,175.44,-0.201
58.10,175.26,-0.201
58.13,175.09,-0.201
58.17,174.91,-0.201
58.20,174.74,-0.201
58.24,174.56,-0.201
58.27,174.39,-0.201
58.31,174.21,-0.201
58.34,174.04,-0.201
58.38,173.86,-0.200
58.41,173.69,-0.200
58.45,173.52,-0.200
58.48,173.34,-0.200
58.52,173.17,-0.200
58.55,172.99,-0.200
58.59,172.81,-0.200
58.62,172.64,-0.200
58.66,172.46,-0.200
58.69,172.29,-0.200
58.73,172.11,-0.200
58.76,171.94,-0.200
58.80,171.76,-0.200
58.83,171.59,-0.200
58.87,171.41,-0.200
58.90,171.24,-0.200
58.94,171.06,-0.200
58.97,170.89,-0.200
59.01,170.71,-0.200
59.04,170.54,-0.200
59.08,170.36,-0.200
59.11,170.19,-0.200
59.15,170.01,-0.200
59.18,169.84,-0.199
59.22,169.66,-0.199
59.25,169.49,-0.199
59.29,169.31,-0.199
59.32,169.14,-0.199
59.36,168.96,-0.199
59.39,168.79,-0.199
59.43,168.61,-0.199
59.46,168.44,-0.199
59.50,168.26,-0.199
59.53,168.09,-0.199
59.57,167.92,-0.199
59.60,167.74,-0.199
59.64,167.57,-0.199
59.67,167.39,-0.199
59.71,167.21,-0.199
59.74,167.04,-0.198
59.78,166.86,-0.198
59.81,166.69,-0.198
59.85,166.51,-0.198
59.88,166.34,-0.198
59.92,166.16,-0.198
59.95,165.99,-0.198
59.99,165.81,-0.198
60.02,165.64,-0.198
60.06,165.46,-0.198
60.09,165.29,-0.197
60.13,165.11,-0.197
60.16,164.94,-0.197
60.20,164.76,-0.197
60.23,164.59,-0.197
60.27,164.41,-0.197
60.30,164.24,-0.197
60.34,164.07,-0.197
60.37,163.89,-0.196
60.41,163.71,-0.196
60.44,163.54,-0.196
60.48,163.36,-0.196
60.51,163.19,-0.196
60.55,163.01,-0.196
60.58,162.84,-0.196
60.62,162.66,-0.195
60.65,162.49,-0.195
60.69,162.31,-0.195
60.72,162.14,-0.195
60.76,161.96,-0.195
60.79,161.79,-0.195
60.83,161.61,-0.195
60.86,161.44,-0.194
60.90,161.26,-0.194
60.93,161.09,-0.194
60.97,160.91,-0.194
61.00,160.74,-0.194
61.04,160.56,-0.194
61.07,160.39,-0.193
61.11,160.21,-0.193
61.14,160.04,-0.193
61.18,159.86,-0.193
61.21,159.69,-0.193
61.25,159.51,-0.192
61.28,159.34,-0.192
61.32,159.16,-0.192
61.35,158.99,-0.192
61.39,158.81,-0.191
61.42,158.64,-0.191
61.46,158.46,-0.191
61.49,158.29,-0.191
61.53,158.11,-0.191
61.56,157.94,-0.191
61.60,157.76,-0.190
61.63,157.59,-0.190
61.67,157.41,-0.190
61.70,157.24,-0.190
61.74,157.06,-0.190
61.77,156.89,-0.189
61.81,156.71,-0.189
61.84,156.54,-0.189
61.88,156.36,-0.189
61.91,156.19,-0.189
61.95,156.01,-0.188
61.98,155.84,-0.188
62.02,155.66,-0.188
62.05,155.49,-0.188
62.09,155.31,-0.187
62.12,155.14,-0.187
62.16,154.96,-0.187
62.19,154.79,-0.187
62.23,154.61,-0.187
62.26,154.44,-0.187
62.30,154.26,-0.186
62.33,154.09,-0.186
62.37,153.91,-0.186
62.40,153.74,-0.186
62.44,153.56,-0.186
62.47,153.39,-0.185
62.51,153.21,-0.185
62.54,153.04,-0.185
62.58,152.86,-0.185
62.61,152.69,-0.185
62.65,152.51,-0.185
62.68,152.34,-0.184
62.72,152.16,-0.184
62.75,151.99,-0.184
62.79,151.81,-0.184
62.82,151.64,-0.184
62.86,151.46,-0.183
62.89,151.29,-0.183
62.93,151.11,-0.183
62.96,150.94,-0.183
63.00,150.76,-0.183
63.03,150.59,-0.182
63.07,150.41,-0.182
63.10,150.24,-0.182
63.14,150.06,-0.182
63.17,149.89,-0.182
63.21,149.71,-0.182
63.24,149.54,-0.181
63.28,149.36,-0.181
63.31,149.19,-0.181
63.35,149.01,-0.181
63.38,148.84,-0.181
63.42,148.66,-0.181
63.45,148.49,-0.181
63.49,148.31,-0.180
63.52,148.14,-0.180
63.56,147.96,-0.180
63.59,147.79,-0.180
63.63,147.61,-0.180
63.66,147.44,-0.180
63.70,147.26,-0.180
63.73,147.09,-0.179
63.77,146.91,-0.179
63.80,146.73,-0.179
63.84,146.56,-0.179
63.87,146.38,-0.179
63.91,146.21,-0.179
63.94,146.04,-0.179
63.98,145.86,-0.179
64.01,145.69,-0.178
64.05,145.51,-0.178
64.08,145.34,-0.178
64.12,145.16,-0.178
64.15,144.99,-0.178
64.19,144.81,-0.178
64.22,144.63,-0.178
64.26,144.46,-0.177
[...]
236.80,63.59,0.072,0.773
236.84,63.77,0.073,0.773
236.87,63.95,0.073,0.774
236.91,64.12,0.073,0.774
236.94,64.30,0.073,0.775
236.98,64.47,0.073,0.775
237.01,64.65,0.073,0.775
237.05,64.82,0.073,0.776
237.08,65.00,0.073,0.777
237.12,65.17,0.073,0.777
237.15,65.35,0.073,0.776
237.19,65.52,0.073,0.777
237.22,65.70,0.073,0.777
237.26,65.87,0.073,0.778
237.29,66.05,0.073,0.777
237.33,66.22,0.073,0.778
237.36,66.40,0.073,0.779
237.40,66.57,0.073,0.780
237.43,66.75,0.073,0.780
237.47,66.92,0.073,0.780
237.50,67.10,0.073,0.781
237.54,67.27,0.073,0.782
237.57,67.45,0.073,0.782
237.61,67.62,0.073,0.782
237.64,67.80,0.073,0.782
237.68,67.97,0.073,0.783
237.71,68.15,0.073,0.783
237.75,68.32,0.073,0.784
237.78,68.50,0.073,0.784
237.82,68.67,0.074,0.785
237.85,68.85,0.074,0.785
237.89,69.02,0.074,0.785
237.92,69.20,0.074,0.786
237.96,69.37,0.074,0.786
237.99,69.55,0.074,0.785
238.03,69.72,0.074,0.785
238.06,69.90,0.074,0.786
238.10,70.07,0.074,0.787
238.13,70.25,0.074,0.788
238.17,70.42,0.074,0.788
238.20,70.60,0.074,0.789
238.24,70.78,0.074,0.790
238.27,70.95,0.074,0.790
238.31,71.13,0.074,0.791
238.34,71.30,0.074,0.792
238.38,71.48,0.074,0.792
238.41,71.65,0.074,0.793
238.45,71.83,0.074,0.793
238.48,72.00,0.074,0.795
238.52,72.18,0.074,0.795
238.55,72.35,0.074,0.794
238.59,72.53,0.074,0.794
238.62,72.70,0.075,0.795
238.66,72.88,0.075,0.794
238.69,73.05,0.075,0.795
238.73,73.23,0.075,0.796
238.76,73.40,0.075,0.797
238.80,73.58,0.075,0.797
238.83,73.75,0.075,0.798
238.87,73.93,0.075,0.798
238.90,74.10,0.075,0.798
238.94,74.28,0.075,0.798
238.97,74.45,0.075,0.799
239.01,74.63,0.075,0.800
239.04,74.80,0.075,0.800
239.08,74.98,0.075,0.801
239.11,75.15,0.075,0.801
239.15,75.33,0.075,0.801
239.18,75.50,0.075,0.803
239.22,75.68,0.075,0.803
239.25,75.85,0.075,0.802
239.29,76.03,0.075,0.802
239.32,76.20,0.075,0.803
239.36,76.38,0.075,0.804
239.39,76.55,0.075,0.803
239.43,76.73,0.075,0.803
239.46,76.90,0.075,0.804
239.50,77.08,0.075,0.804
239.53,77.25,0.076,0.805
239.57,77.43,0.076,0.805
239.60,77.60,0.076,0.807
239.64,77.78,0.076,0.807
239.67,77.96,0.076,0.808
239.71,78.13,0.076,0.807
239.74,78.30,0.076,0.808
239.78,78.48,0.076,0.809
239.81,78.66,0.076,0.809
239.85,78.83,0.076,0.809
239.88,79.00,0.076,0.809
239.92,79.18,0.076,0.810
239.95,79.36,0.076,0.810
239.99,79.53,0.076,0.811
240.02,79.71,0.076,0.812
240.06,79.88,0.076,0.813
240.09,80.06,0.076,0.813
240.13,80.23,0.076,0.814
240.16,80.41,0.076,0.815
240.20,80.58,0.076,0.815
240.23,80.76,0.076,0.815
240.27,80.93,0.076,0.815
240.30,81.11,0.076,0.816
240.34,81.28,0.077,0.816
240.37,81.46,0.077,0.816
240.41,81.63,0.077,0.817
240.44,81.81,0.077,0.817
240.48,81.98,0.077,0.818
240.51,82.16,0.077,0.818
240.55,82.33,0.077,0.819
240.58,82.51,0.077,0.820
240.62,82.69,0.077,0.820
240.65,82.86,0.077,0.821
240.69,83.03,0.077,0.820
240.72,83.21,0.077,0.821
240.76,83.38,0.077,0.821
240.79,83.56,0.077,0.820
240.83,83.74,0.077,0.821
240.86,83.91,0.077,0.823
240.90,84.09,0.077,0.822
240.93,84.26,0.077,0.823
240.97,84.44,0.077,0.823
241.00,84.61,0.077,0.824
241.04,84.78,0.077,0.824
241.07,84.96,0.077,0.823
241.11,85.13,0.077,0.823
241.14,85.31,0.077,0.823
241.18,85.48,0.077,0.824
241.21,85.66,0.077,0.824
241.25,85.83,0.077,0.824
241.28,86.01,0.077,0.824
241.32,86.19,0.077,0.824
241.35,86.36,0.077,0.825
241.39,86.54,0.077,0.825
241.42,86.71,0.077,0.825
241.46,86.89,0.077,0.826
241.49,87.06,0.077,0.826
241.53,87.24,0.077,0.827
241.56,87.41,0.077,0.827
241.60,87.59,0.078,0.828
241.63,87.76,0.078,0.829
241.67,87.94,0.078,0.828
241.70,88.11,0.078,0.829
241.74,88.28,0.078,0.830
241.77,88.46,0.078,0.829
241.81,88.64,0.078,0.829
241.84,88.81,0.078,0.830
241.88,88.99,0.078,0.830
241.91,89.16,0.078,0.830
241.95,89.34,0.078,0.831
241.98,89.51,0.078,0.832
242.02,89.69,0.078,0.833
242.05,89.86,0.078,0.834
242.09,90.04,0.078,0.835
242.12,90.21,0.078,0.836
242.16,90.39,0.078,0.836
242.19,90.56,0.078,0.837
242.23,90.74,0.078,0.836
242.26,90.91,0.078,0.836
242.30,91.09,0.078,0.836
242.33,91.26,0.078,0.836
242.37,91.44,0.078,0.837
242.40,91.61,0.079,0.838
242.44,91.79,0.079,0.837
242.47,91.96,0.079,0.837
242.51,92.14,0.079,0.838
242.54,92.31,0.079,0.840
242.58,92.49,0.079,0.840
242.61,92.66,0.079,0.841
242.65,92.84,0.079,0.843
242.68,93.01,0.079,0.843
242.72,93.19,0.079,0.843
242.75,93.36,0.079,0.843
242.79,93.54,0.079,0.843
242.82,93.71,0.079,0.843
242.86,93.89,0.079,0.844
242.89,94.06,0.079,0.844
242.93,94.24,0.079,0.844
242.96,94.41,0.079,0.844
243.00,94.59,0.079,0.844
243.03,94.77,0.079,0.844
243.07,94.94,0.079,0.845
243.10,95.11,0.079,0.846
243.14,95.29,0.080,0.847
243.17,95.47,0.080,0.847
243.21,95.64,0.080,0.848
243.24,95.82,0.080,0.850
243.28,95.99,0.080,0.851
243.31,96.17,0.080,0.852
243.35,96.34,0.080,0.853
243.38,96.52,0.080,0.854
243.42,96.69,0.080,0.855
243.45,96.87,0.080,0.854
243.49,97.04,0.080,0.854
243.52,97.21,0.080,0.853
243.56,97.39,0.080,0.853
243.59,97.57,0.080,0.852
243.63,97.74,0.080,0.853
243.66,97.92,0.080,0.853
243.70,98.09,0.080,0.854
243.73,98.27,0.080,0.854
243.77,98.44,0.080,0.854
243.80,98.62,0.080,0.855
243.84,98.79,0.080,0.856
243.87,98.97,0.080,0.856
243.91,99.14,0.080,0.857
243.94,99.32,0.080,0.858
243.98,99.49,0.080,0.859
244.01,99.67,0.081,0.859
244.05,99.84,0.081,0.858
244.08,100.02,0.081,0.858
244.12,100.19,0.080,0.858
244.15,100.37,0.081,0.858
244.19,100.54,0.081,0.858
244.22,100.72,0.081,0.858
244.26,100.89,0.081,0.859
244.29,101.07,0.081,0.860
244.33,101.24,0.081,0.859
244.36,101.42,0.081,0.861
244.40,101.59,0.081,0.861
244.43,101.77,0.081,0.862
244.47,101.94,0.081,0.864
244.50,102.12,0.081,0.865
244.54,102.29,0.081,0.865
244.57,102.47,0.081,0.865
244.61,102.64,0.081,0.866
244.64,102.82,0.081,0.865
244.68,103.00,0.081,0.865
244.71,103.17,0.081,0.864
244.75,103.35,0.081,0.865
244.78,103.52,0.081,0.866
244.82,103.69,0.081,0.866
244.85,103.87,0.081,0.867
244.89,104.04,0.081,0.867
244.92,104.22,0.082,0.868
244.96,104.40,0.082,0.869
244.99,104.57,0.082,0.868
245.03,104.75,0.082,0.869
245.06,104.92,0.082,0.869
245.10,105.10,0.082,0.869
245.13,105.27,0.082,0.870
245.17,105.45,0.082,0.869
245.20,105.62,0.082,0.871
245.24,105.80,0.082,0.871
245.27,105.97,0.082,0.872
245.31,106.15,0.082,0.872
245.34,106.32,0.082,0.872
245.38,106.50,0.082,0.872
245.41,106.67,0.082,0.872
245.45,106.85,0.082,0.872
245.48,107.02,0.082,0.872
245.52,107.20,0.082,0.873
245.55,107.37,0.082,0.873
245.59,107.55,0.082,0.874
245.62,107.72,0.082,0.875
245.66,107.90,0.082,0.876
245.69,108.07,0.082,0.876
245.73,108.25,0.082,0.876
245.76,108.42,0.082,0.876
245.80,108.60,0.082,0.877
245.83,108.77,0.082,0.877
245.87,108.95,0.082,0.877
245.90,109.12,0.083,0.877
245.94,109.30,0.083,0.877
245.97,109.47,0.083,0.878
246.01,109.65,0.083,0.879
246.04,109.82,0.083,0.880
246.08,110.00,0.083,0.881
246.11,110.17,0.083,0.881
246.15,110.35,0.083,0.882
246.18,110.52,0.083,0.882
246.22,110.70,0.083,0.880
246.25,110.87,0.083,0.880
246.29,111.05,0.083,0.881
246.32,111.22,0.083,0.881
246.36,111.40,0.083,0.882
246.39,111.57,0.083,0.883
246.43,111.75,0.083,0.884
246.46,111.92,0.083,0.885
246.50,112.10,0.083,0.885
246.53,112.28,0.083,0.886
246.57,112.45,0.083,0.886
246.60,112.63,0.083,0.887
246.64,112.80,0.083,0.887
246.67,112.97,0.084,0.888
246.71,113.15,0.083,0.887
246.74,113.33,0.083,0.887
246.78,113.50,0.084,0.887
246.81,113.68,0.084,0.888
246.85,113.85,0.084,0.889
246.88,114.03,0.084,0.889
246.92,114.20,0.084,0.889
246.95,114.38,0.084,0.889
246.99,114.55,0.084,0.890
247.02,114.73,0.084,0.891
247.06,114.90,0.084,0.891
247.09,115.08,0.084,0.892
247.13,115.25,0.084,0.891
247.16,115.43,0.084,0.892
247.20,115.60,0.084,0.891
247.23,115.78,0.084,0.891
247.27,115.95,0.084,0.892
247.30,116.13,0.084,0.892
247.34,116.30,0.084,0.894
247.37,116.48,0.084,0.894
247.41,116.65,0.084,0.895
247.44,116.83,0.084,0.895
247.48,117.00,0.084,0.897
247.51,117.18,0.084,0.896
247.55,117.35,0.084,0.897
247.58,117.53,0.084,0.896
247.62,117.70,0.084,0.896
247.65,117.88,0.084,0.896
247.69,118.05,0.084,0.895
247.72,118.23,0.084,0.896
247.76,118.40,0.084,0.897
247.79,118.58,0.085,0.898
247.83,118.75,0.085,0.899
247.86,118.93,0.085,0.899
247.90,119.10,0.085,0.899
247.93,119.28,0.085,0.900
247.97,119.45,0.085,0.901
248.00,119.63,0.085,0.901
248.04,119.80,0.085,0.901
248.07,119.98,0.085,0.901
248.11,120.15,0.085,0.900
248.14,120.33,0.085,0.900
248.18,120.50,0.085,0.900
248.21,120.68,0.085,0.901
248.25,120.86,0.085,0.901
248.28,121.03,0.085,0.902
248.32,121.20,0.085,0.902
248.35,121.38,0.085,0.903
248.39,121.56,0.085,0.904
248.42,121.73,0.085,0.905
248.46,121.91,0.085,0.906
248.49,122.08,0.085,0.906
248.53,122.26,0.085,0.908
248.56,122.43,0.085,0.907
248.60,122.61,0.085,0.907
248.63,122.78,0.085,0.908
248.67,122.96,0.085,0.908
248.70,123.13,0.085,0.908
248.74,123.30,0.085,0.908
248.77,123.48,0.085,0.908
248.81,123.66,0.085,0.907
248.84,123.83,0.086,0.907
248.88,124.01,0.086,0.907
248.91,124.18,0.086,0.908
248.95,124.36,0.086,0.909
248.98,124.53,0.086,0.910
249.02,124.71,0.086,0.911
249.05,124.88,0.086,0.912
249.09,125.06,0.086,0.912
249.12,125.23,0.086,0.912
249.16,125.41,0.086,0.913
249.19,125.58,0.086,0.913
249.23,125.76,0.086,0.913
249.26,125.93,0.086,0.913
249.30,126.11,0.086,0.914
249.33,126.28,0.086,0.913
249.37,126.46,0.086,0.913
249.40,126.63,0.086,0.914
249.44,126.81,0.086,0.913
249.47,126.98,0.086,0.914
249.51,127.16,0.086,0.913
249.54,127.33,0.086,0.914
249.58,127.51,0.086,0.915
249.61,127.68,0.086,0.914
249.65,127.86,0.086,0.915
249.68,128.03,0.086,0.916
249.72,128.21,0.086,0.917
249.75,128.38,0.086,0.918
249.79,128.56,0.086,0.918
249.82,128.73,0.086,0.918
249.86,128.91,0.086,0.917
249.89,129.08,0.086,0.916
249.93,129.26,0.086,0.915
249.96,129.43,0.086,0.915
250.00,129.61,0.087,0.916
250.03,129.78,0.087,0.918
250.07,129.96,0.087,0.919
250.10,130.13,0.087,0.920
250.14,130.31,0.087,0.920
250.17,130.48,0.087,0.921
250.21,130.66,0.087,0.921
250.24,130.84,0.087,0.921
250.28,131.01,0.087,0.921
250.31,131.18,0.087,0.922
250.35,131.36,0.087,0.922
250.38,131.53,0.087,0.922
250.42,131.71,0.087,0.922
250.45,131.89,0.087,0.922
250.49,132.06,0.087,0.923
250.52,132.24,0.087,0.924
250.56,132.41,0.087,0.924
250.59,132.59,0.087,0.926
250.63,132.76,0.087,0.926
250.66,132.94,0.087,0.927
250.70,133.11,0.087,0.927
250.73,133.29,0.087,0.928
250.77,133.46,0.088,0.928
250.80,133.64,0.088,0.928
250.84,133.81,0.088,0.928
250.87,133.99,0.088,0.929
250.91,134.16,0.088,0.928
250.94,134.34,0.088,0.929
250.98,134.51,0.088,0.929
251.01,134.69,0.088,0.929
251.05,134.86,0.088,0.930
251.08,135.04,0.088,0.931
251.12,135.21,0.088,0.931
251.15,135.39,0.088,0.932
251.19,135.56,0.088,0.932
251.22,135.74,0.088,0.932
251.26,135.91,0.088,0.933
251.29,136.09,0.088,0.934
251.33,136.26,0.088,0.935
251.36,136.44,0.088,0.935
251.40,136.61,0.088,0.936
251.43,136.79,0.088,0.936
251.47,136.96,0.088,0.935
251.50,137.14,0.088,0.935
251.54,137.31,0.088,0.935
251.57,137.49,0.088,0.936
251.61,137.66,0.089,0.938
251.64,137.84,0.089,0.938
251.68,138.01,0.089,0.939
251.71,138.19,0.089,0.940
251.75,138.36,0.089,0.940
251.78,138.54,0.089,0.941
251.82,138.71,0.089,0.941
251.85,138.89,0.089,0.940
251.89,139.06,0.089,0.940
251.92,139.24,0.089,0.941
251.96,139.41,0.089,0.942
251.99,139.59,0.089,0.941
252.03,139.76,0.089,0.942
252.06,139.94,0.089,0.945
252.10,140.12,0.089,0.946
252.13,140.29,0.089,0.946
252.17,140.46,0.089,0.946
252.20,140.64,0.089,0.947
252.24,140.81,0.090,0.948
252.27,140.99,0.089,0.947
252.31,141.17,0.090,0.947
252.34,141.34,0.090,0.948
252.38,141.52,0.090,0.948
252.41,141.69,0.090,0.949
252.45,141.87,0.090,0.949
252.48,142.04,0.090,0.950
252.52,142.22,0.090,0.950
252.55,142.39,0.090,0.951
252.59,142.57,0.090,0.952
252.62,142.74,0.090,0.952
252.66,142.92,0.090,0.954
252.69,143.09,0.090,0.955
252.73,143.27,0.090,0.955
252.76,143.44,0.090,0.955
252.80,143.62,0.090,0.955
252.83,143.79,0.090,0.955
252.87,143.97,0.090,0.955
252.90,144.14,0.090,0.956
252.94,144.32,0.091,0.957
252.97,144.49,0.091,0.957
253.01,144.67,0.091,0.958
253.04,144.84,0.091,0.958
253.08,145.02,0.091,0.960
253.11,145.19,0.091,0.962
253.15,145.37,0.091,0.963
253.18,145.54,0.091,0.964
253.22,145.72,0.091,0.965
253.25,145.89,0.091,0.965
253.29,146.07,0.091,0.965
253.32,146.24,0.091,0.964
253.36,146.42,0.091,0.966
253.39,146.59,0.091,0.966
253.43,146.77,0.091,0.966
253.46,146.94,0.091,0.967
253.50,147.12,0.091,0.967
253.53,147.29,0.092,0.967
253.57,147.47,0.092,0.967
253.60,147.64,0.092,0.969
253.64,147.82,0.092,0.970
253.67,147.99,0.092,0.971
253.71,148.17,0.092,0.973
253.74,148.34,0.092,0.973
253.78,148.52,0.092,0.974
253.81,148.69,0.092,0.974
253.85,148.87,0.092,0.974
253.88,149.04,0.092,0.973
253.92,149.22,0.092,0.973
253.95,149.39,0.092,0.974
253.99,149.57,0.092,0.975
254.02,149.74,0.092,0.977
254.06,149.92,0.093,0.979
254.09,150.09,0.093,0.981
254.13,150.27,0.093,0.982
254.16,150.44,0.093,0.983
254.20,150.62,0.093,0.982
254.23,150.79,0.093,0.982
254.27,150.97,0.093,0.981
254.30,151.14,0.093,0.981
254.34,151.32,0.093,0.980
254.37,151.49,0.093,0.981
254.41,151.67,0.093,0.983
254.44,151.85,0.093,0.985
254.48,152.02,0.094,0.988
254.51,152.20,0.094,0.992
254.55,152.37,0.094,0.992
254.58,152.54,0.094,0.994
254.62,152.72,0.094,0.994
254.65,152.89,0.094,0.993
254.69,153.07,0.094,0.994
254.72,153.24,0.094,0.995
254.76,153.42,0.094,0.995
254.79,153.59,0.094,0.996
254.83,153.77,0.095,0.998
254.86,153.95,0.095,0.999
254.90,154.12,0.095,1.000
254.93,154.30,0.095,1.001
254.97,154.47,0.095,1.003
255.00,154.65,0.095,1.004
255.04,154.82,0.095,1.007
255.07,155.00,0.096,1.009
255.11,155.17,0.096,1.011
255.14,155.35,0.096,1.012
255.18,155.52,0.096,1.014
255.21,155.70,0.096,1.015
255.25,155.87,0.096,1.016
255.28,156.04,0.096,1.017
255.32,156.22,0.096,1.017
255.35,156.39,0.096,1.019
255.39,156.57,0.097,1.019
255.42,156.74,0.097,1.020
255.46,156.92,0.097,1.021
255.49,157.09,0.097,1.024
255.53,157.27,0.097,1.026
255.56,157.44,0.097,1.028
255.60,157.62,0.098,1.029
255.63,157.80,0.098,1.032
255.67,157.97,0.098,1.033
255.70,158.15,0.098,1.034
255.74,158.32,0.098,1.036
255.77,158.50,0.099,1.038
255.81,158.67,0.099,1.041
255.84,158.85,0.099,1.043
255.88,159.02,0.099,1.045
255.91,159.20,0.100,1.049
255.95,159.37,0.100,1.051
255.98,159.55,0.100,1.054
256.02,159.72,0.100,1.057
256.05,159.90,0.101,1.060
256.09,160.07,0.101,1.065
256.12,160.25,0.101,1.067
256.16,160.42,0.101,1.069
256.19,160.60,0.102,1.071
256.23,160.77,0.102,1.073
256.26,160.95,0.102,1.075
256.30,161.12,0.102,1.077
256.33,161.30,0.103,1.081
256.37,161.47,0.103,1.084
256.40,161.65,0.103,1.088
256.44,161.82,0.104,1.091
256.47,162.00,0.104,1.094
256.51,162.17,0.104,1.097
256.54,162.35,0.104,1.103
256.58,162.52,0.105,1.106
256.61,162.70,0.105,1.110
256.65,162.87,0.106,1.114
256.68,163.04,0.106,1.116
256.72,163.22,0.106,1.119
256.75,163.39,0.106,1.120
256.79,163.57,0.107,1.123
256.82,163.75,0.107,1.126
256.86,163.92,0.108,1.131
256.89,164.10,0.108,1.136
256.93,164.27,0.108,1.141
256.96,164.45,0.109,1.146
257.00,164.62,0.109,1.150
257.03,164.79,0.109,1.154
257.07,164.97,0.110,1.157
257.10,165.15,0.110,1.160
257.14,165.32,0.110,1.163
257.17,165.50,0.111,1.168
257.21,165.67,0.111,1.171
257.24,165.85,0.111,1.173
257.28,166.02,0.112,1.177
257.31,166.20,0.112,1.179
257.35,166.37,0.112,1.183
257.38,166.55,0.113,1.186
257.42,166.72,0.113,1.190
257.45,166.90,0.113,1.194
257.49,167.07,0.114,1.196
257.52,167.25,0.114,1.200
257.56,167.42,0.114,1.204
257.59,167.60,0.115,1.207
257.63,167.77,0.115,1.210
257.66,167.95,0.115,1.211
257.70,168.12,0.115,1.212
257.73,168.30,0.115,1.213
257.77,168.47,0.116,1.215
257.80,168.65,0.116,1.217
257.84,168.82,0.116,1.219
257.87,169.00,0.116,1.223
257.91,169.17,0.116,1.225
257.94,169.35,0.117,1.227
257.98,169.52,0.117,1.228
258.01,169.70,0.117,1.229
258.05,169.87,0.117,1.230
258.08,170.05,0.117,1.230
258.12,170.22,0.117,1.230
258.15,170.40,0.117,1.231
258.19,170.57,0.117,1.232
258.22,170.75,0.117,1.233
258.26,170.92,0.117,1.234
258.29,171.10,0.118,1.236
258.33,171.27,0.118,1.236
258.36,171.45,0.118,1.236
258.40,171.62,0.118,1.237
258.43,171.80,0.118,1.238
258.47,171.97,0.118,1.238
258.50,172.15,0.118,1.238
258.54,172.32,0.118,1.239
258.57,172.50,0.118,1.238
258.61,172.67,0.118,1.237
258.64,172.85,0.118,1.236
258.68,173.02,0.118,1.237
258.71,173.20,0.118,1.236
258.75,173.37,0.118,1.236
258.78,173.55,0.118,1.237
258.82,173.72,0.118,1.237
258.85,173.90,0.118,1.238
258.89,174.07,0.118,1.238
258.92,174.25,0.118,1.237
258.96,174.42,0.118,1.236
258.99,174.60,0.118,1.234
259.03,174.77,0.118,1.232
259.06,174.95,0.117,1.231
259.10,175.12,0.117,1.230
259.13,175.30,0.117,1.230
259.17,175.47,0.117,1.230
259.20,175.65,0.117,1.230
259.24,175.82,0.117,1.231
259.27,176.00,0.117,1.231
259.31,176.17,0.117,1.230
259.34,176.35,0.117,1.229
259.38,176.52,0.117,1.226
259.41,176.70,0.117,1.225
259.45,176.87,0.117,1.223
259.48,177.05,0.117,1.223
259.52,177.23,0.117,1.224
259.55,177.40,0.117,1.224
259.59,177.58,0.117,1.226
259.62,177.75,0.117,1.228
259.66,177.93,0.117,1.227
259.69,178.10,0.117,1.228
259.73,178.27,0.117,1.228
259.76,178.45,0.117,1.226
259.80,178.63,0.117,1.224
259.83,178.80,0.117,1.223
259.87,178.97,0.117,1.223
259.90,179.15,0.117,1.224
259.94,179.33,0.117,1.225
259.97,179.50,0.117,1.227
260.01,179.68,0.117,1.228
260.04,179.85,0.117,1.228
260.08,180.03,0.117,1.228
260.11,180.20,0.117,1.226
260.15,180.38,0.117,1.225
260.18,180.55,0.117,1.224
260.22,180.73,0.117,1.224
260.25,180.90,0.117,1.225
260.29,181.08,0.117,1.227
260.32,181.25,0.117,1.226
260.36,181.43,0.117,1.226
260.39,181.60,0.117,1.227
260.43,181.78,0.117,1.228
260.46,181.95,0.117,1.229
260.50,182.13,0.117,1.230
260.53,182.30,0.117,1.229
260.57,182.48,0.117,1.229
260.60,182.65,0.117,1.229
260.64,182.83,0.117,1.228
260.67,183.00,0.117,1.227
260.71,183.18,0.117,1.226
260.74,183.35,0.117,1.228
260.78,183.53,0.117,1.228
260.81,183.70,0.118,1.229
260.85,183.88,0.118,1.231
260.88,184.05,0.118,1.233
260.92,184.23,0.118,1.234
260.95,184.40,0.118,1.234
260.99,184.58,0.118,1.234
261.02,184.75,0.118,1.234
261.06,184.93,0.118,1.233
261.09,185.10,0.118,1.233
261.13,185.28,0.118,1.232
261.16,185.45,0.118,1.231
261.20,185.63,0.118,1.231
261.23,185.80,0.118,1.232
261.27,185.98,0.118,1.234
261.30,186.15,0.118,1.234
261.34,186.33,0.118,1.236
261.37,186.50,0.118,1.237
261.41,186.68,0.118,1.239
261.44,186.85,0.118,1.240
261.48,187.03,0.118,1.240
261.51,187.20,0.118,1.239
261.55,187.38,0.118,1.238
261.58,187.55,0.118,1.237
261.62,187.73,0.118,1.238
261.65,187.90,0.118,1.238
261.69,188.08,0.119,1.239
261.72,188.25,0.119,1.240
261.76,188.43,0.119,1.241
261.79,188.60,0.119,1.241
261.83,188.78,0.119,1.241
261.86,188.95,0.119,1.239
261.90,189.13,0.119,1.239
261.93,189.30,0.119,1.240
261.97,189.48,0.119,1.241
262.00,189.66,0.119,1.241
262.04,189.83,0.119,1.241
262.07,190.00,0.119,1.244
262.11,190.18,0.119,1.245
262.14,190.36,0.119,1.244
262.18,190.53,0.119,1.245
262.21,190.70,0.119,1.247
262.25,190.88,0.119,1.247
262.28,191.05,0.119,1.245
262.32,191.23,0.119,1.244
262.35,191.40,0.119,1.245
262.39,191.58,0.119,1.245
262.42,191.76,0.119,1.247
262.46,191.93,0.119,1.249
262.49,192.11,0.120,1.251
262.53,192.28,0.120,1.251
262.56,192.45,0.120,1.250
262.60,192.63,0.120,1.249
262.63,192.80,0.120,1.247
262.67,192.98,0.120,1.246
262.70,193.16,0.120,1.247
262.74,193.33,0.120,1.248
262.77,193.51,0.120,1.250
262.81,193.68,0.120,1.252
262.84,193.86,0.120,1.254
262.88,194.03,0.120,1.256
262.91,194.21,0.120,1.257
262.95,194.38,0.120,1.255
262.98,194.56,0.120,1.255
263.02,194.73,0.120,1.254
263.05,194.91,0.120,1.253
263.09,195.08,0.120,1.253
263.12,195.26,0.120,1.255
263.16,195.43,0.120,1.256
263.19,195.61,0.120,1.256
263.23,195.78,0.120,1.257
263.26,195.96,0.121,1.258
263.30,196.13,0.121,1.259
263.33,196.31,0.121,1.259
263.37,196.48,0.121,1.259
263.40,196.66,0.121,1.259
263.44,196.83,0.121,1.260
263.47,197.01,0.121,1.259
263.51,197.18,0.121,1.259
263.54,197.36,0.121,1.261
263.58,197.53,0.121,1.261
263.61,197.71,0.121,1.262
263.65,197.88,0.121,1.262
263.68,198.06,0.121,1.263
263.72,198.23,0.121,1.262
263.75,198.41,0.121,1.262
263.79,198.58,0.121,1.262
263.82,198.76,0.121,1.262
263.86,198.93,0.121,1.262
263.89,199.11,0.121,
263.93,199.28,,
263.96,199.46,,
263.98,,,