File: DSC/Earl/2025_10_04_Al2O3_Powder_Std_5Cmin_n60C_250C_x3.csv
Filename,2025_10_04_Al2O3_Powder_Std_5Cmin_n60C_250C_x3
Instrument name,DSC2A-00468 (192.168.1.100)
Operator,JLY
rundate,10/5/2025
Sample name,2025_10_04_Al2O3_Powder_Std_5Cmin_n60C_250C_x3
proceduresegments,Data Off ; Equilibrate -60.00 °C; Data On ; Ramp 5.00 °C/min to 250.00 °C; Data Off ; Isothermal 1.0 min; Data On ; Ramp 5.00 °C/min to -60.00 °C; Data Off ; Isothermal 1.0 min; Data On ; Ramp 5.00 °C/min to 250.00 °C; Data Off ; Isothermal 1.0 min; Data On ; Ramp 5.00 °C/min to -60.00 °C; Data Off ; Isothermal 1.0 min; Data On ; Ramp 5.00 °C/min to 250.00 °C
[File Parameters]
Run date,10/5/2025 4:21:27 AM
Trios version,5.1.1.46572
Original File Name,
Current File Name,D:\DSC2500\JYarger\2025_10_04_Al2O3_Powder_Std_5Cmin_n60C_250C_x3.tri
[Procedure]
Procedure Name,Al2O3_n60C_250C_5Cmin_3
Sample Name,2025_10_04_Al2O3_Powder_Std_5Cmin_n60C_250C_x3
Sample Mass,1.58 mg
Reference Sample Mass,0 mg
Pan Mass,32.83 mg
Pan Number,2
Reference Pan Mass,32.55 mg
Reference Pan Number,1
Pan Type,Aluminum
Comments,DSC_Samples_Y2_Tray_ASDs_Pharma_Oct2025 Google Sheet.
Project Name,Amorphous Pharma
Operator,JLY
Test,Custom
Unload Max Temperature,30
Unload Min Temperature,30
Load Max Temperature,30
Load Min Temperature,30
Stop on Gas Flow Error,Yes
[Signal List]
Signal #1,Time (min)
Signal #2,Temperature (°C)
Signal #3,Heat Flow (mW)
Signal #4,Delta T (µV)
Signal #5,Delta Tzero (µV)
Signal #6,Tzero Temperature (°C)
Signal #7,Cell Purge (mL/min)
Signal #8,Heater Temp (°C)
Signal #9,Power Delivered (W)
Signal #10,Reference Junction Temperature (°C)
Signal #11,Flange Temperature (°C)
Signal #12,Heat Flow Phase (rad)
Signal #13,Total Heat Capacity (J/°C)
Signal #14,Heat Capacity (J/°C)
[Configuration]
Company Name,ASU
Instrument Name,DSC2A-00468
Instrument Type,DSC2500
Serial Number,DSC2A-00468
IP,192.168.1.100
Location of Instrument,MRRC
DisplayType,Unknown
Sample Interval ,0.1 s/pt
Selected Heat Flow,T4P
Exotherm Direction,Down
Cell Serial,DRC2-00792
Lid Type,Standard
Cooler,RCS 90
Leave Cooler on at End of Sequence,On
Gas 2,Nitrogen
Gas Selected,Channel 1
Flow Rate,50 mL/min
Secondary Purge,On
Licensed Heat Flow,Heat Flow T4P
Modulation Licensed,Yes
[Versions]
Common IDD Version,1
Cortex Version,VER 2.10.2.31
Driver,5.0.0.6
GDM Version,1.0.3.3
TouchscreenVersion,1.0.0.16145
FEP Version,1.2.1.21
FEP Bootloader,2.0.0.5
AutoSampler Version,2.1.1.26
Auto Sampler Bootloader,2.0.0.5
FCM Version,1.1.0.3
FCM Bootloader,2.0.0.5
[Experiment Logs]
Experiment Log Entry # 1,Data On set to 0
Experiment Log Entry # 3,Equilibrate Segment -60 (C) Started
Experiment Log Entry # 5,Air Cool is off.
Experiment Log Entry # 7,Data On set to 1
Experiment Log Entry # 9,Ramp Segment 5 C/min to 250 Started
Experiment Log Entry # 11,Auto sampler has detected that GDM has gone offline
Experiment Log Entry # 13,Data On set to 0
Experiment Log Entry # 15,Isothermal Segment 1 min started
Experiment Log Entry # 17,Data On set to 1
Experiment Log Entry # 19,Ramp Segment 5 C/min to -60 Started
Experiment Log Entry # 21,Data On set to 0
Experiment Log Entry # 23,Isothermal Segment 1 min started
Experiment Log Entry # 25,Data On set to 1
Experiment Log Entry # 27,Ramp Segment 5 C/min to 250 Started
Experiment Log Entry # 29,Auto sampler has detected that GDM has gone offline
Experiment Log Entry # 31,Data On set to 0
Experiment Log Entry # 33,Isothermal Segment 1 min started
Experiment Log Entry # 35,Data On set to 1
Experiment Log Entry # 37,Ramp Segment 5 C/min to -60 Started
Experiment Log Entry # 39,Data On set to 0
Experiment Log Entry # 41,Isothermal Segment 1 min started
Experiment Log Entry # 43,Data On set to 1
Experiment Log Entry # 45,Ramp Segment 5 C/min to 250 Started
[Method Log]
Method Log Entry # 1,Data Off
Method Log Entry # 2,Equilibrate -60 °C
Method Log Entry # 3,Data On
Method Log Entry # 4,(Ramp 129181) Ramp 5 °C/minute to 250 °C
Method Log Entry # 5,Data Off
Method Log Entry # 6,Isothermal 1 minutes
Method Log Entry # 7,Data On
Method Log Entry # 8,(Ramp 129185) Ramp 5 °C/minute to -60 °C
Method Log Entry # 9,Data Off
Method Log Entry # 10,Isothermal 1 minutes
Method Log Entry # 11,Data On
Method Log Entry # 12,(Ramp 129189) Ramp 5 °C/minute to 250 °C
Method Log Entry # 13,Data Off
Method Log Entry # 14,Isothermal 1 minutes
Method Log Entry # 15,Data On
Method Log Entry # 16,(Ramp 129193) Ramp 5 °C/minute to -60 °C
Method Log Entry # 17,Data Off
Method Log Entry # 18,Isothermal 1 minutes
Method Log Entry # 19,Data On
Method Log Entry # 20,(Ramp 129197) Ramp 5 °C/minute to 250 °C
Cell Serial,DRC2-00792
[T1 Calibration]
Slope,-0.008529666
Offset,9.636258
Initial Temperature,98.23
GUID,f8bfdadc-4977-4fdf-ba6d-0ba9134940c3
[TZero Calibration]
Date Applied,11/29/2022 4:06:13 PM
Description,From -89.059 °C to 396.009 °C at 20.000°C/min
Gas Type,Nitrogen
Pan Type,None
Source Files 1,C:\Users\yargerlab\Desktop\DSC Data\General\TZero_calibration_11_29_22_2nd(2).tri
Source Files 2,C:\Users\yargerlab\Desktop\DSC Data\General\TZero_calibration_11_29_22_2nd(3).tri
Delta T Offset,13.05235
Delta T Slope,-0.007271007
Delta T0 Offset,-13.69128
Delta T0 Slope,0.06063341
[Temperature Calibration]
Date Applied,11/29/2022 7:12:28 PM
Description,From 106.590 °C to 186.590 °C at 10.000°C/min
Gas Type,Nitrogen
Pan Type,Tzero Aluminum Hermetic
Source Files 1,C:\Users\yargerlab\Desktop\DSC Data\General\Indium(6).tri
Measured 1,157.391
Known 1,156.598
[Cell Constant Calibration]
Date Applied,11/29/2022 7:12:29 PM
Description,From 106.590 °C to 186.590 °C at 10.000°C/min
Gas Type,Nitrogen
Pan Type,Tzero Aluminum Hermetic
Source Files 1,C:\Users\yargerlab\Desktop\DSC Data\General\Indium(6).tri
T4P KCell,1.006051
Onset Slope,63.26126 mW/°C
[Direct Cp Calibration]
Date Applied,11/30/2022 11:04:51 AM
Description,From -79.983 °C to 298.409 °C at 10.000°C/min
Gas Type,Nitrogen
Pan Type,Tzero Aluminum Hermetic
Source Files 1,C:\Users\yargerlab\Desktop\DSC Data\General\Sapphire_Heat_Capacity_11_30_22.tri
[Rev Cp Calibration]
Date Applied,11/30/2022 1:58:51 PM
Description,From -79.996 °C to 292.812 °C at 3.000°C/min
Gas Type,Nitrogen
Pan Type,Tzero Aluminum Hermetic
Source Files 1,C:\Users\yargerlab\Desktop\DSC Data\General\Sapphire_MDSC_Calibration_11_30_22.tri
[step]
Ramp 5.00 °C/min to 250.00 °C
Time,Temperature,Heat Flow (Normalized)
min,°C,W/g
0.00,-59.84,-0.048
0.04,-59.85,-0.044
0.08,-59.80,0.071
0.13,-59.69,0.160
0.17,-59.52,0.174
0.21,-59.34,0.163
0.25,-59.14,0.155
0.29,-58.94,0.153
0.33,-58.74,0.152
0.38,-58.54,0.151
0.42,-58.33,0.149
0.46,-58.13,0.148
0.50,-57.93,0.147
0.54,-57.72,0.145
0.58,-57.51,0.144
0.63,-57.31,0.143
0.67,-57.10,0.142
0.71,-56.90,0.142
0.75,-56.69,0.141
0.79,-56.48,0.140
0.83,-56.28,0.140
0.88,-56.07,0.139
0.92,-55.86,0.139
0.96,-55.66,0.138
1.00,-55.45,0.138
1.04,-55.24,0.137
1.08,-55.03,0.137
1.13,-54.82,0.136
1.17,-54.62,0.136
1.21,-54.41,0.135
1.25,-54.20,0.135
1.29,-53.99,0.135
1.33,-53.79,0.134
1.38,-53.58,0.134
1.42,-53.37,0.133
1.46,-53.16,0.133
1.50,-52.96,0.132
1.54,-52.75,0.132
1.58,-52.54,0.132
1.63,-52.33,0.132
1.67,-52.12,0.131
1.71,-51.91,0.131
1.75,-51.70,0.130
1.79,-51.50,0.130
1.83,-51.29,0.130
1.88,-51.08,0.130
1.92,-50.87,0.130
1.96,-50.66,0.129
2.00,-50.46,0.129
2.04,-50.25,0.129
2.08,-50.04,0.128
2.13,-49.83,0.128
2.17,-49.62,0.128
2.21,-49.42,0.127
2.25,-49.21,0.127
2.29,-49.00,0.127
2.33,-48.79,0.127
2.38,-48.58,0.126
2.42,-48.37,0.126
2.46,-48.17,0.126
2.50,-47.96,0.126
2.54,-47.75,0.125
2.58,-47.54,0.125
2.63,-47.33,0.125
2.67,-47.13,0.125
2.71,-46.92,0.124
2.75,-46.71,0.124
2.79,-46.50,0.124
2.83,-46.29,0.124
2.88,-46.08,0.124
2.92,-45.88,0.124
2.96,-45.67,0.123
3.00,-45.46,0.123
3.04,-45.25,0.123
3.08,-45.04,0.123
3.13,-44.83,0.123
3.17,-44.63,0.123
3.21,-44.42,0.123
3.25,-44.21,0.123
3.29,-44.00,0.123
3.33,-43.79,0.122
3.38,-43.58,0.122
3.42,-43.38,0.122
3.46,-43.17,0.122
3.50,-42.96,0.122
3.54,-42.75,0.122
3.58,-42.54,0.121
3.63,-42.33,0.121
3.67,-42.13,0.121
3.71,-41.92,0.121
3.75,-41.71,0.121
3.79,-41.50,0.121
3.83,-41.29,0.121
3.88,-41.08,0.121
3.92,-40.87,0.120
3.96,-40.67,0.120
4.00,-40.46,0.120
4.04,-40.25,0.120
4.08,-40.04,0.120
4.13,-39.83,0.120
4.17,-39.63,0.120
4.21,-39.42,0.120
4.25,-39.21,0.120
4.29,-39.00,0.120
4.33,-38.79,0.120
4.38,-38.58,0.120
4.42,-38.37,0.120
4.46,-38.17,0.119
4.50,-37.96,0.119
4.54,-37.75,0.119
4.58,-37.54,0.119
4.63,-37.33,0.119
4.67,-37.12,0.119
4.71,-36.91,0.119
4.75,-36.70,0.119
4.79,-36.50,0.119
4.83,-36.29,0.119
4.88,-36.08,0.119
4.92,-35.87,0.118
4.96,-35.66,0.118
5.00,-35.45,0.118
5.04,-35.25,0.118
5.08,-35.04,0.118
5.13,-34.83,0.118
5.17,-34.62,0.118
5.21,-34.41,0.118
5.25,-34.20,0.118
5.29,-33.99,0.118
5.33,-33.78,0.118
5.38,-33.58,0.118
5.42,-33.37,0.117
5.46,-33.16,0.117
5.50,-32.95,0.117
5.54,-32.74,0.117
5.58,-32.53,0.117
5.63,-32.32,0.117
5.67,-32.11,0.117
5.71,-31.91,0.117
5.75,-31.70,0.117
5.79,-31.49,0.117
5.83,-31.28,0.117
5.88,-31.07,0.117
5.92,-30.86,0.117
5.96,-30.65,0.117
6.00,-30.45,0.117
6.04,-30.24,0.117
6.08,-30.03,0.117
6.13,-29.82,0.117
6.17,-29.61,0.117
6.21,-29.41,0.117
6.25,-29.19,0.117
6.29,-28.99,0.116
6.33,-28.78,0.116
6.38,-28.57,0.116
6.42,-28.36,0.116
6.46,-28.15,0.116
6.50,-27.94,0.116
6.54,-27.74,0.116
6.58,-27.53,0.116
6.63,-27.32,0.116
6.67,-27.11,0.116
6.71,-26.90,0.116
6.75,-26.69,0.116
6.79,-26.48,0.116
6.83,-26.27,0.116
6.88,-26.07,0.116
6.92,-25.86,0.115
6.96,-25.65,0.115
7.00,-25.44,0.115
7.04,-25.23,0.115
7.08,-25.02,0.115
7.13,-24.81,0.115
7.17,-24.61,0.115
7.21,-24.40,0.115
7.25,-24.19,0.115
7.29,-23.98,0.115
7.33,-23.77,0.115
7.38,-23.56,0.115
7.42,-23.35,0.115
7.46,-23.15,0.115
7.50,-22.94,0.115
7.54,-22.73,0.114
7.58,-22.52,0.114
7.63,-22.31,0.114
7.67,-22.10,0.114
7.71,-21.90,0.114
7.75,-21.69,0.114
7.79,-21.48,0.114
7.83,-21.27,0.114
7.88,-21.06,0.114
7.92,-20.85,0.114
7.96,-20.64,0.114
8.00,-20.43,0.114
8.04,-20.23,0.114
8.08,-20.02,0.114
8.13,-19.81,0.114
8.17,-19.60,0.114
8.21,-19.39,0.114
8.25,-19.18,0.114
8.29,-18.97,0.114
8.33,-18.77,0.114
8.38,-18.56,0.114
8.42,-18.35,0.114
8.46,-18.14,0.114
8.50,-17.93,0.114
8.54,-17.72,0.114
8.58,-17.52,0.114
8.63,-17.31,0.114
8.67,-17.10,0.114
8.71,-16.89,0.113
8.75,-16.68,0.113
8.79,-16.47,0.113
8.83,-16.26,0.113
8.88,-16.06,0.113
8.92,-15.85,0.113
8.96,-15.64,0.113
9.00,-15.43,0.113
9.04,-15.22,0.112
9.08,-15.02,0.113
9.13,-14.81,0.113
9.17,-14.60,0.113
9.21,-14.39,0.113
9.25,-14.18,0.113
9.29,-13.97,0.113
9.33,-13.76,0.113
9.38,-13.55,0.113
9.42,-13.34,0.113
9.46,-13.14,0.113
9.50,-12.93,0.113
9.54,-12.72,0.113
9.58,-12.51,0.113
9.63,-12.30,0.113
9.67,-12.09,0.113
9.71,-11.88,0.113
9.75,-11.67,0.113
9.79,-11.47,0.113
9.83,-11.26,0.113
9.88,-11.05,0.113
9.92,-10.84,0.113
9.96,-10.63,0.113
10.00,-10.42,0.113
10.04,-10.21,0.113
10.08,-10.01,0.113
10.13,-9.80,0.113
10.17,-9.59,0.113
10.21,-9.38,0.113
10.25,-9.17,0.113
10.29,-8.96,0.113
10.33,-8.76,0.112
10.38,-8.55,0.112
10.42,-8.34,0.113
10.46,-8.13,0.113
10.50,-7.92,0.113
10.54,-7.71,0.113
10.58,-7.50,0.113
10.63,-7.30,0.113
10.67,-7.09,0.113
10.71,-6.88,0.113
10.75,-6.67,0.113
10.79,-6.46,0.113
10.83,-6.26,0.112
10.88,-6.05,0.112
10.92,-5.84,0.113
10.96,-5.63,0.113
11.00,-5.42,0.113
11.04,-5.21,0.113
11.08,-5.00,0.113
11.13,-4.80,0.113
11.17,-4.59,0.113
11.21,-4.38,0.113
11.25,-4.17,0.113
11.29,-3.96,0.113
11.33,-3.75,0.113
11.38,-3.55,0.113
11.42,-3.34,0.113
11.46,-3.13,0.113
11.50,-2.92,0.113
11.54,-2.71,0.114
11.58,-2.50,0.113
11.63,-2.29,0.113
11.67,-2.08,0.113
11.71,-1.87,0.113
11.75,-1.67,0.113
11.79,-1.46,0.113
11.83,-1.25,0.114
11.88,-1.04,0.114
11.92,-0.83,0.113
11.96,-0.62,0.114
12.00,-0.41,0.113
12.04,-0.21,0.113
12.08,0.00,0.114
12.13,0.21,0.114
12.17,0.42,0.114
12.21,0.63,0.113
12.25,0.84,0.113
12.29,1.04,0.113
12.33,1.25,0.113
12.38,1.46,0.113
12.42,1.67,0.114
12.46,1.88,0.114
12.50,2.09,0.114
12.54,2.29,0.113
12.58,2.50,0.114
12.63,2.71,0.114
12.67,2.92,0.114
12.71,3.13,0.114
12.75,3.34,0.114
12.79,3.55,0.114
12.83,3.76,0.114
12.88,3.97,0.114
12.92,4.17,0.114
12.96,4.38,0.114
13.00,4.59,0.114
13.04,4.80,0.114
13.08,5.01,0.114
13.13,5.22,0.114
13.17,5.42,0.115
13.21,5.63,0.115
13.25,5.84,0.115
13.29,6.05,0.115
13.33,6.26,0.115
13.38,6.47,0.115
13.42,6.67,0.115
13.46,6.88,0.115
13.50,7.09,0.115
13.54,7.30,0.115
13.58,7.51,0.115
13.63,7.72,0.116
13.67,7.93,0.115
13.71,8.13,0.115
13.75,8.34,0.116
13.79,8.55,0.116
13.83,8.76,0.116
13.88,8.97,0.116
13.92,9.18,0.116
13.96,9.39,0.116
14.00,9.59,0.116
14.04,9.80,0.116
14.08,10.01,0.116
14.13,10.22,0.116
14.17,10.43,0.117
14.21,10.64,0.116
14.25,10.84,0.117
14.29,11.05,0.117
14.33,11.26,0.117
14.38,11.47,0.117
14.42,11.68,0.117
14.46,11.89,0.117
14.50,12.10,0.117
14.54,12.31,0.117
14.58,12.51,0.117
14.63,12.72,0.118
14.67,12.93,0.118
14.71,13.14,0.118
14.75,13.35,0.118
14.79,13.56,0.118
14.83,13.77,0.118
14.88,13.97,0.118
14.92,14.18,0.119
14.96,14.39,0.119
15.00,14.60,0.119
15.04,14.81,0.119
15.08,15.02,0.119
15.13,15.22,0.119
15.17,15.43,0.119
15.21,15.64,0.119
15.25,15.85,0.119
15.29,16.06,0.119
15.33,16.27,0.120
15.38,16.47,0.120
15.42,16.68,0.120
15.46,16.89,0.120
15.50,17.10,0.120
15.54,17.31,0.120
15.58,17.52,0.121
15.63,17.73,0.121
15.67,17.94,0.121
15.71,18.14,0.121
15.75,18.35,0.121
15.79,18.56,0.121
15.83,18.77,0.121
15.88,18.98,0.122
15.92,19.19,0.122
15.96,19.39,0.122
16.00,19.60,0.122
16.04,19.81,0.122
16.08,20.02,0.123
16.13,20.23,0.122
16.17,20.44,0.123
16.21,20.65,0.123
16.25,20.85,0.123
16.29,21.06,0.123
16.33,21.27,0.123
16.38,21.48,0.123
16.42,21.69,0.124
16.46,21.89,0.124
16.50,22.10,0.124
16.54,22.31,0.124
16.58,22.52,0.124
16.63,22.73,0.124
16.67,22.94,0.125
16.71,23.15,0.125
16.75,23.36,0.125
16.79,23.57,0.125
16.83,23.77,0.125
16.88,23.98,0.125
16.92,24.19,0.125
16.96,24.40,0.126
17.00,24.61,0.126
17.04,24.82,0.126
17.08,25.02,0.126
17.13,25.23,0.126
17.17,25.44,0.127
17.21,25.65,0.127
17.25,25.86,0.127
17.29,26.07,0.127
17.33,26.28,0.127
17.38,26.48,0.128
17.42,26.69,0.128
17.46,26.90,0.128
17.50,27.11,0.128
17.54,27.32,0.129
17.58,27.53,0.129
17.63,27.74,0.129
17.67,27.94,0.129
17.71,28.15,0.129
17.75,28.36,0.129
17.79,28.57,0.129
17.83,28.78,0.130
17.88,28.99,0.130
17.92,29.19,0.130
17.96,29.40,0.130
18.00,29.61,0.131
18.04,29.82,0.131
18.08,30.03,0.131
18.13,30.24,0.131
18.17,30.44,0.132
18.21,30.65,0.132
18.25,30.86,0.132
18.29,31.07,0.133
18.33,31.28,0.133
18.38,31.49,0.133
18.42,31.70,0.133
18.46,31.90,0.133
18.50,32.11,0.134
18.54,32.32,0.134
18.58,32.53,0.134
18.63,32.74,0.134
18.67,32.95,0.135
18.71,33.16,0.135
18.75,33.37,0.135
18.79,33.58,0.136
18.83,33.78,0.136
18.88,33.99,0.136
18.92,34.20,0.136
18.96,34.41,0.137
19.00,34.61,0.137
19.04,34.82,0.137
19.08,35.03,0.137
19.13,35.24,0.137
19.17,35.45,0.137
19.21,35.66,0.138
19.25,35.87,0.138
19.29,36.07,0.138
19.33,36.28,0.138
19.38,36.49,0.139
19.42,36.70,0.139
19.46,36.91,0.139
19.50,37.12,0.139
19.54,37.32,0.139
19.58,37.53,0.140
19.63,37.74,0.140
19.67,37.95,0.140
19.71,38.16,0.140
19.75,38.37,0.140
19.79,38.57,0.141
19.83,38.78,0.141
19.88,38.99,0.141
19.92,39.20,0.141
19.96,39.41,0.141
20.00,39.62,0.142
20.04,39.83,0.142
20.08,40.04,0.142
20.13,40.25,0.143
20.17,40.46,0.143
20.21,40.66,0.143
20.25,40.87,0.143
20.29,41.08,0.143
20.33,41.29,0.143
20.38,41.50,0.144
20.42,41.70,0.144
20.46,41.91,0.144
20.50,42.12,0.144
20.54,42.33,0.145
20.58,42.54,0.145
20.63,42.74,0.145
20.67,42.95,0.145
20.71,43.16,0.146
20.75,43.37,0.146
20.79,43.58,0.146
20.83,43.79,0.146
20.88,43.99,0.146
20.92,44.20,0.147
20.96,44.41,0.147
21.00,44.62,0.147
21.04,44.83,0.147
21.08,45.04,0.147
21.13,45.25,0.147
21.17,45.45,0.148
21.21,45.66,0.148
21.25,45.87,0.148
21.29,46.08,0.148
21.33,46.29,0.148
21.38,46.50,0.149
21.42,46.71,0.149
21.46,46.91,0.149
21.50,47.12,0.149
21.54,47.33,0.149
21.58,47.54,0.150
21.63,47.75,0.150
21.67,47.96,0.150
21.71,48.16,0.150
21.75,48.37,0.150
21.79,48.58,0.150
21.83,48.79,0.151
21.88,49.00,0.151
21.92,49.21,0.151
21.96,49.42,0.151
22.00,49.63,0.151
22.04,49.83,0.151
22.08,50.04,0.152
22.13,50.25,0.152
22.17,50.46,0.152
22.21,50.67,0.152
22.25,50.88,0.152
22.29,51.08,0.152
22.33,51.29,0.153
22.38,51.50,0.153
22.42,51.71,0.153
22.46,51.92,0.153
22.50,52.13,0.153
22.54,52.33,0.153
22.58,52.54,0.153
22.63,52.75,0.153
22.67,52.96,0.154
22.71,53.17,0.154
22.75,53.38,0.154
22.79,53.59,0.154
22.83,53.79,0.154
22.88,54.00,0.154
22.92,54.21,0.154
22.96,54.42,0.155
23.00,54.63,0.155
23.04,54.84,0.155
23.08,55.05,0.155
23.13,55.25,0.155
23.17,55.46,0.155
23.21,55.67,0.155
23.25,55.88,0.155
23.29,56.09,0.155
23.33,56.30,0.155
23.38,56.50,0.155
23.42,56.71,0.155
23.46,56.92,0.155
23.50,57.13,0.155
23.54,57.34,0.155
23.58,57.55,0.155
23.63,57.76,0.156
23.67,57.96,0.156
23.71,58.17,0.156
23.75,58.38,0.156
23.79,58.59,0.156
23.83,58.80,0.156
23.88,59.01,0.156
23.92,59.22,0.156
23.96,59.42,0.156
24.00,59.63,0.156
24.04,59.84,0.156
24.08,60.05,0.156
24.13,60.26,0.156
24.17,60.47,0.155
24.21,60.68,0.155
24.25,60.89,0.155
24.29,61.09,0.155
24.33,61.30,0.154
24.38,61.51,0.154
24.42,61.72,0.154
24.46,61.92,0.154
24.50,62.13,0.154
24.54,62.34,0.154
24.58,62.55,0.153
24.63,62.75,0.153
24.67,62.96,0.154
24.71,63.17,0.154
24.75,63.38,0.154
24.79,63.59,0.155
24.83,63.80,0.155
24.88,64.01,0.155
24.92,64.22,0.155
24.96,64.42,0.155
25.00,64.63,0.156
25.04,64.84,0.156
25.08,65.05,0.156
25.13,65.26,0.156
25.17,65.47,0.156
25.21,65.68,0.156
25.25,65.89,0.156
25.29,66.09,0.156
25.33,66.30,0.156
25.38,66.51,0.156
25.42,66.72,0.156
25.46,66.93,0.156
25.50,67.14,0.155
25.54,67.35,0.155
25.58,67.56,0.155
25.63,67.76,0.155
25.67,67.97,0.155
25.71,68.18,0.155
25.75,68.39,0.155
25.79,68.60,0.155
25.83,68.81,0.155
25.88,69.01,0.155
25.92,69.22,0.155
25.96,69.43,0.155
26.00,69.64,0.154
26.04,69.85,0.154
26.08,70.06,0.154
26.13,70.27,0.154
26.17,70.47,0.154
26.21,70.68,0.154
26.25,70.89,0.154
26.29,71.10,0.154
26.33,71.31,0.154
26.38,71.52,0.154
26.42,71.72,0.153
26.46,71.93,0.153
26.50,72.14,0.153
26.54,72.35,0.153
26.58,72.56,0.153
26.63,72.77,0.153
26.67,72.98,0.153
26.71,73.18,0.153
26.75,73.39,0.153
26.79,73.60,0.153
26.83,73.81,0.153
26.88,74.02,0.152
26.92,74.23,0.152
26.96,74.44,0.152
27.00,74.64,0.152
27.04,74.85,0.152
27.08,75.06,0.152
27.13,75.27,0.152
27.17,75.48,0.152
27.21,75.69,0.152
27.25,75.89,0.152
27.29,76.10,0.152
27.33,76.31,0.151
27.38,76.52,0.151
27.42,76.73,0.151
27.46,76.94,0.151
27.50,77.15,0.151
27.54,77.35,0.151
27.58,77.56,0.151
27.63,77.77,0.151
27.67,77.98,0.151
27.71,78.19,0.151
27.75,78.40,0.151
27.79,78.61,0.150
27.83,78.81,0.150
27.88,79.02,0.150
27.92,79.23,0.151
27.96,79.44,0.150
28.00,79.65,0.150
28.04,79.86,0.150
28.08,80.07,0.149
28.13,80.28,0.149
28.17,80.48,0.149
28.21,80.69,0.148
28.25,80.90,0.148
28.29,81.11,0.148
28.33,81.32,0.148
28.38,81.53,0.148
28.42,81.74,0.147
28.46,81.94,0.147
28.50,82.15,0.147
28.54,82.36,0.147
28.58,82.57,0.147
28.63,82.78,0.147
28.67,82.98,0.146
28.71,83.19,0.146
28.75,83.40,0.146
28.79,83.61,0.146
28.83,83.82,0.146
28.88,84.03,0.146
28.92,84.24,0.146
28.96,84.45,0.146
29.00,84.65,0.146
29.04,84.86,0.145
29.08,85.07,0.145
29.13,85.28,0.145
29.17,85.49,0.145
29.21,85.70,0.145
29.25,85.90,0.144
29.29,86.11,0.144
29.33,86.32,0.144
29.38,86.53,0.144
29.42,86.74,0.144
29.46,86.94,0.143
29.50,87.15,0.143
29.54,87.36,0.143
29.58,87.57,0.143
29.63,87.78,0.143
29.67,87.99,0.143
29.71,88.20,0.143
29.75,88.41,0.143
29.79,88.61,0.143
29.83,88.82,0.143
29.88,89.03,0.143
29.92,89.24,0.143
29.96,89.45,0.143
30.00,89.66,0.143
30.04,89.86,0.142
30.08,90.07,0.142
30.13,90.28,0.142
30.17,90.49,0.142
30.21,90.70,0.142
30.25,90.91,0.142
30.29,91.12,0.142
30.33,91.32,0.142
30.38,91.53,0.142
30.42,91.74,0.142
30.46,91.95,0.141
30.50,92.16,0.141
30.54,92.37,0.141
30.58,92.58,0.141
30.63,92.78,0.141
30.67,92.99,0.141
30.71,93.20,0.141
30.75,93.41,0.141
30.79,93.62,0.141
30.83,93.83,0.141
30.88,94.03,0.141
30.92,94.24,0.141
30.96,94.45,0.141
31.00,94.66,0.141
31.04,94.87,0.140
31.08,95.08,0.140
31.13,95.28,0.140
31.17,95.49,0.140
31.21,95.70,0.140
31.25,95.91,0.140
31.29,96.12,0.140
31.33,96.33,0.140
31.38,96.53,0.140
31.42,96.74,0.140
31.46,96.95,0.140
31.50,97.16,0.140
31.54,97.37,0.140
31.58,97.58,0.140
31.63,97.79,0.140
31.67,97.99,0.139
31.71,98.20,0.139
31.75,98.41,0.139
31.79,98.62,0.139
31.83,98.83,0.139
31.88,99.03,0.139
31.92,99.24,0.139
31.96,99.45,0.139
32.00,99.66,0.139
32.04,99.87,0.139
32.08,100.08,0.139
32.13,100.29,0.139
32.17,100.50,0.139
32.21,100.70,0.139
32.25,100.91,0.139
32.29,101.12,0.139
32.33,101.33,0.139
32.38,101.54,0.138
32.42,101.75,0.138
32.46,101.96,0.138
32.50,102.16,0.138
32.54,102.37,0.138
32.58,102.58,0.138
32.63,102.79,0.138
32.67,103.00,0.138
32.71,103.21,0.138
32.75,103.41,0.138
32.79,103.62,0.137
32.83,103.83,0.137
32.88,104.04,0.137
32.92,104.25,0.137
32.96,104.46,0.137
33.00,104.67,0.137
33.04,104.87,0.137
33.08,105.08,0.137
33.13,105.29,0.137
33.17,105.50,0.137
33.21,105.71,0.137
33.25,105.92,0.137
33.29,106.12,0.137
33.33,106.33,0.137
33.38,106.54,0.137
33.42,106.75,0.137
33.46,106.96,0.137
33.50,107.17,0.137
33.54,107.38,0.137
33.58,107.59,0.137
33.63,107.79,0.137
33.67,108.00,0.137
33.71,108.21,0.137
33.75,108.42,0.137
33.79,108.63,0.137
33.83,108.84,0.137
33.88,109.04,0.137
33.92,109.25,0.137
33.96,109.46,0.137
34.00,109.67,0.136
34.04,109.88,0.137
34.08,110.09,0.136
34.13,110.30,0.136
34.17,110.50,0.136
34.21,110.71,0.136
34.25,110.92,0.136
34.29,111.13,0.136
34.33,111.34,0.136
34.38,111.55,0.136
34.42,111.75,0.136
34.46,111.96,0.136
34.50,112.17,0.136
34.54,112.38,0.136
34.58,112.59,0.136
34.63,112.80,0.136
34.67,113.01,0.136
34.71,113.21,0.136
34.75,113.42,0.136
34.79,113.63,0.136
34.83,113.84,0.136
34.88,114.05,0.136
34.92,114.26,0.136
34.96,114.46,0.136
35.00,114.67,0.136
35.04,114.88,0.136
35.08,115.09,0.136
35.13,115.30,0.136
35.17,115.51,0.136
35.21,115.71,0.136
35.25,115.92,0.136
35.29,116.13,0.136
35.33,116.34,0.136
35.38,116.55,0.136
35.42,116.76,0.136
35.46,116.97,0.136
35.50,117.17,0.136
35.54,117.38,0.136
35.58,117.59,0.136
35.63,117.80,0.136
35.67,118.01,0.136
35.71,118.22,0.136
35.75,118.43,0.136
35.79,118.63,0.136
35.83,118.84,0.136
35.88,119.05,0.136
35.92,119.26,0.136
35.96,119.47,0.136
36.00,119.68,0.136
36.04,119.89,0.136
36.08,120.09,0.136
36.13,120.30,0.136
36.17,120.51,0.136
36.21,120.72,0.136
36.25,120.93,0.136
36.29,121.14,0.136
36.33,121.35,0.136
36.38,121.55,0.136
36.42,121.76,0.136
36.46,121.97,0.135
36.50,122.18,0.136
36.54,122.39,0.135
36.58,122.60,0.136
36.63,122.80,0.136
36.67,123.01,0.136
36.71,123.22,0.136
36.75,123.43,0.135
36.79,123.64,0.135
36.83,123.85,0.135
36.88,124.05,0.136
36.92,124.26,0.136
36.96,124.47,0.136
37.00,124.68,0.136
37.04,124.89,0.136
37.08,125.10,0.136
37.13,125.30,0.135
37.17,125.51,0.135
37.21,125.72,0.135
37.25,125.93,0.136
37.29,126.14,0.136
37.33,126.35,0.136
37.38,126.55,0.136
37.42,126.76,0.136
37.46,126.97,0.136
37.50,127.18,0.136
37.54,127.39,0.136
37.58,127.60,0.136
37.63,127.81,0.136
37.67,128.01,0.136
37.71,128.22,0.135
37.75,128.43,0.135
37.79,128.64,0.135
37.83,128.85,0.135
37.88,129.06,0.136
37.92,129.26,0.136
37.96,129.47,0.136
38.00,129.68,0.136
38.04,129.89,0.136
38.08,130.10,0.136
38.13,130.31,0.136
38.17,130.52,0.136
38.21,130.72,0.136
38.25,130.93,0.136
38.29,131.14,0.136
38.33,131.35,0.136
38.38,131.56,0.136
38.42,131.77,0.136
38.46,131.98,0.136
38.50,132.18,0.136
38.54,132.39,0.136
38.58,132.60,0.136
38.63,132.81,0.136
38.67,133.02,0.136
38.71,133.23,0.136
38.75,133.43,0.136
38.79,133.64,0.136
38.83,133.85,0.136
38.88,134.06,0.136
38.92,134.27,0.136
38.96,134.48,0.136
39.00,134.69,0.136
39.04,134.89,0.136
39.08,135.10,0.136
39.13,135.31,0.136
39.17,135.52,0.136
39.21,135.73,0.137
39.25,135.93,0.137
39.29,136.14,0.137
39.33,136.35,0.137
39.38,136.56,0.137
39.42,136.77,0.137
39.46,136.98,0.137
39.50,137.19,0.137
39.54,137.39,0.137
39.58,137.60,0.137
39.63,137.81,0.137
39.67,138.02,0.137
39.71,138.23,0.137
39.75,138.44,0.137
39.79,138.65,0.137
39.83,138.85,0.137
39.88,139.06,0.137
39.92,139.27,0.137
39.96,139.48,0.137
40.00,139.69,0.137
40.04,139.89,0.137
40.08,140.10,0.137
40.13,140.31,0.137
40.17,140.52,0.137
40.21,140.73,0.137
40.25,140.94,0.137
40.29,141.14,0.137
40.33,141.35,0.137
40.38,141.56,0.137
40.42,141.77,0.137
40.46,141.98,0.137
40.50,142.19,0.137
40.54,142.40,0.137
40.58,142.61,0.138
40.63,142.82,0.138
40.67,143.02,0.137
40.71,143.23,0.137
40.75,143.44,0.137
40.79,143.65,0.137
40.83,143.86,0.138
40.88,144.07,0.138
40.92,144.27,0.138
40.96,144.48,0.138
41.00,144.69,0.138
41.04,144.90,0.138
41.08,145.10,0.138
41.13,145.31,0.138
41.17,145.52,0.138
41.21,145.73,0.138
41.25,145.94,0.138
41.29,146.15,0.138
41.33,146.36,0.138
41.38,146.57,0.138
41.42,146.77,0.138
41.46,146.98,0.138
41.50,147.19,0.138
41.54,147.40,0.138
41.58,147.61,0.138
41.63,147.82,0.138
41.67,148.02,0.138
41.71,148.23,0.138
41.75,148.44,0.138
41.79,148.65,0.138
41.83,148.86,0.138
41.88,149.07,0.138
41.92,149.28,0.138
41.96,149.48,0.139
42.00,149.69,0.139
42.04,149.90,0.139
42.08,150.11,0.139
42.13,150.32,0.139
42.17,150.53,0.139
42.21,150.74,0.139
42.25,150.94,0.139
42.29,151.15,0.139
42.33,151.36,0.139
42.38,151.57,0.139
42.42,151.78,0.139
42.46,151.98,0.139
42.50,152.19,0.139
42.54,152.40,0.139
42.58,152.61,0.139
42.63,152.82,0.139
42.67,153.03,0.139
42.71,153.24,0.139
42.75,153.45,0.139
42.79,153.65,0.139
42.83,153.86,0.139
42.88,154.07,0.139
42.92,154.28,0.139
42.96,154.49,0.139
43.00,154.69,0.139
43.04,154.90,0.139
43.08,155.11,0.139
43.13,155.32,0.139
43.17,155.53,0.139
43.21,155.74,0.139
43.25,155.94,0.139
43.29,156.15,0.139
43.33,156.36,0.139
43.38,156.57,0.139
43.42,156.78,0.139
43.46,156.99,0.139
43.50,157.20,0.139
43.54,157.41,0.139
43.58,157.61,0.139
43.63,157.82,0.139
43.67,158.03,0.139
43.71,158.24,0.139
43.75,158.45,0.139
43.79,158.66,0.139
43.83,158.86,0.139
43.88,159.07,0.139
43.92,159.28,0.139
43.96,159.49,0.139
44.00,159.70,0.139
44.04,159.91,0.139
44.08,160.11,0.139
44.13,160.32,0.139
44.17,160.53,0.139
44.21,160.74,0.139
44.25,160.95,0.139
44.29,161.16,0.139
44.33,161.37,0.140
44.38,161.57,0.140
44.42,161.78,0.140
44.46,161.99,0.140
44.50,162.20,0.140
44.54,162.41,0.140
44.58,162.61,0.140
44.63,162.82,0.140
44.67,163.03,0.140
44.71,163.24,0.140
44.75,163.45,0.140
44.79,163.66,0.140
44.83,163.87,0.140
44.88,164.07,0.140
44.92,164.28,0.140
44.96,164.49,0.140
45.00,164.70,0.140
45.04,164.91,0.140
45.08,165.12,0.140
45.13,165.32,0.140
45.17,165.53,0.140
45.21,165.74,0.140
45.25,165.95,0.140
45.29,166.16,0.140
45.33,166.37,0.140
45.38,166.58,0.140
45.42,166.78,0.140
45.46,166.99,0.140
45.50,167.20,0.140
45.54,167.41,0.140
45.58,167.62,0.140
45.63,167.83,0.140
45.67,168.03,0.140
45.71,168.24,0.140
45.75,168.45,0.140
45.79,168.66,0.140
45.83,168.87,0.140
45.88,169.08,0.140
45.92,169.28,0.140
45.96,169.49,0.140
46.00,169.70,0.140
46.04,169.91,0.140
46.08,170.12,0.140
46.13,170.33,0.140
46.17,170.53,0.141
46.21,170.74,0.141
46.25,170.95,0.141
46.29,171.16,0.141
46.33,171.37,0.141
46.38,171.58,0.141
46.42,171.79,0.141
46.46,171.99,0.141
46.50,172.20,0.141
46.54,172.41,0.141
46.58,172.62,0.141
46.63,172.83,0.141
46.67,173.04,0.141
46.71,173.24,0.141
46.75,173.45,0.141
46.79,173.66,0.141
46.83,173.87,0.141
46.88,174.08,0.141
46.92,174.29,0.141
46.96,174.50,0.141
47.00,174.70,0.141
47.04,174.91,0.141
47.08,175.12,0.141
47.13,175.33,0.141
47.17,175.54,0.141
47.21,175.75,0.141
47.25,175.96,0.141
47.29,176.16,0.141
47.33,176.37,0.141
47.38,176.58,0.141
47.42,176.79,0.141
47.46,176.99,0.141
47.50,177.20,0.141
47.54,177.41,0.141
47.58,177.62,0.141
47.63,177.83,0.141
47.67,178.04,0.142
47.71,178.25,0.142
47.75,178.46,0.142
47.79,178.66,0.142
47.83,178.87,0.142
47.88,179.08,0.142
47.92,179.29,0.141
47.96,179.50,0.141
48.00,179.70,0.141
48.04,179.91,0.141
48.08,180.12,0.141
48.13,180.33,0.141
48.17,180.54,0.141
48.21,180.75,0.142
48.25,180.96,0.142
48.29,181.17,0.142
48.33,181.37,0.142
48.38,181.58,0.142
48.42,181.79,0.142
48.46,182.00,0.142
48.50,182.21,0.142
48.54,182.41,0.142
48.58,182.62,0.142
48.63,182.83,0.143
48.67,183.04,0.143
48.71,183.25,0.143
48.75,183.46,0.143
48.79,183.67,0.143
48.83,183.88,0.143
48.88,184.08,0.142
48.92,184.29,0.142
48.96,184.50,0.142
49.00,184.71,0.142
49.04,184.92,0.143
49.08,185.12,0.143
49.13,185.33,0.143
49.17,185.54,0.143
49.21,185.75,0.143
49.25,185.96,0.143
49.29,186.17,0.143
49.33,186.37,0.143
49.38,186.58,0.143
49.42,186.79,0.143
49.46,187.00,0.143
49.50,187.21,0.143
49.54,187.42,0.143
49.58,187.63,0.144
49.63,187.83,0.144
49.67,188.04,0.144
49.71,188.25,0.144
49.75,188.46,0.144
49.79,188.67,0.144
49.83,188.88,0.144
49.88,189.09,0.144
49.92,189.29,0.144
49.96,189.50,0.144
50.00,189.71,0.144
50.04,189.92,0.144
50.08,190.12,0.144
50.13,190.33,0.144
50.17,190.54,0.144
50.21,190.75,0.144
50.25,190.96,0.144
50.29,191.17,0.144
50.33,191.38,0.145
50.38,191.59,0.144
50.42,191.80,0.144
50.46,192.00,0.144
50.50,192.21,0.144
50.54,192.42,0.144
50.58,192.63,0.144
50.63,192.84,0.144
50.67,193.05,0.145
50.71,193.25,0.145
50.75,193.46,0.145
50.79,193.67,0.145
50.83,193.88,0.145
50.88,194.09,0.145
50.92,194.30,0.145
50.96,194.50,0.145
51.00,194.71,0.145
51.04,194.92,0.145
51.08,195.13,0.145
51.13,195.34,0.145
51.17,195.55,0.145
51.21,195.75,0.145
51.25,195.96,0.145
51.29,196.17,0.145
51.33,196.38,0.145
51.38,196.59,0.145
51.42,196.80,0.145
51.46,197.00,0.145
51.50,197.21,0.145
51.54,197.42,0.145
51.58,197.63,0.145
51.63,197.84,0.145
51.67,198.05,0.145
51.71,198.26,0.145
51.75,198.46,0.145
51.79,198.67,0.145
51.83,198.88,0.145
51.88,199.09,0.146
51.92,199.30,0.146
51.96,199.51,0.146
52.00,199.72,0.146
52.04,199.93,0.146
52.08,200.14,0.145
52.13,200.34,0.145
52.17,200.55,0.145
52.21,200.76,0.145
52.25,200.97,0.145
52.29,201.18,0.144
52.33,201.38,0.144
52.38,201.59,0.144
52.42,201.80,0.144
52.46,202.01,0.144
52.50,202.22,0.144
52.54,202.43,0.144
52.58,202.63,0.144
52.63,202.84,0.144
52.67,203.05,0.144
52.71,203.26,0.144
52.75,203.47,0.144
52.79,203.67,0.144
52.83,203.88,0.144
52.88,204.09,0.144
52.92,204.30,0.145
52.96,204.51,0.145
53.00,204.72,0.145
53.04,204.92,0.144
53.08,205.13,0.144
53.13,205.34,0.144
53.17,205.55,0.144
53.21,205.76,0.144
53.25,205.97,0.144
53.29,206.17,0.144
53.33,206.38,0.144
53.38,206.59,0.145
53.42,206.80,0.145
53.46,207.01,0.145
53.50,207.22,0.145
53.54,207.43,0.145
53.58,207.64,0.145
53.63,207.84,0.145
53.67,208.05,0.145
53.71,208.26,0.145
53.75,208.47,0.145
53.79,208.67,0.145
53.83,208.88,0.145
53.88,209.09,0.145
53.92,209.30,0.145
53.96,209.51,0.145
54.00,209.72,0.145
54.04,209.93,0.145
54.08,210.13,0.145
54.13,210.34,0.145
54.17,210.55,0.145
54.21,210.76,0.145
54.25,210.97,0.145
54.29,211.18,0.145
54.33,211.38,0.145
54.38,211.59,0.146
54.42,211.80,0.146
54.46,212.01,0.146
54.50,212.22,0.146
54.54,212.43,0.146
54.58,212.64,0.146
54.63,212.85,0.145
54.67,213.06,0.145
54.71,213.26,0.144
54.75,213.47,0.144
54.79,213.68,0.144
54.83,213.88,0.144
54.88,214.09,0.144
54.92,214.30,0.144
54.96,214.50,0.144
55.00,214.71,0.145
55.04,214.92,0.146
55.08,215.13,0.146
55.13,215.34,0.147
55.17,215.55,0.147
55.21,215.76,0.148
55.25,215.97,0.148
55.29,216.18,0.148
55.33,216.39,0.148
55.38,216.59,0.149
55.42,216.80,0.149
55.46,217.01,0.149
55.50,217.22,0.149
55.54,217.43,0.149
55.58,217.64,0.149
55.63,217.85,0.150
55.67,218.06,0.150
55.71,218.27,0.150
55.75,218.48,0.150
55.79,218.68,0.149
55.83,218.89,0.149
55.88,219.10,0.148
55.92,219.31,0.148
55.96,219.52,0.148
56.00,219.72,0.148
56.04,219.93,0.148
56.08,220.14,0.148
56.13,220.35,0.148
56.17,220.56,0.147
56.21,220.76,0.147
56.25,220.97,0.147
56.29,221.18,0.147
56.33,221.39,0.147
56.38,221.60,0.147
56.42,221.81,0.147
56.46,222.01,0.147
56.50,222.22,0.147
56.54,222.43,0.147
56.58,222.64,0.147
56.63,222.85,0.147
56.67,223.06,0.147
56.71,223.26,0.148
56.75,223.47,0.148
56.79,223.68,0.148
56.83,223.89,0.148
56.88,224.10,0.148
56.92,224.31,0.148
56.96,224.52,0.148
57.00,224.72,0.148
57.04,224.93,0.148
57.08,225.14,0.148
57.13,225.35,0.148
57.17,225.56,0.148
57.21,225.77,0.148
57.25,225.97,0.148
57.29,226.18,0.149
57.33,226.39,0.149
57.38,226.60,0.149
57.42,226.81,0.149
57.46,227.02,0.149
57.50,227.22,0.149
57.54,227.43,0.149
57.58,227.64,0.149
57.63,227.85,0.149
57.67,228.06,0.149
57.71,228.26,0.149
57.75,228.47,0.149
57.79,228.68,0.149
57.83,228.89,0.149
57.88,229.10,0.149
57.92,229.31,0.149
57.96,229.51,0.149
58.00,229.72,0.149
58.04,229.93,0.149
58.08,230.14,0.150
58.13,230.35,0.150
58.17,230.56,0.150
58.21,230.77,0.150
58.25,230.98,0.150
58.29,231.18,0.150
58.33,231.39,0.150
58.38,231.60,0.150
58.42,231.81,0.150
58.46,232.02,0.150
58.50,232.22,0.150
58.54,232.43,0.150
58.58,232.64,0.150
58.63,232.85,0.150
58.67,233.06,0.151
58.71,233.27,0.151
58.75,233.48,0.151
58.79,233.69,0.151
58.83,233.89,0.151
58.88,234.10,0.151
58.92,234.31,0.151
58.96,234.52,0.151
59.00,234.73,0.150
59.04,234.94,0.150
59.08,235.14,0.150
59.13,235.35,0.150
59.17,235.56,0.150
59.21,235.77,0.151
59.25,235.98,0.151
59.29,236.18,0.151
59.33,236.39,0.151
59.38,236.60,0.151
59.42,236.81,0.151
59.46,237.02,0.151
59.50,237.23,0.151
59.54,237.43,0.151
59.58,237.64,0.151
59.63,237.85,0.151
59.67,238.06,0.151
59.71,238.27,0.151
59.75,238.48,0.151
59.79,238.69,0.151
59.83,238.89,0.151
59.88,239.10,0.151
59.92,239.31,0.151
59.96,239.52,0.151
60.00,239.73,0.151
60.04,239.94,0.152
60.08,240.14,0.152
60.13,240.35,0.152
60.17,240.56,0.152
60.21,240.77,0.152
60.25,240.98,0.152
60.29,241.19,0.152
60.33,241.39,0.153
60.38,241.60,0.153
60.42,241.81,0.153
60.46,242.02,0.153
60.50,242.23,0.153
60.54,242.44,0.153
60.58,242.64,0.153
60.63,242.85,0.153
60.67,243.06,0.154
60.71,243.27,0.154
60.75,243.48,0.154
60.79,243.69,0.154
60.83,243.89,0.154
60.88,244.10,0.154
60.92,244.31,0.154
60.96,244.52,0.154
61.00,244.73,0.154
61.04,244.94,0.154
61.08,245.15,0.154
61.13,245.36,0.154
61.17,245.56,0.154
61.21,245.77,0.154
61.25,245.98,0.154
61.29,246.19,0.154
61.33,246.40,0.154
61.38,246.60,0.154
61.42,246.81,0.155
61.46,247.02,0.155
61.50,247.23,0.155
61.54,247.44,0.155
61.58,247.65,0.155
61.63,247.86,0.155
61.67,248.06,0.155
61.71,248.27,0.155
61.75,248.48,0.155
61.79,248.69,0.156
61.83,248.90,0.156
61.88,249.11,0.156
61.92,249.31,0.156
61.96,249.52,
61.99,,

[step]
Ramp 5.00 °C/min to -60.00 °C
Time,Temperature,Heat Flow (Normalized)
min,°C,W/g
62.99,250.16,-0.086
63.03,250.16,-0.086
63.07,250.13,-0.188
63.11,250.04,-0.284
63.15,249.88,-0.327
63.19,249.70,-0.328
63.24,249.49,-0.327
63.28,249.29,-0.324
63.32,249.08,-0.324
63.36,248.88,-0.323
63.40,248.67,-0.323
63.44,248.46,-0.322
63.49,248.25,-0.323
63.53,248.05,-0.322
63.57,247.84,-0.322
63.61,247.63,-0.322
63.65,247.43,-0.322
63.69,247.22,-0.322
63.74,247.01,-0.321
63.78,246.81,-0.321
63.82,246.60,-0.321
63.86,246.39,-0.321
63.90,246.18,-0.320
63.94,245.98,-0.321
63.99,245.77,-0.321
64.03,245.56,-0.321
64.07,245.35,-0.321
64.11,245.14,-0.321
64.15,244.94,-0.321
64.19,244.73,-0.320
64.24,244.52,-0.320
64.28,244.32,-0.319
64.32,244.11,-0.319
64.36,243.90,-0.319
64.40,243.69,-0.319
64.44,243.48,-0.319
64.49,243.28,-0.318
64.53,243.07,-0.319
64.57,242.86,-0.319
64.61,242.65,-0.319
64.65,242.44,-0.319
64.69,242.24,-0.319
64.74,242.03,-0.319
64.78,241.82,-0.318
64.82,241.61,-0.318
64.86,241.40,-0.318
64.90,241.19,-0.318
64.94,240.99,-0.317
64.99,240.78,-0.317
65.03,240.57,-0.317
65.07,240.36,-0.317
65.11,240.15,-0.317
65.15,239.94,-0.318
65.19,239.73,-0.317
65.24,239.52,-0.317
65.28,239.32,-0.316
65.32,239.11,-0.316
65.36,238.90,-0.316
65.40,238.69,-0.315
65.44,238.49,-0.316
65.49,238.28,-0.316
65.53,238.07,-0.316
65.57,237.86,-0.316
65.61,237.65,-0.315
65.65,237.45,-0.315
65.69,237.24,-0.315
65.74,237.03,-0.315
65.78,236.82,-0.315
65.82,236.61,-0.316
65.86,236.40,-0.315
65.90,236.20,-0.315
65.94,235.99,-0.315
65.99,235.78,-0.315
66.03,235.57,-0.315
66.07,235.36,-0.315
66.11,235.15,-0.315
66.15,234.95,-0.315
66.19,234.74,-0.315
66.24,234.53,-0.315
66.28,234.32,-0.315
66.32,234.11,-0.315
66.36,233.90,-0.315
66.40,233.69,-0.314
66.44,233.49,-0.314
66.49,233.28,-0.314
66.53,233.07,-0.314
66.57,232.86,-0.314
66.61,232.65,-0.314
66.65,232.45,-0.314
66.69,232.24,-0.314
66.74,232.03,-0.314
66.78,231.82,-0.314
66.82,231.61,-0.314
66.86,231.41,-0.314
66.90,231.20,-0.314
66.94,230.99,-0.314
66.99,230.78,-0.314
67.03,230.57,-0.314
67.07,230.37,-0.314
67.11,230.16,-0.314
67.15,229.95,-0.314
67.19,229.74,-0.314
67.24,229.53,-0.314
67.28,229.32,-0.314
67.32,229.11,-0.314
67.36,228.91,-0.315
67.40,228.70,-0.314
67.44,228.49,-0.314
67.49,228.28,-0.314
67.53,228.07,-0.314
67.57,227.87,-0.315
67.61,227.66,-0.315
67.65,227.45,-0.315
67.69,227.24,-0.315
67.74,227.03,-0.315
67.78,226.82,-0.315
67.82,226.61,-0.315
67.86,226.41,-0.314
67.90,226.20,-0.315
67.94,225.99,-0.314
67.99,225.78,-0.314
68.03,225.57,-0.314
68.07,225.37,-0.314
68.11,225.16,-0.314
68.15,224.95,-0.314
68.19,224.74,-0.315
68.24,224.53,-0.315
68.28,224.32,-0.315
68.32,224.11,-0.314
68.36,223.91,-0.315
68.40,223.70,-0.315
68.45,223.49,-0.315
68.49,223.28,-0.314
68.53,223.07,-0.314
68.57,222.86,-0.314
68.61,222.66,-0.314
68.65,222.45,-0.313
68.70,222.24,-0.313
68.74,222.03,-0.313
68.78,221.82,-0.313
68.82,221.61,-0.313
68.86,221.41,-0.313
68.90,221.20,-0.313
68.95,220.99,-0.313
68.99,220.78,-0.312
69.03,220.57,-0.312
69.07,220.37,-0.312
69.11,220.16,-0.313
69.15,219.95,-0.313
69.20,219.74,-0.313
69.24,219.53,-0.313
69.28,219.32,-0.312
69.32,219.12,-0.312
69.36,218.91,-0.312
69.40,218.70,-0.312
69.45,218.49,-0.312
69.49,218.28,-0.312
69.53,218.08,-0.312
69.57,217.87,-0.313
69.61,217.66,-0.312
69.65,217.45,-0.312
69.70,217.24,-0.313
69.74,217.03,-0.313
69.78,216.83,-0.313
69.82,216.62,-0.313
69.86,216.41,-0.313
69.90,216.20,-0.313
69.95,215.99,-0.313
69.99,215.78,-0.313
70.03,215.58,-0.312
70.07,215.37,-0.312
70.11,215.16,-0.312
70.15,214.95,-0.313
70.20,214.74,-0.313
70.24,214.53,-0.313
70.28,214.32,-0.313
70.32,214.12,-0.313
70.36,213.91,-0.313
70.40,213.70,-0.313
70.45,213.49,-0.313
70.49,213.28,-0.313
70.53,213.08,-0.313
70.57,212.87,-0.313
70.61,212.66,-0.313
70.65,212.45,-0.313
70.70,212.24,-0.313
70.74,212.03,-0.313
70.78,211.83,-0.313
70.82,211.62,-0.313
70.86,211.41,-0.312
70.90,211.20,-0.313
70.95,211.00,-0.313
70.99,210.79,-0.313
71.03,210.58,-0.313
71.07,210.37,-0.313
71.11,210.16,-0.313
71.15,209.95,-0.313
71.20,209.74,-0.313
71.24,209.54,-0.313
71.28,209.33,-0.313
71.32,209.12,-0.313
71.36,208.91,-0.313
71.40,208.70,-0.313
71.45,208.49,-0.313
71.49,208.28,-0.313
71.53,208.08,-0.313
71.57,207.87,-0.313
71.61,207.66,-0.313
71.65,207.45,-0.313
71.70,207.24,-0.313
71.74,207.04,-0.313
71.78,206.83,-0.313
71.82,206.62,-0.313
71.86,206.41,-0.313
71.90,206.20,-0.313
71.95,206.00,-0.313
71.99,205.79,-0.313
72.03,205.58,-0.313
72.07,205.37,-0.313
72.11,205.16,-0.313
72.15,204.95,-0.313
72.20,204.75,-0.313
72.24,204.54,-0.313
72.28,204.33,-0.313
72.32,204.12,-0.313
72.36,203.91,-0.313
72.40,203.70,-0.313
72.45,203.50,-0.313
72.49,203.29,-0.313
72.53,203.08,-0.313
72.57,202.87,-0.313
72.61,202.66,-0.313
72.65,202.45,-0.313
72.70,202.24,-0.313
72.74,202.04,-0.313
72.78,201.83,-0.313
72.82,201.62,-0.313
72.86,201.41,-0.313
72.90,201.20,-0.313
72.95,201.00,-0.313
72.99,200.79,-0.313
73.03,200.58,-0.313
73.07,200.37,-0.313
73.11,200.16,-0.313
73.15,199.95,-0.313
73.20,199.74,-0.313
73.24,199.53,-0.314
73.28,199.33,-0.314
73.32,199.12,-0.313
73.36,198.91,-0.313
73.40,198.70,-0.313
73.45,198.49,-0.313
73.49,198.29,-0.313
73.53,198.08,-0.314
73.57,197.87,-0.314
73.61,197.66,-0.313
73.65,197.45,-0.314
73.70,197.24,-0.314
73.74,197.04,-0.313
73.78,196.83,-0.313
73.82,196.62,-0.313
73.86,196.41,-0.314
73.90,196.20,-0.314
73.95,196.00,-0.314
73.99,195.79,-0.314
74.03,195.58,-0.314
74.07,195.37,-0.314
74.11,195.16,-0.314
74.15,194.96,-0.313
74.20,194.75,-0.314
74.24,194.54,-0.314
74.28,194.33,-0.314
74.32,194.12,-0.314
74.36,193.91,-0.314
74.40,193.70,-0.314
74.45,193.50,-0.314
74.49,193.29,-0.313
74.53,193.08,-0.314
74.57,192.87,-0.314
74.61,192.66,-0.314
74.65,192.45,-0.314
74.70,192.24,-0.314
74.74,192.04,-0.314
74.78,191.83,-0.314
74.82,191.62,-0.314
74.86,191.41,-0.314
74.90,191.20,-0.314
74.95,191.00,-0.314
74.99,190.79,-0.314
75.03,190.58,-0.314
75.07,190.37,-0.314
75.11,190.16,-0.314
75.15,189.96,-0.314
75.20,189.75,-0.314
75.24,189.54,-0.314
75.28,189.33,-0.314
75.32,189.12,-0.314
75.36,188.91,-0.314
75.40,188.71,-0.314
75.45,188.50,-0.314
75.49,188.29,-0.314
75.53,188.08,-0.314
75.57,187.87,-0.314
75.61,187.66,-0.314
75.65,187.46,-0.314
75.70,187.25,-0.314
75.74,187.04,-0.314
[...]
281.86,88.91,0.112,1.194
281.90,89.12,0.112,1.195
281.94,89.33,0.112,1.196
281.99,89.54,0.112,1.196
282.03,89.75,0.112,1.196
282.07,89.96,0.112,1.198
282.11,90.17,0.112,1.198
282.15,90.37,0.112,1.197
282.19,90.58,0.112,1.198
282.24,90.79,0.112,1.198
282.28,91.00,0.112,1.197
282.32,91.21,0.112,1.198
282.36,91.42,0.112,1.198
282.40,91.62,0.112,1.200
282.44,91.83,0.113,1.202
282.49,92.04,0.113,1.202
282.53,92.25,0.113,1.201
282.57,92.46,0.112,1.200
282.61,92.67,0.112,1.200
282.65,92.87,0.113,1.200
282.69,93.08,0.113,1.200
282.74,93.29,0.113,1.202
282.78,93.50,0.113,1.203
282.82,93.71,0.113,1.205
282.86,93.92,0.113,1.204
282.90,94.13,0.113,1.206
282.94,94.33,0.113,1.205
282.99,94.54,0.113,1.206
283.03,94.75,0.113,1.204
283.07,94.96,0.113,1.206
283.11,95.17,0.113,1.206
283.15,95.38,0.113,1.204
283.19,95.58,0.113,1.206
283.24,95.79,0.113,1.205
283.28,96.00,0.113,1.206
283.32,96.21,0.113,1.206
283.36,96.42,0.113,1.206
283.40,96.63,0.113,1.207
283.44,96.84,0.113,1.208
283.49,97.04,0.113,1.206
283.53,97.25,0.113,1.207
283.57,97.46,0.113,1.206
283.61,97.67,0.113,1.208
283.65,97.88,0.113,1.207
283.69,98.09,0.113,1.208
283.74,98.30,0.114,1.209
283.78,98.50,0.114,1.211
283.82,98.71,0.114,1.210
283.86,98.92,0.114,1.211
283.90,99.13,0.114,1.210
283.94,99.34,0.114,1.210
283.99,99.55,0.114,1.212
284.03,99.76,0.114,1.213
284.07,99.96,0.114,1.214
284.11,100.17,0.114,1.214
284.15,100.38,0.114,1.214
284.19,100.59,0.114,1.213
284.24,100.80,0.114,1.212
284.28,101.01,0.114,1.212
284.32,101.21,0.114,1.213
284.36,101.42,0.114,1.214
284.40,101.63,0.114,1.214
284.44,101.84,0.114,1.214
284.49,102.05,0.114,1.214
284.53,102.26,0.114,1.214
284.57,102.47,0.114,1.213
284.61,102.67,0.114,1.213
284.65,102.88,0.114,1.213
284.69,103.09,0.114,1.214
284.74,103.30,0.114,1.213
284.78,103.51,0.114,1.212
284.82,103.72,0.114,1.212
284.86,103.92,0.114,1.211
284.90,104.13,0.114,1.213
284.94,104.34,0.114,1.213
284.99,104.55,0.114,1.216
285.03,104.76,0.114,1.216
285.07,104.97,0.114,1.218
285.11,105.18,0.114,1.218
285.15,105.38,0.114,1.219
285.19,105.59,0.114,1.219
285.24,105.80,0.114,1.219
285.28,106.01,0.114,1.219
285.32,106.22,0.114,1.218
285.36,106.42,0.115,1.219
285.40,106.63,0.115,1.220
285.44,106.84,0.115,1.223
285.49,107.05,0.115,1.224
285.53,107.26,0.115,1.225
285.57,107.47,0.115,1.224
285.61,107.68,0.115,1.225
285.65,107.88,0.115,1.225
285.69,108.09,0.115,1.225
285.74,108.30,0.115,1.225
285.78,108.51,0.115,1.227
285.82,108.72,0.115,1.226
285.86,108.93,0.116,1.228
285.90,109.14,0.116,1.228
285.94,109.34,0.115,1.228
285.99,109.55,0.116,1.230
286.03,109.76,0.116,1.230
286.07,109.97,0.116,1.229
286.11,110.18,0.116,1.229
286.15,110.39,0.116,1.229
286.19,110.60,0.116,1.229
286.24,110.80,0.116,1.229
286.28,111.01,0.116,1.230
286.32,111.22,0.116,1.231
286.36,111.43,0.116,1.231
286.40,111.64,0.116,1.232
286.44,111.85,0.116,1.231
286.49,112.05,0.116,1.232
286.53,112.26,0.116,1.231
286.57,112.47,0.116,1.232
286.61,112.68,0.116,1.234
286.65,112.89,0.116,1.236
286.69,113.10,0.116,1.237
286.74,113.30,0.116,1.237
286.78,113.51,0.116,1.237
286.82,113.72,0.116,1.237
286.86,113.93,0.116,1.237
286.90,114.14,0.116,1.234
286.94,114.35,0.116,1.235
286.99,114.56,0.116,1.235
287.03,114.76,0.116,1.236
287.07,114.97,0.116,1.235
287.11,115.18,0.116,1.237
287.15,115.39,0.117,1.239
287.19,115.60,0.117,1.240
287.24,115.81,0.117,1.238
287.28,116.01,0.116,1.238
287.32,116.22,0.117,1.238
287.36,116.43,0.117,1.239
287.40,116.64,0.116,1.237
287.44,116.85,0.116,1.234
287.49,117.06,0.116,1.235
287.53,117.26,0.116,1.233
287.57,117.47,0.116,1.233
287.61,117.68,0.116,1.236
287.65,117.89,0.117,1.238
287.69,118.10,0.116,1.238
287.74,118.31,0.116,1.237
287.78,118.51,0.116,1.236
287.82,118.72,0.116,1.235
287.86,118.93,0.117,1.236
287.90,119.14,0.117,1.236
287.94,119.35,0.117,1.239
287.99,119.56,0.117,1.239
288.03,119.77,0.117,1.241
288.07,119.97,0.117,1.243
288.11,120.18,0.117,1.242
288.15,120.39,0.117,1.242
288.19,120.60,0.117,1.242
288.24,120.81,0.117,1.243
288.28,121.02,0.117,1.243
288.32,121.23,0.117,1.242
288.36,121.43,0.117,1.242
288.40,121.64,0.117,1.242
288.44,121.85,0.117,1.241
288.49,122.06,0.117,1.243
288.53,122.27,0.117,1.243
288.57,122.48,0.117,1.244
288.61,122.68,0.117,1.243
288.65,122.89,0.117,1.243
288.69,123.10,0.117,1.245
288.74,123.31,0.118,1.246
288.78,123.52,0.118,1.248
288.82,123.73,0.117,1.249
288.86,123.94,0.117,1.248
288.90,124.14,0.117,1.246
288.94,124.35,0.117,1.245
288.99,124.56,0.117,1.245
289.03,124.77,0.118,1.248
289.07,124.98,0.118,1.250
289.11,125.19,0.118,1.250
289.15,125.39,0.117,1.248
289.19,125.60,0.117,1.247
289.24,125.81,0.117,1.246
289.28,126.02,0.118,1.245
289.32,126.23,0.118,1.245
289.36,126.44,0.118,1.246
289.40,126.65,0.118,1.248
289.44,126.85,0.118,1.249
289.49,127.06,0.118,1.249
289.53,127.27,0.118,1.251
289.57,127.48,0.118,1.251
289.61,127.69,0.118,1.251
289.65,127.90,0.118,1.252
289.69,128.10,0.118,1.252
289.74,128.31,0.118,1.253
289.78,128.52,0.118,1.253
289.82,128.73,0.118,1.254
289.86,128.94,0.118,1.254
289.90,129.15,0.118,1.254
289.94,129.36,0.118,1.255
289.99,129.56,0.118,1.254
290.03,129.77,0.118,1.252
290.07,129.98,0.118,1.251
290.11,130.19,0.118,1.252
290.15,130.40,0.118,1.254
290.19,130.61,0.118,1.254
290.24,130.81,0.118,1.252
290.28,131.02,0.118,1.252
290.32,131.23,0.118,1.253
290.36,131.44,0.119,1.255
290.40,131.65,0.119,1.256
290.44,131.86,0.119,1.257
290.49,132.07,0.119,1.257
290.53,132.27,0.119,1.261
290.57,132.48,0.119,1.261
290.61,132.69,0.119,1.261
290.65,132.90,0.119,1.262
290.69,133.11,0.119,1.263
290.74,133.32,0.119,1.262
290.78,133.52,0.119,1.262
290.82,133.73,0.119,1.262
290.86,133.94,0.119,1.261
290.90,134.15,0.119,1.262
290.94,134.36,0.119,1.262
290.99,134.57,0.119,1.263
291.03,134.77,0.119,1.264
291.07,134.98,0.119,1.263
291.11,135.19,0.119,1.262
291.15,135.40,0.119,1.263
291.19,135.61,0.119,1.264
291.24,135.82,0.119,1.265
291.28,136.02,0.119,1.263
291.32,136.23,0.119,1.265
291.36,136.44,0.120,1.265
291.40,136.65,0.120,1.267
291.44,136.86,0.120,1.268
291.49,137.07,0.120,1.270
291.53,137.28,0.120,1.270
291.57,137.49,0.120,1.270
291.61,137.69,0.120,1.270
291.65,137.90,0.120,1.268
291.69,138.11,0.120,1.267
291.74,138.32,0.120,1.268
291.78,138.53,0.120,1.268
291.82,138.73,0.120,1.269
291.86,138.94,0.120,1.270
291.90,139.15,0.120,1.272
291.94,139.36,0.120,1.274
291.99,139.57,0.120,1.276
292.03,139.78,0.120,1.275
292.07,139.99,0.120,1.276
292.11,140.19,0.121,1.276
292.15,140.40,0.121,1.276
292.19,140.61,0.121,1.277
292.24,140.82,0.121,1.276
292.28,141.03,0.121,1.276
292.32,141.24,0.121,1.278
292.36,141.45,0.121,1.279
292.40,141.65,0.121,1.278
292.44,141.86,0.121,1.279
292.49,142.07,0.121,1.279
292.53,142.28,0.121,1.279
292.57,142.49,0.121,1.282
292.61,142.70,0.121,1.282
292.65,142.91,0.121,1.281
292.69,143.11,0.121,1.281
292.74,143.32,0.121,1.280
292.78,143.53,0.121,1.281
292.82,143.74,0.121,1.280
292.86,143.95,0.121,1.282
292.90,144.16,0.121,1.282
292.94,144.36,0.121,1.283
292.99,144.57,0.121,1.282
293.03,144.78,0.121,1.283
293.07,144.99,0.122,1.286
293.11,145.20,0.122,1.287
293.15,145.41,0.122,1.289
293.19,145.61,0.122,1.291
293.24,145.82,0.122,1.292
293.28,146.03,0.122,1.291
293.32,146.24,0.122,1.291
293.36,146.45,0.122,1.290
293.40,146.66,0.122,1.289
293.44,146.86,0.122,1.288
293.49,147.07,0.122,1.288
293.53,147.28,0.122,1.286
293.57,147.49,0.122,1.288
293.61,147.70,0.122,1.289
293.65,147.91,0.122,1.292
293.69,148.12,0.122,1.292
293.74,148.32,0.122,1.293
293.78,148.53,0.122,1.293
293.82,148.74,0.122,1.293
293.86,148.95,0.122,1.294
293.90,149.16,0.123,1.295
293.94,149.37,0.123,1.296
293.99,149.57,0.123,1.297
294.03,149.78,0.123,1.297
294.07,149.99,0.123,1.296
294.11,150.20,0.123,1.297
294.15,150.41,0.123,1.296
294.19,150.62,0.123,1.299
294.24,150.83,0.123,1.300
294.28,151.03,0.123,1.300
294.32,151.24,0.123,1.298
294.36,151.45,0.123,1.298
294.40,151.66,0.123,1.299
294.44,151.87,0.123,1.299
294.49,152.07,0.123,1.299
294.53,152.28,0.123,1.299
294.57,152.49,0.123,1.301
294.61,152.70,0.123,1.302
294.65,152.91,0.123,1.303
294.69,153.12,0.123,1.303
294.74,153.33,0.123,1.304
294.78,153.53,0.123,1.304
294.82,153.74,0.124,1.305
294.86,153.95,0.124,1.303
294.90,154.16,0.124,1.305
294.94,154.37,0.124,1.306
294.99,154.58,0.124,1.305
295.03,154.78,0.124,1.305
295.07,154.99,0.124,1.307
295.11,155.20,0.124,1.307
295.15,155.41,0.124,1.308
295.19,155.62,0.124,1.309
295.24,155.83,0.124,1.310
295.28,156.04,0.124,1.309
295.32,156.24,0.124,1.310
295.36,156.45,0.124,1.310
295.40,156.66,0.124,1.310
295.44,156.87,0.124,1.311
295.49,157.08,0.124,1.310
295.53,157.29,0.124,1.311
295.57,157.49,0.124,1.311
295.61,157.70,0.124,1.309
295.65,157.91,0.124,1.311
295.69,158.12,0.124,1.311
295.74,158.33,0.125,1.313
295.78,158.54,0.125,1.314
295.82,158.75,0.124,1.311
295.86,158.95,0.124,1.312
295.90,159.16,0.124,1.311
295.94,159.37,0.124,1.311
295.99,159.58,0.125,1.311
296.03,159.79,0.125,1.312
296.07,160.00,0.125,1.313
296.11,160.21,0.125,1.315
296.15,160.41,0.125,1.317
296.19,160.62,0.125,1.319
296.24,160.83,0.125,1.316
296.28,161.04,0.125,1.316
296.32,161.25,0.125,1.314
296.36,161.45,0.125,1.315
296.40,161.66,0.125,1.316
296.44,161.87,0.125,1.318
296.49,162.08,0.125,1.318
296.53,162.29,0.125,1.318
296.57,162.50,0.125,1.319
296.61,162.71,0.125,1.320
296.65,162.91,0.125,1.322
296.69,163.12,0.125,1.321
296.74,163.33,0.125,1.321
296.78,163.54,0.125,1.320
296.82,163.75,0.126,1.321
296.86,163.96,0.126,1.322
296.90,164.16,0.126,1.323
296.94,164.37,0.126,1.324
296.99,164.58,0.126,1.326
297.03,164.79,0.126,1.326
297.07,165.00,0.126,1.327
297.11,165.21,0.126,1.328
297.15,165.42,0.126,1.330
297.19,165.62,0.126,1.330
297.24,165.83,0.126,1.330
297.28,166.04,0.126,1.329
297.32,166.25,0.126,1.327
297.36,166.46,0.126,1.328
297.40,166.66,0.126,1.329
297.44,166.87,0.126,1.328
297.49,167.08,0.127,1.329
297.53,167.29,0.127,1.331
297.57,167.50,0.127,1.331
297.61,167.71,0.127,1.331
297.65,167.92,0.127,1.330
297.69,168.13,0.127,1.331
297.74,168.33,0.127,1.332
297.78,168.54,0.126,1.332
297.82,168.75,0.126,1.330
297.86,168.96,0.126,1.330
297.90,169.17,0.126,1.329
297.94,169.37,0.126,1.329
297.99,169.58,0.127,1.329
298.03,169.79,0.127,1.329
298.07,170.00,0.127,1.331
298.11,170.21,0.127,1.332
298.15,170.42,0.127,1.334
298.19,170.63,0.127,1.335
298.24,170.83,0.127,1.335
298.28,171.04,0.127,1.333
298.32,171.25,0.127,1.333
298.36,171.46,0.127,1.333
298.40,171.67,0.127,1.337
298.44,171.88,0.128,1.339
298.49,172.09,0.128,1.340
298.53,172.29,0.128,1.340
298.57,172.50,0.128,1.341
298.61,172.71,0.128,1.341
298.65,172.92,0.128,1.342
298.69,173.13,0.128,1.342
298.74,173.34,0.128,1.344
298.78,173.54,0.128,1.344
298.82,173.75,0.128,1.346
298.86,173.96,0.128,1.346
298.90,174.17,0.129,1.348
298.94,174.38,0.129,1.347
298.99,174.59,0.129,1.349
299.03,174.79,0.129,1.350
299.07,175.00,0.129,1.350
299.11,175.21,0.129,1.352
299.15,175.42,0.129,1.352
299.19,175.63,0.129,1.354
299.24,175.84,0.129,1.356
299.28,176.05,0.129,1.357
299.32,176.25,0.129,1.356
299.36,176.46,0.129,1.355
299.40,176.67,0.129,1.355
299.44,176.88,0.129,1.355
299.49,177.09,0.129,1.355
299.53,177.30,0.129,1.355
299.57,177.50,0.130,1.357
299.61,177.71,0.130,1.359
299.65,177.92,0.130,1.361
299.69,178.13,0.130,1.361
299.74,178.34,0.130,1.361
299.78,178.55,0.130,1.361
299.82,178.75,0.130,1.361
299.86,178.96,0.130,1.361
299.90,179.17,0.130,1.360
299.94,179.38,0.130,1.361
299.99,179.59,0.130,1.364
300.03,179.80,0.130,1.363
300.07,180.00,0.130,1.363
300.11,180.21,0.130,1.363
300.15,180.42,0.130,1.364
300.19,180.63,0.130,1.363
300.24,180.84,0.130,1.363
300.28,181.05,0.130,1.366
300.32,181.25,0.131,1.368
300.36,181.46,0.131,1.369
300.40,181.67,0.131,1.371
300.44,181.88,0.131,1.368
300.49,182.09,0.131,1.366
300.53,182.30,0.131,1.368
300.57,182.50,0.131,1.371
300.61,182.71,0.131,1.371
300.65,182.92,0.131,1.373
300.69,183.13,0.131,1.374
300.74,183.34,0.131,1.377
300.78,183.55,0.131,1.377
300.82,183.76,0.131,1.376
300.86,183.96,0.131,1.374
300.90,184.17,0.131,1.375
300.94,184.38,0.132,1.377
300.99,184.59,0.132,1.378
301.03,184.80,0.132,1.379
301.07,185.01,0.132,1.382
301.11,185.21,0.132,1.383
301.15,185.42,0.132,1.383
301.19,185.63,0.132,1.383
301.24,185.84,0.132,1.383
301.28,186.05,0.132,1.385
301.32,186.26,0.132,1.386
301.36,186.47,0.133,1.388
301.40,186.67,0.133,1.388
301.44,186.88,0.132,1.386
301.49,187.09,0.132,1.386
301.53,187.30,0.133,1.387
301.57,187.51,0.133,1.389
301.61,187.72,0.133,1.388
301.65,187.92,0.133,1.389
301.69,188.13,0.133,1.391
301.74,188.34,0.133,1.391
301.78,188.55,0.133,1.394
301.82,188.76,0.133,1.395
301.86,188.97,0.133,1.394
301.90,189.17,0.133,1.395
301.94,189.38,0.133,1.396
301.99,189.59,0.133,1.396
302.03,189.80,0.133,1.394
302.07,190.01,0.133,1.396
302.11,190.22,0.133,1.397
302.15,190.42,0.134,1.395
302.19,190.63,0.133,1.392
302.24,190.84,0.134,1.395
302.28,191.05,0.134,1.396
302.32,191.26,0.134,1.397
302.36,191.47,0.134,1.399
302.40,191.68,0.134,1.400
302.44,191.88,0.134,1.400
302.49,192.09,0.134,1.404
302.53,192.30,0.134,1.405
302.57,192.51,0.134,1.403
302.61,192.72,0.134,1.403
302.65,192.92,0.134,1.403
302.69,193.13,0.134,1.402
302.74,193.34,0.135,1.404
302.78,193.55,0.135,1.406
302.82,193.76,0.135,1.408
302.86,193.97,0.135,1.408
302.90,194.18,0.135,1.408
302.94,194.38,0.135,1.407
302.99,194.59,0.135,1.408
303.03,194.80,0.135,1.409
303.07,195.01,0.135,1.410
303.11,195.22,0.136,1.412
303.15,195.43,0.136,1.414
303.19,195.64,0.136,1.417
303.24,195.84,0.136,1.417
303.28,196.05,0.136,1.419
303.32,196.26,0.136,1.420
303.36,196.47,0.136,1.420
303.40,196.68,0.136,1.420
303.44,196.88,0.136,1.419
303.49,197.09,0.136,1.420
303.53,197.30,0.136,1.421
303.57,197.51,0.136,1.422
303.61,197.72,0.137,1.423
303.65,197.93,0.137,1.424
303.69,198.14,0.137,1.424
303.74,198.34,0.137,1.424
303.78,198.55,0.137,1.426
303.82,198.76,0.137,1.428
303.86,198.97,0.137,1.429
303.90,199.18,0.137,1.431
303.94,199.39,0.137,1.431
303.99,199.60,0.137,1.433
304.03,199.80,0.138,1.434
304.07,200.01,0.137,1.433
304.11,200.22,0.137,1.432
304.15,200.43,0.138,1.433
304.19,200.64,0.138,1.434
304.24,200.85,0.138,1.435
304.28,201.05,0.138,1.436
304.32,201.26,0.138,1.437
304.36,201.47,0.138,1.437
304.40,201.68,0.138,1.438
304.44,201.89,0.138,1.436
304.49,202.09,0.138,1.436
304.53,202.30,0.138,1.438
304.57,202.51,0.138,1.438
304.61,202.72,0.138,1.438
304.65,202.93,0.138,1.440
304.69,203.14,0.138,1.440
304.74,203.35,0.138,1.441
304.78,203.55,0.138,1.441
304.82,203.76,0.138,1.441
304.86,203.97,0.138,1.440
304.90,204.18,0.139,1.442
304.94,204.39,0.139,1.444
304.99,204.60,0.139,1.444
305.03,204.81,0.139,1.442
305.07,205.01,0.138,1.440
305.11,205.22,0.139,1.440
305.15,205.43,0.139,1.439
305.19,205.64,0.139,1.439
305.24,205.85,0.139,1.440
305.28,206.06,0.139,1.442
305.32,206.27,0.139,1.442
305.36,206.47,0.139,1.445
305.40,206.68,0.139,1.447
305.44,206.89,0.139,1.447
305.49,207.10,0.139,1.447
305.53,207.31,0.139,1.444
305.57,207.51,0.139,1.444
305.61,207.72,0.139,1.446
305.65,207.93,0.139,1.445
305.69,208.14,0.140,1.447
305.74,208.35,0.140,1.450
305.78,208.56,0.140,1.455
305.82,208.77,0.140,1.454
305.86,208.97,0.140,1.457
305.90,209.18,0.140,1.456
305.94,209.39,0.140,1.454
305.99,209.60,0.140,1.454
306.03,209.81,0.140,1.455
306.07,210.02,0.140,1.456
306.11,210.22,0.141,1.458
306.15,210.43,0.141,1.458
306.19,210.64,0.141,1.460
306.24,210.85,0.141,1.462
306.28,211.06,0.141,1.462
306.32,211.27,0.141,1.463
306.36,211.48,0.141,1.463
306.40,211.68,0.141,1.463
306.44,211.89,0.141,1.462
306.49,212.10,0.141,1.462
306.53,212.31,0.141,1.464
306.57,212.52,0.141,1.464
306.61,212.72,0.141,1.463
306.65,212.93,0.141,1.461
306.69,213.14,0.141,1.462
306.74,213.35,0.141,1.463
306.78,213.56,0.141,1.464
306.82,213.77,0.141,1.466
306.86,213.98,0.142,1.469
306.90,214.18,0.142,1.469
306.94,214.39,0.142,1.469
306.99,214.60,0.142,1.468
307.03,214.81,0.142,1.467
307.07,215.02,0.142,1.467
307.11,215.22,0.142,1.467
307.15,215.43,0.142,1.469
307.19,215.64,0.142,1.469
307.24,215.85,0.142,1.470
307.28,216.06,0.142,1.471
307.32,216.27,0.142,1.472
307.36,216.48,0.142,1.471
307.40,216.68,0.142,1.471
307.44,216.89,0.142,1.473
307.49,217.10,0.142,1.474
307.53,217.31,0.143,1.476
307.57,217.52,0.143,1.476
307.61,217.73,0.143,1.478
307.65,217.94,0.143,1.479
307.69,218.14,0.143,1.478
307.74,218.35,0.143,1.479
307.78,218.56,0.143,1.481
307.82,218.77,0.143,1.482
307.86,218.98,0.144,1.484
307.90,219.19,0.144,1.487
307.94,219.39,0.144,1.487
307.99,219.60,0.144,1.486
308.03,219.81,0.144,1.486
308.07,220.02,0.144,1.484
308.11,220.23,0.144,1.484
308.15,220.43,0.144,1.485
308.19,220.64,0.144,1.487
308.24,220.85,0.144,1.489
308.28,221.06,0.144,1.490
308.32,221.27,0.144,1.492
308.36,221.48,0.144,1.493
308.40,221.69,0.144,1.493
308.44,221.89,0.144,1.492
308.49,222.10,0.144,1.492
308.53,222.31,0.145,1.491
308.57,222.52,0.145,1.492
308.61,222.73,0.145,1.493
308.65,222.94,0.145,1.493
308.69,223.15,0.145,1.494
308.74,223.35,0.145,1.495
308.78,223.56,0.145,1.496
308.82,223.77,0.145,1.495
308.86,223.98,0.145,1.496
308.90,224.19,0.145,1.497
308.94,224.40,0.146,1.499
308.99,224.61,0.146,1.501
309.03,224.81,0.146,1.501
309.07,225.02,0.146,1.504
309.11,225.23,0.146,1.505
309.15,225.44,0.146,1.507
309.19,225.65,0.146,1.506
309.24,225.85,0.146,1.506
309.28,226.06,0.145,1.503
309.32,226.27,0.146,1.502
309.36,226.48,0.146,1.502
309.40,226.69,0.146,1.502
309.44,226.90,0.146,1.504
309.49,227.10,0.146,1.507
309.53,227.31,0.147,1.508
309.57,227.52,0.146,1.508
309.61,227.73,0.147,1.510
309.65,227.94,0.147,1.511
309.69,228.15,0.147,1.511
309.74,228.36,0.146,1.510
309.78,228.56,0.147,1.510
309.82,228.77,0.147,1.510
309.86,228.98,0.147,1.510
309.90,229.19,0.147,1.509
309.94,229.40,0.147,1.509
309.99,229.61,0.147,1.509
310.03,229.81,0.147,1.510
310.07,230.02,0.147,1.511
310.11,230.23,0.147,1.513
310.15,230.44,0.147,1.515
310.19,230.65,0.147,1.516
310.24,230.86,0.147,1.518
310.28,231.06,0.148,1.519
310.32,231.27,0.148,1.519
310.36,231.48,0.148,1.519
310.40,231.69,0.148,1.521
310.44,231.90,0.148,1.520
310.49,232.11,0.148,1.521
310.53,232.32,0.148,1.524
310.57,232.52,0.149,1.526
310.61,232.73,0.149,1.527
310.65,232.94,0.148,1.528
310.69,233.15,0.148,1.528
310.74,233.36,0.148,1.526
310.78,233.56,0.148,1.523
310.82,233.77,0.148,1.524
310.86,233.98,0.148,1.523
310.90,234.19,0.148,1.524
310.94,234.40,0.149,1.525
310.99,234.61,0.149,1.527
311.03,234.81,0.149,1.527
311.07,235.02,0.149,1.527
311.11,235.23,0.149,1.528
311.15,235.44,0.149,1.527
311.19,235.65,0.149,1.524
311.24,235.86,0.149,1.526
311.28,236.07,0.149,1.527
311.32,236.27,0.149,1.528
311.36,236.48,0.149,1.531
311.40,236.69,0.149,1.530
311.44,236.90,0.149,1.530
311.49,237.11,0.149,1.529
311.53,237.32,0.149,1.528
311.57,237.52,0.149,1.529
311.61,237.73,0.149,1.529
311.65,237.94,0.149,1.530
311.69,238.15,0.149,1.531
311.74,238.36,0.149,1.530
311.78,238.57,0.149,1.530
311.82,238.77,0.149,1.529
311.86,238.98,0.149,1.530
311.90,239.19,0.150,1.529
311.94,239.40,0.150,1.533
311.99,239.61,0.150,1.532
312.03,239.82,0.150,1.536
312.07,240.03,0.150,1.538
312.11,240.23,0.150,1.538
312.15,240.44,0.150,1.538
312.19,240.65,0.150,1.540
312.24,240.86,0.151,1.541
312.28,241.07,0.151,1.543
312.32,241.28,0.151,1.543
312.36,241.49,0.151,1.546
312.40,241.69,0.151,1.550
312.44,241.90,0.151,1.550
312.49,242.11,0.151,1.552
312.53,242.32,0.151,1.552
312.57,242.53,0.151,1.552
312.61,242.73,0.151,1.551
312.65,242.94,0.151,1.550
312.69,243.15,0.152,1.550
312.74,243.36,0.152,1.550
312.78,243.57,0.152,1.549
312.82,243.78,0.152,1.552
312.86,243.98,0.152,1.551
312.90,244.19,0.152,1.551
312.94,244.40,0.151,1.549
312.99,244.61,0.152,1.548
313.03,244.82,0.152,1.547
313.07,245.03,0.152,1.546
313.11,245.24,0.152,1.546
313.15,245.44,0.152,1.547
313.19,245.65,0.152,1.547
313.24,245.86,0.152,1.549
313.28,246.07,0.152,1.551
313.32,246.28,0.152,1.552
313.36,246.49,0.152,1.555
313.40,246.69,0.152,1.556
313.44,246.90,0.153,1.558
313.49,247.11,0.153,1.558
313.53,247.32,0.153,1.557
313.57,247.53,0.153,1.558
313.61,247.74,0.153,1.558
313.65,247.94,0.153,1.559
313.69,248.15,0.153,1.561
313.74,248.36,0.153,1.558
313.78,248.57,0.153,1.558
313.82,248.78,0.153,1.559
313.86,248.99,0.153,1.561
313.90,249.19,0.153,
313.94,249.40,,
313.98,,,